Workbook

Sheet Info
A7: Avvikende regnskapsår:
A8: Q1: 1. juli - 30. september
A9: Q2: 1. oktober - 31. desember
A10: Q3: 1. januar - 31. mars
A11: Q4: 1. april- 30. juni

Sheet Modell
A3: Kapitalstruktur | C3: SEK million | D3: Q1 22/23 | E3: Q2 22/23 | F3: Q3 22/23 | G3: Q4 22/23 | H3: Q1 23/24 | I3: Q2 23/24 | J3: Q3 23/24 | K3: Q4 23/24 | L3: Q1 24/25 | M3: Q2 24/25 | N3: Q3 24/25 | O3: Q4 24/25 | P3: Q1 25/26 | Q3: Q2 25/26 | R3: Q3 25/26 | S3: Q4 25/26 | V3: FY 18/19 | W3: FY 19/20 | X3: FY 20/21 | Y3: FY 21/22 | Z3: FY 22/23 | AA3: FY 23/24 | AB3: FY 24/25 | AC3: FY 25/26 | AD3: FY 26/27 | AE3: FY 27/28 | AF3: FY 28/29 | AG3: FY 29/30 | AH3: FY 30/31 | AI3: FY 31/32 | AJ3: FY 32/33 | AK3: FY 33/34 | AL3: FY 34/35
A4: Price | B4: 90 | C4: Revenue | D4: 3104 | E4: 4041 | F4: 4195 | G4: 4199 | H4: 3430 | I4: 4433 | J4: 4613 | K4: 4856 | L4: 3842 | M4: 5025 | N4: 5037 | O4: 5118 | P4: 4101 | Q4: 5231 | V4: 11715 | W4: 12271 | X4: 13340 | Y4: 14339 | Z4: 15539 | AA4: 17332 | AB4: 19022 | AC4: =AB4*1.05 -> 19973.1 | AD4: =AC4*1.05 -> 20971.755 | AE4: =AD4*1.05 -> 22020.343 | AF4: =AE4*1.05 -> 23121.36 | AG4: =AF4*1.05 -> 24277.428 | AH4: =AG4*1.05 -> 25491.299 | AI4: =AH4*1.05 -> 26765.864 | AJ4: =AI4*1.05 -> 28104.157 | ... AL4: =AK4*1.05 -> 30984.834
A5: S/O | B5: 105.5 | C5: Cost of service | D5: -314 | E5: -392 | F5: -367 | G5: -362 | H5: -323 | I5: -431 | J5: -384 | K5: -385 | L5: -348 | M5: -479 | N5: -419 | O5: -410 | P5: -383 | Q5: -492 | V5: -997 | W5: -993 | X5: -1120 | Y5: -1274 | Z5: -1435 | AA5: -1523 | AB5: -1656 | AC5: =AC4*-0.1 -> -1997.31 | AD5: =AD4*-0.1 -> -2097.1755 | AE5: =AE4*-0.1 -> -2202.0343 | AF5: =AF4*-0.1 -> -2312.136 | AG5: =AG4*-0.1 -> -2427.7428 | AH5: =AH4*-0.1 -> -2549.1299 | AI5: =AI4*-0.1 -> -2676.5864 | AJ5: =AJ4*-0.1 -> -2810.4157 | ... AL5: =AL4*-0.1 -> -3098.4834
A6: MC SEKm | B6: =B4*B5 -> 9495 | C6: Gross profit | D6: =SUM(D4:D5) -> 2790 | E6: =SUM(E4:E5) -> 3649 | F6: =SUM(F4:F5) -> 3828 | G6: =SUM(G4:G5) -> 3837 | H6: =SUM(H4:H5) -> 3107 | I6: =SUM(I4:I5) -> 4002 | J6: =SUM(J4:J5) -> 4229 | K6: =SUM(K4:K5) -> 4471 | ... S6: =SUM(S4:S5) -> 0 | V6: =SUM(V4:V5) -> 10718 | W6: =SUM(W4:W5) -> 11278 | X6: =SUM(X4:X5) -> 12220 | Y6: =SUM(Y4:Y5) -> 13065 | Z6: =SUM(Z4:Z5) -> 14104 | AA6: =SUM(AA4:AA5) -> 15809 | AB6: =SUM(AB4:AB5) -> 17366 | AC6: =SUM(AC4:AC5) -> 17975.79 | ... AL6: =SUM(AL4:AL5) -> 27886.35
A7: Cash SEKm | B7: =Q37 -> 661 | C7: Other external expenses | D7: -316 | E7: -393 | F7: -422 | G7: -438 | H7: -366 | I7: -432 | J7: -432 | K7: -505 | L7: -387 | M7: -454 | N7: -439 | O7: -509 | P7: -420 | Q7: -468 | V7: -2517 | W7: -1237 | X7: -1352 | Y7: -1370 | Z7: -1566 | AA7: -1731 | AB7: -1789 | AC7: =AB7*1.03 -> -1842.67 | AD7: =AC7*1.045 -> -1925.5901 | AE7: =AD7*1.05 -> -2021.8697 | AF7: =AE7*1.05 -> -2122.9631 | AG7: =AF7*1.05 -> -2229.1113 | AH7: =AG7*1.05 -> -2340.5669 | AI7: =AH7*1.05 -> -2457.5952 | AJ7: =AI7*1.05 -> -2580.475 | AK7: =AJ7*1.05 -> -2709.4987 | AL7: =AK7*1.05 -> -2844.9736
A8: Debt SEKm | B8: =Q40+Q43+Q41+Q44 -> 12748 | C8: Personnel expenses | D8: -1793 | E8: -2495 | F8: -2532 | G8: -2477 | H8: -2006 | I8: -2738 | J8: -2809 | K8: -2854 | L8: -2258 | M8: -3087 | N8: -3079 | O8: -3018 | P8: -2434 | Q8: -3218 | V8: -7272 | W8: -7591 | X8: -8106 | Y8: -8648 | Z8: -9296 | AA8: -10408 | AB8: -11442 | AC8: =AB8*1.03 -> -11785.26 | AD8: =AC8*1.045 -> -12315.597 | AE8: =AD8*1.05 -> -12931.377 | AF8: =AE8*1.05 -> -13577.945 | AG8: =AF8*1.05 -> -14256.843 | AH8: =AG8*1.05 -> -14969.685 | AI8: =AH8*1.05 -> -15718.169 | AJ8: =AI8*1.05 -> -16504.077 | AK8: =AJ8*1.05 -> -17329.281 | AL8: =AK8*1.05 -> -18195.745
A9: EV SEKm | B9: =B6-B7+B8 -> 21582 | C9: D/A | D9: -448 | E9: -474 | F9: -507 | G9: -495 | H9: -498 | I9: -526 | J9: -556 | K9: -580 | L9: -577 | M9: -604 | N9: -583 | O9: -589 | P9: -571 | Q9: -590 | V9: -296 | W9: -1514 | X9: -1580 | Y9: -1755 | Z9: -1924 | AA9: -2159 | AB9: -2353 | AC9: =AB9*1.03 -> -2423.59 | AD9: =AC9*1.045 -> -2532.6516 | AE9: =AD9*1.05 -> -2659.2841 | AF9: =AE9*1.05 -> -2792.2483 | AG9: =AF9*1.05 -> -2931.8608 | AH9: =AG9*1.05 -> -3078.4538 | AI9: =AH9*1.05 -> -3232.3765 | AJ9: =AI9*1.05 -> -3393.9953 | AK9: =AJ9*1.05 -> -3563.6951 | AL9: =AK9*1.05 -> -3741.8798
C10: Items affecting comparability | D10: 6 | E10: -21 | F10: -6 | G10: -23 | H10: -6 | I10: 0 | J10: -11 | K10: 0 | L10: 0 | M10: 2 | N10: -16 | O10: -13 | P10: 0 | Q10: -13 | V10: 1 | W10: 36 | X10: -7 | Y10: -67 | Z10: -49 | AA10: -21 | AB10: -27 | AC10: =AB10*1.03 -> -27.81 | AD10: =AC10*1.045 -> -29.06145 | AE10: =AD10*1.05 -> -30.514523 | AF10: =AE10*1.05 -> -32.040249 | AG10: =AF10*1.05 -> -33.642261 | AH10: =AG10*1.05 -> -35.324374 | AI10: =AH10*1.05 -> -37.090593 | AJ10: =AI10*1.05 -> -38.945122 | AK10: =AJ10*1.05 -> -40.892379 | AL10: =AK10*1.05 -> -42.936998
C11: Total opex | D11: =D5+D7+D8+D9+D10 -> -2865 | E11: =E5+E7+E8+E9+E10 -> -3775 | F11: =F5+F7+F8+F9+F10 -> -3834 | G11: =G5+G7+G8+G9+G10 -> -3795 | H11: =H5+H7+H8+H9+H10 -> -3199 | I11: =I5+I7+I8+I9+I10 -> -4127 | J11: =J5+J7+J8+J9+J10 -> -4192 | K11: =K5+K7+K8+K9+K10 -> -4324 | ... S11: =S5+S7+S8+S9+S10 -> 0 | V11: =V5+V7+V8+V9+V10 -> -11081 | W11: =W5+W7+W8+W9+W10 -> -11299 | X11: =X5+X7+X8+X9+X10 -> -12165 | Y11: =Y5+Y7+Y8+Y9+Y10 -> -13114 | Z11: =Z5+Z7+Z8+Z9+Z10 -> -14270 | AA11: =AA5+AA7+AA8+AA9+AA10 -> -15842 | AB11: =AB5+AB7+AB8+AB9+AB10 -> -17267 | AC11: =AC5+AC7+AC8+AC9+AC10 -> -18076.64 | ... AL11: =AL5+AL7+AL8+AL9+AL10 -> -27924.019
C12: Operating income (EBIT) | D12: =D4+D11 -> 239 | E12: =E4+E11 -> 266 | F12: =F4+F11 -> 361 | G12: =G4+G11 -> 404 | H12: =H4+H11 -> 231 | I12: =I4+I11 -> 306 | J12: =J4+J11 -> 421 | K12: =K4+K11 -> 532 | ... S12: =S4+S11 -> 0 | V12: =V4+V11 -> 634 | W12: =W4+W11 -> 972 | X12: =X4+X11 -> 1175 | Y12: =Y4+Y11 -> 1225 | Z12: =Z4+Z11 -> 1269 | AA12: =AA4+AA11 -> 1490 | AB12: =AB4+AB11 -> 1755 | AC12: =AC4+AC11 -> 1896.46 | ... AL12: =AL4+AL11 -> 3060.8144
C13: Net financial items | D13: -120 | E13: -122 | F13: -144 | G13: -126 | H13: -155 | I13: -168 | J13: -149 | K13: -193 | L13: -179 | M13: -179 | N13: -195 | O13: -157 | P13: -186 | Q13: -200 | V13: -69 | W13: -417 | X13: -402 | Y13: =1-441 -> -440 | Z13: =33-543 -> -510 | AA13: =22-687 -> -665 | AB13: -710 | AC13: =AB13*1.05 -> -745.5 | AD13: =AC13*1.03 -> -767.865 | AE13: =AD13*1.03 -> -790.90095 | AF13: =AE13*1.03 -> -814.62798 | AG13: =AF13*1.03 -> -839.06682 | AH13: =AG13*1.03 -> -864.23882 | AI13: =AH13*1.03 -> -890.16599 | AJ13: =AI13*1.03 -> -916.87097 | AK13: =AJ13*1.03 -> -944.3771 | AL13: =AK13*1.03 -> -972.70841
C14: PTP | D14: =SUM(D12:D13) -> 119 | E14: =SUM(E12:E13) -> 144 | F14: =SUM(F12:F13) -> 217 | G14: =SUM(G12:G13) -> 278 | H14: =SUM(H12:H13) -> 76 | I14: =SUM(I12:I13) -> 138 | J14: =SUM(J12:J13) -> 272 | K14: =SUM(K12:K13) -> 339 | ... S14: =SUM(S12:S13) -> 0 | V14: =SUM(V12:V13) -> 565 | W14: =SUM(W12:W13) -> 555 | X14: =SUM(X12:X13) -> 773 | Y14: =SUM(Y12:Y13) -> 785 | Z14: =SUM(Z12:Z13) -> 759 | AA14: =SUM(AA12:AA13) -> 825 | AB14: =SUM(AB12:AB13) -> 1045 | AC14: =SUM(AC12:AC13) -> 1150.96 | ... AL14: =SUM(AL12:AL13) -> 2088.106
C15: Tax | D15: -25 | E15: -35 | F15: -47 | G15: -74 | H15: -14 | I15: -31 | J15: -58 | K15: -90 | L15: -13 | M15: -45 | N15: -63 | O15: -101 | P15: -25 | Q15: -51 | V15: -136 | W15: -125 | X15: -173 | Y15: -179 | Z15: -181 | AA15: -193 | AB15: -222 | AC15: =AC14*-0.22 -> -253.2112 | AD15: =AD14*-0.22 -> -286.83922 | AE15: =AE14*-0.22 -> -304.55979 | AF15: =AF14*-0.22 -> -323.26774 | AG15: =AG14*-0.22 -> -343.01549 | AH15: =AH14*-0.22 -> -363.85816 | AI15: =AI14*-0.22 -> -385.85372 | AJ15: =AJ14*-0.22 -> -409.06314 | ... AL15: =AL14*-0.22 -> -459.38331
C16: Net income | D16: =SUM(D14:D15) -> 94 | E16: =SUM(E14:E15) -> 109 | F16: =SUM(F14:F15) -> 170 | G16: =SUM(G14:G15) -> 204 | H16: =SUM(H14:H15) -> 62 | I16: =SUM(I14:I15) -> 107 | J16: =SUM(J14:J15) -> 214 | K16: =SUM(K14:K15) -> 249 | ... S16: =SUM(S14:S15) -> 0 | V16: =SUM(V14:V15) -> 429 | W16: =SUM(W14:W15) -> 430 | X16: =SUM(X14:X15) -> 600 | Y16: =SUM(Y14:Y15) -> 606 | Z16: =SUM(Z14:Z15) -> 578 | AA16: =SUM(AA14:AA15) -> 632 | AB16: =SUM(AB14:AB15) -> 823 | AC16: =SUM(AC14:AC15) -> 897.7488 | ... AL16: =SUM(AL14:AL15) -> 1628.7227 | AM16: =AL16*(1+$AO$20) -> 1612.4354 | AN16: =AM16*(1+$AO$20) -> 1596.3111 | AO16: =AN16*(1+$AO$20) -> 1580.348 | AP16: =AO16*(1+$AO$20) -> 1564.5445 | AQ16: =AP16*(1+$AO$20) -> 1548.899 | AR16: =AQ16*(1+$AO$20) -> 1533.41 | AS16: =AR16*(1+$AO$20) -> 1518.0759 | AT16: =AS16*(1+$AO$20) -> 1502.8952 | ... FP16: =FO16*(1+$AO$20) -> 423.60708
C17: Share | D17: 105.5 | E17: 105.5 | F17: 105.5 | G17: 105.5 | H17: 105.5 | I17: 105.5 | J17: 105.5 | K17: 105.5 | L17: 105.5 | M17: 105.5 | N17: 105.5 | O17: 105.5 | P17: 105.5 | Q17: 105.5 | R17: 105.5 | S17: 105.5 | V17: 105.5 | W17: 105.5 | X17: 105.5 | Y17: 105.5 | Z17: 105.58736 | AA17: 101.49169 | AB17: 105.5 | AC17: 105.5 | AD17: 105.5 | AE17: 105.5 | AF17: 105.5 | AG17: 105.5 | AH17: 105.5 | AI17: 105.5 | AJ17: 105.5 | AK17: 105.5 | AL17: 105.5
C18: EPS | D18: =D16/D17 -> 0.89099526 | E18: =E16/E17 -> 1.0331754 | F18: =F16/F17 -> 1.6113744 | G18: =G16/G17 -> 1.9336493 | H18: =H16/H17 -> 0.58767773 | I18: =I16/I17 -> 1.014218 | J18: =J16/J17 -> 2.028436 | K18: =K16/K17 -> 2.3601896 | ... S18: =S16/S17 -> 0 | V18: =V16/V17 -> 4.0663507 | W18: =W16/W17 -> 4.0758294 | X18: =X16/X17 -> 5.6872038 | Y18: =Y16/Y17 -> 5.7440758 | Z18: =Z16/Z17 -> 5.47414 | AA18: =AA16/AA17 -> 6.2271106 | AB18: =AB16/AB17 -> 7.8009479 | AC18: =AC16/AC17 -> 8.5094673 | ... AL18: =AL16/AL17 -> 15.438129
AN19: Discount | AO19: 0.08
C20: Revenue y/y | H20: =(H4-D4)/D4 -> 0.10502577 | I20: =(I4-E4)/E4 -> 0.097005692 | J20: =(J4-F4)/F4 -> 0.099642431 | K20: =(K4-G4)/G4 -> 0.15646583 | L20: =(L4-H4)/H4 -> 0.12011662 | M20: =(M4-I4)/I4 -> 0.13354388 | N20: =(N4-J4)/J4 -> 0.091914156 | O20: =(O4-K4)/K4 -> 0.053953871 | ... S20: =(S4-O4)/O4 -> -1 | W20: =(W4-V4)/V4 -> 0.047460521 | X20: =(X4-W4)/W4 -> 0.087115964 | Y20: =(Y4-X4)/X4 -> 0.074887556 | Z20: =(Z4-Y4)/Y4 -> 0.083687844 | AA20: =(AA4-Z4)/Z4 -> 0.11538709 | AB20: =(AB4-AA4)/AA4 -> 0.097507501 | AC20: =(AC4-AB4)/AB4 -> 0.05 | AD20: =(AD4-AC4)/AC4 -> 0.05 | ... AL20: =(AL4-AK4)/AK4 -> 0.05 | AN20: TV | AO20: -0.01
C21: Organic growth | L21: 0.06 | M21: 0.066 | N21: 0.05 | O21: 0.056 | P21: 0.062 | Q21: 0.045 | AN21: NPV | AO21: =NPV(AO19,AB16:FP16) -> 15990.77
C22: Opex y/y | H22: =(H11-D11)/D11 -> 0.11657941 | I22: =(I11-E11)/E11 -> 0.093245033 | J22: =(J11-F11)/F11 -> 0.093375065 | K22: =(K11-G11)/G11 -> 0.13939394 | L22: =(L11-H11)/H11 -> 0.11597374 | M22: =(M11-I11)/I11 -> 0.11994185 | N22: =(N11-J11)/J11 -> 0.082061069 | O22: =(O11-K11)/K11 -> 0.049722479 | ... S22: =(S11-O11)/O11 -> -1 | W22: =(W11-V11)/V11 -> 0.019673315 | X22: =(X11-W11)/W11 -> 0.076643951 | Y22: =(Y11-X11)/X11 -> 0.078010686 | Z22: =(Z11-Y11)/Y11 -> 0.088150069 | AA22: =(AA11-Z11)/Z11 -> 0.11016118 | AB22: =(AB11-AA11)/AA11 -> 0.089950764 | AC22: =(AC11-AB11)/AB11 -> 0.046889442 | AD22: =(AD11-AC11)/AC11 -> 0.045552456 | ... AL22: =(AL11-AK11)/AK11 -> 0.05 | AN22: S/O | AO22: 105.5
C23: Gross margin | D23: =D6/D4 -> 0.89884021 | E23: =E6/E4 -> 0.90299431 | F23: =F6/F4 -> 0.9125149 | G23: =G6/G4 -> 0.913789 | H23: =H6/H4 -> 0.9058309 | I23: =I6/I4 -> 0.90277464 | J23: =J6/J4 -> 0.91675699 | K23: =K6/K4 -> 0.92071664 | ... S23: =S6/S4 -> #DIV/0! | V23: =V6/V4 -> 0.91489543 | W23: =W6/W4 -> 0.9190775 | X23: =X6/X4 -> 0.91604198 | Y23: =Y6/Y4 -> 0.91115141 | Z23: =Z6/Z4 -> 0.90765172 | AA23: =AA6/AA4 -> 0.91212786 | AB23: =AB6/AB4 -> 0.91294291 | AC23: =AC6/AC4 -> 0.9 | ... AL23: =AL6/AL4 -> 0.9 | AN23: NPV/Share | AO23: =AO21/AO22 -> 151.57128
C24: EBIT margin | D24: =D12/D4 -> 0.076997423 | E24: =E12/E4 -> 0.065825291 | F24: =F12/F4 -> 0.086054827 | G24: =G12/G4 -> 0.096213384 | H24: =H12/H4 -> 0.067346939 | I24: =I12/I4 -> 0.069027746 | J24: =J12/J4 -> 0.09126382 | K24: =K12/K4 -> 0.10955519 | ... S24: =S12/S4 -> #DIV/0! | V24: =V12/V4 -> 0.054118651 | W24: =W12/W4 -> 0.079211148 | X24: =X12/X4 -> 0.08808096 | Y24: =Y12/Y4 -> 0.085431341 | Z24: =Z12/Z4 -> 0.081665487 | AA24: =AA12/AA4 -> 0.085968151 | AB24: =AB12/AB4 -> 0.092261592 | AC24: =AC12/AC4 -> 0.094950709 | ... AL24: =AL12/AL4 -> 0.098784277 | AN24: Opp/nedside | AO24: =(AO23-B4)/B4 -> 0.68412531
C25: ROE | V25: 0.097 | W25: 0.115 | X25: 0.133 | Y25: 0.12 | Z25: 0.107 | AA25: 0.111 | AB25: =AB16/O39 -> 0.12417019
C27: Number of children and students | K27: 109510 | L27: 109281 | M27: 110744 | O27: 113530 | P27: 113082 | Q27: 113176
C28: y/y | H28: =(H27-D27)/D27 -> #DIV/0! | I28: =(I27-E27)/E27 -> #DIV/0! | J28: =(J27-F27)/F27 -> #DIV/0! | K28: =(K27-G27)/G27 -> #DIV/0! | L28: =(L27-H27)/H27 -> #DIV/0! | M28: =(M27-I27)/I27 -> #DIV/0! | N28: =(N27-J27)/J27 -> #DIV/0! | O28: =(O27-K27)/K27 -> 0.036708976 | ... S28: =(S27-O27)/O27 -> -1
C30: Balanse SEKm
C31: Intangible non-current assets | D31: 6687 | E31: 6758 | F31: 6670 | G31: 6695 | H31: 6984 | I31: 7056 | J31: 7632 | K31: 7627 | L31: 7655 | M31: 7673 | N31: 7595 | O31: 7767 | P31: 7761 | Q31: 7717
C32: Buildings | D32: 1066 | E32: 1138 | F32: 1148 | G32: 1170 | H32: 1165 | I32: 1082 | J32: 1092 | K32: 1108 | L32: 1082 | M32: 1102 | N32: 1087 | O32: 1173 | P32: 1155 | Q32: 1184
C33: Right-of-use assets | D33: 8946 | E33: 8987 | F33: 9368 | G33: 9119 | H33: 9696 | I33: 9477 | J33: 10806 | K33: 10474 | L33: 10978 | M33: 10736 | N33: 10133 | O33: 9981 | P33: 10923 | Q33: 10850
C34: Other PP&E | D34: 1011 | E34: 1049 | F34: 1034 | G34: 1035 | H34: 1078 | I34: 1070 | J34: 1071 | K34: 1071 | L34: 1090 | M34: 1095 | N34: 1059 | O34: 1086 | P34: 1108 | Q34: 1090
C35: Other non-current assets | D35: 102 | E35: 102 | F35: 96 | G35: 92 | H35: 119 | I35: 119 | J35: 169 | K35: 170 | L35: 187 | M35: 194 | N35: 178 | O35: 177 | P35: 193 | Q35: 193
C36: Current receivables | D36: 989 | E36: 740 | F36: 901 | G36: 840 | H36: 1173 | I36: 895 | J36: 1132 | K36: 964 | L36: 1305 | M36: 1018 | N36: 1122 | O36: 1055 | P36: 1438 | Q36: 1064
C37: Cash | D37: 907 | E37: 818 | F37: 872 | G37: 967 | H37: 969 | I37: 1108 | J37: 1243 | K37: 1316 | L37: 1047 | M37: 1200 | N37: 1001 | O37: 777 | P37: 793 | Q37: 661
C38: Total assets | D38: =SUM(D31:D37) -> 19708 | E38: =SUM(E31:E37) -> 19592 | F38: =SUM(F31:F37) -> 20089 | G38: =SUM(G31:G37) -> 19918 | H38: =SUM(H31:H37) -> 21184 | I38: =SUM(I31:I37) -> 20807 | J38: =SUM(J31:J37) -> 23145 | K38: =SUM(K31:K37) -> 22730 | ... S38: =SUM(S31:S37) -> 0
C39: Total Equity | D39: 5835 | E39: 5772 | F39: 5905 | G39: 6134 | H39: 6173 | I39: 6069 | J39: 6031 | K39: 6265 | L39: 6324 | M39: 6336 | N39: 6292 | O39: 6628 | P39: 6700 | Q39: 6642
C40: Non-current liabilities to banks | D40: 1559 | E40: 1532 | F40: 1462 | G40: 1424 | H40: 1421 | I40: 1715 | J40: 1716 | K40: 1660 | L40: 1626 | M40: 1632 | N40: 1538 | O40: 1183 | P40: 1164 | Q40: 1126
C41: Long-term lease liabilities | D41: 8004 | E41: 8069 | F41: 8410 | G41: 8203 | H41: 8671 | I41: 8478 | J41: 9712 | K41: 9408 | L41: 9873 | M41: 9697 | N41: 9146 | O41: 9012 | P41: 10014 | Q41: 9964
C42: Provisions and other non-current lia | D42: 244 | E42: 229 | F42: 197 | G42: 180 | H42: 196 | I42: 179 | J42: 271 | K42: 409 | L42: 406 | M42: 371 | N42: 275 | O42: 319 | P42: 336 | Q42: 331
C43: Current IB liabilities | D43: 345 | E43: 348 | F43: 346 | G43: 167 | H43: 529 | I43: 147 | J43: 746 | K43: 446 | L43: 537 | M43: 351 | N43: 439 | O43: 315 | P43: 530 | Q43: 43
C44: Short-term lease liabilities | D44: 1378 | E44: 1251 | F44: 1306 | G44: 1309 | H44: 1462 | I44: 1526 | J44: 1664 | K44: 1574 | L44: 1639 | M44: 1625 | N44: 1592 | O44: 1593 | P44: 1566 | Q44: 1615
...

Sheet Segementer
B3: SEK million | C3: Q1 22/23 | D3: Q2 22/23 | E3: Q3 22/23 | F3: Q4 22/23 | G3: FY 22/23 | H3: Q1 23/24 | I3: Q2 23/24 | J3: Q3 23/24 | K3: Q4 23/24 | L3: FY 23/24 | M3: Q1 24/25 | N3: Q2 24/25 | O3: Q3 24/25 | P3: Q4 24/25 | Q3: FY 24/25 | R3: Q1 25/26 | S3: Q2 25/26 | T3: Q3 25/26 | U3: Q4 25/26 | V3: FY 25/26
B4: Preschool and international
B5: Revenue | C5: 956 | D5: 1252 | E5: 1386 | F5: 1388 | G5: =SUM(C5:F5) -> 4982 | H5: 1165 | I5: 1427 | J5: 1605 | K5: 1876 | L5: =SUM(H5:K5) -> 6073 | M5: 1452 | N5: 1825 | O5: 1871 | P5: 1962 | Q5: =SUM(M5:P5) -> 7110 | R5: 1583 | S5: 1933 | V5: =SUM(R5:U5) -> 3516
B6: Growth % | H6: =(H5-C5)/C5 -> 0.21861925 | I6: =(I5-D5)/D5 -> 0.13977636 | J6: =(J5-E5)/E5 -> 0.15800866 | K6: =(K5-F5)/F5 -> 0.35158501 | L6: =(L5-G5)/G5 -> 0.21898836 | M6: =(M5-H5)/H5 -> 0.24635193 | N6: =(N5-I5)/I5 -> 0.2789068 | O6: =(O5-J5)/J5 -> 0.16573209 | ... V6: =(V5-Q5)/Q5 -> -0.50548523
B7: EBITA | C7: -3 | D7: 15 | E7: 75 | F7: 95 | G7: =SUM(C7:F7) -> 182 | H7: -6 | I7: 31 | J7: 97 | K7: 150 | L7: =SUM(H7:K7) -> 272 | M7: -11 | N7: 68 | O7: 115 | P7: 156 | Q7: =SUM(M7:P7) -> 328 | R7: 0 | S7: 115 | V7: =SUM(R7:U7) -> 115
B8: EBITA margin % | C8: -0.003 | D8: 0.012 | E8: 0.054 | F8: 0.068 | G8: =G7/G5 -> 0.036531513 | H8: -0.005 | I8: 0.022 | J8: 0.06 | K8: 0.08 | L8: =L7/L5 -> 0.044788408 | M8: 0.008 | N8: 0.037 | O8: 0.061 | P8: 0.08 | Q8: =Q7/Q5 -> 0.046132208 | R8: 0 | S8: 0.059 | V8: =V7/V5 -> 0.032707622
B9: Childen and students | C9: 22702 | D9: 24842 | E9: 26446 | F9: 26663 | G9: 26663 | H9: 25989 | I9: 26452 | J9: 29938 | K9: 35475 | L9: 35475 | M9: 33683 | N9: 24233 | O9: 35404 | P9: 37797 | Q9: 37797 | R9: 36371 | S9: 36852
B10: y/y | H10: =(H9-C9)/C9 -> 0.14478901 | I10: =(I9-D9)/D9 -> 0.064809597 | J10: =(J9-E9)/E9 -> 0.13204265 | K10: =(K9-F9)/F9 -> 0.33049544 | L10: =(L9-G9)/G9 -> 0.33049544 | M10: =(M9-H9)/H9 -> 0.29604833 | N10: =(N9-I9)/I9 -> -0.083887797 | O10: =(O9-J9)/J9 -> 0.18257733 | ... V10: =(V9-Q9)/Q9 -> -1
B11: Number of units | C11: 303 | D11: 312 | E11: 317 | F11: 317 | G11: 317 | H11: 328 | I11: 328 | J11: 444 | K11: 445 | L11: 445 | M11: 449 | N11: 453 | O11: 456 | P11: 484 | Q11: 484 | R11: 482 | S11: 482
B12: Compulsory school
B13: Revenue | C13: 746 | D13: 986 | E13: 1008 | F13: 1029 | G13: =SUM(C13:F13) -> 3769 | H13: 799 | I13: 1091 | J13: 1092 | K13: 1091 | L13: =SUM(H13:K13) -> 4073 | M13: 860 | N13: 1193 | O13: 1181 | P13: 1197 | Q13: =SUM(M13:P13) -> 4431 | R13: 904 | S13: 1228 | V13: =SUM(R13:U13) -> 2132
B14: Growth % | H14: =(H13-C13)/C13 -> 0.071045576 | I14: =(I13-D13)/D13 -> 0.10649087 | J14: =(J13-E13)/E13 -> 0.083333333 | K14: =(K13-F13)/F13 -> 0.060252672 | L14: =(L13-G13)/G13 -> 0.080657999 | M14: =(M13-H13)/H13 -> 0.076345432 | N14: =(N13-I13)/I13 -> 0.093492209 | O14: =(O13-J13)/J13 -> 0.081501832 | ... V14: =(V13-Q13)/Q13 -> -0.5188445
B15: EBITA | C15: 57 | D15: 53 | E15: 63 | F15: 88 | G15: =SUM(C15:F15) -> 261 | H15: 51 | I15: 65 | J15: 78 | K15: 99 | L15: =SUM(H15:K15) -> 293 | M15: 44 | N15: 80 | O15: 76 | P15: 114 | Q15: =SUM(M15:P15) -> 314 | R15: 49 | S15: 88 | V15: =SUM(R15:U15) -> 137
B16: EBITA margin % | C16: 0.076 | D16: 0.054 | E16: 0.063 | F16: 0.086 | G16: =G15/G13 -> 0.069249138 | H16: 0.064 | I16: 0.06 | J16: 0.071 | K16: 0.091 | L16: =L15/L13 -> 0.071937147 | M16: 0.051 | N16: 0.067 | O16: 0.064 | P16: 0.095 | Q16: =Q15/Q13 -> 0.070864365 | R16: 0.054 | S16: 0.072 | V16: =V15/V13 -> 0.064258912
B17: Childen and students | C17: 28416 | D17: 28520 | E17: 28715 | F17: 28911 | G17: 28911 | H17: 28825 | I17: 29257 | J17: 29344 | K17: 29377 | L17: 29377 | M17: 29486 | N17: 30648 | O17: 30796 | P17: 30795 | Q17: 30795 | R17: 30236 | S17: 30236
B18: y/y | H18: =(H17-C17)/C17 -> 0.0143933 | I18: =(I17-D17)/D17 -> 0.025841515 | J18: =(J17-E17)/E17 -> 0.021904928 | K18: =(K17-F17)/F17 -> 0.016118432 | L18: =(L17-G17)/G17 -> 0.016118432 | M18: =(M17-H17)/H17 -> 0.022931483 | N18: =(N17-I17)/I17 -> 0.047544177 | O18: =(O17-J17)/J17 -> 0.049482007 | ... U18: =(U17-P17)/P17 -> -1
B19: Number of units | C19: 116 | D19: 116 | E19: 117 | F19: 117 | G19: 117 | H19: 118 | I19: 118 | J19: 118 | K19: 118 | L19: 118 | M19: 126 | N19: 126 | O19: 126 | P19: 126 | Q19: 126 | R19: 122 | S19: 122
B20: Upper secondary school
B21: Revenue | C21: 1025 | D21: 1361 | E21: 1385 | F21: 1383 | G21: =SUM(C21:F21) -> 5154 | H21: 1102 | I21: 1441 | J21: 1473 | K21: 1465 | L21: =SUM(H21:K21) -> 5481 | M21: 1139 | N21: 1515 | O21: 1519 | P21: 1505 | Q21: =SUM(M21:P21) -> 5678 | R21: 1193 | S21: 1569 | V21: =SUM(R21:U21) -> 2762
B22: Growth % | H22: =(H21-C21)/C21 -> 0.075121951 | I22: =(I21-D21)/D21 -> 0.058780309 | J22: =(J21-E21)/E21 -> 0.063537906 | K22: =(K21-F21)/F21 -> 0.059291396 | L22: =(L21-G21)/G21 -> 0.063445867 | M22: =(M21-H21)/H21 -> 0.033575318 | N22: =(N21-I21)/I21 -> 0.051353227 | O22: =(O21-J21)/J21 -> 0.031228785 | ... V22: =(V21-Q21)/Q21 -> -0.51356111
B23: EBITA | C23: 74 | D23: 107 | E23: 116 | F23: 137 | G23: =SUM(C23:F23) -> 434 | H23: 63 | I23: 89 | J23: 121 | K23: 179 | L23: =SUM(H23:K23) -> 452 | M23: 68 | N23: 107 | O23: 138 | P23: 184 | Q23: =SUM(M23:P23) -> 497 | R23: 65 | S23: 101 | V23: =SUM(R23:U23) -> 166
B24: EBITA margin % | C24: 0.072 | D24: 0.079 | E24: 0.084 | F24: 0.099 | G24: =G23/G21 -> 0.084206442 | H24: 0.057 | I24: 0.062 | J24: 0.082 | K24: 0.122 | L24: =L23/L21 -> 0.082466703 | M24: 0.06 | N24: 0.071 | O24: 0.091 | P24: 0.122 | Q24: =Q23/Q21 -> 0.087530821 | R24: 0.054 | S24: 0.073 | V24: =V23/V21 -> 0.060101376
B25: Childen and students | C25: 44716 | D25: 44105 | E25: 43915 | F25: 43413 | G25: 43413 | H25: 45938 | I25: 45583 | J25: 45139 | K25: 44658 | L25: 44658 | M25: 46112 | N25: 45863 | O25: 45403 | P25: 44938 | Q25: 44938 | R25: 46476 | S25: 46088
B26: y/y | H26: =(H25-C25)/C25 -> 0.027328026 | I26: =(I25-D25)/D25 -> 0.03351094 | J26: =(J25-E25)/E25 -> 0.027872026 | K26: =(K25-F25)/F25 -> 0.028678046 | L26: =(L25-G25)/G25 -> 0.028678046 | M26: =(M25-H25)/H25 -> 0.0037877139 | N26: =(N25-I25)/I25 -> 0.0061426409 | O26: =(O25-J25)/J25 -> 0.005848601 | ... U26: =(U25-P25)/P25 -> -1
B27: Number of units | C27: 152 | D27: 152 | E27: 152 | F27: 152 | G27: 152 | H27: 149 | I27: 149 | J27: 149 | K27: 149 | L27: 149 | M27: 148 | N27: 148 | O27: 147 | P27: 147 | Q27: 147 | R27: 145 | S27: 145
B28: Adult education
B29: Revenue | C29: 377 | D29: 438 | E29: 415 | F29: 397 | G29: =SUM(C29:F29) -> 1627 | H29: 365 | I29: 473 | J29: 443 | K29: 423 | L29: =SUM(H29:K29) -> 1704 | M29: 391 | N29: 492 | O29: 465 | P29: 454 | Q29: =SUM(M29:P29) -> 1802 | R29: 421 | S29: 501 | V29: =SUM(R29:U29) -> 922
B30: Growth % | H30: =(H29-C29)/C29 -> -0.031830239 | I30: =(I29-D29)/D29 -> 0.079908676 | J30: =(J29-E29)/E29 -> 0.06746988 | K30: =(K29-F29)/F29 -> 0.065491184 | L30: =(L29-G29)/G29 -> 0.047326368 | M30: =(M29-H29)/H29 -> 0.071232877 | N30: =(N29-I29)/I29 -> 0.040169133 | O30: =(O29-J29)/J29 -> 0.0496614 | ... V30: =(V29-Q29)/Q29 -> -0.48834628
B31: EBITA | C31: 45 | D31: 28 | E31: 33 | F31: 20 | G31: =SUM(C31:F31) -> 126 | H31: 48 | I31: 46 | J31: 43 | K31: 23 | L31: =SUM(H31:K31) -> 160 | M31: 67 | N31: 60 | O31: 53 | P31: 34 | Q31: =SUM(M31:P31) -> 214 | R31: 79 | S31: 67 | V31: =SUM(R31:U31) -> 146
B32: EBITA margin % | C32: 0.119 | D32: 0.064 | E32: 0.08 | F32: 0.05 | G32: =G31/G29 -> 0.077443147 | H32: 0.132 | I32: 0.097 | J32: 0.097 | K32: 0.054 | L32: =L31/L29 -> 0.093896714 | M32: 0.171 | N32: 0.122 | O32: 0.114 | P32: 0.075 | Q32: =Q31/Q29 -> 0.11875694 | R32: 0.188 | S32: 0.134 | V32: =V31/V29 -> 0.15835141

Sheet SOTP
C6: SEKm | D6: EBITA 25/26E | F6: EV/EBITA | G6: Value | H6: SEK/Share
C7: Preschool and international | D7: 402 | F7: 10 | G7: =D7*F7 -> 4020 | H7: =G7/Modell!$B$5 -> 38.104265
C8: Compulsory school | D8: 348 | F8: 8 | G8: =D8*F8 -> 2784 | H8: =G8/Modell!$B$5 -> 26.388626
C9: Upper secondary school | D9: 550 | F9: 7 | G9: =D9*F9 -> 3850 | H9: =G9/Modell!$B$5 -> 36.492891
C10: Adult education | D10: 240 | F10: 10 | G10: =D10*F10 -> 2400 | H10: =G10/Modell!$B$5 -> 22.748815
C11: Enterprise value | G11: =SUM(G7:G10) -> 13054 | H11: =SUM(H7:H10) -> 123.7346
C13: Cash | G13: =Modell!B7 -> 661 | H13: =G13/Modell!$B$5 -> 6.2654028
C14: Debt (Ex lease) | G14: =Modell!Q40+Modell!Q43 -> 1169 | H14: =-G14/Modell!$B$5 -> -11.080569
C16: Equity value | H16: =SUM(H11:H14) -> 118.91943

Sheet Nøkkeltall
D4: 25/26 | E4: 26/27 | F4: 27/28
C5: EV/EBIT | D5: =Modell!$B$9/Modell!AC12 -> 11.38015 | E5: =Modell!$B$9/Modell!AD12 -> 10.417634 | F5: =Modell!$B$9/Modell!AE12 -> 9.921556
C6: P/E | D6: =Modell!$B$4/Modell!AC18 -> 10.576455 | E6: =Modell!$B$4/Modell!AD18 -> 9.3365088 | F6: =Modell!$B$4/Modell!AE18 -> 8.7932715

Sheet Nedsideberegning
A3: Nedside | D3: FY 18/19 | E3: FY 19/20 | F3: FY 20/21 | G3: FY 21/22 | H3: FY 22/23 | I3: FY 23/24 | J3: FY 24/25 | K3: FY 25/26 | L3: FY 26/27 | M3: FY 27/28 | N3: FY 28/29 | O3: FY 29/30 | P3: FY 30/31 | Q3: FY 31/32 | R3: FY 32/33 | S3: FY 33/34 | T3: FY 34/35
A4: Nullvekst og konstante marginer | C4: Revenue | D4: 11715 | E4: 12271 | F4: 13340 | G4: 14339 | H4: 15539 | I4: 17332 | J4: 19022 | K4: =J4*1 -> 19022 | L4: =K4*1 -> 19022 | M4: =L4*1 -> 19022 | N4: =M4*1 -> 19022 | O4: =N4*1 -> 19022 | P4: =O4*1 -> 19022 | Q4: =P4*1 -> 19022 | R4: =Q4*1 -> 19022 | ... T4: =S4*1 -> 19022
A5: =W23 -> 64.497928 | C5: Cost of service | D5: -997 | E5: -993 | F5: -1120 | G5: -1274 | H5: -1435 | I5: -1523 | J5: -1656 | K5: =K4*-0.1 -> -1902.2 | L5: =L4*-0.1 -> -1902.2 | M5: =M4*-0.1 -> -1902.2 | N5: =N4*-0.1 -> -1902.2 | O5: =O4*-0.1 -> -1902.2 | P5: =P4*-0.1 -> -1902.2 | Q5: =Q4*-0.1 -> -1902.2 | R5: =R4*-0.1 -> -1902.2 | ... T5: =T4*-0.1 -> -1902.2
A6: =W24 -> -0.28335635 | C6: Gross profit | D6: =SUM(D4:D5) -> 10718 | E6: =SUM(E4:E5) -> 11278 | F6: =SUM(F4:F5) -> 12220 | G6: =SUM(G4:G5) -> 13065 | H6: =SUM(H4:H5) -> 14104 | I6: =SUM(I4:I5) -> 15809 | J6: =SUM(J4:J5) -> 17366 | K6: =SUM(K4:K5) -> 17119.8 | ... T6: =SUM(T4:T5) -> 17119.8
C7: Other external expenses | D7: -2517 | E7: -1237 | F7: -1352 | G7: -1370 | H7: -1566 | I7: -1731 | J7: -1789 | K7: =J7*1.01 -> -1806.89 | L7: =K7*1 -> -1806.89 | M7: =L7*1 -> -1806.89 | N7: =M7*1 -> -1806.89 | O7: =N7*1 -> -1806.89 | P7: =O7*1 -> -1806.89 | Q7: =P7*1 -> -1806.89 | R7: =Q7*1 -> -1806.89 | S7: =R7*1 -> -1806.89 | T7: =S7*1 -> -1806.89
C8: Personnel expenses | D8: -7272 | E8: -7591 | F8: -8106 | G8: -8648 | H8: -9296 | I8: -10408 | J8: -11442 | K8: =J8*0.99 -> -11327.58 | L8: =K8*1 -> -11327.58 | M8: =L8*1 -> -11327.58 | N8: =M8*1 -> -11327.58 | O8: =N8*1 -> -11327.58 | P8: =O8*1 -> -11327.58 | Q8: =P8*1 -> -11327.58 | R8: =Q8*1 -> -11327.58 | S8: =R8*1 -> -11327.58 | T8: =S8*1 -> -11327.58
C9: D/A | D9: -296 | E9: -1514 | F9: -1580 | G9: -1755 | H9: -1924 | I9: -2159 | J9: -2353 | K9: =J9*1 -> -2353 | L9: =K9*1 -> -2353 | M9: =L9*1 -> -2353 | N9: =M9*1 -> -2353 | O9: =N9*1 -> -2353 | P9: =O9*1 -> -2353 | Q9: =P9*1 -> -2353 | R9: =Q9*1 -> -2353 | ... T9: =S9*1 -> -2353
C10: Items affecting comparability | D10: 1 | E10: 36 | F10: -7 | G10: -67 | H10: -49 | I10: -21 | J10: -27 | K10: =J10*1 -> -27 | L10: =K10*1 -> -27 | M10: =L10*1 -> -27 | N10: =M10*1 -> -27 | O10: =N10*1 -> -27 | P10: =O10*1 -> -27 | Q10: =P10*1 -> -27 | R10: =Q10*1 -> -27 | ... T10: =S10*1 -> -27
C11: Total opex | D11: =D5+D7+D8+D9+D10 -> -11081 | E11: =E5+E7+E8+E9+E10 -> -11299 | F11: =F5+F7+F8+F9+F10 -> -12165 | G11: =G5+G7+G8+G9+G10 -> -13114 | H11: =H5+H7+H8+H9+H10 -> -14270 | I11: =I5+I7+I8+I9+I10 -> -15842 | J11: =J5+J7+J8+J9+J10 -> -17267 | K11: =K5+K7+K8+K9+K10 -> -17416.67 | ... T11: =T5+T7+T8+T9+T10 -> -17416.67
C12: Operating income (EBIT) | D12: =D4+D11 -> 634 | E12: =E4+E11 -> 972 | F12: =F4+F11 -> 1175 | G12: =G4+G11 -> 1225 | H12: =H4+H11 -> 1269 | I12: =I4+I11 -> 1490 | J12: =J4+J11 -> 1755 | K12: =K4+K11 -> 1605.33 | ... T12: =T4+T11 -> 1605.33
C13: Net financial items | D13: -69 | E13: -417 | F13: -402 | G13: =1-441 -> -440 | H13: =33-543 -> -510 | I13: =22-687 -> -665 | J13: -710 | K13: =J13*1.05 -> -745.5 | L13: =K13*1.03 -> -767.865 | M13: =L13*1.03 -> -790.90095 | N13: =M13*1.03 -> -814.62798 | O13: =N13*1.03 -> -839.06682 | P13: =O13*1.03 -> -864.23882 | Q13: =P13*1.03 -> -890.16599 | R13: =Q13*1.03 -> -916.87097 | S13: =R13*1.03 -> -944.3771 | T13: =S13*1.03 -> -972.70841
C14: PTP | D14: =SUM(D12:D13) -> 565 | E14: =SUM(E12:E13) -> 555 | F14: =SUM(F12:F13) -> 773 | G14: =SUM(G12:G13) -> 785 | H14: =SUM(H12:H13) -> 759 | I14: =SUM(I12:I13) -> 825 | J14: =SUM(J12:J13) -> 1045 | K14: =SUM(K12:K13) -> 859.83 | ... T14: =SUM(T12:T13) -> 632.62159
C15: Tax | D15: -136 | E15: -125 | F15: -173 | G15: -179 | H15: -181 | I15: -193 | J15: -222 | K15: =K14*-0.22 -> -189.1626 | L15: =L14*-0.22 -> -184.2423 | M15: =M14*-0.22 -> -179.17439 | N15: =N14*-0.22 -> -173.95444 | O15: =O14*-0.22 -> -168.5779 | P15: =P14*-0.22 -> -163.04006 | Q15: =Q14*-0.22 -> -157.33608 | R15: =R14*-0.22 -> -151.46099 | ... T15: =T14*-0.22 -> -139.17675
C16: Net income | D16: =SUM(D14:D15) -> 429 | E16: =SUM(E14:E15) -> 430 | F16: =SUM(F14:F15) -> 600 | G16: =SUM(G14:G15) -> 606 | H16: =SUM(H14:H15) -> 578 | I16: =SUM(I14:I15) -> 632 | J16: =SUM(J14:J15) -> 823 | K16: =SUM(K14:K15) -> 670.6674 | ... T16: =SUM(T14:T15) -> 493.44484 | U16: =T16*(1+$W$20) -> 488.51039 | V16: =U16*(1+$W$20) -> 483.62529 | W16: =V16*(1+$W$20) -> 478.78904 | X16: =W16*(1+$W$20) -> 474.00115 | Y16: =X16*(1+$W$20) -> 469.26113 | Z16: =Y16*(1+$W$20) -> 464.56852 | AA16: =Z16*(1+$W$20) -> 459.92284 | AB16: =AA16*(1+$W$20) -> 455.32361 | ... EX16: =EW16*(1+$W$20) -> 128.33783
C17: Share | D17: 105.5 | E17: 105.5 | F17: 105.5 | G17: 105.5 | H17: 105.58736 | I17: 101.49169 | J17: 105.5 | K17: 105.5 | L17: 105.5 | M17: 105.5 | N17: 105.5 | O17: 105.5 | P17: 105.5 | Q17: 105.5 | R17: 105.5 | S17: 105.5 | T17: 105.5
C18: EPS | D18: =D16/D17 -> 4.0663507 | E18: =E16/E17 -> 4.0758294 | F18: =F16/F17 -> 5.6872038 | G18: =G16/G17 -> 5.7440758 | H18: =H16/H17 -> 5.47414 | I18: =I16/I17 -> 6.2271106 | J18: =J16/J17 -> 7.8009479 | K18: =K16/K17 -> 6.357037 | ... T18: =T16/T17 -> 4.6772023
V19: Discount | W19: 0.08
C20: Revenue y/y | E20: =(E4-D4)/D4 -> 0.047460521 | F20: =(F4-E4)/E4 -> 0.087115964 | G20: =(G4-F4)/F4 -> 0.074887556 | H20: =(H4-G4)/G4 -> 0.083687844 | I20: =(I4-H4)/H4 -> 0.11538709 | J20: =(J4-I4)/I4 -> 0.097507501 | K20: =(K4-J4)/J4 -> 0 | L20: =(L4-K4)/K4 -> 0 | ... T20: =(T4-S4)/S4 -> 0 | V20: TV | W20: -0.01
C21: Opex y/y | E21: =(E11-D11)/D11 -> 0.019673315 | F21: =(F11-E11)/E11 -> 0.076643951 | G21: =(G11-F11)/F11 -> 0.078010686 | H21: =(H11-G11)/G11 -> 0.088150069 | I21: =(I11-H11)/H11 -> 0.11016118 | J21: =(J11-I11)/I11 -> 0.089950764 | K21: =(K11-J11)/J11 -> 0.0086679794 | L21: =(L11-K11)/K11 -> 0 | ... T21: =(T11-S11)/S11 -> 0 | V21: NPV | W21: =NPV(W19,J16:EX16) -> 6804.5314
C22: Gross margin | D22: =D6/D4 -> 0.91489543 | E22: =E6/E4 -> 0.9190775 | F22: =F6/F4 -> 0.91604198 | G22: =G6/G4 -> 0.91115141 | H22: =H6/H4 -> 0.90765172 | I22: =I6/I4 -> 0.91212786 | J22: =J6/J4 -> 0.91294291 | K22: =K6/K4 -> 0.9 | ... T22: =T6/T4 -> 0.9 | V22: S/O | W22: 105.5
C23: EBIT margin | D23: =D12/D4 -> 0.054118651 | E23: =E12/E4 -> 0.079211148 | F23: =F12/F4 -> 0.08808096 | G23: =G12/G4 -> 0.085431341 | H23: =H12/H4 -> 0.081665487 | I23: =I12/I4 -> 0.085968151 | J23: =J12/J4 -> 0.092261592 | K23: =K12/K4 -> 0.084393334 | ... T23: =T12/T4 -> 0.084393334 | V23: NPV/Share | W23: =W21/W22 -> 64.497928
V24: Opp/nedside | W24: =(W23-Modell!B4)/Modell!B4 -> -0.28335635
