Workbook

Sheet Info
A3: Bonheur er fordelt inn i 4 ulike segmenter
A5: Renewable energy: Inneholder Fred Olsen Renewables og Fred Olsen Seawind (Onshore)
A6: Fred Olsen Renewables AS (FOR) eier 12 windfarms og har en portefølje for utvikling av prosjekter onshore i UK, Norge, Sverige og Italia.
A7: Fred Olsen Seawind (FOS) utvikler offshore vind porsjekt i ulike land og har en JV i Irland med EDF, i Skotland med Vattenfall og i Norge med Hafslund
A9: Wind service: Inneholder Fred Olsen Ocean subsidiaries (FOO) (Offshore)
A10: FOO eier 100% av Fred Olsen Windcarrier (FOWIC)
A11: FOO eier 92% av Global Wind Service (GWS)
A12: FOWIC tilby både Transport & Installation (T&I) og Operation & maintenance services (O&M). De eier 100% i Brave Tern og Bold Tern og 51% av Blue Tern og 100% av Blue wind
A14: Cruise: Inneholder First Olsen Holding AS med subsidiaries
A15: Fred Olsen Cruise lines (FOCL) eier 3 cruiseskip som operer i UK Skipene heter Balmoral, Bolette og Borealis
A17: Other investments: Inneholder 55,13% eierskap i NHST media Group, Fred Olsen 1848, Fred Olsen investments, Fred Olsen Travel
A18: NHTS eier DN
... A23: 19.12.25: MEAG investerer 150 mill euro inn i Fred Olsen Wind carrier. Transaksjonen innebærer både salg av eksisterende akjser og tilførsel av ny EK og verdsetter FOWIC til 600 mill EURO. Etter transaksjonen er fullføfrt Q327 vil MEAG eie 24%

Sheet Modell
A3: Kapitalstruktur | C3: NOK million | D3: Q122 | E3: Q222 | F3: Q322 | G3: Q422 | H3: Q123 | I3: Q223 | J3: Q323 | K3: Q423 | L3: Q124 | M3: Q224 | N3: Q324 | O3: Q424 | P3: Q125 | Q3: Q225 | R3: Q325 | S3: Q425 | Y3: FY 2022 | Z3: FY 2023 | AA3: FY 2024 | AB3: FY 2025 | AC3: FY 2026 | AD3: FY 2027 | AE3: FY 2028 | AF3: FY 2029 | AG3: FY 2030 | AH3: FY 2031 | AI3: FY 2032 | AJ3: FY 2033 | AK3: FY 2034 | AL3: FY 2035
A4: Price | B4: 250 | C4: Revenues | D4: 2476.2 | E4: 2385.9 | F4: 3211.9 | G4: 3361.1 | H4: 2999 | I4: 2833.5 | J4: 3196.5 | K4: 3530.6 | L4: 2973 | M4: 4282.7 | N4: 3606.3 | O4: 3133.5 | P4: 2896 | Q4: 3251 | R4: 3406 | Y4: =SUM(D4:G4) -> 11435.1 | Z4: =SUM(H4:K4) -> 12559.6 | AA4: =SUM(L4:O4) -> 13995.5
A5: S/O | B5: 42.531893 | C5: Operating costs | D5: -1550 | E5: -1824.3 | F5: -2129.2 | G5: -2075.9 | H5: -2073.1 | I5: -2106.8 | J5: -2396.4 | K5: -2426.4 | L5: -2376.6 | M5: -3053.3 | N5: -2668.6 | O5: -2359.8 | P5: -2168 | Q5: -2198 | R5: -2289 | Y5: =SUM(D5:G5) -> -7579.4 | Z5: =SUM(H5:K5) -> -9002.7 | AA5: =SUM(L5:O5) -> -10458.3
A6: MC NOKm | B6: =B4*B5 -> 10632.973 | C6: EBITDA | D6: =SUM(D4:D5) -> 926.2 | E6: =SUM(E4:E5) -> 561.6 | F6: =SUM(F4:F5) -> 1082.7 | G6: =SUM(G4:G5) -> 1285.2 | H6: =SUM(H4:H5) -> 925.9 | I6: =SUM(I4:I5) -> 726.7 | J6: =SUM(J4:J5) -> 800.1 | K6: =SUM(K4:K5) -> 1104.2 | ... R6: =SUM(R4:R5) -> 1117 | Y6: =SUM(D6:G6) -> 3855.7 | Z6: =SUM(H6:K6) -> 3556.9 | AA6: =SUM(L6:O6) -> 3537.2
A7: Cash NOKm | B7: =R29 -> 7219 | C7: Depreciation | D7: -244.8 | E7: -227.9 | F7: -336.9 | G7: -260.9 | H7: -241.5 | I7: -267.8 | J7: -263.4 | K7: -297.4 | L7: -279.4 | M7: -291.8 | N7: -284.4 | O7: -281.2 | P7: -325 | Q7: -270 | R7: -299 | Y7: =SUM(D7:G7) -> -1070.5 | Z7: =SUM(H7:K7) -> -1070.1 | AA7: =SUM(L7:O7) -> -1136.8
A8: Debt NOKm | B8: =R37+R39 -> 9669 | C8: Impairment losses | D8: 0 | E8: 0 | F8: -455.4 | G8: -14.3 | H8: 0 | I8: -0.7 | J8: -39.5 | K8: -4.8 | L8: 0 | M8: 0 | N8: -50.3 | O8: -25.7 | P8: 0 | Q8: 0 | R8: 0 | Y8: =SUM(D8:G8) -> -469.7 | Z8: =SUM(H8:K8) -> -45 | AA8: =SUM(L8:O8) -> -76
A9: EV NOKm | B9: =B6-B7+B8 -> 13082.973 | C9: Operating profit (EBIT) | D9: =SUM(D6:D8) -> 681.4 | E9: =SUM(E6:E8) -> 333.7 | F9: =SUM(F6:F8) -> 290.4 | G9: =SUM(G6:G8) -> 1010 | H9: =SUM(H6:H8) -> 684.4 | I9: =SUM(I6:I8) -> 458.2 | J9: =SUM(J6:J8) -> 497.2 | K9: =SUM(K6:K8) -> 802 | ... R9: =SUM(R6:R8) -> 818 | Y9: =SUM(D9:G9) -> 2315.5 | Z9: =SUM(H9:K9) -> 2441.8 | AA9: =SUM(L9:O9) -> 2324.4
C10: Share from associated | D10: -0.7 | E10: -2.8 | F10: -2.6 | G10: -8.2 | H10: -2.5 | I10: -4.3 | J10: -2.3 | K10: -11.2 | L10: -5.4 | M10: -4 | N10: -4.8 | O10: -6.1 | P10: -7 | Q10: -6 | R10: -5 | Y10: =SUM(D10:G10) -> -14.3 | Z10: =SUM(H10:K10) -> -20.3 | AA10: =SUM(L10:O10) -> -20.3
C11: Net financial | D11: -14.2 | E11: -34 | F11: 387.1 | G11: -166.8 | H11: 95.2 | I11: 92.9 | J11: -211.3 | K11: -361.4 | L11: 113.7 | M11: -130.3 | N11: -160.7 | O11: -34.1 | P11: -199 | Q11: 189 | R11: -133 | Y11: =SUM(D11:G11) -> 172.1 | Z11: =SUM(H11:K11) -> -384.6 | AA11: =SUM(L11:O11) -> -211.4
C12: PTP | D12: =SUM(D9:D11) -> 666.5 | E12: =SUM(E9:E11) -> 296.9 | F12: =SUM(F9:F11) -> 674.9 | G12: =SUM(G9:G11) -> 835 | H12: =SUM(H9:H11) -> 777.1 | I12: =SUM(I9:I11) -> 546.8 | J12: =SUM(J9:J11) -> 283.6 | K12: =SUM(K9:K11) -> 429.4 | ... R12: =SUM(R9:R11) -> 680 | Y12: =SUM(D12:G12) -> 2473.3 | Z12: =SUM(H12:K12) -> 2036.9 | AA12: =SUM(L12:O12) -> 2092.7
A13: P/NAV | B13: =B4/SOTP!M45 -> 0.63357165 | C13: Tax | D13: -236.6 | E13: -135.9 | F13: -281.5 | G13: -103.5 | H13: -212.1 | I13: 7.6 | J13: -111.3 | K13: -142 | L13: -121.7 | M13: -109.2 | N13: -87.2 | O13: -127.3 | P13: -105 | Q13: -47 | R13: -119 | Y13: =SUM(D13:G13) -> -757.5 | Z13: =SUM(H13:K13) -> -457.8 | AA13: =SUM(L13:O13) -> -445.4
C14: Net income | D14: =SUM(D12:D13) -> 429.9 | E14: =SUM(E12:E13) -> 161 | F14: =SUM(F12:F13) -> 393.4 | G14: =SUM(G12:G13) -> 731.5 | H14: =SUM(H12:H13) -> 565 | I14: =SUM(I12:I13) -> 554.4 | J14: =SUM(J12:J13) -> 172.3 | K14: =SUM(K12:K13) -> 287.4 | ... R14: =SUM(R12:R13) -> 561 | Y14: =SUM(D14:G14) -> 1715.8 | Z14: =SUM(H14:K14) -> 1579.1 | AA14: =SUM(L14:O14) -> 1647.3
C15: EPS | D15: =D14/D16 -> 10.107709 | E15: =E14/E16 -> 3.7853946 | F15: =F14/F16 -> 9.2495295 | G15: =G14/G16 -> 17.198858 | H15: =H14/H16 -> 13.284149 | I15: =I14/I16 -> 13.034924 | J15: =J14/J16 -> 4.0510776 | K15: =K14/K16 -> 6.7572821 | ... S15: =S14/S16 -> 0 | Y15: =Y14/Y16 -> 40.341492 | Z15: =Z14/Z16 -> 37.127433 | AA15: =AA14/AA16 -> 38.730935
C16: Share | D16: 42.531893 | E16: 42.531893 | F16: 42.531893 | G16: 42.531893 | H16: 42.531893 | I16: 42.531893 | J16: 42.531893 | K16: 42.531893 | L16: 42.531893 | M16: 42.531893 | N16: 42.531893 | O16: 42.531893 | P16: 42.531893 | Q16: 42.531893 | R16: 42.531893 | S16: 42.531893 | Y16: 42.531893 | Z16: 42.531893 | AA16: 42.531893
C18: Revenue y/y | H18: =(H4-D4)/D4 -> 0.21112996 | I18: =(I4-E4)/E4 -> 0.18760216 | J18: =(J4-F4)/F4 -> -0.0047946698 | K18: =(K4-G4)/G4 -> 0.050429919 | L18: =(L4-H4)/H4 -> -0.0086695565 | M18: =(M4-I4)/I4 -> 0.51145227 | N18: =(N4-J4)/J4 -> 0.12820272 | O18: =(O4-K4)/K4 -> -0.1124738 | ... S18: =(S4-O4)/O4 -> -1 | Z18: =(Z4-Y4)/Y4 -> 0.098337575 | AA18: =(AA4-Z4)/Z4 -> 0.11432689 | AB18: =(AB4-AA4)/AA4 -> -1 | AC18: =(AC4-AB4)/AB4 -> #DIV/0! | AD18: =(AD4-AC4)/AC4 -> #DIV/0! | AE18: =(AE4-AD4)/AD4 -> #DIV/0! | AF18: =(AF4-AE4)/AE4 -> #DIV/0! | AG18: =(AG4-AF4)/AF4 -> #DIV/0! | ... AL18: =(AL4-AK4)/AK4 -> #DIV/0!
C19: EBITDA margin | D19: =D6/D4 -> 0.37404087 | E19: =E6/E4 -> 0.23538287 | F19: =F6/F4 -> 0.3370902 | G19: =G6/G4 -> 0.38237482 | H19: =H6/H4 -> 0.30873625 | I19: =I6/I4 -> 0.25646727 | J19: =J6/J4 -> 0.25030502 | K19: =K6/K4 -> 0.31275137 | ... S19: =S6/S4 -> #DIV/0! | Y19: =Y6/Y4 -> 0.33718114 | Z19: =Z6/Z4 -> 0.28320169 | AA19: =AA6/AA4 -> 0.25273838 | AB19: =AB6/AB4 -> #DIV/0! | AC19: =AC6/AC4 -> #DIV/0! | AD19: =AD6/AD4 -> #DIV/0! | AE19: =AE6/AE4 -> #DIV/0! | AF19: =AF6/AF4 -> #DIV/0! | ... AL19: =AL6/AL4 -> #DIV/0!
C21: Balanse NOKm
C22: Intangiable fixed assets | D22: 1064.9 | E22: 1113.6 | F22: 1115.8 | G22: 1128.2 | H22: 1193.9 | I22: 1250 | J22: 1186.2 | K22: 1222.9 | L22: 1260.8 | M22: 1254.8 | N22: 1248.2 | O22: 1253.6 | P22: 1190 | Q22: 1121 | R22: 1133
C23: Deferred tax assets | D23: 149.1 | E23: 128.9 | F23: 124.3 | G23: 126.7 | H23: 170.4 | I23: 208.2 | J23: 207.1 | K23: 187.8 | L23: 202.3 | M23: 185.5 | N23: 176.4 | O23: 226.6 | P23: 234 | Q23: 186 | R23: 168
C24: PP&E | D24: 10461.5 | E24: 11031.8 | F24: 10518.5 | G24: 10387.1 | H24: 11164.3 | I24: 11628.3 | J24: 11009.1 | K24: 10993.9 | L24: 11339 | M24: 11005.4 | N24: 11747.6 | O24: 12016 | P24: 11470 | Q24: 11947 | R24: 11559
C25: Investments in associates | D25: 44.1 | E25: 164.3 | F25: 163.2 | G25: 185.4 | H25: 236.8 | I25: 310 | J25: 275.6 | K25: 312.5 | L25: 321.2 | M25: 314.8 | N25: 358.9 | O25: 388.7 | P25: 402 | Q25: 418 | R25: 417
C26: Other financial fixed assets | D26: 796.4 | E26: 897.3 | F26: 1265.6 | G26: 1231.4 | H26: 1489.3 | I26: 1624.9 | J26: 1464.5 | K26: 1330.9 | L26: 1517 | M26: 1551.9 | N26: 1639.9 | O26: 1589.5 | P26: 1662 | Q26: 1713 | R26: 1774
C27: Inventories and consumable spareparts | D27: 191.1 | E27: 300.7 | F27: 303.1 | G27: 299.6 | H27: 364.5 | I27: 406.4 | J27: 407.9 | K27: 549 | L27: 556.5 | M27: 392.1 | N27: 350.9 | O27: 376 | P27: 317 | Q27: 333 | R27: 327
C28: trade and other receivables | D28: 2084.5 | E28: 2422.7 | F28: 2716.2 | G28: 2966.7 | H28: 2572.3 | I28: 2830.5 | J28: 2874.6 | K28: 3447.5 | L28: 2838.9 | M28: 2715.4 | N28: 2904.5 | O28: 2829.4 | P28: 3018 | Q28: 3145 | R28: 3403
C29: Cash | D29: 4508.5 | E29: 3776.3 | F29: 5252.3 | G29: 5458.5 | H29: =6263+39.3 -> 6302.3 | I29: =6221.6+39.3 -> 6260.9 | J29: 5997.8 | K29: 5460.2 | L29: 6545.2 | M29: 6802 | N29: 6169.6 | O29: 6582 | P29: =6826+504 -> 7330 | Q29: 6896 | R29: 7219
C30: Assets | D30: =SUM(D22:D29) -> 19300.1 | E30: =SUM(E22:E29) -> 19835.6 | F30: =SUM(F22:F29) -> 21459 | G30: =SUM(G22:G29) -> 21783.6 | H30: =SUM(H22:H29) -> 23493.8 | I30: =SUM(I22:I29) -> 24519.2 | J30: =SUM(J22:J29) -> 23422.8 | K30: =SUM(K22:K29) -> 23504.7 | ... S30: =SUM(S22:S29) -> 0
C31: Share capital | D31: 53.2 | E31: 53.2 | F31: 53.2 | G31: 53.2 | H31: 53.2 | I31: 53.2 | J31: 53.2 | K31: 53.2 | L31: 53.2 | M31: 53.2 | N31: 53.2 | O31: 53.2 | P31: 53 | Q31: 53 | R31: 53
C32: Share premium reserves | D32: 143.3 | E32: 143.3 | F32: 143.3 | G32: 143.3 | H32: 143.3 | I32: 143.3 | J32: 143.3 | K32: 143.3 | L32: 143.3 | M32: 143.3 | N32: 143.3 | O32: 143.3 | P32: 143 | Q32: 143 | R32: 143
C33: Retained earnings | D33: 4362.2 | E33: 4372.9 | F33: 5154.1 | G33: 5537.6 | H33: 6164.7 | I33: 6490 | J33: 6361 | K33: 6481 | L33: 6850.1 | M33: 7068.8 | N33: 7529.8 | O33: 7545.7 | P33: 7647 | Q33: 8256 | R33: 8847
C34: Equitynowned by the shareholders | D34: =SUM(D31:D33) -> 4558.7 | E34: =SUM(E31:E33) -> 4569.4 | F34: =SUM(F31:F33) -> 5350.6 | G34: =SUM(G31:G33) -> 5734.1 | H34: =SUM(H31:H33) -> 6361.2 | I34: =SUM(I31:I33) -> 6686.5 | J34: =SUM(J31:J33) -> 6557.5 | K34: =SUM(K31:K33) -> 6677.5 | ... P34: =SUM(P31:P33) -> 7843 | Q34: 8452 | R34: 9044
C35: Non-controlling interest | D35: 11.9 | E35: 92.7 | F35: 954.5 | G35: 1238 | H35: 1329.5 | I35: 1456.5 | J35: 1050.3 | K35: 1230.4 | L35: 1157.6 | M35: 1198.6 | N35: 1246.8 | O35: 1429.7 | P35: 1585 | Q35: 1422 | R35: 1776
C36: Total equity | D36: =SUM(D34:D35) -> 4570.6 | E36: =SUM(E34:E35) -> 4662.1 | F36: =SUM(F34:F35) -> 6305.1 | G36: =SUM(G34:G35) -> 6972.1 | H36: =SUM(H34:H35) -> 7690.7 | I36: =SUM(I34:I35) -> 8143 | J36: =SUM(J34:J35) -> 7607.8 | K36: =SUM(K34:K35) -> 7907.9 | ... S36: =SUM(S34:S35) -> 0
C37: Non-current IB debt | D37: 8168.7 | E37: 8621.9 | F37: 8567.7 | G37: 8699.9 | H37: 9321.3 | I37: 9421.2 | J37: 8202 | K37: 7717.4 | L37: 8274.9 | M37: 7662.2 | N37: 7893.6 | O37: 7463.2 | P37: 7359 | Q37: 7319 | R37: 7937
C38: Other non-current liabilties | D38: 1602.5 | E38: 1695.7 | F38: 1803.1 | G38: 1590.4 | H38: 1694.3 | I38: 1799.7 | J38: 1763 | K38: 1853.8 | L38: 1936.1 | M38: 1932.6 | N38: 2037.7 | O38: 2132.6 | P38: 2060 | Q38: 2059 | R38: 2077
C39: Current IB liabilties | D39: 2006.1 | E39: 1658.2 | F39: 1770.1 | G39: 1477.2 | H39: 1341.9 | I39: 1568.6 | J39: 2413 | K39: 2362.8 | L39: 2208.9 | M39: 2167.1 | N39: 1512 | O39: 2514.2 | P39: 2414 | Q39: 2483 | R39: 1732
C40: Other current liabilteis | D40: 2952.2 | E40: 3197.7 | F40: 3012.9 | G40: 3044.1 | H40: 3445.6 | I40: 3577.8 | J40: 3475 | K40: 3662.8 | L40: 3957.2 | M40: 3996.9 | N40: 4179 | O40: 3980.6 | P40: 4201 | Q40: 4025 | R40: 3433
C41: Total Debt | D41: =SUM(D37:D40) -> 14729.5 | E41: =SUM(E37:E40) -> 15173.5 | F41: =SUM(F37:F40) -> 15153.8 | G41: =SUM(G37:G40) -> 14811.6 | H41: =SUM(H37:H40) -> 15803.1 | I41: =SUM(I37:I40) -> 16367.3 | J41: =SUM(J37:J40) -> 15853 | K41: =SUM(K37:K40) -> 15596.8 | ... S41: =SUM(S37:S40) -> 0
C42: Total E/D | D42: =D36+D41 -> 19300.1 | E42: =E36+E41 -> 19835.6 | F42: =F36+F41 -> 21458.9 | G42: =G36+G41 -> 21783.7 | H42: =H36+H41 -> 23493.8 | I42: =I36+I41 -> 24510.3 | J42: =J36+J41 -> 23460.8 | K42: =K36+K41 -> 23504.7 | ... S42: =S36+S41 -> 0
C44: Cash flow NOKm
C45: Model NI | D45: =D14 -> 429.9 | E45: =E14 -> 161 | F45: =F14 -> 393.4 | G45: =G14 -> 731.5 | H45: =H14 -> 565 | I45: =I14 -> 554.4 | J45: =J14 -> 172.3 | K45: =K14 -> 287.4 | ... S45: =S14 -> 0 | Y45: =Y14 -> 1715.8 | Z45: =Z14 -> 1579.1 | AA45: =AA14 -> 1647.3
...

Sheet SOTP
B2: Asset/Division | C2: Type | D2: Country | E2: Status | F2: Interest (%) | G2: Capacity net (MW) | H2: Weight | I2: WACC | J2: NPV (NOKm) | K2: NPV/MW (NOKm) | L2: NPV weighted (NOKm) | M2: NOK/Share
B3: Crystal Rig I | C3: Wind | D3: UK | E3: In operation | F3: 0.51 | G3: 32 | H3: 1 | I3: 0.064 | J3: 43 | K3: =J3/G3 -> 1.34375 | L3: =J3*H3 -> 43 | M3: =L3/Modell!$B$5 -> 1.011006
B4: Crystal Rig II | C4: Wind | D4: UK | E4: In operation | F4: 0.51 | G4: 70 | H4: 1 | I4: 0.064 | J4: 876 | K4: =J4/G4 -> 12.514286 | L4: =J4*H4 -> 876 | M4: =L4/Modell!$B$5 -> 20.596309
B5: Crystal Rig III | C5: Wind | D5: UK | E5: In operation | F5: 0.51 | G5: 7 | H5: 1 | I5: 0.064 | J5: 167 | K5: =J5/G5 -> 23.857143 | L5: =J5*H5 -> 167 | M5: =L5/Modell!$B$5 -> 3.9264653
B6: Rothes I | C6: Wind | D6: UK | E6: In operation | F6: 0.51 | G6: 26 | H6: 1 | I6: 0.064 | J6: 162 | K6: =J6/G6 -> 6.2307692 | L6: =J6*H6 -> 162 | M6: =L6/Modell!$B$5 -> 3.8089064
B7: Rothes II | C7: Wind | D7: UK | E7: In operation | F7: 0.51 | G7: 21 | H7: 1 | I7: 0.064 | J7: 485 | K7: =J7/G7 -> 23.095238 | L7: =J7*H7 -> 485 | M7: =L7/Modell!$B$5 -> 11.403207
B8: Paul's Hill | C8: Wind | D8: UK | E8: In operation | F8: 0.51 | G8: 33 | H8: 1 | I8: 0.064 | J8: 313 | K8: =J8/G8 -> 9.4848485 | L8: =J8*H8 -> 313 | M8: =L8/Modell!$B$5 -> 7.3591834
B9: Mid Hill | C9: Wind | D9: UK | E9: In operation | F9: 0.51 | G9: 39 | H9: 1 | I9: 0.064 | J9: 709 | K9: =J9/G9 -> 18.179487 | L9: =J9*H9 -> 709 | M9: =L9/Modell!$B$5 -> 16.669843
B10: Brockloch Rig | C10: Wind | D10: UK | E10: In operation | F10: 0.51 | G10: 31 | H10: 1 | I10: 0.064 | J10: 762 | K10: =J10/G10 -> 24.580645 | L10: =J10*H10 -> 762 | M10: =L10/Modell!$B$5 -> 17.915967
B11: Brockloch Rig I | C11: Wind | D11: UK | E11: In operation | F11: 1 | G11: 22 | H11: 1 | I11: 0.064 | J11: 36 | K11: =J11/G11 -> 1.6363636 | L11: =J11*H11 -> 36 | M11: =L11/Modell!$B$5 -> 0.84642365
B12: Lista | C12: Wind | D12: Norway | E12: In operation | F12: 0.51 | G12: 36 | H12: 1 | I12: 0.07 | J12: 293 | K12: =J12/G12 -> 8.1388889 | L12: =J12*H12 -> 293 | M12: =L12/Modell!$B$5 -> 6.888948
B13: Fäbodliden | C13: Wind | D13: Sweden | E13: In operation | F13: 0.51 | G13: 40 | H13: 1 | I13: 0.067 | J13: 361 | K13: =J13/G13 -> 9.025 | L13: =J13*H13 -> 361 | M13: =L13/Modell!$B$5 -> 8.4877482
B14: Högaliden | C14: Wind | D14: Sweden | E14: In operation | F14: 0.51 | G14: 55 | H14: 1 | I14: 0.067 | J14: 730 | K14: =J14/G14 -> 13.272727 | L14: =J14*H14 -> 730 | M14: =L14/Modell!$B$5 -> 17.163591
... B18: Codling | C18: Offshore | D18: Ireland | E18: Awarded | F18: 0.5 | G18: 650 | H18: 0.6 | I18: 0.067 | J18: 4250 | K18: =J18/G18 -> 6.5384615 | L18: =J18*H18 -> 2550 | M18: =L18/Modell!$B$5 -> 59.955008
B19: EV Renewable Energy | G19: =SUM(G3:G18) -> 1208 | I19: =AVERAGE(I3:I18) -> 0.065125 | J19: =SUM(J3:J18) -> 10281 | L19: =SUM(L3:L18) -> 8558.8 | M19: =SUM(M3:M18) -> 201.23252
B21: NPV unallocated costs 2025 and onwards | L21: -2037 | M21: =L21/Modell!$B$5 -> -47.893471
B22: Ownership-adjusted external net IB cash (debt) end-24 | L22: -2122 | M22: =L22/Modell!$B$5 -> -49.891972
B23: Equity value - Renewable Energy | L23: =SUM(L19:L22) -> 4399.8 | M23: =SUM(M19:M22) -> 103.44708
B25: Asset/Division | E25: Interest (%) | G25: Valuation | I25: EBITDA | J25: EV/EBITDA | L25: NPV (NOKm) | M25: NOK/Share | P25: Investering fra MEAG 19.12.25.
B26: Fred Olsen Windcarrier (FOWIC) | E26: 1 | G26: 26-27e EV/EBITDA | I26: 1471 | J26: 4,85x | L26: =I26*4.85 -> 7134.35 | M26: =L26/Modell!$B$5 -> 167.74118 | P26: FOWIC betaler ekstraodrinært utbytte til BONH på 54 MEUR / BONH gir kortsiktgi akjsonærlån tilbake på 29 MEUR
B27: Global Wind Service (GWS) | E27: 0.92 | G27: 25e EV/EBITDA | I27: 129 | J27: 8,0x | L27: =(129*8)*0.92 -> 949.44 | M27: =L27/Modell!B5 -> 22.323013 | P27: MEAG kjøper eksisterende aksjer for MEUR 70
B28: EV Wind Service | M28: =SUM(M26:M27) -> 190.06419 | P28: MEAG skyter inn ny EK på MEUR 30
P29: Q327, MEAG skyer inn yttligere MEUR 50
B30: NPV unallocated costs 2025 and onwards | L30: 576 | M30: =L30/Modell!B5 -> 13.542778
B31: Ownership-adjusted external net IB cash (debt) end-24 | L31: -517 | M31: =L31/Modell!B5 -> -12.155584
B32: Equity value Wind Service | L32: =SUM(L26:L31) -> 8142.79 | M32: =SUM(M28:M31) -> 191.45139
B34: EV - Cruise | E34: 1 | G34: 25e EV/EBITDA | I34: 600 | J34: 5.0x | L34: =600*5 -> 3000 | M34: =L34/Modell!B5 -> 70.535304
B36: External net cash (debt) end-24 | L36: 280 | M36: =L36/Modell!B5 -> 6.583295
B37: NPV of remaing capex 25 and onwards | L37: 0
B38: Equity value Cruise | L38: =SUM(L34:L37) -> 3280 | M38: =SUM(M34:M37) -> 77.118599
B40: EV - Other investments (Inc NHST) | G40: Book value of equity | L40: 508 | M40: =L40/Modell!B5 -> 11.943978
B42: External net cash (debt) end-24 | L42: 452 | M42: =L42/Modell!B5 -> 10.627319
B43: Equity value - Other investments | L43: =SUM(L40:L42) -> 960 | M43: =L43/Modell!B5 -> 22.571297
B45: NAV | L45: =L23+L32+L38+L43 -> 16782.59 | M45: =L45/Modell!B5 -> 394.58836
B47: Discount | K47: 0.157
B49: Target price | M49: =M45*(1-K47) -> 332.63799

Sheet Segementer
B4: NOK million | C4: Q122 | D4: Q222 | E4: Q322 | F4: Q422 | G4: 2022 | H4: Q123 | I4: Q223 | J4: Q323 | K4: Q423 | L4: 2023 | M4: Q124 | N4: Q224 | O4: Q324 | P4: Q424 | Q4: 2024 | R4: Q125 | S4: Q225 | T4: Q325 | U4: Q425 | V4: 2025
B5: Renewables energy
B6: Revenues | C6: 1442 | D6: 693 | E6: 932 | F6: 1326 | G6: =SUM(C6:F6) -> 4393 | H6: 1170 | I6: 430 | J6: 523 | K6: 870 | L6: =SUM(H6:K6) -> 2993 | M6: 724 | N6: 501 | O6: 529 | P6: 905 | Q6: =SUM(M6:P6) -> 2659 | R6: 774 | S6: 399 | T6: 477 | V6: =SUM(R6:U6) -> 1650
B7: Growth | H7: =(H6-C6)/C6 -> -0.18862691 | I7: =(I6-D6)/D6 -> -0.37950938 | J7: =(J6-E6)/E6 -> -0.4388412 | K7: =(K6-F6)/F6 -> -0.3438914 | L7: =(L6-G6)/G6 -> -0.31868882 | M7: =(M6-H6)/H6 -> -0.38119658 | N7: =(N6-I6)/I6 -> 0.16511628 | O7: =(O6-J6)/J6 -> 0.011472275 | ... V7: =(V6-Q6)/Q6 -> -0.37946596
B8: EBITDA | C8: 1220 | D8: 502 | E8: 748 | F8: 1016 | G8: =SUM(C8:F8) -> 3486 | H8: 763 | I8: 277 | J8: 243 | K8: 638 | L8: =SUM(H8:K8) -> 1921 | M8: 476 | N8: 259 | O8: 263 | P8: 587 | Q8: =SUM(M8:P8) -> 1585 | R8: 506 | S8: 127 | T8: 219 | V8: =SUM(R8:U8) -> 852
B9: EBITDA margin | C9: 0.85 | D9: 0.73 | E9: 0.8 | F9: 0.77 | G9: =G8/G6 -> 0.79353517 | H9: 0.65 | I9: 0.64 | J9: 0.46 | K9: 0.73 | L9: =L8/L6 -> 0.64183094 | M9: 0.66 | N9: 0.52 | O9: 0.5 | P9: 0.65 | Q9: =Q8/Q6 -> 0.59608876 | R9: 0.65 | S9: 0.32 | T9: 0.46 | V9: =V8/V6 -> 0.51636364
B10: EBIT | C10: 1141 | D10: 421 | E10: 695 | F10: 907 | G10: =SUM(C10:F10) -> 3164 | H10: 690 | I10: 195 | J10: 155 | K10: 552 | L10: =SUM(H10:K10) -> 1592 | M10: 387 | N10: 168 | O10: 171 | P10: 478 | Q10: =SUM(M10:P10) -> 1204 | R10: 414 | S10: 32 | T10: 129 | V10: =SUM(R10:U10) -> 575
B11: EBT | C11: 1186 | D11: 380 | E11: 1071 | F11: 750 | G11: =SUM(C11:F11) -> 3387 | H11: 591 | I11: 231 | J11: 76 | K11: 284 | L11: =SUM(H11:K11) -> 1182 | M11: 372 | N11: 132 | O11: -33 | P11: 373 | Q11: =SUM(M11:P11) -> 844 | R11: 343 | S11: -79 | T11: 24 | V11: =SUM(R11:U11) -> 288
B12: Net income | C12: 952 | D12: 283 | E12: 820 | F12: 636 | G12: =SUM(C12:F12) -> 2691 | H12: 387 | I12: 203 | J12: -12 | K12: 193 | L12: =SUM(H12:K12) -> 771 | M12: 262 | N12: 84 | O12: -49 | P12: 241 | Q12: =SUM(M12:P12) -> 538 | R12: 240 | S12: -77 | T12: 9 | V12: =SUM(R12:U12) -> 172
B13: Capex | C13: 35 | D13: 17 | E13: 83 | F13: 73 | H13: 25 | I13: 29 | J13: 140 | K13: 48 | M13: 17 | N13: 120 | O13: 290 | P13: -18 | R13: 225 | S13: 527 | T13: 425
B14: Equity | C14: 1034 | D14: 1268 | E14: 3267 | F14: 1763 | H14: 2645 | I14: 2893 | J14: 2365 | K14: 1958 | M14: 2177 | N14: 2132 | O14: 2133 | P14: 2336 | R14: 2843 | S14: 2783 | T14: 3057
B15: Gross IB debt | C15: 5769 | D15: 5882 | E15: 5452 | F15: 5180 | H15: 5959 | I15: 6193 | J15: 5781 | K15: 5530 | M15: 5844 | N15: 5588 | O15: 6100 | P15: 5960 | R15: 6309 | S15: 6402 | T15: 6315
B16: Cash | C16: 1404 | D16: 1407 | E16: 986 | F16: 1183 | H16: 2155 | I16: 1989 | J16: 1557 | K16: 731 | M16: 1039 | N16: 721 | O16: 913 | P16: 721 | R16: 1244 | S16: 665 | T16: 1105
B17: Net IB debt | C17: =C15-C16 -> 4365 | D17: =D15-D16 -> 4475 | E17: =E15-E16 -> 4466 | F17: =F15-F16 -> 3997 | H17: =H15-H16 -> 3804 | I17: =I15-I16 -> 4204 | J17: =J15-J16 -> 4224 | K17: =K15-K16 -> 4799 | M17: =M15-M16 -> 4805 | N17: =N15-N16 -> 4867 | O17: =O15-O16 -> 5187 | P17: =P15-P16 -> 5239 | R17: =R15-R16 -> 5065 | S17: =S15-S16 -> 5737 | T17: =T15-T16 -> 5210 | U17: =U15-U16 -> 0
B18: Capital employed | C18: =C14+C17 -> 5399 | D18: =D14+D17 -> 5743 | E18: =E14+E17 -> 7733 | F18: =F14+F17 -> 5760 | H18: =H14+H17 -> 6449 | I18: =I14+I17 -> 7097 | J18: =J14+J17 -> 6589 | K18: =K14+K17 -> 6757 | M18: =M14+M17 -> 6982 | N18: =N14+N17 -> 6999 | O18: =O14+O17 -> 7320 | P18: =P14+P17 -> 7575 | R18: =R14+R17 -> 7908 | S18: =S14+S17 -> 8520 | T18: =T14+T17 -> 8267 | U18: =U14+U17 -> 0
B19: Hereof internal debt to Bonheur | C19: 380 | D19: 380 | E19: 0 | F19: 0 | H19: 254 | I19: 339 | J19: 287 | K19: 344 | M19: 388 | N19: 568 | O19: 669 | P19: 787 | R19: 1146 | S19: 1291 | T19: 1440
B20: Wind Service
B21: Revenues | C21: 574 | D21: 846 | E21: 1378 | F21: 1293 | G21: =SUM(C21:F21) -> 4091 | H21: 882 | I21: 1264 | J21: 1476 | K21: 1514 | L21: =SUM(H21:K21) -> 5136 | M21: 1183 | N21: 2451 | O21: 1752 | P21: 1098 | Q21: =SUM(M21:P21) -> 6484 | R21: 1073 | S21: 1452 | T21: 1471 | V21: =SUM(R21:U21) -> 3996
B22: Growth | H22: =(H21-C21)/C21 -> 0.53658537 | I22: =(I21-D21)/D21 -> 0.49408983 | J22: =(J21-E21)/E21 -> 0.071117562 | K22: =(K21-F21)/F21 -> 0.17092034 | L22: =(L21-G21)/G21 -> 0.25543877 | M22: =(M21-H21)/H21 -> 0.34126984 | N22: =(N21-I21)/I21 -> 0.93908228 | O22: =(O21-J21)/J21 -> 0.18699187 | ... V22: =(V21-Q21)/Q21 -> -0.38371376
B23: EBITDA | C23: -9 | D23: 106 | E23: 418 | F23: 405 | G23: =SUM(C23:F23) -> 920 | H23: 206 | I23: 320 | J23: 399 | K23: 402 | L23: =SUM(H23:K23) -> 1327 | M23: 174 | N23: 763 | O23: 435 | P23: 180 | Q23: =SUM(M23:P23) -> 1552 | R23: 280 | S23: 584 | T23: 577 | V23: =SUM(R23:U23) -> 1441
B24: EBITDA margin | C24: -0.01 | D24: 0.12 | E24: 0.3 | F24: 0.31 | G24: =G23/G21 -> 0.22488389 | H24: 0.23 | I24: 0.25 | J24: 0.27 | K24: 0.27 | L24: =L23/L21 -> 0.25837227 | M24: 0.15 | N24: 0.31 | O24: 0.25 | P24: 0.16 | Q24: =Q23/Q21 -> 0.23935842 | R24: 0.26 | S24: 0.4 | T24: 0.39 | V24: =V23/V21 -> 0.36061061
B25: EBIT | C25: -102 | D25: 35 | E25: 212 | F25: 286 | G25: =SUM(C25:F25) -> 431 | H25: 92 | I25: 199 | J25: 282 | K25: 256 | L25: =SUM(H25:K25) -> 829 | M25: 53 | N25: 632 | O25: 315 | P25: 73 | Q25: =SUM(M25:P25) -> 1073 | R25: 127 | S25: 451 | T25: 430 | V25: =SUM(R25:U25) -> 1008
B26: EBT | C26: -118 | D26: 18 | E26: 189 | F26: 268 | G26: =SUM(C26:F26) -> 357 | H26: 69 | I26: 171 | J26: 262 | K26: 226 | L26: =SUM(H26:K26) -> 728 | M26: 50 | N26: 604 | O26: 288 | P26: 110 | Q26: =SUM(M26:P26) -> 1052 | R26: 92 | S26: 757 | T26: 418 | V26: =SUM(R26:U26) -> 1267
B27: Net income | C27: -124 | D27: -17 | E27: 160 | F27: 283 | G27: =SUM(C27:F27) -> 302 | H27: 59 | I27: 205 | J27: 240 | K27: 171 | L27: =SUM(H27:K27) -> 675 | M27: 37 | N27: 542 | O27: 222 | P27: 118 | Q27: =SUM(M27:P27) -> 919 | R27: 92 | S27: 721 | T27: 320 | V27: =SUM(R27:U27) -> 1133
B28: Capex | C28: 264 | D28: 206 | E28: 124 | F28: -22 | H28: 85 | I28: 104 | J28: 148 | K28: 143 | M28: 191 | N28: 52 | O28: 195 | P28: 363 | R28: 139 | S28: 149 | T28: 37 | V28: =SUM(R28:U28) -> 325
B29: Equity | C29: 3048 | D29: 3216 | E29: 3457 | F29: 3722 | H29: 4116 | I29: 4510 | J29: 4468 | K29: 4634 | M29: 4851 | N29: 5259 | O29: 5659 | P29: 5807 | R29: 5709 | S29: 6249 | T29: 5717 | V29: =SUM(R29:U29) -> 17675
B30: Gross IB debt | C30: 1697 | D30: 2184 | E30: 2316 | F30: 2410 | H30: 2388 | I30: 2553 | J30: 1982 | K30: 1760 | M30: 1718 | N30: 1606 | O30: 1680 | P30: 1326 | R30: 1146 | S30: 1220 | T30: 1425 | V30: =SUM(R30:U30) -> 3791
B31: Cash | C31: 569 | D31: 620 | E31: 672 | F31: 888 | H31: 1066 | I31: 1388 | J31: 978 | K31: 732 | M31: 1123 | N31: 2201 | O31: 2307 | P31: 1813 | R31: 1793 | S31: 2680 | T31: 1961 | V31: =SUM(R31:U31) -> 6434
B32: Net IB debt | C32: =C30-C31 -> 1128 | D32: =D30-D31 -> 1564 | E32: =E30-E31 -> 1644 | F32: =F30-F31 -> 1522 | H32: =H30-H31 -> 1322 | I32: =I30-I31 -> 1165 | J32: =J30-J31 -> 1004 | K32: =K30-K31 -> 1028 | M32: =M30-M31 -> 595 | N32: =N30-N31 -> -595 | O32: =O30-O31 -> -627 | P32: =P30-P31 -> -487 | R32: =R30-R31 -> -647 | S32: =S30-S31 -> -1460 | T32: =T30-T31 -> -536 | U32: =U30-U31 -> 0
B33: Capital employed | C33: =C29+C32 -> 4176 | D33: =D29+D32 -> 4780 | E33: =E29+E32 -> 5101 | F33: =F29+F32 -> 5244 | H33: =H29+H32 -> 5438 | I33: =I29+I32 -> 5675 | J33: =J29+J32 -> 5472 | K33: =K29+K32 -> 5662 | M33: =M29+M32 -> 5446 | N33: =N29+N32 -> 4664 | O33: =O29+O32 -> 5032 | P33: =P29+P32 -> 5320 | R33: =R29+R32 -> 5062 | S33: =S29+S32 -> 4789 | T33: =T29+T32 -> 5181 | U33: =U29+U32 -> 0
B34: Hereof internal debt to Bonheur | C34: 243 | D34: 259 | E34: 265 | F34: 263 | H34: 285 | I34: 300 | J34: 315 | K34: 315 | M34: 292 | N34: 285 | O34: 294 | P34: 0 | R34: 0 | S34: 0 | T34: 0
B35: Cruise
B36: Revenues | C36: 209 | D36: 580 | E36: 632 | F36: 472 | G36: =SUM(C36:F36) -> 1893 | H36: 682 | I36: 855 | J36: 921 | K36: 856 | L36: =SUM(H36:K36) -> 3314 | M36: 788 | N36: 1043 | O36: 1016 | P36: 802 | Q36: =SUM(M36:P36) -> 3649 | R36: 737 | S36: 1092 | T36: 1148 | V36: =SUM(R36:U36) -> 2977
B37: Growth | H37: =(H36-C36)/C36 -> 2.2631579 | I37: =(I36-D36)/D36 -> 0.47413793 | J37: =(J36-E36)/E36 -> 0.45727848 | K37: =(K36-F36)/F36 -> 0.81355932 | L37: =(L36-G36)/G36 -> 0.75066033 | M37: =(M36-H36)/H36 -> 0.15542522 | N37: =(N36-I36)/I36 -> 0.21988304 | O37: =(O36-J36)/J36 -> 0.10314875 | ... V37: =(V36-Q36)/Q36 -> -0.18416004
B38: EBITDA | C38: -246 | D38: -42 | E38: -42 | F38: -85 | G38: =SUM(C38:F38) -> -415 | H38: 5 | I38: 132 | J38: 213 | K38: 133 | L38: =SUM(H38:K38) -> 483 | M38: 2 | N38: 212 | O38: 255 | P38: 33 | Q38: =SUM(M38:P38) -> 502 | R38: -33 | S38: 307 | T38: 352 | V38: =SUM(R38:U38) -> 626
B39: EBITDA margin | C39: -1.18 | D39: -0.07 | E39: -0.07 | F39: -0.18 | G39: =G38/G36 -> -0.21922874 | H39: 0.01 | I39: 0.15 | J39: 0.23 | K39: 0.15 | L39: =L38/L36 -> 0.14574532 | M39: 0 | N39: 0.2 | O39: 0.25 | P39: 0.04 | Q39: =Q38/Q36 -> 0.13757194 | R39: -0.04 | S39: 0.28 | T39: 0.31 | V39: =V38/V36 -> 0.2102788
B40: EBIT | C40: -296 | D40: -95 | E40: -550 | F40: -105 | G40: =SUM(C40:F40) -> -1046 | H40: -24 | I40: 93 | J40: 174 | K40: 91 | L40: =SUM(H40:K40) -> 334 | M40: -40 | N40: 169 | O40: 210 | P40: -18 | Q40: =SUM(M40:P40) -> 321 | R40: -89 | S40: 258 | T40: 309 | V40: =SUM(R40:U40) -> 478
B41: EBT | C41: -304 | D41: -108 | E41: -556 | F41: -120 | G41: =SUM(C41:F41) -> -1088 | H41: -52 | I41: 64 | J41: 146 | K41: 41 | L41: =SUM(H41:K41) -> 199 | M41: -48 | N41: 137 | O41: 160 | P41: -28 | Q41: =SUM(M41:P41) -> 221 | R41: -119 | S41: 203 | T41: 277 | V41: =SUM(R41:U41) -> 361
B42: Net income | C42: -304 | D42: -108 | E42: -556 | F42: -120 | G42: =SUM(C42:F42) -> -1088 | H42: -53 | I42: 64 | J42: 146 | K42: 48 | L42: =SUM(H42:K42) -> 205 | M42: -48 | N42: 137 | O42: 160 | P42: -20 | Q42: =SUM(M42:P42) -> 229 | R42: -119 | S42: 203 | T42: 277 | V42: =SUM(R42:U42) -> 361
B43: Capex | C43: 2 | D43: 5 | E43: 42 | F43: 108 | H43: 94 | I43: 19 | J43: -11 | K43: 23 | M43: 11 | N43: 3 | O43: 16 | P43: 187 | R43: 3 | S43: 1 | T43: 32 | V43: =SUM(R43:U43) -> 36
...

Sheet Nøkkeltall
D4: 2025 | E4: 2026 | F4: 2027
C5: EV/EBIT
C6: P/E
