Workbook

Sheet Info
A1: Pr nå er 15MW turbiner de største i verden.
G4: 2026 guidance: | K4: North Sea Summit 2026
G5: Revenue | H5: 854 - 944m | K5: Havvind-mål 2050 | L5: 300 GW
G6: EBITDA | H6: 420 - 510m | K6: Årlig ny kapasitet fra 2031 | L6: 15 GW/år
K7: Installert kapasitet i dag (~) | L7: ~35-40 GW
K8: Opptrapping nødvendig | L8: ~8x
G9: T&I = Transportation and installation
K10: Drivere:
G11: AR8 kommer i juli 2026 | K11: • Energisikkerhet & geopolitikk
K12: • Redusere importavhengighet
G13: Nexra er O&M pool til Cadeler | K13: • Nordsjøen som Europas vind-hub
A19: Press releases:
A20: 31.03.26: Styreleder Sohmen-Pao kjøper 715 000 aksjer til kurs 53,52
A21: 26.03.26: CADL henter 1 965 million NOK at 56kr grunnet mulig investering i to t-class nybygg og et heavy lift-vessel. All in kostand for heavy-lift fartøyet er 120 - 145 EURm. Begge t-class fartøyene kjøper for rundt 400 mill USD.
A22: Til sammenligning ble et fartyø kontrahert for 526 mill USD i februar 26. Capex vil være back-end loaded hvor majoriteten kommer etter 2029 og vil være 65% gjeldfinansiert
A23: 23.03.26: Nexra vinner enda en O&M kontrakt som skal fullføres ila 2026 med wind maker
A24: 09.02.26: Nexra, CADL dedicated service concept, Singerer en kontrakt for O&M campaign in Taiwan. Kontrakten er på 20 mull euro og skal starte mars 26 og vare 3-4 måneder av Wind Maker
A25: 28.01.26: CADL signerer preferred supplier agreement (PSA) for fundament installasjon i 2028. Kontrakten skal begynne H128 og skal kreve 2 fartøy ink et A-klasse fartøy
A26: 02.12.25: Nordea funds flagger 5,02%
A27: 0.12.25: Styreleder Sohmen-Pao kjøper aksjer for 786,2 mill kurs 44,5 (Flagger 25%, eier 27,36%)
A28: 01.12.25: CADL styrker balansen sin med en ekstra usikret grønn lånefasilitet. Fasiliteten er på 60 mill Euro med opsjon til å økes til 80 mill Euro
A29: 28.11.25: Cadeler tar levering av sitt 10 fartøy, Wind mover
A30: 10.11.25: Signerer stor kontrakt for både foundation and turbine trans and install til en verdi a 500 EURm. Fundamenetene skal bli transportert tidlig 2029 (A-class). Turbininstall skal starte tidlig 2030 (O-class) (Ikke avklart enda)
... A70: 27.03.24: Wind Scylla signerner kontrakt verdt EUR 75 - 150mill

Sheet Flåte 
A5: Flåte
C6: Class | D6: Main crain capacity tonnes | E6: Hook height (meters) | F6: Turbine installation capacity (MW) | G6: Built/expected deliv | H6: WTG | I6: FOU | J6: O&M
A7: Wind turbine installation vessels (WTIV) | B7: Wind Zaratan | C7: Z-class | D7: 800 | E7: 92 | F7: 9.5 | G7: 2012
B8: Wind Scylla | C8: S-class | D8: 1540 | E8: 105 | F8: 12-14mw | G8: 2015
B9: Wind Orca | C9: O-class | D9: 1600 | E9: 160 | F9: 15-20 | G9: 2012 | K9: Oppgraderte kranen i Q1 2024 for å kunne ta 20 MW turbin
B10: Wind Osprey | C10: O-class | D10: 1600 | E10: 160 | F10: 15-20 | G10: 2013 | K10: Oppgraderte kranen i Q1 2024 for å kunne ta 20 MW turbin
B11: Wind keeper | C11: K-class | D11: 2200 | F11: 15 | G11: Q3 2025
B12: Wind Maker | C12: M-class | D12: 2600 | E12: 174 | F12: 20+ | G12: Q1 2025
B13: Wind Mover | C13: M-class | D13: 2600 | E13: 174 | F13: 20+ | G13: Q4 2025
B14: Wind peak | C14: P-class | D14: >2600 | E14: >200 | F14: 20+ | G14: 2024
B15: Wind Pace | C15: P-class | D15: >2600 | E15: >200 | F15: 20+ | G15: Q2 2025
A16: Foundation installation vessels (FIV) | B16: Wind Ally | C16: A-class | D16: >3300 | E16: >200 | F16: 20+ & up to 6 XL foundations | G16: Q3 2025
B17: Wind Ace | C17: A-class | D17: >3300 | E17: >200 | F17: 20+ & up to 6 XL foundations | G17: Q3 2026
B18: Wind Apex | C18: A-class | D18: >3300 | E18: >200 | F18: 20+ & up to 6 XL foundations | G18: Q2 2027
B19: Wind T | C19: T-class | G19: Q2-Q3 2030
B20: Wind T | C20: T-class | G20: Q2-Q3 2031
A21: Heavy-lift vessel
H23: Capable
H24: Priority
C30: 2025 | G30: 2026 | K30: 2027 | O30: 2028 | S30: 2029 | W30: 2030 | AA30: 2031 | AE30: 2032
A31: Vessel name | B31: Class | C31: Q1 | D31: Q2 | E31: Q3 | F31: Q4 | G31: Q1 | H31: Q2 | I31: Q3 | J31: Q4 | K31: Q1 | L31: Q2 | M31: Q3 | N31: Q4 | O31: Q1 | P31: Q2 | Q31: Q3 | R31: Q4 | S31: Q1 | T31: Q2 | U31: Q3 | V31: Q4 | W31: Q1 | X31: Q2 | Y31: Q3 | Z31: Q4 | AA31: Q1 | AB31: Q2 | AC31: Q3 | AD31: Q4 | AE31: Q1 | AF31: Q2 | AG31: Q3 | AH31: Q4
A33: Wind Zaratan | B33: Z-class | C33: O&M Changfang and Xidao | G33: Upgrades in 2026, O&M in Asia, then back to Europe
A34: Wind Scylla | B34: S-class | D34: Revolution Wind | G34: Sunrise wind
A35: Wind Orca | B35: O-class | C35: O&M | D35: He Dreiht | G35: Hornsea 3 | K35: Baltyk 2 & 3 | O35: Ocean Winds
A36: Wind Osprey | B36: O-class | C36: O&M | D36: Baltic power | G36: EA3 | M36: EA Hub 2
A37: Wind Keeper | B37: K-class | G37: Vestas O&M | K37: Vestas O&M | O37: Vestas O&M | S37: Vestas O&M | W37: Vestas O&M | AA37: Vestas O&M
A38: Wind Maker | B38: M-class | D38: Changhua | G38: O&M | L38: APAC | P38: Reservation agreement
A39: Wind Mover | B39: M-class | C39: Under construction | F39: Undisclosed | G39: Baltik power project | J39: Inch cape
A40: Wind Peak | B40: P-class | C40: Sofia | J40: Hornsea 3 | O40: Undisclosed
A41: Wind Pace | B41: P-class | D41: USA O&M windyard | H41: EA Hub 3 | K41: Baltyk | M41: Baltica 2
A42: Wind Ally | B42: A-class | C42: Under construction | H42: Hornsea 3
A43: Wind Ace | B43: A-class | C43: Under construction | K43: EA Hub 2 | O43: Undiclosed
A44: Wind Apex | B44: A-class | C44: Under construction | L44: Client with a project from yard
A45: Wind T | B45: T-class | C45: Under construction
A46: Wind T | B46: T-class | C46: Under construction
A48: Firm contract
A49: Assumed options
A50: Mobilisation and pre-delivery availibility

Sheet Modell
AI1: nybygg1 | AJ1: nybygg 2
A3: Kapitalstruktur | C3: EUR million | D3: Q122 | E3: Q222 | F3: Q322 | G3: Q422 | H3: Q123 | I3: Q223 | J3: Q323 | K3: Q423 | L3: Q124 | M3: Q224 | N3: Q324 | O3: Q424 | P3: Q125 | Q3: Q225 | R3: Q325 | S3: Q425 | T3: Q126 | U3: Q226 | V3: Q326 | W3: Q426 | Y3: FY 2021 | Z3: FY 2022 | AA3: FY 2023 | AB3: FY 2024 | AC3: FY 2025 | AD3: FY 2026 | AE3: FY 2027 | AF3: FY 2028 | AG3: FY 2029 | AH3: FY 2030 | AI3: FY 2031 | AJ3: FY 2032 | AK3: FY 2033 | AL3: FY 2034 | AM3: FY 2035
A4: Price | B4: 63 | C4: Revenue | H4: 18.9 | I4: 48.873 | J4: 23.415 | L4: 19 | M4: 63 | N4: 81 | O4: =248.738-163 -> 85.738 | P4: 65.474 | Q4: =298.535-P4 -> 233.061 | R4: =452.782-Q4-P4 -> 154.247 | S4: 167.572 | T4: 124.727 | Y4: 60.938 | Z4: 106.424 | AA4: 108.622 | AB4: =SUM(L4:O4) -> 248.738 | AC4: 620 | AD4: 910 | AE4: =AD4*1.3 -> 1183 | AF4: =AE4*1.05 -> 1242.15 | AG4: =AF4*1.05 -> 1304.2575 | AH4: =AG4*1.05 -> 1369.4704 | AI4: =AH4*1.075 -> 1472.1807 | AJ4: =AI4*1.075 -> 1582.5942 | AK4: =AJ4*1.05 -> 1661.7239 | AL4: =AK4*1.05 -> 1744.8101 | AM4: =AL4*1.05 -> 1832.0506
A5: S/O | B5: 386.05334 | C5: Cost of sales | H5: -12.15 | I5: -13.072 | J5: -15.822 | L5: -26.979 | M5: -30 | N5: -33.3 | O5: =90-124.228 -> -34.228 | P5: -44.558 | Q5: =-100.234-P5 -> -55.676 | R5: =-158.826-Q5-P5 -> -58.592 | S5: -77.929 | T5: -97.964 | Y5: -38.879 | Z5: -49.537 | AA5: -59.858 | AB5: =SUM(L5:O5) -> -124.507 | AC5: -237 | AD5: -450 | AE5: =AE4*-0.45 -> -532.35 | AF5: =AF4*-0.45 -> -558.9675 | AG5: =AG4*-0.45 -> -586.91588 | AH5: =AH4*-0.45 -> -616.26167 | AI5: =AI4*-0.45 -> -662.48129 | AJ5: =AJ4*-0.45 -> -712.16739 | AK5: =AK4*-0.45 -> -747.77576 | AL5: =AL4*-0.45 -> -785.16455 | AM5: =AM4*-0.45 -> -824.42278
A6: MC NOKm | B6: =B4*B5 -> 24321.36 | C6: Gross profit | H6: =SUM(H4:H5) -> 6.75 | I6: =SUM(I4:I5) -> 35.801 | J6: =SUM(J4:J5) -> 7.593 | L6: =SUM(L4:L5) -> -7.979 | M6: =SUM(M4:M5) -> 33 | N6: =SUM(N4:N5) -> 47.7 | O6: =SUM(O4:O5) -> 51.51 | P6: =SUM(P4:P5) -> 20.916 | Q6: =SUM(Q4:Q5) -> 177.385 | R6: =SUM(R4:R5) -> 95.655 | S6: =SUM(S4:S5) -> 89.643 | T6: =SUM(T4:T5) -> 26.763 | Y6: =SUM(Y4:Y5) -> 22.059 | Z6: =SUM(Z4:Z5) -> 56.887 | AA6: =SUM(AA4:AA5) -> 48.764 | AB6: =SUM(AB4:AB5) -> 124.231 | AC6: =SUM(AC4:AC5) -> 383 | AD6: =SUM(AD4:AD5) -> 460 | AE6: =SUM(AE4:AE5) -> 650.65 | AF6: =SUM(AF4:AF5) -> 683.1825 | ... AM6: =SUM(AM4:AM5) -> 1007.6278
A7: Cash NOKm | B7: 2389.986 | C7: Other opex | H7: 0.62 | I7: -0.62 | J7: 0 | L7: 0.62 | M7: 0.127 | N7: 0.65 | O7: 0 | P7: 0 | Q7: 0 | R7: 4.5 | S7: 4.27 | T7: 0 | Y7: 0 | Z7: 0 | AA7: 0.137 | AB7: =SUM(L7:O7) -> 1.397 | AC7: 9 | AD7: -50 | AE7: =AD7*1.03 -> -51.5 | AF7: =AE7*1.03 -> -53.045 | AG7: =AF7*1.03 -> -54.63635 | AH7: =AG7*1.03 -> -56.275441 | AI7: =AH7*1.03 -> -57.963704 | AJ7: =AI7*1.03 -> -59.702615 | AK7: =AJ7*1.03 -> -61.493693 | AL7: =AK7*1.03 -> -63.338504 | AM7: =AL7*1.03 -> -65.238659
A8: Debt NOKm | B8: 17080.492 | C8: EBITDA | H8: =SUM(H6:H7) -> 7.37 | I8: =SUM(I6:I7) -> 35.181 | J8: =SUM(J6:J7) -> 7.593 | L8: =SUM(L6:L7) -> -7.359 | M8: =SUM(M6:M7) -> 33.127 | N8: =SUM(N6:N7) -> 48.35 | O8: =SUM(O6:O7) -> 51.51 | P8: =SUM(P6:P7) -> 20.916 | Q8: =SUM(Q6:Q7) -> 177.385 | R8: =SUM(R6:R7) -> 100.155 | S8: =SUM(S6:S7) -> 93.913 | T8: =SUM(T6:T7) -> 26.763 | Y8: =SUM(Y6:Y7) -> 22.059 | Z8: =SUM(Z6:Z7) -> 56.887 | AA8: =SUM(AA6:AA7) -> 48.901 | AB8: =SUM(AB6:AB7) -> 125.628 | AC8: =SUM(AC6:AC7) -> 392 | AD8: =SUM(AD6:AD7) -> 410 | AE8: =SUM(AE6:AE7) -> 599.15 | AF8: =SUM(AF6:AF7) -> 630.1375 | ... AM8: =SUM(AM6:AM7) -> 942.38918
A9: EV NOKm | B9: =B6-B7+B8 -> 39011.866 | C9: Adminstrative expenses | H9: -4.6 | I9: -8.512 | J9: -6.931 | L9: -12.797 | M9: -13.5 | N9: -15 | O9: =-14 -> -14 | P9: -16.222 | Q9: =2.8-33.2-P9 -> -14.178 | R9: =-50.828-Q9-P9 -> -20.428 | S9: -23.798 | T9: -19 | Y9: -10.925 | Z9: -15.696 | AA9: -34.458 | AB9: =SUM(L9:O9) -> -55.297 | AC9: -75 | AD9: -100 | AE9: =AD9*1.05 -> -105 | AF9: =AE9*1.05 -> -110.25 | AG9: =AF9*1.05 -> -115.7625 | AH9: =AG9*1.05 -> -121.55063 | AI9: =AH9*1.05 -> -127.62816 | AJ9: =AI9*1.05 -> -134.00956 | AK9: =AJ9*1.05 -> -140.71004 | AL9: =AK9*1.05 -> -147.74554 | AM9: =AL9*1.05 -> -155.13282
C10: EBIT | H10: =SUM(H8:H9) -> 2.77 | I10: =SUM(I8:I9) -> 26.669 | J10: =SUM(J8:J9) -> 0.662 | L10: =SUM(L8:L9) -> -20.156 | M10: =SUM(M8:M9) -> 19.627 | N10: =SUM(N8:N9) -> 33.35 | O10: =SUM(O8:O9) -> 37.51 | P10: =SUM(P8:P9) -> 4.694 | Q10: =SUM(Q8:Q9) -> 163.207 | R10: =SUM(R8:R9) -> 79.727 | S10: =SUM(S8:S9) -> 70.115 | T10: =SUM(T8:T9) -> 7.763 | Y10: =SUM(Y8:Y9) -> 11.134 | Z10: =SUM(Z8:Z9) -> 41.191 | AA10: =SUM(AA8:AA9) -> 14.443 | AB10: =SUM(AB8:AB9) -> 70.331 | AC10: =SUM(AC8:AC9) -> 317 | AD10: =SUM(AD8:AD9) -> 310 | AE10: =SUM(AE8:AE9) -> 494.15 | AF10: =SUM(AF8:AF9) -> 519.8875 | ... AM10: =SUM(AM8:AM9) -> 787.25636
C11: Finance income | H11: 0.015 | I11: 0.426 | J11: 0.285 | L11: 0.406 | M11: 4.5 | N11: -1.5 | O11: 3.2 | P11: 0.27 | Q11: 5 | R11: =4.4-Q11 -> -0.6 | S11: 2.828 | T11: 9.5 | Y11: 1.795 | Z11: 4.031 | AA11: 1.541 | AB11: =SUM(L11:O11) -> 6.606 | AC11: 7 | AD11: 10 | AE11: 10 | AF11: 10 | AG11: 10 | AH11: 10 | AI11: 10 | AJ11: 10 | AK11: 10 | AL11: 10 | AM11: 10
A12: Euro/NOK | B12: 10.8 | C12: Finance costs | H12: -0.127 | I12: -0.164 | J12: -0.337 | L12: -1.087 | M12: -1.1 | N12: -3.4 | O12: -1 | P12: -2 | Q12: 0 | R12: -12 | S12: -23.377 | T12: -24.172 | Y12: -5.491 | Z12: -9.681 | AA12: -4.486 | AB12: =SUM(L12:O12) -> -6.587 | AC12: -37 | AD12: -50 | AE12: -50 | AF12: -50 | AG12: =AF12*1.05 -> -52.5 | AH12: =AG12*1.05 -> -55.125 | AI12: =AH12*1.05 -> -57.88125 | AJ12: =AI12*1.05 -> -60.775313 | AK12: -61 | AL12: -61 | AM12: -61
C13: PTP | H13: =SUM(H10:H12) -> 2.658 | I13: =SUM(I10:I12) -> 26.931 | J13: =SUM(J10:J12) -> 0.61 | K13: =SUM(K10:K12) -> 0 | L13: =SUM(L10:L12) -> -20.837 | M13: =SUM(M10:M12) -> 23.027 | N13: =SUM(N10:N12) -> 28.45 | O13: =SUM(O10:O12) -> 39.71 | ... T13: =SUM(T10:T12) -> -6.909 | Y13: =SUM(Y10:Y12) -> 7.438 | Z13: =SUM(Z10:Z12) -> 35.541 | AA13: =SUM(AA10:AA12) -> 11.498 | AB13: =SUM(AB10:AB12) -> 70.35 | AC13: =SUM(AC10:AC12) -> 287 | AD13: =SUM(AD10:AD12) -> 270 | AE13: =SUM(AE10:AE12) -> 454.15 | AF13: =SUM(AF10:AF12) -> 479.8875 | ... AM13: =SUM(AM10:AM12) -> 736.25636
C14: tax | H14: -0.019 | I14: 0.019 | J14: 0 | L14: -0.019 | M14: -1.1 | N14: -0.5 | O14: -1 | P14: -1.2 | Q14: -2 | R14: -2.5 | S14: -1.98 | T14: 0 | Y14: 0.013 | Z14: 0 | AA14: 0 | AB14: =SUM(L14:O14) -> -2.619 | AC14: -8 | AD14: -6 | AE14: =AE13*-0.22 -> -99.913 | AF14: =AF13*-0.22 -> -105.57525 | AG14: =AG13*-0.22 -> -110.97741 | AH14: =AH13*-0.22 -> -116.65668 | AI14: =AI13*-0.22 -> -126.76977 | AJ14: =AJ13*-0.22 -> -137.70665 | AK14: =AK13*-0.22 -> -145.36377 | AL14: =AL13*-0.22 -> -153.46353 | AM14: =AM13*-0.22 -> -161.9764
A15: Bokverdi | C15: Net income | H15: =SUM(H13:H14) -> 2.639 | I15: =SUM(I13:I14) -> 26.95 | J15: =SUM(J13:J14) -> 0.61 | L15: =SUM(L13:L14) -> -20.856 | M15: =SUM(M13:M14) -> 21.927 | N15: =SUM(N13:N14) -> 27.95 | O15: =SUM(O13:O14) -> 38.71 | P15: =SUM(P13:P14) -> 1.764 | Q15: =SUM(Q13:Q14) -> 166.207 | R15: =SUM(R13:R14) -> 64.627 | S15: =SUM(S13:S14) -> 47.586 | T15: =SUM(T13:T14) -> -6.909 | Y15: =SUM(Y13:Y14) -> 7.451 | Z15: =SUM(Z13:Z14) -> 35.541 | AA15: =SUM(AA13:AA14) -> 11.498 | AB15: =SUM(AB13:AB14) -> 67.731 | AC15: =SUM(AC13:AC14) -> 279 | AD15: =SUM(AD13:AD14) -> 264 | AE15: =SUM(AE13:AE14) -> 354.237 | AF15: =SUM(AF13:AF14) -> 374.31225 | ... AM15: =SUM(AM13:AM14) -> 574.27996 | AN15: =AM15*(1+$AP$19) -> 568.53716 | AO15: =AN15*(1+$AP$19) -> 562.85179 | AP15: =AO15*(1+$AP$19) -> 557.22327 | AQ15: =AP15*(1+$AP$19) -> 551.65104 | AR15: =AQ15*(1+$AP$19) -> 546.13453 | AS15: =AR15*(1+$AP$19) -> 540.67318 | AT15: =AS15*(1+$AP$19) -> 535.26645 | AU15: =AT15*(1+$AP$19) -> 529.91378 | ... EG15: =EF15*(1+$AP$19) -> 214.47305
A16: =(T49*B12)/B5 -> 47.049689 | C16: Share | H16: 342 | I16: 342 | J16: 342 | K16: 342 | L16: 342 | M16: 342 | N16: 350.95758 | O16: 350.95758 | P16: 350.95758 | Q16: 350.95758 | R16: 350.95758 | S16: 350.95758 | T16: 350.95758 | Y16: 128 | Z16: 155 | AA16: 203.95758 | AB16: 350.95758 | AC16: 350.95758 | AD16: 386.05334 | AE16: 386.05334 | AF16: 386.05334 | AG16: 386.05334 | AH16: 386.05334 | AI16: 386.05334 | AJ16: 386.05334 | AK16: 386.05334 | AL16: 386.05334 | AM16: 386.05334
C17: EPS (NOK) | H17: =(H15/H16)*$B$12 -> 0.083336842 | I17: =(I15/I16)*$B$12 -> 0.85105263 | J17: =(J15/J16)*$B$12 -> 0.019263158 | K17: =(K15/K16)*$B$12 -> 0 | L17: =(L15/L16)*$B$12 -> -0.65861053 | M17: =(M15/M16)*$B$12 -> 0.69243158 | N17: =(N15/N16)*$B$12 -> 0.86010394 | O17: =(O15/O16)*$B$12 -> 1.1912209 | P17: 0.06 | Q17: 5.31 | R17: 2.06 | S17: 2 | T17: =(T15*10.8)/T16 -> -0.21261031 | Y17: 0.65 | Z17: 2.57 | AA17: 0.63 | AB17: 2.16 | AC17: 8.96 | AD17: =(AD15/AD16)*$B$12 -> 7.3855079 | AE17: =(AE15/AE16)*$B$12 -> 9.9099249 | AF17: =(AF15/AF16)*$B$12 -> 10.471538 | AG17: =(AG15/AG16)*$B$12 -> 11.007354 | AH17: =(AH15/AH16)*$B$12 -> 11.570656 | AI17: =(AI15/AI16)*$B$12 -> 12.573729 | AJ17: =(AJ15/AJ16)*$B$12 -> 13.658508 | AK17: =(AK15/AK16)*$B$12 -> 14.417984 | ... AM17: =(AM15/AM16)*$B$12 -> 16.065717
A18: P/B | AO18: Discount | AP18: 0.1
A19: =B4/A16 -> 1.3390099 | C19: Revenue y/y | H19: =(H4-D4)/D4 -> #DIV/0! | I19: =(I4-E4)/E4 -> #DIV/0! | J19: =(J4-F4)/F4 -> #DIV/0! | K19: =(K4-G4)/G4 -> #DIV/0! | L19: =(L4-H4)/H4 -> 0.0052910053 | M19: =(M4-I4)/I4 -> 0.28905531 | N19: =(N4-J4)/J4 -> 2.4593209 | O19: =(O4-K4)/K4 -> #DIV/0! | ... T19: =(T4-P4)/P4 -> 0.90498518 | Z19: =(Z4-Y4)/Y4 -> 0.7464308 | AA19: =(AA4-Z4)/Z4 -> 0.020653236 | AB19: =(AB4-AA4)/AA4 -> 1.2899413 | AC19: =(AC4-AB4)/AB4 -> 1.4925826 | AD19: =(AD4-AC4)/AC4 -> 0.46774194 | AE19: =(AE4-AD4)/AD4 -> 0.3 | AF19: =(AF4-AE4)/AE4 -> 0.05 | AG19: =(AG4-AF4)/AF4 -> 0.05 | ... AM19: =(AM4-AL4)/AL4 -> 0.05 | AO19: TV | AP19: -0.01
C20: Gross profit | L20: =L6/L4 -> -0.41994737 | M20: =M6/M4 -> 0.52380952 | N20: =N6/N4 -> 0.58888889 | O20: =O6/O4 -> 0.60078378 | P20: =P6/P4 -> 0.31945505 | Q20: =Q6/Q4 -> 0.76110975 | R20: =R6/R4 -> 0.62014172 | S20: =S6/S4 -> 0.53495214 | T20: =T6/T4 -> 0.21457263 | Y20: =Y6/Y4 -> 0.36199088 | Z20: =Z6/Z4 -> 0.53453168 | AA20: =AA6/AA4 -> 0.448933 | AB20: =AB6/AB4 -> 0.4994452 | AC20: =AC6/AC4 -> 0.61774194 | AD20: =AD6/AD4 -> 0.50549451 | AE20: =AE6/AE4 -> 0.55 | AF20: =AF6/AF4 -> 0.55 | ... AM20: =AM6/AM4 -> 0.55 | AO20: NPV Eur | AP20: =NPV(AP18,AD15:EG15) -> 4528.999
A21: Gearing | B21: =(T54+T62-T42)/AD10 -> 4.3878452 | C21: EBITDA margin | H21: =H8/H4 -> 0.38994709 | I21: =I8/I4 -> 0.71984531 | J21: =J8/J4 -> 0.32427931 | K21: =K8/K4 -> #DIV/0! | L21: =L8/L4 -> -0.38731579 | M21: =M8/M4 -> 0.5258254 | N21: =N8/N4 -> 0.59691358 | O21: =O8/O4 -> 0.60078378 | ... T21: =T8/T4 -> 0.21457263 | Y21: =Y8/Y4 -> 0.36199088 | Z21: =Z8/Z4 -> 0.53453168 | AA21: =AA8/AA4 -> 0.45019425 | AB21: =AB8/AB4 -> 0.50506155 | AC21: =AC8/AC4 -> 0.63225806 | AD21: =AD8/AD4 -> 0.45054945 | AE21: =AE8/AE4 -> 0.50646661 | AF21: =AF8/AF4 -> 0.50729582 | ... AM21: =AM8/AM4 -> 0.51439036 | AO21: NPV NOK | AP21: =AP20*B12 -> 48913.189
C22: EBIT margin | H22: =H10/H4 -> 0.14656085 | I22: =I10/I4 -> 0.54567962 | J22: =J10/J4 -> 0.028272475 | K22: =K10/K4 -> #DIV/0! | L22: =L10/L4 -> -1.0608421 | M22: =M10/M4 -> 0.31153968 | N22: =N10/N4 -> 0.4117284 | O22: =O10/O4 -> 0.43749563 | ... T22: =T10/T4 -> 0.062239932 | Y22: =Y10/Y4 -> 0.1827103 | Z22: =Z10/Z4 -> 0.38704616 | AA22: =AA10/AA4 -> 0.1329657 | AB22: =AB10/AB4 -> 0.28275133 | AC22: =AC10/AC4 -> 0.51129032 | AD22: =AD10/AD4 -> 0.34065934 | AE22: =AE10/AE4 -> 0.41770921 | AF22: =AF10/AF4 -> 0.41853842 | ... AM22: =AM10/AM4 -> 0.42971321 | AO22: S/O | AP22: 386.05334
C23: Utilisation | P23: 0.553 | Q23: 0.67 | R23: 0.758 | T23: 0.476 | AO23: NPV/Share | AP23: =AP21/AP22 -> 126.7006
AO24: Opp- nedside | AP24: =(AP23-B4)/B4 -> 1.0111206
C25: ROE | Y25: 0.027 | Z25: 0.083 | AA25: 0.016 | AB25: 0.06
C27: Order backlog (EUR mill) | L27: 1801 | M27: 1915 | N27: 2054 | O27: 2336 | P27: 2487 | Q27: 2492 | R27: 2387 | S27: 2827 | T27: 2705
C28: y/y | P28: =(P27-L27)/L27 -> 0.3808995 | Q28: =(Q27-M27)/M27 -> 0.30130548 | R28: =(R27-N27)/N27 -> 0.16212269 | S28: =(S27-O27)/O27 -> 0.21018836 | T28: =(T27-P27)/P27 -> 0.08765581
C30: Balanse EUR million
C31: Intangible assets | G31: 0.419 | H31: 16.947 | I31: 16.947 | K31: 16.947 | L31: 17.236 | M31: 17.44 | N31: 16.72 | O31: 18.19 | P31: 18.644 | Q31: 19 | R31: 19.283 | S31: 19.432 | T31: 19.493
C32: PP&E | G32: 606.204 | H32: 1085.632 | I32: 1085.632 | K32: 1085.632 | L32: 1188.829 | M32: 1380.924 | N32: 1612.704 | O32: 1712.266 | P32: 2188.349 | Q32: 2384.551 | R32: 2626.254 | S32: 2991.129 | T32: 3016.754
C33: Right-of-use assets | G33: 0.287 | H33: 0.973 | I33: 0.973 | K33: 0.973 | L33: 11 | M33: 11.118 | N33: 10.691 | O33: 10.337 | P33: 10.639 | Q33: 11.133 | R33: 12.428 | S33: 12.598 | T33: 12
C34: Leasehold deposits | G34: 0.238 | H34: 1.22 | I34: 1.22 | K34: 1.22 | L34: 1.226 | M34: 1.047 | N34: 1.047 | O34: 1.014 | P34: 1 | Q34: 1.09 | R34: 1.144 | S34: 1.141 | T34: 1
C35: Derivative assets | G35: 3.376 | H35: 0.338 | I35: 0.338 | K35: 0.338 | L35: 1.248 | M35: 3.192 | N35: 0.695 | O35: 6.593 | P35: 2.9 | Q35: 0.919 | R35: 1.443 | S35: 2.419 | T35: 6.6
C36: Inventories | G36: 0.549 | H36: 1.836 | I36: 1.836 | K36: 1.836 | L36: 1.86 | M36: 0.947 | N36: 1.351 | O36: 1.039 | P36: 3.5 | Q36: 2.269 | R36: 2.871 | S36: 3.54 | T36: 3.784
C37: Trade reveivables | G37: 18.235 | H37: 30.552 | I37: 30.552 | K37: 30.552 | L37: 36.528 | M37: 39.681 | N37: 46.318 | O37: 62.986 | P37: 105.817 | Q37: 111.5 | R37: 127.669 | S37: 139.029 | T37: 145.529
C38: Contract assets | G38: 19.999 | H38: 8.88 | I38: 8.88 | K38: 8.88 | L38: 1.549 | M38: 18.296 | N38: 30.564 | O38: 37.609 | P38: 24 | Q38: 154.3 | R38: 29.376 | S38: 81.923 | T38: 39.891
C39: Prepayments | G39: 1.699 | H39: 9.562 | I39: 9.562 | K39: 9.562 | L39: 15.389 | M39: 21.555 | N39: 15.627 | O39: 16.643 | P39: 13.345 | Q39: 30.8 | R39: 17.4 | S39: 13.523 | T39: 13.97
C40: Current derivate assets | G40: 0 | K40: 0 | O40: 11.875 | P40: 1 | Q40: 0.721 | R40: 0.437 | S40: 0.263 | T40: 1.158
C41: Current income tax reveivables | G41: 0.012 | H41: 0.012 | I41: 0 | K41: 0.012 | L41: 0.012 | M41: 2.278 | N41: 0 | O41: 0 | P41: 1 | Q41: 0 | R41: 0 | S41: 0 | T41: 53.55
C42: Cash | G42: 19.012 | H42: 96.608 | I42: 96.6 | K42: 96.608 | L42: 209.13 | M42: 93.05 | N42: 91.854 | O42: 58.464 | P42: 94.1 | Q42: 53 | R42: 217.757 | S42: 151.679 | T42: 221.295
C43: Total assets | D43: =SUM(D31:D42) -> 0 | E43: =SUM(E31:E42) -> 0 | F43: =SUM(F31:F42) -> 0 | G43: =SUM(G31:G42) -> 670.03 | H43: =SUM(H31:H42) -> 1252.56 | I43: =SUM(I31:I42) -> 1252.54 | J43: =SUM(J31:J42) -> 0 | K43: =SUM(K31:K42) -> 1252.56 | ... T43: =SUM(T31:T42) -> 3535.024
...

Sheet Nøkkeltall
F7: 2026 | G7: 2027 | H7: 2028
E8: EV/EBITDA | F8: =Modell!$B$9/(Modell!AD8*Modell!$B$12) -> 8.8102679 | G8: =Modell!$B$9/(Modell!AE8*Modell!$B$12) -> 6.0288906 | H8: =Modell!$B$9/(Modell!AF8*Modell!$B$12) -> 5.7324153
E9: EV/EBIT | F9: =Modell!$B$9/(Modell!AD10*Modell!$B$12) -> 11.65229 | G9: =Modell!$B$9/(Modell!AE10*Modell!$B$12) -> 7.309946 | H9: =Modell!$B$9/(Modell!AF10*Modell!$B$12) -> 6.9480605
E10: P/E | F10: =Modell!$B$4/Modell!AD17 -> 8.530219 | G10: =Modell!$B$4/Modell!AE17 -> 6.3572631 | H10: =Modell!$B$4/Modell!AF17 -> 6.0163081

Sheet SOTP
B4: New building parity
B6: Vessel name | C6: Ownership | D6: Type | E6: Built | F6: Equivalent newbuild delivery | G6: Equivalent newbuild cost (EURm) | H6: NPV of equivalent newbuld capex (EURm) | I6: NPV of cashflow advantage (EURm) | J6: Total value
B7: Wind Zaratan | C7: 1 | D7: Z-class | E7: 2012 | F7: Q128 | G7: 166 | H7: 54 | I7: 56 | J7: =SUM(H7:I7) -> 110
B8: Wind Scylla | C8: 1 | D8: S-class | E8: 2015 | F8: Q428 | G8: 258 | H8: 111 | I8: 145 | J8: =SUM(H8:I8) -> 256
B9: Wind Orca | C9: 1 | D9: O-class | E9: 2013 | F9: Q428 | G9: 313 | H9: 168 | I9: 158 | J9: =SUM(H9:I9) -> 326
B10: Wind Osprey | C10: 1 | D10: O-class | E10: 2012 | F10: Q428 | G10: 313 | H10: 157 | I10: 135 | J10: =SUM(H10:I10) -> 292
B11: Wind Keeper | C11: 1 | D11: K-class | J11: 250
B12: Wind Maker | C12: 1 | D12: M-class | E12: 2025 | F12: Q129 | G12: 391 | H12: 293 | I12: 161 | J12: =SUM(H12:I12) -> 454
B13: Wind Mover | C13: 1 | D13: M-class | E13: 2025 | F13: Q129 | G13: 391 | H13: 293 | I13: 141 | J13: =SUM(H13:I13) -> 434
B14: Wind Peak | C14: 1 | D14: P-class | E14: 2024 | F14: Q129 | G14: 391 | H14: 279 | I14: 171 | J14: =SUM(H14:I14) -> 450
B15: Wind Pace | C15: 1 | D15: P-class | E15: 2025 | F15: Q129 | G15: 391 | H15: 293 | I15: 164 | J15: =SUM(H15:I15) -> 457
B16: Wind Ally | C16: 1 | D16: A-class | E16: 2025 | F16: Q129 | G16: 391 | H16: 293 | I16: 116 | J16: =SUM(H16:I16) -> 409
B17: Wind Ace | C17: 1 | D17: A-class | E17: 2026 | F17: Q129 | G17: 391 | H17: 307 | I17: 88 | J17: =SUM(H17:I17) -> 395
B18: Wind Apex | C18: 1 | D18: A-class | E18: 2027 | F18: Q129 | G18: 391 | H18: 321 | I18: 53 | J18: =SUM(H18:I18) -> 374
B19: Asset value | J19: =SUM(J7:J18) -> 4207
B20: Foundation T&I services | D20: (5,0x EV/EBITDA) | J20: 405
B21: EV | J21: =SUM(J19:J20) -> 4612
B22: Net debt (Q325) | J22: 1202.464
B23: NPV of remaning Capex (Q325) | J23: 1200
B24: Equity value | J24: =J21-J22-J23 -> 2209.536
B25: EUR/NOK | J25: 11.77
B26: # shares | J26: 350.95758
B27: Equity value/share | J27: =(J24*J25)/J26 -> 74.100803
B29: SOTP
B31: Vessel name | C31: Dayrate (EUR 000) | D31: Util. | E31: Opex/d (EUR 000) | F31: EBITDA (EURm) | G31: Multiple | H31: EV (EURm)
B32: Wind Zaratan | C32: 250 | D32: 0.75 | E32: 40 | F32: 54 | G32: 5x | H32: =F32*5 -> 270
B33: Wind Scylla | C33: 250 | D33: 0.75 | E33: 40 | F33: 54 | G33: 5x | H33: =F33*5 -> 270
B34: Wind Orca | C34: 300 | D34: 0.75 | E34: 40 | F34: 68 | G34: 5x | H34: =F34*5 -> 340
B35: Wind Osprey | C35: 300 | D35: 0.75 | E35: 40 | F35: 68 | G35: 5x | H35: =F35*5 -> 340
B36: Wind Keeper | C36: 250 | D36: 0.75 | E36: 40 | F36: 54 | G36: 5x | H36: =F36*5 -> 270
B37: Wind Maker | C37: 300 | D37: 0.75 | E37: 40 | F37: 68 | G37: 5x | H37: =F37*5 -> 340
B38: Wind Mover | C38: 300 | D38: 0.75 | E38: 40 | F38: 68 | G38: 5x | H38: =F38*5 -> 340
B39: Wind Peak | C39: 300 | D39: 0.75 | E39: 40 | F39: 68 | G39: 5x | H39: =F39*5 -> 340
B40: Wind Pace | C40: 300 | D40: 0.75 | E40: 40 | F40: 68 | G40: 5x | H40: =F40*5 -> 340
B41: Wind Ally | C41: 350 | D41: 0.75 | E41: 40 | F41: 81 | G41: 5x | H41: =F41*5 -> 405
B42: Wind Ace | C42: 350 | D42: 0.75 | E42: 40 | F42: 81 | G42: 5x | H42: =F42*5 -> 405
B43: Wind Apex | C43: 350 | D43: 0.75 | E43: 40 | F43: 81 | G43: 5x | H43: =F43*5 -> 405
B45: T&I services EBITDA | F45: 115 | G45: 5x | H45: =115*5 -> 575
B46: SG&A | F46: -70 | G46: 5x | H46: -350
B48: EV | H48: =SUM(H32:H46) -> 4290
...

Sheet Nedsidebergning
