Workbook

Sheet Info
A5: Clas har et avvikende regnskapsår som går fra 1.mai til 30. april
A7: Q1: | B7: 1. mai - 31. juli
A8: Q2 | B8: 1. august - 31. oktober
A9: Q3 | B9: 1. november - 31. januar
A10: Q4 | B10: 1. februar - 30. april
A15: Clas Ohslon rapporterer salgstall hver måned

Sheet Modell
G1: 1.feb - 30.apr | H1: 1.mai - 31.juli | I1: 1.aug - 31.okt | J1: 1.nov - 31.jan | K1: 1.feb - 30.apr | L1: 1.mai - 31.juli | M1: 1.aug - 31.okt | N1: 1.nov - 31.jan | O1: 1.feb - 30.apr | P1: 1.mai - 31.juli | Q1: 1.aug - 31.okt | R1: 1.nov - 31.jan | S1: 1.feb - 30.apr
A3: Kapitalstruktur | C3: SEK million | D3: Q122/23 | E3: Q222/23 | F3: Q322/23 | G3: Q422/23 | H3: Q123/24 | I3: Q223/24 | J3: Q323/24 | K3: Q423/24 | L3: Q124/25 | M3: Q224/25 | N3: Q324/25 | O3: Q424/25 | P3: Q125/26 | Q3: Q225/26 | R3: Q325/26 | S3: Q425/26 | V3: FY 19/20 | W3: FY 20/21 | X3: FY 21/22 | Y3: FY 22/23 | Z3: FY 23/24 | AA3: FY 24/25 | AB3: FY 25/26 | AC3: FY 26/27 | AD3: FY 27/28 | AE3: FY 28/29 | AF3: FY 29/30 | AG3: FY 30/31 | AH3: FY 31/32 | AI3: FY 32/33 | AJ3: FY 33/34 | AK3: FY 34/35 | AL3: FY 35/36
A4: Price | B4: 298.8 | C4: Revenue | D4: 2043.6 | E4: 2250.2 | F4: 2954.2 | G4: 1776.3 | H4: 2193.1 | I4: 2460.1 | J4: 3411.9 | K4: 2166.7 | L4: 2623 | M4: 2800.9 | N4: 3859.5 | O4: 2343 | P4: 2814.5 | Q4: 3009.1 | V4: 8758.3 | W4: 8284.4 | X4: 8783.7 | Y4: 9024.3 | Z4: 10232 | AA4: =SUM(L4:O4) -> 11626.4 | AB4: =AA4*1.07 -> 12440.248 | AC4: =AB4*1.05 -> 13062.26 | AD4: =AC4*1.05 -> 13715.373 | AE4: =AD4*1.05 -> 14401.142 | AF4: =AE4*1.05 -> 15121.199 | AG4: =AF4*1.05 -> 15877.259 | AH4: =AG4*1.05 -> 16671.122 | AI4: =AH4*1.05 -> 17504.678 | AJ4: =AI4*1.05 -> 18379.912 | ... AL4: =AK4*1.05 -> 20263.853
A5: S/O | B5: 65.6 | C5: COGS | D5: -1325.3 | E5: -1401.9 | F5: -1825.8 | G5: -1087.6 | H5: -1356.3 | I5: -1444.7 | J5: -2102.3 | K5: -1312.5 | L5: -1639 | M5: -1685.6 | N5: -2343.2 | O5: -1417 | P5: -1528 | Q5: -1543.7 | V5: -5268.1 | W5: -4928.6 | X5: -5178.9 | Y5: -5640.6 | Z5: -6215.9 | AA5: =SUM(L5:O5) -> -7084.8 | AB5: =AB4*-0.6 -> -7464.1488 | AC5: =AC4*-0.6 -> -7837.3562 | AD5: =AD4*-0.6 -> -8229.2241 | AE5: =AE4*-0.6 -> -8640.6853 | AF5: =AF4*-0.6 -> -9072.7195 | AG5: =AG4*-0.6 -> -9526.3555 | AH5: =AH4*-0.6 -> -10002.673 | AI5: =AI4*-0.6 -> -10502.807 | ... AL5: =AL4*-0.6 -> -12158.312
A6: MC SEKm | B6: =B4*B5 -> 19601.28 | C6: Gross profit | D6: =SUM(D4:D5) -> 718.3 | E6: =SUM(E4:E5) -> 848.3 | F6: =SUM(F4:F5) -> 1128.4 | G6: =SUM(G4:G5) -> 688.7 | H6: =SUM(H4:H5) -> 836.8 | I6: =SUM(I4:I5) -> 1015.4 | J6: =SUM(J4:J5) -> 1309.6 | K6: =SUM(K4:K5) -> 854.2 | ... S6: =SUM(S4:S5) -> 0 | V6: =SUM(V4:V5) -> 3490.2 | W6: =SUM(W4:W5) -> 3355.8 | X6: =SUM(X4:X5) -> 3604.8 | Y6: =SUM(Y4:Y5) -> 3383.7 | Z6: =SUM(Z4:Z5) -> 4016.1 | AA6: =SUM(AA4:AA5) -> 4541.6 | AB6: =SUM(AB4:AB5) -> 4976.0992 | AC6: =SUM(AC4:AC5) -> 5224.9042 | ... AL6: =SUM(AL4:AL5) -> 8105.5412
A7: Cash SEKm | B7: =Q44 -> 990.9 | C7: Selling expenses | D7: -648.8 | E7: -681 | F7: -760.4 | G7: -637.3 | H7: -652.1 | I7: -691.3 | J7: -836.6 | K7: -736.1 | L7: -730.4 | M7: -757.6 | N7: -904.3 | O7: -768.9 | P7: -566.5 | Q7: -589.5 | V7: -2720 | W7: -2547.5 | X7: -2703.9 | Y7: -2727.6 | Z7: -2916.1 | AA7: =SUM(L7:O7) -> -3161.2 | AB7: =AA7*1.08 -> -3414.096 | AC7: =AB7 -> -3414.096 | AD7: =AC7 -> -3414.096 | AE7: =AD7*1.03 -> -3516.5189 | AF7: =AE7*1.03 -> -3622.0144 | AG7: =AF7*1.03 -> -3730.6749 | AH7: =AG7*1.03 -> -3842.5951 | AI7: =AH7*1.03 -> -3957.873 | AJ7: =AI7*1.03 -> -4076.6092 | AK7: =AJ7*1.03 -> -4198.9074 | AL7: =AK7*1.03 -> -4324.8747
A8: Debt SEKm | B8: =Q51+Q54 -> 1830.7 | C8: Admin cost | D8: -44.4 | E8: -50.2 | F8: -50.6 | G8: -39.6 | H8: -46 | I8: -50.5 | J8: -50.2 | K8: -41.5 | L8: -51.1 | M8: -49.2 | N8: -56.7 | O8: -47.7 | P8: -261 | Q8: -284.8 | V8: -220.8 | W8: -195.2 | X8: -199.9 | Y8: -184.8 | Z8: -188.2 | AA8: =SUM(L8:O8) -> -204.7 | AB8: =AA8*1.05 -> -214.935 | AC8: =AB8 -> -214.935 | AD8: =AC8 -> -214.935 | AE8: =AD8*1.05 -> -225.68175 | AF8: =AE8*1.05 -> -236.96584 | AG8: =AF8*1.05 -> -248.81413 | AH8: =AG8*1.05 -> -261.25484 | AI8: =AH8*1.05 -> -274.31758 | AJ8: =AI8*1.05 -> -288.03346 | AK8: =AJ8*1.05 -> -302.43513 | AL8: =AK8*1.05 -> -317.55689
A9: EV SEKm | B9: =B6-B7+B8 -> 20441.08 | C9: Other operating income | D9: -41.2 | E9: -4.7 | F9: -102.1 | G9: 4.9 | H9: 4.3 | I9: 4.3 | J9: 4.6 | K9: 5.2 | L9: 0.1 | M9: 0 | N9: 0 | O9: 0.1 | P9: -181 | Q9: -180.5 | V9: 25.8 | W9: 7.1 | X9: 33.8 | Y9: 18.4 | Z9: 18.3 | AA9: =SUM(L9:O9) -> 0.2 | AB9: =AA9*1.1 -> 0.22 | AC9: =AB9 -> 0.22 | AD9: =AC9 -> 0.22 | AE9: =AD9*1.05 -> 0.231 | AF9: =AE9*1.05 -> 0.24255 | AG9: =AF9*1.05 -> 0.2546775 | AH9: =AG9*1.05 -> 0.26741138 | AI9: =AH9*1.05 -> 0.28078194 | AJ9: =AI9*1.05 -> 0.29482104 | AK9: =AJ9*1.05 -> 0.30956209 | AL9: =AK9*1.05 -> 0.3250402
C10: Other opex | D10: 0 | E10: 0 | F10: 0 | G10: -23.1 | H10: -158.6 | I10: -32.8 | J10: -5.5 | K10: -16.3 | L10: 0 | M10: -1.2 | N10: -2.8 | O10: -0.6 | P10: -0.1 | Q10: 0 | V10: -25.9 | W10: -12.1 | X10: -15.3 | Y10: -184.7 | Z10: -213.3 | AA10: =SUM(L10:O10) -> -4.6 | AB10: =AA10*1.1 -> -5.06 | AC10: =AB10 -> -5.06 | AD10: =AC10 -> -5.06 | AE10: =AD10*1.05 -> -5.313 | AF10: =AE10*1.05 -> -5.57865 | AG10: =AF10*1.05 -> -5.8575825 | AH10: =AG10*1.05 -> -6.1504616 | AI10: =AH10*1.05 -> -6.4579847 | AJ10: =AI10*1.05 -> -6.7808839 | AK10: =AJ10*1.05 -> -7.1199281 | AL10: =AK10*1.05 -> -7.4759245
C11: Operating profit | D11: =SUM(D6:D10) -> -16.1 | E11: =SUM(E6:E10) -> 112.4 | F11: =SUM(F6:F10) -> 215.3 | G11: =SUM(G6:G10) -> -6.4 | H11: =SUM(H6:H10) -> -15.6 | I11: =SUM(I6:I10) -> 245.1 | J11: =SUM(J6:J10) -> 421.9 | K11: =SUM(K6:K10) -> 65.5 | ... S11: =SUM(S6:S10) -> 0 | V11: =SUM(V6:V10) -> 549.3 | W11: =SUM(W6:W10) -> 608.1 | X11: =SUM(X6:X10) -> 719.5 | Y11: =SUM(Y6:Y10) -> 305 | Z11: =SUM(Z6:Z10) -> 716.8 | AA11: =SUM(AA6:AA10) -> 1171.3 | AB11: =SUM(AB6:AB10) -> 1342.2282 | AC11: =SUM(AC6:AC10) -> 1591.0332 | ... AL11: =SUM(AL6:AL10) -> 3455.9588
C12: Financial income | D12: 1 | E12: 0.7 | F12: 1.2 | G12: 0.5 | H12: 0.5 | I12: 1.2 | J12: 2.7 | K12: 1.6 | L12: 2.2 | M12: 2.1 | N12: 6.1 | O12: 5.9 | P12: 6.3 | Q12: 6 | V12: 0.1 | W12: 0.3 | X12: 2 | Y12: 3.4 | Z12: 6 | AA12: =SUM(L12:O12) -> 16.3 | AB12: 0 | AC12: 0 | AD12: 0 | AE12: 0 | AF12: 0 | AG12: 0 | AH12: 0 | AI12: 0 | AJ12: 0 | AK12: 0 | AL12: 0
C13: Financial expense | D13: -15.5 | E13: -17.5 | F13: -16.5 | G13: -16.4 | H13: -16.6 | I13: -19.6 | J13: -17.4 | K13: -16.4 | L13: -17.8 | M13: -17.2 | N13: -17.2 | O13: -17.4 | P13: -18.6 | Q13: -19.8 | V13: -67.6 | W13: -63.6 | X13: -65.1 | Y13: -65.9 | Z13: -69.9 | AA13: =SUM(L13:O13) -> -69.6 | AB13: 0 | AC13: 0 | AD13: 0 | AE13: 0 | AF13: 0 | AG13: 0 | AH13: 0 | AI13: 0 | AJ13: 0 | AK13: 0 | AL13: 0
C14: PTP | D14: =SUM(D11:D13) -> -30.6 | E14: =SUM(E11:E13) -> 95.6 | F14: =SUM(F11:F13) -> 200 | G14: =SUM(G11:G13) -> -22.3 | H14: =SUM(H11:H13) -> -31.7 | I14: =SUM(I11:I13) -> 226.7 | J14: =SUM(J11:J13) -> 407.2 | K14: =SUM(K11:K13) -> 50.7 | ... S14: =SUM(S11:S13) -> 0 | V14: =SUM(V11:V13) -> 481.8 | W14: =SUM(W11:W13) -> 544.8 | X14: =SUM(X11:X13) -> 656.4 | Y14: =SUM(Y11:Y13) -> 242.5 | Z14: =SUM(Z11:Z13) -> 652.9 | AA14: =SUM(AA11:AA13) -> 1118 | AB14: =SUM(AB11:AB13) -> 1342.2282 | AC14: =SUM(AC11:AC13) -> 1591.0332 | ... AL14: =SUM(AL11:AL13) -> 3455.9588
C15: Tax | D15: 6.5 | E15: -26.1 | F15: -41.5 | G15: -0.7 | H15: 5.2 | I15: -53.4 | J15: -86.2 | K15: -16.4 | L15: -41.3 | M15: -62.1 | N15: -115.1 | O15: -17.2 | P15: -57.6 | Q15: -88.1 | V15: -105.8 | W15: -123.6 | X15: -133.9 | Y15: -61.8 | Z15: -144.2 | AA15: =SUM(L15:O15) -> -235.7 | AB15: =AB14*-0.22 -> -295.2902 | AC15: =AC14*-0.22 -> -350.0273 | AD15: =AD14*-0.22 -> -407.50124 | AE15: =AE14*-0.22 -> -442.89833 | AF15: =AF14*-0.22 -> -480.51592 | AG15: =AG14*-0.22 -> -520.47858 | AH15: =AH14*-0.22 -> -562.91748 | AI15: =AI14*-0.22 -> -607.97078 | ... AL15: =AL14*-0.22 -> -760.31094
C16: Net income | D16: =SUM(D14:D15) -> -24.1 | E16: =SUM(E14:E15) -> 69.5 | F16: =SUM(F14:F15) -> 158.5 | G16: =SUM(G14:G15) -> -23 | H16: =SUM(H14:H15) -> -26.5 | I16: =SUM(I14:I15) -> 173.3 | J16: =SUM(J14:J15) -> 321 | K16: =SUM(K14:K15) -> 34.3 | ... S16: =SUM(S14:S15) -> 0 | V16: =SUM(V14:V15) -> 376 | W16: =SUM(W14:W15) -> 421.2 | X16: =SUM(X14:X15) -> 522.5 | Y16: =SUM(Y14:Y15) -> 180.7 | Z16: =SUM(Z14:Z15) -> 508.7 | AA16: =SUM(AA14:AA15) -> 882.3 | AB16: =SUM(AB14:AB15) -> 1046.938 | AC16: =SUM(AC14:AC15) -> 1241.0059 | ... AL16: =SUM(AL14:AL15) -> 2695.6479 | AM16: =AL16*(1+$AO$20) -> 2668.6914 | AN16: =AM16*(1+$AO$20) -> 2642.0045 | AO16: =AN16*(1+$AO$20) -> 2615.5844 | AP16: =AO16*(1+$AO$20) -> 2589.4286 | AQ16: =AP16*(1+$AO$20) -> 2563.5343 | AR16: =AQ16*(1+$AO$20) -> 2537.899 | AS16: =AR16*(1+$AO$20) -> 2512.52 | AT16: =AS16*(1+$AO$20) -> 2487.3948 | ... EC16: =EB16*(1+$AO$20) -> 1037.5443
C17: Shares | D17: 65.6 | E17: 65.6 | F17: 65.6 | G17: 65.6 | H17: 65.6 | I17: 65.6 | J17: 65.6 | K17: 65.6 | L17: 65.6 | M17: 65.6 | N17: 65.6 | O17: 65.6 | P17: 65.6 | Q17: 65.6 | R17: 65.6 | S17: 65.6 | V17: 65.6 | W17: 65.6 | X17: 65.6 | Y17: 65.6 | Z17: 65.6 | AA17: 65.6 | AB17: 65.6 | AC17: 65.6 | AD17: 65.6 | AE17: 65.6 | AF17: 65.6 | AG17: 65.6 | AH17: 65.6 | AI17: 65.6 | AJ17: 65.6 | AK17: 65.6 | AL17: 65.6
C18: EPS | D18: =D16/D17 -> -0.36737805 | E18: =E16/E17 -> 1.0594512 | F18: =F16/F17 -> 2.4161585 | G18: =G16/G17 -> -0.35060976 | H18: =H16/H17 -> -0.40396341 | I18: =I16/I17 -> 2.6417683 | J18: =J16/J17 -> 4.8932927 | K18: =K16/K17 -> 0.52286585 | ... S18: =S16/S17 -> 0 | V18: =V16/V17 -> 5.7317073 | W18: =W16/W17 -> 6.4207317 | X18: =X16/X17 -> 7.964939 | Y18: =Y16/Y17 -> 2.7545732 | Z18: =Z16/Z17 -> 7.7545732 | AA18: =AA16/AA17 -> 13.449695 | AB18: =AB16/AB17 -> 15.959421 | AC18: =AC16/AC17 -> 18.917772 | ... AL18: =AL16/AL17 -> 41.092193
AN19: Discount | AO19: 0.08
C20: Revenue y/y | H20: =(H4-D4)/D4 -> 0.073155216 | I20: =(I4-E4)/E4 -> 0.093280597 | J20: =(J4-F4)/F4 -> 0.15493196 | K20: =(K4-G4)/G4 -> 0.21978269 | L20: =(L4-H4)/H4 -> 0.19602389 | M20: =(M4-I4)/I4 -> 0.13853095 | N20: =(N4-J4)/J4 -> 0.1311879 | O20: =(O4-K4)/K4 -> 0.081367979 | ... S20: =(S4-O4)/O4 -> -1 | W20: =(W4-V4)/V4 -> -0.054108674 | X20: =(X4-W4)/W4 -> 0.060269905 | Y20: =(Y4-X4)/X4 -> 0.027391646 | Z20: =(Z4-Y4)/Y4 -> 0.13382755 | AA20: =(AA4-Z4)/Z4 -> 0.13627834 | AB20: =(AB4-AA4)/AA4 -> 0.07 | AC20: =(AC4-AB4)/AB4 -> 0.05 | AD20: =(AD4-AC4)/AC4 -> 0.05 | ... AL20: =(AL4-AK4)/AK4 -> 0.05 | AN20: TV | AO20: -0.01
C21: Organic growth | P21: 0.1 | Q21: 0.09 | AN21: NPV | AO21: =NPV(AO19,AB16:EC16) -> 25179.398
C22: Gross margin | D22: =D6/D4 -> 0.35148757 | E22: =E6/E4 -> 0.37698871 | F22: =F6/F4 -> 0.38196466 | G22: =G6/G4 -> 0.38771604 | H22: =H6/H4 -> 0.38156035 | I22: =I6/I4 -> 0.41274745 | J22: =J6/J4 -> 0.38383305 | K22: =K6/K4 -> 0.39424009 | ... S22: =S6/S4 -> #DIV/0! | V22: =V6/V4 -> 0.39850199 | W22: =W6/W4 -> 0.4050746 | X22: =X6/X4 -> 0.41039653 | Y22: =Y6/Y4 -> 0.37495429 | Z22: =Z6/Z4 -> 0.39250391 | AA22: =AA6/AA4 -> 0.39062823 | AB22: =AB6/AB4 -> 0.4 | AC22: =AC6/AC4 -> 0.4 | ... AL22: =AL6/AL4 -> 0.4 | AN22: S/O | AO22: 65.6
C23: EBIT margin | D23: =(D11/D4) -> -0.0078782541 | E23: =(E11/E4) -> 0.049951115 | F23: =(F11/F4) -> 0.072879291 | G23: =(G11/G4) -> -0.003602995 | H23: =(H11/H4) -> -0.0071132187 | I23: =(I11/I4) -> 0.099630096 | J23: =(J11/J4) -> 0.12365544 | K23: =(K11/K4) -> 0.030230304 | ... S23: =(S11/S4) -> #DIV/0! | V23: =V11/V4 -> 0.062717651 | W23: =W11/W4 -> 0.073403023 | X23: =X11/X4 -> 0.081913089 | Y23: =Y11/Y4 -> 0.033797635 | Z23: =Z11/Z4 -> 0.07005473 | AA23: =AA11/AA4 -> 0.10074486 | AB23: =AB11/AB4 -> 0.10789401 | AC23: =AC11/AC4 -> 0.12180382 | ... AL23: =AL11/AL4 -> 0.17054796 | AN23: NPV/Share | AO23: =AO21/AO22 -> 383.83228
C24: ROE | V24: 0.214 | W24: 0.21 | X24: 0.233 | Y24: 0.106 | Z24: 0.315 | AA24: 0.41 | AN24: Opp/nedside | AO24: =(AO23-B4)/B4 -> 0.28457926
C25: Number of stores | H25: 221 | I25: 221 | J25: 224 | L25: 233 | M25: 237 | N25: 238 | O25: 241 | P25: 241 | Q25: 244
C26: Number if club clas members (m) | G26: 5 | H26: 5.1 | I26: 5.2 | J26: 5.4 | K26: 5.4 | L26: 5.5 | M26: 5.6 | N26: 5.8 | O26: 5.9 | P26: 5.9 | Q26: 6
C28: Balanse SEKm
C29: Goodwill | G29: 0 | H29: 0 | I29: 0 | J29: 400.4 | K29: 400.4 | L29: 400.4 | M29: 405.4 | N29: 405.4 | O29: 405.4 | P29: 405.4 | Q29: 405
C30: Trademarks | G30: 0 | H30: 0 | I30: 0 | J30: 34.4 | K30: 32.6 | L30: 30.8 | M30: 28.9 | N30: 27.1 | O30: 25.4 | P30: 23.5 | Q30: 21.7
C31: Customer relationships | G31: 0 | H31: 0 | I31: 0 | J31: 24.2 | K31: 22.6 | L31: 21 | M31: 19.3 | N31: 17.7 | O31: 16.1 | P31: 14.4 | Q31: 12.8
C32: IT and software costs | G32: 307.5 | H32: 138 | I32: 120.9 | J32: 110 | K32: 89.7 | L32: 82 | M32: 75.1 | N32: 71.6 | O32: 75.6 | P32: 79.8 | Q32: 90.4
C33: Land and buildings | G33: 248.3 | H33: 241.5 | I33: 234.8 | J33: 230.1 | K33: 223 | L33: 216.4 | M33: 209.9 | N33: 203.8 | O33: 197.7 | P33: 191.6 | Q33: 185.5
C34: Equipment, tools, fixtures and fittings | G34: 413.7 | H34: 409.5 | I34: 401.2 | J34: 394.6 | K34: 417.7 | L34: 417.3 | M34: 423.2 | N34: 412.9 | O34: 414.5 | P34: 412.9 | Q34: 414.8
C35: Right-of-use assets | G35: 1553.6 | H35: 1644.7 | I35: 1763.3 | J35: 1771.4 | K35: 1784.1 | L35: 1685.5 | M35: 1605.1 | N35: 1764.1 | O35: 1670.5 | P35: 1707.2 | Q35: 1656.3
C36: Securities held as fixed assets | G36: 9.5 | H36: 9.5 | I36: 6.3 | J36: 6.3 | K36: 6.3 | L36: 2.3 | M36: 0 | N36: 0 | O36: 0 | P36: 0 | Q36: 0
C37: Deferred tax assets | G37: 71.3 | H37: 74.5 | I37: 80 | J37: 74.7 | K37: 73.1 | L37: 72.1 | M37: 75.3 | N37: 70.5 | O37: 75 | P37: 73.6 | Q37: 75.8
C38: other non-current receivables | G38: 15.6 | H38: 12.3 | I38: 8.8 | J38: 5.4 | K38: 1.9 | L38: 0.8 | M38: 0.8 | N38: 0.8 | O38: 0.7 | P38: 118.6 | Q38: 113
C39: Inventories | G39: 2177.1 | H39: 2221.3 | I39: 2614 | J39: 2303.1 | K39: 2448.3 | L39: 2606 | M39: 2868.9 | N39: 2323.7 | O39: 2414.5 | P39: 2508.4 | Q39: 2865.9
C40: Accounts receivable | G40: 51.1 | H40: 41.5 | I40: 69.3 | J40: 103 | K40: 69.2 | L40: 40.3 | M40: 85.2 | N40: 115.6 | O40: 67.7 | P40: 46.5 | Q40: 67.7
... C44: Cash | G44: 143.1 | H44: 108.9 | I44: 117.7 | J44: 475.3 | K44: 170.7 | L44: 417.4 | M44: 211.3 | N44: 1252 | O44: 1010.7 | P44: 1317.5 | Q44: 990.9
C45: Total assets | D45: =SUM(D29:D44) -> 0 | E45: =SUM(E29:E44) -> 0 | F45: =SUM(F29:F44) -> 0 | G45: =SUM(G29:G44) -> 5109.8 | H45: =SUM(H29:H44) -> 5028.4 | I45: =SUM(I29:I44) -> 5564.2 | J45: =SUM(J29:J44) -> 6023.5 | K45: =SUM(K29:K44) -> 5850.6 | ... S45: =SUM(S29:S44) -> 0
...

Sheet Segementer
C4: 1.mai - 31.juli | D4: 1.aug - 31.okt | E4: 1.nov - 31.jan | F4: 1.feb - 30.apr | H4: 1.mai - 31.juli | I4: 1.aug - 31.okt | J4: 1.nov - 31.jan | K4: 1.feb - 30.apr | M4: 1.mai - 31.juli | N4: 1.aug - 31.okt | O4: 1.nov - 31.jan | P4: 1.feb - 30.apr | R4: 1.mai - 31.juli | S4: 1.aug - 31.okt | T4: 1.nov - 31.jan | U4: 1.feb - 30.apr
B6: SEK million | C6: Q122 | D6: Q222 | E6: Q322 | F6: Q422 | G6: FY 22/23 | H6: Q123 | I6: Q223 | J6: Q323 | K6: Q423 | L6: FY 23/24 | M6: Q124 | N6: Q224 | O6: Q324 | P6: Q424 | Q6: FY 24/25 | R6: Q125 | S6: Q225 | T6: Q325 | U6: Q425 | V6: FY 25/26
B7: Sweden
B8: Revenues | C8: 930.4 | D8: 1010.7 | E8: 1299.9 | F8: 846.8 | G8: =SUM(C8:F8) -> 4087.8 | H8: 1013.8 | I8: 1102 | J8: 1483.1 | K8: 947.5 | L8: =SUM(H8:K8) -> 4546.4 | M8: 1142 | N8: 1219.4 | O8: 1693.5 | P8: 1034 | Q8: =SUM(M8:P8) -> 5088.9 | R8: 1320 | S8: 1410 | V8: =SUM(R8:U8) -> 2730
B9: Growth % | H9: =(H8-C8)/C8 -> 0.089638865 | I9: =(I8-D8)/D8 -> 0.090333432 | J9: =(J8-E8)/E8 -> 0.14093392 | K9: =(K8-F8)/F8 -> 0.11891828 | L9: =(L8-G8)/G8 -> 0.11218748 | M9: =(M8-H8)/H8 -> 0.12645492 | N9: =(N8-I8)/I8 -> 0.10653358 | O9: =(O8-J8)/J8 -> 0.14186501 | ... V9: =(V8-Q8)/Q8 -> -0.46353829
B10: Norway
B11: Revenues | C11: 870.2 | D11: 973.2 | E11: 1318 | F11: 728.3 | G11: =SUM(C11:F11) -> 3889.7 | H11: 933.6 | I11: 1055.7 | J11: 1384.6 | K11: 833.1 | L11: =SUM(H11:K11) -> 4207 | M11: 1018 | N11: 1067.8 | O11: 1571.8 | P11: 898.2 | Q11: =SUM(M11:P11) -> 4555.8 | R11: 1163 | S11: 1214 | V11: =SUM(R11:U11) -> 2377
B12: Growth % | H12: =(H11-C11)/C11 -> 0.072856815 | I12: =(I11-D11)/D11 -> 0.084771887 | J12: =(J11-E11)/E11 -> 0.050531108 | K12: =(K11-F11)/F11 -> 0.14389675 | L12: =(L11-G11)/G11 -> 0.081574414 | M12: =(M11-H11)/H11 -> 0.090402742 | N12: =(N11-I11)/I11 -> 0.011461589 | O12: =(O11-J11)/J11 -> 0.1352015 | ... V12: =(V11-Q11)/Q11 -> -0.47824751
B13: Finland
B14: Revenues | C14: 231 | D14: 266.7 | E14: 336.2 | F14: 201.2 | G14: =SUM(C14:F14) -> 1035.1 | H14: 245.7 | I14: 302.5 | J14: 365.5 | K14: 217.6 | L14: =SUM(H14:K14) -> 1131.3 | M14: 253.2 | N14: 302.7 | O14: 389.8 | P14: 217 | Q14: =SUM(M14:P14) -> 1162.7 | R14: 259 | S14: 309 | V14: =SUM(R14:U14) -> 568
B15: Growth % | H15: =(H14-C14)/C14 -> 0.063636364 | I15: =(I14-D14)/D14 -> 0.13423322 | J15: =(J14-E14)/E14 -> 0.087150506 | K15: =(K14-F14)/F14 -> 0.081510934 | L15: =(L14-G14)/G14 -> 0.09293788 | M15: =(M14-H14)/H14 -> 0.030525031 | N15: =(N14-I14)/I14 -> 0.00066115702 | O15: =(O14-J14)/J14 -> 0.066484268 | ... V15: =(V14-Q14)/Q14 -> -0.5114819

Sheet Nøkkeltall
D4: 25/26 | E4: 26/27 | F4: 27/28
C5: EV/EBIT | D5: =Modell!$B$9/Modell!AB11 -> 15.229214 | E5: =Modell!$B$9/Modell!AC11 -> 12.847677 | F5: =Modell!$B$9/Modell!AD11 -> 11.035641
C6: P/E | D6: =Modell!$B$4/Modell!AB18 -> 18.722484 | E6: =Modell!$B$4/Modell!AC18 -> 15.794672 | F6: =Modell!$B$4/Modell!AD18 -> 13.566992

Sheet Nedsideberegning
D3: FY 19/20 | E3: FY 20/21 | F3: FY 21/22 | G3: FY 22/23 | H3: FY 23/24 | I3: FY 24/25 | J3: FY 25/26 | K3: FY 26/27 | L3: FY 27/28 | M3: FY 28/29 | N3: FY 29/30 | O3: FY 30/31 | P3: FY 31/32 | Q3: FY 32/33 | R3: FY 33/34 | S3: FY 34/35 | T3: FY 35/36
A4: Nullvekst konstante marginer | C4: Revenue | D4: 8758.3 | E4: 8284.4 | F4: 8783.7 | G4: 9024.3 | H4: 10232 | I4: 11626 | J4: =I4*1.07 -> 12439.82 | K4: =J4*1 -> 12439.82 | L4: =K4*1 -> 12439.82 | M4: =L4*1 -> 12439.82 | N4: =M4*1 -> 12439.82 | O4: =N4*1 -> 12439.82 | P4: =O4*1 -> 12439.82 | Q4: =P4*1 -> 12439.82 | R4: =Q4*1 -> 12439.82 | ... T4: =S4*1 -> 12439.82
A5: =W23 -> 189.06714 | C5: COGS | D5: -5268.1 | E5: -4928.6 | F5: -5178.9 | G5: -5640.6 | H5: -6215.9 | I5: -7085 | J5: =J4*-0.6 -> -7463.892 | K5: =K4*-0.6 -> -7463.892 | L5: =L4*-0.6 -> -7463.892 | M5: =M4*-0.6 -> -7463.892 | N5: =N4*-0.6 -> -7463.892 | O5: =O4*-0.6 -> -7463.892 | P5: =P4*-0.6 -> -7463.892 | Q5: =Q4*-0.6 -> -7463.892 | ... T5: =T4*-0.6 -> -7463.892
A6: =W24 -> -0.36724518 | C6: Gross profit | D6: =SUM(D4:D5) -> 3490.2 | E6: =SUM(E4:E5) -> 3355.8 | F6: =SUM(F4:F5) -> 3604.8 | G6: =SUM(G4:G5) -> 3383.7 | H6: =SUM(H4:H5) -> 4016.1 | I6: =SUM(I4:I5) -> 4541 | J6: =SUM(J4:J5) -> 4975.928 | K6: =SUM(K4:K5) -> 4975.928 | ... T6: =SUM(T4:T5) -> 4975.928
C7: Selling expenses | D7: -2720 | E7: -2547.5 | F7: -2703.9 | G7: -2727.6 | H7: -2916.1 | I7: -3161 | J7: =I7*1.08 -> -3413.88 | K7: =J7 -> -3413.88 | L7: =K7 -> -3413.88 | M7: =L7*1 -> -3413.88 | N7: =M7*1 -> -3413.88 | O7: =N7*1 -> -3413.88 | P7: =O7*1 -> -3413.88 | Q7: =P7*1 -> -3413.88 | R7: =Q7*1 -> -3413.88 | S7: =R7*1 -> -3413.88 | T7: =S7*1 -> -3413.88
C8: Admin cost | D8: -220.8 | E8: -195.2 | F8: -199.9 | G8: -184.8 | H8: -188.2 | I8: -205 | J8: =I8*1.05 -> -215.25 | K8: =J8 -> -215.25 | L8: =K8 -> -215.25 | M8: =L8*1 -> -215.25 | N8: =M8*1 -> -215.25 | O8: =N8*1 -> -215.25 | P8: =O8*1 -> -215.25 | Q8: =P8*1 -> -215.25 | R8: =Q8*1 -> -215.25 | S8: =R8*1 -> -215.25 | T8: =S8*1 -> -215.25
C9: Other operating income | D9: 25.8 | E9: 7.1 | F9: 33.8 | G9: 18.4 | H9: 18.3 | I9: 0 | J9: =I9*1.1 -> 0 | K9: =J9 -> 0 | L9: =K9 -> 0 | M9: =L9*1 -> 0 | N9: =M9*1 -> 0 | O9: =N9*1 -> 0 | P9: =O9*1 -> 0 | Q9: =P9*1 -> 0 | R9: =Q9*1 -> 0 | S9: =R9*1 -> 0 | T9: =S9*1 -> 0
C10: Other opex | D10: -25.9 | E10: -12.1 | F10: -15.3 | G10: -184.7 | H10: -213.3 | I10: -5 | J10: =I10*1.1 -> -5.5 | K10: =J10 -> -5.5 | L10: =K10 -> -5.5 | M10: =L10*1 -> -5.5 | N10: =M10*1 -> -5.5 | O10: =N10*1 -> -5.5 | P10: =O10*1 -> -5.5 | Q10: =P10*1 -> -5.5 | R10: =Q10*1 -> -5.5 | S10: =R10*1 -> -5.5 | T10: =S10*1 -> -5.5
C11: Operating profit | D11: =SUM(D6:D10) -> 549.3 | E11: =SUM(E6:E10) -> 608.1 | F11: =SUM(F6:F10) -> 719.5 | G11: =SUM(G6:G10) -> 305 | H11: =SUM(H6:H10) -> 716.8 | I11: =SUM(I6:I10) -> 1170 | J11: =SUM(J6:J10) -> 1341.298 | K11: =SUM(K6:K10) -> 1341.298 | ... T11: =SUM(T6:T10) -> 1341.298
C12: Financial income | D12: 0.1 | E12: 0.3 | F12: 2 | G12: 3.4 | H12: 6 | I12: 16 | J12: 0 | K12: 0 | L12: 0 | M12: 0 | N12: 0 | O12: 0 | P12: 0 | Q12: 0 | R12: 0 | S12: 0 | T12: 0
C13: Financial expense | D13: -67.6 | E13: -63.6 | F13: -65.1 | G13: -65.9 | H13: -69.9 | I13: -70 | J13: 0 | K13: 0 | L13: 0 | M13: 0 | N13: 0 | O13: 0 | P13: 0 | Q13: 0 | R13: 0 | S13: 0 | T13: 0
C14: PTP | D14: =SUM(D11:D13) -> 481.8 | E14: =SUM(E11:E13) -> 544.8 | F14: =SUM(F11:F13) -> 656.4 | G14: =SUM(G11:G13) -> 242.5 | H14: =SUM(H11:H13) -> 652.9 | I14: =SUM(I11:I13) -> 1116 | J14: =SUM(J11:J13) -> 1341.298 | K14: =SUM(K11:K13) -> 1341.298 | ... T14: =SUM(T11:T13) -> 1341.298
C15: Tax | D15: -105.8 | E15: -123.6 | F15: -133.9 | G15: -61.8 | H15: -144.2 | I15: -236 | J15: =J14*-0.22 -> -295.08556 | K15: =K14*-0.22 -> -295.08556 | L15: =L14*-0.22 -> -295.08556 | M15: =M14*-0.22 -> -295.08556 | N15: =N14*-0.22 -> -295.08556 | O15: =O14*-0.22 -> -295.08556 | P15: =P14*-0.22 -> -295.08556 | Q15: =Q14*-0.22 -> -295.08556 | ... T15: =T14*-0.22 -> -295.08556
C16: Net income | D16: =SUM(D14:D15) -> 376 | E16: =SUM(E14:E15) -> 421.2 | F16: =SUM(F14:F15) -> 522.5 | G16: =SUM(G14:G15) -> 180.7 | H16: =SUM(H14:H15) -> 508.7 | I16: =SUM(I14:I15) -> 880 | J16: =SUM(J14:J15) -> 1046.2124 | K16: =SUM(K14:K15) -> 1046.2124 | ... T16: =SUM(T14:T15) -> 1046.2124 | U16: =T16*(1+$W$20) -> 1035.7503 | V16: =U16*(1+$W$20) -> 1025.3928 | W16: =V16*(1+$W$20) -> 1015.1389 | X16: =W16*(1+$W$20) -> 1004.9875 | Y16: =X16*(1+$W$20) -> 994.93762 | Z16: =Y16*(1+$W$20) -> 984.98824 | AA16: =Z16*(1+$W$20) -> 975.13836 | AB16: =AA16*(1+$W$20) -> 965.38698 | ... DG16: =DF16*(1+$W$20) -> 419.20127
C17: Shares | D17: 65.6 | E17: 65.6 | F17: 65.6 | G17: 65.6 | H17: 65.6 | I17: 65.6 | J17: 65.6 | K17: 65.6 | L17: 65.6 | M17: 65.6 | N17: 65.6 | O17: 65.6 | P17: 65.6 | Q17: 65.6 | R17: 65.6 | S17: 65.6 | T17: 65.6
C18: EPS | D18: =D16/D17 -> 5.7317073 | E18: =E16/E17 -> 6.4207317 | F18: =F16/F17 -> 7.964939 | G18: =G16/G17 -> 2.7545732 | H18: =H16/H17 -> 7.7545732 | I18: =I16/I17 -> 13.414634 | J18: =J16/J17 -> 15.94836 | K18: =K16/K17 -> 15.94836 | ... T18: =T16/T17 -> 15.94836
V19: Discount | W19: 0.08
C20: Revenue y/y | E20: =(E4-D4)/D4 -> -0.054108674 | F20: =(F4-E4)/E4 -> 0.060269905 | G20: =(G4-F4)/F4 -> 0.027391646 | H20: =(H4-G4)/G4 -> 0.13382755 | I20: =(I4-H4)/H4 -> 0.13623925 | J20: =(J4-I4)/I4 -> 0.07 | K20: =(K4-J4)/J4 -> 0 | L20: =(L4-K4)/K4 -> 0 | ... T20: =(T4-S4)/S4 -> 0 | V20: TV | W20: -0.01
C21: Organic growth | V21: NPV | W21: =NPV(W19,J16:DG16) -> 12402.804
C22: Gross margin | D22: =D6/D4 -> 0.39850199 | E22: =E6/E4 -> 0.4050746 | F22: =F6/F4 -> 0.41039653 | G22: =G6/G4 -> 0.37495429 | H22: =H6/H4 -> 0.39250391 | I22: =I6/I4 -> 0.39059006 | J22: =J6/J4 -> 0.4 | K22: =K6/K4 -> 0.4 | ... T22: =T6/T4 -> 0.4 | V22: S/O | W22: 65.6
C23: EBIT margin | D23: =D11/D4 -> 0.062717651 | E23: =E11/E4 -> 0.073403023 | F23: =F11/F4 -> 0.081913089 | G23: =G11/G4 -> 0.033797635 | H23: =H11/H4 -> 0.07005473 | I23: =I11/I4 -> 0.1006365 | J23: =J11/J4 -> 0.10782294 | K23: =K11/K4 -> 0.10782294 | ... T23: =T11/T4 -> 0.10782294 | V23: NPV/Share | W23: =W21/W22 -> 189.06714
V24: Opp/nedside | W24: =(W23-Modell!B4)/Modell!B4 -> -0.36724518
