Workbook

Sheet Info
T2: Radiation therapy | U2: Handler om ekstern strålebehandling der en linac leverer presiuse stråledoser mot svulster
T3: Linac=Maskinen som strålebehandler
T5: Maskiner
A15: Elekta utvikler og leverer avansert utstyr, prgramvare og tjenester for presisjonsbasert behandling av kreft og hjernesykdommer
A16: Kjernen i virksomheten er strålebehanlding (Radiation therapy), stereotaktisk radiosurgery og tilhørende onkologisk programvare, | T16: MR-bilder i sanntid mens pasienten | W16: CT-basert strålebehandling som tar | AA16: Designet for høy dose strålebehandling, | AF16: Designet for standard behandling, | AK16: Allrounder for Elekta, fleksibel CT-styrt
A17: som gjør det mulig for sykehus å planlegge, tilpasse og gjennomføre behandling med høy presisjon og minst mulig skade på friskt vev | T17: ligger på bordet. | W17: i bruk AI-støttet bildebehandling for | AA17: særlig enget for komplekse kreftbehandlinger | AF17: vært Elektas kjerneprodukt gjennom årene | AK17: som kurerer de fleste standard og avanserte
A18: Elekta selger både store kapitalvarer (Maskiner/systemer) og langsiktige service- og prgramvareløsninger, og kundene er primært sykehus, lreftentre og spesialiserte klinikker | T18: Mulighet for adaptiv strålebehandling: | W18: å forbedre planlegging og gjennomføring | AA18: som krever stereotaktiske teknikker (SRS/SRBT) | AK18: krefttypene
T19: Planen kan justeres samme dag hvis
T20: svulsten eller organene har flyttet seg
T22: Stereotactic radiosurgery | U22: Form for ekstremt presis strålebehandling der en svært høy stråledose leveres til et lite, nøyaktig definert mål. Ofte i en eller få behandlinger
A28: Press releases:
A29: 16.01.26: Elekta fåpr godkjenning fra FDA for Elekta EVO
A30: 08.09.25: Elekta gjør endringer i ledelsen, Klara Eiritz blir ny CFO, tidligere CFO, COO og CPO vil forlate Elekta. Det vil ikke bli ansatt en ny COO, men en ny CPO vil de jobbe med å finne
A31: 09.06.25: Elekta utnevner Jakob Just-Blomholt som ny CEO
A32: 21.02.25: Med sin Q3 rapport nedjusterer Elekta sine EBIT-marginer for fiscal 24/25 grunnet svakere i Kina og USA
T34: Avansert Gamma Knife-system for
T35: som leverer ekstremt nøyaktig
T36: stråledoser for behandling av
T37: hjernesvulster og andre intrakraniale
T38: mål, men mål om å bevare friskt vev
T39: og høy pasientkomfort
T41: Oncology software | U41: Programvare som knytter sammen hele strålebehandlingsprosessen. Fra planlegging og beslutning, til gjennomføring, og oppfølging. "Digitale limet"
T43: Brachytherapy | U43: Intern strålebehandling der en radioaktiv kilde plasseres direkte i eller nær svulsten for å gi svært høy lokal dose
T45: Neurosurgery | U45: Behandling av hjernesykdommer ved hjelp av ekstremt presis stereokatisk stråling, der gamma Knife-systemet er kjernen i tilbudet

Sheet Modell
D2: mai-juli | E2: aug-okt | F2: nov-jan | G2: feb-apr | H2: mai-juli | I2: aug-okt | J2: nov-jan | K2: feb-apr | L2: mai-juli | M2: aug-okt | N2: nov-jan | O2: feb-apr | P2: mai-juli | Q2: aug-okt | R2: nov-jan | S2: feb-apr
A3: Kapitalstruktur | C3: SEKm | D3: Q1 22/23 | E3: Q2 22/23 | F3: Q3 22/23 | G3: Q4 22/23 | H3: Q1 23/24 | I3: Q2 23/24 | J3: Q3 23/24 | K3: Q4 23/24 | L3: Q1 24/25 | M3: Q2 24/25 | N3: Q3 24/25 | O3: Q4 24/25 | P3: Q1 25/26 | Q3: Q2 25/26 | R3: Q3 25/26 | S3: Q4 25/26 | V3: FY 15/16 | W3: FY 16/17 | X3: FY 17/18 | Y3: FY 18/19 | Z3: FY 19/20 | AA3: FY 20/21 | AB3: FY 21/22 | AC3: FY 22/23 | AD3: FY 23/24 | AE3: FY 24/25 | AF3: FY 25/26 | AG3: FY 26/27 | AH3: FY 27/28 | AI3: FY 28/29 | AJ3: FY 29/30 | AK3: FY 30/31 | AL3: FY 31/32 | AM3: FY 32/33 | AN3: FY 33/34 | AO3: FY 34/35 | AP3: FY 35/36
A4: Price | B4: 64 | C4: Revenue | D4: 3327 | E4: 4081 | F4: 4337 | G4: 5125 | H4: 3828 | I4: 4732 | J4: 4537 | K4: 5023 | L4: 3825 | M4: 4341 | N4: 4695 | O4: 5156 | P4: 3646 | Q4: 4070 | V4: 11221 | W4: 10704 | X4: 11573 | Y4: 13555 | Z4: 14601 | AA4: 13763 | AB4: 14548 | AC4: 16869 | AD4: 18119 | AE4: 18016 | AF4: =AE4*1.02 -> 18376.32 | AG4: =AF4*1.05 -> 19295.136 | AH4: =AG4*1.05 -> 20259.893 | AI4: =AH4*1.05 -> 21272.887 | AJ4: =AI4*1.05 -> 22336.532 | AK4: =AJ4*1.05 -> 23453.358 | AL4: =AK4*1.05 -> 24626.026 | AM4: =AL4*1.05 -> 25857.328 | AN4: =AM4*1.05 -> 27150.194 | ... AP4: =AO4*1.05 -> 29933.089
A5: S/O | B5: 382.083 | C5: COGS | D5: -2039 | E5: -2602 | F5: -2686 | G5: -3194 | H5: -2238 | I5: -3037 | J5: -2873 | K5: -3194 | L5: -2408 | M5: -2798 | N5: -2961 | O5: -3102 | P5: -2305 | Q5: -2532 | V5: -6608 | W5: -6277 | X5: -6517 | Y5: -7875 | Z5: -8464 | AA5: -8153 | AB5: -9111 | AC5: -10520 | AD5: -11342 | AE5: -11270 | AF5: =AF4*-0.63 -> -11577.082 | AG5: =AG4*-0.61 -> -11770.033 | AH5: =AH4*-0.6 -> -12155.936 | AI5: =AI4*-0.6 -> -12763.732 | AJ5: =AJ4*-0.6 -> -13401.919 | AK5: =AK4*-0.6 -> -14072.015 | AL5: =AL4*-0.6 -> -14775.616 | AM5: =AM4*-0.6 -> -15514.397 | AN5: =AN4*-0.6 -> -16290.116 | AO5: =AO4*-0.6 -> -17104.622 | AP5: =AP4*-0.6 -> -17959.853
A6: MC SEKm | B6: =B4*B5 -> 24453.312 | C6: Gross profit | D6: =SUM(D4:D5) -> 1288 | E6: =SUM(E4:E5) -> 1479 | F6: =SUM(F4:F5) -> 1651 | G6: =SUM(G4:G5) -> 1931 | H6: =SUM(H4:H5) -> 1590 | I6: =SUM(I4:I5) -> 1695 | J6: =SUM(J4:J5) -> 1664 | K6: =SUM(K4:K5) -> 1829 | ... S6: =SUM(S4:S5) -> 0 | V6: =SUM(V4:V5) -> 4613 | W6: =SUM(W4:W5) -> 4427 | X6: =SUM(X4:X5) -> 5056 | Y6: =SUM(Y4:Y5) -> 5680 | Z6: =SUM(Z4:Z5) -> 6137 | AA6: =SUM(AA4:AA5) -> 5610 | AB6: =SUM(AB4:AB5) -> 5437 | AC6: =SUM(AC4:AC5) -> 6349 | ... AP6: =SUM(AP4:AP5) -> 11973.236
A7: Cash SEKm | B7: =Q40 -> 2576 | C7: Selling expenses | D7: -391 | E7: -421 | F7: -392 | G7: -399 | H7: -434 | I7: -427 | J7: -369 | K7: -411 | L7: -425 | M7: -403 | N7: -411 | O7: -411 | P7: -377 | Q7: -382 | V7: -1336 | W7: -1165 | X7: -1208 | Y7: -1296 | Z7: -1444 | AA7: -1143 | AB7: -1355 | AC7: -1603 | AD7: -1641 | AE7: -1650 | AF7: =AE7*1.09 -> -1798.5 | AG7: =AF7*1.05 -> -1888.425 | AH7: =AG7*1.04 -> -1963.962 | AI7: =AH7*1.04 -> -2042.5205 | AJ7: =AI7*1.04 -> -2124.2213 | AK7: =AJ7*1.04 -> -2209.1902 | AL7: =AK7*1.04 -> -2297.5578 | AM7: =AL7*1.04 -> -2389.4601 | AN7: =AM7*1.04 -> -2485.0385 | AO7: =AN7*1.04 -> -2584.44 | AP7: =AO7*1.04 -> -2687.8176
A8: Debt SEKm | B8: =Q45+Q48 -> 6512 | C8: Adminstrative expenses | D8: -317 | E8: -339 | F8: -416 | G8: -325 | H8: -314 | I8: -343 | J8: -346 | K8: -366 | L8: -379 | M8: -317 | N8: -354 | O8: -363 | P8: -321 | Q8: -345 | V8: -1026 | W8: -928 | X8: -949 | Y8: -1039 | Z8: -1093 | AA8: -1086 | AB8: -1173 | AC8: -1398 | AD8: -1370 | AE8: -1412 | AF8: =AE8*1.1 -> -1553.2 | AG8: =AF8*1.05 -> -1630.86 | AH8: =AG8*1.04 -> -1696.0944 | AI8: =AH8*1.04 -> -1763.9382 | AJ8: =AI8*1.04 -> -1834.4957 | AK8: =AJ8*1.04 -> -1907.8755 | AL8: =AK8*1.04 -> -1984.1906 | AM8: =AL8*1.04 -> -2063.5582 | AN8: =AM8*1.04 -> -2146.1005 | AO8: =AN8*1.04 -> -2231.9445 | AP8: =AO8*1.04 -> -2321.2223
A9: EV SEKm | B9: =B6-B7+B8 -> 28389.312 | C9: R&D expenses | D9: -387 | E9: -362 | F9: -364 | G9: -305 | H9: -386 | I9: -323 | J9: -341 | K9: -354 | L9: -436 | M9: -421 | N9: -443 | O9: -1376 | P9: -438 | Q9: -434 | V9: -1065 | W9: -1018 | X9: -1095 | Y9: -1592 | Z9: -1657 | AA9: -1486 | AB9: -1372 | AC9: -1418 | AD9: -1404 | AE9: -2676 | AF9: -1500 | AG9: =AF9*1.05 -> -1575 | AH9: =AG9*1.04 -> -1638 | AI9: =AH9*1.04 -> -1703.52 | AJ9: =AI9*1.04 -> -1771.6608 | AK9: =AJ9*1.04 -> -1842.5272 | AL9: =AK9*1.04 -> -1916.2283 | AM9: =AL9*1.04 -> -1992.8775 | AN9: =AM9*1.04 -> -2072.5926 | AO9: =AN9*1.04 -> -2155.4963 | AP9: =AO9*1.04 -> -2241.7161
C10: Other operatign income/expense | D10: -8 | E10: -15 | F10: -22 | G10: -20 | H10: -13 | I10: -20 | J10: -40 | K10: -29 | L10: -12 | M10: -25 | N10: -15 | O10: -56 | P10: -10 | Q10: -8 | V10: -598 | W10: -518 | X10: 0 | Y10: 23 | Z10: 11 | AA10: -85 | AB10: -48 | AC10: -65 | AD10: -102 | AE10: -108 | AF10: =AE10*1.04 -> -112.32 | AG10: =AF10*1.05 -> -117.936 | AH10: =AG10*1.04 -> -122.65344 | AI10: =AH10*1.04 -> -127.55958 | AJ10: =AI10*1.04 -> -132.66196 | AK10: =AJ10*1.04 -> -137.96844 | AL10: =AK10*1.04 -> -143.48718 | AM10: =AL10*1.04 -> -149.22666 | AN10: =AM10*1.04 -> -155.19573 | AO10: =AN10*1.04 -> -161.40356 | AP10: =AO10*1.04 -> -167.8597
C11: Exchange rate diff | D11: -68 | E11: -142 | F11: -126 | G11: -99 | H11: -31 | I11: -57 | J11: -81 | K11: -51 | L11: 9 | M11: 11 | N11: 15 | O11: -45 | P11: 23 | Q11: 22 | V11: -165 | W11: -201 | X11: 42 | Y11: -80 | Z11: -298 | AA11: 97 | AB11: 155 | AC11: -434 | AD11: -221 | AE11: -9 | AF11: =AE11*1.04 -> -9.36 | AG11: =AF11*1.05 -> -9.828 | AH11: =AG11*1.04 -> -10.22112 | AI11: =AH11*1.04 -> -10.629965 | AJ11: =AI11*1.04 -> -11.055163 | AK11: =AJ11*1.04 -> -11.49737 | AL11: =AK11*1.04 -> -11.957265 | AM11: =AL11*1.04 -> -12.435555 | AN11: =AM11*1.04 -> -12.932978 | AO11: =AN11*1.04 -> -13.450297 | AP11: =AO11*1.04 -> -13.988308
C12: Operating profit (EBIT) | D12: =SUM(D6:D11) -> 117 | E12: =SUM(E6:E11) -> 200 | F12: =SUM(F6:F11) -> 331 | G12: =SUM(G6:G11) -> 783 | H12: =SUM(H6:H11) -> 412 | I12: =SUM(I6:I11) -> 525 | J12: =SUM(J6:J11) -> 487 | K12: =SUM(K6:K11) -> 618 | ... S12: =SUM(S6:S11) -> 0 | V12: =SUM(V6:V11) -> 423 | W12: =SUM(W6:W11) -> 597 | X12: =SUM(X6:X11) -> 1846 | Y12: =SUM(Y6:Y11) -> 1696 | Z12: =SUM(Z6:Z11) -> 1656 | AA12: =SUM(AA6:AA11) -> 1907 | AB12: =SUM(AB6:AB11) -> 1644 | AC12: =SUM(AC6:AC11) -> 1431 | ... AP12: =SUM(AP6:AP11) -> 4540.6315
C13: Financial items, net | D13: -39 | E13: -40 | F13: -58 | G13: -95 | H13: -107 | I13: -83 | J13: -93 | K13: -88 | L13: -83 | M13: -113 | N13: -95 | O13: -109 | P13: -83 | Q13: -80 | V13: =11+37-285+3 -> -234 | W13: =-17+31-271-1 -> -258 | X13: =-7+67-225+1 -> -164 | Y13: =3+66-186+2 -> -115 | Z13: =-4+63-215-51+4 -> -203 | AA13: =-7+30-253-41-5 -> -276 | AB13: =5+42-159-41+12 -> -141 | AC13: =1+79-272-38-3 -> -233 | AD13: -371 | AE13: -400 | AF13: 0 | AG13: 0 | AH13: 0 | AI13: 0 | AJ13: 0 | AK13: 0 | AL13: 0 | AM13: 0 | AN13: 0 | AO13: 0 | AP13: 0
C14: PTP | D14: =SUM(D12:D13) -> 78 | E14: =SUM(E12:E13) -> 160 | F14: =SUM(F12:F13) -> 273 | G14: =SUM(G12:G13) -> 688 | H14: =SUM(H12:H13) -> 305 | I14: =SUM(I12:I13) -> 442 | J14: =SUM(J12:J13) -> 394 | K14: =SUM(K12:K13) -> 530 | ... S14: =SUM(S12:S13) -> 0 | V14: =SUM(V12:V13) -> 189 | W14: =SUM(W12:W13) -> 339 | X14: =SUM(X12:X13) -> 1682 | Y14: =SUM(Y12:Y13) -> 1581 | Z14: =SUM(Z12:Z13) -> 1453 | AA14: =SUM(AA12:AA13) -> 1631 | AB14: =SUM(AB12:AB13) -> 1503 | AC14: =SUM(AC12:AC13) -> 1198 | ... AP14: =SUM(AP12:AP13) -> 4540.6315
C15: Tax | D15: -18 | E15: -38 | F15: -57 | G15: -142 | H15: -67 | I15: -97 | J15: -86 | K15: -115 | L15: -20 | M15: -61 | N15: -95 | O15: -74 | P15: -30 | Q15: -81 | V15: -44 | W15: -214 | X15: -333 | Y15: -382 | Z15: -370 | AA15: -377 | AB15: -345 | AC15: -254 | AD15: -365 | AE15: -250 | AF15: =AF14*-0.2 -> -365.17168 | AG15: =AG14*-0.2 -> -460.61081 | AH15: =AH14*-0.2 -> -534.60523 | AI15: =AI14*-0.2 -> -572.19736 | AJ15: =AJ14*-0.2 -> -612.10356 | AK15: =AK14*-0.2 -> -654.45693 | AL15: =AL14*-0.2 -> -699.39789 | AM15: =AM14*-0.2 -> -747.07463 | ... AP15: =AP14*-0.2 -> -908.12631
C16: Net income | D16: =SUM(D14:D15) -> 60 | E16: =SUM(E14:E15) -> 122 | F16: =SUM(F14:F15) -> 216 | G16: =SUM(G14:G15) -> 546 | H16: =SUM(H14:H15) -> 238 | I16: =SUM(I14:I15) -> 345 | J16: =SUM(J14:J15) -> 308 | K16: =SUM(K14:K15) -> 415 | ... S16: =SUM(S14:S15) -> 0 | V16: =SUM(V14:V15) -> 145 | W16: =SUM(W14:W15) -> 125 | X16: =SUM(X14:X15) -> 1349 | Y16: =SUM(Y14:Y15) -> 1199 | Z16: =SUM(Z14:Z15) -> 1083 | AA16: =SUM(AA14:AA15) -> 1254 | AB16: =SUM(AB14:AB15) -> 1158 | AC16: =SUM(AC14:AC15) -> 944 | ... AP16: =SUM(AP14:AP15) -> 3632.5052 | AQ16: =AP16*(1+$AS$20) -> 3596.1802 | AR16: =AQ16*(1+$AS$20) -> 3560.2184 | AS16: =AR16*(1+$AS$20) -> 3524.6162 | AT16: =AS16*(1+$AS$20) -> 3489.37 | AU16: =AT16*(1+$AS$20) -> 3454.4763 | AV16: =AU16*(1+$AS$20) -> 3419.9316 | AW16: =AV16*(1+$AS$20) -> 3385.7323 | AX16: =AW16*(1+$AS$20) -> 3351.8749 | ... GV16: =GU16*(1+$AS$20) -> 713.02995
C17: Share | D17: 382.083 | E17: 382.083 | F17: 382.083 | G17: 382.083 | H17: 382.083 | I17: 382.083 | J17: 382.083 | K17: 382.083 | L17: 382.083 | M17: 382.083 | N17: 382.083 | O17: 382.083 | P17: 382.083 | Q17: 382.083 | R17: 382.083 | S17: 382.083 | V17: 382.083 | W17: 382.083 | X17: 382.083 | Y17: 382.083 | Z17: 382.083 | AA17: 382.083 | AB17: 382.083 | AC17: 382.083 | AD17: 382.083 | AE17: 382.083 | AF17: 382.083 | AG17: 382.083 | AH17: 382.083 | AI17: 382.083 | AJ17: 382.083 | AK17: 382.083 | AL17: 382.083 | AM17: 382.083 | AN17: 382.083 | AO17: 382.083 | AP17: 382.083
C18: EPS | D18: =D16/D17 -> 0.15703394 | E18: =E16/E17 -> 0.31930235 | F18: =F16/F17 -> 0.56532219 | G18: =G16/G17 -> 1.4290089 | H18: =H16/H17 -> 0.62290131 | I18: =I16/I17 -> 0.90294517 | J18: =J16/J17 -> 0.80610757 | K18: =K16/K17 -> 1.0861514 | ... S18: =S16/S17 -> 0 | V18: =V16/V17 -> 0.3794987 | W18: =W16/W17 -> 0.32715405 | X18: =X16/X17 -> 3.5306465 | Y18: =Y16/Y17 -> 3.1380616 | Z18: =Z16/Z17 -> 2.8344627 | AA18: =AA16/AA17 -> 3.2820094 | AB18: =AB16/AB17 -> 3.0307551 | AC18: =AC16/AC17 -> 2.4706674 | ... AP18: =AP16/AP17 -> 9.5071103
AR19: Discount | AS19: 0.08
C20: Revenue y/y | G20: 0.21 | H20: =(H4-D4)/D4 -> 0.15058611 | I20: =(I4-E4)/E4 -> 0.15951973 | J20: =(J4-F4)/F4 -> 0.046114826 | K20: =(K4-G4)/G4 -> -0.019902439 | L20: =(L4-H4)/H4 -> -0.00078369906 | M20: =(M4-I4)/I4 -> -0.08262891 | N20: =(N4-J4)/J4 -> 0.034824774 | O20: =(O4-K4)/K4 -> 0.0264782 | ... S20: =(S4-O4)/O4 -> -1 | W20: =(W4-V4)/V4 -> -0.046074325 | X20: =(X4-W4)/W4 -> 0.081184604 | Y20: =(Y4-X4)/X4 -> 0.17126069 | Z20: =(Z4-Y4)/Y4 -> 0.077167097 | AA20: =(AA4-Z4)/Z4 -> -0.057393329 | AB20: =(AB4-AA4)/AA4 -> 0.057036983 | AC20: =(AC4-AB4)/AB4 -> 0.15954083 | AD20: =(AD4-AC4)/AC4 -> 0.074100421 | ... AP20: =(AP4-AO4)/AO4 -> 0.05 | AR20: TV | AS20: -0.01
C21: Revenue constant FX | D21: 0.03 | E21: -0.05 | F21: 0.08 | G21: 0.1 | H21: 0.08 | I21: 0.1 | J21: 0.04 | K21: -0.02 | L21: 0.01 | M21: -0.04 | N21: 0.02 | O21: 0.06 | P21: 0.03 | Q21: 0.01 | AR21: NPV | AS21: =NPV(AS19,AF16:GV16) -> 34743.148
C22: Gross margin | D22: =D6/D4 -> 0.38713556 | E22: =E6/E4 -> 0.36241117 | F22: =F6/F4 -> 0.38067789 | G22: =G6/G4 -> 0.37678049 | H22: =H6/H4 -> 0.4153605 | I22: =I6/I4 -> 0.35819949 | J22: =J6/J4 -> 0.36676218 | K22: =K6/K4 -> 0.36412502 | ... S22: =S6/S4 -> #DIV/0! | V22: =V6/V4 -> 0.41110418 | W22: =W6/W4 -> 0.41358371 | X22: =X6/X4 -> 0.43687894 | Y22: =Y6/Y4 -> 0.41903357 | Z22: =Z6/Z4 -> 0.42031368 | AA22: =AA6/AA4 -> 0.40761462 | AB22: =AB6/AB4 -> 0.37372835 | AC22: =AC6/AC4 -> 0.37637086 | ... AP22: =AP6/AP4 -> 0.4 | AR22: S/O | AS22: 382.083
C23: EBIT margin | D23: =D12/D4 -> 0.035166817 | E23: =E12/E4 -> 0.049007596 | F23: =F12/F4 -> 0.076320037 | G23: =G12/G4 -> 0.15278049 | H23: =H12/H4 -> 0.107628 | I23: =I12/I4 -> 0.11094675 | J23: =J12/J4 -> 0.10733965 | K23: =K12/K4 -> 0.12303404 | ... S23: =S12/S4 -> #DIV/0! | V23: =V12/V4 -> 0.037697175 | W23: =W12/W4 -> 0.055773543 | X23: =X12/X4 -> 0.1595092 | Y23: =Y12/Y4 -> 0.12511988 | Z23: =Z12/Z4 -> 0.11341689 | AA23: =AA12/AA4 -> 0.13855991 | AB23: =AB12/AB4 -> 0.11300522 | AC23: =AC12/AC4 -> 0.084830162 | ... AP23: =AP12/AP4 -> 0.15169272 | AR23: NPV/Share | AS23: =AS21/AS22 -> 90.930893
C24: ROCE | V24: 0.04 | W24: 0.05 | X24: 0.17 | Y24: 0.15 | Z24: 0.12 | AA24: 0.12 | AB24: 0.12 | AC24: 0.1 | AD24: 0.12 | AE24: 0.06 | AR24: Opp-/nedside | AS24: =(AS23-B4)/B4 -> 0.4207952
C26: Order intake (SEKm) | D26: 3871 | E26: 4598 | F26: 5316 | G26: 6359 | H26: 3839 | I26: 4989 | J26: 4433 | K26: 6436 | L26: 4192 | M26: 4317 | N26: 5418 | O26: 5792 | P26: 3838 | Q26: 4081 | Z26: 17735 | AA26: 17411 | AB26: 18364 | AC26: 20143 | AD26: 19697 | AE26: 19718
C27: Y/Y (SEK) | H27: =(H26-D26)/D26 -> -0.0082665978 | I27: =(I26-E26)/E26 -> 0.085036973 | J27: =(J26-F26)/F26 -> -0.16610233 | K27: =(K26-G26)/G26 -> 0.012108822 | L27: =(L26-H26)/H26 -> 0.091951029 | M27: =(M26-I26)/I26 -> -0.13469633 | N27: =(N26-J26)/J26 -> 0.22219716 | O27: =(O26-K26)/K26 -> -0.10006215 | ... S27: =(S26-O26)/O26 -> -1 | W27: =(W26-V26)/V26 -> #DIV/0! | X27: =(X26-W26)/W26 -> #DIV/0! | Y27: =(Y26-X26)/X26 -> #DIV/0! | Z27: =(Z26-Y26)/Y26 -> #DIV/0! | AA27: =(AA26-Z26)/Z26 -> -0.01826896 | AB27: =(AB26-AA26)/AA26 -> 0.054735512 | AC27: =(AC26-AB26)/AB26 -> 0.096874319 | AD27: =(AD26-AC26)/AC26 -> -0.022141687 | AE27: =(AE26-AD26)/AD26 -> 0.0010661522
C28: Y/Y (Constant FX) | M28: -0.09 | N28: 0.21 | O28: -0.07 | P28: -0.01 | Q28: 0.02
C30: Balanse SEKm
C31: Intangible assets | D31: 10666 | E31: 11390 | F31: 11492 | G31: 11722 | H31: 12450 | I31: 13090 | J31: 12610 | K31: 13336 | L31: 13343 | M31: 13705 | N31: 13907 | O31: 11917 | P31: 12111 | Q31: 11806
C32: Right of use assets | D32: 946 | E32: 923 | F32: 795 | G32: 773 | H32: 772 | I32: 873 | J32: 1139 | K32: 1164 | L32: 1083 | M32: 1068 | N32: 1070 | O32: 1006 | P32: 977 | Q32: 915
C33: Tangible assets | D33: 961 | E33: 969 | F33: 999 | G33: 980 | H33: 1001 | I33: 1010 | J33: 1014 | K33: 1062 | L33: 1063 | M33: 1064 | N33: 1046 | O33: 901 | P33: 884 | Q33: 827
C34: Financial assets | D34: 719 | E34: 720 | F34: 726 | G34: 1055 | H34: 1041 | I34: 1038 | J34: 1056 | K34: 1092 | L34: 1021 | M34: 1019 | N34: 981 | O34: 895 | P34: 826 | Q34: 769
C35: Deferred tax assets | D35: 636 | E35: 696 | F35: 713 | G35: 703 | H35: 732 | I35: 786 | J35: 712 | K35: 801 | L35: 865 | M35: 913 | N35: 943 | O35: 841 | P35: 910 | Q35: 886
C36: Invetories | D36: 2990 | E36: 3216 | F36: 3337 | G36: 3070 | H36: 3732 | I36: 3806 | J36: 3538 | K36: 3259 | L36: 3524 | M36: 3398 | N36: 3229 | O36: 2756 | P36: 3029 | Q36: 3086
C37: Account receivables | D37: 3275 | E37: 3666 | F37: 4239 | G37: 3990 | H37: 4173 | I37: 4376 | J37: 4158 | K37: 3877 | L37: 3922 | M37: 4015 | N37: 4109 | O37: 3625 | P37: 3572 | Q37: 3324
C38: Accrued income | D38: 1850 | E38: 2047 | F38: 2287 | G38: 2119 | H38: 2358 | I38: 2524 | J38: 1893 | K38: 2050 | L38: 2092 | M38: 1870 | N38: 1902 | O38: 2261 | P38: 2123 | Q38: 2168
C39: Other current receivables | D39: 1857 | E39: 2062 | F39: 2165 | G39: 1917 | H39: 2197 | I39: 2243 | J39: 2260 | K39: 1994 | L39: 2138 | M39: 2131 | N39: 2184 | O39: 1820 | P39: 1959 | Q39: 1880
C40: Cash | D40: 2423 | E40: 1535 | F40: 1218 | G40: 3278 | H40: 2367 | I40: 1869 | J40: 2352 | K40: 2779 | L40: 2364 | M40: 3352 | N40: 3583 | O40: 2955 | P40: 2760 | Q40: 2576
C41: Total assets | D41: =SUM(D31:D40) -> 26323 | E41: =SUM(E31:E40) -> 27224 | F41: =SUM(F31:F40) -> 27971 | G41: =SUM(G31:G40) -> 29607 | H41: =SUM(H31:H40) -> 30823 | I41: =SUM(I31:I40) -> 31615 | J41: =SUM(J31:J40) -> 30732 | K41: =SUM(K31:K40) -> 31414 | ... S41: =SUM(S31:S40) -> 0
C42: Equity attributable to parent company | D42: 9079 | E42: 9128 | F42: 9625 | G42: 9729 | H42: 10214 | I42: 10364 | J42: 10247 | K42: 10774 | L42: 10703 | M42: 10419 | N42: 10784 | O42: 8803 | P42: 9086 | Q42: 8449
C43: Non-controlling interests | D43: 3 | E43: 4 | F43: 4 | G43: 4 | H43: 5 | I43: 5 | J43: 5 | K43: 5 | L43: 5 | M43: 50 | N43: 46 | O43: 45 | P43: 46 | Q43: 43
...

Sheet Segementer
C3: mai-juli | D3: aug-okt | E3: nov-jan | F3: feb-apr | H3: mai-juli | I3: aug-okt | J3: nov-jan | K3: feb-apr | M3: mai-juli | N3: aug-okt | O3: nov-jan | P3: feb-apr | R3: mai-juli | S3: aug-okt | T3: nov-jan | U3: feb-apr
B4: SEKm | C4: Q1 22/23 | D4: Q2 22/23 | E4: Q3 22/23 | F4: Q4 22/23 | G4: 22/23 | H4: Q1 23/24 | I4: Q2 23/24 | J4: Q3 23/24 | K4: Q4 23/24 | L4: 23/24 | M4: Q1 24/25 | N4: Q2 24/25 | O4: Q3 24/25 | P4: Q4 24/25 | Q4: 24/25 | R4: Q1 25/26 | S4: Q2 25/26 | T4: Q3 25/26 | U4: Q4 25/26 | V4: 25/26
B5: Americas
B6: Revenue | C6: 1038 | D6: 1327 | E6: 1342 | F6: 1532 | G6: =SUM(C6:F6) -> 5239 | H6: 1071 | I6: 1405 | J6: 1434 | K6: 1526 | L6: =SUM(H6:K6) -> 5436 | M6: 1241 | N6: 1212 | O6: 1359 | P6: 1371 | Q6: =SUM(M6:P6) -> 5183 | R6: 1071 | S6: 1031 | V6: =SUM(R6:U6) -> 2102
B7: y/y | H7: =(H6-C6)/C6 -> 0.031791908 | I7: =(I6-D6)/D6 -> 0.058779201 | J7: =(J6-E6)/E6 -> 0.068554396 | K7: =(K6-F6)/F6 -> -0.0039164491 | L7: =(L6-G6)/G6 -> 0.037602596 | M7: =(M6-H6)/H6 -> 0.15873016 | N7: =(N6-I6)/I6 -> -0.13736655 | O7: =(O6-J6)/J6 -> -0.052301255 | ... V7: =(V6-Q6)/Q6 -> -0.59444337
B8: y/y constant FX | S8: -0.08
B9: Opex | C9: -677 | D9: -800 | E9: -752 | F9: -917 | G9: =SUM(C9:F9) -> -3146 | H9: -653 | I9: -914 | J9: -868 | K9: -923 | L9: =SUM(H9:K9) -> -3358 | M9: -743 | N9: -760 | O9: -798 | P9: -914 | Q9: =SUM(M9:P9) -> -3215 | R9: -697 | S9: -670 | V9: =SUM(R9:U9) -> -1367
B10: Contribution margin | C10: =C6+C9 -> 361 | D10: =D6+D9 -> 527 | E10: =E6+E9 -> 590 | F10: =F6+F9 -> 615 | G10: =SUM(C10:F10) -> 2093 | H10: =H6+H9 -> 418 | I10: =I6+I9 -> 491 | J10: =J6+J9 -> 566 | K10: =K6+K9 -> 603 | L10: =SUM(H10:K10) -> 2078 | M10: =M6+M9 -> 498 | N10: =N6+N9 -> 452 | O10: =O6+O9 -> 561 | P10: =P6+P9 -> 457 | Q10: =SUM(M10:P10) -> 1968 | R10: =R6+R9 -> 374 | S10: =S6+S9 -> 361 | T10: =T6+T9 -> 0 | U10: =U6+U9 -> 0 | V10: =SUM(R10:U10) -> 735
B11: Contribution margin % | C11: 0.35 | D11: 0.4 | E11: 0.44 | F11: 0.4 | G11: =G10/G6 -> 0.39950372 | H11: 0.39 | I11: 0.35 | J11: 0.39 | K11: 0.4 | L11: =L10/L6 -> 0.38226637 | M11: 0.4 | N11: 0.37 | O11: 0.41 | P11: 0.33 | Q11: =Q10/Q6 -> 0.37970287 | R11: 0.35 | S11: 0.35 | V11: =V10/V6 -> 0.34966698
B12: Global costs | C12: 0 | D12: 0 | E12: 0 | F12: 0 | G12: =SUM(C12:F12) -> 0 | H12: 0 | I12: 0 | J12: 0 | K12: 0 | L12: =SUM(H12:K12) -> 0 | M12: 0 | N12: 0 | O12: 0 | P12: 0 | Q12: =SUM(M12:P12) -> 0 | R12: 0 | S12: 0 | V12: =SUM(R12:U12) -> 0
B13: Adjusted EBIT | C13: =C10+C12 -> 361 | D13: =D10+D12 -> 527 | E13: =E10+E12 -> 590 | F13: =F10+F12 -> 615 | G13: =SUM(C13:F13) -> 2093 | H13: =H10+H12 -> 418 | I13: =I10+I12 -> 491 | J13: =J10+J12 -> 566 | K13: =K10+K12 -> 603 | L13: =SUM(H13:K13) -> 2078 | M13: =M10+M12 -> 498 | N13: =N10+N12 -> 452 | O13: =O10+O12 -> 561 | P13: =P10+P12 -> 457 | Q13: =SUM(M13:P13) -> 1968 | R13: =R10+R12 -> 374 | S13: =S10+S12 -> 361 | T13: =T10+T12 -> 0 | U13: =U10+U12 -> 0 | V13: =SUM(R13:U13) -> 735
B14: Items affecting comp | C14: -2 | D14: -31 | E14: -40 | F14: -4 | G14: =SUM(C14:F14) -> -77 | H14: 0 | I14: 0 | J14: 0 | K14: -8 | L14: =SUM(H14:K14) -> -8 | M14: -7 | N14: -5 | O14: -10 | P14: 0 | Q14: =SUM(M14:P14) -> -22 | R14: -6 | S14: 0 | V14: =SUM(R14:U14) -> -6
B15: Operating income (EBIT) | C15: =SUM(C13:C14) -> 359 | D15: =SUM(D13:D14) -> 496 | E15: =SUM(E13:E14) -> 550 | F15: =SUM(F13:F14) -> 611 | G15: =SUM(C15:F15) -> 2016 | H15: =SUM(H13:H14) -> 418 | I15: =SUM(I13:I14) -> 491 | J15: =SUM(J13:J14) -> 566 | K15: =SUM(K13:K14) -> 595 | L15: =SUM(H15:K15) -> 2070 | M15: =SUM(M13:M14) -> 491 | N15: =SUM(N13:N14) -> 447 | O15: =SUM(O13:O14) -> 551 | P15: =SUM(P13:P14) -> 457 | Q15: =SUM(M15:P15) -> 1946 | R15: =SUM(R13:R14) -> 368 | S15: =SUM(S13:S14) -> 361 | T15: =SUM(T13:T14) -> 0 | U15: =SUM(U13:U14) -> 0 | V15: =SUM(R15:U15) -> 729
B16: Net financial items | C16: 0 | D16: 0 | E16: 0 | F16: 0 | G16: =SUM(C16:F16) -> 0 | H16: 0 | I16: 0 | J16: 0 | K16: 0 | L16: =SUM(H16:K16) -> 0 | M16: 0 | N16: 0 | O16: 0 | P16: 0 | Q16: =SUM(M16:P16) -> 0 | R16: 0 | S16: 0 | V16: =SUM(R16:U16) -> 0
B17: PTP | C17: =SUM(C15:C16) -> 359 | D17: =SUM(D15:D16) -> 496 | E17: =SUM(E15:E16) -> 550 | F17: =SUM(F15:F16) -> 611 | G17: =SUM(C17:F17) -> 2016 | H17: =SUM(H15:H16) -> 418 | I17: =SUM(I15:I16) -> 491 | J17: =SUM(J15:J16) -> 566 | K17: =SUM(K15:K16) -> 595 | L17: =SUM(H17:K17) -> 2070 | M17: =SUM(M15:M16) -> 491 | N17: =SUM(N15:N16) -> 447 | O17: =SUM(O15:O16) -> 551 | P17: =SUM(P15:P16) -> 457 | Q17: =SUM(M17:P17) -> 1946 | R17: =SUM(R15:R16) -> 368 | S17: =SUM(S15:S16) -> 361 | T17: =SUM(T15:T16) -> 0 | U17: =SUM(U15:U16) -> 0 | V17: =SUM(R17:U17) -> 729
B18: Tax | C18: 0 | D18: 0 | E18: 0 | F18: 0 | G18: =SUM(C18:F18) -> 0 | H18: 0 | I18: 0 | J18: 0 | K18: 0 | L18: =SUM(H18:K18) -> 0 | M18: 0 | N18: 0 | O18: 0 | P18: 0 | Q18: =SUM(M18:P18) -> 0 | R18: 0 | S18: 0 | V18: =SUM(R18:U18) -> 0
B19: Net income | C19: =SUM(C17:C18) -> 359 | D19: =SUM(D17:D18) -> 496 | E19: =SUM(E17:E18) -> 550 | F19: =SUM(F17:F18) -> 611 | G19: =SUM(C19:F19) -> 2016 | H19: =SUM(H17:H18) -> 418 | I19: =SUM(I17:I18) -> 491 | J19: =SUM(J17:J18) -> 566 | K19: =SUM(K17:K18) -> 595 | L19: =SUM(H19:K19) -> 2070 | M19: =SUM(M17:M18) -> 491 | N19: =SUM(N17:N18) -> 447 | O19: =SUM(O17:O18) -> 551 | P19: =SUM(P17:P18) -> 457 | Q19: =SUM(M19:P19) -> 1946 | R19: =SUM(R17:R18) -> 368 | S19: =SUM(S17:S18) -> 361 | T19: =SUM(T17:T18) -> 0 | U19: =SUM(U17:U18) -> 0 | V19: =SUM(R19:U19) -> 729
B20: EMEA
B21: Revenue | C21: 1190 | D21: 1332 | E21: 1524 | F21: 1860 | G21: =SUM(C21:F21) -> 5906 | H21: 1498 | I21: 1733 | J21: 1550 | K21: 1769 | L21: =SUM(H21:K21) -> 6550 | M21: 1314 | N21: 1597 | O21: 1655 | P21: 2014 | Q21: =SUM(M21:P21) -> 6580 | R21: 1443 | S21: 1693 | V21: =SUM(R21:U21) -> 3136
B22: y/y | H22: =(H21-C21)/C21 -> 0.25882353 | I22: =(I21-D21)/D21 -> 0.30105105 | J22: =(J21-E21)/E21 -> 0.017060367 | K22: =(K21-F21)/F21 -> -0.048924731 | L22: =(L21-G21)/G21 -> 0.10904165 | M22: =(M21-H21)/H21 -> -0.12283044 | N22: =(N21-I21)/I21 -> -0.07847663 | O22: =(O21-J21)/J21 -> 0.067741935 | ... V22: =(V21-Q21)/Q21 -> -0.52340426
B23: y/y constant FX | S23: 0.11
B24: Opex | C24: -797 | D24: -914 | E24: -1035 | F24: -1161 | G24: =SUM(C24:F24) -> -3907 | H24: -1013 | I24: -1170 | J24: -1085 | K24: -1259 | L24: =SUM(H24:K24) -> -4527 | M24: -890 | N24: -1081 | O24: -1065 | P24: -1210 | Q24: =SUM(M24:P24) -> -4246 | R24: -908 | S24: -1051 | V24: =SUM(R24:U24) -> -1959
B25: Contribution margin | C25: =C21+C24 -> 393 | D25: =D21+D24 -> 418 | E25: =E21+E24 -> 489 | F25: =F21+F24 -> 699 | G25: =SUM(C25:F25) -> 1999 | H25: =H21+H24 -> 485 | I25: =I21+I24 -> 563 | J25: =J21+J24 -> 465 | K25: =K21+K24 -> 510 | L25: =SUM(H25:K25) -> 2023 | M25: =M21+M24 -> 424 | N25: =N21+N24 -> 516 | O25: =O21+O24 -> 590 | P25: =P21+P24 -> 804 | Q25: =SUM(M25:P25) -> 2334 | R25: =R21+R24 -> 535 | S25: =S21+S24 -> 642 | T25: =T21+T24 -> 0 | U25: =U21+U24 -> 0 | V25: =SUM(R25:U25) -> 1177
B26: Contribution margin % | C26: 0.33 | D26: 0.31 | E26: 0.32 | F26: 0.38 | G26: =G25/G21 -> 0.33846935 | H26: 0.32 | I26: 0.32 | J26: 0.3 | K26: 0.29 | L26: =L25/L21 -> 0.30885496 | M26: 0.32 | N26: 0.32 | O26: 0.36 | P26: 0.4 | Q26: =Q25/Q21 -> 0.35471125 | R26: 0.37 | S26: 0.38 | V26: =V25/V21 -> 0.37531888
B27: Global costs | C27: 0 | D27: 0 | E27: 0 | F27: 0 | G27: =SUM(C27:F27) -> 0 | H27: 0 | I27: 0 | J27: 0 | K27: 0 | L27: =SUM(H27:K27) -> 0 | M27: 0 | N27: 0 | O27: 0 | P27: 0 | Q27: =SUM(M27:P27) -> 0 | R27: 0 | S27: 0 | V27: =SUM(R27:U27) -> 0
B28: Adjusted EBIT | C28: =C25+C27 -> 393 | D28: =D25+D27 -> 418 | E28: =E25+E27 -> 489 | F28: =F25+F27 -> 699 | G28: =SUM(C28:F28) -> 1999 | H28: =H25+H27 -> 485 | I28: =I25+I27 -> 563 | J28: =J25+J27 -> 465 | K28: =K25+K27 -> 510 | L28: =SUM(H28:K28) -> 2023 | M28: =M25+M27 -> 424 | N28: =N25+N27 -> 516 | O28: =O25+O27 -> 590 | P28: =P25+P27 -> 804 | Q28: =SUM(M28:P28) -> 2334 | R28: =R25+R27 -> 535 | S28: =S25+S27 -> 642 | T28: =T25+T27 -> 0 | U28: =U25+U27 -> 0 | V28: =SUM(R28:U28) -> 1177
B29: Items affecting comp | C29: -3 | D29: -10 | E29: -6 | F29: -1 | G29: =SUM(C29:F29) -> -20 | H29: -3 | I29: -4 | J29: -2 | K29: -1 | L29: =SUM(H29:K29) -> -10 | M29: -3 | N29: -2 | O29: -1 | P29: -6 | Q29: =SUM(M29:P29) -> -12 | R29: 0 | S29: -2 | V29: =SUM(R29:U29) -> -2
B30: Operating income (EBIT) | C30: =SUM(C28:C29) -> 390 | D30: =SUM(D28:D29) -> 408 | E30: =SUM(E28:E29) -> 483 | F30: =SUM(F28:F29) -> 698 | G30: =SUM(C30:F30) -> 1979 | H30: =SUM(H28:H29) -> 482 | I30: =SUM(I28:I29) -> 559 | J30: =SUM(J28:J29) -> 463 | K30: =SUM(K28:K29) -> 509 | L30: =SUM(H30:K30) -> 2013 | M30: =SUM(M28:M29) -> 421 | N30: =SUM(N28:N29) -> 514 | O30: =SUM(O28:O29) -> 589 | P30: =SUM(P28:P29) -> 798 | Q30: =SUM(M30:P30) -> 2322 | R30: =SUM(R28:R29) -> 535 | S30: =SUM(S28:S29) -> 640 | T30: =SUM(T28:T29) -> 0 | U30: =SUM(U28:U29) -> 0 | V30: =SUM(R30:U30) -> 1175
B31: Net financial items | C31: 0 | D31: 0 | E31: 0 | F31: 0 | G31: =SUM(C31:F31) -> 0 | H31: 0 | I31: 0 | J31: 0 | K31: 0 | L31: =SUM(H31:K31) -> 0 | M31: 0 | N31: 0 | O31: 0 | P31: 0 | Q31: =SUM(M31:P31) -> 0 | R31: 404 | S31: 34 | V31: =SUM(R31:U31) -> 438
B32: PTP | C32: =SUM(C30:C31) -> 390 | D32: =SUM(D30:D31) -> 408 | E32: =SUM(E30:E31) -> 483 | F32: =SUM(F30:F31) -> 698 | G32: =SUM(C32:F32) -> 1979 | H32: =SUM(H30:H31) -> 482 | I32: =SUM(I30:I31) -> 559 | J32: =SUM(J30:J31) -> 463 | K32: =SUM(K30:K31) -> 509 | L32: =SUM(H32:K32) -> 2013 | M32: =SUM(M30:M31) -> 421 | N32: =SUM(N30:N31) -> 514 | O32: =SUM(O30:O31) -> 589 | P32: =SUM(P30:P31) -> 798 | Q32: =SUM(M32:P32) -> 2322 | R32: =SUM(R30:R31) -> 939 | S32: =SUM(S30:S31) -> 674 | T32: =SUM(T30:T31) -> 0 | U32: =SUM(U30:U31) -> 0 | V32: =SUM(R32:U32) -> 1613
B33: Tax | C33: 0 | D33: 0 | E33: 0 | F33: 0 | G33: =SUM(C33:F33) -> 0 | H33: 0 | I33: 0 | J33: 0 | K33: 0 | L33: =SUM(H33:K33) -> 0 | M33: 0 | N33: 0 | O33: 0 | P33: 0 | Q33: =SUM(M33:P33) -> 0 | R33: 0 | S33: 0 | V33: =SUM(R33:U33) -> 0
B34: Net income | C34: =SUM(C32:C33) -> 390 | D34: =SUM(D32:D33) -> 408 | E34: =SUM(E32:E33) -> 483 | F34: =SUM(F32:F33) -> 698 | G34: =SUM(C34:F34) -> 1979 | H34: =SUM(H32:H33) -> 482 | I34: =SUM(I32:I33) -> 559 | J34: =SUM(J32:J33) -> 463 | K34: =SUM(K32:K33) -> 509 | L34: =SUM(H34:K34) -> 2013 | M34: =SUM(M32:M33) -> 421 | N34: =SUM(N32:N33) -> 514 | O34: =SUM(O32:O33) -> 589 | P34: =SUM(P32:P33) -> 798 | Q34: =SUM(M34:P34) -> 2322 | R34: =SUM(R32:R33) -> 939 | S34: =SUM(S32:S33) -> 674 | T34: =SUM(T32:T33) -> 0 | U34: =SUM(U32:U33) -> 0 | V34: =SUM(R34:U34) -> 1613
B35: APAC
B36: Revenue | C36: 1099 | D36: 1421 | E36: 1471 | F36: 1733 | G36: =SUM(C36:F36) -> 5724 | H36: 1259 | I36: 1595 | J36: 1553 | K36: 1728 | L36: =SUM(H36:K36) -> 6135 | M36: 1270 | N36: 1532 | O36: 1681 | P36: 1771 | Q36: =SUM(M36:P36) -> 6254 | R36: 1132 | S36: 1346 | V36: =SUM(R36:U36) -> 2478
B37: y/y | H37: =(H36-C36)/C36 -> 0.1455869 | I37: =(I36-D36)/D36 -> 0.12244898 | J37: =(J36-E36)/E36 -> 0.055744392 | K37: =(K36-F36)/F36 -> -0.0028851702 | L37: =(L36-G36)/G36 -> 0.071802935 | M37: =(M36-H36)/H36 -> 0.0087370929 | N37: =(N36-I36)/I36 -> -0.039498433 | O37: =(O36-J36)/J36 -> 0.08242112 | ... V37: =(V36-Q36)/Q36 -> -0.60377358
B38: y/y constant FX | S38: -0.03
B39: Opex | C39: -749 | D39: -961 | E39: -946 | F39: -1158 | G39: =SUM(C39:F39) -> -3814 | H39: -866 | I39: -1152 | J39: -1091 | K39: -1184 | L39: =SUM(H39:K39) -> -4293 | M39: -825 | N39: -978 | O39: -1122 | P39: -1095 | Q39: =SUM(M39:P39) -> -4020 | R39: -731 | S39: -877 | V39: =SUM(R39:U39) -> -1608
B40: Contribution margin | C40: =C36+C39 -> 350 | D40: =D36+D39 -> 460 | E40: =E36+E39 -> 525 | F40: =F36+F39 -> 575 | G40: =SUM(C40:F40) -> 1910 | H40: =H36+H39 -> 393 | I40: =I36+I39 -> 443 | J40: =J36+J39 -> 462 | K40: =K36+K39 -> 544 | L40: =SUM(H40:K40) -> 1842 | M40: =M36+M39 -> 445 | N40: =N36+N39 -> 554 | O40: =O36+O39 -> 559 | P40: =P36+P39 -> 676 | Q40: =SUM(M40:P40) -> 2234 | R40: =R36+R39 -> 401 | S40: =S36+S39 -> 469 | T40: =T36+T39 -> 0 | U40: =U36+U39 -> 0 | V40: =SUM(R40:U40) -> 870
B41: Contribution margin % | C41: 0.32 | D41: 0.32 | E41: 0.36 | F41: 0.33 | G41: =G40/G36 -> 0.33368274 | H41: 0.31 | I41: 0.28 | J41: 0.3 | K41: 0.31 | L41: =L40/L36 -> 0.3002445 | M41: 0.35 | N41: 0.36 | O41: 0.33 | P41: 0.38 | Q41: =Q40/Q36 -> 0.35721138 | R41: 0.35 | S41: 0.35 | V41: =V40/V36 -> 0.35108959
B42: Global costs | C42: 0 | D42: 0 | E42: 0 | F42: 0 | G42: =SUM(C42:F42) -> 0 | H42: 0 | I42: 0 | J42: 0 | K42: 0 | L42: =SUM(H42:K42) -> 0 | M42: 0 | N42: 0 | O42: 0 | P42: 0 | Q42: =SUM(M42:P42) -> 0 | R42: 0 | S42: 0 | V42: =SUM(R42:U42) -> 0
...

Sheet Product type
C7: mai-juli | D7: aug-okt | E7: nov-jan | F7: feb-apr | H7: mai-juli | I7: aug-okt | J7: nov-jan | K7: feb-apr | M7: mai-juli | N7: aug-okt | O7: nov-jan | P7: feb-apr | R7: mai-juli | S7: aug-okt | T7: nov-jan | U7: feb-apr | W7: mai-juli | X7: aug-okt | Y7: nov-jan | Z7: feb-apr
B8: SEKm | C8: Q1 22/23 | D8: Q2 22/23 | E8: Q3 22/23 | F8: Q4 22/23 | G8: 22/23 | H8: Q1 23/24 | I8: Q2 23/24 | J8: Q3 23/24 | K8: Q4 23/24 | L8: 23/24 | M8: Q1 24/25 | N8: Q2 24/25 | O8: Q3 24/25 | P8: Q4 24/25 | Q8: 24/25 | R8: Q1 25/26 | S8: Q2 25/26 | T8: Q3 25/26 | U8: Q4 25/26 | V8: 25/26 | W8: Q1 26/27 | X8: Q2 26/27 | Y8: Q3 26/27 | Z8: Q4 26/27
B9: Solutions
B10: Americas | C10: 340 | D10: 572 | E10: 610 | F10: 801 | G10: =SUM(C10:F10) -> 2323 | H10: 305 | I10: 622 | J10: 707 | K10: 711 | L10: =SUM(H10:K10) -> 2345 | M10: 475 | N10: 498 | O10: 566 | P10: 642 | Q10: =SUM(M10:P10) -> 2181 | R10: 400 | S10: 367 | V10: =SUM(R10:U10) -> 767
B11: y/y | H11: =(H10-C10)/C10 -> -0.10294118 | I11: =(I10-D10)/D10 -> 0.087412587 | J11: =(J10-E10)/E10 -> 0.15901639 | K11: =(K10-F10)/F10 -> -0.11235955 | L11: =(L10-G10)/G10 -> 0.0094705123 | M11: =(M10-H10)/H10 -> 0.55737705 | N11: =(N10-I10)/I10 -> -0.19935691 | O11: =(O10-J10)/J10 -> -0.19943423 | ... V11: =(V10-Q10)/Q10 -> -0.64832646
B12: EMEA | C12: 632 | D12: 732 | E12: 936 | F12: 1203 | G12: =SUM(C12:F12) -> 3503 | H12: 855 | I12: 1051 | J12: 905 | K12: 1072 | L12: =SUM(H12:K12) -> 3883 | M12: 623 | N12: 880 | O12: 925 | P12: 1265 | Q12: =SUM(M12:P12) -> 3693 | R12: 711 | S12: 944 | V12: =SUM(R12:U12) -> 1655
B13: y/y | H13: =(H12-C12)/C12 -> 0.3528481 | I13: =(I12-D12)/D12 -> 0.43579235 | J13: =(J12-E12)/E12 -> -0.033119658 | K13: =(K12-F12)/F12 -> -0.10889443 | L13: =(L12-G12)/G12 -> 0.10847845 | M13: =(M12-H12)/H12 -> -0.27134503 | N13: =(N12-I12)/I12 -> -0.16270219 | O13: =(O12-J12)/J12 -> 0.022099448 | ... V13: =(V12-Q12)/Q12 -> -0.55185486
B14: APAC | C14: 734 | D14: 1019 | E14: 1082 | F14: 1320 | G14: =SUM(C14:F14) -> 4155 | H14: 834 | I14: 1162 | J14: 1131 | K14: 1277 | L14: =SUM(H14:K14) -> 4404 | M14: 817 | N14: 1079 | O14: 1182 | P14: 1279 | Q14: =SUM(M14:P14) -> 4357 | R14: 694 | S14: 893 | V14: =SUM(R14:U14) -> 1587
B15: y/y | H15: =(H14-C14)/C14 -> 0.13623978 | I15: =(I14-D14)/D14 -> 0.14033366 | J15: =(J14-E14)/E14 -> 0.045286506 | K15: =(K14-F14)/F14 -> -0.032575758 | L15: =(L14-G14)/G14 -> 0.059927798 | M15: =(M14-H14)/H14 -> -0.020383693 | N15: =(N14-I14)/I14 -> -0.071428571 | O15: =(O14-J14)/J14 -> 0.045092838 | ... V15: =(V14-Q14)/Q14 -> -0.63575855
B16: Total sales | C16: =C10+C12+C14 -> 1706 | D16: =D10+D12+D14 -> 2323 | E16: =E10+E12+E14 -> 2628 | F16: =F10+F12+F14 -> 3324 | G16: =SUM(C16:F16) -> 9981 | H16: =H10+H12+H14 -> 1994 | I16: =I10+I12+I14 -> 2835 | J16: =J10+J12+J14 -> 2743 | K16: =K10+K12+K14 -> 3060 | L16: =SUM(H16:K16) -> 10632 | M16: =M10+M12+M14 -> 1915 | N16: =N10+N12+N14 -> 2457 | O16: =O10+O12+O14 -> 2673 | P16: =P10+P12+P14 -> 3186 | Q16: =SUM(M16:P16) -> 10231 | R16: =R10+R12+R14 -> 1805 | S16: =S10+S12+S14 -> 2204 | T16: =T10+T12+T14 -> 0 | U16: =U10+U12+U14 -> 0 | V16: =SUM(R16:U16) -> 4009
B17: y/y | H17: =(H16-C16)/C16 -> 0.16881594 | I17: =(I16-D16)/D16 -> 0.22040465 | J17: =(J16-E16)/E16 -> 0.043759513 | K17: =(K16-F16)/F16 -> -0.079422383 | L17: =(L16-G16)/G16 -> 0.065223925 | M17: =(M16-H16)/H16 -> -0.039618857 | N17: =(N16-I16)/I16 -> -0.13333333 | O17: =(O16-J16)/J16 -> -0.025519504 | ... V17: =(V16-Q16)/Q16 -> -0.6081517
B18: y/y constant FX | C18: -0.01 | D18: -0.13 | E18: 0.12 | F18: 0.12 | H18: 0.09 | I18: 0.15 | J18: 0.04 | K18: -0.08 | M18: -0.03 | N18: -0.1 | O18: -0.04 | P18: 0.07 | R18: 0.01 | S18: -0.04
B20: Service
B21: Americas | C21: 697 | D21: 756 | E21: 732 | F21: 731 | G21: =SUM(C21:F21) -> 2916 | H21: 766 | I21: 782 | J21: 727 | K21: 815 | L21: =SUM(H21:K21) -> 3090 | M21: 766 | N21: 714 | O21: 792 | P21: 729 | Q21: =SUM(M21:P21) -> 3001 | R21: 671 | S21: 664 | V21: =SUM(R21:U21) -> 1335
B22: y/y | H22: =(H21-C21)/C21 -> 0.098995696 | I22: =(I21-D21)/D21 -> 0.034391534 | J22: =(J21-E21)/E21 -> -0.0068306011 | K22: =(K21-F21)/F21 -> 0.11491108 | L22: =(L21-G21)/G21 -> 0.059670782 | M22: =(M21-H21)/H21 -> 0 | N22: =(N21-I21)/I21 -> -0.086956522 | O22: =(O21-J21)/J21 -> 0.089408528 | ... V22: =(V21-Q21)/Q21 -> -0.55514828
B23: EMEA | C23: 559 | D23: 600 | E23: 588 | F23: 657 | G23: =SUM(C23:F23) -> 2404 | H23: 542 | I23: 681 | J23: 645 | K23: 697 | L23: =SUM(H23:K23) -> 2565 | M23: 691 | N23: 717 | O23: 729 | P23: 749 | Q23: =SUM(M23:P23) -> 2886 | R23: 733 | S23: 749 | V23: =SUM(R23:U23) -> 1482
B24: y/y | H24: =(H23-C23)/C23 -> -0.030411449 | I24: =(I23-D23)/D23 -> 0.135 | J24: =(J23-E23)/E23 -> 0.096938776 | K24: =(K23-F23)/F23 -> 0.060882801 | L24: =(L23-G23)/G23 -> 0.066971714 | M24: =(M23-H23)/H23 -> 0.27490775 | N24: =(N23-I23)/I23 -> 0.052863436 | O24: =(O23-J23)/J23 -> 0.13023256 | ... V24: =(V23-Q23)/Q23 -> -0.48648649
B25: APAC | C25: 365 | D25: 403 | E25: 389 | F25: 412 | G25: =SUM(C25:F25) -> 1569 | H25: 425 | I25: 433 | J25: 422 | K25: 450 | L25: =SUM(H25:K25) -> 1730 | M25: 453 | N25: 452 | O25: 499 | P25: 491 | Q25: =SUM(M25:P25) -> 1895 | R25: 438 | S25: 452 | V25: =SUM(R25:U25) -> 890
B26: y/y | H26: =(H25-C25)/C25 -> 0.16438356 | I26: =(I25-D25)/D25 -> 0.074441687 | J26: =(J25-E25)/E25 -> 0.084832905 | K26: =(K25-F25)/F25 -> 0.09223301 | L26: =(L25-G25)/G25 -> 0.10261313 | M26: =(M25-H25)/H25 -> 0.065882353 | N26: =(N25-I25)/I25 -> 0.043879908 | O26: =(O25-J25)/J25 -> 0.18246445 | ... V26: =(V25-Q25)/Q25 -> -0.53034301
B27: Total sales | C27: =C21+C23+C25 -> 1621 | D27: =D21+D23+D25 -> 1759 | E27: =E21+E23+E25 -> 1709 | F27: =F21+F23+F25 -> 1800 | G27: =SUM(C27:F27) -> 6889 | H27: =H21+H23+H25 -> 1733 | I27: =I21+I23+I25 -> 1896 | J27: =J21+J23+J25 -> 1794 | K27: =K21+K23+K25 -> 1962 | L27: =SUM(H27:K27) -> 7385 | M27: =M21+M23+M25 -> 1910 | N27: =N21+N23+N25 -> 1883 | O27: =O21+O23+O25 -> 2020 | P27: =P21+P23+P25 -> 1969 | Q27: =SUM(M27:P27) -> 7782 | R27: =R21+R23+R25 -> 1842 | S27: =S21+S23+S25 -> 1865 | T27: =T21+T23+T25 -> 0 | U27: =U21+U23+U25 -> 0 | V27: =SUM(R27:U27) -> 3707
B28: y/y | H28: =(H27-C27)/C27 -> 0.069093152 | I28: =(I27-D27)/D27 -> 0.077885162 | J28: =(J27-E27)/E27 -> 0.049736688 | K28: =(K27-F27)/F27 -> 0.09 | L28: =(L27-G27)/G27 -> 0.071998839 | M28: =(M27-H27)/H27 -> 0.10213503 | N28: =(N27-I27)/I27 -> -0.0068565401 | O28: =(O27-J27)/J27 -> 0.12597547 | ... V28: =(V27-Q27)/Q27 -> -0.52364431
B29: y/y constant FX | C29: 0.06 | D29: 0.07 | E29: 0.03 | F29: 0.07 | H29: 0.07 | I29: 0.04 | J29: 0.05 | K29: 0.09 | M29: 0.05 | N29: 0.04 | O29: 0.1 | P29: 0.04 | R29: 0.04 | S29: 0.07

Sheet Nøkkeltall
D4: 25/26 | E4: 26/27 | F4: 27/28
C5: EV/EBIT | D5: =Modell!$B$9/Modell!AF12 -> 15.548474 | E5: =Modell!$B$9/Modell!AG12 -> 12.326811 | F5: =Modell!$B$9/Modell!AH12 -> 10.620664
C6: P/E | D6: =Modell!$B$4/Modell!AF18 -> 16.74097 | E6: =Modell!$B$4/Modell!AG18 -> 13.27222 | F6: =Modell!$B$4/Modell!AH18 -> 11.435219

Sheet Nedsideberegning
A3: Nedside | D3: FY 15/16 | E3: FY 16/17 | F3: FY 17/18 | G3: FY 18/19 | H3: FY 19/20 | I3: FY 20/21 | J3: FY 21/22 | K3: FY 22/23 | L3: FY 23/24 | M3: FY 24/25 | N3: FY 25/26 | O3: FY 26/27 | P3: FY 27/28 | Q3: FY 28/29 | R3: FY 29/30 | S3: FY 30/31 | T3: FY 31/32 | U3: FY 32/33 | V3: FY 33/34 | W3: FY 34/35 | X3: FY 35/36
A4: Null vekst og dårligste marginer | C4: Revenue | D4: 11221 | E4: 10704 | F4: 11573 | G4: 13555 | H4: 14601 | I4: 13763 | J4: 14548 | K4: 16869 | L4: 18119 | M4: 18016 | N4: =M4 -> 18016 | O4: =N4 -> 18016 | P4: =O4 -> 18016 | Q4: =P4 -> 18016 | R4: =Q4 -> 18016 | S4: =R4 -> 18016 | T4: =S4 -> 18016 | U4: =T4 -> 18016 | ... X4: =W4 -> 18016
A5: =AA23 -> 39.359572 | C5: COGS | D5: -6608 | E5: -6277 | F5: -6517 | G5: -7875 | H5: -8464 | I5: -8153 | J5: -9111 | K5: -10520 | L5: -11342 | M5: -11270 | N5: =N4*-0.64 -> -11530.24 | O5: =O4*-0.64 -> -11530.24 | P5: =P4*-0.64 -> -11530.24 | Q5: =Q4*-0.64 -> -11530.24 | R5: =R4*-0.64 -> -11530.24 | S5: =S4*-0.64 -> -11530.24 | T5: =T4*-0.64 -> -11530.24 | U5: =U4*-0.64 -> -11530.24 | ... X5: =X4*-0.64 -> -11530.24
A6: =AA24 -> -0.38500668 | C6: Gross profit | D6: =SUM(D4:D5) -> 4613 | E6: =SUM(E4:E5) -> 4427 | F6: =SUM(F4:F5) -> 5056 | G6: =SUM(G4:G5) -> 5680 | H6: =SUM(H4:H5) -> 6137 | I6: =SUM(I4:I5) -> 5610 | J6: =SUM(J4:J5) -> 5437 | K6: =SUM(K4:K5) -> 6349 | ... X6: =SUM(X4:X5) -> 6485.76
C7: Selling expenses | D7: -1336 | E7: -1165 | F7: -1208 | G7: -1296 | H7: -1444 | I7: -1143 | J7: -1355 | K7: -1603 | L7: -1641 | M7: -1650 | N7: =M7*0.85 -> -1402.5 | O7: =N7 -> -1402.5 | P7: =O7 -> -1402.5 | Q7: =P7 -> -1402.5 | R7: =Q7 -> -1402.5 | S7: =R7 -> -1402.5 | T7: =S7 -> -1402.5 | U7: =T7 -> -1402.5 | V7: =U7 -> -1402.5 | ... X7: =W7 -> -1402.5
C8: Adminstrative expenses | D8: -1026 | E8: -928 | F8: -949 | G8: -1039 | H8: -1093 | I8: -1086 | J8: -1173 | K8: -1398 | L8: -1370 | M8: -1412 | N8: =M8*0.8 -> -1129.6 | O8: =N8 -> -1129.6 | P8: =O8 -> -1129.6 | Q8: =P8 -> -1129.6 | R8: =Q8 -> -1129.6 | S8: =R8 -> -1129.6 | T8: =S8 -> -1129.6 | U8: =T8 -> -1129.6 | V8: =U8 -> -1129.6 | ... X8: =W8 -> -1129.6
C9: R&D expenses | D9: -1065 | E9: -1018 | F9: -1095 | G9: -1592 | H9: -1657 | I9: -1486 | J9: -1372 | K9: -1418 | L9: -1404 | M9: -2676 | N9: =M9*0.85 -> -2274.6 | O9: =N9 -> -2274.6 | P9: =O9 -> -2274.6 | Q9: =P9 -> -2274.6 | R9: =Q9 -> -2274.6 | S9: =R9 -> -2274.6 | T9: =S9 -> -2274.6 | U9: =T9 -> -2274.6 | V9: =U9 -> -2274.6 | ... X9: =W9 -> -2274.6
C10: Other operatign income/expense | D10: -598 | E10: -518 | F10: 0 | G10: 23 | H10: 11 | I10: -85 | J10: -48 | K10: -65 | L10: -102 | M10: -108 | N10: =M10*0.8 -> -86.4 | O10: =N10 -> -86.4 | P10: =O10 -> -86.4 | Q10: =P10 -> -86.4 | R10: =Q10 -> -86.4 | S10: =R10 -> -86.4 | T10: =S10 -> -86.4 | U10: =T10 -> -86.4 | V10: =U10 -> -86.4 | ... X10: =W10 -> -86.4
C11: Exchange rate diff | D11: -165 | E11: -201 | F11: 42 | G11: -80 | H11: -298 | I11: 97 | J11: 155 | K11: -434 | L11: -221 | M11: -9 | N11: =M11*0.8 -> -7.2 | O11: =N11 -> -7.2 | P11: =O11 -> -7.2 | Q11: =P11 -> -7.2 | R11: =Q11 -> -7.2 | S11: =R11 -> -7.2 | T11: =S11 -> -7.2 | U11: =T11 -> -7.2 | V11: =U11 -> -7.2 | ... X11: =W11 -> -7.2
C12: Operating profit (EBIT) | D12: =SUM(D6:D11) -> 423 | E12: =SUM(E6:E11) -> 597 | F12: =SUM(F6:F11) -> 1846 | G12: =SUM(G6:G11) -> 1696 | H12: =SUM(H6:H11) -> 1656 | I12: =SUM(I6:I11) -> 1907 | J12: =SUM(J6:J11) -> 1644 | K12: =SUM(K6:K11) -> 1431 | ... X12: =SUM(X6:X11) -> 1585.46
C13: Financial items, net | D13: =11+37-285+3 -> -234 | E13: =-17+31-271-1 -> -258 | F13: =-7+67-225+1 -> -164 | G13: =3+66-186+2 -> -115 | H13: =-4+63-215-51+4 -> -203 | I13: =-7+30-253-41-5 -> -276 | J13: =5+42-159-41+12 -> -141 | K13: =1+79-272-38-3 -> -233 | L13: -371 | M13: -400 | N13: 0 | O13: 0 | P13: 0 | Q13: 0 | R13: 0 | S13: 0 | T13: 0 | U13: 0 | V13: 0 | W13: 0 | X13: 0
C14: PTP | D14: =SUM(D12:D13) -> 189 | E14: =SUM(E12:E13) -> 339 | F14: =SUM(F12:F13) -> 1682 | G14: =SUM(G12:G13) -> 1581 | H14: =SUM(H12:H13) -> 1453 | I14: =SUM(I12:I13) -> 1631 | J14: =SUM(J12:J13) -> 1503 | K14: =SUM(K12:K13) -> 1198 | ... X14: =SUM(X12:X13) -> 1585.46
C15: Tax | D15: -44 | E15: -214 | F15: -333 | G15: -382 | H15: -370 | I15: -377 | J15: -345 | K15: -254 | L15: -365 | M15: -250 | N15: =N14*-0.2 -> -317.092 | O15: =O14*-0.2 -> -317.092 | P15: =P14*-0.2 -> -317.092 | Q15: =Q14*-0.2 -> -317.092 | R15: =R14*-0.2 -> -317.092 | S15: =S14*-0.2 -> -317.092 | T15: =T14*-0.2 -> -317.092 | U15: =U14*-0.2 -> -317.092 | ... X15: =X14*-0.2 -> -317.092
C16: Net income | D16: =SUM(D14:D15) -> 145 | E16: =SUM(E14:E15) -> 125 | F16: =SUM(F14:F15) -> 1349 | G16: =SUM(G14:G15) -> 1199 | H16: =SUM(H14:H15) -> 1083 | I16: =SUM(I14:I15) -> 1254 | J16: =SUM(J14:J15) -> 1158 | K16: =SUM(K14:K15) -> 944 | ... X16: =SUM(X14:X15) -> 1268.368 | Y16: =X16*(1+$AA$20) -> 1255.6843 | Z16: =Y16*(1+$AA$20) -> 1243.1275 | AA16: =Z16*(1+$AA$20) -> 1230.6962 | AB16: =AA16*(1+$AA$20) -> 1218.3892 | AC16: =AB16*(1+$AA$20) -> 1206.2053 | AD16: =AC16*(1+$AA$20) -> 1194.1433 | AE16: =AD16*(1+$AA$20) -> 1182.2019 | AF16: =AE16*(1+$AA$20) -> 1170.3798 | ... GD16: =GC16*(1+$AA$20) -> 248.96988
C17: Share | D17: 382.083 | E17: 382.083 | F17: 382.083 | G17: 382.083 | H17: 382.083 | I17: 382.083 | J17: 382.083 | K17: 382.083 | L17: 382.083 | M17: 382.083 | N17: 382.083 | O17: 382.083 | P17: 382.083 | Q17: 382.083 | R17: 382.083 | S17: 382.083 | T17: 382.083 | U17: 382.083 | V17: 382.083 | W17: 382.083 | X17: 382.083
C18: EPS | D18: =D16/D17 -> 0.3794987 | E18: =E16/E17 -> 0.32715405 | F18: =F16/F17 -> 3.5306465 | G18: =G16/G17 -> 3.1380616 | H18: =H16/H17 -> 2.8344627 | I18: =I16/I17 -> 3.2820094 | J18: =J16/J17 -> 3.0307551 | K18: =K16/K17 -> 2.4706674 | ... X18: =X16/X17 -> 3.3196138
Z19: Discount | AA19: 0.08
C20: Revenue y/y | E20: =(E4-D4)/D4 -> -0.046074325 | F20: =(F4-E4)/E4 -> 0.081184604 | G20: =(G4-F4)/F4 -> 0.17126069 | H20: =(H4-G4)/G4 -> 0.077167097 | I20: =(I4-H4)/H4 -> -0.057393329 | J20: =(J4-I4)/I4 -> 0.057036983 | K20: =(K4-J4)/J4 -> 0.15954083 | L20: =(L4-K4)/K4 -> 0.074100421 | ... X20: =(X4-W4)/W4 -> 0 | Z20: TV | AA20: -0.01
C21: Gross margin | D21: =D6/D4 -> 0.41110418 | E21: =E6/E4 -> 0.41358371 | F21: =F6/F4 -> 0.43687894 | G21: =G6/G4 -> 0.41903357 | H21: =H6/H4 -> 0.42031368 | I21: =I6/I4 -> 0.40761462 | J21: =J6/J4 -> 0.37372835 | K21: =K6/K4 -> 0.37637086 | ... X21: =X6/X4 -> 0.36 | Z21: NPV | AA21: =NPV(AA19,N16:GD16) -> 15038.624
C22: EBIT margin | D22: =D12/D4 -> 0.037697175 | E22: =E12/E4 -> 0.055773543 | F22: =F12/F4 -> 0.1595092 | G22: =G12/G4 -> 0.12511988 | H22: =H12/H4 -> 0.11341689 | I22: =I12/I4 -> 0.13855991 | J22: =J12/J4 -> 0.11300522 | K22: =K12/K4 -> 0.084830162 | ... X22: =X12/X4 -> 0.088002886 | Z22: S/O | AA22: 382.083
D23: 0.04 | E23: 0.05 | F23: 0.17 | G23: 0.15 | H23: 0.12 | I23: 0.12 | J23: 0.12 | K23: 0.1 | L23: 0.12 | M23: 0.06 | Z23: NPV/Share | AA23: =AA21/AA22 -> 39.359572
Z24: Opp-/nedside | AA24: =(AA23-Modell!B4)/Modell!B4 -> -0.38500668
