Workbook

Sheet Info
A1: Elektroimportøren er Norges 4 største el-grossist.
A2: De har 29 butikker i Norge og 1 i Sverige gjennom oppkjøpet av Elbutik AB
A5: Namron er Elimp sitt eget varemerke og ble etablert i 2007.
A6: Namron har raskt blitt en markedaleder innenfor lys, varme kabler, elektromateriell og smarthusløsninger
A8: SpotOn er Elimp sin unike tjeneste som gjør det enkelt å få jobben gjort trygt og effektivt. Spoton lar kunden bestille produjter og tjenseter, inkludert montering, til en fast pris
A9: Spoton leverer fagmessig arbeid utføert av sertifiserte elektrikere
A10: Spoton ble integrert inn i Elimp fra Q424
A30: Press releases:
A31: 12.02.26: Styret og CEO Andreas Niss har blitt enig om at Niss skal gå av som CEO etter 12 år i jobben. Niss vil være i rollen sin frem til 15.mai 26
A32: 19.03.24: Kjørte en rep-emi og fikk inn 30m
A33: 14.02.24: hentet 150m til 7,5kr

Sheet Modell
A3: Kapitalstruktur | C3: NOK million | D3: Q122 | E3: Q222 | F3: Q322 | G3: Q422 | H3: Q123 | I3: Q223 | J3: Q323 | K3: Q423 | L3: Q124 | M3: Q224 | N3: Q324 | O3: Q424 | P3: Q125 | Q3: Q225 | R3: Q325 | S3: Q425 | T3: Q126 | U3: Q226 | V3: Q326 | W3: Q426 | Z3: FY 2015 | AA3: FY 2016 | AB3: FY 2017 | AC3: FY 2018 | AD3: FY 2019 | AE3: FY 2020 | AF3: FY 2021 | AG3: FY 2022 | AH3: FY 2023 | AI3: FY 2024 | AJ3: FY 2025 | AK3: FY 2026 | AL3: FY 2027 | AM3: FY 2028 | AN3: FY 2029 | AO3: FY 2030 | AP3: FY 2031 | AQ3: FY 2032 | AR3: FY 2033 | AS3: FY 2034 | AT3: FY 2035
A4: Price | B4: 15.1 | C4: Revenue | D4: 367 | E4: 358 | F4: 398 | G4: 502 | H4: 383 | I4: 326 | J4: 401 | K4: 495 | L4: 350 | M4: 349 | N4: 407 | O4: 520 | P4: 396 | Q4: 367.2 | R4: 436.4 | S4: 588.8 | T4: 430.6 | Z4: 277.829 | AA4: 417.451 | AB4: 593.77549 | AC4: 786.56742 | AD4: 964.15985 | AE4: 1315.894 | AF4: 1485.33 | AG4: 1625 | AH4: 1605 | AI4: 1626 | AJ4: 1788.4 | AK4: =AJ4*1.09 -> 1949.356 | AL4: =AK4*1.07 -> 2085.8109 | AM4: =AL4*1.07 -> 2231.8177 | AN4: =AM4*1.07 -> 2388.0449 | AO4: =AN4*1.07 -> 2555.2081 | AP4: =AO4*1.07 -> 2734.0726 | AQ4: =AP4*1.07 -> 2925.4577 | AR4: =AQ4*1.07 -> 3130.2398 | AS4: =AR4*1.07 -> 3349.3565 | AT4: =AS4*1.07 -> 3583.8115
A5: S/O | B5: 50.7822 | C5: COGS | D5: -230 | E5: -232 | F5: -248 | G5: -308 | H5: -246 | I5: -213 | J5: -259 | K5: -332 | L5: -229 | M5: -236 | N5: -271 | O5: -338 | P5: -253 | Q5: -238.3 | R5: -276.2 | S5: -383 | T5: -272.8 | Z5: -153.393 | AA5: -231.157 | AB5: -336.04035 | AC5: -464.25608 | AD5: -589.66906 | AE5: -798.389 | AF5: -912.305 | AG5: -1018 | AH5: -1050 | AI5: -1074 | AJ5: -1150.5 | AK5: =AK4*-0.635 -> -1237.8411 | AL5: =AL4*-0.63 -> -1314.0609 | AM5: =AM4*-0.63 -> -1406.0451 | AN5: =AN4*-0.63 -> -1504.4683 | AO5: =AO4*-0.63 -> -1609.7811 | AP5: =AP4*-0.63 -> -1722.4658 | AQ5: =AQ4*-0.63 -> -1843.0384 | AR5: =AR4*-0.63 -> -1972.051 | AS5: =AS4*-0.63 -> -2110.0946 | AT5: =AT4*-0.63 -> -2257.8012
A6: MC NOKm | B6: =B4*B5 -> 766.81122 | C6: Gross profit | D6: =SUM(D4:D5) -> 137 | E6: =SUM(E4:E5) -> 126 | F6: =SUM(F4:F5) -> 150 | G6: =SUM(G4:G5) -> 194 | H6: =SUM(H4:H5) -> 137 | I6: =SUM(I4:I5) -> 113 | J6: =SUM(J4:J5) -> 142 | K6: =SUM(K4:K5) -> 163 | ... T6: =SUM(T4:T5) -> 157.8 | Z6: =SUM(Z4:Z5) -> 124.436 | AA6: =SUM(AA4:AA5) -> 186.294 | AB6: =SUM(AB4:AB5) -> 257.73514 | AC6: =SUM(AC4:AC5) -> 322.31134 | AD6: =SUM(AD4:AD5) -> 374.49079 | AE6: =SUM(AE4:AE5) -> 517.505 | AF6: =SUM(AF4:AF5) -> 573.025 | AG6: =SUM(AG4:AG5) -> 607 | ... AT6: =SUM(AT4:AT5) -> 1326.0103
A7: Cash NOKm | B7: =T41 -> 136.6 | C7: Employee benefits exp | D7: -63 | E7: -47 | F7: -70.543 | G7: -74 | H7: -68 | I7: -52 | J7: -75 | K7: -77 | L7: -65 | M7: -48 | N7: -74 | O7: -79 | P7: -73 | Q7: -54.5 | R7: -79.3 | S7: -89 | T7: =-81.4+1.9 -> -79.5 | Z7: -50.324 | AA7: -80.6 | AB7: -117.86964 | AC7: -144.4926 | AD7: -176.14434 | AE7: -219.294 | AF7: -243.321 | AG7: -255 | AH7: -272 | AI7: -266 | AJ7: -295.8 | AK7: =AJ7*1.05 -> -310.59 | AL7: =AK7*1.07 -> -332.3313 | AM7: =AL7*1.07 -> -355.59449 | AN7: =AM7*1.07 -> -380.48611 | AO7: =AN7*1.07 -> -407.12013 | AP7: =AO7*1.07 -> -435.61854 | AQ7: =AP7*1.07 -> -466.11184 | AR7: =AQ7*1.07 -> -498.73967 | AS7: =AR7*1.07 -> -533.65145 | AT7: =AS7*1.07 -> -571.00705
A8: Debt NOKm | B8: =T48+T51+T47+T50 -> 631.2 | C8: D/A | D8: -22 | E8: -23 | F8: -23.71 | G8: -23 | H8: -25 | I8: -26 | J8: -26 | K8: -19 | L8: -28 | M8: -25 | N8: -29 | O8: -29 | P8: -29 | Q8: -29.5 | R8: -29.7 | S8: -27.8 | T8: -30.7 | Z8: -13.54 | AA8: =-16.943 -> -16.943 | AB8: =-21.263035-3.145 -> -24.408035 | AC8: =-27.230979-2.46 -> -29.690979 | AD8: =-28.105644-0.736 -> -28.841644 | AE8: -70.74 | AF8: -77.325 | AG8: -92 | AH8: -96 | AI8: -111 | AJ8: -116 | AK8: =AJ8*1.06 -> -122.96 | AL8: =AK8*1.07 -> -131.5672 | AM8: =AL8*1.07 -> -140.7769 | AN8: =AM8*1.07 -> -150.63129 | AO8: =AN8*1.07 -> -161.17548 | AP8: =AO8*1.07 -> -172.45776 | AQ8: =AP8*1.07 -> -184.5298 | AR8: =AQ8*1.07 -> -197.44689 | AS8: =AR8*1.07 -> -211.26817 | AT8: =AS8*1.07 -> -226.05694
A9: EV NOKm | B9: =B6-B7+B8 -> 1261.4112 | C9: Other opex | D9: -30 | E9: -29 | F9: -34 | G9: -50 | H9: -37 | I9: -30 | J9: -38 | K9: -40 | L9: -32 | M9: -35 | N9: -33 | O9: -38 | P9: -34 | Q9: -34.7 | R9: -32.8 | S9: -47.1 | T9: -40.3 | Z9: -38.486 | AA9: -56.4 | AB9: -75.756888 | AC9: -106.936 | AD9: -121.10791 | AE9: -94.081 | AF9: -107.446 | AG9: -146 | AH9: -145 | AI9: -138 | AJ9: -148.6 | AK9: =AJ9*1.06 -> -157.516 | AL9: =AK9*1.07 -> -168.54212 | AM9: =AL9*1.07 -> -180.34007 | AN9: =AM9*1.07 -> -192.96387 | AO9: =AN9*1.07 -> -206.47134 | AP9: =AO9*1.07 -> -220.92434 | AQ9: =AP9*1.07 -> -236.38904 | AR9: =AQ9*1.07 -> -252.93628 | AS9: =AR9*1.07 -> -270.64181 | AT9: =AS9*1.07 -> -289.58674
C10: Total opex | D10: =D5+D7+D8+D9 -> -345 | E10: =E5+E7+E8+E9 -> -331 | F10: =F5+F7+F8+F9 -> -376.253 | G10: =G5+G7+G8+G9 -> -455 | H10: =H5+H7+H8+H9 -> -376 | I10: =I5+I7+I8+I9 -> -321 | J10: =J5+J7+J8+J9 -> -398 | K10: =K5+K7+K8+K9 -> -468 | ... T10: =T5+T7+T8+T9 -> -423.3 | Z10: =Z5+Z7+Z8+Z9 -> -255.743 | AA10: =AA5+AA7+AA8+AA9 -> -385.1 | AB10: =AB5+AB7+AB8+AB9 -> -554.07492 | AC10: =AC5+AC7+AC8+AC9 -> -745.37566 | AD10: =AD5+AD7+AD8+AD9 -> -915.76295 | AE10: =AE5+AE7+AE8+AE9 -> -1182.504 | AF10: =AF5+AF7+AF8+AF9 -> -1340.397 | AG10: =AG5+AG7+AG8+AG9 -> -1511 | ... AT10: =AT5+AT7+AT8+AT9 -> -3344.452
C11: Operating profit (EBIT) | D11: =D4+D10 -> 22 | E11: =E4+E10 -> 27 | F11: =F4+F10 -> 21.747 | G11: =G4+G10 -> 47 | H11: =H4+H10 -> 7 | I11: =I4+I10 -> 5 | J11: =J4+J10 -> 3 | K11: =K4+K10 -> 27 | ... T11: =T4+T10 -> 7.3 | Z11: =Z4+Z10 -> 22.086 | AA11: =AA4+AA10 -> 32.351 | AB11: =AB4+AB10 -> 39.700577 | AC11: =AC4+AC10 -> 41.191759 | AD11: =AD4+AD10 -> 48.396899 | AE11: =AE4+AE10 -> 133.39 | AF11: =AF4+AF10 -> 144.933 | AG11: =AG4+AG10 -> 114 | ... AT11: =AT4+AT10 -> 239.35952
C12: Net financials | D12: -8 | E12: -8 | F12: -7 | G12: -23 | H12: -12 | I12: -14 | J12: -12 | K12: -18 | L12: -8 | M12: -12 | N12: 30 | O12: -5 | P12: -16 | Q12: -9.9 | R12: -9.2 | S12: -2.6 | T12: -13.7 | Z12: -8.496 | AA12: -9.4 | AB12: -15.442 | AC12: -18.718 | AD12: -15 | AE12: -29.196 | AF12: -20.354 | AG12: -46 | AH12: -56 | AI12: 5 | AJ12: -37.7 | AK12: -30 | AL12: -30 | AM12: -30 | AN12: -30 | AO12: -30 | AP12: -30 | AQ12: -30 | AR12: -30 | AS12: -30 | AT12: -30
A13: NIBD/EBITDA | B13: =(B8-B7)/AK26 -> 2.0319714 | C13: PTP | D13: =SUM(D11:D12) -> 14 | E13: =SUM(E11:E12) -> 19 | F13: =SUM(F11:F12) -> 14.747 | G13: =SUM(G11:G12) -> 24 | H13: =SUM(H11:H12) -> -5 | I13: =SUM(I11:I12) -> -9 | J13: =SUM(J11:J12) -> -9 | K13: =SUM(K11:K12) -> 9 | ... T13: =SUM(T11:T12) -> -6.4 | Z13: =SUM(Z11:Z12) -> 13.59 | AA13: =SUM(AA11:AA12) -> 22.951 | AB13: =SUM(AB11:AB12) -> 24.258577 | AC13: =SUM(AC11:AC12) -> 22.473759 | AD13: =SUM(AD11:AD12) -> 33.396899 | AE13: =SUM(AE11:AE12) -> 104.194 | AF13: =SUM(AF11:AF12) -> 124.579 | AG13: =SUM(AG11:AG12) -> 68 | ... AT13: =SUM(AT11:AT12) -> 209.35952
C14: Tax | D14: -3 | E14: -4 | F14: -3 | G14: -7 | H14: 1 | I14: 2 | J14: 3 | K14: -2 | L14: 1 | M14: 2 | N14: 2 | O14: -9 | P14: 2 | Q14: -0.1 | R14: -2.1 | S14: -7.4 | T14: 1.3 | Z14: -6.7 | AA14: -9 | AB14: -9.5 | AC14: -7.9 | AD14: -9.6 | AE14: -22.919 | AF14: -27.328 | AG14: -17 | AH14: 4 | AI14: -4 | AJ14: -7.6 | AK14: =AK13*-0.22 -> -19.898767 | AL14: =AL13*-0.22 -> -24.048072 | AM14: =AM13*-0.22 -> -26.193438 | AN14: =AN13*-0.22 -> -28.488978 | AO14: =AO13*-0.22 -> -30.945207 | AP14: =AP13*-0.22 -> -33.573371 | AQ14: =AQ13*-0.22 -> -36.385507 | AR14: =AR13*-0.22 -> -39.394493 | ... AT14: =AT13*-0.22 -> -46.059095
A15: NIBD/EBITDA ex lease | B15: =(T48+T51)/T28 -> 0.9202454 | C15: Net income | D15: =SUM(D13:D14) -> 11 | E15: =SUM(E13:E14) -> 15 | F15: =SUM(F13:F14) -> 11.747 | G15: =SUM(G13:G14) -> 17 | H15: =SUM(H13:H14) -> -4 | I15: =SUM(I13:I14) -> -7 | J15: =SUM(J13:J14) -> -6 | K15: =SUM(K13:K14) -> 7 | ... T15: =SUM(T13:T14) -> -5.1 | Z15: =SUM(Z13:Z14) -> 6.89 | AA15: =SUM(AA13:AA14) -> 13.951 | AB15: =SUM(AB13:AB14) -> 14.758577 | AC15: =SUM(AC13:AC14) -> 14.573759 | AD15: =SUM(AD13:AD14) -> 23.796899 | AE15: =SUM(AE13:AE14) -> 81.275 | AF15: =SUM(AF13:AF14) -> 97.251 | AG15: =SUM(AG13:AG14) -> 51 | ... AT15: =SUM(AT13:AT14) -> 163.30043 | AU15: =AT15*(1+$AW$18) -> 161.66742 | AV15: =AU15*(1+$AW$18) -> 160.05075 | AW15: =AV15*(1+$AW$18) -> 158.45024 | AX15: =AW15*(1+$AW$18) -> 156.86574 | AY15: =AX15*(1+$AW$18) -> 155.29708 | AZ15: =AY15*(1+$AW$18) -> 153.74411 | BA15: =AZ15*(1+$AW$18) -> 152.20667 | BB15: =BA15*(1+$AW$18) -> 150.6846 | ... EK15: =EJ15*(1+$AW$18) -> 62.853694
C16: Shares | D16: 22.7822 | E16: 22.7822 | F16: 25.7822 | G16: 20.7822 | H16: 22.7822 | I16: 22.7822 | J16: 25.7822 | K16: 25.7822 | L16: 50.8 | M16: 50.7822 | N16: 50.7822 | O16: 50.7822 | P16: 50.7822 | Q16: 50.7822 | R16: 50.7822 | S16: 50.7822 | T16: 50.7822 | AE16: 21.3 | AF16: 21.3 | AG16: 50.7822 | AH16: 50.7822 | AI16: 50.7822 | AJ16: 50.7822 | AK16: 50.7822 | AL16: 50.7822 | AM16: 50.7822 | AN16: 50.7822 | AO16: 50.7822 | AP16: 50.7822 | AQ16: 50.7822 | AR16: 50.7822 | AS16: 50.7822 | AT16: 50.7822
A17: Covenant ex lease | B17: 3.5 | C17: EPS | D17: =D15/D16 -> 0.48283309 | E17: =E15/E16 -> 0.65840876 | F17: =F15/F16 -> 0.45562442 | G17: =G15/G16 -> 0.81800772 | H17: =H15/H16 -> -0.17557567 | I17: =I15/I16 -> -0.30725742 | J17: =J15/J16 -> -0.2327187 | K17: =K15/K16 -> 0.27150515 | ... T17: =T15/T16 -> -0.10042889 | AE17: =AE15/AE16 -> 3.8157277 | AF17: =AF15/AF16 -> 4.5657746 | AG17: =AG15/AG16 -> 1.0042889 | AH17: =AH15/AH16 -> -0.19691939 | AI17: =AI15/AI16 -> 0.74829369 | AJ17: =AJ15/AJ16 -> 0.63408045 | AK17: =AK15/AK16 -> 1.3892697 | AL17: =AL15/AL16 -> 1.6789613 | ... AT17: =AT15/AT16 -> 3.2157021 | AV17: Discount | AW17: 0.08
AV18: TV | AW18: -0.01
C19: Revenue y/y | D19: 0.063 | E19: 0.116 | F19: 0.106 | G19: 0.094 | H19: =(H4-D4)/D4 -> 0.04359673 | I19: =(I4-E4)/E4 -> -0.089385475 | J19: =(J4-F4)/F4 -> 0.0075376884 | K19: =(K4-G4)/G4 -> -0.013944223 | L19: =(L4-H4)/H4 -> -0.08616188 | M19: =(M4-I4)/I4 -> 0.070552147 | N19: =(N4-J4)/J4 -> 0.014962594 | O19: =(O4-K4)/K4 -> 0.050505051 | ... T19: =(T4-P4)/P4 -> 0.087373737 | AA19: =(AA4-Z4)/Z4 -> 0.50254653 | AB19: =(AB4-AA4)/AA4 -> 0.42238369 | AC19: =(AC4-AB4)/AB4 -> 0.32468825 | AD19: =(AD4-AC4)/AC4 -> 0.22578157 | AE19: =(AE4-AD4)/AD4 -> 0.36480896 | AF19: =(AF4-AE4)/AE4 -> 0.12876113 | AG19: =(AG4-AF4)/AF4 -> 0.094032976 | AH19: =(AH4-AG4)/AG4 -> -0.012307692 | ... AT19: =(AT4-AS4)/AS4 -> 0.07 | AV19: NPV | AW19: =NPV(AW17,AJ15:EK15) -> 1483.3727
C20: Like-for-like y/y | D20: -0.012 | E20: -0.024 | F20: -0.014 | G20: -0.025 | H20: -0.032 | I20: -0.107 | J20: -0.033 | K20: -0.041 | L20: -0.102 | M20: 0.044 | N20: 0.011 | O20: 0.018 | P20: 0.088 | Q20: 0.013 | R20: 0.036 | S20: 0.076 | T20: 0.049 | AV20: S/O | AW20: 50.7822
C21: Opex y/y | H21: =(H10-D10)/D10 -> 0.089855072 | I21: =(I10-E10)/E10 -> -0.03021148 | J21: =(J10-F10)/F10 -> 0.057798875 | K21: =(K10-G10)/G10 -> 0.028571429 | L21: =(L10-H10)/H10 -> -0.058510638 | M21: =(M10-I10)/I10 -> 0.07165109 | N21: =(N10-J10)/J10 -> 0.022613065 | O21: =(O10-K10)/K10 -> 0.034188034 | ... T21: =(T10-P10)/P10 -> 0.088174807 | AA21: =(AA10-Z10)/Z10 -> 0.50580857 | AB21: =(AB10-AA10)/AA10 -> 0.43878192 | AC21: =(AC10-AB10)/AB10 -> 0.34526151 | AD21: =(AD10-AC10)/AC10 -> 0.2285925 | AE21: =(AE10-AD10)/AD10 -> 0.2912774 | AF21: =(AF10-AE10)/AE10 -> 0.13352428 | AG21: =(AG10-AF10)/AF10 -> 0.12727796 | AH21: =(AH10-AG10)/AG10 -> 0.034414295 | ... AT21: =(AT10-AS10)/AS10 -> 0.07 | AV21: NPV/Share | AW21: =AW19/AW20 -> 29.210485
C22: Gross margin | D22: =D6/D4 -> 0.373297 | E22: =E6/E4 -> 0.35195531 | F22: =F6/F4 -> 0.37688442 | G22: =G6/G4 -> 0.38645418 | H22: =H6/H4 -> 0.35770235 | I22: =I6/I4 -> 0.34662577 | J22: =J6/J4 -> 0.35411471 | K22: =K6/K4 -> 0.32929293 | ... P22: =P6/P4 -> 0.36111111 | Q22: =(Q4+Q5)/Q4 -> 0.35103486 | R22: =(R4+R5)/R4 -> 0.36709441 | S22: =(S4+S5)/S4 -> 0.34952446 | T22: =(T4+T5)/T4 -> 0.3664654 | Z22: =Z6/Z4 -> 0.44788701 | AA22: =AA6/AA4 -> 0.44626555 | AB22: =AB6/AB4 -> 0.4340616 | AC22: =AC6/AC4 -> 0.4097695 | AD22: =AD6/AD4 -> 0.38841152 | AE22: =AE6/AE4 -> 0.39327256 | AF22: =AF6/AF4 -> 0.38578969 | AG22: =AG6/AG4 -> 0.37353846 | ... AT22: =AT6/AT4 -> 0.37 | AV22: Opp-/nedside | AW22: =(AW21-B4)/B4 -> 0.93446922
C23: EBIT margin | D23: =D11/D4 -> 0.059945504 | E23: =E11/E4 -> 0.075418994 | F23: =F11/F4 -> 0.054640704 | G23: =G11/G4 -> 0.093625498 | H23: =H11/H4 -> 0.018276762 | I23: =I11/I4 -> 0.015337423 | J23: =J11/J4 -> 0.0074812968 | K23: =K11/K4 -> 0.054545455 | ... T23: =T11/T4 -> 0.016953089 | Z23: =Z11/Z4 -> 0.079494941 | AA23: =AA11/AA4 -> 0.077496521 | AB23: =AB11/AB4 -> 0.066861259 | AC23: =AC11/AC4 -> 0.052369013 | AD23: =AD11/AD4 -> 0.050195929 | AE23: =AE11/AE4 -> 0.10136835 | AF23: =AF11/AF4 -> 0.097576296 | AG23: =AG11/AG4 -> 0.070153846 | ... AT23: =AT11/AT4 -> 0.066789093
C24: ROE | Z24: 0.379 | AA24: 0.381 | AB24: 0.131 | AC24: 0.141 | AD24: 0.177 | AG24: =AG15/G46 -> 0.15407855 | AH24: =AH15/K46 -> -0.023255814 | AI24: =AI15/O46 -> 0.056886228 | AJ24: =AJ15/S46 -> 0.044815588
C26: EBITDA | D26: 43 | E26: 49 | F26: 45 | G26: 70 | H26: 32 | I26: 31 | J26: 28 | K26: 46 | L26: 24 | M26: 30.3 | N26: 30 | O26: 65.8 | P26: 36 | Q26: 39.7 | R26: 48.2 | S26: 69.7 | T26: 38 | AG26: 206 | AH26: 136 | AI26: 150.1 | AJ26: 193.4 | AK26: =SUM(AK6:AK7)+AK9 -> 243.40894 | AL26: =SUM(AL6:AL7)+AL9 -> 270.87662 | AM26: =SUM(AM6:AM7)+AM9 -> 289.83798 | AN26: =SUM(AN6:AN7)+AN9 -> 310.12664 | AO26: =SUM(AO6:AO7)+AO9 -> 331.83551 | AP26: =SUM(AP6:AP7)+AP9 -> 355.06399 | AQ26: =SUM(AQ6:AQ7)+AQ9 -> 379.91847 | AR26: =SUM(AR6:AR7)+AR9 -> 406.51277 | ... AT26: =SUM(AT6:AT7)+AT9 -> 465.41647
C27: EBITDA % | D27: =D26/D4 -> 0.11716621 | E27: =E26/E4 -> 0.13687151 | F27: =F26/F4 -> 0.11306533 | G27: =G26/G4 -> 0.13944223 | H27: =H26/H4 -> 0.083550914 | I27: =I26/I4 -> 0.095092025 | J27: =J26/J4 -> 0.069825436 | K27: =K26/K4 -> 0.092929293 | ... T27: =T26/T4 -> 0.088248955 | AG27: =AG26/AG4 -> 0.12676923 | AH27: =AH26/AH4 -> 0.084735202 | AI27: =AI26/AI4 -> 0.092312423 | AJ27: =AJ26/AJ4 -> 0.10814136 | AK27: =AK26/AK4 -> 0.12486634 | AL27: =AL26/AL4 -> 0.12986634 | AM27: =AM26/AM4 -> 0.12986634 | AN27: =AN26/AN4 -> 0.12986634 | ... AT27: =AT26/AT4 -> 0.12986634
C28: EBITDA LTM | G28: =SUM(D26:G26) -> 207 | H28: =SUM(E26:H26) -> 196 | I28: =SUM(F26:I26) -> 178 | J28: =SUM(G26:J26) -> 161 | K28: =SUM(H26:K26) -> 137 | L28: =SUM(I26:L26) -> 129 | M28: =SUM(J26:M26) -> 128.3 | N28: =SUM(K26:N26) -> 130.3 | ... T28: =SUM(Q26:T26) -> 195.6
C30: Balanse NOKm
C32: Goodwill | D32: 413.179 | E32: 395.153 | F32: 395.153 | G32: 432 | H32: 432 | I32: 432 | J32: 432 | K32: 432 | L32: 452 | M32: 449 | N32: 459 | O32: 456 | P32: 462 | Q32: 464.6 | R32: 464.3 | S32: 473.2 | T32: 454.8 | AE32: 185.084 | AF32: 185.077 | AG32: 432.406 | AH32: 451.784 | AI32: 456.074 | AJ32: 473.214
C33: Trademark and intangible assets | D33: 6.669 | E33: 6.53 | F33: 6.629 | G33: 22 | H33: 22 | I33: 22 | J33: 22 | K33: 21 | L33: 20 | M33: 20 | N33: 18 | O33: 58 | P33: 57 | Q33: 55 | R33: 53.4 | S33: 52 | T33: 54.8 | AE33: 7.356 | AF33: 6.807 | AG33: 22.415 | AH33: 21.502 | AI33: 58.146 | AJ33: 52.037
C34: Right-of-use assets | D34: 0 | E34: 0 | F34: 0 | G34: 0 | H34: 0 | I34: 0 | J34: 0 | K34: 0 | L34: 0 | M34: 0 | N34: 0 | O34: 0 | P34: 0 | Q34: 0 | R34: 382.9 | S34: 393.9 | T34: 405.6 | AE34: 0 | AF34: 0 | AG34: 331.447 | AH34: 363.92 | AI34: 409.2 | AJ34: 393.908
C35: Deferred tax assets | D35: 5.234 | E35: 5.629 | F35: 5.547 | G35: 8 | H35: 9 | I35: 11 | J35: 14 | K35: 16 | L35: 18 | M35: 21 | N35: 22 | O35: 21 | P35: 27 | Q35: 27.9 | R35: 27.6 | S35: 30.9 | T35: 31 | AE35: 0 | AF35: 0 | AG35: 8.445 | AH35: 18.616 | AI35: 24.51 | AJ35: 30.879
C36: Other non-current assets | D36: 0 | E36: 0 | F36: 0 | G36: 0 | H36: 0 | I36: 0 | J36: 0 | K36: 0 | L36: 0 | M36: 0 | N36: 0 | O36: 2 | P36: =2+406 -> 408 | Q36: 1.5 | R36: 1.2 | S36: 1 | T36: 0.9 | AE36: 0 | AF36: 0 | AG36: 0 | AH36: 0 | AI36: 1.95 | AJ36: 1.011
C37: PP&E | D37: 488.154 | E37: 473.097 | F37: 470.254 | G37: 463 | H37: 471 | I37: 473 | J37: 450 | K37: 497 | L37: 545 | M37: 525 | N37: 528 | O37: 489 | P37: 81 | Q37: 78.9 | R37: 77.3 | S37: 78 | T37: 82.2 | AE37: 435.374 | AF37: 457.712 | AG37: 131.666 | AH37: 129.424 | AI37: 79.449 | AJ37: 78.013
C38: Inventories | D38: 326.138 | E38: 311.6 | F38: 310.25 | G38: 319 | H38: 335 | I38: 356 | J38: 410 | K38: 357 | L38: 338 | M38: 324 | N38: 354 | O38: 339 | P38: 369 | Q38: 376.2 | R38: 416.9 | S38: 356.2 | T38: 355.4 | AE38: 208.16 | AF38: 263.898 | AG38: 319.273 | AH38: 356.588 | AI38: 338.911 | AJ38: 356.229
C39: Trade receivables | D39: 80.142 | E39: 86.049 | F39: 100.397 | G39: 70 | H39: 80 | I39: 79 | J39: 96 | K39: 66 | L39: 70 | M39: 82 | N39: 86 | O39: 53 | P39: 75 | Q39: 80.9 | R39: 94.9 | S39: 59.7 | T39: 73.4 | AE39: 54.387 | AF39: 64.239 | AG39: 70.055 | AH39: 74.504 | AI39: 52.706 | AJ39: 59.653
C40: Other current assets | D40: 34.897 | E40: 49.655 | F40: 45.224 | G40: 40 | H40: 37 | I40: 32 | J40: 52 | K40: 23 | L40: 32 | M40: 31 | N40: 21 | O40: 16 | P40: 21 | Q40: 20.4 | R40: 24 | S40: 22.7 | T40: 25.6 | AE40: 28.495 | AF40: 40.572 | AG40: 39.559 | AH40: 26.596 | AI40: 15.624 | AJ40: 22.677
C41: cash | D41: 23.9 | E41: 0 | F41: 0 | G41: 3 | H41: 0 | I41: 22 | J41: 0 | K41: 0 | L41: 58 | M41: 85 | N41: 97 | O41: 139 | P41: 95 | Q41: 54.7 | R41: 81.7 | S41: 150.4 | T41: 136.6 | AE41: 94.08 | AF41: 76.435 | AG41: 2.914 | AH41: 8.758 | AI41: 139.465 | AJ41: 150.395
C42: Total assets | D42: =SUM(D32:D41) -> 1378.313 | E42: =SUM(E32:E41) -> 1327.713 | F42: =SUM(F32:F41) -> 1333.454 | G42: =SUM(G32:G41) -> 1357 | H42: =SUM(H32:H41) -> 1386 | I42: =SUM(I32:I41) -> 1427 | J42: =SUM(J32:J41) -> 1476 | K42: =SUM(K32:K41) -> 1412 | ... T42: =SUM(T32:T41) -> 1620.3 | AE42: =SUM(AE32:AE41) -> 1012.936 | AF42: =SUM(AF32:AF41) -> 1094.74 | AG42: =SUM(AG32:AG41) -> 1358.18 | AH42: =SUM(AH32:AH41) -> 1451.692 | AI42: =SUM(AI32:AI41) -> 1576.035 | AJ42: =SUM(AJ32:AJ41) -> 1618.016
C43: Total paid-in equity | D43: 13 | E43: 13.011 | F43: 13.011 | G43: 78 | H43: 78 | I43: 196 | J43: 196 | K43: 196 | L43: 341 | M43: 369 | N43: 369 | O43: 369 | P43: 369 | Q43: 369.5 | R43: 369.5 | S43: 369.5 | T43: 369.5 | AE43: 13.011 | AF43: 13.011 | AG43: 77.841 | AH43: 194.662 | AI43: 369.499 | AJ43: 370.505
C44: Retained earnings | D44: 275.159 | E44: 289.01 | F44: 299.754 | G44: 253 | H44: 239 | I44: 229 | J44: 223 | K44: 234 | L44: 242 | M44: 234 | N44: 278 | O44: 298 | P44: 297 | Q44: 300 | R44: 0.9 | S44: 1 | T44: 1.2 | AE44: 213.923 | AF44: 261.164 | AG44: 253.592 | AH44: 252.205 | AI44: 298.249 | AJ44: 348.341
C45: Non-controlling interests | D45: 0 | E45: 0 | F45: 0 | G45: 0 | H45: 0 | I45: 0 | J45: 0 | K45: 0 | L45: 2 | M45: 2 | N45: 1 | O45: 1 | P45: 2 | Q45: 0 | R45: 307 | S45: 348 | T45: 323.9 | AE45: 0 | AF45: 0 | AG45: 0 | AH45: 2.122 | AI45: 2.092 | AJ45: 0
...

Sheet Segementer
B4: NOKm | C4: Q122 | D4: Q222 | E4: Q322 | F4: Q422 | G4: 2022 | H4: Q123 | I4: Q223 | J4: Q323 | K4: Q423 | L4: 2023 | M4: Q124 | N4: Q224 | O4: Q324 | P4: Q424 | Q4: 2024 | R4: Q125 | S4: Q225 | T4: Q325 | U4: Q425 | V4: 2025 | W4: Q126 | X4: Q226 | Y4: Q326 | Z4: Q426 | AA4: 2026
B5: Norge
B6: Revenue | D6: 358 | E6: 370 | F6: 464 | H6: 352 | I6: 296 | J6: 362 | K6: 451 | L6: =SUM(H6:K6) -> 1461 | M6: 317 | N6: 315 | O6: 366 | P6: 469 | Q6: =SUM(M6:P6) -> 1467 | R6: 356 | S6: 325.2 | T6: 388.3 | U6: 525.2 | V6: =SUM(R6:U6) -> 1594.7 | W6: 383.9 | AA6: =SUM(W6:Z6) -> 383.9
B7: Revenue Y/Y | I7: =(I6-D6)/D6 -> -0.17318436 | J7: =(J6-E6)/E6 -> -0.021621622 | K7: =(K6-F6)/F6 -> -0.028017241 | M7: =(M6-H6)/H6 -> -0.099431818 | N7: =(N6-I6)/I6 -> 0.064189189 | O7: =(O6-J6)/J6 -> 0.011049724 | P7: =(P6-K6)/K6 -> 0.039911308 | Q7: =(Q6-L6)/L6 -> 0.0041067762 | R7: =(R6-M6)/M6 -> 0.12302839 | S7: =(S6-N6)/N6 -> 0.032380952 | T7: =(T6-O6)/O6 -> 0.060928962 | ... AA7: =(AA6-V6)/V6 -> -0.75926507
B8: COGS | E8: -227 | F8: -286 | H8: -222 | I8: -190 | J8: -229 | K8: -296 | L8: =SUM(H8:K8) -> -937 | M8: -203 | N8: -208 | O8: -225 | P8: -299 | Q8: =SUM(M8:P8) -> -935 | R8: -224 | S8: -208.8 | T8: -243 | U8: -337.1 | V8: =SUM(R8:U8) -> -1012.9 | W8: -238.6 | AA8: =SUM(W8:Z8) -> -238.6
B9: Gross Profit | E9: 143 | F9: 177 | H9: 130 | I9: 106 | J9: 133 | K9: 155 | L9: =SUM(H9:K9) -> 524 | M9: 115 | N9: 107 | O9: 141 | P9: =SUM(P6:P8) -> 170.03991 | Q9: =SUM(M9:P9) -> 533.03991 | R9: 132 | S9: 116.4 | T9: 145.2 | U9: 188.1 | V9: =SUM(R9:U9) -> 581.7 | W9: 145.3 | AA9: =SUM(W9:Z9) -> 145.3
B10: Gross margin | E10: 0.386 | F10: 0.382 | H10: 0.368 | I10: 0.359 | J10: 0.368 | K10: 0.344 | L10: =L9/L6 -> 0.35865845 | M10: 0.361 | N10: 0.339 | O10: 0.386 | P10: =P9/P6 -> 0.36255845 | Q10: =Q9/Q6 -> 0.36335372 | R10: 0.37 | S10: 0.358 | T10: 0.374 | U10: 0.358 | V10: =V9/V6 -> 0.3647708 | W10: 0.379 | AA10: =AA9/AA6 -> 0.37848398
B11: EBITDA | M11: 27 | N11: 36 | O11: 30 | P11: 65 | Q11: =SUM(M11:P11) -> 158 | R11: 35 | S11: 38 | T11: 43 | U11: 66 | V11: =SUM(R11:U11) -> 182 | W11: 36 | AA11: =SUM(W11:Z11) -> 36
B12: EBITDA % | M12: =M11/M6 -> 0.085173502 | N12: =N11/N6 -> 0.11428571 | O12: =O11/O6 -> 0.081967213 | P12: =P11/P6 -> 0.13859275 | Q12: =Q11/Q6 -> 0.10770279 | R12: =R11/R6 -> 0.098314607 | S12: =S11/S6 -> 0.11685117 | T12: =T11/T6 -> 0.11073912 | U12: 0.126 | V12: =V11/V6 -> 0.11412805 | W12: =W11/W6 -> 0.09377442 | X12: =X11/X6 -> #DIV/0! | Y12: =Y11/Y6 -> #DIV/0! | Z12: =Z11/Z6 -> #DIV/0! | AA12: =AA11/AA6 -> 0.09377442
B13: Opex | E13: -97 | F13: -106 | H13: -97 | I13: -71 | J13: -100 | K13: -102 | L13: =SUM(H13:K13) -> -370 | M13: -87 | N13: -71 | O13: -97 | P13: -104 | Q13: =SUM(M13:P13) -> -359 | R13: -96 | S13: -78 | T13: -101.7 | U13: -111.2 | V13: =SUM(R13:U13) -> -386.9 | W13: -103.5 | AA13: =SUM(W13:Z13) -> -103.5
B14: Opex to sales % | E14: -0.266 | F14: -0.228 | H14: -0.275 | I14: -0.24 | J14: -0.277 | K14: -0.226 | L14: =L13/L6 -> -0.2532512 | M14: -0.274 | N14: -0.225 | O14: -0.266 | P14: =P13/P6 -> -0.2217484 | Q14: =Q13/Q6 -> -0.24471711 | R14: -0.269 | S14: 0.24 | T14: -0.262 | U14: -0.212 | V14: =V13/V6 -> -0.24261617 | W14: -0.27 | AA14: =AA13/AA6 -> -0.26960146
B15: EBIT | E15: 22 | F15: 51 | H15: 9 | I15: 12 | J15: 9 | K15: 35 | L15: =SUM(H15:K15) -> 65 | M15: 4 | N15: 13 | O15: 5 | P15: 40 | Q15: =SUM(M15:P15) -> 62 | R15: 9 | S15: 12.2 | T15: 17 | U15: 42.5 | V15: =SUM(R15:U15) -> 80.7 | W15: 9.6 | AA15: =SUM(W15:Z15) -> 9.6
B16: EBIT % | E16: 0.058 | F16: 0.109 | H16: 0.026 | I16: 0.039 | J16: 0.025 | K16: 0.078 | L16: =L15/L6 -> 0.044490075 | M16: 0.012 | N16: 0.04 | O16: 0.013 | P16: =P15/P6 -> 0.085287846 | Q16: =Q15/Q6 -> 0.042263122 | R16: 0.027 | S16: 0.037 | T16: 0.044 | U16: 0.081 | V16: =V15/V6 -> 0.050605129 | W16: 0.025 | AA16: =AA15/AA6 -> 0.025006512
B17: Net financials | E17: -7 | H17: -12 | I17: -14 | J17: -12 | K17: -15 | L17: =SUM(H17:K17) -> -53 | M17: -7 | N17: -11 | O17: -13 | P17: -4 | Q17: =SUM(M17:P17) -> -35 | R17: -15 | S17: -8.8 | T17: -8 | U17: -2.5 | V17: =SUM(R17:U17) -> -34.3 | W17: -12.3 | AA17: =SUM(W17:Z17) -> -12.3
B18: PTP | E18: 14 | H18: -2 | I18: -2 | J18: -3 | K18: 20 | L18: =SUM(H18:K18) -> 13 | M18: -3 | N18: 2 | O18: -8 | P18: 36 | Q18: =SUM(M18:P18) -> 27 | R18: -6 | S18: 3.4 | T18: 9 | U18: 40 | V18: =SUM(R18:U18) -> 46.4 | W18: -2.6 | AA18: =SUM(W18:Z18) -> -2.6
B19: Net profit | E19: 11 | H19: -2 | I19: -2 | J19: -1 | K19: 16 | L19: =SUM(H19:K19) -> 11 | M19: -3 | N19: 2 | O19: -7 | P19: 25 | Q19: =SUM(M19:P19) -> 17 | R19: -5 | S19: 2.7 | T19: 7 | U19: 30.9 | V19: =SUM(R19:U19) -> 35.6 | W19: -2.1 | AA19: =SUM(W19:Z19) -> -2.1
B20: Stores | C20: 26 | D20: 26 | E20: 27 | F20: 27 | G20: 27 | H20: 27 | I20: 27 | J20: 27 | K20: 27 | L20: 27 | M20: 27 | N20: 27 | O20: 27 | P20: 29 | Q20: 29 | R20: 30 | S20: 30 | T20: 30 | U20: 31 | V20: 31 | W20: 32 | AA20: =SUM(W20:Z20) -> 32
B21: Sverige
B22: Revenue | E22: 28 | F22: 38 | H22: 31 | I22: 30 | J22: 39 | K22: 43 | L22: =SUM(H22:K22) -> 143 | M22: 33 | N22: 34 | O22: 42 | P22: 52 | Q22: =SUM(M22:P22) -> 161 | R22: 40 | S22: 42 | T22: 48 | U22: 61.8 | V22: =SUM(R22:U22) -> 191.8 | W22: 46.7 | AA22: =SUM(W22:Z22) -> 46.7
B23: Revenue Y/Y | J23: =(J22-E22)/E22 -> 0.39285714 | K23: =(K22-F22)/F22 -> 0.13157895 | M23: =(M22-H22)/H22 -> 0.064516129 | N23: =(N22-I22)/I22 -> 0.13333333 | O23: =(O22-J22)/J22 -> 0.076923077 | P23: =(P22-K22)/K22 -> 0.20930233 | Q23: =(Q22-L22)/L22 -> 0.12587413 | R23: =(R22-M22)/M22 -> 0.21212121 | S23: =(S22-N22)/N22 -> 0.23529412 | T23: =(T22-O22)/O22 -> 0.14285714 | ... AA23: =(AA22-V22)/V22 -> -0.75651721
B24: COGS | E24: -21 | F24: -28 | H24: -24 | I24: -23 | J24: -30 | K24: -36 | L24: =SUM(H24:K24) -> -113 | M24: -26 | N24: -28 | O24: -33 | P24: -40 | Q24: =SUM(M24:P24) -> -127 | R24: -29 | S24: -30.3 | T24: -34.2 | U24: -43.7 | V24: =SUM(R24:U24) -> -137.2 | W24: -34.2 | AA24: =SUM(W24:Z24) -> -34.2
B25: Gross Profit | E25: 7 | F25: 10 | H25: 7 | I25: 6 | J25: 8 | K25: 7 | L25: =SUM(H25:K25) -> 28 | M25: 7 | N25: 6 | O25: 9 | P25: =SUM(P22:P24) -> 12.209302 | Q25: =SUM(M25:P25) -> 34.209302 | R25: 11 | S25: 11.7 | T25: 14 | U25: 18.1 | V25: =SUM(R25:U25) -> 54.8 | W25: 12.5 | AA25: =SUM(W25:Z25) -> 12.5
B26: Gross margin | E26: 0.245 | F26: 0.26 | H26: 0.23 | I26: 0.218 | J26: 0.211 | K26: 0.161 | L26: =L25/L22 -> 0.1958042 | M26: 0.216 | N26: 0.185 | O26: 0.209 | P26: 0.224 | Q26: =Q25/Q22 -> 0.21248014 | R26: 0.269 | S26: 0.279 | T26: 0.291 | U26: 0.294 | V26: =V25/V22 -> 0.28571429 | W26: 0.268 | AA26: =AA25/AA22 -> 0.26766595
B27: EBITDA | M27: -3 | N27: -6 | O27: 0 | P27: 1 | Q27: =SUM(M27:P27) -> -8 | R27: 1 | S27: 2 | T27: 0.8 | U27: 3.7 | V27: 12.7 | W27: 2 | AA27: 35
B28: EBITDA % | M28: =M27/M22 -> -0.090909091 | N28: =N27/N22 -> -0.17647059 | O28: =O27/O22 -> 0 | P28: =P27/P22 -> 0.019230769 | Q28: =Q27/Q22 -> -0.049689441 | R28: =R27/R22 -> 0.025 | S28: =S27/S22 -> 0.047619048 | T28: =T27/T22 -> 0.016666667 | U28: 0.06 | V28: =V27/V22 -> 0.066214807 | W28: =W27/W22 -> 0.042826552 | X28: =X27/X22 -> #DIV/0! | Y28: =Y27/Y22 -> #DIV/0! | Z28: =Z27/Z22 -> #DIV/0!
B29: Opex | E29: -6 | F29: -12 | H29: -8 | I29: -11 | J29: -12 | K29: -15 | L29: =SUM(H29:K29) -> -46 | M29: -9 | N29: -9 | O29: -8 | P29: -10 | Q29: =SUM(M29:P29) -> -36 | R29: -9 | S29: -9.3 | T29: -8 | U29: -12 | V29: =SUM(R29:U29) -> -38.3 | W29: -10.2 | AA29: =SUM(W29:Z29) -> -10.2
B30: Opex to sales % | E30: -0.226 | F30: -0.314 | H30: -0.273 | I30: -0.377 | J30: -0.302 | K30: -0.339 | L30: =L29/L22 -> -0.32167832 | M30: -0.283 | N30: -0.263 | O30: -0.195 | P30: =P29/P22 -> -0.19230769 | Q30: =Q29/Q22 -> -0.22360248 | R30: -0.235 | S30: -0.222 | T30: -0.167 | U30: -0.194 | V30: =V29/V22 -> -0.19968717 | W30: -0.219 | AA30: =AA29/AA22 -> -0.21841542
B31: EBIT | E31: 1 | F31: -4 | H31: -2 | I31: -7 | J31: -7 | K31: -9 | L31: =SUM(H31:K31) -> -25 | M31: -7 | N31: -8 | O31: -4 | P31: -3 | Q31: =SUM(M31:P31) -> -22 | R31: -3 | S31: -1.9 | T31: 1.7 | U31: 2.1 | V31: =SUM(R31:U31) -> -1.1 | W31: -2.2 | AA31: =SUM(W31:Z31) -> -2.2
B32: EBIT % | E32: 0.019 | F32: -0.098 | H32: -0.07 | I32: -0.241 | J32: -0.169 | K32: -0.218 | L32: =L31/L22 -> -0.17482517 | M32: -0.219 | N32: -0.222 | O32: -0.085 | P32: =P31/P22 -> -0.057692308 | Q32: =Q31/Q22 -> -0.13664596 | R32: -0.072 | S32: -0.045 | T32: 0.035 | U32: 0.033 | V32: =V31/V22 -> -0.0057351408 | W32: -0.047 | AA32: =AA31/AA22 -> -0.047109208
B33: Net financials | E33: 0 | H33: -1 | I33: -1 | J33: 0 | K33: -2 | L33: =SUM(H33:K33) -> -4 | M33: -1 | N33: -1 | O33: -1 | P33: -1 | Q33: =SUM(M33:P33) -> -4 | R33: -1 | S33: -1.2 | T33: -1.2 | U33: -0.1 | V33: =SUM(R33:U33) -> -3.5 | W33: -1.5 | AA33: =SUM(W33:Z33) -> -1.5
B34: PTP | E34: 1 | H34: -8 | I34: -8 | J34: -6 | K34: -12 | L34: =SUM(H34:K34) -> -34 | M34: -8 | N34: -9 | O34: -5 | P34: -4 | Q34: =SUM(M34:P34) -> -26 | R34: -4 | S34: -3.1 | T34: 0.5 | U34: -0.5 | V34: =SUM(R34:U34) -> -7.1 | W34: -3.7 | AA34: =SUM(W34:Z34) -> -3.7
B35: Net profit | E35: 1 | H35: -7 | I35: -2 | J35: -6 | K35: -9 | L35: =SUM(H35:K35) -> -24 | M35: -7 | N35: -6 | O35: -4 | P35: -3 | Q35: =SUM(M35:P35) -> -20 | R35: -3 | S35: -2.4 | T35: 0.4 | U35: 1.1 | V35: =SUM(R35:U35) -> -3.9 | W35: -2.9 | AA35: =SUM(W35:Z35) -> -2.9
B36: Stores | C36: 0 | D36: 0 | E36: 0 | F36: 0 | H36: 0 | I36: 1 | J36: 1 | K36: 1 | L36: 1 | M36: 1 | N36: 1 | O36: 1 | P36: 1 | Q36: 1 | R36: 1 | S36: 1 | T36: 1 | U36: 1 | V36: 1 | W36: 1 | X36: 2 | AA36: =SUM(W36:Z36) -> 3

Sheet SOTP
B6: SOTP 26E valuation
B8: NOKm
C9: EBITDA 26E | D9: EV/EBITDA (x) | F9: EV | G9: Per share
B10: Norge | C10: 210 | D10: 6.5 | F10: =C10*D10 -> 1365 | G10: =F10/Modell!$B$5 -> 26.879497
B11: Sverige | C11: 35 | D11: 5 | F11: =C11*D11 -> 175 | G11: =F11/Modell!$B$5 -> 3.4460894
B12: Enterprise value | G12: =SUM(G10:G11) -> 30.325587
B14: Debt | F14: =Modell!B8 -> 631.2 | G14: =-F14/Modell!$B$5 -> -12.429552
B15: Cash | F15: =Modell!B7 -> 136.6 | G15: =F15/Modell!$B$5 -> 2.6899189
B16: ELIMP | G16: =SUM(G12:G15) -> 20.585953

Sheet Nøkkeltall
F7: 2026 | G7: 2027 | H7: 2028
E8: EV/EBITDA | F8: =Modell!$B$9/Modell!AK26 -> 5.1822715 | G8: =Modell!$B$9/Modell!AL26 -> 4.6567741 | H8: =Modell!$B$9/Modell!AM26 -> 4.3521253
E9: EV/EBIT | F9: =Modell!$B$9/Modell!AK11 -> 10.47258 | G9: =Modell!$B$9/Modell!AL11 -> 9.0547446 | H9: =Modell!$B$9/Modell!AM11 -> 8.4623781
E10: P/E | F10: =Modell!$B$4/Modell!AK17 -> 10.86902 | G10: =Modell!$B$4/Modell!AL17 -> 8.9936558 | H10: =Modell!$B$4/Modell!AM17 -> 8.2570334

Sheet Nedsideberegning
A3: Nedside | D3: FY 2015 | E3: FY 2016 | F3: FY 2017 | G3: FY 2018 | H3: FY 2019 | I3: FY 2020 | J3: FY 2021 | K3: FY 2022 | L3: FY 2023 | M3: FY 2024 | N3: FY 2025 | O3: FY 2026 | P3: FY 2027 | Q3: FY 2028 | R3: FY 2029 | S3: FY 2030 | T3: FY 2031 | U3: FY 2032 | V3: FY 2033 | W3: FY 2034 | X3: FY 2035
A4: Nullvekst og flate marginer | C4: Revenue | D4: 277.829 | E4: 417.451 | F4: 593.77549 | G4: 786.56742 | H4: 964.15985 | I4: 1315.894 | J4: 1485.33 | K4: 1625 | L4: 1605 | M4: 1626 | N4: =M4*1.08 -> 1756.08 | O4: =N4*1 -> 1756.08 | P4: =O4*1 -> 1756.08 | Q4: =P4*1 -> 1756.08 | R4: =Q4*1 -> 1756.08 | S4: =R4*1 -> 1756.08 | T4: =S4*1 -> 1756.08 | U4: =T4*1 -> 1756.08 | V4: =U4*1 -> 1756.08 | ... X4: =W4*1 -> 1756.08
A5: =AA22 -> 7.0522333 | C5: COGS | D5: -153.393 | E5: -231.157 | F5: -336.04035 | G5: -464.25608 | H5: -589.66906 | I5: -798.389 | J5: -912.305 | K5: -1018 | L5: -1050 | M5: -1074 | N5: =N4*-0.65 -> -1141.452 | O5: =O4*-0.65 -> -1141.452 | P5: =P4*-0.65 -> -1141.452 | Q5: =Q4*-0.65 -> -1141.452 | R5: =R4*-0.65 -> -1141.452 | S5: =S4*-0.65 -> -1141.452 | T5: =T4*-0.65 -> -1141.452 | U5: =U4*-0.65 -> -1141.452 | ... X5: =X4*-0.65 -> -1141.452
A6: =AA23 -> -0.53296468 | C6: Gross profit | D6: =SUM(D4:D5) -> 124.436 | E6: =SUM(E4:E5) -> 186.294 | F6: =SUM(F4:F5) -> 257.73514 | G6: =SUM(G4:G5) -> 322.31134 | H6: =SUM(H4:H5) -> 374.49079 | I6: =SUM(I4:I5) -> 517.505 | J6: =SUM(J4:J5) -> 573.025 | K6: =SUM(K4:K5) -> 607 | ... X6: =SUM(X4:X5) -> 614.628
C7: Employee benefits exp | D7: -50.324 | E7: -80.6 | F7: -117.86964 | G7: -144.4926 | H7: -176.14434 | I7: -219.294 | J7: -243.321 | K7: -255 | L7: -272 | M7: -266 | N7: =M7*1.06 -> -281.96 | O7: =N7*1 -> -281.96 | P7: =O7*1 -> -281.96 | Q7: =P7*1 -> -281.96 | R7: =Q7*1 -> -281.96 | S7: =R7*1 -> -281.96 | T7: =S7*1 -> -281.96 | U7: =T7*1 -> -281.96 | V7: =U7*1 -> -281.96 | ... X7: =W7*1 -> -281.96
C8: D/A | D8: -13.54 | E8: =-16.943 -> -16.943 | F8: =-21.263035-3.145 -> -24.408035 | G8: =-27.230979-2.46 -> -29.690979 | H8: =-28.105644-0.736 -> -28.841644 | I8: -70.74 | J8: -77.325 | K8: -92 | L8: -96 | M8: -111 | N8: =M8*1.06 -> -117.66 | O8: =N8*1 -> -117.66 | P8: =O8*1 -> -117.66 | Q8: =P8*1 -> -117.66 | R8: =Q8*1 -> -117.66 | S8: =R8*1 -> -117.66 | T8: =S8*1 -> -117.66 | U8: =T8*1 -> -117.66 | V8: =U8*1 -> -117.66 | ... X8: =W8*1 -> -117.66
C9: Other opex | D9: -38.486 | E9: -56.4 | F9: -75.756888 | G9: -106.936 | H9: -121.10791 | I9: -94.081 | J9: -107.446 | K9: -146 | L9: -145 | M9: -138 | N9: =M9*1.06 -> -146.28 | O9: =N9*1 -> -146.28 | P9: =O9*1 -> -146.28 | Q9: =P9*1 -> -146.28 | R9: =Q9*1 -> -146.28 | S9: =R9*1 -> -146.28 | T9: =S9*1 -> -146.28 | U9: =T9*1 -> -146.28 | V9: =U9*1 -> -146.28 | ... X9: =W9*1 -> -146.28
C10: Total opex | D10: =D5+D7+D8+D9 -> -255.743 | E10: =E5+E7+E8+E9 -> -385.1 | F10: =F5+F7+F8+F9 -> -554.07492 | G10: =G5+G7+G8+G9 -> -745.37566 | H10: =H5+H7+H8+H9 -> -915.76295 | I10: =I5+I7+I8+I9 -> -1182.504 | J10: =J5+J7+J8+J9 -> -1340.397 | K10: =K5+K7+K8+K9 -> -1511 | ... X10: =X5+X7+X8+X9 -> -1687.352
C11: Operating profit (EBIT) | D11: =D4+D10 -> 22.086 | E11: =E4+E10 -> 32.351 | F11: =F4+F10 -> 39.700577 | G11: =G4+G10 -> 41.191759 | H11: =H4+H10 -> 48.396899 | I11: =I4+I10 -> 133.39 | J11: =J4+J10 -> 144.933 | K11: =K4+K10 -> 114 | ... X11: =X4+X10 -> 68.728
C12: Net financials | D12: -8.496 | E12: -9.4 | F12: -15.442 | G12: -18.718 | H12: -15 | I12: -29.196 | J12: -20.354 | K12: -46 | L12: -56 | M12: 5 | N12: -30 | O12: -30 | P12: -30 | Q12: -30 | R12: -30 | S12: -30 | T12: -30 | U12: -30 | V12: -30 | W12: -30 | X12: -30
C13: PTP | D13: =SUM(D11:D12) -> 13.59 | E13: =SUM(E11:E12) -> 22.951 | F13: =SUM(F11:F12) -> 24.258577 | G13: =SUM(G11:G12) -> 22.473759 | H13: =SUM(H11:H12) -> 33.396899 | I13: =SUM(I11:I12) -> 104.194 | J13: =SUM(J11:J12) -> 124.579 | K13: =SUM(K11:K12) -> 68 | ... X13: =SUM(X11:X12) -> 38.728
C14: Tax | D14: -6.7 | E14: -9 | F14: -9.5 | G14: -7.9 | H14: -9.6 | I14: -22.919 | J14: -27.328 | K14: -17 | L14: 4 | M14: -4 | N14: =N13*-0.22 -> -8.52016 | O14: =O13*-0.22 -> -8.52016 | P14: =P13*-0.22 -> -8.52016 | Q14: =Q13*-0.22 -> -8.52016 | R14: =R13*-0.22 -> -8.52016 | S14: =S13*-0.22 -> -8.52016 | T14: =T13*-0.22 -> -8.52016 | U14: =U13*-0.22 -> -8.52016 | ... X14: =X13*-0.22 -> -8.52016
C15: Net income | D15: =SUM(D13:D14) -> 6.89 | E15: =SUM(E13:E14) -> 13.951 | F15: =SUM(F13:F14) -> 14.758577 | G15: =SUM(G13:G14) -> 14.573759 | H15: =SUM(H13:H14) -> 23.796899 | I15: =SUM(I13:I14) -> 81.275 | J15: =SUM(J13:J14) -> 97.251 | K15: =SUM(K13:K14) -> 51 | ... X15: =SUM(X13:X14) -> 30.20784 | Y15: =X15*(1+$AA$19) -> 29.905762 | Z15: =Y15*(1+$AA$19) -> 29.606704 | AA15: =Z15*(1+$AA$19) -> 29.310637 | AB15: =AA15*(1+$AA$19) -> 29.017531 | AC15: =AB15*(1+$AA$19) -> 28.727355 | AD15: =AC15*(1+$AA$19) -> 28.440082 | AE15: =AD15*(1+$AA$19) -> 28.155681 | AF15: =AE15*(1+$AA$19) -> 27.874124 | ... DO15: =DN15*(1+$AA$19) -> 11.626879
C16: Shares | I16: 21.3 | J16: 21.3 | K16: 50.7822 | L16: 50.7822 | M16: 50.7822 | N16: 50.7822 | O16: 50.7822 | P16: 50.7822 | Q16: 50.7822 | R16: 50.7822 | S16: 50.7822 | T16: 50.7822 | U16: 50.7822 | V16: 50.7822 | W16: 50.7822 | X16: 50.7822
C17: EPS | I17: =I15/I16 -> 3.8157277 | J17: =J15/J16 -> 4.5657746 | K17: =K15/K16 -> 1.0042889 | L17: =L15/L16 -> -0.19691939 | M17: =M15/M16 -> 0.74829369 | N17: =N15/N16 -> 0.59485095 | O17: =O15/O16 -> 0.59485095 | P17: =P15/P16 -> 0.59485095 | ... X17: =X15/X16 -> 0.59485095
Z18: Discount | AA18: 0.08
C19: Revenue y/y | E19: =(E4-D4)/D4 -> 0.50254653 | F19: =(F4-E4)/E4 -> 0.42238369 | G19: =(G4-F4)/F4 -> 0.32468825 | H19: =(H4-G4)/G4 -> 0.22578157 | I19: =(I4-H4)/H4 -> 0.36480896 | J19: =(J4-I4)/I4 -> 0.12876113 | K19: =(K4-J4)/J4 -> 0.094032976 | L19: =(L4-K4)/K4 -> -0.012307692 | ... X19: =(X4-W4)/W4 -> 0 | Z19: TV | AA19: -0.01
C20: Like-for-like y/y | Z20: NPV | AA20: =NPV(AA18,N15:DO15) -> 358.12792
C21: Opex y/y | E21: =(E10-D10)/D10 -> 0.50580857 | F21: =(F10-E10)/E10 -> 0.43878192 | G21: =(G10-F10)/F10 -> 0.34526151 | H21: =(H10-G10)/G10 -> 0.2285925 | I21: =(I10-H10)/H10 -> 0.2912774 | J21: =(J10-I10)/I10 -> 0.13352428 | K21: =(K10-J10)/J10 -> 0.12727796 | L21: =(L10-K10)/K10 -> 0.034414295 | ... X21: =(X10-W10)/W10 -> 0 | Z21: S/O | AA21: 50.7822
C22: Gross margin | D22: =D6/D4 -> 0.44788701 | E22: =E6/E4 -> 0.44626555 | F22: =F6/F4 -> 0.4340616 | G22: =G6/G4 -> 0.4097695 | H22: =H6/H4 -> 0.38841152 | I22: =I6/I4 -> 0.39327256 | J22: =J6/J4 -> 0.38578969 | K22: =K6/K4 -> 0.37353846 | ... X22: =X6/X4 -> 0.35 | Z22: NPV/Share | AA22: =AA20/AA21 -> 7.0522333
C23: EBIT margin | D23: =D11/D4 -> 0.079494941 | E23: =E11/E4 -> 0.077496521 | F23: =F11/F4 -> 0.066861259 | G23: =G11/G4 -> 0.052369013 | H23: =H11/H4 -> 0.050195929 | I23: =I11/I4 -> 0.10136835 | J23: =J11/J4 -> 0.097576296 | K23: =K11/K4 -> 0.070153846 | ... X23: =X11/X4 -> 0.039137169 | Z23: Opp-/nedside | AA23: =(AA22-Modell!$B$4)/Modell!$B$4 -> -0.53296468
C24: ROE | D24: 0.379 | E24: 0.381 | F24: 0.131 | G24: 0.141 | H24: 0.177
A26: Nedside | D26: FY 2015 | E26: FY 2016 | F26: FY 2017 | G26: FY 2018 | H26: FY 2019 | I26: FY 2020 | J26: FY 2021 | K26: FY 2022 | L26: FY 2023 | M26: FY 2024 | N26: FY 2025 | O26: FY 2026 | P26: FY 2027 | Q26: FY 2028 | R26: FY 2029 | S26: FY 2030 | T26: FY 2031 | U26: FY 2032 | V26: FY 2033 | W26: FY 2034 | X26: FY 2035
A27: Nullvekst og flate marginer | C27: Revenue | D27: 277.829 | E27: 417.451 | F27: 593.77549 | G27: 786.56742 | H27: 964.15985 | I27: 1315.894 | J27: 1485.33 | K27: 1625 | L27: 1605 | M27: 1626 | N27: =M27*1.1 -> 1788.6 | O27: =N27*1 -> 1788.6 | P27: =O27*1 -> 1788.6 | Q27: =P27*1 -> 1788.6 | R27: =Q27*1 -> 1788.6 | S27: =R27*1 -> 1788.6 | T27: =S27*1 -> 1788.6 | U27: =T27*1 -> 1788.6 | V27: =U27*1 -> 1788.6 | ... X27: =W27*1 -> 1788.6
A28: =AA45 -> 8.6115913 | C28: COGS | D28: -153.393 | E28: -231.157 | F28: -336.04035 | G28: -464.25608 | H28: -589.66906 | I28: -798.389 | J28: -912.305 | K28: -1018 | L28: -1050 | M28: -1074 | N28: =N27*-0.65 -> -1162.59 | O28: =O27*-0.65 -> -1162.59 | P28: =P27*-0.65 -> -1162.59 | Q28: =Q27*-0.65 -> -1162.59 | R28: =R27*-0.65 -> -1162.59 | S28: =S27*-0.65 -> -1162.59 | T28: =T27*-0.65 -> -1162.59 | U28: =U27*-0.65 -> -1162.59 | ... X28: =X27*-0.65 -> -1162.59
A29: =AA46 -> -0.42969594 | C29: Gross profit | D29: =SUM(D27:D28) -> 124.436 | E29: =SUM(E27:E28) -> 186.294 | F29: =SUM(F27:F28) -> 257.73514 | G29: =SUM(G27:G28) -> 322.31134 | H29: =SUM(H27:H28) -> 374.49079 | I29: =SUM(I27:I28) -> 517.505 | J29: =SUM(J27:J28) -> 573.025 | K29: =SUM(K27:K28) -> 607 | ... X29: =SUM(X27:X28) -> 626.01
C30: Employee benefits exp | D30: -50.324 | E30: -80.6 | F30: -117.86964 | G30: -144.4926 | H30: -176.14434 | I30: -219.294 | J30: -243.321 | K30: -255 | L30: -272 | M30: -266 | N30: =M30*1.02 -> -271.32 | O30: =N30*1.05 -> -284.886 | P30: =O30*1 -> -284.886 | Q30: =P30*1 -> -284.886 | R30: =Q30*1 -> -284.886 | S30: =R30*1 -> -284.886 | T30: =S30*1 -> -284.886 | U30: =T30*1 -> -284.886 | V30: =U30*1 -> -284.886 | W30: =V30*1 -> -284.886 | X30: =W30*1 -> -284.886
C31: D/A | D31: -13.54 | E31: =-16.943 -> -16.943 | F31: =-21.263035-3.145 -> -24.408035 | G31: =-27.230979-2.46 -> -29.690979 | H31: =-28.105644-0.736 -> -28.841644 | I31: -70.74 | J31: -77.325 | K31: -92 | L31: -96 | M31: -111 | N31: =M31*1.02 -> -113.22 | O31: =N31*1.05 -> -118.881 | P31: =O31*1 -> -118.881 | Q31: =P31*1 -> -118.881 | R31: =Q31*1 -> -118.881 | S31: =R31*1 -> -118.881 | T31: =S31*1 -> -118.881 | U31: =T31*1 -> -118.881 | V31: =U31*1 -> -118.881 | W31: =V31*1 -> -118.881 | X31: =W31*1 -> -118.881
C32: Other opex | D32: -38.486 | E32: -56.4 | F32: -75.756888 | G32: -106.936 | H32: -121.10791 | I32: -94.081 | J32: -107.446 | K32: -146 | L32: -145 | M32: -138 | N32: -140 | O32: =N32*1.05 -> -147 | P32: =O32*1 -> -147 | Q32: =P32*1 -> -147 | R32: =Q32*1 -> -147 | S32: =R32*1 -> -147 | T32: =S32*1 -> -147 | U32: =T32*1 -> -147 | V32: =U32*1 -> -147 | W32: =V32*1 -> -147 | X32: =W32*1 -> -147
C33: Total opex | D33: =D28+D30+D31+D32 -> -255.743 | E33: =E28+E30+E31+E32 -> -385.1 | F33: =F28+F30+F31+F32 -> -554.07492 | G33: =G28+G30+G31+G32 -> -745.37566 | H33: =H28+H30+H31+H32 -> -915.76295 | I33: =I28+I30+I31+I32 -> -1182.504 | J33: =J28+J30+J31+J32 -> -1340.397 | K33: =K28+K30+K31+K32 -> -1511 | ... X33: =X28+X30+X31+X32 -> -1713.357
C34: Operating profit (EBIT) | D34: =D27+D33 -> 22.086 | E34: =E27+E33 -> 32.351 | F34: =F27+F33 -> 39.700577 | G34: =G27+G33 -> 41.191759 | H34: =H27+H33 -> 48.396899 | I34: =I27+I33 -> 133.39 | J34: =J27+J33 -> 144.933 | K34: =K27+K33 -> 114 | ... X34: =X27+X33 -> 75.243
C35: Net financials | D35: -8.496 | E35: -9.4 | F35: -15.442 | G35: -18.718 | H35: -15 | I35: -29.196 | J35: -20.354 | K35: -46 | L35: -56 | M35: 5 | N35: -30 | O35: -30 | P35: -30 | Q35: -30 | R35: -30 | S35: -30 | T35: -30 | U35: -30 | V35: -30 | W35: -30 | X35: -30
C36: PTP | D36: =SUM(D34:D35) -> 13.59 | E36: =SUM(E34:E35) -> 22.951 | F36: =SUM(F34:F35) -> 24.258577 | G36: =SUM(G34:G35) -> 22.473759 | H36: =SUM(H34:H35) -> 33.396899 | I36: =SUM(I34:I35) -> 104.194 | J36: =SUM(J34:J35) -> 124.579 | K36: =SUM(K34:K35) -> 68 | ... X36: =SUM(X34:X35) -> 45.243
C37: Tax | D37: -6.7 | E37: -9 | F37: -9.5 | G37: -7.9 | H37: -9.6 | I37: -22.919 | J37: -27.328 | K37: -17 | L37: 4 | M37: -4 | N37: =N36*-0.22 -> -15.7234 | O37: =O36*-0.22 -> -9.95346 | P37: =P36*-0.22 -> -9.95346 | Q37: =Q36*-0.22 -> -9.95346 | R37: =R36*-0.22 -> -9.95346 | S37: =S36*-0.22 -> -9.95346 | T37: =T36*-0.22 -> -9.95346 | U37: =U36*-0.22 -> -9.95346 | ... X37: =X36*-0.22 -> -9.95346
C38: Net income | D38: =SUM(D36:D37) -> 6.89 | E38: =SUM(E36:E37) -> 13.951 | F38: =SUM(F36:F37) -> 14.758577 | G38: =SUM(G36:G37) -> 14.573759 | H38: =SUM(H36:H37) -> 23.796899 | I38: =SUM(I36:I37) -> 81.275 | J38: =SUM(J36:J37) -> 97.251 | K38: =SUM(K36:K37) -> 51 | ... X38: =SUM(X36:X37) -> 35.28954 | Y38: =X38*(1+$AA$19) -> 34.936645 | Z38: =Y38*(1+$AA$19) -> 34.587278 | AA38: =Z38*(1+$AA$19) -> 34.241405 | AB38: =AA38*(1+$AA$19) -> 33.898991 | AC38: =AB38*(1+$AA$19) -> 33.560001 | AD38: =AC38*(1+$AA$19) -> 33.224401 | AE38: =AD38*(1+$AA$19) -> 32.892157 | AF38: =AE38*(1+$AA$19) -> 32.563236 | ... DO38: =DN38*(1+$AA$19) -> 13.582806
C39: Shares | I39: 21.3 | J39: 21.3 | K39: 50.7822 | L39: 50.7822 | M39: 50.7822 | N39: 50.7822 | O39: 50.7822 | P39: 50.7822 | Q39: 50.7822 | R39: 50.7822 | S39: 50.7822 | T39: 50.7822 | U39: 50.7822 | V39: 50.7822 | W39: 50.7822 | X39: 50.7822
C40: EPS | I40: =I38/I39 -> 3.8157277 | J40: =J38/J39 -> 4.5657746 | K40: =K38/K39 -> 1.0042889 | L40: =L38/L39 -> -0.19691939 | M40: =M38/M39 -> 0.74829369 | N40: =N38/N39 -> 1.0977587 | O40: =O38/O39 -> 0.69491948 | P40: =P38/P39 -> 0.69491948 | ... X40: =X38/X39 -> 0.69491948
Z41: Discount | AA41: 0.08
C42: Revenue y/y | E42: =(E27-D27)/D27 -> 0.50254653 | F42: =(F27-E27)/E27 -> 0.42238369 | G42: =(G27-F27)/F27 -> 0.32468825 | H42: =(H27-G27)/G27 -> 0.22578157 | I42: =(I27-H27)/H27 -> 0.36480896 | J42: =(J27-I27)/I27 -> 0.12876113 | K42: =(K27-J27)/J27 -> 0.094032976 | L42: =(L27-K27)/K27 -> -0.012307692 | ... X42: =(X27-W27)/W27 -> 0 | Z42: TV | AA42: -0.01
C43: Like-for-like y/y | Z43: NPV | AA43: =NPV(AA41,N38:DO38) -> 437.31555
...
