Workbook

Sheet Info
S3: Tilbakekjøpsprogram | Y3: Tilbakekjøpsprogram
S4: Dato kjøp | T4: Antall aksjer | U4: Akummelert antall aksjer | V4: Kjøp | W4: Akkumelert kjøp | Y4: Dato kjøp | Z4: Antall aksjer | AA4: Akummelert antall aksjer | AB4: Kjøp | AC4: Akkumelert kjøp
S5: 46160 | T5: 198501 | U5: =T5 -> 198501 | V5: 49255563 | W5: =V5 -> 49255563 | Y5: 17.06.2024 | Z5: 216000 | AA5: 216000 | AB5: 59463893 | AC5: 59463893
S6: 46167 | T6: 324469 | U6: =SUM(T5:T6) -> 522970 | V6: 82497532 | W6: =SUM(V5:V6) -> 131753095 | Y6: 45474 | Z6: 270000 | AA6: =SUM(Z5:Z6) -> 486000 | AB6: 74186113 | AC6: =SUM(AB5:AB6) -> 133650006
S7: 46174 | T7: 311814 | U7: =SUM(T5:T7) -> 834784 | V7: 81517876 | W7: =SUM(V5:V7) -> 213270971 | Y7: 45481 | Z7: 270000 | AA7: =SUM(Z5:Z7) -> 756000 | AB7: 74019641 | AC7: =SUM(AB5:AB7) -> 207669647
S8: 46181 | T8: 319589 | U8: =SUM(T5:T8) -> 1154373 | V8: 81966522 | W8: =SUM(V5:V8) -> 295237493 | Y8: 45488 | Z8: 270000 | AA8: =SUM(Z5:Z8) -> 1026000 | AB8: 75127338 | AC8: =SUM(AB5:AB8) -> 282796985
S9: 46188 | T9: 307819 | U9: =SUM(T$5:T9) -> 1462192 | V9: 80348681 | W9: =SUM(V$5:V9) -> 375586174 | Y9: 45495 | Z9: 270000 | AA9: =SUM(Z$5:Z9) -> 1296000 | AB9: 77475047 | AC9: =SUM(AB$5:AB9) -> 360272032
S10: 46195 | T10: 243164 | U10: =SUM(T$5:T10) -> 1705356 | V10: 64724062 | W10: =SUM(V$5:V10) -> 440310236 | Y10: 45502 | Z10: 270000 | AA10: =SUM(Z$5:Z10) -> 1566000 | AB10: 82200820 | AC10: =SUM(AB$5:AB10) -> 442472852
S11: 46202 | T11: 294782 | U11: =SUM(T5:T11) -> 2000138 | V11: 80607860 | W11: =SUM(V5:V11) -> 520918096 | Y11: 45509 | Z11: 270000 | AA11: =SUM(Z$5:Z11) -> 1836000 | AB11: 81870529 | AC11: =SUM(AB$5:AB11) -> 524343381
S12: 46209 | T12: 290631 | U12: =SUM(T5:T12) -> 2290769 | V12: 80079360 | W12: =SUM(V5:V12) -> 600997456 | Y12: 45516 | Z12: 270000 | AA12: =SUM(Z$5:Z12) -> 2106000 | AB12: 81082015 | AC12: =SUM(AB$5:AB12) -> 605425396
S13: 46216 | T13: 286149 | U13: =SUM(T5:T13) -> 2576918 | V13: 79530196 | W13: =SUM(V5:V13) -> 680527652 | Y13: 45523 | Z13: 270000 | AA13: =SUM(Z$5:Z13) -> 2376000 | AB13: 80157875 | AC13: =SUM(AB$5:AB13) -> 685583271
S14: 46223 | T14: 286026 | U14: =SUM(T5:T14) -> 2862944 | V14: 79506289 | W14: =SUM(V5:V14) -> 760033941 | Y14: 45530 | Z14: 270000 | AA14: =SUM(Z$5:Z14) -> 2646000 | AB14: 80749121 | AC14: =SUM(AB$5:AB14) -> 766332392
S15: 46230 | T15: 280871 | U15: =SUM(T5:T15) -> 3143815 | V15: 78055194 | W15: =SUM(V5:V15) -> 838089135 | Y15: 45537 | Z15: 270000 | AA15: =SUM(Z$5:Z15) -> 2916000 | AB15: 82629245 | AC15: =SUM(AB$5:AB15) -> 848961637
S16: 46237 | T16: 280884 | U16: =SUM(T5:T16) -> 3424699 | V16: 78399793 | W16: =SUM(V5:V16) -> 916488928 | Y16: 45544 | Z16: 270000 | AA16: =SUM(Z$5:Z16) -> 3186000 | AB16: 84947821 | AC16: =SUM(AB$5:AB16) -> 933909458
A17: CEO: Ulrika Kolsrud, ble CEO i 2025 | S17: 46244 | T17: 277688 | U17: =SUM(T5:T17) -> 3702387 | V17: 77757836 | W17: =SUM(V5:V17) -> 994246764 | Y17: 45551 | Z17: 270000 | AA17: =SUM(Z$5:Z17) -> 3456000 | AB17: 86611468 | AC17: =SUM(AB$5:AB17) -> 1020520926
A18: CFO: Fredrik Rystedt, ble CFO i 2017 | S18: 46251 | T18: 275953 | U18: =SUM(T5:T18) -> 3978340 | V18: 76765020 | W18: =SUM(V5:V18) -> 1071011784 | Y18: 45558 | Z18: 270000 | AA18: =SUM(Z$5:Z18) -> 3726000 | AB18: 86119643 | AC18: =SUM(AB$5:AB18) -> 1106640569
A19: Health & medical: Anand Chandarana, ble sheriff i 2025 | S19: 46258 | T19: 282790 | U19: =SUM(T5:T19) -> 4261130 | V19: 76750144 | W19: =SUM(V5:V19) -> 1147761928 | Y19: 45565 | Z19: 270000 | AA19: =SUM(Z$5:Z19) -> 3996000 | AB19: 84493061 | AC19: =SUM(AB$5:AB19) -> 1191133630
S20: 46265 | T20: 267157 | U20: =SUM(T5:T20) -> 4528287 | V20: 74940755 | W20: =SUM(V5:V20) -> 1222702683 | Y20: 45572 | Z20: 270000 | AA20: =SUM(Z$5:Z20) -> 4266000 | AB20: 84288913 | AC20: =SUM(AB$5:AB20) -> 1275422543
A21: Professional Hygiene: Pablo Fuentes, ble sheriff 2023 | S21: 46272 | T21: 273715 | U21: =SUM(T5:T21) -> 4802002 | V21: 75551773 | W21: =SUM(V5:V21) -> 1298254456 | Y21: 45579 | Z21: 270000 | AA21: =SUM(Z$5:Z21) -> 4536000 | AB21: 83821137 | AC21: =SUM(AB$5:AB21) -> 1359243680
S22: 46279 | T22: 362503 | U22: =SUM(T5:T22) -> 5164505 | V22: 96106904 | W22: =SUM(V5:V22) -> 1394361360 | Y22: 45586 | Z22: 270000 | AA22: =SUM(Z$5:Z22) -> 4806000 | AB22: 84946250 | AC22: =SUM(AB$5:AB22) -> 1444189930
S23: 46286 | T23: 397967 | U23: =SUM(T5:T23) -> 5562472 | V23: 105152187 | W23: =SUM(V5:V23) -> 1499513547 | Y23: 45593 | Z23: 270000 | AA23: =SUM(Z$5:Z23) -> 5076000 | AB23: 83079383 | AC23: =SUM(AB$5:AB23) -> 1527269313
S24: 46293 | T24: 402677 | U24: =SUM(T5:T24) -> 5965149 | V24: 105621968 | W24: =SUM(V5:V24) -> 1605135515 | Y24: 45600 | Z24: 270000 | AA24: =SUM(Z$5:Z24) -> 5346000 | AB24: 82374273 | AC24: =SUM(AB$5:AB24) -> 1609643586
Y25: 45607 | Z25: 270000 | AA25: =SUM(Z$5:Z25) -> 5616000 | AB25: 80715398 | AC25: =SUM(AB$5:AB25) -> 1690358984
Y26: 45614 | Z26: 270000 | AA26: =SUM(Z$5:Z26) -> 5886000 | AB26: 79988175 | AC26: =SUM(AB$5:AB26) -> 1770347159
A27: Press releases: | Y27: 45621 | Z27: 270000 | AA27: =SUM(Z$5:Z27) -> 6156000 | AB27: 80358809 | AC27: =SUM(AB$5:AB27) -> 1850705968
A28: 28.09.26: Essity kjøper tilbake 402 677 B-aksjer | Y28: 45628 | Z28: 270000 | AA28: =SUM(Z$5:Z28) -> 6426000 | AB28: 81613618 | AC28: =SUM(AB$5:AB28) -> 1932319586
A29: 21.09.26: Essity kjøper tilbake 397 967 B-aksjer | Y29: 45635 | Z29: 270000 | AA29: =SUM(Z$5:Z29) -> 6696000 | AB29: 82481640 | AC29: =SUM(AB$5:AB29) -> 2014801226
A30: 21.09.26: Essity sin CFO planlegger å gi seg i rollen ila 2027 | Y30: 45642 | Z30: 270000 | AA30: =SUM(Z$5:Z30) -> 6966000 | AB30: 81340945 | AC30: =SUM(AB$5:AB30) -> 2096142171
A31: 14.09.26: Essity kjøper tilbake 362 503 B-aksjer | Y31: 45649 | Z31: 270000 | AA31: =SUM(Z$5:Z31) -> 7236000 | AB31: 79849222 | AC31: =SUM(AB$5:AB31) -> 2175991393
A32: 07.09.26: Essity kjøper tilbake 273 715 B-aksjer | Y32: 45656 | Z32: 108000 | AA32: =SUM(Z$5:Z32) -> 7344000 | AB32: 31795043 | AC32: =SUM(AB$5:AB32) -> 2207786436
A33: 31.08.26: Essity kjøper tilbake 267 157 B-aksjer | Y33: 45663 | Z33: 162000 | AA33: =SUM(Z$5:Z33) -> 7506000 | AB33: 48012756 | AC33: =SUM(AB$5:AB33) -> 2255799192
A34: 24.08.26: Essity kjøper tilbake 282 790 B-aksjer | Y34: 45670 | Z34: 216000 | AA34: =SUM(Z$5:Z34) -> 7722000 | AB34: 63849681 | AC34: =SUM(AB$5:AB34) -> 2319648873
A35: 17.08.26: Essity kjøper tilbake 275 953 B-aksjer | Y35: 45677 | Z35: 216000 | AA35: =SUM(Z$5:Z35) -> 7938000 | AB35: 63849681 | AC35: =SUM(AB$5:AB35) -> 2383498554
A36: 10.08.26: Essity kjøper tilbake 277 688 B-aksjer | Y36: 45684 | Z36: 270000 | AA36: =SUM(Z$5:Z36) -> 8208000 | AB36: 78829384 | AC36: =SUM(AB$5:AB36) -> 2462327938
A37: 03.08.26: Essity kjøper tilbake 280 884 B-aksjer | Y37: 45691 | Z37: 270000 | AA37: =SUM(Z$5:Z37) -> 8478000 | AB37: 76193460 | AC37: =SUM(AB$5:AB37) -> 2538521398
A38: 27.07.26: Essity kjøper tilbake 280 871 B-aksjer | Y38: 45698 | Z38: 270000 | AA38: =SUM(Z$5:Z38) -> 8748000 | AB38: 74747842 | AC38: =SUM(AB$5:AB38) -> 2613269240
... A40: 13.07.26: Essity kjøper tilbake 286 149 B-aksjer | Y40: 45712 | Z40: 270000 | AA40: =SUM(Z$5:Z40) -> 9288000 | AB40: 76940674 | AC40: =SUM(AB$5:AB40) -> 2766029370
A41: 06.07.26: Essity kjøper tilbake 290 631 B-aksjer | Y41: 45719 | Z41: 270000 | AA41: =SUM(Z5:Z41) -> 9558000 | AB41: 79742497 | AC41: =SUM(AB5:AB41) -> 2845771867
A42: 29.06.26: Essity kjøper tilbake 294 782 B-aksjer | Y42: 45726 | Z42: 270000 | AA42: =SUM(Z5:Z42) -> 9828000 | AB42: 81121565 | AC42: =SUM(AB5:AB42) -> 2926893432
A43: 22.06.26: Essity kjøper tilbake 243 164 B-aksjer | Y43: 45733 | Z43: 188500 | AA43: =SUM(Z5:Z43) -> 10016500 | AB43: 57682239 | AC43: =SUM(AB5:AB43) -> 2984575671
...

Sheet Modell
A3: Kapitalstruktur | C3: SEKm | D3: Q122 | E3: Q222 | F3: Q322 | G3: Q422 | H3: Q123 | I3: Q223 | J3: Q323 | K3: Q423 | L3: Q124 | M3: Q224 | N3: Q324 | O3: Q424 | P3: Q125 | Q3: Q225 | R3: Q325 | S3: Q425 | T3: Q126 | U3: Q226 | V3: Q326 | W3: Q426 | Z3: FY 2015 | AA3: FY 2016 | AB3: FY 2017 | AC3: FY 2018 | AD3: FY 2019 | AE3: FY 2020 | AF3: FY 2021 | AG3: FY 2022 | AH3: FY 2023 | AI3: FY 2024 | AJ3: FY 2025 | AK3: FY 2026 | AL3: FY 2027 | AM3: FY 2028 | AN3: FY 2029 | AO3: FY 2030 | AP3: FY 2031 | AQ3: FY 2032 | AR3: FY 2033 | AS3: FY 2034 | AT3: FY 2035
A4: Price | B4: 263 | C4: Revenue | D4: 34301 | E4: 37929 | F4: 40109 | G4: 36629 | H4: 42926 | I4: 43930 | J4: 43516 | K4: 36625 | L4: 34850 | M4: 36617 | N4: 36274 | O4: 37805 | P4: 34976 | Q4: 34185 | R4: 34638 | S4: 34695 | T4: 33177 | U4: 35061 | Z4: 98519 | AA4: 101238 | AB4: 109265 | AC4: 118500 | AD4: 128975 | AE4: 121752 | AF4: 121867 | AG4: 156173 | AH4: 147147 | AI4: 145546 | AJ4: 138494 | AK4: =AJ4*1 -> 138494 | AL4: =AK4*1.05 -> 145418.7 | AM4: =AL4*1.05 -> 152689.64 | AN4: =AM4*1.05 -> 160324.12 | AO4: =AN4*1.05 -> 168340.32 | AP4: =AO4*1.05 -> 176757.34 | AQ4: =AP4*1.05 -> 185595.21 | AR4: =AQ4*1.05 -> 194874.97 | AS4: =AR4*1.05 -> 204618.71 | AT4: =AS4*1.05 -> 214849.65
A5: S/O | B5: 681.9 | C5: COGS | D5: -26684 | E5: -28704 | F5: -30756 | G5: -26392 | H5: -31340 | I5: -32206 | J5: -31509 | K5: -24905 | L5: -23283 | M5: -24467 | N5: -24448 | O5: -25731 | P5: -23502 | Q5: -22784 | R5: -23065 | S5: -23000 | T5: -22092 | U5: -23616 | Z5: =-71960-267 -> -72227 | AA5: =-72476-532 -> -73008 | AB5: =-76899-509 -> -77408 | AC5: =-85058-1437 -> -86495 | AD5: =-90876-243 -> -91119 | AE5: =-82132-181 -> -82313 | AF5: =-86628-146 -> -86774 | AG5: =-117046-1899 -> -118945 | AH5: -102627 | AI5: -97929 | AJ5: -92351 | AK5: =AK4*-0.67 -> -92790.98 | AL5: =AL4*-0.67 -> -97430.529 | AM5: =AM4*-0.67 -> -102302.06 | AN5: =AN4*-0.67 -> -107417.16 | AO5: =AO4*-0.67 -> -112788.02 | AP5: =AP4*-0.67 -> -118427.42 | AQ5: =AQ4*-0.67 -> -124348.79 | AR5: =AR4*-0.67 -> -130566.23 | ... AT5: =AT4*-0.67 -> -143949.27
A6: MC SEKm | B6: =B4*B5 -> 179339.7 | C6: Gross profit | D6: =SUM(D4:D5) -> 7617 | E6: =SUM(E4:E5) -> 9225 | F6: =SUM(F4:F5) -> 9353 | G6: =SUM(G4:G5) -> 10237 | H6: =SUM(H4:H5) -> 11586 | I6: =SUM(I4:I5) -> 11724 | J6: =SUM(J4:J5) -> 12007 | K6: =SUM(K4:K5) -> 11720 | ... U6: =SUM(U4:U5) -> 11445 | Z6: =SUM(Z4:Z5) -> 26292 | AA6: =SUM(AA4:AA5) -> 28230 | AB6: =SUM(AB4:AB5) -> 31857 | AC6: =SUM(AC4:AC5) -> 32005 | AD6: =SUM(AD4:AD5) -> 37856 | AE6: =SUM(AE4:AE5) -> 39439 | AF6: =SUM(AF4:AF5) -> 35093 | AG6: =SUM(AG4:AG5) -> 37228 | ... AT6: =SUM(AT4:AT5) -> 70900.384
A7: Cash SEKm | B7: =T43 -> 10741 | C7: Sales, general and admin costs | D7: -5968 | E7: -6585 | F7: -6575 | G7: -6132 | H7: -7143 | I7: -7517 | J7: -8366 | K7: -6874 | L7: -6689 | M7: -6808 | N7: -6735 | O7: -7119 | P7: -6768 | Q7: -6708 | R7: -6517 | S7: -6578 | T7: -6482 | U7: -6760 | Z7: =-16287-519 -> -16806 | AA7: =-17086-2293 -> -19379 | AB7: =-19130-346 -> -19476 | AC7: =-20570+62 -> -20508 | AD7: =-22319-470 -> -22789 | AE7: =-22088+122 -> -21966 | AF7: =-21617+517 -> -21100 | AG7: =-26107-272 -> -26379 | AH7: -25661 | AI7: -27351 | AJ7: -26571 | AK7: =AJ7*1.04 -> -27633.84 | AL7: =AK7*1.05 -> -29015.532 | AM7: =AL7*1.05 -> -30466.309 | AN7: =AM7*1.05 -> -31989.624 | AO7: =AN7*1.05 -> -33589.105 | AP7: =AO7*1.05 -> -35268.56 | AQ7: =AP7*1.05 -> -37031.989 | AR7: =AQ7*1.05 -> -38883.588 | AS7: =AR7*1.05 -> -40827.767 | AT7: =AS7*1.05 -> -42869.156
A8: Debt SEKm | B8: =(T50+T55) -> 42311 | C8: share of profits of associates and JV | D8: 14 | E8: 10 | F8: 6 | G8: 7 | H8: 2 | I8: 8 | J8: 22 | K8: 7 | L8: 2 | M8: 56 | N8: 0 | O8: 14 | P8: 0 | Q8: 0 | R8: 0 | S8: 0 | T8: -179 | U8: -581 | Z8: 198 | AA8: 157 | AB8: 169 | AC8: 63 | AD8: 60 | AE8: 94 | AF8: 58 | AG8: 38 | AH8: 39 | AI8: 78 | AJ8: 0 | AK8: =AJ8*1.03 -> 0 | AL8: 0 | AM8: 0 | AN8: 0 | AO8: 0 | AP8: 0 | AQ8: 0 | AR8: 0 | AS8: 0 | AT8: 0
A9: EV SEKm | B9: =B6-B7+B8 -> 210909.7 | C9: EBITA | D9: =SUM(D6:D8) -> 1663 | E9: =SUM(E6:E8) -> 2650 | F9: =SUM(F6:F8) -> 2784 | G9: =SUM(G6:G8) -> 4112 | H9: =SUM(H6:H8) -> 4445 | I9: =SUM(I6:I8) -> 4215 | J9: =SUM(J6:J8) -> 3663 | K9: =SUM(K6:K8) -> 4853 | ... U9: =SUM(U6:U8) -> 4104 | Z9: =SUM(Z6:Z8) -> 9684 | AA9: =SUM(AA6:AA8) -> 9008 | AB9: =SUM(AB6:AB8) -> 12550 | AC9: =SUM(AC6:AC8) -> 11560 | AD9: =SUM(AD6:AD8) -> 15127 | AE9: =SUM(AE6:AE8) -> 17567 | AF9: =SUM(AF6:AF8) -> 14051 | AG9: =SUM(AG6:AG8) -> 10887 | ... AT9: =SUM(AT6:AT8) -> 28031.229
C10: Amortization | D10: -513 | E10: -283 | F10: -293 | G10: -288 | H10: -286 | I10: -314 | J10: -596 | K10: -270 | L10: -320 | M10: -258 | N10: -262 | O10: -270 | P10: -256 | Q10: -241 | R10: -243 | S10: -232 | T10: -245 | U10: -259 | Z10: 0 | AA10: 0 | AB10: =-560-85 -> -645 | AC10: =-732-69 -> -801 | AD10: -778 | AE10: -809 | AF10: -852 | AG10: =-1116-292 -> -1408 | AH10: -1109 | AI10: -1110 | AJ10: -972 | AK10: =AJ10*1.01 -> -981.72 | AL10: =AK10*1.01 -> -991.5372 | AM10: =AL10*1.01 -> -1001.4526 | AN10: =AM10*1.01 -> -1011.4671 | AO10: =AN10*1.01 -> -1021.5818 | AP10: =AO10*1.01 -> -1031.7976 | AQ10: =AP10*1.01 -> -1042.1156 | AR10: =AQ10*1.01 -> -1052.5367 | ... AT10: =AS10*1.01 -> -1073.6927
C11: Operating profit (EBIT) | D11: =SUM(D9:D10) -> 1150 | E11: =SUM(E9:E10) -> 2367 | F11: =SUM(F9:F10) -> 2491 | G11: =SUM(G9:G10) -> 3824 | H11: =SUM(H9:H10) -> 4159 | I11: =SUM(I9:I10) -> 3901 | J11: =SUM(J9:J10) -> 3067 | K11: =SUM(K9:K10) -> 4583 | ... U11: =SUM(U9:U10) -> 3845 | Z11: =SUM(Z9:Z10) -> 9684 | AA11: =SUM(AA9:AA10) -> 9008 | AB11: =SUM(AB9:AB10) -> 11905 | AC11: =SUM(AC9:AC10) -> 10759 | AD11: =SUM(AD9:AD10) -> 14349 | AE11: =SUM(AE9:AE10) -> 16758 | AF11: =SUM(AF9:AF10) -> 13199 | AG11: =SUM(AG9:AG10) -> 9479 | ... AT11: =SUM(AT9:AT10) -> 26957.536
A12: Gearing | B12: =(B8-B7)/AK9 -> 1.7471739 | C12: Shares of profit from assoc and JV | D12: 0 | E12: 0 | F12: 0 | G12: 0 | H12: 0 | I12: 0 | J12: 0 | K12: 0 | L12: 0 | M12: 0 | N12: 0 | O12: 0 | P12: -1 | Q12: 14 | R12: -4 | S12: 5 | T12: -4 | U12: 37 | Z12: 0 | AA12: 0 | AB12: 0 | AC12: 0 | AD12: 0 | AE12: 0 | AF12: 0 | AG12: 0 | AH12: 412 | AI12: 593 | AJ12: 14 | AK12: 0 | AL12: 0 | AM12: 0 | AN12: 0 | AO12: 0 | AP12: 0 | AQ12: 0 | AR12: 0 | AS12: 0 | AT12: 0
C13: Financial items | D13: -208 | E13: -224 | F13: -368 | G13: -561 | H13: -655 | I13: -633 | J13: -691 | K13: -499 | L13: -607 | M13: -478 | N13: -430 | O13: -416 | P13: -373 | Q13: -333 | R13: -369 | S13: -309 | T13: -250 | U13: -307 | Z13: =312-1140 -> -828 | AA13: =202-1037 -> -835 | AB13: =158-1340 -> -1182 | AC13: =91-1248 -> -1157 | AD13: =106-1415 -> -1309 | AE13: =108-1066 -> -958 | AF13: =102-764 -> -662 | AG13: =173-1543 -> -1370 | AH13: -2768 | AI13: -2524 | AJ13: -1384 | AK13: 0 | AL13: 0 | AM13: 0 | AN13: 0 | AO13: 0 | AP13: 0 | AQ13: 0 | AR13: 0 | AS13: 0 | AT13: 0
C14: PTP | D14: =SUM(D11:D13) -> 942 | E14: =SUM(E11:E13) -> 2143 | F14: =SUM(F11:F13) -> 2123 | G14: =SUM(G11:G13) -> 3263 | H14: =SUM(H11:H13) -> 3504 | I14: =SUM(I11:I13) -> 3268 | J14: =SUM(J11:J13) -> 2376 | K14: =SUM(K11:K13) -> 4084 | ... U14: =SUM(U11:U13) -> 3575 | Z14: =SUM(Z11:Z13) -> 8856 | AA14: =SUM(AA11:AA13) -> 8173 | AB14: =SUM(AB11:AB13) -> 10723 | AC14: =SUM(AC11:AC13) -> 9602 | AD14: =SUM(AD11:AD13) -> 13040 | AE14: =SUM(AE11:AE13) -> 15800 | AF14: =SUM(AF11:AF13) -> 12537 | AG14: =SUM(AG11:AG13) -> 8109 | ... AT14: =SUM(AT11:AT13) -> 26957.536
C15: Tax | D15: -421 | E15: -470 | F15: -499 | G15: -736 | H15: -801 | I15: -717 | J15: -725 | K15: -984 | L15: -1050 | M15: -1166 | N15: -1109 | O15: -1106 | P15: -1025 | Q15: -1014 | R15: -1178 | S15: -1226 | T15: -1041 | U15: -883 | Z15: -2278 | AA15: -3931 | AB15: -1938 | AC15: -1050 | AD15: -2828 | AE15: -4053 | AF15: -2727 | AG15: -2045 | AH15: -3275 | AI15: -4331 | AJ15: -4443 | AK15: =AK14*-0.2 -> -3417.492 | AL15: =AL14*-0.2 -> -3596.2204 | AM15: =AM14*-0.2 -> -3783.9637 | AN15: =AN14*-0.2 -> -3981.1735 | AO15: =AO14*-0.2 -> -4188.3239 | AP15: =AP14*-0.2 -> -4405.9127 | AQ15: =AQ14*-0.2 -> -4634.4628 | AR15: =AR14*-0.2 -> -4874.5228 | ... AT15: =AT14*-0.2 -> -5391.5072
C16: Net income | D16: =SUM(D14:D15) -> 521 | E16: =SUM(E14:E15) -> 1673 | F16: =SUM(F14:F15) -> 1624 | G16: =SUM(G14:G15) -> 2527 | H16: =SUM(H14:H15) -> 2703 | I16: =SUM(I14:I15) -> 2551 | J16: =SUM(J14:J15) -> 1651 | K16: =SUM(K14:K15) -> 3100 | ... U16: =SUM(U14:U15) -> 2692 | Z16: =SUM(Z14:Z15) -> 6578 | AA16: =SUM(AA14:AA15) -> 4242 | AB16: =SUM(AB14:AB15) -> 8785 | AC16: =SUM(AC14:AC15) -> 8552 | AD16: =SUM(AD14:AD15) -> 10212 | AE16: =SUM(AE14:AE15) -> 11747 | AF16: =SUM(AF14:AF15) -> 9810 | AG16: =SUM(AG14:AG15) -> 6064 | ... AT16: =SUM(AT14:AT15) -> 21566.029 | AU16: =AT16*(1+$AW$20) -> 21350.369 | AV16: =AU16*(1+$AW$20) -> 21136.865 | AW16: =AV16*(1+$AW$20) -> 20925.496 | AX16: =AW16*(1+$AW$20) -> 20716.241 | AY16: =AX16*(1+$AW$20) -> 20509.079 | AZ16: =AY16*(1+$AW$20) -> 20303.988 | BA16: =AZ16*(1+$AW$20) -> 20100.948 | BB16: =BA16*(1+$AW$20) -> 19899.939 | ... KN16: =KM16*(1+$AW$20) -> 1679.2278
C17: Shares | D17: 702.3 | E17: 702.3 | F17: 702.3 | G17: 702.3 | H17: 702.3 | I17: 702.3 | J17: 702.3 | K17: 702.3 | L17: 702.3 | M17: 702.3 | N17: 700 | O17: 696.5 | P17: 693.4 | Q17: 691.5 | R17: 687.4 | S17: 683.9 | T17: 681.9 | U17: 678.58781 | Z17: 702.3 | AA17: 702.3 | AB17: 702.3 | AC17: 702.3 | AD17: 702.3 | AE17: 702.3 | AF17: 702.3 | AG17: 702.3 | AH17: 702.3 | AI17: 649.9 | AJ17: 683.9 | AK17: 681.9 | AL17: 681.9 | AM17: 681.9 | AN17: 681.9 | AO17: 681.9 | AP17: 681.9 | AQ17: 681.9 | AR17: 681.9 | AS17: 681.9 | AT17: 681.9
C18: EPS | D18: =D16/D17 -> 0.74184821 | E18: =E16/E17 -> 2.3821729 | F18: =F16/F17 -> 2.3124021 | G18: =G16/G17 -> 3.5981774 | H18: =H16/H17 -> 3.8487826 | I18: =I16/I17 -> 3.6323508 | J18: =J16/J17 -> 2.3508472 | K18: =K16/K17 -> 4.4140681 | ... U18: =U16/U17 -> 3.9670621 | Z18: =Z16/Z17 -> 9.3663676 | AA18: =AA16/AA17 -> 6.0401538 | AB18: =AB16/AB17 -> 12.508899 | AC18: =AC16/AC17 -> 12.177132 | AD18: =AD16/AD17 -> 14.540795 | AE18: =AE16/AE17 -> 16.72647 | AF18: =AF16/AF17 -> 13.96839 | AG18: =AG16/AG17 -> 8.6344867 | ... AT18: =AT16/AT17 -> 31.62638
AV19: Discount | AW19: 0.08
C20: Revenue y/y | H20: =(H4-D4)/D4 -> 0.2514504 | I20: =(I4-E4)/E4 -> 0.15821667 | J20: =(J4-F4)/F4 -> 0.084943529 | K20: =(K4-G4)/G4 -> -0.00010920309 | L20: =(L4-H4)/H4 -> -0.18813773 | M20: =(M4-I4)/I4 -> -0.16646938 | N20: =(N4-J4)/J4 -> -0.16642155 | O20: =(O4-K4)/K4 -> 0.03221843 | ... U20: =(U4-Q4)/Q4 -> 0.025625274 | AA20: =(AA4-Z4)/Z4 -> 0.027598737 | AB20: =(AB4-AA4)/AA4 -> 0.079288409 | AC20: =(AC4-AB4)/AB4 -> 0.084519288 | AD20: =(AD4-AC4)/AC4 -> 0.088396624 | AE20: =(AE4-AD4)/AD4 -> -0.056003101 | AF20: =(AF4-AE4)/AE4 -> 0.00094454301 | AG20: =(AG4-AF4)/AF4 -> 0.28150361 | AH20: =(AH4-AG4)/AG4 -> -0.057794881 | ... AT20: =(AT4-AS4)/AS4 -> 0.05 | AV20: TV | AW20: -0.01
C21: Organic growth | G21: 0.177 | H21: 0.172 | I21: 0.128 | J21: 0.046 | K21: -0.007 | L21: -0.04 | M21: -0.009 | N21: 0.019 | O21: 0.039 | P21: 0.021 | Q21: 0.019 | R21: 0.009 | S21: -0.011 | T21: 0.004 | U21: 0.003 | AB21: 0.1 | AC21: 0.026 | AD21: 0.045 | AE21: -0.019 | AF21: 0.033 | AG21: 0.157 | AH21: 0.067 | AI21: 0.002 | AV21: NPV | AW21: =NPV(AW19,AK16:KN16) -> 222698.69
C22: Gross margin | D22: =D6/D4 -> 0.2220635 | E22: =E6/E4 -> 0.24321759 | F22: =F6/F4 -> 0.23318956 | G22: =G6/G4 -> 0.27947801 | H22: =H6/H4 -> 0.26990635 | I22: =I6/I4 -> 0.26687913 | J22: =J6/J4 -> 0.2759215 | K22: =K6/K4 -> 0.32 | ... U22: =U6/U4 -> 0.32643108 | Z22: =Z6/Z4 -> 0.26687238 | AA22: =AA6/AA4 -> 0.27884786 | AB22: =AB6/AB4 -> 0.29155722 | AC22: =AC6/AC4 -> 0.27008439 | AD22: =AD6/AD4 -> 0.29351425 | AE22: =AE6/AE4 -> 0.32392897 | AF22: =AF6/AF4 -> 0.28796147 | AG22: =AG6/AG4 -> 0.23837667 | ... AT22: =AT6/AT4 -> 0.33 | AV22: S/O | AW22: 681.9
C23: EBITA margin | D23: =D9/D4 -> 0.048482552 | E23: =E9/E4 -> 0.069867384 | F23: =F9/F4 -> 0.069410855 | G23: =G9/G4 -> 0.11226078 | H23: =H9/H4 -> 0.1035503 | I23: =I9/I4 -> 0.095948099 | J23: =J9/J4 -> 0.084175935 | K23: =K9/K4 -> 0.13250512 | ... U23: =U9/U4 -> 0.11705314 | Z23: =Z9/Z4 -> 0.09829576 | AA23: =AA9/AA4 -> 0.088978447 | AB23: =AB9/AB4 -> 0.11485837 | AC23: =AC9/AC4 -> 0.097552743 | AD23: =AD9/AD4 -> 0.1172863 | AE23: =AE9/AE4 -> 0.1442851 | AF23: =AF9/AF4 -> 0.11529782 | AG23: =AG9/AG4 -> 0.069711154 | ... AT23: =AT9/AT4 -> 0.13046905 | AV23: NPV/Share | AW23: =AW21/AW22 -> 326.58556
C24: EBIT margin | D24: =D11/D4 -> 0.033526719 | E24: =E11/E4 -> 0.062406075 | F24: =F11/F4 -> 0.062105762 | G24: =G11/G4 -> 0.10439815 | H24: =H11/H4 -> 0.096887667 | I24: =I11/I4 -> 0.088800364 | J24: =J11/J4 -> 0.070479824 | K24: =K11/K4 -> 0.12513311 | ... U24: =U11/U4 -> 0.10966601 | Z24: =Z11/Z4 -> 0.09829576 | AA24: =AA11/AA4 -> 0.088978447 | AB24: =AB11/AB4 -> 0.10895529 | AC24: =AC11/AC4 -> 0.090793249 | AD24: =AD11/AD4 -> 0.11125412 | AE24: =AE11/AE4 -> 0.13764045 | AF24: =AF11/AF4 -> 0.1083066 | AG24: =AG11/AG4 -> 0.060695511 | ... AT24: =AT11/AT4 -> 0.12547163 | AV24: Opp/Nedside | AW24: =(AW23-B4)/B4 -> 0.2417702
C25: ROCE | Z25: 0.292 | AA25: 0.128 | AB25: 0.139 | AC25: 0.153 | AD25: 0.152 | AE25: 0.164 | AF25: 0.163 | AG25: 0.089 | AH25: 0.144 | AI25: 0.169
C27: Balanse SEKm
C28: Goodwill | D28: 38554 | E28: 40524 | F28: 45763 | G28: 44786 | H28: 44964 | I28: 47005 | J28: 45777 | K28: 38337 | L28: 41271 | M28: 40841 | N28: 38769 | O28: 41137 | P28: 38124 | Q28: 37914 | R28: 37614 | S28: 36861 | T28: 38804 | U28: 39324 | Z28: 15412 | AA28: 19253 | AB28: 31697 | AC28: 33553 | AD28: 34581 | AE28: 32324 | AF28: 37803 | AG28: 44786 | AH28: 38337 | AI28: 41137 | AJ28: 36861
C29: Intangible assets | D29: 22699 | E29: 23118 | F29: 25667 | G29: 25346 | H29: 25713 | I29: 26202 | J29: 25431 | K29: 21345 | L29: 21968 | M29: 21393 | N29: 20679 | O29: 20734 | P29: 19343 | Q29: 19204 | R29: 18818 | S29: 18273 | T29: 19478 | U29: 19105 | Z29: 7351 | AA29: 7665 | AB29: 21424 | AC29: 21475 | AD29: 21182 | AE29: 18574 | AF29: 21806 | AG29: 25346 | AH29: 21345 | AI29: 20734 | AJ29: 18273
C30: PP&E | D30: 58974 | E30: 61540 | F30: 63857 | G30: 62898 | H30: 63583 | I30: 66054 | J30: 64719 | K30: 48843 | L30: 47328 | M30: 46596 | N30: 45478 | O30: 48304 | P30: 45097 | Q30: 45847 | R30: 46130 | S30: 46308 | T30: 48054 | U30: 49188 | Z30: 42402 | AA30: 47494 | AB30: 48482 | AC30: 51673 | AD30: 56900 | AE30: 53631 | AF30: 58918 | AG30: 57471 | AH30: 48843 | AI30: 48304 | AJ30: 46308
C31: Right of use assets | D31: 0 | E31: 0 | F31: 0 | G31: 0 | H31: 0 | I31: 0 | J31: 0 | K31: 0 | L31: 4066 | M31: 4040 | N31: 3916 | O31: 4088 | P31: 4055 | Q31: 3930 | R31: 3807 | S31: 3752 | T31: 3823 | U31: 3834 | Z31: 0 | AA31: 0 | AB31: 0 | AC31: 0 | AD31: 0 | AE31: 0 | AF31: 0 | AG31: 5427 | AH31: 0 | AI31: 4088 | AJ31: 3752
C32: Investments in associates and JV | D32: 255 | E32: 268 | F32: 280 | G32: 291 | H32: 297 | I32: 302 | J32: 299 | K32: 294 | L32: 309 | M32: 329 | N32: 330 | O32: 351 | P32: 330 | Q32: 325 | R32: 311 | S32: 307 | T32: 307 | U32: 332 | Z32: 1041 | AA32: 1096 | AB32: 1062 | AC32: 777 | AD32: 865 | AE32: 847 | AF32: 239 | AG32: 291 | AH32: 294 | AI32: 351 | AJ32: 307
C33: Shares and participations | D33: 8 | E33: 9 | F33: 9 | G33: 6 | H33: 6 | I33: 6 | J33: 6 | K33: 6 | L33: 6 | M33: 8 | N33: 8 | O33: 8 | P33: 8 | Q33: 8 | R33: 8 | S33: 8 | T33: 8 | U33: 8 | Z33: 33 | AA33: 32 | AB33: 32 | AC33: 29 | AD33: 8 | AE33: 1 | AF33: 7 | AG33: 6 | AH33: 6 | AI33: 8 | AJ33: 8
C34: Surplus in funded pension plans | D34: 1637 | E34: 2118 | F34: 1876 | G34: 1965 | H34: 2349 | I34: 2845 | J34: 2780 | K34: 3072 | L34: 4012 | M34: 3798 | N34: 3788 | O34: 2475 | P34: 2593 | Q34: 2688 | R34: 3489 | S34: 4340 | T34: 7811 | U34: 9453 | Z34: 35 | AA34: 335 | AB34: 1148 | AC34: 1117 | AD34: 2841 | AE34: 2817 | AF34: 1439 | AG34: 1965 | AH34: 3072 | AI34: 2475 | AJ34: 4340
C35: Non-current financial assets | D35: 300 | E35: 116 | F35: 119 | G35: 123 | H35: 131 | I35: 140 | J35: 130 | K35: 117 | L35: 123 | M35: 122 | N35: 127 | O35: 128 | P35: 221 | Q35: 229 | R35: 124 | S35: 142 | T35: 124 | U35: 129 | Z35: 728 | AA35: 714 | AB35: 552 | AC35: 634 | AD35: 694 | AE35: 281 | AF35: 412 | AG35: 123 | AH35: 117 | AI35: 128 | AJ35: 142
C36: Deferred assets | D36: 1999 | E36: 2165 | F36: 2666 | G36: 2545 | H36: 2710 | I36: 3032 | J36: 3071 | K36: 2343 | L36: 2561 | M36: 2394 | N36: 2195 | O36: 2326 | P36: 2203 | Q36: 2274 | R36: 2279 | S36: 2122 | T36: 2067 | U36: 2185 | Z36: 1056 | AA36: 1457 | AB36: 2232 | AC36: 2158 | AD36: 2539 | AE36: 1823 | AF36: 2012 | AG36: 2545 | AH36: 2343 | AI36: 2326 | AJ36: 2122
C37: Other non-current assets | D37: 1625 | E37: 2457 | F37: 4039 | G37: 1620 | H37: 989 | I37: 952 | J37: 884 | K37: 745 | L37: 778 | M37: 778 | N37: 746 | O37: 824 | P37: 728 | Q37: 727 | R37: 747 | S37: 725 | T37: 898 | U37: 860 | Z37: 149 | AA37: 241 | AB37: 469 | AC37: 705 | AD37: 704 | AE37: 768 | AF37: 1411 | AG37: 1620 | AH37: 745 | AI37: 824 | AJ37: 725
C38: Inventories | D38: 20695 | E38: 23283 | F38: 27127 | G38: 28888 | H38: 29845 | I38: 28027 | J38: 24784 | K38: 17546 | L38: 19031 | M38: 19110 | N38: 18814 | O38: 18914 | P38: 18493 | Q38: 19258 | R38: 19193 | S38: 18153 | T38: 19395 | U38: 20339 | Z38: 11229 | AA38: 10944 | AB38: 13739 | AC38: 15234 | AD38: 15764 | AE38: 16383 | AF38: 19339 | AG38: 28888 | AH38: 17546 | AI38: 18914 | AJ38: 18153
C39: Trade receivables | D39: 21180 | E39: 24870 | F39: 25996 | G39: 25990 | H39: 26395 | I39: 28444 | J39: 26824 | K39: 21920 | L39: 23686 | M39: 23554 | N39: 22447 | O39: 23538 | P39: 22278 | Q39: 23137 | R39: 22425 | S39: 21332 | T39: 22689 | U39: 23993 | Z39: 14806 | AA39: 15843 | AB39: 17607 | AC39: 18687 | AD39: 19864 | AE39: 17825 | AF39: 19871 | AG39: 25990 | AH39: 21920 | AI39: 23538 | AJ39: 21332
... C43: Cash | D43: 5273 | E43: 4995 | F43: 10113 | G43: 4288 | H43: 8904 | I43: 6513 | J43: 6391 | K43: 5159 | L43: 11373 | M43: 10442 | N43: 11826 | O43: 10962 | P43: 9769 | Q43: 3927 | R43: 6229 | S43: 8487 | T43: 10741 | U43: 5495 | Z43: 4828 | AA43: 4244 | AB43: 4107 | AC43: 3008 | AD43: 2992 | AE43: 4982 | AF43: 3904 | AG43: 4288 | AH43: 5159 | AI43: 10982 | AJ43: 8487
C44: Total assets | D44: =SUM(D28:D43) -> 184276 | E44: =SUM(E28:E43) -> 198381 | F44: =SUM(F28:F43) -> 225210 | G44: =SUM(G28:G43) -> 210600 | H44: =SUM(H28:H43) -> 215752 | I44: =SUM(I28:I43) -> 221603 | J44: =SUM(J28:J43) -> 211863 | K44: =SUM(K28:K43) -> 169666 | ... U44: =SUM(U28:U43) -> 181535 | Z44: =SUM(Z28:Z43) -> 102814 | AA44: =SUM(AA28:AA43) -> 112635 | AB44: =SUM(AB28:AB43) -> 146290 | AC44: =SUM(AC28:AC43) -> 152156 | AD44: =SUM(AD28:AD43) -> 162317 | AE44: =SUM(AE28:AE43) -> 154182 | AF44: =SUM(AF28:AF43) -> 175050 | AG44: =SUM(AG28:AG43) -> 210600 | ... AJ44: =SUM(AJ28:AJ43) -> 167116
C45: Share capital | D45: 2350 | E45: 2350 | F45: 2350 | G45: 2350 | H45: 2350 | I45: 2350 | J45: 2350 | K45: 2350 | L45: 2350 | M45: 2350 | N45: 2350 | O45: 2350 | P45: 2350 | Q45: 2350 | R45: 2350 | S45: 2350 | T45: 2350 | U45: 2350 | Z45: 0 | AA45: 0 | AB45: 2350 | AC45: 2350 | AD45: 2350 | AE45: 2350 | AF45: 2350 | AG45: 2350 | AH45: 2350 | AI45: 2350 | AJ45: 2350
C46: Reserves | D46: 9753 | E46: 14785 | F46: 20339 | G46: 11477 | H46: 10596 | I46: 14299 | J46: 13883 | K46: 9421 | L46: 13685 | M46: 12250 | N46: 9624 | O46: 13224 | P46: 6768 | Q46: 6495 | R46: 6035 | S46: 4257 | T46: 7490 | U46: 9128 | Z46: 1501 | AA46: 4061 | AB46: 3154 | AC46: 5003 | AD46: 6284 | AE46: 581 | AF46: 6416 | AG46: 11477 | AH46: 9421 | AI46: 13224 | AJ46: 4257
...

Sheet Segementer
B4: SEKm | C4: Q122 | D4: Q222 | E4: Q322 | F4: Q422 | G4: 2022 | H4: Q123 | I4: Q223 | J4: Q323 | K4: Q423 | L4: 2023 | M4: Q124 | N4: Q224 | O4: Q324 | P4: Q424 | Q4: 2024 | R4: Q125 | S4: Q225 | T4: Q325 | U4: Q425 | V4: 2025 | W4: Q126 | X4: Q226 | Y4: Q326 | Z4: Q426 | AA4: 2026
B5: Health & medical
B6: Revenue | G6: 25239 | H6: 6665 | I6: 6905 | J6: 7158 | K6: 7001 | L6: =SUM(H6:K6) -> 27729 | M6: 6842 | N6: 7213 | O6: 7127 | P6: 7417 | Q6: =SUM(M6:P6) -> 28599 | R6: 6936 | S6: 6723 | T6: 6883 | U6: 6926 | V6: =SUM(R6:U6) -> 27468 | W6: 6499 | X6: 6918
B7: y/y | G7: 0.096 | H7: =(H6-C6)/C6 -> #DIV/0! | I7: =(I6-D6)/D6 -> #DIV/0! | J7: =(J6-E6)/E6 -> #DIV/0! | K7: =(K6-F6)/F6 -> #DIV/0! | L7: =(L6-G6)/G6 -> 0.098656841 | M7: =(M6-H6)/H6 -> 0.026556639 | N7: =(N6-I6)/I6 -> 0.044605358 | O7: =(O6-J6)/J6 -> -0.0043308187 | ... AA7: =(AA6-V6)/V6 -> -1
B8: Organic growth | G8: 0.078 | H8: 0.106 | I8: 0.08 | J8: 0.058 | K8: 0.043 | L8: 0.07 | M8: 0.026 | N8: 0.045 | O8: 0.028 | P8: 0.056 | Q8: 0.039 | R8: 0.017 | S8: 0.001 | T8: 0.017 | U8: 0.007 | W8: 0.005 | X8: 0.031
B9: Gross profit margin | G9: 0.369 | H9: 0.378 | I9: 0.39 | J9: 0.42 | K9: 0.423 | L9: 0.403 | M9: 0.452 | N9: 0.455 | O9: 0.447 | P9: 0.441 | Q9: 0.449 | R9: 0.444 | S9: 0.437 | T9: 0.438 | U9: 0.442 | W9: 0.449 | X9: 0.448
B10: EBITA | C10: 836 | D10: 673 | E10: 673 | F10: 719 | G10: =SUM(C10:F10) -> 2901 | H10: 777 | I10: 947 | J10: 1188 | K10: 1125 | L10: =SUM(H10:K10) -> 4037 | M10: 1290 | N10: 1472 | O10: 1386 | P10: 1361 | Q10: =SUM(M10:P10) -> 5509 | R10: 1231 | S10: 1159 | T10: 1260 | U10: 1296 | V10: =SUM(R10:U10) -> 4946 | W10: 1193 | X10: 1310 | AA10: =SUM(W10:Z10) -> 2503
B11: EBITA margin | G11: =G10/G6 -> 0.11494116 | H11: 0.117 | I11: 0.137 | J11: 0.166 | K11: 0.161 | L11: =L10/L6 -> 0.14558765 | M11: 0.189 | N11: 0.204 | O11: 0.194 | P11: 0.183 | Q11: =Q10/Q6 -> 0.19262911 | R11: 0.177 | S11: 0.172 | T11: 0.183 | U11: 0.161 | V11: =V10/V6 -> 0.18006407 | W11: 0.184 | X11: 0.189 | AA11: =AA10/AA6 -> #DIV/0!
B12: ROCE | M12: 0.154 | N12: 0.172 | O12: 0.165 | P12: 0.161 | R12: 0.147 | S12: 0.141 | T12: 0.153 | U12: 0.161 | W12: 0.149 | X12: 0.16
B13: Personal care
B14: Revenue | L14: =SUM(H14:K14) -> 0 | M14: 8090 | N14: 8422 | O14: 8083 | P14: 8411 | Q14: =SUM(M14:P14) -> 33006 | R14: 7984 | S14: 7763 | T14: 7927 | U14: 7884 | V14: =SUM(R14:U14) -> 31558 | W14: 8180 | X14: 8815 | AA14: =SUM(W14:Z14) -> 16995
B15: y/y | H15: =(H14-C14)/C14 -> #DIV/0! | I15: =(I14-D14)/D14 -> #DIV/0! | J15: =(J14-E14)/E14 -> #DIV/0! | K15: =(K14-F14)/F14 -> #DIV/0! | L15: =(L14-G14)/G14 -> #DIV/0! | M15: =(M14-H14)/H14 -> #DIV/0! | N15: =(N14-I14)/I14 -> #DIV/0! | O15: =(O14-J14)/J14 -> #DIV/0! | ... AA15: =(AA14-V14)/V14 -> -0.46146777
B16: Organic growth | M16: 0.023 | N16: 0.037 | O16: 0.044 | P16: 0.048 | R16: 0.03 | S16: 0.036 | T16: 0.045 | U16: 0.015 | W16: 0.041 | X16: 0.038
B17: Gross profit margin | R17: 0.423 | W17: 0.425 | X17: 0.399
B18: EBITA | L18: =SUM(H18:K18) -> 0 | M18: 1214 | N18: 1349 | O18: 1261 | P18: 1221 | Q18: =SUM(M18:P18) -> 5045 | R18: 1198 | S18: 1120 | T18: 1110 | U18: 990 | V18: =SUM(R18:U18) -> 4418 | W18: 1262 | X18: 1131 | AA18: =SUM(W18:Z18) -> 2393
B19: EBITA margin | L19: =L18/L14 -> #DIV/0! | M19: 0.15 | N19: 0.16 | O19: 0.156 | P19: 0.145 | Q19: =Q18/Q14 -> 0.152851 | R19: 0.15 | S19: 0.144 | T19: 0.14 | U19: 0.126 | V19: =V18/V14 -> 0.1399962 | W19: 0.154 | X19: 0.128 | AA19: =AA18/AA14 -> 0.14080612
B20: ROCE | M20: 0.271 | N20: 0.293 | O20: 0.284 | P20: 0.273 | R20: 0.262 | S20: 0.247 | T20: 0.24 | U20: 0.215 | W20: 0.247 | X20: 0.198
B21: Consumer Tissue
B22: Revenue | L22: =SUM(H22:K22) -> 0 | M22: 11248 | N22: 11250 | O22: 11327 | P22: 12061 | Q22: =SUM(M22:P22) -> 45886 | R22: 11301 | S22: 10671 | T22: 10656 | U22: 10909 | V22: =SUM(R22:U22) -> 43537 | W22: 10356 | X22: 10202 | AA22: =SUM(W22:Z22) -> 20558
B23: y/y | H23: =(H22-C22)/C22 -> #DIV/0! | I23: =(I22-D22)/D22 -> #DIV/0! | J23: =(J22-E22)/E22 -> #DIV/0! | K23: =(K22-F22)/F22 -> #DIV/0! | L23: =(L22-G22)/G22 -> #DIV/0! | M23: =(M22-H22)/H22 -> #DIV/0! | N23: =(N22-I22)/I22 -> #DIV/0! | O23: =(O22-J22)/J22 -> #DIV/0! | ... AA23: =(AA22-V22)/V22 -> -0.52780394
B24: Organic growth | M24: -0.09 | N24: -0.047 | O24: 0.02 | P24: 0.043 | R24: 0.027 | S24: 0.029 | T24: -0.019 | U24: -0.044 | W24: -0.035 | X24: -0.053
B25: Gross profit margin | R25: 0.205 | W25: 0.207 | X25: 0.194
B26: EBITA | L26: =SUM(H26:K26) -> 0 | M26: 1331 | N26: 1085 | O26: 1024 | P26: 1024 | Q26: =SUM(M26:P26) -> 4464 | R26: 1245 | S26: 1248 | T26: 1252 | U26: 1442 | V26: =SUM(R26:U26) -> 5187 | W26: 1112 | X26: 988 | AA26: =SUM(W26:Z26) -> 2100
B27: EBITA margin | L27: =L26/L22 -> #DIV/0! | M27: 0.118 | N27: 0.096 | O27: 0.09 | P27: 0.085 | Q27: =Q26/Q22 -> 0.097284575 | R27: 0.11 | S27: 0.117 | T27: 0.117 | U27: 0.132 | V27: =V26/V22 -> 0.11914004 | W27: 0.107 | X27: 0.097 | AA27: =AA26/AA22 -> 0.10215001
B28: ROCE | M28: 0.15 | N28: 0.12 | O28: 0.115 | P28: 0.114 | R28: 0.141 | S28: 0.143 | T28: 0.141 | U28: 0.164 | W28: 0.128 | X28: 0.111
B29: Professional Hygiene
B30: Revenue | G30: 36114 | H30: 9422 | I30: 10123 | J30: 10184 | K30: 9752 | L30: =SUM(H30:K30) -> 39481 | M30: 8686 | N30: 9729 | O30: 9729 | P30: 9923 | Q30: =SUM(M30:P30) -> 38067 | R30: 8757 | S30: 9003 | T30: 9183 | U30: 8961 | V30: =SUM(R30:U30) -> 35904 | W30: 8139 | X30: 9127 | AA30: =SUM(W30:Z30) -> 17266
B31: y/y | G31: 0.25 | H31: =(H30-C30)/C30 -> #DIV/0! | I31: =(I30-D30)/D30 -> #DIV/0! | J31: =(J30-E30)/E30 -> #DIV/0! | K31: =(K30-F30)/F30 -> #DIV/0! | L31: =(L30-G30)/G30 -> 0.093232541 | M31: =(M30-H30)/H30 -> -0.07811505 | N31: =(N30-I30)/I30 -> -0.038921268 | O31: =(O30-J30)/J30 -> -0.044677926 | ... AA31: =(AA30-V30)/V30 -> -0.51910651
B32: Organic growth | G32: 0.229 | H32: 0.226 | I32: 0.117 | J32: 0.057 | K32: 0.001 | L32: 0.091 | M32: -0.069 | N32: -0.039 | O32: -0.008 | P32: 0.014 | Q32: -0.025 | R32: 0.007 | S32: 0.006 | T32: 0.007 | U32: -0.008 | W32: 0.019 | X32: 0.021
B33: Gross profit margin | G33: 0.231 | H33: 0.263 | I33: 0.281 | J33: 0.302 | K33: 0.305 | L33: 0.288 | M33: 0.299 | N33: 0.325 | O33: 0.318 | P33: 0.322 | Q33: 0.317 | R33: 0.31 | S33: 0.317 | T33: 0.325 | U33: 0.34 | W33: 0.313 | X33: 0.312
B34: EBITA | C34: 563 | D34: 916 | E34: 1096 | F34: 1405 | G34: =SUM(C34:F34) -> 3980 | H34: 1288 | I34: 1582 | J34: 1887 | K34: 1531 | L34: =SUM(H34:K34) -> 6288 | M34: 1332 | N34: 1868 | O34: 1812 | P34: 1817 | Q34: =SUM(M34:P34) -> 6829 | R34: 1413 | S34: 1525 | T34: 1676 | U34: 1750 | V34: =SUM(R34:U34) -> 6364 | W34: 1311 | X34: 1573 | AA34: =SUM(W34:Z34) -> 2884
B35: EBITA margin | G35: =G34/G30 -> 0.11020657 | H35: 0.137 | I35: 0.156 | J35: 0.185 | K35: 0.157 | L35: =L34/L30 -> 0.15926648 | M35: 0.153 | N35: 0.192 | O35: 0.186 | P35: 0.183 | Q35: =Q34/Q30 -> 0.17939423 | R35: 0.161 | S35: 0.169 | T35: 0.183 | U35: 0.195 | V35: =V34/V30 -> 0.17725045 | W35: 0.161 | X35: 0.172 | AA35: =AA34/AA30 -> 0.16703348
B36: ROCE | M36: 0.214 | N36: 0.289 | O36: 0.287 | P36: 0.288 | R36: 0.22 | S36: 0.238 | T36: 0.262 | U36: 0.277 | W36: 0.204 | X36: 0.235
B41: Consumer goods
B42: Revenue | G42: 94841 | H42: 20257 | I42: 20056 | J42: 19729 | K42: 19870 | L42: =SUM(H42:K42) -> 79912 | M42: 19338 | N42: 19672 | O42: 19410 | P42: 20472 | Q42: =SUM(M42:P42) -> 78892 | R42: 19285 | S42: 18434 | T42: 18583 | U42: 18793 | V42: =SUM(R42:U42) -> 75095 | AA42: =SUM(W42:Z42) -> 0
B43: y/y | G43: 0.175 | H43: =(H42-C42)/C42 -> #DIV/0! | I43: =(I42-D42)/D42 -> #DIV/0! | J43: =(J42-E42)/E42 -> #DIV/0! | K43: =(K42-F42)/F42 -> #DIV/0! | L43: =(L42-G42)/G42 -> -0.15741082 | M43: =(M42-H42)/H42 -> -0.045367034 | N43: =(N42-I42)/I42 -> -0.01914639 | O43: =(O42-J42)/J42 -> -0.016169091 | ... AA43: =(AA42-V42)/V42 -> -1
B44: Organic growth | G44: 0.157 | H44: 0.148 | I44: 0.057 | J44: -0.004 | K44: -0.028 | L44: 0.037 | M44: -0.048 | N44: -0.013 | O44: 0.03 | P44: 0.045 | Q44: 0.003 | R44: 0.029 | S44: 0.032 | T44: 0.008 | U44: -0.02
B45: Gross profit margin | G45: 0.226 | H45: 0.263 | I45: 0.263 | J45: 0.283 | K45: 0.293 | L45: 0.275 | M45: 0.304 | N45: 0.29 | O45: 0.285 | P45: 0.275 | Q45: 0.288 | R45: 0.295 | S45: 0.305 | T45: 0.299 | U45: 0.297
B46: EBITA | C46: 1645 | D46: 1861 | E46: 1460 | F46: 2293 | G46: =SUM(C46:F46) -> 7259 | H46: 2400 | I46: 2417 | J46: 2395 | K46: 2585 | L46: =SUM(H46:K46) -> 9797 | M46: 2545 | N46: 2434 | O46: 2285 | P46: 2245 | Q46: =SUM(M46:P46) -> 9509 | R46: 2443 | S46: 2368 | T46: 2362 | U46: 2432 | V46: =SUM(R46:U46) -> 9605 | AA46: =SUM(W46:Z46) -> 0
B47: EBITA margin | G47: =G46/G42 -> 0.076538628 | H47: 0.118 | I47: 0.121 | J47: 0.121 | K47: 0.13 | L47: =L46/L42 -> 0.12259736 | M47: 0.132 | N47: 0.124 | O47: 0.118 | P47: 0.11 | Q47: =Q46/Q42 -> 0.12053187 | R47: 0.127 | S47: 0.128 | T47: 0.127 | U47: 0.129 | V47: =V46/V42 -> 0.12790465 | AA47: =AA46/AA42 -> #DIV/0!

Sheet SOTP
A4: EBITDA 26E
A5: =Modell!AK9 -> 18069.18
B7: SEKm | D7: EBITA 26E | E7: Multippel | F7: Value | G7: Per/share
B8: Health & medical | D8: 4800 | E8: 14 | F8: =D8*E8 -> 67200 | G8: =F8/Modell!$B$5 -> 98.548174
B9: Personal Care | D9: 4600 | E9: 12 | F9: =D9*E9 -> 55200 | G9: =F9/Modell!$B$5 -> 80.950286
B10: Consumer Tissue | D10: 4450 | E10: 9 | F10: =D10*E10 -> 40050 | G10: =F10/Modell!$B$5 -> 58.732952
B11: Professional Hygiene | D11: 5950 | E11: 13 | F11: =D11*E11 -> 77350 | G11: =F11/Modell!$B$5 -> 113.43305
B13: Enterprise value | G13: =SUM(G8:G11) -> 351.66447
B15: Debt | F15: =Modell!B8 -> 42311 | G15: =-F15/Modell!$B$5 -> -62.048687
B16: Cash | F16: =Modell!B7 -> 10741 | G16: =F16/Modell!$B$5 -> 15.751576
B18: Implied value/Share | G18: =SUM(G13:G16) -> 305.36736

Sheet Nøkkeltall
D4: 2026 | E4: 2027 | F4: 2028
C5: EV/EBITA | D5: =Modell!$B$9/Modell!AK9 -> 11.672345 | E5: =Modell!$B$9/Modell!AL9 -> 11.116519 | F5: =Modell!$B$9/Modell!AM9 -> 10.587161
C6: EV/EBIT | D6: =Modell!$B$9/Modell!AK11 -> 12.342952 | E6: =Modell!$B$9/Modell!AL11 -> 11.72952 | F6: =Modell!$B$9/Modell!AM11 -> 11.147554
C7: P/E | D7: =Modell!$B$4/Modell!AK18 -> 13.119248 | E7: =Modell!$B$4/Modell!AL18 -> 12.467235 | F7: =Modell!$B$4/Modell!AM18 -> 11.848667

Sheet Nedsideberegning
A3: Nedside | D3: FY 2015 | E3: FY 2016 | F3: FY 2017 | G3: FY 2018 | H3: FY 2019 | I3: FY 2020 | J3: FY 2021 | K3: FY 2022 | L3: FY 2023 | M3: FY 2024 | N3: FY 2025 | O3: FY 2026 | P3: FY 2027 | Q3: FY 2028 | R3: FY 2029 | S3: FY 2030 | T3: FY 2031 | U3: FY 2032 | V3: FY 2033 | W3: FY 2034 | X3: FY 2035
A4: Nullvekst og ned på marginer | C4: Revenue | D4: 98519 | E4: 101238 | F4: 109265 | G4: 118500 | H4: 128975 | I4: 121752 | J4: 121867 | K4: 156173 | L4: 147147 | M4: 145546 | N4: 138494 | O4: =N4*1 -> 138494 | P4: =O4*1 -> 138494 | Q4: =P4*1 -> 138494 | R4: =Q4*1 -> 138494 | S4: =R4*1 -> 138494 | T4: =S4*1 -> 138494 | U4: =T4*1 -> 138494 | V4: =U4*1 -> 138494 | ... X4: =W4*1 -> 138494
A5: =AA23 -> 192.41355 | C5: COGS | D5: =-71960-267 -> -72227 | E5: =-72476-532 -> -73008 | F5: =-76899-509 -> -77408 | G5: =-85058-1437 -> -86495 | H5: =-90876-243 -> -91119 | I5: =-82132-181 -> -82313 | J5: =-86628-146 -> -86774 | K5: =-117046-1899 -> -118945 | L5: -102627 | M5: -97929 | N5: -92351 | O5: =O4*-0.7 -> -96945.8 | P5: =P4*-0.7 -> -96945.8 | Q5: =Q4*-0.7 -> -96945.8 | R5: =R4*-0.7 -> -96945.8 | S5: =S4*-0.7 -> -96945.8 | T5: =T4*-0.7 -> -96945.8 | U5: =U4*-0.7 -> -96945.8 | V5: =V4*-0.7 -> -96945.8 | ... X5: =X4*-0.7 -> -96945.8
A6: =AA24 -> -0.26838953 | C6: Gross profit | D6: =SUM(D4:D5) -> 26292 | E6: =SUM(E4:E5) -> 28230 | F6: =SUM(F4:F5) -> 31857 | G6: =SUM(G4:G5) -> 32005 | H6: =SUM(H4:H5) -> 37856 | I6: =SUM(I4:I5) -> 39439 | J6: =SUM(J4:J5) -> 35093 | K6: =SUM(K4:K5) -> 37228 | ... X6: =SUM(X4:X5) -> 41548.2
C7: Sales, general and admin costs | D7: =-16287-519 -> -16806 | E7: =-17086-2293 -> -19379 | F7: =-19130-346 -> -19476 | G7: =-20570+62 -> -20508 | H7: =-22319-470 -> -22789 | I7: =-22088+122 -> -21966 | J7: =-21617+517 -> -21100 | K7: =-26107-272 -> -26379 | L7: -25661 | M7: -27351 | N7: -26571 | O7: =N7*1 -> -26571 | P7: =O7*1 -> -26571 | Q7: =P7*1 -> -26571 | R7: =Q7*1 -> -26571 | S7: =R7*1 -> -26571 | T7: =S7*1 -> -26571 | U7: =T7*1 -> -26571 | V7: =U7*1 -> -26571 | ... X7: =W7*1 -> -26571
C8: share of profits of associates and JV | D8: 198 | E8: 157 | F8: 169 | G8: 63 | H8: 60 | I8: 94 | J8: 58 | K8: 38 | L8: 39 | M8: 78 | N8: 0 | O8: =N8*1.03 -> 0 | P8: 0 | Q8: 0 | R8: 0 | S8: 0 | T8: 0 | U8: 0 | V8: 0 | W8: 0 | X8: 0
C9: EBITA | D9: =SUM(D6:D8) -> 9684 | E9: =SUM(E6:E8) -> 9008 | F9: =SUM(F6:F8) -> 12550 | G9: =SUM(G6:G8) -> 11560 | H9: =SUM(H6:H8) -> 15127 | I9: =SUM(I6:I8) -> 17567 | J9: =SUM(J6:J8) -> 14051 | K9: =SUM(K6:K8) -> 10887 | ... X9: =SUM(X6:X8) -> 14977.2
C10: Amortization | D10: 0 | E10: 0 | F10: =-560-85 -> -645 | G10: =-732-69 -> -801 | H10: -778 | I10: -809 | J10: -852 | K10: =-1116-292 -> -1408 | L10: -1109 | M10: -1110 | N10: -972 | O10: =N10*1.01 -> -981.72 | P10: =O10*1.01 -> -991.5372 | Q10: =P10*1.01 -> -1001.4526 | R10: =Q10*1.01 -> -1011.4671 | S10: =R10*1.01 -> -1021.5818 | T10: =S10*1.01 -> -1031.7976 | U10: =T10*1.01 -> -1042.1156 | V10: =U10*1.01 -> -1052.5367 | ... X10: =W10*1.01 -> -1073.6927
C11: Operating profit (EBIT) | D11: =SUM(D9:D10) -> 9684 | E11: =SUM(E9:E10) -> 9008 | F11: =SUM(F9:F10) -> 11905 | G11: =SUM(G9:G10) -> 10759 | H11: =SUM(H9:H10) -> 14349 | I11: =SUM(I9:I10) -> 16758 | J11: =SUM(J9:J10) -> 13199 | K11: =SUM(K9:K10) -> 9479 | ... X11: =SUM(X9:X10) -> 13903.507
C12: Shares of profit from assoc and JV | D12: 0 | E12: 0 | F12: 0 | G12: 0 | H12: 0 | I12: 0 | J12: 0 | K12: 0 | L12: 412 | M12: 593 | N12: 14 | O12: 0 | P12: 0 | Q12: 0 | R12: 0 | S12: 0 | T12: 0 | U12: 0 | V12: 0 | W12: 0 | X12: 0
C13: Financial items | D13: =312-1140 -> -828 | E13: =202-1037 -> -835 | F13: =158-1340 -> -1182 | G13: =91-1248 -> -1157 | H13: =106-1415 -> -1309 | I13: =108-1066 -> -958 | J13: =102-764 -> -662 | K13: =173-1543 -> -1370 | L13: -2768 | M13: -2524 | N13: -1384 | O13: 0 | P13: 0 | Q13: 0 | R13: 0 | S13: 0 | T13: 0 | U13: 0 | V13: 0 | W13: 0 | X13: 0
C14: PTP | D14: =SUM(D11:D13) -> 8856 | E14: =SUM(E11:E13) -> 8173 | F14: =SUM(F11:F13) -> 10723 | G14: =SUM(G11:G13) -> 9602 | H14: =SUM(H11:H13) -> 13040 | I14: =SUM(I11:I13) -> 15800 | J14: =SUM(J11:J13) -> 12537 | K14: =SUM(K11:K13) -> 8109 | ... X14: =SUM(X11:X13) -> 13903.507
C15: Tax | D15: -2278 | E15: -3931 | F15: -1938 | G15: -1050 | H15: -2828 | I15: -4053 | J15: -2727 | K15: -2045 | L15: -3275 | M15: -4331 | N15: -4443 | O15: =O14*-0.2 -> -2799.096 | P15: =P14*-0.2 -> -2797.1326 | Q15: =Q14*-0.2 -> -2795.1495 | R15: =R14*-0.2 -> -2793.1466 | S15: =S14*-0.2 -> -2791.1236 | T15: =T14*-0.2 -> -2789.0805 | U15: =U14*-0.2 -> -2787.0169 | V15: =V14*-0.2 -> -2784.9327 | ... X15: =X14*-0.2 -> -2780.7015
C16: Net income | D16: =SUM(D14:D15) -> 6578 | E16: =SUM(E14:E15) -> 4242 | F16: =SUM(F14:F15) -> 8785 | G16: =SUM(G14:G15) -> 8552 | H16: =SUM(H14:H15) -> 10212 | I16: =SUM(I14:I15) -> 11747 | J16: =SUM(J14:J15) -> 9810 | K16: =SUM(K14:K15) -> 6064 | ... X16: =SUM(X14:X15) -> 11122.806 | Y16: =X16*(1+$AA$20) -> 11011.578 | Z16: =Y16*(1+$AA$20) -> 10901.462 | AA16: =Z16*(1+$AA$20) -> 10792.447 | AB16: =AA16*(1+$AA$20) -> 10684.523 | AC16: =AB16*(1+$AA$20) -> 10577.678 | AD16: =AC16*(1+$AA$20) -> 10471.901 | AE16: =AD16*(1+$AA$20) -> 10367.182 | AF16: =AE16*(1+$AA$20) -> 10263.51 | ... HQ16: =HP16*(1+$AA$20) -> 1475.3276
C17: Shares | D17: 702.3 | E17: 702.3 | F17: 702.3 | G17: 702.3 | H17: 702.3 | I17: 702.3 | J17: 702.3 | K17: 702.3 | L17: 702.3 | M17: 649.9 | N17: 683.9 | O17: 683.9 | P17: 683.9 | Q17: 683.9 | R17: 683.9 | S17: 683.9 | T17: 683.9 | U17: 683.9 | V17: 683.9 | W17: 683.9 | X17: 683.9
C18: EPS | D18: =D16/D17 -> 9.3663676 | E18: =E16/E17 -> 6.0401538 | F18: =F16/F17 -> 12.508899 | G18: =G16/G17 -> 12.177132 | H18: =H16/H17 -> 14.540795 | I18: =I16/I17 -> 16.72647 | J18: =J16/J17 -> 13.96839 | K18: =K16/K17 -> 8.6344867 | ... X18: =X16/X17 -> 16.26379
Z19: Discount | AA19: 0.08
C20: Revenue y/y | E20: =(E4-D4)/D4 -> 0.027598737 | F20: =(F4-E4)/E4 -> 0.079288409 | G20: =(G4-F4)/F4 -> 0.084519288 | H20: =(H4-G4)/G4 -> 0.088396624 | I20: =(I4-H4)/H4 -> -0.056003101 | J20: =(J4-I4)/I4 -> 0.00094454301 | K20: =(K4-J4)/J4 -> 0.28150361 | L20: =(L4-K4)/K4 -> -0.057794881 | ... X20: =(X4-W4)/W4 -> 0 | Z20: TV | AA20: -0.01
C21: Gross margin | D21: =D6/D4 -> 0.26687238 | E21: =E6/E4 -> 0.27884786 | F21: =F6/F4 -> 0.29155722 | G21: =G6/G4 -> 0.27008439 | H21: =H6/H4 -> 0.29351425 | I21: =I6/I4 -> 0.32392897 | J21: =J6/J4 -> 0.28796147 | K21: =K6/K4 -> 0.23837667 | ... X21: =X6/X4 -> 0.3 | Z21: NPV | AA21: =NPV(AA19,O16:JR16) -> 131591.63
C22: EBIT margin | D22: =D11/D4 -> 0.09829576 | E22: =E11/E4 -> 0.088978447 | F22: =F11/F4 -> 0.10895529 | G22: =G11/G4 -> 0.090793249 | H22: =H11/H4 -> 0.11125412 | I22: =I11/I4 -> 0.13764045 | J22: =J11/J4 -> 0.1083066 | K22: =K11/K4 -> 0.060695511 | ... X22: =X11/X4 -> 0.10039068 | Z22: S/O | AA22: 683.9
Z23: NPV/Share | AA23: =AA21/AA22 -> 192.41355
Z24: Opp/Nedside | AA24: =(AA23-Modell!B4)/Modell!B4 -> -0.26838953
