Workbook

Sheet Info
A3: Finansielle mål (fra prospekt) | P3: Covenants
A4: Mål | B4: 2026E | C4: Mellomlang sikt | D4: Kommentar
A5: Omsetning | B5: > NOK 1 500m | C5: NOK 2 800m | D5: Inkl. fullårseffekt av ny M&A / organisk vekst og M&A
A6: EBITA-margin | B6: N/A | C6: ~20% | T6: =Modell!B12 -> -1.7280388
A7: Capex (% av omsetning) | B7: ~2-4% | C7: ~4% | D7: Kan avvike pga. produktsykluser, FoU og PPE-investeringer | T7: =Modell!U60/Modell!U53 -> 0.73234452
A8: Arbeidskapital (% av omsetning) | B8: ~15-20% | C8: ~15-20% | D8: Potensielle svingninger drevet av backlog og forskuddsbetalte kontrakter | T8: =Modell!B7 -> 545.818
A9: Justert ROCE | B9: N/A | C9: >30%
A10: NIBD/EBITDA | B10: Robust balanse for M&A | C10: ~1.0-2.0x | D10: Fleksibilitet til å avvike basert på M&A og verdiskapende investeringer
A11: Utbyttepolitikk | B11: — | C11: 40-60% av nettoresultat | D11: Langsiktig ambisjon; fleksibilitet for M&A og verdiskapende investeringer
D12: Kilde: General Oceans ASA – Prospekt
A14: Datterselskaper i General Oceans
A16: SENSORS-segmentet
A17: Selskap | B17: Land | C17: Spesialisering | D17: Beskrivelse
A18: Nortek | B18: 🇳🇴 Norge | C18: ADCP / Doppler-sensorer | D18: Eldste og største selskapet. Akustiske strømmålere og Doppler-sensorer for havmåling. Brukes i offshore-energi, havforskning og navigasjon. Kjernen i General Oceans-konseptet.
A19: Tritech | B19: 🇬🇧 UK | C19: Imaging sonarer / undervannsk. | D19: Imaging sonarer og undervannskameraer for inspeksjon og navigasjon. Gjennomgått stor transformasjon etter oppkjøp med ny ledelse og produktrasjonalisering. Ny produktgenerasjon i 2026.
A20: Klein Marine Systems | B20: 🇺🇸 USA | C20: Side-scan sonarer | D20: Produserer side-scan sonarer for havbunnskartlegging og søk. Turnaround-case som krevde mer restrukturering enn forventet etter oppkjøp i 2023, inkl. relokasjon og ny ledelse.
A21: RS Aqua | B21: 🇬🇧🇦🇺 UK/Australia | C21: Havmåleutstyr / distribusjon | D21: Nyeste tilskuddet (nov. 2024). Distribuerer og integrerer havmåleutstyr og sensorer. Fungerer delvis som salgskanal for andre GO-produkter. Bidrar med tilstedeværelse i Australia.
A23: ROBOTICS-segmentet
A24: Selskap | B24: Land | C24: Spesialisering | D24: Beskrivelse
A25: Reach Robotics | B25: 🇬🇧 UK | C25: Elektriske manipulatorer / ROV | D25: Produserer elektriske manipulatorer og robotarmer for undervannsfartøy (ROV-er). Leverer til forsvars- og kommersielle kunder. Sterk vekst drevet av forsvarskontrakter.
A26: SRS (Strategic Robotic Systems) | B26: 🇺🇸🇦🇺 USA/Australia | C26: Hybrid ROV/AUV | D26: Produserer hybrid ROV-er (Fusion-modellen) som kan operere både som ROV og autonom farkost (AUV). Hadde store utfordringer etter tapt forsvarskontrakt i 2023 (nedskrivning NOK 117m), men nå snudd under ny ledelse.
A27: MRV Systems | B27: 🇺🇸 USA | C27: Autonome havobservasjonsflåter | D27: Oppkjøpt april 2026 for USD 18m (EV/Rev 1,5x). Produserer autonome profileringsflåter (Argo-floats) som samler havdata (temperatur, saltholdighet, strøm) ned til 2000m dyp. Inngår i ARGO-programmet – et globalt nettverk av ~4 000 havobservasjonsboier. Integreres i Robotics-segmentet.
A29: Oppsummert: Nortek og Tritech er mest modne. Klein og RS Aqua er under integrasjon. Reach Robotics er vekststjernen i robotics. SRS har hatt mest turbulens, men viser nå tegn til bedring.
A32: IPO info
A33: Eksisterende aksjer før IPO | B33: 168.43578 | C33: =B33*21 -> 3537.1514
A34: Nye aksjer utstedt i IPO | B34: 23.809523 | C34: =B34*21 -> 499.99998
A35: Nedsalg eksiterende aksjonærer | B35: 26.190477 | C35: =B35*21 -> 550.00002
A36: Greenshoe (15% over-allotment) | B36: 7.5 | C36: =B36*21 -> 157.5
A37: Maks total etter IPO | B37: =B33+B34 -> 192.24531 | C37: =B37*21 -> 4037.1514
A39: Emisjon på 500 mill
A40: Nedsalg på inntil 550 mill
A41: Green shoe 150 mill
A42: Selskapsverdi før nye penger 3,44 mrd
A43: De nye pengene skal brukes til M&A og generelle bedriftsmål
A45: Press releases:
A46: 31.07.26 Trøgda flagger 5%
A47: 21.07.26: Fidelity flagger 7,67%
A48: 10.04.26: GENO kjøper opp MRV systems for 18 USDm cash. MRV leverer avanserte profildroner til havforskning, klimaovervåking og maritim overvåking. Oppkjøpet er på EV/REV 1,5x
A49: 27.03.26: Dnb Asset managment kjøpte 2 702 207 nye aksjer og flagger 6,28%
A50: 26.03.26: General Oceans sin første handelsdag

Sheet Modell
AJ1: Mål: 2800
A3: Kapitalstruktur | C3: NOKm | D3: Q122 | E3: Q222 | F3: Q322 | G3: Q422 | H3: Q123 | I3: Q223 | J3: Q323 | K3: Q423 | L3: Q124 | M3: Q224 | N3: Q324 | O3: Q424 | P3: Q125 | Q3: Q225 | R3: Q325 | S3: Q425 | T3: Q126 | U3: Q226 | W3: Q326 | X3: Q426 | Z3: FY 2020 | AA3: FY 2021 | AB3: FY 2022 | AC3: FY 2023 | AD3: FY 2024 | AE3: FY 2025 | AF3: FY 2026 | AG3: FY 2027 | AH3: FY 2028 | AI3: FY 2029 | AJ3: FY 2030 | AK3: FY 2031 | AL3: FY 2032 | AM3: FY 2033 | AN3: FY 2034 | AO3: FY 2035
A4: Price | B4: 18.5 | C4: Revenue | L4: 220 | M4: 230 | N4: 213 | O4: 298 | P4: 341.664 | Q4: 307.97 | R4: 282 | S4: 361 | T4: 324.015 | U4: 381.139 | Z4: 279.976 | AA4: 334.384 | AB4: 629.639 | AC4: 809.769 | AD4: 953.269 | AE4: 1280.41 | AF4: =AE4*1.12 -> 1434.0592 | AG4: =AF4*1.15 -> 1649.1681 | AH4: =AG4*1.18 -> 1946.0183 | AI4: =AH4*1.18 -> 2296.3016 | AJ4: =AI4*1.18 -> 2709.6359 | AK4: =AJ4*1.15 -> 3116.0813 | AL4: =AK4*1.12 -> 3490.0111 | AM4: =AL4*1.1 -> 3839.0122 | AN4: =AM4*1.1 -> 4222.9134 | AO4: =AN4*1.1 -> 4645.2047
A5: S/O | B5: 192.24531 | C5: Lease and other income | P5: 3 | Q5: 8.3 | T5: 3 | U5: 4 | Z5: 34.068 | AA5: 29.345 | AB5: 10.81 | AC5: 7.209 | AD5: 7.352 | AE5: 23.452 | AF5: 0 | AG5: 0 | AH5: 0 | AJ5: 0 | AK5: 0 | AL5: 0 | AM5: 0 | AN5: 0
A6: MC NOKm | B6: =B4*B5 -> 3556.5382 | C6: Raw materials | P6: -130.407 | Q6: -97.974 | T6: -106.607 | U6: -116.082 | Z6: -76.896 | AA6: -101.228 | AB6: -195.172 | AC6: -247.986 | AD6: -319.815 | AE6: -459.06 | AF6: =AF4*-0.3 -> -430.21776 | AG6: =AG4*-0.3 -> -494.75042 | AH6: =AH4*-0.3 -> -583.8055 | AI6: =AI4*-0.3 -> -688.89049 | AJ6: =AJ4*-0.3 -> -812.89078 | AK6: =AK4*-0.3 -> -934.8244 | AL6: =AL4*-0.3 -> -1047.0033 | AM6: =AM4*-0.3 -> -1151.7037 | ... AO6: =AO4*-0.3 -> -1393.5614
A7: Cash NOKm | B7: =U52 -> 545.818 | C7: Gross profit | P7: =SUM(P4:P6) -> 214.257 | Q7: =SUM(Q4:Q6) -> 218.296 | T7: =SUM(T4:T6) -> 220.408 | U7: =SUM(U4:U6) -> 269.057 | Z7: =SUM(Z4:Z6) -> 237.148 | AA7: =SUM(AA4:AA6) -> 262.501 | AB7: =SUM(AB4:AB6) -> 445.277 | AC7: =SUM(AC4:AC6) -> 568.992 | AD7: =SUM(AD4:AD6) -> 640.806 | AE7: =SUM(AE4:AE6) -> 844.802 | AF7: =SUM(AF4:AF6) -> 1003.8414 | AG7: =SUM(AG4:AG6) -> 1154.4177 | ... AO7: =SUM(AO4:AO6) -> 3251.6433
A8: Debt NOKm | B8: =(U61+U67) -> 0 | C8: Employee benefits | P8: -100.365 | Q8: -97 | T8: -108.72 | U8: -123.155 | Z8: -117.809 | AA8: -127.423 | AB8: -214.007 | AC8: -278.114 | AD8: -371.141 | AE8: -427.673 | AF8: =AE8*1.16 -> -496.10068 | AG8: =AF8*1.14 -> -565.55478 | AH8: =AG8*1.17 -> -661.69909 | AI8: =AH8*1.18 -> -780.80492 | AJ8: =AI8*1.17 -> -913.54176 | AK8: =AJ8*1.15 -> -1050.573 | AL8: =AK8*1.12 -> -1176.6418 | AM8: =AL8*1.1 -> -1294.306 | AN8: =AM8*1.1 -> -1423.7366 | AO8: =AN8*1.1 -> -1566.1102
A9: EV NOKm | B9: =B6-B7+B8 -> 3010.7202 | C9: D/A | P9: -17 | Q9: -15.861 | T9: -15.699 | U9: -25.138 | Z9: -7.312 | AA9: -10.481 | AB9: -30.707 | AC9: -50.047 | AD9: -59.385 | AE9: -64.818 | AF9: =AE9*1.15 -> -74.5407 | AG9: =AF9*1.14 -> -84.976398 | AH9: =AG9*1.18 -> -100.27215 | AI9: =AH9*1.18 -> -118.32114 | AJ9: =AI9*1.18 -> -139.61894 | AK9: =AJ9*1.15 -> -160.56178 | AL9: =AK9*1.12 -> -179.8292 | AM9: =AL9*1.1 -> -197.81212 | AN9: =AM9*1.1 -> -217.59333 | AO9: =AN9*1.1 -> -239.35266
C10: Other operating expenses | P10: -37.15 | Q10: -40.219 | T10: -49 | U10: -53.131 | Z10: -41.729 | AA10: -50.564 | AB10: -85.62 | AC10: -280.083 | AD10: -140.47 | AE10: -158.632 | AF10: =AE10*1.15 -> -182.4268 | AG10: =AF10*1.14 -> -207.96655 | AH10: =AG10*1.18 -> -245.40053 | AI10: =AH10*1.18 -> -289.57263 | AJ10: =AI10*1.18 -> -341.6957 | AK10: =AJ10*1.15 -> -392.95005 | AL10: =AK10*1.12 -> -440.10406 | AM10: =AL10*1.1 -> -484.11447 | AN10: =AM10*1.1 -> -532.52591 | AO10: =AN10*1.1 -> -585.77851
C11: Other gains and lossen | P11: 1.4 | Q11: 0.305 | T11: 0 | U11: -0.125 | Z11: 0 | AA11: 0 | AB11: 0 | AC11: 0 | AD11: 0.133 | AE11: -8.221 | AF11: =AE11*1.15 -> -9.45415 | AG11: =AF11*1.14 -> -10.777731 | AH11: =AG11*1.18 -> -12.717723 | AI11: 0 | AJ11: 0 | AK11: 0 | AL11: 0 | AM11: 0 | AN11: 0 | AO11: 0
A12: Gearing | B12: =(B8-B7)/AF27 -> -1.7280388 | C12: Operating profit (EBIT) | D12: =SUM(D7:D11) -> 0 | E12: =SUM(E7:E11) -> 0 | F12: =SUM(F7:F11) -> 0 | G12: =SUM(G7:G11) -> 0 | H12: =SUM(H7:H11) -> 0 | I12: =SUM(I7:I11) -> 0 | J12: =SUM(J7:J11) -> 0 | K12: =SUM(K7:K11) -> 0 | ... U12: =SUM(U7:U11) -> 67.508 | Z12: =SUM(Z7:Z11) -> 70.298 | AA12: =SUM(AA7:AA11) -> 74.033 | AB12: =SUM(AB7:AB11) -> 114.943 | AC12: =SUM(AC7:AC11) -> -39.252 | AD12: =SUM(AD7:AD11) -> 69.943 | AE12: =SUM(AE7:AE11) -> 185.458 | AF12: =SUM(AF7:AF11) -> 241.31911 | AG12: =SUM(AG7:AG11) -> 285.1422 | ... AO12: =SUM(AO7:AO11) -> 860.40194
C13: Finance income | P13: 5.648 | Q13: 16.899 | T13: 5.8 | U13: 15.316 | Z13: 13.796 | AA13: 9.784 | AB13: 20.99 | AC13: 23.025 | AD13: 41.228 | AE13: 49.906 | AF13: =AE13*1.1 -> 54.8966 | AG13: =AF13*1.1 -> 60.38626 | AH13: =AG13*1.1 -> 66.424886 | AI13: =AH13*1.1 -> 73.067375 | AJ13: =AI13*1.1 -> 80.374112 | AK13: =AJ13*1.1 -> 88.411523 | AL13: =AK13*1.1 -> 97.252676 | AM13: =AL13*1.1 -> 106.97794 | ... AO13: =AN13*1.1 -> 129.44331
C14: Finance expenses | P14: -7.465 | Q14: -9.6 | T14: -10.789 | U14: -12.144 | Z14: -25.664 | AA14: -10.781 | AB14: -26.009 | AC14: -35.867 | AD14: -48.732 | AE14: -48.112 | AF14: =AE14*1.05 -> -50.5176 | AG14: =AF14*1.05 -> -53.04348 | AH14: =AG14*1.05 -> -55.695654 | AI14: =AH14*1.05 -> -58.480437 | AJ14: =AI14*1.05 -> -61.404459 | AK14: =AJ14*1.05 -> -64.474681 | AL14: =AK14*1.05 -> -67.698416 | AM14: =AL14*1.05 -> -71.083336 | ... AO14: =AN14*1.05 -> -78.369378
C15: Share of gains / (Losses) from associate | P15: 0 | Q15: 0 | T15: 0 | U15: 0 | Z15: 0 | AA15: 0 | AB15: -4.592 | AC15: -3.392 | AD15: -1.782 | AE15: 0 | AF15: 0 | AG15: 0 | AH15: 0 | AI15: 0 | AJ15: 0 | AK15: 0 | AL15: 0 | AM15: 0 | AN15: 0 | AO15: 0
C16: PTP | D16: =SUM(D12:D15) -> 0 | E16: =SUM(E12:E15) -> 0 | F16: =SUM(F12:F15) -> 0 | G16: =SUM(G12:G15) -> 0 | H16: =SUM(H12:H15) -> 0 | I16: =SUM(I12:I15) -> 0 | J16: =SUM(J12:J15) -> 0 | K16: =SUM(K12:K15) -> 0 | ... U16: =SUM(U12:U15) -> 70.68 | Z16: =SUM(Z12:Z15) -> 58.43 | AA16: =SUM(AA12:AA15) -> 73.036 | AB16: =SUM(AB12:AB15) -> 105.332 | AC16: =SUM(AC12:AC15) -> -55.486 | AD16: =SUM(AD12:AD15) -> 60.657 | AE16: =SUM(AE12:AE15) -> 187.252 | AF16: =SUM(AF12:AF15) -> 245.69811 | AG16: =SUM(AG12:AG15) -> 292.48498 | ... AO16: =SUM(AO12:AO15) -> 911.47587
C17: Tax | P17: -15.298 | Q17: -14 | T17: -16 | U17: -6 | Z17: -10.734 | AA17: -16.061 | AB17: -26.601 | AC17: -17.039 | AD17: -21.475 | AE17: -22.171 | AF17: =AF16*-0.22 -> -54.053584 | AG17: =AG16*-0.22 -> -64.346696 | AH17: =AH16*-0.22 -> -77.627567 | AI17: =AI16*-0.22 -> -95.325867 | AJ17: =AJ16*-0.22 -> -114.58885 | AK17: =AK16*-0.22 -> -132.24396 | AL17: =AL16*-0.22 -> -148.71713 | AM17: =AM16*-0.22 -> -164.33353 | ... AO17: =AO16*-0.22 -> -200.52469
C18: Net income | D18: =SUM(D16:D17) -> 0 | E18: =SUM(E16:E17) -> 0 | F18: =SUM(F16:F17) -> 0 | G18: =SUM(G16:G17) -> 0 | H18: =SUM(H16:H17) -> 0 | I18: =SUM(I16:I17) -> 0 | J18: =SUM(J16:J17) -> 0 | K18: =SUM(K16:K17) -> 0 | ... U18: =SUM(U16:U17) -> 64.68 | Z18: =SUM(Z16:Z17) -> 47.696 | AA18: =SUM(AA16:AA17) -> 56.975 | AB18: =SUM(AB16:AB17) -> 78.731 | AC18: =SUM(AC16:AC17) -> -72.525 | AD18: =SUM(AD16:AD17) -> 39.182 | AE18: =SUM(AE16:AE17) -> 165.081 | AF18: =SUM(AF16:AF17) -> 191.64453 | AG18: =SUM(AG16:AG17) -> 228.13828 | ... AO18: =SUM(AO16:AO17) -> 710.95118 | AP18: =AO18*(1+$AR$22) -> 703.84167 | AQ18: =AP18*(1+$AR$22) -> 696.80325 | AR18: =AQ18*(1+$AR$22) -> 689.83522 | AS18: =AR18*(1+$AR$22) -> 682.93686 | AT18: =AS18*(1+$AR$22) -> 676.1075 | AU18: =AT18*(1+$AR$22) -> 669.34642 | AV18: =AU18*(1+$AR$22) -> 662.65296 | AW18: =AV18*(1+$AR$22) -> 656.02643 | ... IG18: =IF18*(1+$AR$22) -> 95.253008
C19: Shares | P19: 168.43578 | Q19: 168.43578 | T19: 165.65506 | U19: 190.4513 | Z19: 48.76543 | AA19: 48.76543 | AB19: 48.76543 | AC19: 49.32 | AD19: 169.56 | AE19: 168.5 | AF19: 190.4513 | AG19: 190.4513 | AH19: 190.4513 | AI19: 190.4513 | AJ19: 190.4513 | AK19: 190.4513 | AL19: 190.4513 | AM19: 190.4513 | AN19: 190.4513 | AO19: 190.4513
C20: EPS | D20: =D18/D19 -> #DIV/0! | E20: =E18/E19 -> #DIV/0! | F20: =F18/F19 -> #DIV/0! | G20: =G18/G19 -> #DIV/0! | H20: =H18/H19 -> #DIV/0! | I20: =I18/I19 -> #DIV/0! | J20: =J18/J19 -> #DIV/0! | K20: =K18/K19 -> #DIV/0! | ... U20: =U18/U19 -> 0.33961438 | Z20: =Z18/Z19 -> 0.97806992 | AA20: =AA18/AA19 -> 1.1683482 | AB20: =AB18/AB19 -> 1.6144839 | AC20: =AC18/AC19 -> -1.4704988 | AD20: =AD18/AD19 -> 0.23108044 | AE20: =AE18/AE19 -> 0.9797092 | AF20: =AF18/AF19 -> 1.0062653 | AG20: =AG18/AG19 -> 1.1978825 | ... AO20: =AO18/AO19 -> 3.7329815
AQ21: Discount | AR21: 0.08
C22: Revenue y/y | H22: =(H4-D4)/D4 -> #DIV/0! | I22: =(I4-E4)/E4 -> #DIV/0! | J22: =(J4-F4)/F4 -> #DIV/0! | K22: =(K4-G4)/G4 -> #DIV/0! | L22: =(L4-H4)/H4 -> #DIV/0! | M22: =(M4-I4)/I4 -> #DIV/0! | N22: =(N4-J4)/J4 -> #DIV/0! | O22: =(O4-K4)/K4 -> #DIV/0! | ... U22: =(U4-Q4)/Q4 -> 0.23758483 | AA22: =(AA4-Z4)/Z4 -> 0.19433094 | AB22: =(AB4-AA4)/AA4 -> 0.88298184 | AC22: =(AC4-AB4)/AB4 -> 0.28608457 | AD22: =(AD4-AC4)/AC4 -> 0.17721103 | AE22: =(AE4-AD4)/AD4 -> 0.34317805 | AF22: =(AF4-AE4)/AE4 -> 0.12 | AG22: =(AG4-AF4)/AF4 -> 0.15 | AH22: =(AH4-AG4)/AG4 -> 0.18 | ... AO22: =(AO4-AN4)/AN4 -> 0.1 | AQ22: TV | AR22: -0.01
C23: Gross margin | D23: =D7/D4 -> #DIV/0! | E23: =E7/E4 -> #DIV/0! | F23: =F7/F4 -> #DIV/0! | G23: =G7/G4 -> #DIV/0! | H23: =H7/H4 -> #DIV/0! | I23: =I7/I4 -> #DIV/0! | J23: =J7/J4 -> #DIV/0! | K23: =K7/K4 -> #DIV/0! | ... U23: =U7/U4 -> 0.70592881 | Z23: =Z7/Z4 -> 0.84702975 | AA23: =AA7/AA4 -> 0.78502859 | AB23: =AB7/AB4 -> 0.70719412 | AC23: =AC7/AC4 -> 0.70265965 | AD23: =AD7/AD4 -> 0.67221949 | AE23: =AE7/AE4 -> 0.65979022 | AF23: =AF7/AF4 -> 0.7 | AG23: =AG7/AG4 -> 0.7 | ... AO23: =AO7/AO4 -> 0.7 | AQ23: NPV | AR23: =NPV(AR21,AF18:IG18) -> 6308.0379
C24: EBIT margin | D24: =D12/D4 -> #DIV/0! | E24: =E12/E4 -> #DIV/0! | F24: =F12/F4 -> #DIV/0! | G24: =G12/G4 -> #DIV/0! | H24: =H12/H4 -> #DIV/0! | I24: =I12/I4 -> #DIV/0! | J24: =J12/J4 -> #DIV/0! | K24: =K12/K4 -> #DIV/0! | ... U24: =U12/U4 -> 0.17712173 | Z24: =Z12/Z4 -> 0.25108581 | AA24: =AA12/AA4 -> 0.22140114 | AB24: =AB12/AB4 -> 0.18255381 | AC24: =AC12/AC4 -> -0.048473083 | AD24: =AD12/AD4 -> 0.073371735 | AE24: =AE12/AE4 -> 0.14484267 | AF24: =AF12/AF4 -> 0.16827695 | AG24: =AG12/AG4 -> 0.17290063 | ... AO24: =AO12/AO4 -> 0.18522368 | AQ24: S/O | AR24: 190.4513
C25: ROCE | AC25: 0.15 | AD25: 0.123 | AE25: 0.432 | AQ25: NPV/Share | AR25: =AR23/AR24 -> 33.121527
AQ26: Opp/nedside | AR26: =(AR25-B4)/B4 -> 0.79035283
C27: EBITDA | P27: =P12-P9 -> 78.142 | T27: =T12-T9 -> 62.688 | U27: =U12-U9 -> 92.646 | AC27: 128.218 | AD27: 128.368 | AE27: 250.276 | AF27: =AF12-AF9 -> 315.85981 | AG27: =AG12-AG9 -> 370.1186 | AH27: =AH12-AH9 -> 442.39549 | AI27: =AI12-AI9 -> 537.03359 | AJ27: =AJ12-AJ9 -> 641.50769 | AK27: =AK12-AK9 -> 737.73384 | AL27: =AL12-AL9 -> 826.26191 | AM27: =AM12-AM9 -> 908.8881 | ... AO27: =AO12-AO9 -> 1099.7546
C28: EBITDA margin | P28: =P27/P4 -> 0.22871008 | T28: =T27/T4 -> 0.19347252 | U28: =U27/U4 -> 0.24307667 | AC28: =AC27/AC4 -> 0.15833898 | AD28: =AD27/AD4 -> 0.13466084 | AE28: =AE27/AE4 -> 0.19546551 | AF28: =AF27/AF4 -> 0.22025577 | AG28: =AG27/AG4 -> 0.22442746 | AH28: =AH27/AH4 -> 0.22733367 | AI28: =AI27/AI4 -> 0.23386892 | AJ28: =AJ27/AJ4 -> 0.23675051 | ... AO28: =AO27/AO4 -> 0.23675051
C29: EBITDA LTM | T29: =SUM(Q27:T27) -> 62.688 | U29: =SUM(R27:U27) -> 155.334
C30: Adjusted EBITA | L30: 15 | M30: 22 | N30: 22 | O30: 35 | P30: 67 | Q30: 71 | R30: 49 | S30: 47 | T30: 59 | U30: 85 | AC30: -17.196 | AD30: 93.789 | AE30: =212.078 -> 212.078
C31: Adjusted EBITA margin | L31: =L30/L4 -> 0.068181818 | M31: =M30/M4 -> 0.095652174 | N31: =N30/N4 -> 0.10328638 | O31: =O30/O4 -> 0.11744966 | P31: =P30/P4 -> 0.19609909 | Q31: =Q30/Q4 -> 0.23054194 | R31: =R30/R4 -> 0.17375887 | S31: =S30/S4 -> 0.13019391 | ... U31: =U30/U4 -> 0.22301575 | AC31: =AC30/AC4 -> -0.021235686 | AD31: =AD30/AD4 -> 0.098386709 | AE31: =AE30/AE4 -> 0.16563288
C33: Order intake | P33: 325 | Q33: 200 | R33: 420 | S33: 204 | T33: 304 | U33: 331
C34: y/y | T34: =(T33-P33)/P33 -> -0.064615385 | U34: =(U33-Q33)/Q33 -> 0.655
C35: Backlog | P35: 573 | Q35: 496 | R35: 647 | S35: 587 | T35: 546 | U35: 548
C36: Book/bill | P36: =P33/P4 -> 0.95122694 | Q36: =Q33/Q4 -> 0.6494139 | R36: =R33/R4 -> 1.4893617 | S36: =S33/S4 -> 0.56509695 | T36: =T33/T4 -> 0.93822817 | U36: =U33/U4 -> 0.86844957
C39: Balanse NOKm
C40: Goodwill | P40: 110.639 | Q40: 110.958 | S40: 110.393 | T40: 106.764 | U40: 186.075 | Z40: 0 | AA40: 169.439 | AB40: 0 | AC40: 0 | AD40: 116.258 | AE40: 110.393
C41: Intangible assets | P41: 185.006 | Q41: 176.932 | S41: 161.474 | T41: 150.687 | U41: 258.728 | Z41: 0.067 | AA41: 2.544 | AB41: 351.776 | AC41: 252.006 | AD41: 202.748 | AE41: 161.474
C42: PP&E | P42: 166.487 | Q42: 166.723 | S42: 130.029 | T42: 126.803 | U42: 131.236 | Z42: 19.733 | AA42: 25.388 | AB42: 91.58 | AC42: 159.283 | AD42: 178.447 | AE42: 130.029
C43: Right of use assets | P43: 80.863 | Q43: 82.417 | S43: 81.618 | T43: 76.581 | U43: 86.151 | Z43: 0 | AA43: 0 | AB43: 63.591 | AC43: 75.976 | AD43: 86.321 | AE43: 81.618
C44: Deferred tax assets | P44: 22.184 | Q44: 21.811 | S44: 42.108 | T44: 34.33 | U44: 55.48 | Z44: 0.373 | AA44: 1.581 | AB44: 3.257 | AC44: 7.362 | AD44: 24.122 | AE44: 42.108
...

Sheet Segementer
B5: NOKm | C5: Q122 | D5: Q222 | E5: Q322 | F5: Q422 | G5: 2022 | H5: Q123 | I5: Q223 | J5: Q323 | K5: Q423 | L5: 2023 | M5: Q124 | N5: Q224 | O5: Q324 | P5: Q424 | Q5: 2024 | R5: Q125 | S5: Q225 | T5: Q325 | U5: Q425 | V5: 2025 | W5: Q126 | X5: Q226 | Y5: Q326 | Z5: Q426 | AA5: 2026
B6: Sensors
B7: Revenue | Q7: 882.203 | R7: 318.013 | S7: 293.108 | V7: 1133.038 | W7: 257.02 | X7: 285.689 | AA7: =V7*1.15 -> 1302.9937
B8: y/y | H8: #DIV/0! | I8: =(I7-D7)/D7 -> #DIV/0! | J8: =(J7-E7)/E7 -> #DIV/0! | K8: =(K7-F7)/F7 -> #DIV/0! | L8: =(L7-G7)/G7 -> #DIV/0! | M8: =(M7-H7)/H7 -> #DIV/0! | N8: =(N7-I7)/I7 -> #DIV/0! | O8: =(O7-J7)/J7 -> #DIV/0! | P8: =(P7-K7)/K7 -> #DIV/0! | ... AA8: =(AA7-V7)/V7 -> 0.15
B9: Marine construction | Q9: 558.435 | V9: 596.909
B10: y/y | H10: =(H9-C9)/C9 -> #DIV/0! | I10: =(I9-D9)/D9 -> #DIV/0! | J10: =(J9-E9)/E9 -> #DIV/0! | K10: =(K9-F9)/F9 -> #DIV/0! | M10: =(M9-H9)/H9 -> #DIV/0! | N10: =(N9-I9)/I9 -> #DIV/0! | O10: =(O9-J9)/J9 -> #DIV/0! | P10: =(P9-K9)/K9 -> #DIV/0! | R10: =(R9-M9)/M9 -> #DIV/0! | S10: =(S9-N9)/N9 -> #DIV/0! | T10: =(T9-O9)/O9 -> #DIV/0! | U10: =(U9-P9)/P9 -> #DIV/0! | V10: =(V9-Q9)/Q9 -> 0.068896111 | W10: =(W9-R9)/R9 -> #DIV/0! | X10: =(X9-S9)/S9 -> #DIV/0! | Y10: =(Y9-T9)/T9 -> #DIV/0! | ... AA10: =(AA9-V9)/V9 -> -1
B11: Defence | Q11: 186.99 | V11: 258.365
B12: y/y | H12: =(H11-C11)/C11 -> #DIV/0! | I12: =(I11-D11)/D11 -> #DIV/0! | J12: =(J11-E11)/E11 -> #DIV/0! | K12: =(K11-F11)/F11 -> #DIV/0! | M12: =(M11-H11)/H11 -> #DIV/0! | N12: =(N11-I11)/I11 -> #DIV/0! | O12: =(O11-J11)/J11 -> #DIV/0! | P12: =(P11-K11)/K11 -> #DIV/0! | R12: =(R11-M11)/M11 -> #DIV/0! | S12: =(S11-N11)/N11 -> #DIV/0! | T12: =(T11-O11)/O11 -> #DIV/0! | U12: =(U11-P11)/P11 -> #DIV/0! | V12: =(V11-Q11)/Q11 -> 0.3817049 | W12: =(W11-R11)/R11 -> #DIV/0! | X12: =(X11-S11)/S11 -> #DIV/0! | Y12: =(Y11-T11)/T11 -> #DIV/0! | ... AA12: =(AA11-V11)/V11 -> -1
B13: Ocean science | Q13: 136.778 | V13: 277.764
B14: y/y | H14: =(H13-C13)/C13 -> #DIV/0! | I14: =(I13-D13)/D13 -> #DIV/0! | J14: =(J13-E13)/E13 -> #DIV/0! | K14: =(K13-F13)/F13 -> #DIV/0! | M14: =(M13-H13)/H13 -> #DIV/0! | N14: =(N13-I13)/I13 -> #DIV/0! | O14: =(O13-J13)/J13 -> #DIV/0! | P14: =(P13-K13)/K13 -> #DIV/0! | R14: =(R13-M13)/M13 -> #DIV/0! | S14: =(S13-N13)/N13 -> #DIV/0! | T14: =(T13-O13)/O13 -> #DIV/0! | U14: =(U13-P13)/P13 -> #DIV/0! | V14: =(V13-Q13)/Q13 -> 1.0307652 | W14: =(W13-R13)/R13 -> #DIV/0! | X14: =(X13-S13)/S13 -> #DIV/0! | Y14: =(Y13-T13)/T13 -> #DIV/0! | ... AA14: =(AA13-V13)/V13 -> -1
B15: EBITA | Q15: 147.842 | R15: 71.169 | S15: 66 | V15: 210.744 | W15: 37 | X15: 49.61
B16: EBITA % | C16: =C15/C7 -> #DIV/0! | D16: =D15/D7 -> #DIV/0! | E16: =E15/E7 -> #DIV/0! | F16: =F15/F7 -> #DIV/0! | G16: =G15/G7 -> #DIV/0! | H16: =H15/H7 -> #DIV/0! | I16: =I15/I7 -> #DIV/0! | J16: =J15/J7 -> #DIV/0! | ... AA16: =AA15/AA7 -> 0
B17: EBIT | Q17: 140.068 | R17: 68.811 | S17: 63.961 | V17: 199.995 | W17: 34.337 | X17: 46.954 | AA17: 210
B18: EBIT% | C18: =C17/C7 -> #DIV/0! | D18: =D17/D7 -> #DIV/0! | E18: =E17/E7 -> #DIV/0! | F18: =F17/F7 -> #DIV/0! | G18: =G17/G7 -> #DIV/0! | H18: =H17/H7 -> #DIV/0! | I18: =I17/I7 -> #DIV/0! | J18: =J17/J7 -> #DIV/0! | ... AA18: =AA17/AA7 -> 0.16116732
B19: Robotics
B20: Revenue | Q20: 79.048 | R20: 24.184 | S20: 23.323 | V20: 169.672 | W20: 73 | X20: 96.888 | AA20: 290
B21: y/y | H21: #DIV/0! | I21: =(I20-D20)/D20 -> #DIV/0! | J21: =(J20-E20)/E20 -> #DIV/0! | K21: =(K20-F20)/F20 -> #DIV/0! | L21: =(L20-G20)/G20 -> #DIV/0! | M21: =(M20-H20)/H20 -> #DIV/0! | N21: =(N20-I20)/I20 -> #DIV/0! | O21: =(O20-J20)/J20 -> #DIV/0! | P21: =(P20-K20)/K20 -> #DIV/0! | ... AA21: =(AA20-V20)/V20 -> 0.70918007
B22: Marine construction | Q22: 18.119 | V22: 19.282
B23: y/y | H23: =(H22-C22)/C22 -> #DIV/0! | I23: =(I22-D22)/D22 -> #DIV/0! | J23: =(J22-E22)/E22 -> #DIV/0! | K23: =(K22-F22)/F22 -> #DIV/0! | M23: =(M22-H22)/H22 -> #DIV/0! | N23: =(N22-I22)/I22 -> #DIV/0! | O23: =(O22-J22)/J22 -> #DIV/0! | P23: =(P22-K22)/K22 -> #DIV/0! | R23: =(R22-M22)/M22 -> #DIV/0! | S23: =(S22-N22)/N22 -> #DIV/0! | T23: =(T22-O22)/O22 -> #DIV/0! | U23: =(U22-P22)/P22 -> #DIV/0! | V23: =(V22-Q22)/Q22 -> 0.064186765 | W23: =(W22-R22)/R22 -> #DIV/0! | X23: =(X22-S22)/S22 -> #DIV/0! | Y23: =(Y22-T22)/T22 -> #DIV/0! | ... AA23: =(AA22-V22)/V22 -> -1
B24: Defence | Q24: 47 | V24: 144.321
B25: y/y | H25: =(H24-C24)/C24 -> #DIV/0! | I25: =(I24-D24)/D24 -> #DIV/0! | J25: =(J24-E24)/E24 -> #DIV/0! | K25: =(K24-F24)/F24 -> #DIV/0! | M25: =(M24-H24)/H24 -> #DIV/0! | N25: =(N24-I24)/I24 -> #DIV/0! | O25: =(O24-J24)/J24 -> #DIV/0! | P25: =(P24-K24)/K24 -> #DIV/0! | R25: =(R24-M24)/M24 -> #DIV/0! | S25: =(S24-N24)/N24 -> #DIV/0! | T25: =(T24-O24)/O24 -> #DIV/0! | U25: =(U24-P24)/P24 -> #DIV/0! | V25: =(V24-Q24)/Q24 -> 2.0706596 | W25: =(W24-R24)/R24 -> #DIV/0! | X25: =(X24-S24)/S24 -> #DIV/0! | Y25: =(Y24-T24)/T24 -> #DIV/0! | ... AA25: =(AA24-V24)/V24 -> -1
B26: Ocean science | Q26: 13.876 | V26: 6
B27: y/y | H27: =(H26-C26)/C26 -> #DIV/0! | I27: =(I26-D26)/D26 -> #DIV/0! | J27: =(J26-E26)/E26 -> #DIV/0! | K27: =(K26-F26)/F26 -> #DIV/0! | M27: =(M26-H26)/H26 -> #DIV/0! | N27: =(N26-I26)/I26 -> #DIV/0! | O27: =(O26-J26)/J26 -> #DIV/0! | P27: =(P26-K26)/K26 -> #DIV/0! | R27: =(R26-M26)/M26 -> #DIV/0! | S27: =(S26-N26)/N26 -> #DIV/0! | T27: =(T26-O26)/O26 -> #DIV/0! | U27: =(U26-P26)/P26 -> #DIV/0! | V27: =(V26-Q26)/Q26 -> -0.56759873 | W27: =(W26-R26)/R26 -> #DIV/0! | X27: =(X26-S26)/S26 -> #DIV/0! | Y27: =(Y26-T26)/T26 -> #DIV/0! | ... AA27: =(AA26-V26)/V26 -> -1
B28: EBITA | Q28: -34.434 | R28: -6.5 | S28: 1.275 | V28: 22.174 | W28: 29 | X28: 41.269
B29: EBITA % | C29: =C28/C20 -> #DIV/0! | D29: =D28/D20 -> #DIV/0! | E29: =E28/E20 -> #DIV/0! | F29: =F28/F20 -> #DIV/0! | G29: =G28/G20 -> #DIV/0! | H29: =H28/H20 -> #DIV/0! | I29: =I28/I20 -> #DIV/0! | J29: =J28/J20 -> #DIV/0! | ... AA29: =AA28/AA20 -> 0
B30: EBIT | Q30: -52.278 | R30: -10.6 | S30: -2.4 | V30: 6.427 | W30: 25.266 | X30: 29.715 | AA30: 60
B31: EBIT% | C31: =C30/C20 -> #DIV/0! | D31: =D30/D20 -> #DIV/0! | E31: =E30/E20 -> #DIV/0! | F31: =F30/F20 -> #DIV/0! | G31: =G30/G20 -> #DIV/0! | H31: =H30/H20 -> #DIV/0! | I31: =I30/I20 -> #DIV/0! | J31: =J30/J20 -> #DIV/0! | ... AA31: =AA30/AA20 -> 0.20689655
B32: Corporate
B33: Revenue | Q33: 0 | S33: 14.254 | V33: 52.705 | W33: 10.68 | X33: 11.237
B34: EBITA | Q34: -28 | S34: 3.964 | V34: -17.771 | W34: -8.5 | X34: -12.899
B35: EBIT | Q35: -28 | S35: 3.964 | V35: -17.785 | W35: -8.5 | X35: -12.906
B36: Eliminations
B37: Revenue | Q37: -8.352 | S37: -22.715 | V37: -75 | W37: -16.727 | X37: -12.675
B38: EBITA | Q38: 10.266 | S38: 0 | V38: -3 | W38: -4 | X38: 3.755
B39: EBIT | Q39: 10.266 | S39: 0 | V39: -3 | W39: -4 | X39: 3.755

Sheet Market area
B4: NOKm | C4: 2024 | D4: Q125 | E4: Q225 | F4: Q325 | G4: Q425 | H4: 2025 | I4: Q126 | J4: Q226 | K4: Q326 | L4: Q426 | M4: 2026
B5: Marine construcions | C5: 577 | D5: 169.752 | E5: 153 | H5: 616 | I5: 135.197 | J5: 143 | M5: =SUM(I5:L5) -> 278.197
B6: y/y | H6: =(H5-C5)/C5 -> 0.067590988 | I6: =(I5-D5)/D5 -> -0.20356167 | J6: =(J5-E5)/E5 -> -0.065359477 | K6: =(K5-F5)/F5 -> #DIV/0! | L6: =(L5-G5)/G5 -> #DIV/0! | M6: =(M5-H5)/H5 -> -0.54838149
B7: Defence | C7: 234 | D7: 93.086 | E7: =177.307-D7 -> 84.221 | H7: 403 | I7: 124.617 | J7: =281.629-I7 -> 157.012 | M7: =SUM(I7:L7) -> 281.629
B8: y/y | H8: =(H7-C7)/C7 -> 0.72222222 | I8: =(I7-D7)/D7 -> 0.33872978 | J8: =(J7-E7)/E7 -> 0.86428563 | K8: =(K7-F7)/F7 -> #DIV/0! | L8: =(L7-G7)/G7 -> #DIV/0! | M8: =(M7-H7)/H7 -> -0.30116873
B9: Ocean science | C9: 151 | D9: 78.826 | E9: =149.446-D9 -> 70.62 | H9: 284 | I9: 64.201 | J9: =144.925-I9 -> 80.724 | M9: =SUM(I9:L9) -> 144.925
B10: y/y | H10: =(H9-C9)/C9 -> 0.8807947 | I10: =(I9-D9)/D9 -> -0.18553523 | J10: =(J9-E9)/E9 -> 0.14307562 | K10: =(K9-F9)/F9 -> #DIV/0! | L10: =(L9-G9)/G9 -> #DIV/0! | M10: =(M9-H9)/H9 -> -0.4897007

Sheet SOTP
A2: EBIT 26E
A3: =Modell!AF12 -> 241.31911 | D3: =SUM(D6:D9) -> 225
C5: NOKm | D5: EBIT 26E | E5: EV/EBIT | F5: EV | G5: NOK/share
C6: SENSORS | D6: 160 | E6: 15 | F6: =D6*E6 -> 2400 | G6: =F6/Modell!$B$5 -> 12.48405
C7: ROBOTICS | D7: 110 | E7: 25 | F7: =D7*E7 -> 2750 | G7: =F7/Modell!$B$5 -> 14.304641
C8: CORP | D8: -30 | E8: 5 | F8: =D8*E8 -> -150 | G8: =F8/Modell!$B$5 -> -0.78025312
C9: ELIMINATIONS | D9: -15 | E9: 5 | F9: =D9*E9 -> -75 | G9: =F9/Modell!$B$5 -> -0.39012656
C10: ENTERPRISE VALUE | D10: =SUM(D6:D9) -> 225 | G10: =SUM(G6:G9) -> 25.618311
C12: Cash | F12: =Modell!B7 -> 545.818 | G12: =F12/Modell!B5 -> 2.8391747
C13: Debt | F13: =Modell!B8 -> 0 | G13: =-F13/Modell!B5 -> 0
C15: Equity value | G15: =SUM(G10:G13) -> 28.457485

Sheet Nøkkeltall
D4: 2026 | E4: 2027 | F4: 2028
C5: EV/EBITDA | D5: =Modell!$B$9/Modell!AF27 -> 9.5318241 | E5: =Modell!$B$9/Modell!AG27 -> 8.1344741 | F5: =Modell!$B$9/Modell!AH27 -> 6.8054946
C6: EV/EBIT | D6: =Modell!$B$9/Modell!AF12 -> 12.476095 | E6: =Modell!$B$9/Modell!AG12 -> 10.558662 | F6: =Modell!$B$9/Modell!AH12 -> 8.8001015
C7: P/E | D7: =Modell!$B$4/Modell!AF20 -> 18.384814 | E7: =Modell!$B$4/Modell!AG20 -> 15.443918 | F7: =Modell!$B$4/Modell!AH20 -> 12.801704

Sheet Nedsideberegning
A3: Nedside | D3: FY 2020 | E3: FY 2021 | F3: FY 2022 | G3: FY 2023 | H3: FY 2024 | I3: FY 2025 | J3: FY 2026 | K3: FY 2027 | L3: FY 2028 | M3: FY 2029 | N3: FY 2030 | O3: FY 2031 | P3: FY 2032 | Q3: FY 2033 | R3: FY 2034 | S3: FY 2035
C4: Revenue | D4: 279.976 | E4: 334.384 | F4: 629.639 | G4: 809.769 | H4: 953.269 | I4: 1280.41 | J4: =I4*1.18 -> 1510.8838 | K4: =J4*1.18 -> 1782.8429 | L4: =K4*1.18 -> 2103.7546 | M4: =L4*1.18 -> 2482.4304 | N4: =M4*1.18 -> 2929.2679 | O4: =N4*1.15 -> 3368.6581 | P4: =O4*1.12 -> 3772.8971 | Q4: =P4*1.1 -> 4150.1868 | R4: =Q4*1.1 -> 4565.2055 | S4: =R4*1.1 -> 5021.726
C5: Lease and other income | D5: 34.068 | E5: 29.345 | F5: 10.81 | G5: 7.209 | H5: 7.352 | I5: 23.452 | J5: 0 | K5: 0 | L5: 0 | N5: 0 | O5: 0 | P5: 0 | Q5: 0 | R5: 0
C6: Raw materials | D6: -76.896 | E6: -101.228 | F6: -195.172 | G6: -247.986 | H6: -319.815 | I6: -459.06 | J6: =J4*-0.33 -> -498.59165 | K6: =K4*-0.32 -> -570.50972 | L6: =L4*-0.31 -> -652.16393 | M6: =M4*-0.3 -> -744.72913 | N6: =N4*-0.3 -> -878.78037 | O6: =O4*-0.3 -> -1010.5974 | P6: =P4*-0.3 -> -1131.8691 | Q6: =Q4*-0.3 -> -1245.056 | R6: =R4*-0.3 -> -1369.5616 | S6: =S4*-0.3 -> -1506.5178
C7: Gross profit | D7: =SUM(D4:D6) -> 237.148 | E7: =SUM(E4:E6) -> 262.501 | F7: =SUM(F4:F6) -> 445.277 | G7: =SUM(G4:G6) -> 568.992 | H7: =SUM(H4:H6) -> 640.806 | I7: =SUM(I4:I6) -> 844.802 | J7: =SUM(J4:J6) -> 1012.2921 | K7: =SUM(K4:K6) -> 1212.3332 | ... S7: =SUM(S4:S6) -> 3515.2082
C8: Employee benefits | D8: -117.809 | E8: -127.423 | F8: -214.007 | G8: -278.114 | H8: -371.141 | I8: -427.673 | J8: =I8*1.17 -> -500.37741 | K8: =J8*1.18 -> -590.44534 | L8: =K8*1.18 -> -696.72551 | M8: =L8*1.18 -> -822.1361 | N8: =M8*1.17 -> -961.89923 | O8: =N8*1.15 -> -1106.1841 | P8: =O8*1.12 -> -1238.9262 | Q8: =P8*1.1 -> -1362.8188 | R8: =Q8*1.1 -> -1499.1007 | S8: =R8*1.1 -> -1649.0108
C9: D/A | D9: -7.312 | E9: -10.481 | F9: -30.707 | G9: -50.047 | H9: -59.385 | I9: -64.818 | J9: =I9*1.16 -> -75.18888 | K9: =J9*1.18 -> -88.722878 | L9: =K9*1.18 -> -104.693 | M9: =L9*1.18 -> -123.53774 | N9: =M9*1.18 -> -145.77453 | O9: =N9*1.15 -> -167.64071 | P9: =O9*1.12 -> -187.75759 | Q9: =P9*1.1 -> -206.53335 | R9: =Q9*1.1 -> -227.18669 | S9: =R9*1.1 -> -249.90536
C10: Other operating expenses | D10: -41.729 | E10: -50.564 | F10: -85.62 | G10: -280.083 | H10: -140.47 | I10: -158.632 | J10: =I10*1.16 -> -184.01312 | K10: =J10*1.18 -> -217.13548 | L10: =K10*1.18 -> -256.21987 | M10: =L10*1.18 -> -302.33944 | N10: =M10*1.18 -> -356.76054 | O10: =N10*1.15 -> -410.27463 | P10: =O10*1.12 -> -459.50758 | Q10: =P10*1.1 -> -505.45834 | R10: =Q10*1.1 -> -556.00417 | S10: =R10*1.1 -> -611.60459
C11: Other gains and lossen | D11: 0 | E11: 0 | F11: 0 | G11: 0 | H11: 0.133 | I11: -8.221 | J11: 0 | K11: 0 | L11: 0 | M11: 0 | N11: 0 | O11: 0 | P11: 0 | Q11: 0 | R11: 0 | S11: 0
C12: Operating profit (EBIT) | D12: =SUM(D7:D11) -> 70.298 | E12: =SUM(E7:E11) -> 74.033 | F12: =SUM(F7:F11) -> 114.943 | G12: =SUM(G7:G11) -> -39.252 | H12: =SUM(H7:H11) -> 69.943 | I12: =SUM(I7:I11) -> 185.458 | J12: =SUM(J7:J11) -> 252.71274 | K12: =SUM(K7:K11) -> 316.02946 | ... S12: =SUM(S7:S11) -> 1004.6875
C13: Finance income | D13: 13.796 | E13: 9.784 | F13: 20.99 | G13: 23.025 | H13: 41.228 | I13: 49.906 | J13: =I13*1.1 -> 54.8966 | K13: =J13*1.1 -> 60.38626 | L13: =K13*1.1 -> 66.424886 | M13: =L13*1.1 -> 73.067375 | N13: =M13*1.1 -> 80.374112 | O13: =N13*1.1 -> 88.411523 | P13: =O13*1.1 -> 97.252676 | Q13: =P13*1.1 -> 106.97794 | ... S13: =R13*1.1 -> 129.44331
C14: Finance expenses | D14: -25.664 | E14: -10.781 | F14: -26.009 | G14: -35.867 | H14: -48.732 | I14: -48.112 | J14: =I14*1.05 -> -50.5176 | K14: =J14*1.05 -> -53.04348 | L14: =K14*1.05 -> -55.695654 | M14: =L14*1.05 -> -58.480437 | N14: =M14*1.05 -> -61.404459 | O14: =N14*1.05 -> -64.474681 | P14: =O14*1.05 -> -67.698416 | Q14: =P14*1.05 -> -71.083336 | ... S14: =R14*1.05 -> -78.369378
C15: Share of gains / (Losses) from associate | D15: 0 | E15: 0 | F15: -4.592 | G15: -3.392 | H15: -1.782 | I15: 0 | J15: 0 | K15: 0 | L15: 0 | M15: 0 | N15: 0 | O15: 0 | P15: 0 | Q15: 0 | R15: 0 | S15: 0
C16: PTP | D16: =SUM(D12:D15) -> 58.43 | E16: =SUM(E12:E15) -> 73.036 | F16: =SUM(F12:F15) -> 105.332 | G16: =SUM(G12:G15) -> -55.486 | H16: =SUM(H12:H15) -> 60.657 | I16: =SUM(I12:I15) -> 187.252 | J16: =SUM(J12:J15) -> 257.09174 | K16: =SUM(K12:K15) -> 323.37224 | ... S16: =SUM(S12:S15) -> 1055.7614
C17: Tax | D17: -10.734 | E17: -16.061 | F17: -26.601 | G17: -17.039 | H17: -21.475 | I17: -22.171 | J17: =J16*-0.22 -> -56.560182 | K17: =K16*-0.22 -> -71.141892 | L17: =L16*-0.22 -> -89.029938 | M17: =M16*-0.22 -> -110.94049 | N17: =N16*-0.22 -> -133.10503 | O17: =O16*-0.22 -> -153.53757 | P17: =P16*-0.22 -> -172.56598 | Q17: =Q16*-0.22 -> -190.56726 | ... S17: =S16*-0.22 -> -232.26751
C18: Net income | D18: =SUM(D16:D17) -> 47.696 | E18: =SUM(E16:E17) -> 56.975 | F18: =SUM(F16:F17) -> 78.731 | G18: =SUM(G16:G17) -> -72.525 | H18: =SUM(H16:H17) -> 39.182 | I18: =SUM(I16:I17) -> 165.081 | J18: =SUM(J16:J17) -> 200.53155 | K18: =SUM(K16:K17) -> 252.23035 | ... S18: =SUM(S16:S17) -> 823.49389
C19: Shares | D19: 48.76543 | E19: 48.76543 | F19: 48.76543 | G19: 49.32 | H19: 169.56 | I19: 168.5 | J19: 192.24531 | K19: 192.24531 | L19: 192.24531 | M19: 192.24531 | N19: 192.24531 | O19: 192.24531 | P19: 192.24531 | Q19: 192.24531 | R19: 192.24531 | S19: 192.24531
C20: EPS | D20: =D18/D19 -> 0.97806992 | E20: =E18/E19 -> 1.1683482 | F20: =F18/F19 -> 1.6144839 | G20: =G18/G19 -> -1.4704988 | H20: =H18/H19 -> 0.23108044 | I20: =I18/I19 -> 0.9797092 | J20: =J18/J19 -> 1.0431025 | K20: =K18/K19 -> 1.3120234 | ... S20: =S18/S19 -> 4.2835578
C22: Revenue y/y | E22: =(E4-D4)/D4 -> 0.19433094 | F22: =(F4-E4)/E4 -> 0.88298184 | G22: =(G4-F4)/F4 -> 0.28608457 | H22: =(H4-G4)/G4 -> 0.17721103 | I22: =(I4-H4)/H4 -> 0.34317805 | J22: =(J4-I4)/I4 -> 0.18 | K22: =(K4-J4)/J4 -> 0.18 | L22: =(L4-K4)/K4 -> 0.18 | ... S22: =(S4-R4)/R4 -> 0.1
C23: Gross margin | D23: =D7/D4 -> 0.84702975 | E23: =E7/E4 -> 0.78502859 | F23: =F7/F4 -> 0.70719412 | G23: =G7/G4 -> 0.70265965 | H23: =H7/H4 -> 0.67221949 | I23: =I7/I4 -> 0.65979022 | J23: =J7/J4 -> 0.67 | K23: =K7/K4 -> 0.68 | ... S23: =S7/S4 -> 0.7
C24: EBIT margin | D24: =D12/D4 -> 0.25108581 | E24: =E12/E4 -> 0.22140114 | F24: =F12/F4 -> 0.18255381 | G24: =G12/G4 -> -0.048473083 | H24: =H12/H4 -> 0.073371735 | I24: =I12/I4 -> 0.14484267 | J24: =J12/J4 -> 0.16726153 | K24: =K12/K4 -> 0.17726153 | ... S24: =S12/S4 -> 0.20006816
