Workbook

Sheet Info
L9: Tilbakekjøpsprogram | S9: Tilbakekjøpsprogram
L10: Dato kjøp | M10: Antall aksjer | N10: Akummelert antall aksjer | O10: Kjøp | P10: Akkumelert kjøp | S10: Dato kjøp | T10: Antall aksjer | U10: Akummelert antall aksjer | V10: Kjøp | W10: Akkumelert kjøp
L11: 46160 | M11: 80000 | N11: =M11 -> 80000 | O11: =2060336+2150884+2151590+2201280 -> 8564090 | P11: =O11 -> 8564090 | S11: 46111 | T11: 143050 | U11: =T11 -> 143050 | V11: =2098438+2056670+2089808+6496357+2009566 -> 14750839 | W11: =V11 -> 14750839
L12: 46167 | M12: 125000 | N12: =SUM(M11:M12) -> 205000 | O12: =2367668+2414588+2333464+2452363+2434958 -> 12003041 | P12: =SUM(O11:O12) -> 20567131 | S12: 46119 | T12: 80000 | U12: =SUM(T11:T12) -> 223050 | V12: =1981314+2098874+2135638+2113074 -> 8328900 | W12: =SUM(V11:V12) -> 23079739
L13: 46174 | M13: 125000 | N13: =SUM(M11:M13) -> 330000 | O13: =2357160+2295290+2400070+2435685+2523293 -> 12011498 | P13: =SUM(O11:O13) -> 32578629 | S13: 46125 | T13: 80000 | U13: =SUM(T11:T13) -> 303050 | V13: =2188888+2292750+2147558+2169802 -> 8798998 | W13: =SUM(V11:V13) -> 31878737
L14: 46181 | M14: 125000 | N14: =SUM(M11:M14) -> 455000 | O14: =2317923+2265573+2277198+2427205+2423010 -> 11710909 | P14: =SUM(O11:O14) -> 44289538 | S14: 46132 | T14: 100000 | U14: =SUM(T11:T14) -> 403050 | V14: =2121074+2210124+2232266+2363304+2476244 -> 11403012 | W14: =SUM(V11:V14) -> 43281749
L15: 46188 | M15: 125000 | N15: =SUM(M11:M15) -> 580000 | O15: =2053298+2134355+2142228+2204675+2281223 -> 10815779 | P15: =SUM(O11:O15) -> 55105317 | S15: 46139 | T15: 100000 | U15: =SUM(T11:T15) -> 503050 | V15: =2439114+2459594+2409192+2384776+2282340 -> 11975016 | W15: =SUM(V11:V15) -> 55256765
L16: 46195 | M16: 120000 | N16: =SUM(M11:M16) -> 700000 | O16: =2163444+2189877+2208306+2302131 -> 8863758 | P16: =SUM(O11:O16) -> 63969075 | S16: 46146 | T16: 175000 | U16: =SUM(T11:T16) -> 678050 | V16: =4672408+7157064+4777940+4179655 -> 20787067 | W16: =SUM(V11:V16) -> 76043832
L17: 46202 | M17: 150000 | N17: =SUM(M11:M17) -> 850000 | O17: =2114391+2026527+2118468+2147988+2086704 -> 10494078 | P17: =SUM(O11:O17) -> 74463153 | S17: 46149 | T17: 92000 | U17: =SUM(T11:T17) -> 770050 | V17: =3210424+3522330+4210563 -> 10943317 | W17: =SUM(V11:V17) -> 86987149
L18: 46209 | M18: 150000 | N18: =SUM(M11:M18) -> 1000000 | O18: =2152629+2223816+2245770+2647461+2763897 -> 12033573 | P18: =SUM(O11:O18) -> 86496726
L19: 46216 | M19: 150000 | N19: =SUM(M11:M19) -> 1150000 | O19: =2629713+2603649+2498823+2477481+2466021 -> 12675687 | P19: =SUM(O11:O19) -> 99172413
L20: 46223 | M20: 139314 | N20: =SUM(M11:M20) -> 1289314 | O20: =2425200+2371137+2389767+2052513+2060762 -> 11299379 | P20: =SUM(O11:O20) -> 110471792
L21: 46230 | M21: 125000 | N21: =SUM(M11:M21) -> 1414314 | O21: =2172578+2193673+2159755+2098008+2075510 -> 10699524 | P21: =SUM(O11:O21) -> 121171316
L22: 46237 | M22: 123000 | N22: =SUM(M11:M22) -> 1537314 | O22: =2144525+2270753+2318220+2203942+2067048 -> 11004488 | P22: =SUM(O11:O22) -> 132175804
L23: 46244 | M23: 120000 | N23: =SUM(M11:M23) -> 1657314 | O23: =1993606+1992838+1993927+1976184+2073434 -> 10029989 | P23: =SUM(O11:O23) -> 142205793
L24: 46251 | M24: 120000 | N24: =SUM(M11:M24) -> 1777314 | O24: =2115127+2196410+2249364+2290718+2447254 -> 11298873 | P24: =SUM(O11:O24) -> 153504666
L25: 46258 | M25: 233610 | N25: =SUM(M11:M25) -> 2010924 | O25: =9964430+6154114+2528405+2516355+2465148 -> 23628452 | P25: =SUM(O11:O25) -> 177133118
L26: 46265 | M26: 125000 | N26: =SUM(M11:M26) -> 2135924 | O26: =2417395+2540775+2513665+2497990+2472325 -> 12442150 | P26: =SUM(O11:O26) -> 189575268
A27: Press releases: | L27: 46272 | M27: 125000 | N27: =SUM(M11:M27) -> 2260924 | O27: =2413280+2294688+2224273+2258573+2250153 -> 11440967 | P27: =SUM(O11:O27) -> 201016235
A28: 09.07.26: Hemnet setter tilbakekjøpsprogrammet på pause | L28: 46274 | O28: Setter programmet på pause
A29: 07.09.26: Hemnet kjøper tilbake 125 000 aksjer
A30: 31.08.26: Hemnet kjøper tilbake 125 000 aksjer
A31: 24.08.26: Hemnet kjøper tilbake 233 610 aksjer
A32: 17.08.26: Hemnet kjøper tilbake 120 000 aksjer
A33: 10.08.26: Hemnet kjøper tilbake 120 000 aksjer
A34: 03.08.26: hemnet kjøper tilbake 123 000 aksjer
A35: 27.07.26: Hemnet kjøper tilbake 125 000 aksjer
A36: 20.07.26: Hemnet kjøper tilbake 139 314 aksjer
A37: 13.07.26: Hemnet kjøper tilbake 150 000 aksjer
A38: 06.07.26: Hemnet kjøper tilbake 150 000 aksjer
A39: 29.06.26: Hemnet kjøper tilbake 150 000 aksjer
A40: 22.06.26: Hemnet kjøper tilbake 120 000 aksjer
... A54: 30.03.26: Hemnet kjøper tilbake 143 050 aksjer

Sheet Modell
A3: Kapitalstruktur | C3: SEKm | D3: Q122 | E3: Q222 | F3: Q322 | G3: Q422 | H3: Q123 | I3: Q223 | J3: Q323 | K3: Q423 | L3: Q124 | M3: Q224 | N3: Q324 | O3: Q424 | P3: Q125 | Q3: Q225 | R3: Q325 | S3: Q425 | T3: Q126 | U3: Q226 | V3: Q326 | W3: Q426 | Z3: FY 2017 | AA3: FY 2018 | AB3: FY 2019 | AC3: FY 2020 | AD3: FY 2021 | AE3: FY 2022 | AF3: FY 2023 | AG3: FY 2024 | AH3: FY 2025 | AI3: FY 2026 | AJ3: FY 2027 | AK3: FY 2028 | AL3: FY 2029 | AM3: FY 2030 | AN3: FY 2031 | AO3: FY 2032 | AP3: FY 2033 | AQ3: FY 2034 | AR3: FY 2035
A4: Price | B4: 69 | C4: Revenue | D4: 180.1 | E4: 270.5 | F4: 240 | G4: 202 | H4: 190.5 | I4: 268.4 | J4: 272.7 | K4: 275.8 | L4: 254 | M4: 405.6 | N4: 372.6 | O4: 364.5 | P4: 329 | Q4: 484 | R4: 367.2 | S4: 348 | T4: 247.4 | U4: 371.7 | Z4: 318.475 | AA4: 374 | AB4: 446.369 | AC4: 545.846 | AD4: 729.9 | AE4: 891.8 | AF4: 1007 | AG4: 1396.7 | AH4: 1528 | AI4: =AH4*0.75 -> 1146 | AJ4: =AI4*1.05 -> 1203.3 | AK4: =AJ4*1.05 -> 1263.465 | AL4: =AK4*1.05 -> 1326.6382 | AM4: =AL4*1.05 -> 1392.9702 | AN4: =AM4*1.05 -> 1462.6187 | AO4: =AN4*1.05 -> 1535.7496 | AP4: =AO4*1.05 -> 1612.5371 | AQ4: =AP4*1.05 -> 1693.1639 | AR4: =AQ4*1.05 -> 1777.8221
A5: S/O | B5: 95.008346 | C5: Capitalised development | D5: 2.5 | E5: 2.9 | F5: 1.3 | G5: 3.3 | H5: 3.4 | I5: 2.3 | J5: 3.2 | K5: 4 | L5: 3.9 | M5: 2.7 | N5: 1.2 | O5: 2.9 | P5: 6.4 | Q5: 2 | R5: 3.7 | S5: 3.8 | T5: 4.4 | U5: 5 | Z5: 0 | AA5: 0 | AB5: 4.3 | AC5: 3.9 | AD5: 4.6 | AE5: 10 | AF5: 13 | AG5: 10.7 | AH5: 16 | AI5: 0 | AJ5: 0 | AK5: 0 | AL5: 0 | AM5: 0 | AN5: 0 | AO5: 0 | AP5: 0 | AQ5: 0 | AR5: 0
A6: MC SEKm | B6: =B4*B5 -> 6555.5759 | C6: Other external expensee | D6: -59 | E6: -86.8 | F6: -79.2 | G6: -74 | H6: -63.2 | I6: -85.2 | J6: -82.5 | K6: -92.8 | L6: -86.9 | M6: -137.7 | N6: -120.1 | O6: -136 | P6: -118 | Q6: -165.7 | R6: -131.7 | S6: -133.6 | T6: -103 | U6: -142.4 | Z6: -181.48 | AA6: -166.752 | AB6: -189 | AC6: -245.308 | AD6: -299.9 | AE6: -299 | AF6: -323.7 | AG6: -480.7 | AH6: -549 | AI6: =AH6*0.85 -> -466.65 | AJ6: =AI6*1.05 -> -489.9825 | AK6: =AJ6*1.05 -> -514.48163 | AL6: =AK6*1.05 -> -540.20571 | AM6: =AL6*1.05 -> -567.21599 | AN6: =AM6*1.05 -> -595.57679 | AO6: =AN6*1.05 -> -625.35563 | AP6: =AO6*1.05 -> -656.62341 | AQ6: =AP6*1.05 -> -689.45458 | AR6: =AQ6*1.05 -> -723.92731
A7: Cash SEKm | B7: =U41 -> 173.8 | C7: Personell costs | D7: -37.8 | E7: -41 | F7: -32.7 | G7: -41.7 | H7: -43.1 | I7: -44.4 | J7: -37 | K7: -45.1 | L7: -50.9 | M7: -53.9 | N7: -45.7 | O7: -54.7 | P7: -59.5 | Q7: -58.7 | R7: -43.3 | S7: -64.4 | T7: -59 | U7: -62.9 | Z7: -60.5 | AA7: -69.885 | AB7: -88.679 | AC7: -114.756 | AD7: -130 | AE7: -153.2 | AF7: -169.6 | AG7: -205.2 | AH7: -226 | AI7: =AH7*0.85 -> -192.1 | AJ7: =AI7*1.05 -> -201.705 | AK7: =AJ7*1.05 -> -211.79025 | AL7: =AK7*1.05 -> -222.37976 | AM7: =AL7*1.05 -> -233.49875 | AN7: =AM7*1.05 -> -245.17369 | AO7: =AN7*1.05 -> -257.43237 | AP7: =AO7*1.05 -> -270.30399 | AQ7: =AP7*1.05 -> -283.81919 | AR7: =AQ7*1.05 -> -298.01015
A8: Debt SEKm | B8: =U45 -> 846.8 | C8: D/A | D8: -17.7 | E8: -17.8 | F8: -17.6 | G8: -17.5 | H8: -19.1 | I8: -19 | J8: -19.1 | K8: -20.1 | L8: -20.8 | M8: -20.6 | N8: -21.9 | O8: -22.7 | P8: -22.5 | Q8: -23.2 | R8: -24.1 | S8: -23.9 | T8: -23.9 | U8: -23 | Z8: -63.3 | AA8: -64.793 | AB8: -73.2 | AC8: -77.447 | AD8: -79 | AE8: -70.6 | AF8: -77.3 | AG8: -86 | AH8: -94 | AI8: =AH8*0.85 -> -79.9 | AJ8: =AI8*1.05 -> -83.895 | AK8: =AJ8*1.05 -> -88.08975 | AL8: =AK8*1.05 -> -92.494237 | AM8: =AL8*1.05 -> -97.118949 | AN8: =AM8*1.05 -> -101.9749 | AO8: =AN8*1.05 -> -107.07364 | AP8: =AO8*1.05 -> -112.42732 | AQ8: =AP8*1.05 -> -118.04869 | AR8: =AQ8*1.05 -> -123.95112
A9: EV SEKm | B9: =B6-B7+B8 -> 7228.5759 | C9: Other opex | D9: 0 | E9: 0 | F9: 0 | G9: 0 | H9: -0.4 | I9: 0 | J9: 0 | K9: -0.4 | L9: -0.4 | M9: -0.5 | N9: -0.4 | O9: -0.4 | P9: -0.4 | Q9: -0.7 | R9: -0.5 | S9: -0.5 | T9: -0.5 | U9: 0 | Z9: 0 | AA9: 0 | AB9: -1 | AC9: -1.7 | AD9: -1.7 | AE9: -1.5 | AF9: -1.6 | AG9: -1.7 | AH9: -2 | AI9: =AH9*0.85 -> -1.7 | AJ9: =AI9*1.05 -> -1.785 | AK9: =AJ9*1.05 -> -1.87425 | AL9: =AK9*1.05 -> -1.9679625 | AM9: =AL9*1.05 -> -2.0663606 | AN9: =AM9*1.05 -> -2.1696787 | AO9: =AN9*1.05 -> -2.2781626 | AP9: =AO9*1.05 -> -2.3920707 | AQ9: =AP9*1.05 -> -2.5116743 | AR9: =AQ9*1.05 -> -2.637258
C10: Total opex | D10: =SUM(D6:D9) -> -114.5 | E10: =SUM(E6:E9) -> -145.6 | F10: =SUM(F6:F9) -> -129.5 | G10: =SUM(G6:G9) -> -133.2 | H10: =SUM(H6:H9) -> -125.8 | I10: =SUM(I6:I9) -> -148.6 | J10: =SUM(J6:J9) -> -138.6 | K10: =SUM(K6:K9) -> -158.4 | ... U10: =SUM(U6:U9) -> -228.3 | Z10: =SUM(Z6:Z9) -> -305.28 | AA10: =SUM(AA6:AA9) -> -301.43 | AB10: =SUM(AB6:AB9) -> -351.879 | AC10: =SUM(AC6:AC9) -> -439.211 | AD10: =SUM(AD6:AD9) -> -510.6 | AE10: =SUM(AE6:AE9) -> -524.3 | AF10: =SUM(AF6:AF9) -> -572.2 | AG10: =SUM(AG6:AG9) -> -773.6 | ... AR10: =SUM(AR6:AR9) -> -1148.5258
C11: Operating profit (EBIT) | D11: =D4+D10+D5 -> 68.1 | E11: =E4+E10+E5 -> 127.8 | F11: =F4+F10+F5 -> 111.8 | G11: =G4+G10+G5 -> 72.1 | H11: =H4+H10+H5 -> 68.1 | I11: =I4+I10+I5 -> 122.1 | J11: =J4+J10+J5 -> 137.3 | K11: =K4+K10+K5 -> 121.4 | ... U11: =U4+U10+U5 -> 148.4 | Z11: =Z4+Z10+Z5 -> 13.195 | AA11: =AA4+AA10+AA5 -> 72.57 | AB11: =AB4+AB10+AB5 -> 98.79 | AC11: =AC4+AC10+AC5 -> 110.535 | AD11: =AD4+AD10+AD5 -> 223.9 | AE11: =AE4+AE10+AE5 -> 377.5 | AF11: =AF4+AF10+AF5 -> 447.8 | AG11: =AG4+AG10+AG5 -> 633.8 | ... AR11: =AR4+AR10+AR5 -> 629.29629
A12: Gearing | B12: =(B8-B7)/U26 -> 1.1018337 | C12: Net financial items | D12: -1.6 | E12: -1.2 | F12: -1.4 | G12: -2.6 | H12: -4.1 | I12: -5.7 | J12: -7.4 | K12: -3.6 | L12: -7.6 | M12: -8 | N12: -7.5 | O12: -3.6 | P12: -5.3 | Q12: -4.4 | R12: -4.5 | S12: -3.3 | T12: -4.5 | U12: -6.4 | Z12: -36.13 | AA12: -25.587 | AB12: -15 | AC12: -23.723 | AD12: -25.8 | AE12: -6.8 | AF12: -20.8 | AG12: -26.7 | AH12: -18 | AI12: 0 | AJ12: 0 | AK12: 0 | AL12: 0 | AM12: 0 | AN12: 0 | AO12: 0 | AP12: 0 | AQ12: 0 | AR12: 0
C13: PTP | D13: =SUM(D11:D12) -> 66.5 | E13: =SUM(E11:E12) -> 126.6 | F13: =SUM(F11:F12) -> 110.4 | G13: =SUM(G11:G12) -> 69.5 | H13: =SUM(H11:H12) -> 64 | I13: =SUM(I11:I12) -> 116.4 | J13: =SUM(J11:J12) -> 129.9 | K13: =SUM(K11:K12) -> 117.8 | ... U13: =SUM(U11:U12) -> 142 | Z13: =SUM(Z11:Z12) -> -22.935 | AA13: =SUM(AA11:AA12) -> 46.983 | AB13: =SUM(AB11:AB12) -> 83.79 | AC13: =SUM(AC11:AC12) -> 86.812 | AD13: =SUM(AD11:AD12) -> 198.1 | AE13: =SUM(AE11:AE12) -> 370.7 | AF13: =SUM(AF11:AF12) -> 427 | AG13: =SUM(AG11:AG12) -> 607.1 | ... AR13: =SUM(AR11:AR12) -> 629.29629
C14: Tax | D14: -13.77 | E14: -26.3 | F14: -22.7 | G14: -14.2 | H14: -13.3 | I14: -24.1 | J14: -26.7 | K14: -24.6 | L14: -18.9 | M14: -38.9 | N14: -36.8 | O14: -31.1 | P14: -26.8 | Q14: -48.3 | R14: -34.4 | S14: -26.2 | T14: -12.6 | U14: -29.7 | Z14: -2.2 | AA14: 5.5 | AB14: -18 | AC14: -19 | AD14: -41.6 | AE14: -76.9 | AF14: -88.7 | AG14: -125.7 | AH14: -136 | AI14: =AI13*-0.2 -> -81.13 | AJ14: =AJ13*-0.2 -> -85.1865 | AK14: =AK13*-0.2 -> -89.445825 | AL14: =AL13*-0.2 -> -93.918116 | AM14: =AM13*-0.2 -> -98.614022 | AN14: =AN13*-0.2 -> -103.54472 | AO14: =AO13*-0.2 -> -108.72196 | AP14: =AP13*-0.2 -> -114.15806 | ... AR14: =AR13*-0.2 -> -125.85926
C15: Net income | D15: =SUM(D13:D14) -> 52.73 | E15: =SUM(E13:E14) -> 100.3 | F15: =SUM(F13:F14) -> 87.7 | G15: =SUM(G13:G14) -> 55.3 | H15: =SUM(H13:H14) -> 50.7 | I15: =SUM(I13:I14) -> 92.3 | J15: =SUM(J13:J14) -> 103.2 | K15: =SUM(K13:K14) -> 93.2 | ... U15: =SUM(U13:U14) -> 112.3 | Z15: =SUM(Z13:Z14) -> -25.135 | AA15: =SUM(AA13:AA14) -> 52.483 | AB15: =SUM(AB13:AB14) -> 65.79 | AC15: =SUM(AC13:AC14) -> 67.812 | AD15: =SUM(AD13:AD14) -> 156.5 | AE15: =SUM(AE13:AE14) -> 293.8 | AF15: =SUM(AF13:AF14) -> 338.3 | AG15: =SUM(AG13:AG14) -> 481.4 | ... AR15: =SUM(AR13:AR14) -> 503.43703 | AS15: =AR15*(1+$AU$19) -> 498.40266 | AT15: =AS15*(1+$AU$19) -> 493.41864 | AU15: =AT15*(1+$AU$19) -> 488.48445 | AV15: =AU15*(1+$AU$19) -> 483.5996 | AW15: =AV15*(1+$AU$19) -> 478.76361 | AX15: =AW15*(1+$AU$19) -> 473.97597 | AY15: =AX15*(1+$AU$19) -> 469.23621 | AZ15: =AY15*(1+$AU$19) -> 464.54385 | ... GX15: =GW15*(1+$AU$19) -> 98.820417
C16: Shares | D16: 101.13148 | E16: 100.8223 | F16: 99.433623 | G16: 98.838795 | H16: 98.236929 | I16: 97.681992 | J16: 97.042211 | K16: 96.535933 | L16: 96.146181 | M16: 96.146298 | N16: 95.812288 | O16: 95.566788 | P16: 95.257288 | Q16: 95.008346 | R16: 95.008346 | S16: 94.058502 | T16: 93.087465 | U16: 91.707931 | Z16: 100.71942 | AA16: 100.71942 | AB16: 100.71942 | AC16: 100.71942 | AD16: 100.99939 | AE16: 100.34598 | AF16: 97.638241 | AG16: 96.146298 | AH16: 96.146298 | AI16: 93.087465 | AJ16: 93.087465 | AK16: 93.087465 | AL16: 93.087465 | AM16: 93.087465 | AN16: 93.087465 | AO16: 93.087465 | AP16: 93.087465 | AQ16: 93.087465 | AR16: 93.087465
C17: EPS | D17: =D15/D16 -> 0.52140047 | E17: =E15/E16 -> 0.99481959 | F17: =F15/F16 -> 0.88199542 | G17: =G15/G16 -> 0.55949691 | H17: =H15/H16 -> 0.5160992 | I17: =I15/I16 -> 0.94490293 | J17: =J15/J16 -> 1.0634547 | K17: =K15/K16 -> 0.96544361 | ... U17: =U15/U16 -> 1.2245397 | Z17: =Z15/Z16 -> -0.24955465 | AA17: =AA15/AA16 -> 0.52108123 | AB17: =AB15/AB16 -> 0.65320074 | AC17: =AC15/AC16 -> 0.67327631 | AD17: =AD15/AD16 -> 1.5495142 | AE17: =AE15/AE16 -> 2.9278701 | AF17: =AF15/AF16 -> 3.464831 | AG17: =AG15/AG16 -> 5.006953 | AH17: 5.48 | AI17: =AI15/AI16 -> 3.4861837 | AJ17: =AJ15/AJ16 -> 3.6604928 | AK17: =AK15/AK16 -> 3.8435175 | AL17: =AL15/AL16 -> 4.0356934 | AM17: =AM15/AM16 -> 4.237478 | AN17: =AN15/AN16 -> 4.4493519 | AO17: =AO15/AO16 -> 4.6718195 | AP17: =AP15/AP16 -> 4.9054105 | ... AR17: =AR15/AR16 -> 5.4082151
AT18: Disocunt | AU18: 0.08
C19: Revenue y/y | H19: =(H4-D4)/D4 -> 0.057745697 | I19: =(I4-E4)/E4 -> -0.0077634011 | J19: =(J4-F4)/F4 -> 0.13625 | K19: =(K4-G4)/G4 -> 0.36534653 | L19: =(L4-H4)/H4 -> 0.33333333 | M19: =(M4-I4)/I4 -> 0.51117735 | N19: =(N4-J4)/J4 -> 0.36633663 | O19: =(O4-K4)/K4 -> 0.32160986 | ... U19: =(U4-Q4)/Q4 -> -0.23202479 | Z19: =(Z4-Y4)/Y4 -> #DIV/0! | AA19: =(AA4-Z4)/Z4 -> 0.1743465 | AB19: =(AB4-AA4)/AA4 -> 0.1935 | AC19: =(AC4-AB4)/AB4 -> 0.22285822 | AD19: =(AD4-AC4)/AC4 -> 0.33719034 | AE19: =(AE4-AD4)/AD4 -> 0.22181121 | AF19: =(AF4-AE4)/AE4 -> 0.12917695 | AG19: =(AG4-AF4)/AF4 -> 0.38699106 | ... AR19: =(AR4-AQ4)/AQ4 -> 0.05 | AT19: TV | AU19: -0.01
C20: Opex y/y | H20: =(H10-D10)/D10 -> 0.098689956 | I20: =(I10-E10)/E10 -> 0.020604396 | J20: =(J10-F10)/F10 -> 0.07027027 | K20: =(K10-G10)/G10 -> 0.18918919 | L20: =(L10-H10)/H10 -> 0.26391097 | M20: =(M10-I10)/I10 -> 0.43135935 | N20: =(N10-J10)/J10 -> 0.35714286 | O20: =(O10-K10)/K10 -> 0.34974747 | ... U20: =(U10-Q10)/Q10 -> -0.080547725 | AA20: =(AA10-Z10)/Z10 -> -0.012611373 | AB20: =(AB10-AA10)/AA10 -> 0.16736556 | AC20: =(AC10-AB10)/AB10 -> 0.24818759 | AD20: =(AD10-AC10)/AC10 -> 0.16253919 | AE20: =(AE10-AD10)/AD10 -> 0.026831179 | AF20: =(AF10-AE10)/AE10 -> 0.091359908 | AG20: =(AG10-AF10)/AF10 -> 0.35197483 | AH20: =(AH10-AG10)/AG10 -> 0.12590486 | ... AR20: =(AR10-AQ10)/AQ10 -> 0.05 | AT20: NPV | AU20: =NPV(AU18,AH15:GX15) -> 5314.6308
C21: EBIT margin | D21: =D11/D4 -> 0.37812326 | E21: =E11/E4 -> 0.47245841 | F21: =F11/F4 -> 0.46583333 | G21: =G11/G4 -> 0.35693069 | H21: =H11/H4 -> 0.35748031 | I21: =I11/I4 -> 0.45491803 | J21: =J11/J4 -> 0.50348368 | K21: =K11/K4 -> 0.44017404 | ... U21: =U11/U4 -> 0.3992467 | Z21: =Z11/Z4 -> 0.041431824 | AA21: =AA11/AA4 -> 0.19403743 | AB21: =AB11/AB4 -> 0.22131913 | AC21: =AC11/AC4 -> 0.20250217 | AD21: =AD11/AD4 -> 0.30675435 | AE21: =AE11/AE4 -> 0.42330119 | AF21: =AF11/AF4 -> 0.44468719 | AG21: =AG11/AG4 -> 0.45378392 | ... AR21: =AR11/AR4 -> 0.35397033 | AT21: S/O | AU21: 93.087465
C22: ROE | AE22: =AE15/G44 -> 0.20506736 | AF22: =AF15/K44 -> 0.26857733 | AG22: =AG15/O44 -> 0.38552094 | AT22: NPV/Share | AU22: =AU20/AU21 -> 57.092873
AT23: Opp/nedside | AU23: =(AU22-B4)/B4 -> -0.17256706
C24: EBITDA | D24: 85.5 | E24: 145 | F24: 128.5 | G24: 88.8 | H24: 87.2 | I24: 140.7 | J24: 156 | K24: 141.6 | L24: 141.6 | M24: 216.2 | N24: 207.6 | O24: 176.3 | P24: 157.5 | Q24: 260.9 | R24: 195.4 | S24: 153.7 | T24: 89.3 | U24: 172.4 | Z24: 108 | AA24: 138 | AB24: 172 | AC24: 202 | AD24: 355 | AE24: 448 | AF24: 526 | AG24: 720 | AH24: 768 | AI24: =AI11-AI8 -> 485.55 | AJ24: =AJ11-AJ8 -> 509.8275 | AK24: =AK11-AK8 -> 535.31887 | AL24: =AL11-AL8 -> 562.08482 | AM24: =AM11-AM8 -> 590.18906 | AN24: =AN11-AN8 -> 619.69851 | AO24: =AO11-AO8 -> 650.68344 | AP24: =AP11-AP8 -> 683.21761 | ... AR24: =AR11-AR8 -> 753.24742
C25: EBITDA margin | D25: =D24/D4 -> 0.47473626 | E25: =E24/E4 -> 0.53604436 | F25: =F24/F4 -> 0.53541667 | G25: =G24/G4 -> 0.43960396 | H25: =H24/H4 -> 0.45774278 | I25: =I24/I4 -> 0.52421759 | J25: =J24/J4 -> 0.57205721 | K25: =K24/K4 -> 0.51341552 | ... U25: =U24/U4 -> 0.4638149 | Z25: =Z24/Z4 -> 0.3391161 | AA25: =AA24/AA4 -> 0.36898396 | AB25: =AB24/AB4 -> 0.38533142 | AC25: =AC24/AC4 -> 0.37006775 | AD25: =AD24/AD4 -> 0.486368 | AE25: =AE24/AE4 -> 0.50235479 | AF25: =AF24/AF4 -> 0.52234359 | AG25: =AG24/AG4 -> 0.51550082 | ... AR25: =AR24/AR4 -> 0.4236911
C26: EBITDA LTM | G26: =SUM(D24:G24) -> 447.8 | H26: =SUM(E24:H24) -> 449.5 | I26: =SUM(F24:I24) -> 445.2 | J26: =SUM(G24:J24) -> 472.7 | K26: =SUM(H24:K24) -> 525.5 | L26: =SUM(I24:L24) -> 579.9 | M26: =SUM(J24:M24) -> 655.4 | N26: =SUM(L24:N24) -> 565.4 | O26: =SUM(L24:O24) -> 741.7 | P26: =SUM(M24:P24) -> 757.6 | Q26: =SUM(N24:Q24) -> 802.3 | R26: =SUM(O24:R24) -> 790.1 | S26: =SUM(P24:S24) -> 767.5 | T26: =SUM(Q24:T24) -> 699.3 | U26: =SUM(R24:U24) -> 610.8
C28: ARPL | D28: 2681 | E28: 3163 | F28: 3404 | G28: 4044 | H28: 3706 | I28: 4138 | J28: 4343 | K28: 5911 | L28: 4911 | M28: 6274 | N28: 6183 | O28: 8452 | P28: 6722 | Q28: 8451 | R28: 7477 | S28: 10916 | T28: 9109 | U28: 9095 | Z28: 946 | AA28: 1079 | AB28: 1414 | AC28: 1760 | AD28: 2467 | AE28: 3275 | AF28: 4490 | AG28: 6382 | AH28: 8175
C29: y/y | H29: =(H28-D28)/D28 -> 0.38232003 | I29: =(I28-E28)/E28 -> 0.30825166 | J29: =(J28-F28)/F28 -> 0.27585194 | K29: =(K28-G28)/G28 -> 0.46167161 | L29: =(L28-H28)/H28 -> 0.32514841 | M29: =(M28-I28)/I28 -> 0.5161914 | N29: =(N28-J28)/J28 -> 0.42367027 | O29: =(O28-K28)/K28 -> 0.4298765 | ... U29: =(U28-Q28)/Q28 -> 0.076204 | AA29: =(AA28-Z28)/Z28 -> 0.14059197 | AB29: =(AB28-AA28)/AA28 -> 0.31047266 | AC29: =(AC28-AB28)/AB28 -> 0.2446959 | AD29: =(AD28-AC28)/AC28 -> 0.40170455 | AE29: =(AE28-AD28)/AD28 -> 0.32752331 | AF29: =(AF28-AE28)/AE28 -> 0.37099237 | AG29: =(AG28-AF28)/AF28 -> 0.42138085 | AH29: =(AH28-AG28)/AG28 -> 0.28094641
C31: Number of published listings, thousand | D31: 45.7 | E31: 64.5 | F31: 52.2 | G31: 35.8 | H31: 36.9 | I31: 50.6 | J31: 50.1 | K31: 37.7 | L31: 41.1 | M31: 55.7 | N31: 51.5 | O31: 37.1 | P31: 41.2 | Q31: 50.5 | R31: 41.6 | S31: 27.3 | T31: 28.6 | U31: 32.9 | AD31: 198400 | AE31: 198300 | AF31: 175300 | AG31: 185300 | AH31: 160700
C32: y/y | H32: =(H31-D31)/D31 -> -0.19256018 | I32: =(I31-E31)/E31 -> -0.21550388 | J32: =(J31-F31)/F31 -> -0.040229885 | K32: =(K31-G31)/G31 -> 0.053072626 | L32: =(L31-H31)/H31 -> 0.11382114 | M32: =(M31-I31)/I31 -> 0.10079051 | N32: =(N31-J31)/J31 -> 0.027944112 | O32: =(O31-K31)/K31 -> -0.015915119 | ... U32: =(U31-Q31)/Q31 -> -0.34851485 | AA32: =(AA31-Z31)/Z31 -> #DIV/0! | AB32: =(AB31-AA31)/AA31 -> #DIV/0! | AC32: =(AC31-AB31)/AB31 -> #DIV/0! | AD32: =(AD31-AC31)/AC31 -> #DIV/0! | AE32: =(AE31-AD31)/AD31 -> -0.00050403226 | AF32: =(AF31-AE31)/AE31 -> -0.11598588 | AG32: =(AG31-AF31)/AF31 -> 0.057045066
C34: Balanse SEKm
C35: Goodwill | D35: 903 | E35: 903 | F35: 903 | G35: 903 | H35: 903 | I35: 903 | J35: 903 | K35: 903 | L35: 903 | M35: 902.8 | N35: 903 | O35: 903 | P35: 903 | Q35: 902.8 | R35: 902.8 | S35: 903 | T35: 902.8 | U35: 903 | AE35: 903 | AF35: 903 | AG35: 903 | AH35: 903
C36: Customer relations | D36: 800.9 | E36: 787 | F36: 773.2 | G36: 759.3 | H36: 745.5 | I36: 731.6 | J36: 717.8 | K36: 703.9 | L36: 690.1 | M36: 676.2 | N36: 662.4 | O36: 648.5 | P36: 634.7 | Q36: 620.8 | R36: 607 | S36: 593.2 | T36: 579.3 | U36: 565.5 | AE36: 759.3 | AF36: 703.9 | AG36: 648.5 | AH36: 593.2
C37: Right of use assets | D37: 6.3 | E37: 4.4 | F37: 2.5 | G37: 0.6 | H37: 53.7 | I37: 50.9 | J37: 48 | K37: 45.2 | L37: 42.4 | M37: 39.6 | N37: 36.1 | O37: 36.9 | P37: 33.8 | Q37: 30.8 | R37: 27.7 | S37: 23.8 | T37: 21.7 | U37: 18.6 | AE37: 0.6 | AF37: 45.2 | AG37: 36.9 | AH37: 23.8
C38: Other non-current assets | D38: 257.5 | E38: 259.6 | F38: 260 | G38: 263.3 | H38: 276.7 | I38: 282.2 | J38: 287.4 | K38: 292.5 | L38: 296.5 | M38: 299.2 | N38: 297.2 | O38: 297 | P38: 301 | Q38: 298.4 | R38: 298 | S38: 296.8 | T38: 297 | U38: 297.5 | AE38: 263.3 | AF38: 292.5 | AG38: 297 | AH38: 296.8
C39: accounts receivables | D39: 38.2 | E39: 56 | F39: 47.9 | G39: 31.5 | H39: 35 | I39: 43.5 | J39: 54.1 | K39: 38.3 | L39: 48.1 | M39: 40.3 | N39: 35.4 | O39: 29.8 | P39: 35.1 | Q39: 41.2 | R39: 42.3 | S39: 28.9 | T39: 50.7 | U39: 75.5 | AE39: 31.5 | AF39: 38.3 | AG39: 29.8 | AH39: 28.9
C40: Other current assets | D40: 23.3 | E40: 26.4 | F40: 42.5 | G40: 36.7 | H40: 29.1 | I40: 40.2 | J40: 49.2 | K40: 70.7 | L40: 128.6 | M40: 174.7 | N40: 235.6 | O40: 167.2 | P40: 204.5 | Q40: 215.2 | R40: 194.6 | S40: 147.6 | T40: 120 | U40: 77.7 | AE40: 36.7 | AF40: 70.7 | AG40: 167.2 | AH40: 147.6
C41: Cash | D41: 96.3 | E41: 138.2 | F41: 124 | G41: 100.4 | H41: 79.8 | I41: 156.4 | J41: 156 | K41: 102.6 | L41: 96.5 | M41: 118.9 | N41: 145.1 | O41: 111.7 | P41: 70.5 | Q41: 130.3 | R41: 195.6 | S41: 103.3 | T41: 113.8 | U41: 173.8 | AE41: 100.4 | AF41: 102.6 | AG41: 111.7 | AH41: 103.3
C42: Total assets | D42: =SUM(D35:D41) -> 2125.5 | E42: =SUM(E35:E41) -> 2174.6 | F42: =SUM(F35:F41) -> 2153.1 | G42: =SUM(G35:G41) -> 2094.8 | H42: =SUM(H35:H41) -> 2122.8 | I42: =SUM(I35:I41) -> 2207.8 | J42: =SUM(J35:J41) -> 2215.5 | K42: =SUM(K35:K41) -> 2156.2 | ... U42: =SUM(U35:U41) -> 2111.6 | Z42: =SUM(Z35:Z41) -> 0 | AA42: =SUM(AA35:AA41) -> 0 | AB42: =SUM(AB35:AB41) -> 0 | AC42: =SUM(AC35:AC41) -> 0 | AD42: =SUM(AD35:AD41) -> 0 | AE42: =SUM(AE35:AE41) -> 2094.8 | AF42: =SUM(AF35:AF41) -> 2156.2 | AG42: =SUM(AG35:AG41) -> 2194.1 | AH42: =SUM(AH35:AH41) -> 2096.6
C43: Equity | D43: 1569.4 | E43: 1576.1 | F43: 1457.4 | G43: 1432.7 | H43: 1388.9 | I43: 1292.2 | J43: 1276 | K43: 1259.6 | L43: 1216.3 | M43: 1197 | N43: 1214.2 | O43: 1248.7 | P43: 1232.8 | Q43: 1145.2 | R43: 1129.2 | S43: 1072.2 | T43: 965.5 | U43: 844.4 | AE43: 1432.7 | AF43: 1259.6 | AG43: 1248.7 | AH43: 1072.2
C44: Total Equity | D44: =D43 -> 1569.4 | E44: =E43 -> 1576.1 | F44: =F43 -> 1457.4 | G44: =G43 -> 1432.7 | H44: =H43 -> 1388.9 | I44: =I43 -> 1292.2 | J44: =J43 -> 1276 | K44: =K43 -> 1259.6 | ... U44: =U43 -> 844.4 | Z44: =Z43 -> 0 | AA44: =AA43 -> 0 | AB44: =AB43 -> 0 | AC44: =AC43 -> 0 | AD44: =AD43 -> 0 | AE44: =AE43 -> 1432.7 | AF44: =AF43 -> 1259.6 | AG44: =AG43 -> 1248.7 | AH44: =AH43 -> 1072.2
C45: Long-term liabilities to banks | D45: 213.3 | E45: 213.5 | F45: 298.4 | G45: 328.5 | H45: 348.8 | I45: 498.9 | J45: 497.9 | K45: 497.1 | L45: 527.4 | M45: 522.7 | N45: 547.9 | O45: 468.5 | P45: 438.8 | Q45: 546.4 | R45: 596.6 | S45: 596.9 | T45: 706.8 | U45: 846.8 | AE45: 328.5 | AF45: 497.1 | AG45: 468.5 | AH45: 596.9
...

Sheet Månedstall
C5: Q1 | F5: Q2 | I5: Q3 | L5: Q4
B6: SEKm | C6: Januar | D6: Februar | E6: Mars | F6: april | G6: mai | H6: juni | I6: juli | J6: august | K6: september | L6: oktober | M6: november | N6: desember
B7: Net sales, total | F7: 116.6 | G7: 126.6
B8: y/y | F8: -0.212 | G8: -0.27
B9: Net sales, property sellers | F9: 97.7 | G9: 107.5
B10: y/y | F10: 0.245 | G10: -0.299
B11: Net sales B2B | F11: 18.9 | G11: 19.1
B12: y/y | F12: 0.024 | G12: -0.047
B13: ARPL paid | F13: 9104 | G13: 9244
B14: y/y | F14: 0.108 | G14: 0.131
B15: Published listings (thousand) | F15: 15.4 | G15: 16.4
B16: y/y | F16: -0.113 | G16: -0.197
B17: Paid listings (thousand) | F17: 11.1 | G17: 12.4
B18: y/y | F18: -0.364 | G18: -0.394

Sheet Nøkkeltall
D4: 2026 | E4: 2027 | F4: 2028
C5: EV/EBIT | D5: =Modell!$B$9/Modell!AI11 -> 17.819736 | E5: =Modell!$B$9/Modell!AJ11 -> 16.971177 | F5: =Modell!$B$9/Modell!AK11 -> 16.163026
C6: P/E | D6: =Modell!$B$4/Modell!AI17 -> 19.792417 | E6: =Modell!$B$4/Modell!AJ17 -> 18.849921 | F6: =Modell!$B$4/Modell!AK17 -> 17.952305

Sheet Nedsideberegning
A3: Nedside | D3: FY 2017 | E3: FY 2018 | F3: FY 2019 | G3: FY 2020 | H3: FY 2021 | I3: FY 2022 | J3: FY 2023 | K3: FY 2024 | L3: FY 2025 | M3: FY 2026 | N3: FY 2027 | O3: FY 2028 | P3: FY 2029 | Q3: FY 2030 | R3: FY 2031 | S3: FY 2032 | T3: FY 2033 | U3: FY 2034 | V3: FY 2035
A4: 0% vekst og konstante marginer | C4: Revenue | D4: 318.475 | E4: 374 | F4: 446.369 | G4: 545.846 | H4: 729.9 | I4: 891.8 | J4: 1007 | K4: 1396.7 | L4: 1528 | M4: =L4*1 -> 1528 | N4: =M4*1 -> 1528 | O4: =N4*1 -> 1528 | P4: =O4*1 -> 1528 | Q4: =P4*1 -> 1528 | R4: =Q4*1 -> 1528 | S4: =R4*1 -> 1528 | T4: =S4*1 -> 1528 | ... V4: =U4*1 -> 1528
A5: =Y22 -> 65.528514 | C5: Capitalised development | D5: 0 | E5: 0 | F5: 4.3 | G5: 3.9 | H5: 4.6 | I5: 10 | J5: 13 | K5: 10.7 | L5: 16 | M5: 0 | N5: 0 | O5: 0 | P5: 0 | Q5: 0 | R5: 0 | S5: 0 | T5: 0 | U5: 0 | V5: 0
A6: =Y23 -> -0.050311385 | C6: Other external expensee | D6: -181.48 | E6: -166.752 | F6: -189 | G6: -245.308 | H6: -299.9 | I6: -299 | J6: -323.7 | K6: -480.7 | L6: -549 | M6: =L6*1 -> -549 | N6: =M6*1 -> -549 | O6: =N6*1 -> -549 | P6: =O6*1 -> -549 | Q6: =P6*1 -> -549 | R6: =Q6*1 -> -549 | S6: =R6*1 -> -549 | T6: =S6*1 -> -549 | ... V6: =U6*1 -> -549
C7: Personell costs | D7: -60.5 | E7: -69.885 | F7: -88.679 | G7: -114.756 | H7: -130 | I7: -153.2 | J7: -169.6 | K7: -205.2 | L7: -226 | M7: =L7*1 -> -226 | N7: =M7*1 -> -226 | O7: =N7*1 -> -226 | P7: =O7*1 -> -226 | Q7: =P7*1 -> -226 | R7: =Q7*1 -> -226 | S7: =R7*1 -> -226 | T7: =S7*1 -> -226 | ... V7: =U7*1 -> -226
C8: D/A | D8: -63.3 | E8: -64.793 | F8: -73.2 | G8: -77.447 | H8: -79 | I8: -70.6 | J8: -77.3 | K8: -86 | L8: -94 | M8: =L8*1 -> -94 | N8: =M8*1 -> -94 | O8: =N8*1 -> -94 | P8: =O8*1 -> -94 | Q8: =P8*1 -> -94 | R8: =Q8*1 -> -94 | S8: =R8*1 -> -94 | T8: =S8*1 -> -94 | ... V8: =U8*1 -> -94
C9: Other opex | D9: 0 | E9: 0 | F9: -1 | G9: -1.7 | H9: -1.7 | I9: -1.5 | J9: -1.6 | K9: -1.7 | L9: -2 | M9: =L9*1 -> -2 | N9: =M9*1 -> -2 | O9: =N9*1 -> -2 | P9: =O9*1 -> -2 | Q9: =P9*1 -> -2 | R9: =Q9*1 -> -2 | S9: =R9*1 -> -2 | T9: =S9*1 -> -2 | ... V9: =U9*1 -> -2
C10: Total opex | D10: =SUM(D6:D9) -> -305.28 | E10: =SUM(E6:E9) -> -301.43 | F10: =SUM(F6:F9) -> -351.879 | G10: =SUM(G6:G9) -> -439.211 | H10: =SUM(H6:H9) -> -510.6 | I10: =SUM(I6:I9) -> -524.3 | J10: =SUM(J6:J9) -> -572.2 | K10: =SUM(K6:K9) -> -773.6 | ... V10: =SUM(V6:V9) -> -871
C11: Operating profit (EBIT) | D11: =D4+D10+D5 -> 13.195 | E11: =E4+E10+E5 -> 72.57 | F11: =F4+F10+F5 -> 98.79 | G11: =G4+G10+G5 -> 110.535 | H11: =H4+H10+H5 -> 223.9 | I11: =I4+I10+I5 -> 377.5 | J11: =J4+J10+J5 -> 447.8 | K11: =K4+K10+K5 -> 633.8 | ... V11: =V4+V10+V5 -> 657
C12: Net financial items | D12: -36.13 | E12: -25.587 | F12: -15 | G12: -23.723 | H12: -25.8 | I12: -6.8 | J12: -20.8 | K12: -26.7 | L12: -18 | M12: 0 | N12: 0 | O12: 0 | P12: 0 | Q12: 0 | R12: 0 | S12: 0 | T12: 0 | U12: 0 | V12: 0
C13: PTP | D13: =SUM(D11:D12) -> -22.935 | E13: =SUM(E11:E12) -> 46.983 | F13: =SUM(F11:F12) -> 83.79 | G13: =SUM(G11:G12) -> 86.812 | H13: =SUM(H11:H12) -> 198.1 | I13: =SUM(I11:I12) -> 370.7 | J13: =SUM(J11:J12) -> 427 | K13: =SUM(K11:K12) -> 607.1 | ... V13: =SUM(V11:V12) -> 657
C14: Tax | D14: -2.2 | E14: 5.5 | F14: -18 | G14: -19 | H14: -41.6 | I14: -76.9 | J14: -88.7 | K14: -125.7 | L14: -136 | M14: =M13*-0.2 -> -131.4 | N14: =N13*-0.2 -> -131.4 | O14: =O13*-0.2 -> -131.4 | P14: =P13*-0.2 -> -131.4 | Q14: =Q13*-0.2 -> -131.4 | R14: =R13*-0.2 -> -131.4 | S14: =S13*-0.2 -> -131.4 | T14: =T13*-0.2 -> -131.4 | ... V14: =V13*-0.2 -> -131.4
C15: Net income | D15: =SUM(D13:D14) -> -25.135 | E15: =SUM(E13:E14) -> 52.483 | F15: =SUM(F13:F14) -> 65.79 | G15: =SUM(G13:G14) -> 67.812 | H15: =SUM(H13:H14) -> 156.5 | I15: =SUM(I13:I14) -> 293.8 | J15: =SUM(J13:J14) -> 338.3 | K15: =SUM(K13:K14) -> 481.4 | ... V15: =SUM(V13:V14) -> 525.6 | W15: =V15*(1+$Y$19) -> 520.344 | X15: =W15*(1+$Y$19) -> 515.14056 | Y15: =X15*(1+$Y$19) -> 509.98915 | Z15: =Y15*(1+$Y$19) -> 504.88926 | AA15: =Z15*(1+$Y$19) -> 499.84037 | AB15: =AA15*(1+$Y$19) -> 494.84197 | AC15: =AB15*(1+$Y$19) -> 489.89355 | AD15: =AC15*(1+$Y$19) -> 484.99461 | ... GB15: =GA15*(1+$Y$19) -> 103.17082
C16: Shares | D16: 100.71942 | E16: 100.71942 | F16: 100.71942 | G16: 100.71942 | H16: 100.99939 | I16: 100.34598 | J16: 97.638241 | K16: 96.146298 | L16: 96.146298 | M16: 96.146298 | N16: 96.146298 | O16: 96.146298 | P16: 96.146298 | Q16: 96.146298 | R16: 96.146298 | S16: 96.146298 | T16: 96.146298 | U16: 96.146298 | V16: 96.146298
C17: EPS | D17: =D15/D16 -> -0.24955465 | E17: =E15/E16 -> 0.52108123 | F17: =F15/F16 -> 0.65320074 | G17: =G15/G16 -> 0.67327631 | H17: =H15/H16 -> 1.5495142 | I17: =I15/I16 -> 2.9278701 | J17: =J15/J16 -> 3.464831 | K17: =K15/K16 -> 5.006953 | L17: 5.48 | M17: =M15/M16 -> 5.4666691 | N17: =N15/N16 -> 5.4666691 | O17: =O15/O16 -> 5.4666691 | P17: =P15/P16 -> 5.4666691 | Q17: =Q15/Q16 -> 5.4666691 | R17: =R15/R16 -> 5.4666691 | S17: =S15/S16 -> 5.4666691 | T17: =T15/T16 -> 5.4666691 | ... V17: =V15/V16 -> 5.4666691
X18: Disocunt | Y18: 0.08
C19: Revenue y/y | E19: =(E4-D4)/D4 -> 0.1743465 | F19: =(F4-E4)/E4 -> 0.1935 | G19: =(G4-F4)/F4 -> 0.22285822 | H19: =(H4-G4)/G4 -> 0.33719034 | I19: =(I4-H4)/H4 -> 0.22181121 | J19: =(J4-I4)/I4 -> 0.12917695 | K19: =(K4-J4)/J4 -> 0.38699106 | L19: =(L4-K4)/K4 -> 0.094007303 | ... V19: =(V4-U4)/U4 -> 0 | X19: TV | Y19: -0.01
C20: Opex y/y | E20: =(E10-D10)/D10 -> -0.012611373 | F20: =(F10-E10)/E10 -> 0.16736556 | G20: =(G10-F10)/F10 -> 0.24818759 | H20: =(H10-G10)/G10 -> 0.16253919 | I20: =(I10-H10)/H10 -> 0.026831179 | J20: =(J10-I10)/I10 -> 0.091359908 | K20: =(K10-J10)/J10 -> 0.35197483 | L20: =(L10-K10)/K10 -> 0.12590486 | ... V20: =(V10-U10)/U10 -> 0 | X20: NPV | Y20: =NPV(Y18,L15:GB15) -> 6225.7558
C21: EBIT margin | D21: =D11/D4 -> 0.041431824 | E21: =E11/E4 -> 0.19403743 | F21: =F11/F4 -> 0.22131913 | G21: =G11/G4 -> 0.20250217 | H21: =H11/H4 -> 0.30675435 | I21: =I11/I4 -> 0.42330119 | J21: =J11/J4 -> 0.44468719 | K21: =K11/K4 -> 0.45378392 | ... V21: =V11/V4 -> 0.42997382 | X21: S/O | Y21: 95.008346
X22: NPV/Share | Y22: =Y20/Y21 -> 65.528514
X23: Opp/nedside | Y23: =(Y22-Modell!B4)/Modell!B4 -> -0.050311385
