Workbook

Sheet Info
A14: New targets CMD December 25:
A16: Gjennomsnittlig vekst på 4% i antall igangsatte boliger.
A17: Driftsmargin på 12% i snitt over en syklus
A18: Avkastning på sysselsatt kapital > 20%
A20: Mål om 3 800 igangsettinger forventes senest 2028
A23: Press releases:

Sheet Modell
A3: Kapitalstruktur | C3: SEK million | D3: Q122 | E3: Q222 | F3: Q322 | G3: Q422 | H3: Q123 | I3: Q223 | J3: Q323 | K3: Q423 | L3: Q124 | M3: Q224 | N3: Q324 | O3: Q424 | P3: Q125 | Q3: Q225 | R3: Q325 | S3: Q425 | T3: Q126 | U3: Q226 | V3: Q326 | W3: Q426 | Y3: FY 2015 | Z3: FY 2016 | AA3: FY 2017 | AB3: FY 2018 | AC3: FY 2019 | AD3: FY 2020 | AE3: FY 2021 | AF3: FY 2022 | AG3: FY 2023 | AH3: FY 2024 | AI3: FY 2025 | AJ3: FY 2026 | AK3: FY 2027 | AL3: FY 2028 | AM3: FY 2029 | AN3: FY 2030 | AO3: FY 2031 | AP3: FY 2032 | AQ3: FY 2033 | AR3: FY 2034 | AS3: FY 2035
A4: Price | B4: 133 | C4: Revenue | D4: 3854 | E4: 3790 | F4: 3790 | G4: 5152 | H4: 3962 | I4: 3636 | J4: 2846 | K4: 3407 | L4: 3034 | M4: 3583 | N4: 2515 | O4: 3375 | P4: 2539 | Q4: 2540 | R4: 2137 | S4: 2766 | T4: 2981 | U4: 2815 | Y4: 13939 | Z4: 15291 | AA4: 17008 | AB4: 16161 | AC4: 15692 | AD4: 15388 | AE4: 14608 | AF4: 16385 | AG4: 13851 | AH4: 12507 | AI4: 9982 | AJ4: =AI4*1.14 -> 11379.48 | AK4: =AJ4*1.1 -> 12517.428 | AL4: =AK4*1.1 -> 13769.171 | AM4: =AL4*1.075 -> 14801.859 | AN4: =AM4*1.05 -> 15541.952 | AO4: =AN4*1.05 -> 16319.049 | AP4: =AO4*1.05 -> 17135.002 | AQ4: =AP4*1.05 -> 17991.752 | AR4: =AQ4*1.05 -> 18891.339 | AS4: =AR4*1.05 -> 19835.906
A5: S/O | B5: 64.50484 | C5: Production and operating costs | D5: -3140 | E5: -3035 | F5: -3035 | G5: -4099 | H5: -3290 | I5: -3073 | J5: -2489 | K5: -3025 | L5: -2653 | M5: -3196 | N5: -2221 | O5: -2971 | P5: -2179 | Q5: -2194 | R5: -1931 | S5: -2459 | T5: -2642 | U5: -2492 | Y5: -11630 | Z5: -12440 | AA5: -13648 | AB5: -13247 | AC5: -12994 | AD5: -12607 | AE5: -11814 | AF5: -13216 | AG5: -11877 | AH5: -11040 | AI5: -8763 | AJ5: =AJ4*-0.885 -> -10070.84 | AK5: =AK4*-0.88 -> -11015.337 | AL5: =AL4*-0.85 -> -11703.795 | AM5: =AM4*-0.85 -> -12581.58 | AN5: =AN4*-0.85 -> -13210.659 | AO5: =AO4*-0.85 -> -13871.192 | AP5: =AP4*-0.85 -> -14564.751 | AQ5: =AQ4*-0.85 -> -15292.989 | AR5: =AR4*-0.85 -> -16057.638 | AS5: =AS4*-0.85 -> -16860.52
A6: MC SEKm | B6: =B4*B5 -> 8579.1437 | C6: Gross profit | D6: =SUM(D4:D5) -> 714 | E6: =SUM(E4:E5) -> 755 | F6: =SUM(F4:F5) -> 755 | G6: =SUM(G4:G5) -> 1053 | H6: =SUM(H4:H5) -> 672 | I6: =SUM(I4:I5) -> 563 | J6: =SUM(J4:J5) -> 357 | K6: =SUM(K4:K5) -> 382 | ... U6: =SUM(U4:U5) -> 323 | Y6: =SUM(Y4:Y5) -> 2309 | Z6: =SUM(Z4:Z5) -> 2851 | AA6: =SUM(AA4:AA5) -> 3360 | AB6: =SUM(AB4:AB5) -> 2914 | AC6: =SUM(AC4:AC5) -> 2698 | AD6: =SUM(AD4:AD5) -> 2781 | AE6: =SUM(AE4:AE5) -> 2794 | AF6: =SUM(AF4:AF5) -> 3169 | ... AS6: =SUM(AS4:AS5) -> 2975.3859
A7: Cash SEKm | B7: =T35 -> 450 | C7: Selling and adminstrative expenses | D7: -255 | E7: -317 | F7: -317 | G7: -284 | H7: -252 | I7: -305 | J7: -203 | K7: -227 | L7: -222 | M7: -227 | N7: -215 | O7: -264 | P7: -227 | Q7: -236 | R7: -204 | S7: -235 | T7: -242 | U7: -255 | Y7: -866 | Z7: -935 | AA7: -1005 | AB7: -1041 | AC7: -966 | AD7: -944 | AE7: -1015 | AF7: -1094 | AG7: -985 | AH7: -927 | AI7: -902 | AJ7: =AI7*0.8 -> -721.6 | AK7: =AJ7*0.9 -> -649.44 | AL7: =AK7*1 -> -649.44 | AM7: =AL7*1 -> -649.44 | AN7: =AM7*1 -> -649.44 | AO7: =AN7*1 -> -649.44 | AP7: =AO7*1 -> -649.44 | AQ7: =AP7*1 -> -649.44 | AR7: =AQ7*1 -> -649.44 | AS7: =AR7*1 -> -649.44
A8: Debt SEKm | B8: =T38+T41 -> 2363 | C8: Gains/losses on sale of property | D8: 7 | E8: -6 | F8: -6 | G8: -3 | H8: -4 | I8: 1 | J8: -8 | K8: -245 | L8: 1 | M8: 9 | N8: 15 | O8: -34 | P8: -3 | Q8: 6 | R8: 57 | S8: -80 | T8: 116 | U8: 1 | Y8: 56 | Z8: 15 | AA8: 14 | AB8: 13 | AC8: 276 | AD8: 191 | AE8: 436 | AF8: -11 | AG8: -256 | AH8: -8 | AI8: -20 | AJ8: =AI8*0.9 -> -18 | AK8: 0 | AL8: 0 | AM8: 0 | AN8: 0 | AO8: 0 | AP8: 0 | AQ8: 0 | AR8: 0 | AS8: 0
A9: EV SEKm | B9: =B6-B7+B8 -> 10492.144 | C9: Operating profit (EBIT) | D9: =SUM(D6:D8) -> 466 | E9: =SUM(E6:E8) -> 432 | F9: =SUM(F6:F8) -> 432 | G9: =SUM(G6:G8) -> 766 | H9: =SUM(H6:H8) -> 416 | I9: =SUM(I6:I8) -> 259 | J9: =SUM(J6:J8) -> 146 | K9: =SUM(K6:K8) -> -90 | ... U9: =SUM(U6:U8) -> 69 | Y9: =SUM(Y6:Y8) -> 1499 | Z9: =SUM(Z6:Z8) -> 1931 | AA9: =SUM(AA6:AA8) -> 2369 | AB9: =SUM(AB6:AB8) -> 1886 | AC9: =SUM(AC6:AC8) -> 2008 | AD9: =SUM(AD6:AD8) -> 2028 | AE9: =SUM(AE6:AE8) -> 2215 | AF9: =SUM(AF6:AF8) -> 2064 | ... AS9: =SUM(AS6:AS8) -> 2325.9459
C10: Financial income | D10: -16 | E10: -14 | F10: -14 | G10: -21 | H10: -23 | I10: -27 | J10: -27 | K10: -23 | L10: 5 | M10: 2 | N10: -24 | O10: -26 | P10: 6 | Q10: 2 | R10: 1 | S10: 7 | T10: 9 | U10: 1 | Y10: 11 | Z10: 17 | AA10: 279 | AB10: 10 | AC10: 6 | AD10: 6 | AE10: 4 | AF10: 19 | AG10: 33 | AH10: 24 | AI10: 16 | AJ10: 20 | AK10: 0 | AL10: 0 | AM10: 0 | AN10: 0 | AO10: 0 | AP10: 0 | AQ10: 0 | AR10: 0 | AS10: 0
C11: Financial expenses | D11: 0 | E11: 0 | F11: 0 | G11: 0 | H11: 0 | I11: 0 | J11: 0 | K11: 0 | L11: -37 | M11: -48 | N11: 0 | O11: 0 | P11: -47 | Q11: -49 | R11: -46 | S11: -35 | T11: -51 | U11: -55 | Y11: -83 | Z11: -77 | AA11: -69 | AB11: -79 | AC11: -86 | AD11: -79 | AE11: -62 | AF11: -89 | AG11: -133 | AH11: -151 | AI11: -177 | AJ11: -200 | AK11: 0 | AL11: 0 | AM11: 0 | AN11: 0 | AO11: 0 | AP11: 0 | AQ11: 0 | AR11: 0 | AS11: 0
A12: P/B | B12: =B6/S37 -> 1.0473866 | C12: PTP | D12: =SUM(D9:D11) -> 450 | E12: =SUM(E9:E11) -> 418 | F12: =SUM(F9:F11) -> 418 | G12: =SUM(G9:G11) -> 745 | H12: =SUM(H9:H11) -> 393 | I12: =SUM(I9:I11) -> 232 | J12: =SUM(J9:J11) -> 119 | K12: =SUM(K9:K11) -> -113 | ... U12: =SUM(U9:U11) -> 15 | Y12: =SUM(Y9:Y11) -> 1427 | Z12: =SUM(Z9:Z11) -> 1871 | AA12: =SUM(AA9:AA11) -> 2579 | AB12: =SUM(AB9:AB11) -> 1817 | AC12: =SUM(AC9:AC11) -> 1928 | AD12: =SUM(AD9:AD11) -> 1955 | AE12: =SUM(AE9:AE11) -> 2157 | AF12: =SUM(AF9:AF11) -> 1994 | ... AS12: =SUM(AS9:AS11) -> 2325.9459
C13: Taxes | D13: -94 | E13: -87 | F13: -87 | G13: -152 | H13: -83 | I13: -49 | J13: -43 | K13: -23 | L13: -49 | M13: -48 | N13: -35 | O13: -26 | P13: -38 | Q13: -32 | R13: -20 | S13: 16 | T13: -25 | U13: -21 | Y13: -342 | Z13: -393 | AA13: -385 | AB13: -379 | AC13: -358 | AD13: -380 | AE13: -360 | AF13: -419 | AG13: -199 | AH13: -157 | AI13: -74 | AJ13: =AJ12*-0.2 -> -77.80804 | AK13: =AK12*-0.2 -> -170.53027 | AL13: =AL12*-0.2 -> -283.18712 | AM13: =AM12*-0.2 -> -314.16776 | AN13: =AN12*-0.2 -> -336.37055 | AO13: =AO12*-0.2 -> -359.68347 | AP13: =AP12*-0.2 -> -384.16205 | AQ13: =AQ12*-0.2 -> -409.86455 | ... AS13: =AS12*-0.2 -> -465.18919
C14: Net income | D14: =SUM(D12:D13) -> 356 | E14: =SUM(E12:E13) -> 331 | F14: =SUM(F12:F13) -> 331 | G14: =SUM(G12:G13) -> 593 | H14: =SUM(H12:H13) -> 310 | I14: =SUM(I12:I13) -> 183 | J14: =SUM(J12:J13) -> 76 | K14: =SUM(K12:K13) -> -136 | ... U14: =SUM(U12:U13) -> -6 | Y14: =SUM(Y12:Y13) -> 1085 | Z14: =SUM(Z12:Z13) -> 1478 | AA14: =SUM(AA12:AA13) -> 2194 | AB14: =SUM(AB12:AB13) -> 1438 | AC14: =SUM(AC12:AC13) -> 1570 | AD14: =SUM(AD12:AD13) -> 1575 | AE14: =SUM(AE12:AE13) -> 1797 | AF14: =SUM(AF12:AF13) -> 1575 | ... AS14: =SUM(AS12:AS13) -> 1860.7567 | AT14: =AS14*(1+$AV$18) -> 1842.1492 | AU14: =AT14*(1+$AV$18) -> 1823.7277 | AV14: =AU14*(1+$AV$18) -> 1805.4904 | AW14: =AV14*(1+$AV$18) -> 1787.4355 | AX14: =AW14*(1+$AV$18) -> 1769.5611 | AY14: =AX14*(1+$AV$18) -> 1751.8655 | AZ14: =AY14*(1+$AV$18) -> 1734.3469 | BA14: =AZ14*(1+$AV$18) -> 1717.0034 | ... EB14: =EA14*(1+$AV$18) -> 776.16049
A15: Gearing | B15: =(B8-B7)/SUM(R9:U9) -> 5.7447447 | C15: Share | D15: 67.384072 | E15: 67.384072 | F15: 67.384072 | G15: 67.384072 | H15: 64.50484 | I15: 64.50484 | J15: 64.50484 | K15: 64.50484 | L15: 64.50484 | M15: 64.50484 | N15: 64.50484 | O15: 64.50484 | P15: 64.50484 | Q15: 64.50484 | R15: 64.50484 | S15: 64.50484 | T15: 64.50484 | U15: 64.50484 | Y15: 70.844023 | Z15: 70.844023 | AA15: 70.844023 | AB15: 69.865418 | AC15: 69.985557 | AD15: 70.061421 | AE15: 69.560505 | AF15: 67.384072 | AG15: 64.50484 | AH15: 64.50484 | AI15: 64.50484 | AJ15: 64.50484 | AK15: 64.50484 | AL15: 64.50484 | AM15: 64.50484 | AN15: 64.50484 | AO15: 64.50484 | AP15: 64.50484 | AQ15: 64.50484 | AR15: 64.50484 | AS15: 64.50484
C16: EPS | D16: =D14/D15 -> 5.2831476 | E16: =E14/E15 -> 4.9121401 | F16: =F14/F15 -> 4.9121401 | G16: =G14/G15 -> 8.8002993 | H16: =H14/H15 -> 4.8058409 | I16: =I14/I15 -> 2.8369964 | J16: =J14/J15 -> 1.1782062 | K16: =K14/K15 -> -2.1083689 | ... U16: =U14/U15 -> -0.093016276 | Y16: =Y14/Y15 -> 15.315336 | Z16: =Z14/Z15 -> 20.862734 | AA16: =AA14/AA15 -> 30.969444 | AB16: =AB14/AB15 -> 20.582429 | AC16: =AC14/AC15 -> 22.4332 | AD16: =AD14/AD15 -> 22.480275 | AE16: =AE14/AE15 -> 25.833625 | AF16: =AF14/AF15 -> 23.373476 | ... AS16: =AS14/AS15 -> 28.846777
AU17: Disocunt | AV17: 0.08
C18: Revenue y/y | H18: =(H4-D4)/D4 -> 0.028022833 | I18: =(I4-E4)/E4 -> -0.040633245 | J18: =(J4-F4)/F4 -> -0.24907652 | K18: =(K4-G4)/G4 -> -0.33870342 | L18: =(L4-H4)/H4 -> -0.23422514 | M18: =(M4-I4)/I4 -> -0.014576458 | N18: =(N4-J4)/J4 -> -0.11630358 | O18: =(O4-K4)/K4 -> -0.0093924274 | ... U18: =(U4-Q4)/Q4 -> 0.10826772 | Z18: =(Z4-Y4)/Y4 -> 0.096994045 | AA18: =(AA4-Z4)/Z4 -> 0.11228827 | AB18: =(AB4-AA4)/AA4 -> -0.049800094 | AC18: =(AC4-AB4)/AB4 -> -0.029020481 | AD18: =(AD4-AC4)/AC4 -> -0.019372929 | AE18: =(AE4-AD4)/AD4 -> -0.050688848 | AF18: =(AF4-AE4)/AE4 -> 0.12164567 | AG18: =(AG4-AF4)/AF4 -> -0.15465365 | ... AS18: =(AS4-AR4)/AR4 -> 0.05 | AU18: TV | AV18: -0.01
C19: Gross margin | D19: =D6/D4 -> 0.18526207 | E19: =E6/E4 -> 0.19920844 | F19: =F6/F4 -> 0.19920844 | G19: =G6/G4 -> 0.20438665 | H19: =H6/H4 -> 0.16961131 | I19: =I6/I4 -> 0.15484048 | J19: =J6/J4 -> 0.12543921 | K19: =K6/K4 -> 0.1121221 | ... U19: =U6/U4 -> 0.11474245 | Y19: =Y6/Y4 -> 0.16565033 | Z19: =Z6/Z4 -> 0.18644955 | AA19: =AA6/AA4 -> 0.19755409 | AB19: =AB6/AB4 -> 0.18031062 | AC19: =AC6/AC4 -> 0.17193474 | AD19: =AD6/AD4 -> 0.18072524 | AE19: =AE6/AE4 -> 0.19126506 | AF19: =AF6/AF4 -> 0.19340861 | ... AS19: =AS6/AS4 -> 0.15 | AU19: NPV | AV19: =NPV(AV17,AJ14:EB14) -> 17512.552
C20: EBIT margin | D20: =D9/D4 -> 0.12091334 | E20: =E9/E4 -> 0.11398417 | F20: =F9/F4 -> 0.11398417 | G20: =G9/G4 -> 0.14868012 | H20: =H9/H4 -> 0.10499748 | I20: =I9/I4 -> 0.071232123 | J20: =J9/J4 -> 0.05130007 | K20: =K9/K4 -> -0.026416202 | ... U20: =U9/U4 -> 0.024511545 | Y20: =Y9/Y4 -> 0.10754 | Z20: =Z9/Z4 -> 0.12628343 | AA20: =AA9/AA4 -> 0.13928739 | AB20: =AB9/AB4 -> 0.1167007 | AC20: =AC9/AC4 -> 0.12796329 | AD20: =AD9/AD4 -> 0.13179101 | AE20: =AE9/AE4 -> 0.15162924 | AF20: =AF9/AF4 -> 0.12596887 | ... AS20: =AS9/AS4 -> 0.11725937 | AU20: S/O | AV20: 64.50484
C21: ROE | Y21: 0.237 | Z21: 0.312 | AA21: 0.387 | AB21: 0.222 | AC21: 0.222 | AD21: 0.208 | AE21: 0.219 | AF21: 0.179 | AG21: 0.05 | AH21: 0.029 | AI21: =AI14/T37 -> 0.0073809524 | AU21: NPV/share | AV21: =AV19/AV20 -> 271.49205
AU22: Opp/nedside | AV22: =(AV21-B4)/B4 -> 1.0412936
C23: Housing starts | D23: 808 | E23: 719 | F23: 688 | G23: 898 | H23: 214 | I23: 454 | J23: 201 | K23: 740 | L23: 145 | M23: 722 | N23: 637 | O23: 733 | P23: 577 | Q23: 647 | R23: 296 | S23: 750 | T23: 425 | U23: 784 | Y23: 3731 | Z23: 4187 | AA23: 3873 | AB23: 3135 | AC23: 3269 | AD23: 3199 | AE23: 3972 | AF23: 3113 | AG23: 1609 | AH23: 2237 | AI23: =SUM(P23:S23) -> 2270
C24: y/y | H24: =(H23-D23)/D23 -> -0.73514851 | I24: =(I23-E23)/E23 -> -0.36856745 | J24: =(J23-F23)/F23 -> -0.70784884 | K24: =(K23-G23)/G23 -> -0.17594655 | L24: =(L23-H23)/H23 -> -0.32242991 | M24: =(M23-I23)/I23 -> 0.59030837 | N24: =(N23-J23)/J23 -> 2.1691542 | O24: =(O23-K23)/K23 -> -0.0094594595 | ... U24: =(U23-Q23)/Q23 -> 0.21174652 | Z24: =(Z23-Y23)/Y23 -> 0.12221924 | AA24: =(AA23-Z23)/Z23 -> -0.074994029 | AB24: =(AB23-AA23)/AA23 -> -0.19054996 | AC24: =(AC23-AB23)/AB23 -> 0.042743222 | AD24: =(AD23-AC23)/AC23 -> -0.021413276 | AE24: =(AE23-AD23)/AD23 -> 0.24163801 | AF24: =(AF23-AE23)/AE23 -> -0.21626385 | AG24: =(AG23-AF23)/AF23 -> -0.48313524 | ... AS24: =(AS23-AR23)/AR23 -> #DIV/0!
C25: Units sold | D25: 995 | E25: 732 | F25: 470 | G25: 462 | H25: 479 | I25: 363 | J25: 286 | K25: 773 | L25: 480 | M25: 1075 | N25: 649 | O25: 574 | P25: 555 | Q25: 433 | R25: 562 | S25: 478 | T25: 920 | U25: 679 | Y25: 3770 | Z25: 3843 | AA25: 3100 | AB25: 2463 | AC25: 3595 | AD25: 4026 | AE25: 4248 | AF25: 2659 | AG25: 1901 | AH25: 2778 | AI25: =SUM(P25:S25) -> 2028
C27: Balanse SEKm
C28: Intangible assets | D28: 351 | E28: 326 | F28: 318 | G28: 351 | H28: 339 | I28: 335 | J28: 344 | K28: 351 | L28: 218 | M28: 219 | N28: 389 | O28: 418 | P28: 218 | Q28: 220 | R28: 221 | S28: 215 | T28: 247 | U28: 251 | Y28: 168 | Z28: 185 | AA28: 176 | AB28: 180 | AC28: 186 | AD28: 168 | AE28: 180 | AF28: 351 | AG28: 351 | AH28: 418 | AI28: 215
C29: Participations in operations and JV | D29: 0 | E29: 0 | F29: 0 | G29: 0 | H29: 0 | I29: 0 | J29: 0 | K29: 0 | L29: 111 | M29: 126 | N29: 0 | O29: 0 | P29: 130 | Q29: 132 | R29: 134 | S29: 138 | T29: 139 | U29: 135 | Y29: 15 | Z29: 15 | AA29: 1 | AB29: 1 | AC29: 1 | AD29: 78 | AE29: 118 | AF29: 0 | AG29: 0 | AH29: 0 | AI29: 138
C30: Other non-current assets | D30: 0 | E30: 0 | F30: 0 | G30: 0 | H30: 0 | I30: 0 | J30: 0 | K30: 0 | L30: 48 | M30: 43 | N30: 0 | O30: 0 | P30: 75 | Q30: 115 | R30: 117 | S30: 113 | T30: 98 | U30: 103 | Y30: 26 | Z30: 30 | AA30: 32 | AB30: 33 | AC30: 32 | AD30: 32 | AE30: 32 | AF30: 0 | AG30: 0 | AH30: 0 | AI30: 113
C31: Project properties | D31: 896 | E31: 1225 | F31: 1369 | G31: 932 | H31: 800 | I31: 960 | J31: 1027 | K31: 1030 | L31: 818 | M31: 260 | N31: 578 | O31: 360 | P31: 168 | Q31: 199 | R31: 111 | S31: 207 | T31: 0 | U31: 0 | Y31: 378 | Z31: 602 | AA31: 1074 | AB31: 1635 | AC31: 1399 | AD31: 1246 | AE31: 813 | AF31: 932 | AG31: 1030 | AH31: 360 | AI31: 207
C32: Development properties | D32: 7995 | E32: 8336 | F32: 8607 | G32: 8465 | H32: 8239 | I32: 8746 | J32: 9013 | K32: 8504 | L32: 8849 | M32: 8438 | N32: 7974 | O32: 7660 | P32: 7602 | Q32: 7721 | R32: 7580 | S32: 7323 | T32: 8034 | U32: 8054 | Y32: 7067 | Z32: 7121 | AA32: 7543 | AB32: 8306 | AC32: 8938 | AD32: 7831 | AE32: 8205 | AF32: 8465 | AG32: 8504 | AH32: 7660 | AI32: 7323
C33: Participations in tenant-owned ass | D33: 330 | E33: 389 | F33: 339 | G33: 308 | H33: 363 | I33: 503 | J33: 751 | K33: 803 | L33: 566 | M33: 648 | N33: 948 | O33: 1111 | P33: 1278 | Q33: 2062 | R33: 1843 | S33: 1711 | T33: 1387 | U33: 1134 | Y33: 235 | Z33: 233 | AA33: 309 | AB33: 567 | AC33: 366 | AD33: 445 | AE33: 377 | AF33: 308 | AG33: 803 | AH33: 1111 | AI33: 1711
C34: Other current receivables | D34: 3770 | E34: 4218 | F34: 4536 | G34: 5225 | H34: 4856 | I34: 5126 | J34: 4872 | K34: 4541 | L34: 5172 | M34: 5034 | N34: 4515 | O34: 4721 | P34: 5044 | Q34: 4470 | R34: 4268 | S34: 4041 | T34: 5081 | U34: 4681 | Y34: 2808 | Z34: 3142 | AA34: 3698 | AB34: 4083 | AC34: 4274 | AD34: 3828 | AE34: 3527 | AF34: 5225 | AG34: 4541 | AH34: 4721 | AI34: 4041
C35: Cash | D35: 4115 | E35: 2481 | F35: 1902 | G35: 1840 | H35: 2577 | I35: 699 | J35: 742 | K35: 1582 | L35: 566 | M35: 417 | N35: 465 | O35: 431 | P35: 361 | Q35: 157 | R35: 449 | S35: 532 | T35: 450 | U35: 864 | Y35: 1275 | Z35: 1520 | AA35: 2572 | AB35: 1682 | AC35: 2397 | AD35: 3037 | AE35: 3981 | AF35: 1840 | AG35: 1582 | AH35: 431 | AI35: 532
C36: Total assets | D36: =SUM(D28:D35) -> 17457 | E36: =SUM(E28:E35) -> 16975 | F36: =SUM(F28:F35) -> 17071 | G36: =SUM(G28:G35) -> 17121 | H36: =SUM(H28:H35) -> 17174 | I36: =SUM(I28:I35) -> 16369 | J36: =SUM(J28:J35) -> 16749 | K36: =SUM(K28:K35) -> 16811 | ... U36: =SUM(U28:U35) -> 15222 | Y36: =SUM(Y28:Y35) -> 11972 | Z36: =SUM(Z28:Z35) -> 12848 | AA36: =SUM(AA28:AA35) -> 15405 | AB36: =SUM(AB28:AB35) -> 16487 | AC36: =SUM(AC28:AC35) -> 17593 | AD36: =SUM(AD28:AD35) -> 16665 | AE36: =SUM(AE28:AE35) -> 17233 | AF36: =SUM(AF28:AF35) -> 17121 | ... AI36: =SUM(AI28:AI35) -> 14280
C37: Equity | D37: 8904 | E37: 8210 | F37: 8396 | G37: 9006 | H37: 9314 | I37: 8687 | J37: 8806 | K37: 8332 | L37: 8491 | M37: 8376 | N37: 8215 | O37: 8424 | P37: 8379 | Q37: 8257 | R37: 8240 | S37: 8191 | T37: 8400 | U37: 8311 | Y37: 4521 | Z37: 5158 | AA37: 6178 | AB37: 6798 | AC37: 7326 | AD37: 7817 | AE37: 8608 | AF37: 9006 | AG37: 8332 | AH37: 8424 | AI37: 8191
C38: Non-current IB liabilities | D38: 193 | E38: 247 | F38: 250 | G38: 268 | H38: 257 | I38: 186 | J38: 188 | K38: 397 | L38: 280 | M38: 264 | N38: 199 | O38: 109 | P38: 66 | Q38: 45 | R38: 45 | S38: 128 | T38: 519 | U38: 470 | Y38: 410 | Z38: 282 | AA38: 203 | AB38: 146 | AC38: 425 | AD38: 354 | AE38: 190 | AF38: 268 | AG38: 397 | AH38: 109 | AI38: 128
C39: Other non-current liabilities | D39: 374 | E39: 373 | F39: 374 | G39: 414 | H39: 413 | I39: 413 | J39: 413 | K39: 364 | L39: 364 | M39: 240 | N39: 239 | O39: 84 | P39: 84 | Q39: 12 | R39: 12 | S39: 11 | T39: 12 | U39: 12 | Y39: 160 | Z39: 168 | AA39: 273 | AB39: 696 | AC39: 765 | AD39: 372 | AE39: 373 | AF39: 414 | AG39: 364 | AH39: 84 | AI39: 11
C40: Non-current provisions | D40: 3066 | E40: 3036 | F40: 2862 | G40: 2717 | H40: 2591 | I40: 2671 | J40: 2631 | K40: 2559 | L40: 2398 | M40: 2382 | N40: 2503 | O40: 2246 | P40: 2208 | Q40: 2230 | R40: 2272 | S40: 2148 | T40: 2234 | U40: 2164 | Y40: 2069 | Z40: 2297 | AA40: 2656 | AB40: 3037 | AC40: 3223 | AD40: 3290 | AE40: 3078 | AF40: 2717 | AG40: 2559 | AH40: 2246 | AI40: 2148
C41: Current IB liabilities | D41: 658 | E41: 617 | F41: 662 | G41: 507 | H41: 461 | I41: 711 | J41: 852 | K41: 1526 | L41: 1499 | M41: 785 | N41: 459 | O41: 1111 | P41: 1699 | Q41: 1970 | R41: 1956 | S41: 1533 | T41: 1844 | U41: 1770 | Y41: 934 | Z41: 438 | AA41: 332 | AB41: 694 | AC41: 690 | AD41: 579 | AE41: 667 | AF41: 507 | AG41: 1526 | AH41: 1111 | AI41: 1533
C42: Other current liabilities | D42: 4118 | E42: 4349 | F42: 4391 | G42: 4088 | H42: 4013 | I42: 3577 | J42: 3745 | K42: 3522 | L42: 3206 | M42: 3029 | N42: 3148 | O42: 2597 | P42: 2313 | Q42: 2429 | R42: 2056 | S42: 2135 | T42: 2295 | U42: 2370 | Y42: 3784 | Z42: 4404 | AA42: 5654 | AB42: 4994 | AC42: 5030 | AD42: 4120 | AE42: 4172 | AF42: 4088 | AG42: 3522 | AH42: 2597 | AI42: 2135
C43: Current provisions | D43: 144 | E43: 142 | F43: 137 | G43: 122 | H43: 126 | I43: 124 | J43: 115 | K43: 113 | L43: 109 | M43: 109 | N43: 106 | O43: 130 | P43: 127 | Q43: 135 | R43: 142 | S43: 135 | T43: 131 | U43: 125 | Y43: 94 | Z43: 101 | AA43: 109 | AB43: 122 | AC43: 134 | AD43: 133 | AE43: 145 | AF43: 122 | AG43: 113 | AH43: 130 | AI43: 135
...

Sheet Segementer
B3: SEK million | C3: Q122 | D3: Q222 | E3: Q322 | F3: Q422 | G3: 2022 | H3: Q123 | I3: Q223 | J3: Q323 | K3: Q423 | L3: 2023 | M3: Q124 | N3: Q224 | O3: Q324 | P3: Q424 | Q3: 2024 | R3: Q125 | S3: Q225 | T3: Q325 | U3: Q425 | V3: 2025 | W3: Q126 | X3: Q226 | Y3: Q326 | Z3: Q426 | AA3: 2026
B4: Stockholm
B5: Revenue | C5: 1285 | D5: 1196 | E5: 1141 | F5: 1344 | G5: =SUM(C5:F5) -> 4966 | H5: 1095 | I5: 1176 | J5: 955 | K5: 1022 | L5: =SUM(H5:K5) -> 4248 | M5: 882 | N5: 1280 | O5: 783 | P5: 1255 | Q5: =SUM(M5:P5) -> 4200 | R5: 849 | S5: 764 | T5: 619 | U5: 955 | V5: =SUM(R5:U5) -> 3187 | W5: 994 | X5: 1109 | AA5: =SUM(W5:Z5) -> 2103
B6: Growth % | H6: =(H5-C5)/C5 -> -0.14785992 | I6: =(I5-D5)/D5 -> -0.016722408 | J6: =(J5-E5)/E5 -> -0.1630149 | K6: =(K5-F5)/F5 -> -0.23958333 | L6: =(L5-G5)/G5 -> -0.14458317 | M6: =(M5-H5)/H5 -> -0.19452055 | N6: =(N5-I5)/I5 -> 0.088435374 | O6: =(O5-J5)/J5 -> -0.18010471 | ... AA6: =(AA5-V5)/V5 -> -0.34013179
B7: Operating profit | C7: 190 | D7: 182 | E7: 160 | F7: 188 | G7: =SUM(C7:F7) -> 720 | H7: 116 | I7: 90 | J7: 24 | K7: -118 | L7: =SUM(H7:K7) -> 112 | M7: -47 | N7: 4 | O7: -2 | P7: -58 | Q7: =SUM(M7:P7) -> -103 | R7: 1 | S7: 1 | T7: -11 | U7: -19 | V7: =SUM(R7:U7) -> -28 | W7: 142 | X7: 39 | AA7: =SUM(W7:Z7) -> 181
B8: Operating margin % | C8: 0.148 | D8: 0.152 | E8: 0.141 | F8: 0.14 | G8: =G7/G5 -> 0.1449859 | H8: 0.106 | I8: 0.076 | J8: 0.025 | K8: -0.115 | L8: =L7/L5 -> 0.026365348 | M8: -0.053 | N8: 0.003 | O8: -0.002 | P8: -0.047 | Q8: =Q7/Q5 -> -0.02452381 | R8: 0.001 | S8: 0.001 | T8: -0.017 | U8: -0.02 | V8: =V7/V5 -> -0.0087856919 | W8: 0.143 | X8: 0.035 | AA8: =AA7/AA5 -> 0.086067523
B9: Operating cashflow | C9: 244 | D9: -182 | E9: 242 | F9: -6 | G9: =SUM(C9:F9) -> 298 | H9: 76 | I9: -806 | J9: 144 | K9: 54 | L9: =SUM(H9:K9) -> -532 | M9: -312 | N9: -30 | O9: 115 | P9: -385 | Q9: =SUM(M9:P9) -> -612 | R9: -444 | S9: 56 | T9: 226 | U9: 413 | V9: =SUM(R9:U9) -> 251 | W9: 330 | X9: 646 | AA9: =SUM(W9:Z9) -> 976
B10: Units sold | C10: 264 | D10: 230 | E10: 102 | F10: 61 | G10: =SUM(C10:F10) -> 657 | H10: 51 | I10: 66 | J10: 74 | K10: 124 | L10: =SUM(H10:K10) -> 315 | M10: 168 | N10: 223 | O10: 162 | P10: 232 | Q10: =SUM(M10:P10) -> 785 | R10: 224 | S10: 155 | T10: 143 | U10: 198 | V10: =SUM(R10:U10) -> 720 | W10: =226+165 -> 391 | X10: 275 | AA10: =SUM(W10:Z10) -> 666
B11: Housing starts | C11: 73 | D11: 178 | E11: 205 | F11: 265 | G11: =SUM(C11:F11) -> 721 | H11: 0 | I11: 0 | J11: 133 | K11: 98 | L11: =SUM(H11:K11) -> 231 | M11: 145 | N11: 253 | O11: 144 | P11: 216 | Q11: =SUM(M11:P11) -> 758 | R11: 86 | S11: 117 | T11: 211 | U11: 223 | V11: =SUM(R11:U11) -> 637 | W11: 118 | X11: 294 | AA11: =SUM(W11:Z11) -> 412
B12: Sweden
B13: Revenue | C13: 1127 | D13: 1205 | E13: 1012 | F13: 1156 | G13: =SUM(C13:F13) -> 4500 | H13: 1129 | I13: 982 | J13: 639 | K13: 726 | L13: =SUM(H13:K13) -> 3476 | M13: 600 | N13: 584 | O13: 557 | P13: 641 | Q13: =SUM(M13:P13) -> 2382 | R13: 598 | S13: 654 | T13: 533 | U13: 688 | V13: =SUM(R13:U13) -> 2473 | W13: 694 | X13: 675 | AA13: =SUM(W13:Z13) -> 1369
B14: Growth % | H14: =(H13-C13)/C13 -> 0.0017746229 | I14: =(I13-D13)/D13 -> -0.18506224 | J14: =(J13-E13)/E13 -> -0.36857708 | K14: =(K13-F13)/F13 -> -0.37197232 | L14: =(L13-G13)/G13 -> -0.22755556 | M14: =(M13-H13)/H13 -> -0.46855624 | N14: =(N13-I13)/I13 -> -0.40529532 | O14: =(O13-J13)/J13 -> -0.12832551 | ... AA14: =(AA13-V13)/V13 -> -0.44642135
B15: Operating profit | C15: 174 | D15: 185 | E15: 153 | F15: 171 | G15: =SUM(C15:F15) -> 683 | H15: 126 | I15: 51 | J15: 32 | K15: -71 | L15: =SUM(H15:K15) -> 138 | M15: 17 | N15: 15 | O15: 23 | P15: 21 | Q15: =SUM(M15:P15) -> 76 | R15: 18 | S15: 22 | T15: 17 | U15: -8 | V15: =SUM(R15:U15) -> 49 | W15: 28 | X15: 28 | AA15: =SUM(W15:Z15) -> 56
B16: Operating margin % | C16: 0.155 | D16: 0.153 | E16: 0.151 | F16: 0.148 | G16: =G15/G13 -> 0.15177778 | H16: 0.112 | I16: 0.052 | J16: 0.05 | K16: -0.097 | L16: =L15/L13 -> 0.039700806 | M16: 0.029 | N16: 0.025 | O16: 0.042 | P16: 0.032 | Q16: =Q15/Q13 -> 0.031905961 | R16: 0.031 | S16: 0.034 | T16: 0.032 | U16: -0.011 | V16: =V15/V13 -> 0.019813991 | W16: 0.04 | X16: 0.041 | AA16: =AA15/AA13 -> 0.040905771
B17: Operating cashflow | C17: 304 | D17: 156 | E17: -356 | F17: 8 | G17: =SUM(C17:F17) -> 112 | H17: -135 | I17: -85 | J17: -94 | K17: -110 | L17: =SUM(H17:K17) -> -424 | M17: -135 | N17: 16 | O17: 267 | P17: -369 | Q17: =SUM(M17:P17) -> -221 | R17: -148 | S17: -33 | T17: 78 | U17: 85 | V17: =SUM(R17:U17) -> -18 | W17: 158 | X17: -71 | AA17: =SUM(W17:Z17) -> 87
B18: Units sold (Consumer) | C18: 375 | D18: 290 | E18: 189 | F18: 92 | G18: =SUM(C18:F18) -> 946 | H18: 113 | I18: 140 | J18: 139 | K18: 142 | L18: =SUM(H18:K18) -> 534 | M18: 172 | N18: 178 | O18: 281 | P18: 100 | Q18: =SUM(M18:P18) -> 731 | R18: 146 | S18: 99 | T18: 129 | U18: 112 | V18: =SUM(R18:U18) -> 486 | X18: 234 | AA18: =SUM(W18:Z18) -> 234
B19: Units sold (Investor) | C19: 0 | D19: 0 | E19: 0 | F19: 0 | G19: =SUM(C19:F19) -> 0 | H19: 0 | I19: 0 | J19: 0 | K19: 0 | L19: =SUM(H19:K19) -> 0 | M19: 0 | N19: 0 | P19: 0 | Q19: =SUM(M19:P19) -> 0 | R19: 0 | S19: 0 | T19: 0 | U19: 0 | V19: =SUM(R19:U19) -> 0 | X19: 71 | AA19: =SUM(W19:Z19) -> 71
B20: Housing starts (Consumer) | C20: 357 | D20: 262 | E20: 255 | F20: 148 | G20: =SUM(C20:F20) -> 1022 | H20: 139 | I20: 159 | J20: 0 | K20: 145 | L20: =SUM(H20:K20) -> 443 | M20: 0 | N20: 74 | O20: 306 | P20: 158 | Q20: =SUM(M20:P20) -> 538 | R20: 166 | S20: 365 | T20: 0 | U20: 215 | V20: =SUM(R20:U20) -> 746 | X20: 165 | AA20: =SUM(W20:Z20) -> 165
B21: Housing starts (Investor) | C21: 0 | D21: 0 | E21: 0 | F21: 0 | G21: 0 | H21: 0 | I21: 0 | J21: 0 | K21: 0 | L21: 0 | M21: 0 | N21: 0 | O21: 0 | P21: 0 | Q21: 0 | R21: 0 | S21: 0 | T21: 0 | U21: 0 | V21: 0 | X21: 71 | AA21: 0
B22: Norway
B23: Revenue | C23: 856 | D23: 747 | E23: 829 | F23: 960 | G23: =SUM(C23:F23) -> 3392 | H23: 632 | I23: 645 | J23: 561 | K23: 751 | L23: =SUM(H23:K23) -> 2589 | M23: 690 | N23: 457 | O23: 366 | P23: 511 | Q23: =SUM(M23:P23) -> 2024 | R23: 460 | S23: 380 | T23: 395 | U23: 578 | V23: =SUM(R23:U23) -> 1813 | W23: 829 | X23: 584 | AA23: =SUM(W23:Z23) -> 1413
B24: Growth % | H24: =(H23-C23)/C23 -> -0.26168224 | I24: =(I23-D23)/D23 -> -0.13654618 | J24: =(J23-E23)/E23 -> -0.32328106 | K24: =(K23-F23)/F23 -> -0.21770833 | L24: =(L23-G23)/G23 -> -0.23673349 | M24: =(M23-H23)/H23 -> 0.091772152 | N24: =(N23-I23)/I23 -> -0.29147287 | O24: =(O23-J23)/J23 -> -0.34759358 | ... AA24: =(AA23-V23)/V23 -> -0.22062879
B25: Operating profit | C25: 73 | D25: 61 | E25: 54 | F25: 51 | G25: =SUM(C25:F25) -> 239 | H25: 42 | I25: 43 | J25: 30 | K25: 34 | L25: =SUM(H25:K25) -> 149 | M25: 70 | N25: 28 | O25: 24 | P25: 21 | Q25: =SUM(M25:P25) -> 143 | R25: 26 | S25: 27 | T25: 23 | U25: 34 | V25: =SUM(R25:U25) -> 110 | W25: 47 | X25: 40 | AA25: =SUM(W25:Z25) -> 87
B26: Operating margin % | C26: 0.086 | D26: 0.081 | E26: 0.065 | F26: 0.053 | G26: =G25/G23 -> 0.070459906 | H26: 0.067 | I26: 0.067 | J26: 0.053 | K26: 0.045 | L26: =L25/L23 -> 0.057551178 | M26: 0.101 | N26: 0.06 | O26: 0.066 | P26: 0.041 | Q26: =Q25/Q23 -> 0.070652174 | R26: 0.057 | S26: 0.072 | T26: 0.058 | U26: 0.058 | V26: =V25/V23 -> 0.060672918 | W26: 0.056 | X26: 0.069 | AA26: =AA25/AA23 -> 0.061571125
B27: Operating cashflow | C27: -61 | D27: -2 | E27: 16 | F27: 249 | G27: =SUM(C27:F27) -> 202 | H27: -12 | I27: 109 | J27: -105 | K27: 46 | L27: =SUM(H27:K27) -> 38 | M27: -246 | N27: 200 | O27: 76 | P27: 81 | Q27: =SUM(M27:P27) -> 111 | R27: 40 | S27: 12 | T27: 72 | U27: 238 | V27: =SUM(R27:U27) -> 362 | W27: -378 | X27: 34 | AA27: =SUM(W27:Z27) -> -344
B28: Units sold (Consumer) | C28: 194 | D28: 93 | E28: 140 | F28: 100 | G28: =SUM(C28:F28) -> 527 | H28: 77 | I28: 144 | J28: 71 | K28: 196 | L28: =SUM(H28:K28) -> 488 | M28: 62 | N28: 143 | O28: 165 | P28: 41 | Q28: =SUM(M28:P28) -> 411 | R28: 160 | S28: 60 | T28: 46 | U28: 103 | V28: =SUM(R28:U28) -> 369 | X28: 71 | AA28: =SUM(W28:Z28) -> 71
B29: Units sold (Investor) | C29: 0 | D29: 0 | E29: 0 | F29: 0 | G29: =SUM(C29:F29) -> 0 | H29: 0 | I29: 0 | J29: 0 | K29: 0 | L29: =SUM(H29:K29) -> 0 | M29: 0 | N29: 0 | O29: 0 | P29: 0 | Q29: =SUM(M29:P29) -> 0 | R29: 0 | S29: 0 | T29: 0 | U29: 0 | V29: =SUM(R29:U29) -> 0 | X29: 0 | AA29: =SUM(W29:Z29) -> 0
B30: Housing starts (Consumer) | C30: 250 | D30: 34 | E30: 132 | F30: 189 | G30: =SUM(C30:F30) -> 605 | H30: 41 | I30: 140 | J30: 68 | K30: 156 | L30: =SUM(H30:K30) -> 405 | M30: 0 | N30: 188 | O30: 187 | P30: 0 | Q30: =SUM(M30:P30) -> 375 | R30: 202 | S30: 0 | T30: 25 | U30: 156 | V30: =SUM(R30:U30) -> 383 | X30: 0 | AA30: =SUM(W30:Z30) -> 0
B31: Housing starts (Investor) | C31: 0 | D31: 0 | E31: 0 | F31: 0 | G31: =SUM(C31:F31) -> 0 | H31: 0 | I31: 0 | J31: 0 | K31: 0 | L31: 0 | M31: 0 | N31: 0 | O31: 0 | P31: 0 | Q31: 0 | R31: 0 | S31: 0 | T31: 0 | U31: 0 | V31: 0 | X31: 0 | AA31: 0
B32: Finland
B33: Revenue | C33: 375 | D33: 449 | E33: 399 | F33: 505 | G33: =SUM(C33:F33) -> 1728 | H33: 439 | I33: 389 | J33: 326 | K33: 437 | L33: =SUM(H33:K33) -> 1591 | M33: 388 | N33: 494 | O33: 345 | P33: 381 | Q33: =SUM(M33:P33) -> 1608 | R33: 332 | S33: 498 | T33: 336 | U33: 361 | V33: =SUM(R33:U33) -> 1527 | W33: 316 | X33: 327 | AA33: =SUM(W33:Z33) -> 643
B34: Growth % | H34: =(H33-C33)/C33 -> 0.17066667 | I34: =(I33-D33)/D33 -> -0.13363029 | J34: =(J33-E33)/E33 -> -0.18295739 | K34: =(K33-F33)/F33 -> -0.13465347 | L34: =(L33-G33)/G33 -> -0.079282407 | M34: =(M33-H33)/H33 -> -0.11617312 | N34: =(N33-I33)/I33 -> 0.26992288 | O34: =(O33-J33)/J33 -> 0.058282209 | ... AA34: =(AA33-V33)/V33 -> -0.5789129
B35: Operating profit | C35: 33 | D35: 41 | E35: 37 | F35: 47 | G35: =SUM(C35:F35) -> 158 | H35: 38 | I35: 29 | J35: 27 | K35: 46 | L35: =SUM(H35:K35) -> 140 | M35: 26 | N35: 38 | O35: 21 | P35: 8 | Q35: =SUM(M35:P35) -> 93 | R35: 20 | S35: 39 | T35: 17 | U35: 22 | V35: =SUM(R35:U35) -> 98 | W35: 21 | X35: 2 | AA35: =SUM(W35:Z35) -> 23
B36: Operating margin % | C36: 0.087 | D36: 0.091 | E36: 0.093 | F36: 0.094 | G36: =G35/G33 -> 0.091435185 | H36: 0.086 | I36: 0.075 | J36: 0.084 | K36: 0.105 | L36: =L35/L33 -> 0.087994972 | M36: 0.067 | N36: 0.077 | O36: 0.06 | P36: 0.021 | Q36: =Q35/Q33 -> 0.057835821 | R36: 0.06 | S36: 0.078 | T36: 0.049 | U36: 0.06 | V36: =V35/V33 -> 0.064178127 | W36: 0.067 | X36: 0.007 | AA36: =AA35/AA33 -> 0.035769829
B37: Operating cashflow | C37: 24 | D37: -141 | E37: 79 | F37: 231 | G37: =SUM(C37:F37) -> 193 | H37: -29 | I37: 79 | J37: -45 | K37: -61 | L37: =SUM(H37:K37) -> -56 | M37: 85 | N37: 203 | O37: 44 | P37: -185 | Q37: =SUM(M37:P37) -> 147 | R37: 89 | S37: -322 | T37: 71 | U37: -250 | V37: =SUM(R37:U37) -> -412 | W37: -339 | X37: -5 | AA37: =SUM(W37:Z37) -> -344
B38: Units sold (Consumer) | C38: 162 | D38: 119 | E38: 39 | F38: 139 | G38: =SUM(C38:F38) -> 459 | H38: 20 | I38: 13 | J38: 2 | K38: 311 | L38: =SUM(H38:K38) -> 346 | M38: 28 | N38: 11 | O38: 41 | P38: 100 | Q38: =SUM(M38:P38) -> 180 | R38: 25 | S38: 48 | T38: 8 | U38: 26 | V38: =SUM(R38:U38) -> 107 | X38: 18 | AA38: =SUM(W38:Z38) -> 18
B39: Units sold (Investor) | C39: 0 | D39: 0 | E39: 0 | F39: 0 | G39: =SUM(C39:F39) -> 0 | H39: 0 | I39: 0 | J39: 0 | K39: 0 | L39: =SUM(H39:K39) -> 0 | M39: 50 | N39: 242 | O39: 0 | P39: 0 | Q39: =SUM(M39:P39) -> 292 | R39: 0 | S39: 71 | T39: 31 | U39: 39 | V39: =SUM(R39:U39) -> 141 | X39: 115 | AA39: =SUM(W39:Z39) -> 115
B40: Housing starts (Consumer) | C40: 128 | D40: 245 | E40: 0 | F40: 226 | G40: =SUM(C40:F40) -> 599 | H40: 34 | I40: 0 | J40: 0 | K40: 341 | L40: =SUM(H40:K40) -> 375 | M40: 0 | N40: 0 | O40: 0 | P40: 154 | Q40: =SUM(M40:P40) -> 154 | R40: 52 | S40: 0 | T40: 29 | U40: 52 | V40: =SUM(R40:U40) -> 133 | X40: 34 | AA40: =SUM(W40:Z40) -> 34
B41: Housing starts (Investor) | C41: 0 | D41: 0 | E41: 0 | F41: 0 | G41: =SUM(C41:F41) -> 0 | H41: 0 | I41: 0 | J41: 0 | K41: 0 | L41: 0 | M41: 0 | N41: 207 | O41: 0 | P41: 0 | Q41: 0 | R41: 71 | S41: 0 | T41: 31 | U41: 104 | V41: 0 | X41: 115 | AA41: 0
B42: Property dev
...

Sheet SOTP

Sheet Nøkkeltall
D4: 2026 | E4: 2027 | F4: 2028
C5: EV/EBIT | D5: =Modell!$B$9/Modell!AJ9 -> 18.438317 | E5: =Modell!$B$9/Modell!AK9 -> 12.305315 | F5: =Modell!$B$9/Modell!AL9 -> 7.4100429
C6: P/E | D6: =Modell!$B$4/Modell!AJ16 -> 27.565094 | E6: =Modell!$B$4/Modell!AK16 -> 12.577157 | F6: =Modell!$B$4/Modell!AL16 -> 7.573741

Sheet Nedsideberegning
A3: Nedside | D3: FY 2015 | E3: FY 2016 | F3: FY 2017 | G3: FY 2018 | H3: FY 2019 | I3: FY 2020 | J3: FY 2021 | K3: FY 2022 | L3: FY 2023 | M3: FY 2024 | N3: FY 2025 | O3: FY 2026 | P3: FY 2027 | Q3: FY 2028 | R3: FY 2029 | S3: FY 2030 | T3: FY 2031 | U3: FY 2032 | V3: FY 2033 | W3: FY 2034 | X3: FY 2035
A4: Nullvekst og konstante marginer | C4: Revenue | D4: 13939 | E4: 15291 | F4: 17008 | G4: 16161 | H4: 15692 | I4: 15388 | J4: 14608 | K4: 16385 | L4: 13851 | M4: 12507 | N4: =M4*0.84 -> 10505.88 | O4: =N4*1 -> 10505.88 | P4: =O4*1 -> 10505.88 | Q4: =P4*1 -> 10505.88 | R4: =Q4*1 -> 10505.88 | S4: =R4*1 -> 10505.88 | T4: =S4*1 -> 10505.88 | U4: =T4*1 -> 10505.88 | V4: =U4*1 -> 10505.88 | ... X4: =W4*1 -> 10505.88
A5: =AA21 -> 105.49795 | C5: Production and operating costs | D5: -11630 | E5: -12440 | F5: -13648 | G5: -13247 | H5: -12994 | I5: -12607 | J5: -11814 | K5: -13216 | L5: -11877 | M5: -11040 | N5: =N4*-0.865 -> -9087.5862 | O5: =O4*-0.85 -> -8929.998 | P5: =P4*-0.85 -> -8929.998 | Q5: =Q4*-0.85 -> -8929.998 | R5: =R4*-0.85 -> -8929.998 | S5: =S4*-0.85 -> -8929.998 | T5: =T4*-0.85 -> -8929.998 | U5: =U4*-0.85 -> -8929.998 | V5: =V4*-0.85 -> -8929.998 | ... X5: =X4*-0.85 -> -8929.998
A6: =AA22 -> -0.20678236 | C6: Gross profit | D6: =SUM(D4:D5) -> 2309 | E6: =SUM(E4:E5) -> 2851 | F6: =SUM(F4:F5) -> 3360 | G6: =SUM(G4:G5) -> 2914 | H6: =SUM(H4:H5) -> 2698 | I6: =SUM(I4:I5) -> 2781 | J6: =SUM(J4:J5) -> 2794 | K6: =SUM(K4:K5) -> 3169 | ... X6: =SUM(X4:X5) -> 1575.882
C7: Selling and adminstrative expenses | D7: -866 | E7: -935 | F7: -1005 | G7: -1041 | H7: -966 | I7: -944 | J7: -1015 | K7: -1094 | L7: -985 | M7: -927 | N7: =M7*1.025 -> -950.175 | O7: =N7*0.9 -> -855.1575 | P7: =O7 -> -855.1575 | Q7: =P7 -> -855.1575 | R7: =Q7 -> -855.1575 | S7: =R7 -> -855.1575 | T7: =S7 -> -855.1575 | U7: =T7 -> -855.1575 | V7: =U7 -> -855.1575 | W7: =V7 -> -855.1575 | X7: =W7 -> -855.1575
C8: Gains/losses on sale of property | D8: 56 | E8: 15 | F8: 14 | G8: 13 | H8: 276 | I8: 191 | J8: 436 | K8: -11 | L8: -256 | M8: -8 | N8: =M8*1.025 -> -8.2 | O8: 0 | P8: 0 | Q8: 0 | R8: 0 | S8: 0 | T8: 0 | U8: 0 | V8: 0 | W8: 0 | X8: 0
C9: Operating profit (EBIT) | D9: =SUM(D6:D8) -> 1499 | E9: =SUM(E6:E8) -> 1931 | F9: =SUM(F6:F8) -> 2369 | G9: =SUM(G6:G8) -> 1886 | H9: =SUM(H6:H8) -> 2008 | I9: =SUM(I6:I8) -> 2028 | J9: =SUM(J6:J8) -> 2215 | K9: =SUM(K6:K8) -> 2064 | ... X9: =SUM(X6:X8) -> 720.7245
C10: Financial income | D10: 11 | E10: 17 | F10: 279 | G10: 10 | H10: 6 | I10: 6 | J10: 4 | K10: 19 | L10: 33 | M10: 24 | N10: 0 | O10: 0 | P10: 0 | Q10: 0 | R10: 0 | S10: 0 | T10: 0 | U10: 0 | V10: 0 | W10: 0 | X10: 0
C11: Financial expenses | D11: -83 | E11: -77 | F11: -69 | G11: -79 | H11: -86 | I11: -79 | J11: -62 | K11: -89 | L11: -133 | M11: -151 | N11: 0 | O11: 0 | P11: 0 | Q11: 0 | R11: 0 | S11: 0 | T11: 0 | U11: 0 | V11: 0 | W11: 0 | X11: 0
C12: PTP | D12: =SUM(D9:D11) -> 1427 | E12: =SUM(E9:E11) -> 1871 | F12: =SUM(F9:F11) -> 2579 | G12: =SUM(G9:G11) -> 1817 | H12: =SUM(H9:H11) -> 1928 | I12: =SUM(I9:I11) -> 1955 | J12: =SUM(J9:J11) -> 2157 | K12: =SUM(K9:K11) -> 1994 | ... X12: =SUM(X9:X11) -> 720.7245
C13: Taxes | D13: -342 | E13: -393 | F13: -385 | G13: -379 | H13: -358 | I13: -380 | J13: -360 | K13: -419 | L13: -199 | M13: -157 | N13: =N12*-0.2 -> -91.98376 | O13: =O12*-0.2 -> -144.1449 | P13: =P12*-0.2 -> -144.1449 | Q13: =Q12*-0.2 -> -144.1449 | R13: =R12*-0.2 -> -144.1449 | S13: =S12*-0.2 -> -144.1449 | T13: =T12*-0.2 -> -144.1449 | U13: =U12*-0.2 -> -144.1449 | ... X13: =X12*-0.2 -> -144.1449
C14: Net income | D14: =SUM(D12:D13) -> 1085 | E14: =SUM(E12:E13) -> 1478 | F14: =SUM(F12:F13) -> 2194 | G14: =SUM(G12:G13) -> 1438 | H14: =SUM(H12:H13) -> 1570 | I14: =SUM(I12:I13) -> 1575 | J14: =SUM(J12:J13) -> 1797 | K14: =SUM(K12:K13) -> 1575 | ... X14: =SUM(X12:X13) -> 576.5796 | Y14: =X14*(1+$AA$18) -> 570.8138 | Z14: =Y14*(1+$AA$18) -> 565.10567 | AA14: =Z14*(1+$AA$18) -> 559.45461 | AB14: =AA14*(1+$AA$18) -> 553.86006 | AC14: =AB14*(1+$AA$18) -> 548.32146 | AD14: =AC14*(1+$AA$18) -> 542.83825 | AE14: =AD14*(1+$AA$18) -> 537.40987 | AF14: =AE14*(1+$AA$18) -> 532.03577 | ... DG14: =DF14*(1+$AA$18) -> 240.50339
C15: Share | D15: 70.844023 | E15: 70.844023 | F15: 70.844023 | G15: 69.865418 | H15: 69.985557 | I15: 70.061421 | J15: 69.560505 | K15: 67.384072 | L15: 64.50484 | M15: 64.50484 | N15: 64.50484 | O15: 64.50484 | P15: 64.50484 | Q15: 64.50484 | R15: 64.50484 | S15: 64.50484 | T15: 64.50484 | U15: 64.50484 | V15: 64.50484 | W15: 64.50484 | X15: 64.50484
C16: EPS | D16: =D14/D15 -> 15.315336 | E16: =E14/E15 -> 20.862734 | F16: =F14/F15 -> 30.969444 | G16: =G14/G15 -> 20.582429 | H16: =H14/H15 -> 22.4332 | I16: =I14/I15 -> 22.480275 | J16: =J14/J15 -> 25.833625 | K16: =K14/K15 -> 23.373476 | ... X16: =X14/X15 -> 8.9385479
Z17: Disocunt | AA17: 0.08
C18: Revenue y/y | E18: =(E4-D4)/D4 -> 0.096994045 | F18: =(F4-E4)/E4 -> 0.11228827 | G18: =(G4-F4)/F4 -> -0.049800094 | H18: =(H4-G4)/G4 -> -0.029020481 | I18: =(I4-H4)/H4 -> -0.019372929 | J18: =(J4-I4)/I4 -> -0.050688848 | K18: =(K4-J4)/J4 -> 0.12164567 | L18: =(L4-K4)/K4 -> -0.15465365 | ... X18: =(X4-W4)/W4 -> 0 | Z18: TV | AA18: -0.01
C19: Gross margin | D19: =D6/D4 -> 0.16565033 | E19: =E6/E4 -> 0.18644955 | F19: =F6/F4 -> 0.19755409 | G19: =G6/G4 -> 0.18031062 | H19: =H6/H4 -> 0.17193474 | I19: =I6/I4 -> 0.18072524 | J19: =J6/J4 -> 0.19126506 | K19: =K6/K4 -> 0.19340861 | ... X19: =X6/X4 -> 0.15 | Z19: NPV | AA19: =NPV(AA17,O14:DG14) -> 6805.1281
C20: EBIT margin | D20: =D9/D4 -> 0.10754 | E20: =E9/E4 -> 0.12628343 | F20: =F9/F4 -> 0.13928739 | G20: =G9/G4 -> 0.1167007 | H20: =H9/H4 -> 0.12796329 | I20: =I9/I4 -> 0.13179101 | J20: =J9/J4 -> 0.15162924 | K20: =K9/K4 -> 0.12596887 | ... X20: =X9/X4 -> 0.068602011 | Z20: S/O | AA20: 64.50484
Z21: NPV/share | AA21: =AA19/AA20 -> 105.49795
Z22: Opp/nedside | AA22: =(AA21-Modell!B4)/Modell!B4 -> -0.20678236
