Workbook

Sheet Info
H1: Q126 | K1: KID jobber aktivt med å ekspandere alle sine butikker til å at de er minst 600 kvadratmeter, på denne måten får de stilt ut hele sortimentet sitt på en god måte
K24: Antall butikker totalt | L24: 286 | M24: %
K25: Antall butikker > 600 sqm | L25: 69 | M25: =L25/L24 -> 0.24125874
K26: Antall butikker < 600 sqm | L26: 207 | M26: =L26/L24 -> 0.72377622
A36: Press releases
A37: 07.09.26: Salt Value flagger 5%
A38: 13.01.26: DNB AM solgte 314 121 aksjer og flagger under 5%
A39: 07.11.25: Mads Kigen, CFO, kjøpte 1 100 aksjer på 133,6 NOK
A40: 07.11.25: Marianne Fulford, CEO, kjøpte 1 350 aksjer til 133,35 NOK
A41: 06.11.25: Josephine Gisaeus kjøpte 1 480 aksjer til 133,6 NOK
A42: 19.05.25: Jon Brannsten, styremedlem, kjøper 1 000 aksjer til 149,60
A43: 19.02.25: Anders Lorentzon, sheriff over Hemtex, kjøper 4 950 aksjer, eier 4 950
A44: 11.02.25: Marianne Fulford blir ny CEO, hun vil tre inn 1.mai 2025
A45: 03.12.24: Kid selger varehus og kontorbygg i Vserige til STB nordic real estate. Solgt for 600 mill
A46: 22.11.24: Kaja Myhra kjøper 600 aksjer, eier 600 etter dette
A47: 12.11.24: Mads Kigen, CFO, kjøper 1 500 aksjer, eier 2 000 etter dette
A48: 01.11.24: Andere Fjeld slutter som CEO

Sheet Modell
A3: Kapitalstruktur | C3: NOK million | D3: Q122 | E3: Q222 | F3: Q322 | G3: Q422 | H3: Q123 | I3: Q223 | J3: Q323 | K3: Q423 | L3: Q124 | M3: Q224 | N3: Q324 | O3: Q424 | P3: Q125 | Q3: Q225 | R3: Q325 | S3: Q425 | T3: Q126 | U3: Q226 | V3: Q326 | W3: Q426 | Z3: FY 2015 | AA3: FY 2016 | AB3: FY 2017 | AC3: FY 2018 | AD3: FY 2019 | AE3: FY 2020 | AF3: FY 2021 | AG3: FY 2022 | AH3: FY 2023 | AI3: FY 2024 | AJ3: FY 2025 | AK3: FY 2026 | AL3: FY 2027 | AM3: FY 2028 | AN3: FY 2029 | AO3: FY 2030 | AP3: FY 2031 | AQ3: FY 2032 | AR3: FY 2033 | AS3: FY 2034 | AT3: FY 2035
A4: Price | B4: 118 | C4: Revenue | D4: 605 | E4: 730 | F4: 735 | G4: 1109 | H4: 605 | I4: 724 | J4: 831 | K4: 1253 | L4: 696 | M4: 798 | N4: 887 | O4: 1404 | P4: 733.7 | Q4: 856.4 | R4: 902 | S4: 1452 | T4: 800.457 | U4: 914.794 | Z4: 1188.433 | AA4: 1293.932 | AB4: 1381.675 | AC4: 1466.729 | AD4: 2342.18 | AE4: 2994.658 | AF4: 3097.096 | AG4: 3179 | AH4: 3413 | AI4: 3785 | AJ4: 3944 | AK4: =AJ4*1.075 -> 4239.8 | AL4: =AK4*1.065 -> 4515.387 | AM4: =AL4*1.065 -> 4808.8872 | AN4: =AM4*1.065 -> 5121.4648 | AO4: =AN4*1.065 -> 5454.36 | AP4: =AO4*1.065 -> 5808.8934 | AQ4: =AP4*1.065 -> 6186.4715 | AR4: =AQ4*1.065 -> 6588.5922 | AS4: =AR4*1.065 -> 7016.8506 | AT4: =AS4*1.065 -> 7472.9459
A5: S/O | B5: 40.645162 | C5: other revenue | D5: 0.699 | E5: 1.795 | F5: 1.532 | G5: 1.201 | H5: 0.623 | I5: 0.952 | J5: 1.007 | K5: 1.661 | L5: 0.844 | M5: 1.333 | N5: 1.304 | O5: 1.357 | P5: 0 | Q5: 1.3 | R5: 1 | S5: 2 | T5: 1.355 | U5: 4.193 | Z5: 1.3 | AA5: 1.6 | AB5: 0.667 | AC5: 0.336 | AD5: 2 | AE5: 1.6 | AF5: 10 | AG5: 5 | AH5: 4 | AI5: 5 | AJ5: 4 | AK5: =AJ5*1.065 -> 4.26 | AL5: =AK5*1.065 -> 4.5369 | AM5: =AL5*1.065 -> 4.8317985 | AN5: =AM5*1.065 -> 5.1458654 | AO5: =AN5*1.065 -> 5.4803467 | AP5: =AO5*1.065 -> 5.8365692 | AQ5: =AP5*1.065 -> 6.2159462 | AR5: =AQ5*1.065 -> 6.6199827 | ... AT5: =AS5*1.065 -> 7.5085499
A6: MC NOKm | B6: =B4*B5 -> 4796.1291 | C6: Total revenue | D6: =SUM(D4:D5) -> 605.699 | E6: =SUM(E4:E5) -> 731.795 | F6: =SUM(F4:F5) -> 736.532 | G6: =SUM(G4:G5) -> 1110.201 | H6: =SUM(H4:H5) -> 605.623 | I6: =SUM(I4:I5) -> 724.952 | J6: =SUM(J4:J5) -> 832.007 | K6: =SUM(K4:K5) -> 1254.661 | ... U6: =SUM(U4:U5) -> 918.987 | Z6: =SUM(Z4:Z5) -> 1189.733 | AA6: =SUM(AA4:AA5) -> 1295.532 | AB6: =SUM(AB4:AB5) -> 1382.342 | AC6: =SUM(AC4:AC5) -> 1467.065 | AD6: =SUM(AD4:AD5) -> 2344.18 | AE6: =SUM(AE4:AE5) -> 2996.258 | AF6: =SUM(AF4:AF5) -> 3107.096 | AG6: =SUM(AG4:AG5) -> 3184 | ... AT6: =SUM(AT4:AT5) -> 7480.4545
A7: Cash NOKm | B7: 0 | C7: Purchased goods/Change in inventory | D7: -234.501 | E7: -292.082 | F7: -326.898 | G7: -478.132 | H7: -266.198 | I7: -273.828 | J7: -315.148 | K7: -459.106 | L7: -268.238 | M7: -293.371 | N7: -336.308 | O7: -545.307 | P7: -289.383 | Q7: -322.538 | R7: -344.777 | S7: -563.586 | T7: -310.899 | U7: -336.626 | Z7: -492 | AA7: -515.299 | AB7: -547.627 | AC7: -573.23 | AD7: =-1019.79+94.124 -> -925.666 | AE7: =-1128.69+15.677 -> -1113.013 | AF7: -1159.506 | AG7: -1332 | AH7: -1314 | AI7: -1443 | AJ7: -1520 | AK7: =AK6*-0.38 -> -1612.7428 | AL7: =AL6*-0.38 -> -1717.5711 | AM7: =AM6*-0.38 -> -1829.2132 | AN7: =AN6*-0.38 -> -1948.1121 | AO7: =AO6*-0.38 -> -2074.7393 | AP7: =AP6*-0.38 -> -2209.5974 | AQ7: =AQ6*-0.38 -> -2353.2212 | AR7: =AR6*-0.38 -> -2506.1806 | ... AT7: =AT6*-0.38 -> -2842.5727
A8: Debt NOKm | B8: =U56+U58 -> 1081.209 | C8: Gross profit | D8: =SUM(D6:D7) -> 371.198 | E8: =SUM(E6:E7) -> 439.713 | F8: =SUM(F6:F7) -> 409.634 | G8: =SUM(G6:G7) -> 632.069 | H8: =SUM(H6:H7) -> 339.425 | I8: =SUM(I6:I7) -> 451.124 | J8: =SUM(J6:J7) -> 516.859 | K8: =SUM(K6:K7) -> 795.555 | ... U8: =SUM(U6:U7) -> 582.361 | Z8: =SUM(Z6:Z7) -> 697.733 | AA8: =SUM(AA6:AA7) -> 780.233 | AB8: =SUM(AB6:AB7) -> 834.715 | AC8: =SUM(AC6:AC7) -> 893.835 | AD8: =SUM(AD6:AD7) -> 1418.514 | AE8: =SUM(AE6:AE7) -> 1883.245 | AF8: =SUM(AF6:AF7) -> 1947.59 | AG8: =SUM(AG6:AG7) -> 1852 | ... AT8: =SUM(AT6:AT7) -> 4637.8818
A9: EV NOKm | B9: =B6-B7+B8 -> 5877.3381 | C9: Employee benefits | D9: -153.134 | E9: -155.888 | F9: -144.48 | G9: -176.39 | H9: -160.855 | I9: -162.331 | J9: -161.495 | K9: -220.04 | L9: -178.47 | M9: -179.554 | N9: -188.329 | O9: -236.158 | P9: -191.529 | Q9: -198.698 | R9: -183.223 | S9: -218.336 | T9: -201.371 | U9: -200.048 | Z9: -271.342 | AA9: -289.547 | AB9: -306.471 | AC9: -310.898 | AD9: -503.494 | AE9: -607.119 | AF9: -617.3 | AG9: -630 | AH9: -705 | AI9: -783 | AJ9: -792 | AK9: =AJ9*1.03 -> -815.76 | AL9: =AK9*1.055 -> -860.6268 | AM9: =AL9*1.055 -> -907.96127 | AN9: =AM9*1.055 -> -957.89914 | AO9: =AN9*1.055 -> -1010.5836 | AP9: =AO9*1.055 -> -1066.1657 | AQ9: =AP9*1.055 -> -1124.8048 | AR9: =AQ9*1.055 -> -1186.6691 | AS9: =AR9*1.055 -> -1251.9359 | AT9: =AS9*1.055 -> -1320.7923
C10: D/A | D10: -86.667 | E10: -87.798 | F10: -86.422 | G10: -87.408 | H10: -95.818 | I10: -100.833 | J10: -101.774 | K10: -105.711 | L10: -114.974 | M10: -118.16 | N10: -118.195 | O10: -120.334 | P10: -131.663 | Q10: -155.571 | R10: -131.929 | S10: -136.092 | T10: -143.621 | U10: -139.386 | Z10: -24.447 | AA10: -28.953 | AB10: -34.839 | AC10: -37 | AD10: -264.974 | AE10: -340.84 | AF10: -336.376 | AG10: -348 | AH10: -404 | AI10: -472 | AJ10: -555 | AK10: =AJ10*1.03 -> -571.65 | AL10: =AK10*1.055 -> -603.09075 | AM10: =AL10*1.055 -> -636.26074 | AN10: =AM10*1.055 -> -671.25508 | AO10: =AN10*1.055 -> -708.17411 | AP10: =AO10*1.055 -> -747.12369 | AQ10: =AP10*1.055 -> -788.21549 | AR10: =AQ10*1.055 -> -831.56734 | AS10: =AR10*1.055 -> -877.30355 | AT10: =AS10*1.055 -> -925.55524
C11: Other opex | D11: -107.256 | E11: -116.281 | F11: -122.143 | G11: -158.519 | H11: -122.329 | I11: -122.311 | J11: -113.923 | K11: -155.808 | L11: -126.113 | M11: -124.739 | N11: -127.195 | O11: -159.037 | P11: -138.291 | Q11: -147.353 | R11: -170.265 | S11: -232.721 | T11: -156.86 | U11: -164.562 | Z11: -282.69 | AA11: -289.627 | AB11: -313.716 | AC11: -332.73 | AD11: -348.153 | AE11: -452.65 | AF11: -452.73 | AG11: -504 | AH11: -514 | AI11: -537 | AJ11: -689 | AK11: =AJ11*1.03 -> -709.67 | AL11: =AK11*1.055 -> -748.70185 | AM11: =AL11*1.055 -> -789.88045 | AN11: =AM11*1.055 -> -833.32388 | AO11: =AN11*1.055 -> -879.15669 | AP11: =AO11*1.055 -> -927.51031 | AQ11: =AP11*1.055 -> -978.52337 | AR11: =AQ11*1.055 -> -1032.3422 | AS11: =AR11*1.055 -> -1089.121 | AT11: =AS11*1.055 -> -1149.0226
A12: Gearing | B12: =B8/U30 -> 1.0858783 | C12: Operating profit (EBIT) | D12: =SUM(D8:D11) -> 24.141 | E12: =SUM(E8:E11) -> 79.746 | F12: =SUM(F8:F11) -> 56.589 | G12: =SUM(G8:G11) -> 209.752 | H12: =SUM(H8:H11) -> -39.577 | I12: =SUM(I8:I11) -> 65.649 | J12: =SUM(J8:J11) -> 139.667 | K12: =SUM(K8:K11) -> 313.996 | ... U12: =SUM(U8:U11) -> 78.365 | Z12: =SUM(Z8:Z11) -> 119.254 | AA12: =SUM(AA8:AA11) -> 172.106 | AB12: =SUM(AB8:AB11) -> 179.689 | AC12: =SUM(AC8:AC11) -> 213.207 | AD12: =SUM(AD8:AD11) -> 301.893 | AE12: =SUM(AE8:AE11) -> 482.636 | AF12: =SUM(AF8:AF11) -> 541.184 | AG12: =SUM(AG8:AG11) -> 370 | ... AT12: =SUM(AT8:AT11) -> 1242.5116
C13: Net financial | D13: -11.571 | E13: -10.733 | F13: -12.446 | G13: -12.779 | H13: -17.903 | I13: -20.542 | J13: -20.231 | K13: -17.954 | L13: -19.891 | M13: -23.118 | N13: -25.006 | O13: -22.454 | P13: -21.974 | Q13: -40.657 | R13: 4.5 | S13: -23.18 | T13: -36 | U13: -28.572 | Z13: -20.2 | AA13: -12.6 | AB13: -12.6 | AC13: -12.7 | AD13: -40.943 | AE13: -28.435 | AF13: -56 | AG13: -48 | AH13: -77 | AI13: -90 | AJ13: -81 | AK13: =AJ13*1.05 -> -85.05 | AL13: =AK13*1.05 -> -89.3025 | AM13: =AL13*1.05 -> -93.767625 | AN13: =AM13*1.05 -> -98.456006 | AO13: =AN13*1.05 -> -103.37881 | AP13: =AO13*1.05 -> -108.54775 | AQ13: =AP13*1.05 -> -113.97513 | AR13: =AQ13*1.05 -> -119.67389 | ... AT13: =AS13*1.05 -> -131.94046
A14: P/B | B14: =B6/U53 -> 3.5555775 | C14: Share of JV | D14: -0.688 | E14: -1.186 | F14: -2.53 | G14: 1.618 | H14: -0.358 | I14: 0.102 | J14: -1.332 | K14: 0.388 | L14: -0.59 | M14: -0.919 | N14: -0.695 | O14: 35.531 | P14: 0.383 | Q14: 3.1 | R14: -28.3 | S14: 0.276 | T14: -0.231 | U14: -1 | Z14: 0 | AA14: 0 | AB14: 0 | AC14: 0 | AD14: 0 | AE14: 0 | AF14: 0 | AG14: -3 | AH14: -1 | AI14: 33 | AJ14: -25 | AK14: -2.5 | AL14: -2.5 | AM14: -2.5 | AN14: -2.5 | AO14: -2.5 | AP14: -2.5 | AQ14: -2.5 | AR14: -2.5 | AS14: -2.5 | AT14: -2.5
C15: PTP | D15: =SUM(D12:D14) -> 11.882 | E15: =SUM(E12:E14) -> 67.827 | F15: =SUM(F12:F14) -> 41.613 | G15: =SUM(G12:G14) -> 198.591 | H15: =SUM(H12:H14) -> -57.838 | I15: =SUM(I12:I14) -> 45.209 | J15: =SUM(J12:J14) -> 118.104 | K15: =SUM(K12:K14) -> 296.43 | ... U15: =SUM(U12:U14) -> 48.793 | Z15: =SUM(Z12:Z14) -> 99.054 | AA15: =SUM(AA12:AA14) -> 159.506 | AB15: =SUM(AB12:AB14) -> 167.089 | AC15: =SUM(AC12:AC14) -> 200.507 | AD15: =SUM(AD12:AD14) -> 260.95 | AE15: =SUM(AE12:AE14) -> 454.201 | AF15: =SUM(AF12:AF14) -> 485.184 | AG15: =SUM(AG12:AG14) -> 319 | ... AT15: =SUM(AT12:AT14) -> 1108.0711
C16: Tax | D16: -2.801 | E16: -15.909 | F16: -11.801 | G16: -39.157 | H16: 10.795 | I16: -8.874 | J16: -27.371 | K16: -63.251 | L16: 1.8 | M16: -10.891 | N16: -22.283 | O16: -68.183 | P16: 7.782 | Q16: 1.273 | R16: -9 | S16: -58.7 | T16: 8.317 | U16: -12 | Z16: 2.3 | AA16: -25.4 | AB16: -25.7 | AC16: -31.6 | AD16: -53 | AE16: -98.196 | AF16: -100.741 | AG16: -70 | AH16: -89 | AI16: -100 | AJ16: -59 | AK16: =AK15*-0.22 -> -98.271184 | AL16: =AL15*-0.22 -> -109.5888 | AM16: =AM15*-0.22 -> -121.90985 | AN16: =AN15*-0.22 -> -135.31419 | AO16: =AO15*-0.22 -> -149.88772 | AP16: =AP15*-0.22 -> -165.72274 | AQ16: =AQ15*-0.22 -> -182.91843 | AR16: =AR15*-0.22 -> -201.58139 | ... AT16: =AT15*-0.22 -> -243.77564
C17: Net income | D17: =SUM(D15:D16) -> 9.081 | E17: =SUM(E15:E16) -> 51.918 | F17: =SUM(F15:F16) -> 29.812 | G17: =SUM(G15:G16) -> 159.434 | H17: =SUM(H15:H16) -> -47.043 | I17: =SUM(I15:I16) -> 36.335 | J17: =SUM(J15:J16) -> 90.733 | K17: =SUM(K15:K16) -> 233.179 | ... U17: =SUM(U15:U16) -> 36.793 | Z17: =SUM(Z15:Z16) -> 101.354 | AA17: =SUM(AA15:AA16) -> 134.106 | AB17: =SUM(AB15:AB16) -> 141.389 | AC17: =SUM(AC15:AC16) -> 168.907 | AD17: =SUM(AD15:AD16) -> 207.95 | AE17: =SUM(AE15:AE16) -> 356.005 | AF17: =SUM(AF15:AF16) -> 384.443 | AG17: =SUM(AG15:AG16) -> 249 | ... AT17: =SUM(AT15:AT16) -> 864.29546 | AU17: =AT17*(1+$AW$21) -> 855.6525 | AV17: =AU17*(1+$AW$21) -> 847.09598 | AW17: =AV17*(1+$AW$21) -> 838.62502 | AX17: =AW17*(1+$AW$21) -> 830.23877 | AY17: =AX17*(1+$AW$21) -> 821.93638 | AZ17: =AY17*(1+$AW$21) -> 813.71702 | BA17: =AZ17*(1+$AW$21) -> 805.57985 | BB17: =BA17*(1+$AW$21) -> 797.52405 | ... EC17: =EB17*(1+$AW$21) -> 360.51568
C18: Shares | D18: 40.645162 | E18: 40.645162 | F18: 40.645162 | G18: 40.645162 | H18: 40.645162 | I18: 40.645162 | J18: 40.645162 | K18: 40.645162 | L18: 40.645162 | M18: 40.645162 | N18: 40.645162 | O18: 40.645162 | P18: 40.645162 | Q18: 40.645162 | R18: 40.645162 | S18: 40.645162 | T18: 40.645162 | U18: 40.645162 | Z18: 40.645162 | AA18: 40.645162 | AB18: 40.645162 | AC18: 40.645162 | AD18: 40.645162 | AE18: 40.645162 | AF18: 40.645162 | AG18: 40.645162 | AH18: 40.645162 | AI18: 40.645162 | AJ18: 40.645162 | AK18: 40.645162 | AL18: 40.645162 | AM18: 40.645162 | AN18: 40.645162 | AO18: 40.645162 | AP18: 40.645162 | AQ18: 40.645162 | AR18: 40.645162 | AS18: 40.645162 | AT18: 40.645162
C19: EPS | D19: =D17/D18 -> 0.22342142 | E19: =E17/E18 -> 1.2773476 | F19: =F17/F18 -> 0.73346983 | G19: =G17/G18 -> 3.9225825 | H19: =H17/H18 -> -1.1574071 | I19: =I17/I18 -> 0.89395633 | J19: =J17/J18 -> 2.2323198 | K19: =K17/K18 -> 5.7369436 | ... U19: =U17/U18 -> 0.90522459 | Z19: =Z17/Z18 -> 2.4936301 | AA19: =AA17/AA18 -> 3.2994333 | AB19: =AB17/AB18 -> 3.4786182 | AC19: =AC17/AC18 -> 4.1556483 | AD19: =AD17/AD18 -> 5.1162301 | AE19: =AE17/AE18 -> 8.758853 | AF19: =AF17/AF18 -> 9.4585181 | AG19: =AG17/AG18 -> 6.1261904 | ... AT19: =AT17/AT18 -> 21.264412
AV20: Discount | AW20: 0.08
C21: Revenue y/y | H21: =(H6-D6)/D6 -> -0.00012547486 | I21: =(I6-E6)/E6 -> -0.0093509794 | J21: =(J6-F6)/F6 -> 0.12962777 | K21: =(K6-G6)/G6 -> 0.13012058 | L21: =(L6-H6)/H6 -> 0.15062341 | M21: =(M6-I6)/I6 -> 0.10260128 | N21: =(N6-J6)/J6 -> 0.067664094 | O21: =(O6-K6)/K6 -> 0.12010894 | ... U21: =(U6-Q6)/Q6 -> 0.071455054 | AA21: =(AA6-Z6)/Z6 -> 0.088926675 | AB21: =(AB6-AA6)/AA6 -> 0.067007222 | AC21: =(AC6-AB6)/AB6 -> 0.061289464 | AD21: =(AD6-AC6)/AC6 -> 0.59787058 | AE21: =(AE6-AD6)/AD6 -> 0.27816891 | AF21: =(AF6-AE6)/AE6 -> 0.036992142 | AG21: =(AG6-AF6)/AF6 -> 0.024751086 | AH21: =(AH6-AG6)/AG6 -> 0.073178392 | ... AT21: =(AT6-AS6)/AS6 -> 0.065 | AV21: TV | AW21: -0.01
C22: Like-for-like y/y | D22: 0.073 | E22: 0.056 | F22: -0.004 | G22: 0.018 | H22: -0.003 | I22: -0.033 | J22: 0.129 | K22: 0.093 | L22: 0.135 | M22: 0.092 | N22: 0.03 | O22: 0.101 | P22: 0.029 | Q22: 0.046 | R22: -0.017 | S22: 0.008 | T22: 0.061 | U22: 0.083 | AJ22: 0.014 | AV22: NPV | AW22: =NPV(AW20,AJ17:EC17) -> 7657.5357
C23: Opex y/y | H23: =((H9+H11)-(D9+D11))/(D9+D11) -> 0.087537924 | I23: =((I9+I11)-(E9+E11))/(E9+E11) -> 0.045828144 | J23: =((J9+J11)-(F9+F11))/(F9+F11) -> 0.032986652 | K23: =((K9+K11)-(G9+G11))/(G9+G11) -> 0.12223918 | L23: =((L9+L11)-(H9+H11))/(H9+H11) -> 0.07556571 | M23: =((M9+M11)-(I9+I11))/(I9+I11) -> 0.069037598 | N23: =((N9+N11)-(J9+J11))/(J9+J11) -> 0.14561866 | O23: =((O9+O11)-(K9+K11))/(K9+K11) -> 0.051475597 | ... U23: =((U9+U11)-(Q9+Q11))/(Q9+Q11) -> 0.053630823 | AA23: =((AA9+AA11)-(Z9+Z11))/(Z9+Z11) -> 0.04538005 | AB23: =((AB9+AB11)-(AA9+AA11))/(AA9+AA11) -> 0.070812916 | AC23: =((AC9+AC11)-(AB9+AB11))/(AB9+AB11) -> 0.037796665 | AD23: =((AD9+AD11)-(AC9+AC11))/(AC9+AC11) -> 0.32319756 | AE23: =((AE9+AE11)-(AD9+AD11))/(AD9+AD11) -> 0.2443759 | AF23: =((AF9+AF11)-(AE9+AE11))/(AE9+AE11) -> 0.0096822987 | AG23: =((AG9+AG11)-(AF9+AF11))/(AF9+AF11) -> 0.059783371 | AH23: =((AH9+AH11)-(AG9+AG11))/(AG9+AG11) -> 0.074955908 | ... AT23: =((AT9+AT11)-(AS9+AS11))/(AS9+AS11) -> 0.055 | AV23: S/O | AW23: 40.645162
C24: Gross margin | D24: =D8/D6 -> 0.61284235 | E24: =E8/E6 -> 0.6008691 | F24: =F8/F6 -> 0.55616592 | G24: =G8/G6 -> 0.56932844 | H24: =H8/H6 -> 0.56045593 | I24: =I8/I6 -> 0.6222812 | J24: =J8/J6 -> 0.62121953 | K24: =K8/K6 -> 0.63407964 | ... U24: =U8/U6 -> 0.63369884 | Z24: =Z8/Z6 -> 0.58646184 | AA24: =AA8/AA6 -> 0.60224911 | AB24: =AB8/AB6 -> 0.60384116 | AC24: =AC8/AC6 -> 0.60926748 | AD24: =AD8/AD6 -> 0.60512162 | AE24: =AE8/AE6 -> 0.62853232 | AF24: =AF8/AF6 -> 0.62682003 | AG24: =AG8/AG6 -> 0.58165829 | ... AT24: =AT8/AT6 -> 0.62 | AV24: NPV/Share | AW24: =AW22/AW23 -> 188.39969
C25: EBIT margin | D25: =D12/D6 -> 0.03985643 | E25: =E12/E6 -> 0.10897314 | F25: =F12/F6 -> 0.076831692 | G25: =G12/G6 -> 0.18893155 | H25: =H12/H6 -> -0.065349235 | I25: =I12/I6 -> 0.09055634 | J25: =J12/J6 -> 0.16786758 | K25: =K12/K6 -> 0.25026362 | ... U25: =U12/U6 -> 0.085273241 | Z25: =Z12/Z6 -> 0.10023594 | AA25: =AA12/AA6 -> 0.13284581 | AB25: =AB12/AB6 -> 0.12998882 | AC25: =AC12/AC6 -> 0.14532894 | AD25: =AD12/AD6 -> 0.12878405 | AE25: =AE12/AE6 -> 0.16107959 | AF25: =AF12/AF6 -> 0.17417679 | AG25: =AG12/AG6 -> 0.11620603 | ... AT25: =AT12/AT6 -> 0.16610108 | AV25: Opp/nedside | AW25: =(AW24-B4)/B4 -> 0.5966075
C26: ROE | Z26: =Z17/938.411 -> 0.10800598 | AA26: =AA17/1002 -> 0.13383832 | AB26: =AB17/1018 -> 0.138889 | AC26: =AC17/1090 -> 0.15496055 | AD26: =AD17/1150 -> 0.18082609 | AE26: =AE17/1184 -> 0.3006799 | AF26: =AF17/1262 -> 0.30462995 | AG26: 0.1954 | AH26: 0.238 | AI26: 0.2592 | AJ26: =AJ17/S53 -> 0.15636161
C28: EBITDA | P28: 115.3 | Q28: 189 | R28: 205 | S28: 440 | T28: 132.7 | U28: 218 | Z28: 174.038 | AA28: 201.063 | AB28: 214.528 | AC28: 250.206 | AD28: 566.949 | AE28: 823.57 | AF28: 877.567 | AG28: 717.521 | AH28: 884.493 | AI28: 1026 | AJ28: 949.094 | AK28: =AK12-AK10 -> 1105.8872 | AL28: =AL12-AL10 -> 1193.0242 | AM28: =AM12-AM10 -> 1286.664 | AN28: =AN12-AN10 -> 1387.2756 | AO28: =AO12-AO10 -> 1495.3607 | AP28: =AP12-AP10 -> 1611.4566 | AQ28: =AQ12-AQ10 -> 1736.138 | AR28: =AR12-AR10 -> 1870.0203 | ... AT28: =AT12-AT10 -> 2168.0668
C29: EBITDA margin | D29: =D28/D6 -> 0 | E29: =E28/E6 -> 0 | F29: =F28/F6 -> 0 | G29: =G28/G6 -> 0 | H29: =H28/H6 -> 0 | I29: =I28/I6 -> 0 | J29: =J28/J6 -> 0 | K29: =K28/K6 -> 0 | ... U29: =U28/U6 -> 0.23721772 | Z29: =Z28/Z6 -> 0.14628324 | AA29: =AA28/AA6 -> 0.15519725 | AB29: =AB28/AB6 -> 0.1551917 | AC29: =AC28/AC6 -> 0.17054868 | AD29: =AD28/AD6 -> 0.24185387 | AE29: =AE28/AE6 -> 0.27486618 | AF29: =AF28/AF6 -> 0.28243962 | AG29: =AG28/AG6 -> 0.22535207 | ... AT29: =AT28/AT6 -> 0.28983089
C30: EBITDA LTM | G30: =SUM(D28:G28) -> 0 | H30: =SUM(E28:H28) -> 0 | I30: =SUM(F28:I28) -> 0 | J30: =SUM(G28:J28) -> 0 | K30: =SUM(H28:K28) -> 0 | L30: =SUM(I28:L28) -> 0 | M30: =SUM(J28:M28) -> 0 | N30: =SUM(K28:N28) -> 0 | ... U30: =SUM(R28:U28) -> 995.7
C32: Share of online sales | Q32: 0.122 | U32: 0.159
C34: Balanse NOK million
C35: Goodwill | D35: 65 | E35: 67 | F35: 67 | G35: 65 | H35: 69.957 | I35: 68.662 | J35: 68 | K35: 70 | L35: 70.328 | M35: 69.5 | N35: 72.115 | O35: 71.298 | P35: 73 | Q35: 73.542 | R35: 73.466 | S35: 75.807 | T35: 70.972 | U35: 70.671 | Z35: 0 | AA35: 0 | AB35: 0 | AC35: 0 | AD35: 65.402 | AE35: 72.28 | AF35: 70.286 | AG35: 65 | AH35: 70 | AI35: 71.298 | AJ35: 75.807
C36: Trademark | D36: 1509.9 | E36: 1511 | F36: 1511.6 | G36: 1510 | H36: 1513.696 | I36: 1512.694 | J36: 1511.8 | K36: 1513.851 | L36: 1513.974 | M36: 1513.331 | N36: 1515.356 | O36: 1514.724 | P36: 1515.94 | Q36: 1516.46 | R36: 1516.401 | S36: 1518.211 | T36: 1514.472 | U36: 1514.204 | Z36: 1459.585 | AA36: 1463.023 | AB36: 1462.354 | AC36: 1459.585 | AD36: 1510.145 | AE36: 1515.485 | AF36: 1511.788 | AG36: 1510 | AH36: 1513.851 | AI36: 1514.724 | AJ36: 1518.211
C37: Other intang assets | D37: 21 | E37: 22 | F37: 24.5 | G37: 35 | H37: 34.656 | I37: 34.504 | J37: 42.6 | K37: 46.7 | L37: 46.276 | M37: 45.226 | N37: 44.775 | O37: 54.934 | P37: 57.128 | Q37: 63.752 | R37: 69.399 | S37: 81.837 | T37: 84.65 | U37: 86.542 | Z37: 0 | AA37: 0 | AB37: 8.423 | AC37: 9.835 | AD37: 10.085 | AE37: 5.623 | AF37: 19.096 | AG37: 35 | AH37: 46.7 | AI37: 54.934 | AJ37: 81.837
C38: Deferred tax assets | D38: 9.6 | E38: 6 | F38: 0 | G38: 2 | H38: 17.45 | I38: 0 | J38: 0 | K38: 7 | L38: 6.562 | M38: 9.232 | N38: 6.111 | O38: 0 | P38: 0 | Q38: 13.406 | R38: 0 | S38: 0 | T38: 7.638 | U38: 0 | Z38: 0 | AA38: 0 | AB38: 0 | AC38: 0 | AD38: 2.185 | AE38: 15.81 | AF38: 22.968 | AG38: 2 | AH38: 7 | AI38: 0 | AJ38: 0
C39: Right of use assets | D39: 737.7 | E39: 777 | F39: 795.4 | G39: 761 | H39: 1067.142 | I39: 1042.467 | J39: 1039.5 | K39: 1050 | L39: 1182.535 | M39: 1199.167 | N39: 1181.866 | O39: 1198.955 | P39: 1212.168 | Q39: 1337.115 | R39: 1313.81 | S39: 1311.38 | T39: 1358.203 | U39: 1275.642 | Z39: 0 | AA39: 0 | AB39: 0 | AC39: 0 | AD39: 796.5 | AE39: 778.4 | AF39: 732.3 | AG39: 761 | AH39: 1050 | AI39: 1198.955 | AJ39: 1311.38
C40: Fixture and fittings, tools. Office machins | D40: 194.3 | E40: 200 | F40: 202 | G40: 237 | H40: 274.966 | I40: 308.316 | J40: 299.6 | K40: 303 | L40: 319.111 | M40: 328.862 | N40: 336.955 | O40: 383.495 | P40: 387.445 | Q40: 449.438 | R40: 454.703 | S40: 487.194 | T40: 476.535 | U40: 486.349 | Z40: 86.081 | AA40: 88.492 | AB40: 91.896 | AC40: 91.53 | AD40: 205.338 | AE40: 242.795 | AF40: 227.799 | AG40: 237 | AH40: 303 | AI40: 383.495 | AJ40: 487.194
C41: Investments in JV | D41: 0 | E41: 0 | F41: 0 | G41: 0 | H41: 0 | I41: 0 | J41: 0 | K41: 1 | L41: 0.424 | M41: 0 | N41: 0 | O41: 34.331 | P41: 1.214 | Q41: 4.366 | R41: 4 | S41: 4.375 | T41: 4.145 | U41: 3.106 | Z41: 0 | AA41: 0 | AB41: 0 | AC41: 0 | AD41: 0 | AE41: 0 | AF41: 0.03 | AG41: 0 | AH41: 1 | AI41: 34.331 | AJ41: 4.375
C42: Loans to assosciated JV | D42: 22.5 | E42: 31 | F42: 23 | G42: 24 | H42: 35.8 | I42: 37.024 | J42: 37.5 | K42: 51 | L42: 51.476 | M42: 70 | N42: 71.074 | O42: 0 | P42: 0 | Q42: 0 | R42: 0 | S42: 0 | T42: 0.5 | U42: 0.5 | Z42: 0 | AA42: 0 | AB42: 0 | AC42: 0 | AD42: 0 | AE42: 0 | AF42: 0 | AG42: 24 | AH42: 51 | AI42: 0 | AJ42: 0
C43: Inventories | D43: 722.188 | E43: 779.6 | F43: 876.5 | G43: 669 | H43: 672.806 | I43: 666.049 | J43: 728.7 | K43: 576 | L43: 700 | M43: 759.889 | N43: 930.785 | O43: 775.911 | P43: 865.751 | Q43: 833.415 | R43: 992.259 | S43: 934.484 | T43: 972.059 | U43: 911.421 | Z43: 215.211 | AA43: 222.19 | AB43: 301.997 | AC43: 253.157 | AD43: 484.988 | AE43: 482.161 | AF43: 646.764 | AG43: 669 | AH43: 576 | AI43: 775.911 | AJ43: 934.484
C44: Trade receivables | D44: 16 | E44: 21 | F44: 16 | G44: 12 | H44: 15.3322 | I44: 32.841 | J44: 10.1 | K44: 33 | L44: 25.876 | M44: 27.274 | N44: 25.708 | O44: 31.511 | P44: 43.704 | Q44: 37.754 | R44: 27.991 | S44: 27.415 | T44: 35.845 | U44: 29.951 | Z44: 2.996 | AA44: 2.527 | AB44: 3.5 | AC44: 2.962 | AD44: 23.201 | AE44: 18.381 | AF44: 21.999 | AG44: 12 | AH44: 33 | AI44: 31.511 | AJ44: 27.415
C45: Other receivables | D45: 35.3 | E45: 31 | F45: 33 | G45: 35 | H45: 16.495 | I45: 50.141 | J45: 27 | K45: 43 | L45: 41.943 | M45: 41.421 | N45: 31.038 | O45: 52.794 | P45: 64.26 | Q45: 84 | R45: 85.8 | S45: 113.864 | T45: 91.168 | U45: 96.322 | Z45: 23.322 | AA45: 26.435 | AB45: 28.506 | AC45: 24.823 | AD45: 25.815 | AE45: 32.725 | AF45: 25.023 | AG45: 35 | AH45: 43 | AI45: 52.794 | AJ45: 113.864
...

Sheet Segment
B4: NOKm | C4: Q122 | D4: Q222 | E4: Q322 | F4: Q422 | G4: 2022 | H4: Q123 | I4: Q223 | J4: Q323 | K4: Q423 | L4: 2023 | M4: Q124 | N4: Q224 | O4: Q324 | P4: Q424 | Q4: 2024 | R4: Q125 | S4: Q225 | T4: Q325 | U4: Q425 | V4: 2025 | W4: Q126 | X4: Q226 | Y4: Q326 | Z4: Q426 | AA4: 2026
B5: Kid interiør
B6: Revenue | C6: 366.8 | D6: 455.5 | E6: 457.9 | F6: 703.4 | G6: =SUM(C6:F6) -> 1983.6 | H6: 385.9 | I6: 450.7 | J6: 517.8 | K6: 768.5 | L6: =SUM(H6:K6) -> 2122.9 | M6: 437.7 | N6: 500.4 | O6: 562.9 | P6: 836.4 | Q6: =SUM(M6:P6) -> 2337.4 | R6: 452.4 | S6: 535.9 | T6: 573.6 | U6: 873.6 | V6: =SUM(R6:U6) -> 2435.5 | W6: 492.7 | X6: 574.3 | AA6: =SUM(W6:Z6) -> 1067
B7: Growth % | C7: 0.125 | D7: 0.089 | E7: 0.014 | F7: 0.023 | H7: 0.052 | I7: -0.011 | J7: 0.131 | K7: 0.093 | L7: =(L6-G6)/G6 -> 0.070225852 | M7: 0.134 | N7: 0.11 | O7: 0.087 | P7: 0.088 | Q7: =(Q6-L6)/L6 -> 0.10104103 | R7: 0.033 | S7: 0.071 | T7: 0.019 | U7: 0.044 | V7: =(V6-Q6)/Q6 -> 0.04196971 | W7: 0.089 | X7: 0.071 | AA7: =(AA6-V6)/V6 -> -0.56189694
B8: LFL inc online sales | C8: 0.107 | D8: 0.058 | E8: -0.01 | F8: 0.009 | G8: =AVERAGE(C8:F8) -> 0.041 | H8: 0.035 | I8: -0.02 | J8: 0.127 | K8: 0.085 | L8: =AVERAGE(H8:K8) -> 0.05675 | M8: 0.127 | N8: 0.095 | O8: 0.07 | P8: 0.067 | Q8: =AVERAGE(M8:P8) -> 0.08975 | R8: 0.018 | S8: 0.057 | T8: 0.005 | U8: 0.04 | V8: 0.031 | W8: 0.074 | X8: 0.067
B9: Gross profit | C9: 225 | D9: 273.3 | E9: 248.6 | F9: 408.7 | G9: =SUM(C9:F9) -> 1155.6 | H9: 213.7 | I9: 284.3 | J9: 325.3 | K9: 503.3 | L9: =SUM(H9:K9) -> 1326.6 | M9: 269.4 | N9: 316.6 | O9: 346.5 | P9: 512.6 | Q9: =SUM(M9:P9) -> 1445.1 | R9: 274.3 | S9: 334.2 | T9: 353.6 | U9: 528.2 | V9: =SUM(R9:U9) -> 1490.3 | W9: 299 | X9: 361.6 | AA9: =SUM(W9:Z9) -> 660.6
B10: Gross margin % | C10: 0.614 | D10: 0.6 | E10: 0.543 | F10: 0.581 | G10: =G9/G6 -> 0.58257713 | H10: 0.554 | I10: 0.631 | J10: 0.628 | K10: 0.655 | L10: =L9/L6 -> 0.6248999 | M10: 0.615 | N10: 0.633 | O10: 0.616 | P10: 0.613 | Q10: =Q9/Q6 -> 0.61825105 | R10: =R9/R6 -> 0.60632184 | S10: =S9/S6 -> 0.62362381 | T10: =T9/T6 -> 0.61645746 | U10: =U9/U6 -> 0.60462454 | V10: =V9/V6 -> 0.61190721 | W10: =W9/W6 -> 0.60686016 | X10: =X9/X6 -> 0.62963608 | ... AA10: =AA9/AA6 -> 0.61911903
B11: EBITDA | C11: 75.9 | D11: 118.1 | E11: 95.8 | F11: 208 | G11: =SUM(C11:F11) -> 497.8 | H11: 52 | I11: 121.2 | J11: 166.9 | K11: 275.4 | L11: =SUM(H11:K11) -> 615.5 | M11: 91.6 | N11: 146 | O11: 159.9 | P11: 287.9 | Q11: =SUM(M11:P11) -> 685.4 | R11: 81.8 | S11: 132.8 | T11: 145.5 | U11: 266 | V11: =SUM(R11:U11) -> 626.1 | W11: 91 | X11: 151.9 | AA11: =SUM(W11:Z11) -> 242.9
B12: EBITDA % | C12: 0.207 | D12: 0.259 | E12: 0.209 | F12: 0.296 | G12: =G11/G6 -> 0.25095785 | H12: 0.135 | I12: 0.269 | J12: 0.322 | K12: 0.358 | L12: =L11/L6 -> 0.28993358 | M12: 0.109 | N12: 0.292 | O12: 0.284 | P12: 0.344 | Q12: =Q11/Q6 -> 0.2932318 | R12: =R11/R6 -> 0.18081344 | S12: =S11/S6 -> 0.24780743 | T12: =T11/T6 -> 0.25366109 | U12: =U11/U6 -> 0.30448718 | V12: =V11/V6 -> 0.25707247 | W12: =W11/W6 -> 0.18469657 | X12: =X11/X6 -> 0.26449591 | Y12: =Y11/Y6 -> #DIV/0! | Z12: =Z11/Z8 -> #DIV/0! | AA12: =AA11/AA6 -> 0.22764761
B13: Shopping days | C13: 76 | D13: 72 | E13: 79 | F13: 81 | G13: =SUM(C13:F13) -> 308 | H13: 77 | I13: 71 | J13: 79 | K13: 79 | L13: =SUM(H13:K13) -> 306 | M13: 75 | N13: 73 | O13: 79 | P13: 80 | Q13: =SUM(M13:P13) -> 307 | R13: 76 | S13: 71 | T13: 79 | U13: 80 | V13: =SUM(R13:U13) -> 306 | W13: 76 | X13: 72 | AA13: =SUM(W13:Z13) -> 148
B14: Physical stores | C14: 153 | D14: 155 | E14: 155 | F14: 156 | G14: 156 | H14: 155 | I14: 156 | J14: 156 | K14: 157 | L14: 157 | M14: 157 | N14: 158 | O14: 158 | P14: 158 | Q14: 158 | R14: 158 | S14: 159 | T14: 159 | U14: 160 | V14: 160 | W14: 162 | X14: 161
B15: Hemtex
B16: Revenue | C16: 237.8 | D16: 274.6 | E16: 276.8 | F16: 405.2 | G16: =SUM(C16:F16) -> 1194.4 | H16: 219.5 | I16: 273.4 | J16: 313.1 | K16: 484.7 | L16: =SUM(H16:K16) -> 1290.7 | M16: 258.8 | N16: 297.4 | O16: 324 | P16: 567.3 | Q16: =SUM(M16:P16) -> 1447.5 | R16: 281.3 | S16: 320.4 | T16: 309.6 | U16: 579 | V16: =SUM(R16:U16) -> 1490.3 | W16: 307.8 | X16: 338.3 | AA16: =SUM(W16:Z16) -> 646.1
B17: Growth % | C17: 0.048 | D17: 0.088 | E17: -0.01 | F17: 0.017 | H17: -0.109 | I17: -0.048 | J17: 0.105 | K17: 0.119 | L17: =(L16-G16)/G16 -> 0.080626256 | M17: 0.143 | N17: 0.099 | O17: -0.023 | P17: 0.167 | Q17: =(Q16-L16)/L16 -> 0.12148447 | R17: 0.061 | S17: 0.017 | T17: -0.018 | U17: -0.026 | V17: =(V16-Q16)/Q16 -> 0.029568221 | W17: 0.066 | X17: 0.125 | AA17: =(AA16-V16)/V16 -> -0.56646313
B18: LFL inc online sales | C18: 0.02 | D18: 0.052 | E18: 0.008 | F18: 0.035 | G18: =AVERAGE(C18:F18) -> 0.02875 | H18: -0.065 | I18: -0.054 | J18: 0.133 | K18: 0.107 | L18: =AVERAGE(H18:K18) -> 0.03025 | M18: 0.149 | N18: 0.087 | O18: -0.035 | P18: 0.157 | Q18: =AVERAGE(M18:P18) -> 0.0895 | R18: 0.047 | S18: 0.027 | T18: -0.053 | U18: -0.038 | V18: =AVERAGE(R18:U18) -> -0.00425 | W18: 0.04 | X18: 0.114
B19: Gross profit | C19: 145.1 | D19: 164.7 | E19: 159.2 | F19: 221.8 | G19: =SUM(C19:F19) -> 690.8 | H19: 125.5 | I19: 166 | J19: 190.4 | K19: 290.8 | L19: =SUM(H19:K19) -> 772.7 | M19: 158.9 | N19: 187.8 | O19: 204.1 | P19: 290.8 | Q19: =SUM(M19:P19) -> 841.6 | R19: 170 | S19: 199.6 | T19: 203.7 | U19: 360.7 | V19: =SUM(R19:U19) -> 934 | W19: 190.6 | X19: 216.5 | AA19: =SUM(W19:Z19) -> 407.1
B20: Gross margin % | C20: 0.61 | D20: 0.6 | E20: 0.575 | F20: 0.547 | G20: =G19/G16 -> 0.57836571 | H20: 0.572 | I20: 0.607 | J20: 0.608 | K20: 0.6 | L20: =L19/L16 -> 0.59866739 | M20: 0.614 | N20: 0.632 | O20: 0.63 | P20: 0.6 | Q20: =Q19/Q16 -> 0.58141623 | R20: =R19/R16 -> 0.60433701 | S20: =S19/S16 -> 0.62297129 | T20: =T19/T16 -> 0.65794574 | U20: =U19/U16 -> 0.62297064 | V20: =V19/V16 -> 0.62671945 | W20: =W19/W16 -> 0.61923327 | X20: =X19/X16 -> 0.63996453 | ... AA20: =AA19/AA16 -> 0.63008822
B21: EBITDA | C21: 34.5 | D21: 49.6 | E21: 46.9 | F21: 88.8 | G21: =SUM(C21:F21) -> 219.8 | H21: 4.6 | I21: 45.4 | J21: 74.5 | K21: 144.5 | L21: =SUM(H21:K21) -> 269 | M21: 33 | N21: 55.5 | O21: 76.5 | P21: 144.5 | Q21: =SUM(M21:P21) -> 309.5 | R21: 33.6 | S21: 56.3 | T21: 59.2 | U21: 174 | V21: =SUM(R21:U21) -> 323.1 | W21: 41.7 | X21: 65.9 | AA21: =SUM(W21:Z21) -> 107.6
B22: EBITDA % | C22: 0.145 | D22: 0.179 | E22: 0.168 | F22: 0.218 | G22: =G21/G16 -> 0.18402545 | H22: 0.021 | I22: 0.166 | J22: 0.237 | K22: 0.297 | L22: =L21/L16 -> 0.20841404 | M22: 0.127 | N22: 0.186 | O22: 0.235 | P22: 0.311 | Q22: =Q21/Q16 -> 0.21381693 | R22: =R21/R16 -> 0.11944543 | S22: =S21/S16 -> 0.17571785 | T22: =T21/T16 -> 0.19121447 | U22: =U21/U16 -> 0.30051813 | V22: =V21/V16 -> 0.21680199 | W22: =W21/W16 -> 0.13547758 | X22: =X21/X16 -> 0.19479752 | ... AA22: =AA21/AA16 -> 0.16653769
B23: Shopping days | C23: 89 | D23: 90 | E23: 92 | F23: 91 | G23: =SUM(C23:F23) -> 362 | H23: 89 | I23: 90 | J23: 92 | K23: 91 | L23: =SUM(H23:K23) -> 362 | M23: 90 | N23: 90 | O23: 92 | P23: 91 | Q23: =SUM(M23:P23) -> 363 | R23: 89 | S23: 90 | T23: 92 | U23: 91 | V23: =SUM(R23:U23) -> 362 | W23: 89 | X23: 90 | AA23: =SUM(W23:Z23) -> 179
B24: Physical stores | C24: 119 | D24: 118 | E24: 117 | F24: 119 | G24: 156 | H24: 118 | I24: 117 | J24: 117 | K24: 119 | L24: 119 | M24: 118 | N24: 117 | O24: 117 | P24: 119 | Q24: 119 | R24: 131 | S24: 123 | T24: 123 | U24: 123 | V24: 123 | W24: 124 | X24: 122 | AA24: 134

Sheet SOTP
A3: 26E EBITDA
A4: =Modell!AK28 -> 1105.8872
C7: SOTP 26E valuation
C9: NOKm
D10: EBITDA 26E | E10: EV/EBITDA (x) | G10: EV | H10: Per share
C11: Kid interiør | D11: 675 | E11: 8 | G11: =D11*E11 -> 5400 | H11: =G11/[1]Modell!$B$5 -> 106.33647
C12: Hemtex | D12: 450 | E12: 7.5 | G12: =D12*E12 -> 3375 | H12: =G12/[1]Modell!$B$5 -> 66.460295
C13: Enterprise value | D13: =SUM(D11:D12) -> 1125 | G13: =SUM(G11:G12) -> 8775 | H13: =SUM(H11:H12) -> 172.79677
C15: Cash | G15: =Modell!B7 -> 0 | H15: =G15 -> 0
C16: Debt | G16: =Modell!B8 -> 1081.209 | H16: =-G16/Modell!B5 -> -26.601173
C17: Equity value | G17: =G13-G16 -> 7693.791 | H17: =SUM(H13:H16) -> 146.19559

Sheet Nøkkeltall
F6: 2026 | G6: 2027 | H6: 2028
E7: EV/EBITDA | F7: =Modell!$B$9/Modell!AK28 -> 5.314591 | G7: =Modell!$B$9/Modell!AL28 -> 4.92642 | H7: =Modell!$B$9/Modell!AM28 -> 4.5678887
E8: EV/EBIT | F8: =Modell!$B$9/Modell!AK12 -> 11.001364 | G8: =Modell!$B$9/Modell!AL12 -> 9.9627143 | H8: =Modell!$B$9/Modell!AM12 -> 9.0364521
E9: P/E | F9: =Modell!$B$4/Modell!AK19 -> 13.765524 | G9: =Modell!$B$4/Modell!AL19 -> 12.343911 | H9: =Modell!$B$4/Modell!AM19 -> 11.09635

Sheet Nedsideberegning
A3: Nedside | D3: FY 2015 | E3: FY 2016 | F3: FY 2017 | G3: FY 2018 | H3: FY 2019 | I3: FY 2020 | J3: FY 2021 | K3: FY 2022 | L3: FY 2023 | M3: FY 2024 | N3: FY 2025 | O3: FY 2026 | P3: FY 2027 | Q3: FY 2028 | R3: FY 2029 | S3: FY 2030 | T3: FY 2031 | U3: FY 2032 | V3: FY 2033 | W3: FY 2034 | X3: FY 2035
A4: Nedside | C4: Revenue | D4: 1188.433 | E4: 1293.932 | F4: 1381.675 | G4: 1466.729 | H4: 2342.18 | I4: 2994.658 | J4: 3097.096 | K4: 3179 | L4: 3413 | M4: 3785 | N4: 3944 | O4: =N4 -> 3944 | P4: =O4 -> 3944 | Q4: =P4 -> 3944 | R4: =Q4 -> 3944 | S4: =R4 -> 3944 | T4: =S4 -> 3944 | U4: =T4 -> 3944 | V4: =U4 -> 3944 | ... X4: =W4 -> 3944
A5: 0 vekst og konstante marginer | C5: other revenue | D5: 1.3 | E5: 1.6 | F5: 0.667 | G5: 0.336 | H5: 2 | I5: 1.6 | J5: 10 | K5: 5 | L5: 4 | M5: 5 | N5: 4 | O5: 0 | P5: =O5*1.065 -> 0 | Q5: =P5*1.065 -> 0 | R5: =Q5*1.065 -> 0 | S5: =R5*1.065 -> 0 | T5: =S5*1.065 -> 0 | U5: =T5*1.065 -> 0 | V5: =U5*1.065 -> 0 | W5: =V5*1.065 -> 0 | X5: =W5*1.065 -> 0
A6: =AA24 -> 83.523579 | C6: Total revenue | D6: =SUM(D4:D5) -> 1189.733 | E6: =SUM(E4:E5) -> 1295.532 | F6: =SUM(F4:F5) -> 1382.342 | G6: =SUM(G4:G5) -> 1467.065 | H6: =SUM(H4:H5) -> 2344.18 | I6: =SUM(I4:I5) -> 2996.258 | J6: =SUM(J4:J5) -> 3107.096 | K6: =SUM(K4:K5) -> 3184 | ... X6: =SUM(X4:X5) -> 3944
A7: =AA25 -> -0.29217306 | C7: Purchased goods/Change in inventory | D7: -492 | E7: -515.299 | F7: -547.627 | G7: -573.23 | H7: =-1019.79+94.124 -> -925.666 | I7: =-1128.69+15.677 -> -1113.013 | J7: -1159.506 | K7: -1332 | L7: -1314 | M7: -1443 | N7: -1520 | O7: =O6*-0.38 -> -1498.72 | P7: =P6*-0.38 -> -1498.72 | Q7: =Q6*-0.38 -> -1498.72 | R7: =R6*-0.38 -> -1498.72 | S7: =S6*-0.38 -> -1498.72 | T7: =T6*-0.38 -> -1498.72 | U7: =U6*-0.38 -> -1498.72 | V7: =V6*-0.38 -> -1498.72 | ... X7: =X6*-0.38 -> -1498.72
C8: Gross profit | D8: =SUM(D6:D7) -> 697.733 | E8: =SUM(E6:E7) -> 780.233 | F8: =SUM(F6:F7) -> 834.715 | G8: =SUM(G6:G7) -> 893.835 | H8: =SUM(H6:H7) -> 1418.514 | I8: =SUM(I6:I7) -> 1883.245 | J8: =SUM(J6:J7) -> 1947.59 | K8: =SUM(K6:K7) -> 1852 | ... X8: =SUM(X6:X7) -> 2445.28
C9: Employee benefits | D9: -271.342 | E9: -289.547 | F9: -306.471 | G9: -310.898 | H9: -503.494 | I9: -607.119 | J9: -617.3 | K9: -630 | L9: -705 | M9: -783 | N9: -792 | O9: =N9*0.98 -> -776.16 | P9: =O9*1 -> -776.16 | Q9: =P9*1 -> -776.16 | R9: =Q9*1 -> -776.16 | S9: =R9*1 -> -776.16 | T9: =S9*1 -> -776.16 | U9: =T9*1 -> -776.16 | V9: =U9*1 -> -776.16 | W9: =V9*1 -> -776.16 | X9: =W9*1 -> -776.16
C10: D/A | D10: -24.447 | E10: -28.953 | F10: -34.839 | G10: -37 | H10: -264.974 | I10: -340.84 | J10: -336.376 | K10: -348 | L10: -404 | M10: -472 | N10: -555 | O10: =N10*0.98 -> -543.9 | P10: =O10*1 -> -543.9 | Q10: =P10*1 -> -543.9 | R10: =Q10*1 -> -543.9 | S10: =R10*1 -> -543.9 | T10: =S10*1 -> -543.9 | U10: =T10*1 -> -543.9 | V10: =U10*1 -> -543.9 | W10: =V10*1 -> -543.9 | X10: =W10*1 -> -543.9
C11: Other opex | D11: -282.69 | E11: -289.627 | F11: -313.716 | G11: -332.73 | H11: -348.153 | I11: -452.65 | J11: -452.73 | K11: -504 | L11: -514 | M11: -537 | N11: -689 | O11: =N11*0.98 -> -675.22 | P11: =O11*1 -> -675.22 | Q11: =P11*1 -> -675.22 | R11: =Q11*1 -> -675.22 | S11: =R11*1 -> -675.22 | T11: =S11*1 -> -675.22 | U11: =T11*1 -> -675.22 | V11: =U11*1 -> -675.22 | W11: =V11*1 -> -675.22 | X11: =W11*1 -> -675.22
C12: Operating profit (EBIT) | D12: =SUM(D8:D11) -> 119.254 | E12: =SUM(E8:E11) -> 172.106 | F12: =SUM(F8:F11) -> 179.689 | G12: =SUM(G8:G11) -> 213.207 | H12: =SUM(H8:H11) -> 301.893 | I12: =SUM(I8:I11) -> 482.636 | J12: =SUM(J8:J11) -> 541.184 | K12: =SUM(K8:K11) -> 370 | ... X12: =SUM(X8:X11) -> 450
C13: Net financial | D13: -20.2 | E13: -12.6 | F13: -12.6 | G13: -12.7 | H13: -40.943 | I13: -28.435 | J13: -56 | K13: -48 | L13: -77 | M13: -90 | N13: -81 | O13: =N13*1.05 -> -85.05 | P13: =O13*1.05 -> -89.3025 | Q13: =P13*1.05 -> -93.767625 | R13: =Q13*1.05 -> -98.456006 | S13: =R13*1.05 -> -103.37881 | T13: =S13*1.05 -> -108.54775 | U13: =T13*1.05 -> -113.97513 | V13: =U13*1.05 -> -119.67389 | ... X13: =W13*1.05 -> -131.94046
C14: Share of JV | D14: 0 | E14: 0 | F14: 0 | G14: 0 | H14: 0 | I14: 0 | J14: 0 | K14: -3 | L14: -1 | M14: 33 | N14: -25 | O14: -2.5 | P14: -2.5 | Q14: -2.5 | R14: -2.5 | S14: -2.5 | T14: -2.5 | U14: -2.5 | V14: -2.5 | W14: -2.5 | X14: -2.5
C15: PTP | D15: =SUM(D12:D14) -> 99.054 | E15: =SUM(E12:E14) -> 159.506 | F15: =SUM(F12:F14) -> 167.089 | G15: =SUM(G12:G14) -> 200.507 | H15: =SUM(H12:H14) -> 260.95 | I15: =SUM(I12:I14) -> 454.201 | J15: =SUM(J12:J14) -> 485.184 | K15: =SUM(K12:K14) -> 319 | ... X15: =SUM(X12:X14) -> 315.55954
C16: Tax | D16: 2.3 | E16: -25.4 | F16: -25.7 | G16: -31.6 | H16: -53 | I16: -98.196 | J16: -100.741 | K16: -70 | L16: -89 | M16: -100 | N16: -59 | O16: =O15*-0.22 -> -79.739 | P16: =P15*-0.22 -> -78.80345 | Q16: =Q15*-0.22 -> -77.821122 | R16: =R15*-0.22 -> -76.789679 | S16: =S15*-0.22 -> -75.706663 | T16: =T15*-0.22 -> -74.569496 | U16: =U15*-0.22 -> -73.37547 | V16: =V15*-0.22 -> -72.121744 | ... X16: =X15*-0.22 -> -69.423098
C17: Net income | D17: =SUM(D15:D16) -> 101.354 | E17: =SUM(E15:E16) -> 134.106 | F17: =SUM(F15:F16) -> 141.389 | G17: =SUM(G15:G16) -> 168.907 | H17: =SUM(H15:H16) -> 207.95 | I17: =SUM(I15:I16) -> 356.005 | J17: =SUM(J15:J16) -> 384.443 | K17: =SUM(K15:K16) -> 249 | ... X17: =SUM(X15:X16) -> 246.13644 | Y17: =X17*(1+$AA$21) -> 248.5978 | Z17: =Y17*(1+$AA$21) -> 251.08378 | AA17: =Z17*(1+$AA$21) -> 253.59462 | AB17: =AA17*(1+$AA$21) -> 256.13056 | AC17: =AB17*(1+$AA$21) -> 258.69187 | AD17: =AC17*(1+$AA$21) -> 261.27879 | AE17: =AD17*(1+$AA$21) -> 263.89158 | AF17: =AE17*(1+$AA$21) -> 266.53049 | ... EU17: =ET17*(1+$AA$21) -> 870.9443
C18: Shares | D18: 40.645162 | E18: 40.645162 | F18: 40.645162 | G18: 40.645162 | H18: 40.645162 | I18: 40.645162 | J18: 40.645162 | K18: 40.645162 | L18: 40.645162 | M18: 40.645162 | N18: 40.645162 | O18: 40.645162 | P18: 40.645162 | Q18: 40.645162 | R18: 40.645162 | S18: 40.645162 | T18: 40.645162 | U18: 40.645162 | V18: 40.645162 | W18: 40.645162 | X18: 40.645162
C19: EPS | D19: =D17/D18 -> 2.4936301 | E19: =E17/E18 -> 3.2994333 | F19: =F17/F18 -> 3.4786182 | G19: =G17/G18 -> 4.1556483 | H19: =H17/H18 -> 5.1162301 | I19: =I17/I18 -> 8.758853 | J19: =J17/J18 -> 9.4585181 | K19: =K17/K18 -> 6.1261904 | ... X19: =X17/X18 -> 6.0557376
Z20: Discount | AA20: 0.08
C21: Revenue y/y | E21: =(E6-D6)/D6 -> 0.088926675 | F21: =(F6-E6)/E6 -> 0.067007222 | G21: =(G6-F6)/F6 -> 0.061289464 | H21: =(H6-G6)/G6 -> 0.59787058 | I21: =(I6-H6)/H6 -> 0.27816891 | J21: =(J6-I6)/I6 -> 0.036992142 | K21: =(K6-J6)/J6 -> 0.024751086 | L21: =(L6-K6)/K6 -> 0.073178392 | ... X21: =(X6-W6)/W6 -> 0 | Z21: TV | AA21: 0.01
C22: Like-for-like y/y | N22: 0.014 | Z22: NPV | AA22: =NPV(AA20,N17:DG17) -> 3394.8294
C23: Opex y/y | E23: =((E9+E10+E11)-(D9+D10+D11))/(D9+D10+D11) -> 0.051251644 | F23: =((F9+F10+F11)-(E9+E10+E11))/(E9+E10+E11) -> 0.077120404 | G23: =((G9+G10+G11)-(F9+F10+F11))/(F9+F10+F11) -> 0.039085471 | H23: =((H9+H10+H11)-(G9+G10+G11))/(G9+G10+G11) -> 0.64057459 | I23: =((I9+I10+I11)-(H9+H10+H11))/(H9+H10+H11) -> 0.25432801 | J23: =((J9+J10+J11)-(I9+I10+I11))/(I9+I10+I11) -> 0.0041389139 | K23: =((K9+K10+K11)-(J9+J10+J11))/(J9+J10+J11) -> 0.053749771 | L23: =((L9+L10+L11)-(K9+K10+K11))/(K9+K10+K11) -> 0.0951417 | ... X23: =((X9+X10+X11)-(W9+W10+W11))/(W9+W10+W11) -> 0 | Z23: S/O | AA23: 40.645162
C24: Gross margin | D24: =D8/D6 -> 0.58646184 | E24: =E8/E6 -> 0.60224911 | F24: =F8/F6 -> 0.60384116 | G24: =G8/G6 -> 0.60926748 | H24: =H8/H6 -> 0.60512162 | I24: =I8/I6 -> 0.62853232 | J24: =J8/J6 -> 0.62682003 | K24: =K8/K6 -> 0.58165829 | ... X24: =X8/X6 -> 0.62 | Z24: NPV/Share | AA24: =AA22/AA23 -> 83.523579
C25: EBIT margin | D25: =D12/D6 -> 0.10023594 | E25: =E12/E6 -> 0.13284581 | F25: =F12/F6 -> 0.12998882 | G25: =G12/G6 -> 0.14532894 | H25: =H12/H6 -> 0.12878405 | I25: =I12/I6 -> 0.16107959 | J25: =J12/J6 -> 0.17417679 | K25: =K12/K6 -> 0.11620603 | ... X25: =X12/X6 -> 0.11409736 | Z25: Opp/nedside | AA25: =(AA24-Modell!B4)/Modell!B4 -> -0.29217306
