Workbook

Sheet Info
A18: Q126
A28: Financial targets:
A29: Sales growth: 15%
A30: Profitiability: EBITA margin 12% | D30: (Virker lite sannsynlig i nærmer fremtid mtp at de har ikke vært der enda)
A34: Press releases:
A35: 29.04.26: CEO Per Wallentin slutter som CEO. Han fortsetter frem til 1 august 2026. Fredrik Ekerhovd vil ta over

Sheet Modell
A3: Kapitalstruktur | C3: SEK million | D3: Q122 | E3: Q222 | F3: Q322 | G3: Q422 | H3: Q123 | I3: Q223 | J3: Q323 | K3: Q423 | L3: Q124 | M3: Q224 | N3: Q324 | O3: Q424 | P3: Q125 | Q3: Q225 | R3: Q325 | S3: Q425 | T3: Q126 | U3: Q226 | V3: Q326 | W3: Q426 | Y3: FY 2015 | Z3: FY 2016 | AA3: FY 2017 | AB3: FY 2018 | AC3: FY 2019 | AD3: FY 2020 | AE3: FY 2021 | AF3: FY 2022 | AG3: FY 2023 | AH3: FY 2024 | AI3: FY 2025 | AJ3: FY 2026 | AK3: FY 2027 | AL3: FY 2028 | AM3: FY 2029 | AN3: FY 2030 | AO3: FY 2031 | AP3: FY 2032 | AQ3: FY 2033 | AR3: FY 2034 | AS3: FY 2035
A4: Price | B4: 88.1 | C4: Revenues | D4: 1970.5 | E4: 1644.7 | F4: 1520.9 | G4: 1972.9 | H4: 1766.3 | I4: 1758.8 | J4: 1560.5 | K4: 1824 | L4: 1766.3 | M4: 1681.3 | N4: 1326 | O4: 1641.9 | P4: 1593.6 | Q4: 1490.5 | R4: 1238.8 | S4: 1492 | T4: 1450 | Y4: 2230 | Z4: 2426.218 | AA4: 2733.501 | AB4: 3083.304 | AC4: 3335 | AD4: 3379 | AE4: 4811.839 | AF4: 6833.746 | AG4: 7113.82 | AH4: 6415.744 | AI4: 5815 | AJ4: =AI4*0.93 -> 5407.95 | AK4: =AJ4*1.05 -> 5678.3475 | AL4: =AK4*1.05 -> 5962.2649 | AM4: =AL4*1.05 -> 6260.3781 | AN4: =AM4*1.05 -> 6573.397 | AO4: =AN4*1.05 -> 6902.0669 | AP4: =AO4*1.05 -> 7247.1702 | AQ4: =AP4*1.05 -> 7609.5287 | AR4: =AQ4*1.05 -> 7990.0052 | AS4: =AR4*1.05 -> 8389.5054
A5: S/O | B5: 27.307 | C5: Operating costs | D5: -1727.5 | E5: -1473.6 | F5: -1393.9 | G5: -1752.6 | H5: -1586.2 | I5: -1637.1 | J5: -1441.8 | K5: -1633 | L5: -1586.2 | M5: -1571.6 | N5: -1224.8 | O5: -1492.5 | P5: -1446 | Q5: -1396.7 | R5: -1119 | S5: -1334.1 | T5: -1324.2 | Y5: =-304-212.543-1537.9 -> -2054.443 | Z5: =-387.311-203.347-1612.596 -> -2203.254 | AA5: =-457.262-216.441-1767.168 -> -2440.871 | AB5: =-512.288-226.87-2017.075 -> -2756.233 | AC5: =-556.803-171.737-2215.079 -> -2943.619 | AD5: =-637.286-168.285-2166.451 -> -2972.022 | AE5: =-987.377-299.714-2963.271 -> -4250.362 | AF5: =-1699.746-425.25-3963.482 -> -6088.478 | AG5: =-1588.977-410.948-4439.502 -> -6439.427 | AH5: =-1241.735-4285.279-348 -> -5875.014 | AI5: -5296 | AJ5: =AJ4*-0.913 -> -4937.4584 | AK5: =AK4*-0.9 -> -5110.5128 | AL5: =AL4*-0.9 -> -5366.0384 | AM5: =AM4*-0.9 -> -5634.3403 | AN5: =AN4*-0.9 -> -5916.0573 | AO5: =AO4*-0.9 -> -6211.8602 | AP5: =AP4*-0.9 -> -6522.4532 | AQ5: =AQ4*-0.9 -> -6848.5759 | AR5: =AR4*-0.9 -> -7191.0047 | AS5: =AS4*-0.9 -> -7550.5549
A6: MC SEKm | B6: =B4*B5 -> 2405.7467 | C6: Gross profit | D6: =SUM(D4:D5) -> 243 | E6: =SUM(E4:E5) -> 171.1 | F6: =SUM(F4:F5) -> 127 | G6: =SUM(G4:G5) -> 220.3 | H6: =SUM(H4:H5) -> 180.1 | I6: =SUM(I4:I5) -> 121.7 | J6: =SUM(J4:J5) -> 118.7 | K6: =SUM(K4:K5) -> 191 | ... T6: =SUM(T4:T5) -> 125.8 | Y6: =SUM(Y4:Y5) -> 175.557 | Z6: =SUM(Z4:Z5) -> 222.964 | AA6: =SUM(AA4:AA5) -> 292.63 | AB6: =SUM(AB4:AB5) -> 327.071 | AC6: =SUM(AC4:AC5) -> 391.381 | AD6: =SUM(AD4:AD5) -> 406.978 | AE6: =SUM(AE4:AE5) -> 561.477 | AF6: =SUM(AF4:AF5) -> 745.268 | ... AS6: =SUM(AS4:AS5) -> 838.95054
A7: Cash SEKm | B7: =T36 -> 409.8 | C7: Dep and write-downs of tangible assets | D7: -45.8 | E7: -34.7 | F7: -37 | G7: -42.3 | H7: -43.9 | I7: -45.1 | J7: -43.9 | K7: -43.3 | L7: -43.9 | M7: -43.8 | N7: -43.5 | O7: -42.8 | P7: -43.1 | Q7: -42.6 | R7: -42.4 | S7: -42.2 | T7: -41.9 | Y7: -28.6 | Z7: -10.58 | AA7: -5.7 | AB7: -6 | AC7: -73.304 | AD7: -73.666 | AE7: -123.572 | AF7: -148.793 | AG7: -178 | AH7: -174 | AI7: -170 | AJ7: =AI7*0.87 -> -147.9 | AK7: =AJ7*1.05 -> -155.295 | AL7: =AK7*1.02 -> -158.4009 | AM7: =AL7*1.02 -> -161.56892 | AN7: =AM7*1.02 -> -164.8003 | AO7: =AN7*1.02 -> -168.0963 | AP7: =AO7*1.02 -> -171.45823 | AQ7: =AP7*1.02 -> -174.88739 | AR7: =AQ7*1.02 -> -178.38514 | AS7: =AR7*1.02 -> -181.95284
A8: Debt SEKm | B8: =T44+T45 -> 748.4 | C8: EBITA | D8: =SUM(D6:D7) -> 197.2 | E8: =SUM(E6:E7) -> 136.4 | F8: =SUM(F6:F7) -> 90 | G8: =SUM(G6:G7) -> 178 | H8: =SUM(H6:H7) -> 136.2 | I8: =SUM(I6:I7) -> 76.6 | J8: =SUM(J6:J7) -> 74.8 | K8: =SUM(K6:K7) -> 147.7 | ... T8: =SUM(T6:T7) -> 83.9 | Y8: =SUM(Y6:Y7) -> 146.957 | Z8: =SUM(Z6:Z7) -> 212.384 | AA8: =SUM(AA6:AA7) -> 286.93 | AB8: =SUM(AB6:AB7) -> 321.071 | AC8: =SUM(AC6:AC7) -> 318.077 | AD8: =SUM(AD6:AD7) -> 333.312 | AE8: =SUM(AE6:AE7) -> 437.905 | AF8: =SUM(AF6:AF7) -> 596.475 | ... AS8: =SUM(AS6:AS7) -> 656.9977
A9: EV SEKm | B9: =B6-B7+B8 -> 2744.3467 | C9: Amort and write-downs on intangible assets | D9: -42.7 | E9: -31.8 | F9: -39.9 | G9: -46.4 | H9: -41.4 | I9: -43.1 | J9: -58.9 | K9: -41.8 | L9: -41.4 | M9: -41.9 | N9: -41.6 | O9: -41.8 | P9: -40.5 | Q9: -40.1 | R9: -41.4 | S9: =-41.1-399 -> -440.1 | T9: -40 | Y9: -11.56 | Z9: -11.8 | AA9: -11.7 | AB9: -11.9 | AC9: -5 | AD9: =-12.301+1.6 -> -10.701 | AE9: -75.247 | AF9: -149.331 | AG9: -186.537 | AH9: -166 | AI9: -562 | AJ9: -160 | AK9: -160 | AL9: -160 | AM9: -160 | AN9: -160 | AO9: -160 | AP9: -160 | AQ9: -160 | AR9: -160 | AS9: -160
C10: Operating income (EBIT) | D10: =SUM(D8:D9) -> 154.5 | E10: =SUM(E8:E9) -> 104.6 | F10: =SUM(F8:F9) -> 50.1 | G10: =SUM(G8:G9) -> 131.6 | H10: =SUM(H8:H9) -> 94.8 | I10: =SUM(I8:I9) -> 33.5 | J10: =SUM(J8:J9) -> 15.9 | K10: =SUM(K8:K9) -> 105.9 | ... T10: =SUM(T8:T9) -> 43.9 | Y10: =SUM(Y8:Y9) -> 135.397 | Z10: =SUM(Z8:Z9) -> 200.584 | AA10: =SUM(AA8:AA9) -> 275.23 | AB10: =SUM(AB8:AB9) -> 309.171 | AC10: =SUM(AC8:AC9) -> 313.077 | AD10: =SUM(AD8:AD9) -> 322.611 | AE10: =SUM(AE8:AE9) -> 362.658 | AF10: =SUM(AF8:AF9) -> 447.144 | ... AS10: =SUM(AS8:AS9) -> 496.9977
C11: Financial income | D11: 4.2 | E11: 66.5 | F11: 16.3 | G11: 11.6 | H11: 3.6 | I11: 23.2 | J11: 34.3 | K11: 14.4 | L11: 3.6 | M11: 3 | N11: 2.8 | O11: 3.8 | P11: 2.5 | Q11: 2.2 | R11: 1.4 | S11: 6.2 | T11: 3.3 | Y11: 1.1 | Z11: 2.5 | AA11: 0.612 | AB11: 0.979 | AC11: 15.518 | AD11: 15.548 | AE11: 20.607 | AF11: 94.963 | AG11: 76 | AH11: 12.56 | AI11: 12 | AJ11: 12 | AK11: 12 | AL11: 12 | AM11: 12 | AN11: 12 | AO11: 12 | AP11: 12 | AQ11: 12 | AR11: 12 | AS11: 12
A12: P/B | B12: =B4/(T42/B5) -> 0.64811733 | C12: Financial expense | D12: -25.4 | E12: -17.9 | F12: -29.2 | G12: -6.5 | H12: -16.3 | I12: -23.6 | J12: -11.5 | K12: -21.3 | L12: -16.3 | M12: -15.1 | N12: -14 | O12: -14.5 | P12: -14.9 | Q12: -9.6 | R12: -10.4 | S12: -11.2 | T12: -8 | Y12: -20.177 | Z12: -11.8 | AA12: -9.8 | AB12: -6.2 | AC12: -15.4 | AD12: -6.369 | AE12: -13.77 | AF12: -58.431 | AG12: -81.725 | AH12: -59.272 | AI12: -46 | AJ12: -45 | AK12: -45 | AL12: -45 | AM12: -45 | AN12: -45 | AO12: -45 | AP12: -45 | AQ12: -45 | AR12: -45 | AS12: -45
C13: PTP | D13: =SUM(D10:D12) -> 133.3 | E13: =SUM(E10:E12) -> 153.2 | F13: =SUM(F10:F12) -> 37.2 | G13: =SUM(G10:G12) -> 136.7 | H13: =SUM(H10:H12) -> 82.1 | I13: =SUM(I10:I12) -> 33.1 | J13: =SUM(J10:J12) -> 38.7 | K13: =SUM(K10:K12) -> 99 | ... T13: =SUM(T10:T12) -> 39.2 | Y13: =SUM(Y10:Y12) -> 116.32 | Z13: =SUM(Z10:Z12) -> 191.284 | AA13: =SUM(AA10:AA12) -> 266.042 | AB13: =SUM(AB10:AB12) -> 303.95 | AC13: =SUM(AC10:AC12) -> 313.195 | AD13: =SUM(AD10:AD12) -> 331.79 | AE13: =SUM(AE10:AE12) -> 369.495 | AF13: =SUM(AF10:AF12) -> 483.676 | ... AS13: =SUM(AS10:AS12) -> 463.9977
C14: Tax | D14: -29.2 | E14: -22.9 | F14: -16 | G14: -17.7 | H14: -18.2 | I14: -13.2 | J14: -12.4 | K14: -7.5 | L14: -18.2 | M14: -6.4 | N14: -1.7 | O14: -16.3 | P14: -12.1 | Q14: -3 | R14: -6.8 | S14: -13.2 | T14: -8.4 | Y14: -24 | Z14: -47.2 | AA14: -64.3 | AB14: -71.7 | AC14: -71.452 | AD14: -74 | AE14: -75.318 | AF14: -91.489 | AG14: -62.293 | AH14: -42.668 | AI14: -35 | AJ14: =AJ13*-0.205 -> -26.566288 | AK14: =AK13*-0.205 -> -45.005649 | AL14: =AL13*-0.205 -> -50.189245 | AM14: =AM13*-0.205 -> -55.651123 | AN14: =AN13*-0.205 -> -61.405578 | AO14: =AO13*-0.205 -> -67.467629 | AP14: =AP13*-0.205 -> -73.853053 | AQ14: =AQ13*-0.205 -> -80.578423 | ... AS14: =AS13*-0.205 -> -95.119528
C15: Net income | D15: =SUM(D13:D14) -> 104.1 | E15: =SUM(E13:E14) -> 130.3 | F15: =SUM(F13:F14) -> 21.2 | G15: =SUM(G13:G14) -> 119 | H15: =SUM(H13:H14) -> 63.9 | I15: =SUM(I13:I14) -> 19.9 | J15: =SUM(J13:J14) -> 26.3 | K15: =SUM(K13:K14) -> 91.5 | ... T15: =SUM(T13:T14) -> 30.8 | Y15: =SUM(Y13:Y14) -> 92.32 | Z15: =SUM(Z13:Z14) -> 144.084 | AA15: =SUM(AA13:AA14) -> 201.742 | AB15: =SUM(AB13:AB14) -> 232.25 | AC15: =SUM(AC13:AC14) -> 241.743 | AD15: =SUM(AD13:AD14) -> 257.79 | AE15: =SUM(AE13:AE14) -> 294.177 | AF15: =SUM(AF13:AF14) -> 392.187 | ... AS15: =SUM(AS13:AS14) -> 368.87817 | AT15: =AS15*(1+$AV$19) -> 365.18939 | AU15: =AT15*(1+$AV$19) -> 361.5375 | AV15: =AU15*(1+$AV$19) -> 357.92212 | AW15: =AV15*(1+$AV$19) -> 354.3429 | AX15: =AW15*(1+$AV$19) -> 350.79947 | AY15: =AX15*(1+$AV$19) -> 347.29148 | AZ15: =AY15*(1+$AV$19) -> 343.81856 | BA15: =AZ15*(1+$AV$19) -> 340.38037 | ... EQ15: =EP15*(1+$AV$19) -> 132.33442
C16: Share | D16: 27.349 | E16: 27.349 | F16: 27.349 | G16: 27.349 | H16: 27.349 | I16: 27.349 | J16: 27.349 | K16: 27.349 | L16: 27.349 | M16: 27.307 | N16: 27.307 | O16: 27.307 | P16: 27.307 | Q16: 27.307 | R16: 27.307 | S16: 27.307 | T16: 27.307 | Y16: 18.389 | Z16: 18.914 | AA16: 19.139 | AB16: 19.253 | AC16: 19.254 | AD16: 19.28 | AE16: 23.726 | AF16: 27.409 | AG16: 27.307 | AH16: 27.307 | AI16: 27.307 | AJ16: 27.307 | AK16: 27.307 | AL16: 27.307 | AM16: 27.307 | AN16: 27.307 | AO16: 27.307 | AP16: 27.307 | AQ16: 27.307 | AR16: 27.307 | AS16: 27.307
C17: EPS | D17: =D15/D16 -> 3.8063549 | E17: =E15/E16 -> 4.7643424 | F17: =F15/F16 -> 0.77516545 | G17: =G15/G16 -> 4.3511646 | H17: =H15/H16 -> 2.3364657 | I17: =I15/I16 -> 0.72763172 | J17: =J15/J16 -> 0.96164394 | K17: =K15/K16 -> 3.3456434 | ... T17: =T15/T16 -> 1.1279159 | Y17: =Y15/Y16 -> 5.0203926 | Z17: =Z15/Z16 -> 7.6178492 | AA17: =AA15/AA16 -> 10.540885 | AB17: =AB15/AB16 -> 12.063055 | AC17: =AC15/AC16 -> 12.555469 | AD17: =AD15/AD16 -> 13.370851 | AE17: =AE15/AE16 -> 12.398929 | AF17: =AF15/AF16 -> 14.308694 | ... AS17: =AS15/AS16 -> 13.508557
AU18: Discount | AV18: 0.08
C19: Revenue y/y | H19: =(H4-D4)/D4 -> -0.10362852 | I19: =(I4-E4)/E4 -> 0.069374354 | J19: =(J4-F4)/F4 -> 0.026037215 | K19: =(K4-G4)/G4 -> -0.075472654 | L19: =(L4-H4)/H4 -> 0 | M19: =(M4-I4)/I4 -> -0.044064135 | N19: =(N4-J4)/J4 -> -0.15027235 | O19: =(O4-K4)/K4 -> -0.099835526 | ... T19: =(T4-P4)/P4 -> -0.090110442 | Z19: =(Z4-Y4)/Y4 -> 0.087990135 | AA19: =(AA4-Z4)/Z4 -> 0.12665103 | AB19: =(AB4-AA4)/AA4 -> 0.12796886 | AC19: =(AC4-AB4)/AB4 -> 0.081631912 | AD19: =(AD4-AC4)/AC4 -> 0.013193403 | AE19: =(AE4-AD4)/AD4 -> 0.42404232 | AF19: =(AF4-AE4)/AE4 -> 0.42019423 | AG19: =(AG4-AF4)/AF4 -> 0.040983964 | ... AS19: =(AS4-AR4)/AR4 -> 0.05 | AU19: TV | AV19: -0.01
C20: Operating costs y/y | H20: =(H5-D5)/D5 -> -0.081794501 | I20: =(I5-E5)/E5 -> 0.11095277 | J20: =(J5-F5)/F5 -> 0.034364015 | K20: =(K5-G5)/G5 -> -0.06824147 | L20: =(L5-H5)/H5 -> 0 | M20: =(M5-I5)/I5 -> -0.040009773 | N20: =(N5-J5)/J5 -> -0.15050631 | O20: =(O5-K5)/K5 -> -0.086037967 | ... T20: =(T5-P5)/P5 -> -0.084232365 | Z20: =(Z5-Y5)/Y5 -> 0.072433745 | AA20: =(AA5-Z5)/Z5 -> 0.10784821 | AB20: =(AB5-AA5)/AA5 -> 0.1292006 | AC20: =(AC5-AB5)/AB5 -> 0.06798627 | AD20: =(AD5-AC5)/AC5 -> 0.0096490069 | AE20: =(AE5-AD5)/AD5 -> 0.43012468 | AF20: =(AF5-AE5)/AE5 -> 0.43246105 | AG20: =(AG5-AF5)/AF5 -> 0.057641499 | ... AS20: =(AS5-AR5)/AR5 -> 0.05 | AU20: NPV | AV20: =NPV(AV18,AI15:EQ15) -> 2925.1885
C21: Gross profit | D21: =D6/D4 -> 0.12331895 | E21: =E6/E4 -> 0.10403113 | F21: =F6/F4 -> 0.083503189 | G21: =G6/G4 -> 0.11166303 | H21: =H6/H4 -> 0.10196456 | I21: =I6/I4 -> 0.069194906 | J21: =J6/J4 -> 0.076065364 | K21: =K6/K4 -> 0.10471491 | ... T21: =T6/T4 -> 0.086758621 | Y21: =Y6/Y4 -> 0.078725112 | Z21: =Z6/Z4 -> 0.09189776 | AA21: =AA6/AA4 -> 0.10705319 | AB21: =AB6/AB4 -> 0.10607809 | AC21: =AC6/AC4 -> 0.11735562 | AD21: =AD6/AD4 -> 0.12044333 | AE21: =AE6/AE4 -> 0.11668657 | AF21: =AF6/AF4 -> 0.10905702 | ... AS21: =AS6/AS4 -> 0.1 | AU21: S/O | AV21: 27.307
C22: EBITA margin | D22: =D8/D4 -> 0.10007612 | E22: =E8/E4 -> 0.082933058 | F22: =F8/F4 -> 0.059175488 | G22: =G8/G4 -> 0.090222515 | H22: =H8/H4 -> 0.077110344 | I22: =I8/I4 -> 0.043552422 | J22: =J8/J4 -> 0.047933355 | K22: =K8/K4 -> 0.080975877 | ... T22: =T8/T4 -> 0.057862069 | Y22: =Y8/Y4 -> 0.0659 | Z22: =Z8/Z4 -> 0.087537064 | AA22: =AA8/AA4 -> 0.10496795 | AB22: =AB8/AB4 -> 0.10413213 | AC22: =AC8/AC4 -> 0.095375412 | AD22: =AD8/AD4 -> 0.098642202 | AE22: =AE8/AE4 -> 0.091005746 | AF22: =AF8/AF4 -> 0.087283753 | ... AS22: =AS8/AS4 -> 0.078311851 | AU22: NPV/Share | AV22: =AV20/AV21 -> 107.1223
C23: EBIT margin | D23: =D10/D4 -> 0.078406496 | E23: =E10/E4 -> 0.063598225 | F23: =F10/F4 -> 0.032941022 | G23: =G10/G4 -> 0.066703837 | H23: =H10/H4 -> 0.053671517 | I23: =I10/I4 -> 0.019047078 | J23: =J10/J4 -> 0.010189042 | K23: =K10/K4 -> 0.058059211 | ... T23: =T10/T4 -> 0.030275862 | Y23: =Y10/Y4 -> 0.060716143 | Z23: =Z10/Z4 -> 0.082673527 | AA23: =AA10/AA4 -> 0.10068773 | AB23: =AB10/AB4 -> 0.10027263 | AC23: =AC10/AC4 -> 0.093876162 | AD23: =AD10/AD4 -> 0.095475289 | AE23: =AE10/AE4 -> 0.075367858 | AF23: =AF10/AF4 -> 0.065431756 | ... AS23: =AS10/AS4 -> 0.059240405 | AU23: Opp-/nedside | AV23: =(AV22-B4)/B4 -> 0.21591709
C24: ROE | Y24: 0.119 | Z24: 0.181 | AA24: 0.225 | AB24: 0.225 | AC24: 0.206 | AD24: 0.185 | AE24: 0.108 | AF24: 0.097 | AG24: 0.058 | AH24: 0.027 | AI24: =AI15/S42 -> -0.077715923
C26: FTE | D26: 3645 | E26: 3933 | F26: 4315 | G26: 4410 | H26: 4377 | I26: 4347 | J26: 4383 | K26: 4265 | L26: 4109 | M26: 3997 | N26: 3941 | O26: 3860 | P26: 3772 | Q26: 3732 | R26: 3774 | S26: 3714 | T26: 3652
C27: y/y | H27: =(H26-D26)/D26 -> 0.20082305 | I27: =(I26-E26)/E26 -> 0.10526316 | J27: =(J26-F26)/F26 -> 0.01575898 | K27: =(K26-G26)/G26 -> -0.032879819 | L27: =(L26-H26)/H26 -> -0.061229152 | M27: =(M26-I26)/I26 -> -0.080515298 | N27: =(N26-J26)/J26 -> -0.10084417 | O27: =(O26-K26)/K26 -> -0.094958968 | ... T27: =(T26-P26)/P26 -> -0.031813362
C28: Q/Q | E28: =(E26-D26)/D26 -> 0.079012346 | F28: =(F26-E26)/E26 -> 0.097126875 | G28: =(G26-F26)/F26 -> 0.022016222 | H28: =(H26-G26)/G26 -> -0.0074829932 | I28: =(I26-H26)/H26 -> -0.0068540096 | J28: =(J26-I26)/I26 -> 0.0082815735 | K28: =(K26-J26)/J26 -> -0.026922199 | L28: =(L26-K26)/K26 -> -0.036576788 | ... T28: =(T26-S26)/S26 -> -0.016693592
C30: Balanse SEKm
C31: Intangible assets | D31: 4585.1 | E31: 4066.5 | F31: 4379.2 | G31: 4629.7 | H31: 4443.1 | I31: 4626.3 | J31: 4528.6 | K31: 4438 | L31: 4443.1 | M31: 4390.4 | N31: 4330.2 | O31: 4313.1 | P31: 4201.1 | Q31: 4070 | R31: 4172.4 | S31: 3705.1 | T31: 3702.7 | Y31: 898.592 | Z31: 915.724 | AA31: 921.443 | AB31: 962.987 | AC31: 983.383 | AD31: 1380.683 | AE31: 3839.52 | AF31: 4629.7 | AG31: 4438 | AH31: 4313.1 | AI31: 3705.1
C32: PP&E | D32: 717.1 | E32: 500 | F32: 504.8 | G32: 723.9 | H32: 605.2 | I32: 680.5 | J32: 652.6 | K32: 619.1 | L32: 601.8 | M32: 594 | N32: 578.1 | O32: 546.6 | P32: 515.4 | Q32: =488.2+189 -> 677.2 | R32: 458.5 | S32: 461.5 | T32: 451.2 | Y32: 43.32 | Z32: 42.307 | AA32: 41.433 | AB32: 42.523 | AC32: 234.294 | AD32: 232.318 | AE32: 290.71 | AF32: 723.9 | AG32: 619.1 | AH32: 546.6 | AI32: 461.5
C33: Financial non-current assets | D33: 10.3 | E33: 6.7 | F33: 10.8 | G33: 11.4 | H33: 3.8 | I33: 10.4 | J33: 9.3 | K33: 7.2 | L33: 7.2 | M33: 3.8 | N33: 3.7 | O33: 7 | P33: 6.9 | Q33: 6.9 | R33: 6.9 | S33: 6.5 | T33: 6.3 | Y33: 1.84 | Z33: 5.551 | AA33: 5.711 | AB33: 5.966 | AC33: 9.001 | AD33: 15.127 | AE33: 17.028 | AF33: 11.4 | AG33: 7.2 | AH33: 7 | AI33: 6.5
C34: Deferred tax assets | D34: 108.1 | E34: 96.8 | F34: 105 | G34: 106.5 | H34: 101.7 | I34: 112.9 | J34: 100.6 | K34: 99.8 | L34: 101.7 | M34: 110.2 | N34: 111.8 | O34: 111.2 | P34: 111 | Q34: 108.7 | R34: 106.2 | S34: 102.3 | T34: 98.9 | Y34: 7.582 | Z34: 5.733 | AA34: 4.698 | AB34: 2.555 | AC34: 2.634 | AD34: 17.911 | AE34: 96.763 | AF34: 106.5 | AG34: 99.8 | AH34: 111.2 | AI34: 102.3
C35: Current receivables | D35: 1682.6 | E35: 1470.5 | F35: 1586.2 | G35: 1636.5 | H35: 1847.1 | I35: 1693.6 | J35: 1853.4 | K35: 1734.4 | L35: 1847.1 | M35: 1836.4 | N35: 1488 | O35: 1433.6 | P35: 1521 | Q35: 1397.9 | R35: 1472.4 | S35: 1367.8 | T35: 1440.5 | Y35: 517.255 | Z35: 597.519 | AA35: 715.565 | AB35: 713.967 | AC35: 718.51 | AD35: 738.963 | AE35: 1239.994 | AF35: 1636.5 | AG35: 1734.4 | AH35: 1433.6 | AI35: 1367.8
C36: Cash | D36: 444.6 | E36: 715.9 | F36: 638.5 | G36: 497.6 | H36: 193.4 | I36: 365.1 | J36: 101.9 | K36: 127.6 | L36: 193.4 | M36: 139.1 | N36: 358.4 | O36: 397.8 | P36: 362.7 | Q36: 240.9 | R36: 211.5 | S36: 325.7 | T36: 409.8 | Y36: 6.669 | Z36: 44.81 | AA36: 105.167 | AB36: 194.609 | AC36: 278.372 | AD36: 675.555 | AE36: 851.381 | AF36: 497.6 | AG36: 127.6 | AH36: 397.8 | AI36: 325.7
C37: Total assets | D37: =SUM(D31:D36) -> 7547.8 | E37: =SUM(E31:E36) -> 6856.4 | F37: =SUM(F31:F36) -> 7224.5 | G37: =SUM(G31:G36) -> 7605.6 | H37: =SUM(H31:H36) -> 7194.3 | I37: =SUM(I31:I36) -> 7488.8 | J37: =SUM(J31:J36) -> 7246.4 | K37: =SUM(K31:K36) -> 7026.1 | ... T37: =SUM(T31:T36) -> 6109.4 | Y37: =SUM(Y31:Y36) -> 1475.258 | Z37: =SUM(Z31:Z36) -> 1611.644 | AA37: =SUM(AA31:AA36) -> 1794.017 | AB37: =SUM(AB31:AB36) -> 1922.607 | AC37: =SUM(AC31:AC36) -> 2226.194 | AD37: =SUM(AD31:AD36) -> 3060.557 | AE37: =SUM(AE31:AE36) -> 6335.396 | AF37: =SUM(AF31:AF36) -> 7605.6 | ... AI37: =SUM(AI31:AI36) -> 5968.9
C38: Share capital | D38: 27.4 | E38: 27.4 | F38: 27.4 | G38: 27.4 | H38: 27.4 | I38: 27.4 | J38: 27.4 | K38: 27.4 | L38: 27.4 | M38: 27.4 | N38: 27.4 | O38: 27.4 | P38: 27.4 | Q38: 27.4 | R38: 27.4 | S38: 27.4 | T38: 27.4 | Y38: 18.389 | Z38: 18.914 | AA38: 19.139 | AB38: 19.254 | AC38: 19.254 | AD38: 19.652 | AE38: 27.409 | AF38: 27.4 | AG38: 27.4 | AH38: 27.4 | AI38: 27.4
C39: Other capital | D39: 2945.1 | E39: 2888.6 | F39: 2920.5 | G39: 2971.4 | H39: 2981.1 | I39: 3046.2 | J39: 2998.1 | K39: 2918.3 | L39: 2981.1 | M39: 2963.4 | N39: 2922.9 | O39: 2962.1 | P39: 2870.9 | Q39: 2900.3 | R39: 2885.8 | S39: 2820.8 | T39: 2883 | Y39: 440.908 | Z39: 512.197 | AA39: 530.351 | AB39: 558.839 | AC39: 574.454 | AD39: 632.161 | AE39: 2831.887 | AF39: 2971.4 | AG39: 2918.3 | AH39: 2962.1 | AI39: 2820.8
C40: Profit brought forward | D40: 1286.6 | E40: 1167.6 | F40: 1181.5 | G40: 1187.7 | H40: 1264.5 | I40: 1200.6 | J40: 1124.1 | K40: 1205.3 | L40: 1264.5 | M40: 1130 | N40: 1122.8 | O40: 1149 | P40: 1186.1 | Q40: 1099.2 | R40: 1108.2 | S40: 783.3 | T40: 804 | Y40: 279.56 | Z40: 303.884 | AA40: 389.182 | AB40: 513.288 | AC40: 631.358 | AD40: 878.99 | AE40: 1025.343 | AF40: 1187.7 | AG40: 1205.3 | AH40: 1149 | AI40: 783.3
C41: Non-controlling interests | D41: 24.6 | E41: 0.2 | F41: 7.5 | G41: 21.2 | H41: 17.8 | I41: 14.8 | J41: 14.5 | K41: 14.7 | L41: 17.8 | M41: 10.3 | N41: 5.9 | O41: -0.9 | P41: 0.4 | Q41: -4.5 | R41: -3.8 | S41: -2.9 | T41: -2.5 | Y41: 13.328 | Z41: 9.28 | AA41: 12.53 | AB41: 14.908 | AC41: 16.032 | AD41: 14.211 | AE41: 7.732 | AF41: 21.2 | AG41: 14.7 | AH41: -0.9 | AI41: -2.9
C42: Total equity | D42: =SUM(D38:D41) -> 4283.7 | E42: =SUM(E38:E41) -> 4083.8 | F42: =SUM(F38:F41) -> 4136.9 | G42: =SUM(G38:G41) -> 4207.7 | H42: =SUM(H38:H41) -> 4290.8 | I42: =SUM(I38:I41) -> 4289 | J42: =SUM(J38:J41) -> 4164.1 | K42: =SUM(K38:K41) -> 4165.7 | ... T42: =SUM(T38:T41) -> 3711.9 | Y42: =SUM(Y38:Y41) -> 752.185 | Z42: =SUM(Z38:Z41) -> 844.275 | AA42: =SUM(AA38:AA41) -> 951.202 | AB42: =SUM(AB38:AB41) -> 1106.289 | AC42: =SUM(AC38:AC41) -> 1241.098 | AD42: =SUM(AD38:AD41) -> 1545.014 | AE42: =SUM(AE38:AE41) -> 3892.371 | AF42: =SUM(AF38:AF41) -> 4207.7 | ... AI42: =SUM(AI38:AI41) -> 3628.6
C43: Non-current provisions | D43: 269.2 | E43: 239.5 | F43: 261.3 | G43: 276.5 | H43: 235.9 | I43: 265 | J43: 254.7 | K43: 238.8 | L43: 235.9 | M43: 226.9 | N43: 218.9 | O43: 203.8 | P43: 193.3 | Q43: 184.3 | R43: 193.7 | S43: 137.2 | T43: 7.4 | Y43: 36.163 | Z43: 34.793 | AA43: 38.999 | AB43: 0 | AC43: 2.472 | AD43: 2.773 | AE43: 4.135 | AF43: 276.5 | AG43: 238.8 | AH43: 203.8 | AI43: 137.2
C44: IB non-current debt | D44: 1184.7 | E44: 1080.6 | F44: 1259.7 | G44: 1303.3 | H44: 916.8 | I44: 1168.4 | J44: 1049.6 | K44: 936.1 | L44: 916.8 | M44: 902.8 | N44: 993.4 | O44: 863.1 | P44: 835.2 | Q44: 737.1 | R44: 663.8 | S44: 607.9 | T44: 598.1 | Y44: 81.639 | Z44: 10.138 | AA44: 55.017 | AB44: 79.513 | AC44: 164.407 | AD44: 326.66 | AE44: 286.306 | AF44: 1303.3 | AG44: 936.1 | AH44: 863.1 | AI44: 607.9
...

Sheet Segementer
B4: SEK million | C4: Q122 | D4: Q222 | E4: Q322 | F4: Q422 | G4: 2022 | H4: Q123 | I4: Q223 | J4: Q323 | K4: Q423 | L4: 2023 | M4: Q124 | N4: Q224 | O4: Q324 | P4: Q424 | Q4: 2024 | R4: Q125 | S4: Q225 | T4: Q325 | U4: Q425 | V4: 2025 | W4: Q126 | X4: Q226 | Y4: Q326 | Z4: Q426 | AA4: 2026
B5: Solutions
B6: Revenue | C6: 976 | D6: 832.7 | E6: 894.8 | F6: 1120.9 | G6: =SUM(C6:F6) -> 3824.4 | H6: 1091.5 | I6: 936.3 | J6: 861.5 | K6: 1003.2 | L6: =SUM(H6:K6) -> 3892.5 | M6: 988.9 | N6: 933.2 | O6: 749.9 | P6: 915.2 | Q6: =SUM(M6:P6) -> 3587.2 | R6: 880.2 | S6: 802.9 | T6: 647.7 | U6: 770.5 | V6: 3366 | W6: 716.7 | AA6: =SUM(W6:Z6) -> 716.7
B7: Growth % | H7: =(H6-C6)/C6 -> 0.11834016 | I7: =(I6-D6)/D6 -> 0.12441456 | J7: =(J6-E6)/E6 -> -0.03721502 | K7: =(K6-F6)/F6 -> -0.10500491 | L7: =(L6-G6)/G6 -> 0.017806715 | M7: =(M6-H6)/H6 -> -0.093999084 | N7: =(N6-I6)/I6 -> -0.0033109046 | O7: =(O6-J6)/J6 -> -0.1295415 | ... AA7: =(AA6-V6)/V6 -> -0.78707665
B8: EBITA | C8: 126.2 | D8: 89.6 | E8: 72.2 | F8: 110.5 | G8: =SUM(C8:F8) -> 398.5 | H8: 114.9 | I8: 46.5 | J8: 63.2 | K8: 91.9 | L8: =SUM(H8:K8) -> 316.5 | M8: 82.7 | N8: 68 | O8: 60.7 | P8: 84.8 | Q8: =SUM(M8:P8) -> 296.2 | R8: 80.3 | S8: 54.3 | T8: 64.2 | U8: 77.4 | V8: =SUM(R8:U8) -> 276.2 | W8: 66.8 | AA8: =SUM(W8:Z8) -> 66.8
B9: EBITA Margin % | C9: =C8/C6 -> 0.12930328 | D9: =D8/D6 -> 0.10760178 | E9: =E8/E6 -> 0.080688422 | F9: =F8/F6 -> 0.098581497 | G9: =G8/G6 -> 0.10419935 | H9: =H8/H6 -> 0.10526798 | I9: =I8/I6 -> 0.049663569 | J9: =J8/J6 -> 0.073360418 | ... AA9: =AA8/AA6 -> 0.093204967
B10: Employees | C10: 1717 | D10: 1720 | E10: 1921 | F10: 1931 | G10: 1931 | H10: 1910 | I10: 1961 | J10: 1953 | K10: 1923 | L10: 1923 | M10: 1856 | N10: 1812 | O10: 1762 | P10: 1715 | Q10: 1715 | R10: 1671 | S10: 1646 | T10: 1656 | U10: 1636 | V10: 1636 | W10: 1508
B11: y/y % | H11: =(H10-C10)/C10 -> 0.11240536 | I11: =(I10-D10)/D10 -> 0.14011628 | J11: =(J10-E10)/E10 -> 0.016657991 | K11: =(K10-F10)/F10 -> -0.0041429311 | L11: =(L10-G10)/G10 -> -0.0041429311 | M11: =(M10-H10)/H10 -> -0.028272251 | N11: =(N10-I10)/I10 -> -0.075981642 | O11: =(O10-J10)/J10 -> -0.097798259 | ... AA11: =(AA10-V10)/V10 -> -1
B12: Experience
B13: Revenue | C13: 413.2 | D13: 401.5 | E13: 338.7 | F13: 431.9 | G13: =SUM(C13:F13) -> 1585.3 | H13: 447 | I13: 366.4 | J13: 306.3 | K13: 354.8 | L13: =SUM(H13:K13) -> 1474.5 | M13: 335.2 | N13: 320.3 | O13: 235.4 | P13: 290 | Q13: =SUM(M13:P13) -> 1180.9 | R13: 286.1 | S13: 267.4 | T13: 225.1 | U13: 274.3 | V13: =SUM(R13:U13) -> 1052.9 | W13: 276.1 | AA13: =SUM(W13:Z13) -> 276.1
B14: Growth % | H14: =(H13-C13)/C13 -> 0.081800581 | I14: =(I13-D13)/D13 -> -0.087422167 | J14: =(J13-E13)/E13 -> -0.095659876 | K14: =(K13-F13)/F13 -> -0.17851354 | L14: =(L13-G13)/G13 -> -0.069892134 | M14: =(M13-H13)/H13 -> -0.25011186 | N14: =(N13-I13)/I13 -> -0.12581878 | O14: =(O13-J13)/J13 -> -0.23147241 | ... AA14: =(AA13-V13)/V13 -> -0.73777187
B15: EBITA | C15: 59.3 | D15: 38.8 | E15: 21.4 | F15: 48.4 | G15: =SUM(C15:F15) -> 167.9 | H15: 59.1 | I15: 20.1 | J15: 7.4 | K15: 29 | L15: =SUM(H15:K15) -> 115.6 | M15: 28 | N15: 19.3 | O15: -1.3 | P15: 8 | Q15: =SUM(M15:P15) -> 54 | R15: 17.7 | S15: 6.3 | T15: 6.8 | U15: 17 | V15: =SUM(R15:U15) -> 47.8 | W15: 17.3 | AA15: =SUM(W15:Z15) -> 17.3
B16: EBITA Margin % | C16: =C15/C13 -> 0.14351404 | D16: =D15/D13 -> 0.096637609 | E16: =E15/E13 -> 0.063182758 | F16: =F15/F13 -> 0.11206298 | G16: =G15/G13 -> 0.10591055 | H16: =H15/H13 -> 0.13221477 | I16: =I15/I13 -> 0.054858079 | J16: =J15/J13 -> 0.024159321 | ... AA16: =AA15/AA13 -> 0.062658457
B17: Employees | C17: 959 | D17: 960 | E17: 1002 | F17: 1000 | G17: 1000 | H17: 987 | I17: 975 | J17: 979 | K17: 937 | L17: 937 | M17: 889 | N17: 846 | O17: 817 | P17: 805 | Q17: 805 | R17: 775 | S17: 770 | T17: 775 | U17: 763 | V17: 763 | W17: 726
B18: y/y % | H18: =(H17-C17)/C17 -> 0.02919708 | I18: =(I17-D17)/D17 -> 0.015625 | J18: =(J17-E17)/E17 -> -0.022954092 | K18: =(K17-F17)/F17 -> -0.063 | L18: =(L17-G17)/G17 -> -0.063 | M18: =(M17-H17)/H17 -> -0.09929078 | N18: =(N17-I17)/I17 -> -0.13230769 | O18: =(O17-J17)/J17 -> -0.16547497 | ... AA18: =(AA17-V17)/V17 -> -1
B19: Connectivity
B20: Revenue | C20: 246 | D20: 259.4 | E20: 247.5 | F20: 287.5 | G20: =SUM(C20:F20) -> 1040.4 | H20: 304.1 | I20: 236.2 | J20: 225.8 | K20: 244 | L20: =SUM(H20:K20) -> 1010.1 | M20: 219.4 | N20: 206.7 | O20: 189.3 | P20: 211.6 | Q20: =SUM(M20:P20) -> 827 | R20: 208.4 | S20: 200.9 | T20: 190.8 | U20: 224.6 | V20: 819 | W20: 145.3 | AA20: =SUM(W20:Z20) -> 145.3
B21: Growth % | H21: =(H20-C20)/C20 -> 0.23617886 | I21: =(I20-D20)/D20 -> -0.089437163 | J21: =(J20-E20)/E20 -> -0.087676768 | K21: =(K20-F20)/F20 -> -0.15130435 | L21: =(L20-G20)/G20 -> -0.029123414 | M21: =(M20-H20)/H20 -> -0.2785268 | N21: =(N20-I20)/I20 -> -0.12489416 | O21: =(O20-J20)/J20 -> -0.16164748 | ... AA21: =(AA20-V20)/V20 -> -0.82258852
B22: EBITA | C22: 29.4 | D22: 25.4 | E22: 29 | F22: 34.7 | G22: =SUM(C22:F22) -> 118.5 | H22: 34.8 | I22: 19.3 | J22: 26.2 | K22: 31 | L22: =SUM(H22:K22) -> 111.3 | M22: 28.5 | N22: 16.6 | O22: 21.3 | P22: 22.6 | Q22: =SUM(M22:P22) -> 89 | R22: 17.3 | S22: 13.4 | T22: 20.7 | U22: 25.4 | V22: =SUM(R22:U22) -> 76.8 | W22: 7.8 | AA22: =SUM(W22:Z22) -> 7.8
B23: EBITA Margin % | C23: =C22/C20 -> 0.1195122 | D23: =D22/D20 -> 0.097918273 | E23: =E22/E20 -> 0.11717172 | F23: =F22/F20 -> 0.12069565 | G23: =G22/G20 -> 0.1138985 | H23: =H22/H20 -> 0.11443604 | I23: =I22/I20 -> 0.081710415 | J23: =J22/J20 -> 0.11603189 | ... AA23: =AA22/AA20 -> 0.053682037
B24: Employees | C24: 676 | D24: 740 | E24: 757 | F24: 773 | G24: 773 | H24: 774 | I24: 764 | J24: 763 | K24: 739 | L24: 739 | M24: 717 | N24: 710 | O24: 709 | P24: 697 | Q24: 697 | R24: 698 | S24: 687 | T24: 696 | U24: 691 | V24: 691 | W24: 549 | AA24: 691
B25: y/y % | H25: =(H24-C24)/C24 -> 0.14497041 | I25: =(I24-D24)/D24 -> 0.032432432 | J25: =(J24-E24)/E24 -> 0.0079260238 | K25: =(K24-F24)/F24 -> -0.043984476 | L25: =(L24-G24)/G24 -> -0.043984476 | M25: =(M24-H24)/H24 -> -0.073643411 | N25: =(N24-I24)/I24 -> -0.070680628 | O25: =(O24-J24)/J24 -> -0.070773263 | ... AA25: =(AA24-V24)/V24 -> 0
B26: Insight
B27: Revenue | C27: 169.9 | D27: 170.7 | E27: 136 | F27: 254.3 | G27: =SUM(C27:F27) -> 730.9 | H27: 246.9 | I27: 226.1 | J27: 162.2 | K27: 237.1 | L27: =SUM(H27:K27) -> 872.3 | M27: 234.8 | N27: 232.6 | O27: 159.1 | P27: 233.4 | Q27: =SUM(M27:P27) -> 859.9 | R27: 227.9 | S27: 229.1 | T27: 166.6 | U27: 233.6 | V27: =SUM(R27:U27) -> 857.2 | W27: 226 | AA27: =SUM(W27:Z27) -> 226
B28: Growth % | H28: =(H27-C27)/C27 -> 0.45320777 | I28: =(I27-D27)/D27 -> 0.32454599 | J28: =(J27-E27)/E27 -> 0.19264706 | K28: =(K27-F27)/F27 -> -0.06763665 | L28: =(L27-G27)/G27 -> 0.19346012 | M28: =(M27-H27)/H27 -> -0.049007695 | N28: =(N27-I27)/I27 -> 0.028748341 | O28: =(O27-J27)/J27 -> -0.019112207 | ... AA28: =(AA27-V27)/V27 -> -0.73635091
B29: EBITA | C29: 20.2 | D29: 24 | E29: -8.3 | F29: 32.7 | G29: =SUM(C29:F29) -> 68.6 | H29: 26.5 | I29: 19 | J29: -10.2 | K29: 22.2 | L29: =SUM(H29:K29) -> 57.5 | M29: 19.8 | N29: 15.1 | O29: -10.3 | P29: 12.4 | Q29: =SUM(M29:P29) -> 37 | R29: 13.4 | S29: 8.6 | T29: -10.8 | U29: 21.1 | V29: =SUM(R29:U29) -> 32.3 | W29: 3.9 | AA29: =SUM(W29:Z29) -> 3.9
B30: EBITA Margin % | C30: =C29/C27 -> 0.11889347 | D30: =D29/D27 -> 0.14059754 | E30: =E29/E27 -> -0.061029412 | F30: =F29/F27 -> 0.12858828 | G30: =G29/G27 -> 0.093856889 | H30: =H29/H27 -> 0.1073309 | I30: =I29/I27 -> 0.084033613 | J30: =J29/J27 -> -0.062885327 | ... AA30: =AA29/AA27 -> 0.017256637
B31: Employees | C31: 376 | D31: 370 | E31: 482 | F31: 553 | G31: 553 | H31: 544 | I31: 542 | J31: 594 | K31: 578 | L31: 578 | M31: 565 | N31: 548 | O31: 565 | P31: 554 | Q31: 554 | R31: 538 | S31: 539 | T31: 556 | U31: 537 | V31: 537 | W31: 538
B32: y/y % | H32: =(H31-C31)/C31 -> 0.44680851 | I32: =(I31-D31)/D31 -> 0.46486486 | J32: =(J31-E31)/E31 -> 0.23236515 | K32: =(K31-F31)/F31 -> 0.045207957 | L32: =(L31-G31)/G31 -> 0.045207957 | M32: =(M31-H31)/H31 -> 0.038602941 | N32: =(N31-I31)/I31 -> 0.011070111 | O32: =(O31-J31)/J31 -> -0.048821549 | ... AA32: =(AA31-V31)/V31 -> -1
B33: Products
B34: Revenue | G34: =SUM(C34:F34) -> 0 | L34: =SUM(H34:K34) -> 0 | Q34: =SUM(M34:P34) -> 0 | R34: 77.7 | V34: =SUM(R34:U34) -> 77.7 | W34: 95.3 | AA34: =SUM(W34:Z34) -> 95.3
B35: Growth % | H35: =(H34-C34)/C34 -> #DIV/0! | I35: =(I34-D34)/D34 -> #DIV/0! | J35: =(J34-E34)/E34 -> #DIV/0! | K35: =(K34-F34)/F34 -> #DIV/0! | L35: =(L34-G34)/G34 -> #DIV/0! | M35: =(M34-H34)/H34 -> #DIV/0! | N35: =(N34-I34)/I34 -> #DIV/0! | O35: =(O34-J34)/J34 -> #DIV/0! | ... AA35: =(AA34-V34)/V34 -> 0.22651223
B36: EBITA | G36: =SUM(C36:F36) -> 0 | L36: =SUM(H36:K36) -> 0 | Q36: =SUM(M36:P36) -> 0 | R36: 10.2 | V36: =SUM(R36:U36) -> 10.2 | W36: 12.2 | AA36: =SUM(W36:Z36) -> 12.2
B37: EBITA Margin % | C37: =C36/C34 -> #DIV/0! | D37: =D36/D34 -> #DIV/0! | E37: =E36/E34 -> #DIV/0! | F37: =F36/F34 -> #DIV/0! | G37: =G36/G34 -> #DIV/0! | H37: =H36/H34 -> #DIV/0! | I37: =I36/I34 -> #DIV/0! | J37: =J36/J34 -> #DIV/0! | ... AA37: =AA36/AA34 -> 0.12801679
B38: Employees | R38: 179 | W38: 232
B39: y/y % | H39: =(H38-C38)/C38 -> #DIV/0! | I39: =(I38-D38)/D38 -> #DIV/0! | J39: =(J38-E38)/E38 -> #DIV/0! | K39: =(K38-F38)/F38 -> #DIV/0! | L39: =(L38-G38)/G38 -> #DIV/0! | M39: =(M38-H38)/H38 -> #DIV/0! | N39: =(N38-I38)/I38 -> #DIV/0! | O39: =(O38-J38)/J38 -> #DIV/0! | ... AA39: =(AA38-V38)/V38 -> #DIV/0!

Sheet SOTP
B3: EBITA 2026E
B4: =Modell!AJ8 -> 322.59165
C6: SEKm | D6: EBITA 26E | E6: EV/EBITA | F6: Value | G6: SEK/Share
C7: Solutions | D7: 280 | E7: 9 | F7: =D7*E7 -> 2520 | G7: =F7/Modell!$B$5 -> 92.28403
C8: Experience | D8: 60 | E8: 5 | F8: =D8*E8 -> 300 | G8: =F8/Modell!$B$5 -> 10.986194
C9: Connectivity | D9: 30 | E9: 5 | F9: =D9*E9 -> 150 | G9: =F9/Modell!$B$5 -> 5.493097
C10: Insight | D10: 25 | E10: 5 | F10: =D10*E10 -> 125 | G10: =F10/Modell!$B$5 -> 4.5775808
C11: Products | D11: 45 | E11: 10 | F11: =D11*E11 -> 450 | G11: =F11/Modell!$B$5 -> 16.479291
C12: Enterprise value | F12: =SUM(F7:F11) -> 3545 | G12: =SUM(G7:G10) -> 113.3409
C14: Cash | F14: =Modell!B7 -> 409.8 | G14: =F14/Modell!$B$5 -> 15.007141
C15: Debt | F15: =Modell!B8 -> 748.4 | G15: =-F15/Modell!$B$5 -> -27.406892
C17: Equity value | G17: =SUM(G12:G15) -> 100.94115
A60: Solutions | B60: 92.28403
A61: Experience | B61: 8.2396455
A62: Connectivity | B62: 25.634453
A63: Insight | B63: 6.4086132
A64: Products | B64: =G11 -> 16.479291
A65: Enterprise value | B65: 132.56674
A67: Cash | B67: 11.927345
A68: Debt | B68: -27.776761
A70: Equity value | B70: 116.71733

Sheet Nøkkeltall
D4: 2026 | E4: 2027 | F4: 2028
C5: EV/EBITA | D5: =Modell!$B$9/Modell!AJ8 -> 8.5071845 | E5: =Modell!$B$9/Modell!AK8 -> 6.6523207 | F5: =Modell!$B$9/Modell!AL8 -> 6.2681277
C6: EV/EBIT | D6: =Modell!$B$9/Modell!AJ10 -> 16.878768 | E6: =Modell!$B$9/Modell!AK10 -> 10.866989 | F6: =Modell!$B$9/Modell!AL10 -> 9.877948
C7: P/E | D7: =Modell!$B$4/Modell!AJ17 -> 23.351014 | E7: =Modell!$B$4/Modell!AK17 -> 13.78382 | F7: =Modell!$B$4/Modell!AL17 -> 12.360213

Sheet Nedsideberegninger
A3: Nedside | D3: FY 2015 | E3: FY 2016 | F3: FY 2017 | G3: FY 2018 | H3: FY 2019 | I3: FY 2020 | J3: FY 2021 | K3: FY 2022 | L3: FY 2023 | M3: FY 2024 | N3: FY 2025 | O3: FY 2026 | P3: FY 2027 | Q3: FY 2028 | R3: FY 2029 | S3: FY 2030 | T3: FY 2031 | U3: FY 2032 | V3: FY 2033 | W3: FY 2034 | X3: FY 2035
A4: Nullvekst og konstante marg | C4: Revenue | D4: 2230 | E4: 2426.218 | F4: 2733.501 | G4: 3083.304 | H4: 3335 | I4: 3379 | J4: 4811.839 | K4: 6833.746 | L4: 7113.82 | M4: 6415.744 | N4: =M4*0.9 -> 5774.1696 | O4: =N4*1 -> 5774.1696 | P4: =O4*1 -> 5774.1696 | Q4: =P4*1 -> 5774.1696 | R4: =Q4*1 -> 5774.1696 | S4: =R4*1 -> 5774.1696 | T4: =S4*1 -> 5774.1696 | U4: =T4*1 -> 5774.1696 | V4: =U4*1 -> 5774.1696 | ... X4: =W4*1 -> 5774.1696
A5: =AA21 -> 76.333161 | C5: Operating costs | D5: =-304-212.543-1537.9 -> -2054.443 | E5: =-387.311-203.347-1612.596 -> -2203.254 | F5: =-457.262-216.441-1767.168 -> -2440.871 | G5: =-512.288-226.87-2017.075 -> -2756.233 | H5: =-556.803-171.737-2215.079 -> -2943.619 | I5: =-637.286-168.285-2166.451 -> -2972.022 | J5: =-987.377-299.714-2963.271 -> -4250.362 | K5: =-1699.746-425.25-3963.482 -> -6088.478 | L5: =-1588.977-410.948-4439.502 -> -6439.427 | M5: =-1241.735-4285.279-348 -> -5875.014 | N5: =M5*0.89 -> -5228.7625 | O5: =N5*1 -> -5228.7625 | P5: =O5*1 -> -5228.7625 | Q5: =P5*1 -> -5228.7625 | R5: =Q5*1 -> -5228.7625 | S5: =R5*1 -> -5228.7625 | T5: =S5*1 -> -5228.7625 | U5: =T5*1 -> -5228.7625 | V5: =U5*1 -> -5228.7625 | ... X5: =W5*1 -> -5228.7625
A6: =AA22 -> -0.13356231 | C6: Dep and write-downs of tangiable assets | D6: -28.6 | E6: -10.58 | F6: -5.7 | G6: -6 | H6: -73.304 | I6: -73.666 | J6: -123.572 | K6: -148.793 | L6: -178 | M6: -174 | N6: =M6*0.9 -> -156.6 | O6: =N6*1 -> -156.6 | P6: =O6*1 -> -156.6 | Q6: =P6*1 -> -156.6 | R6: =Q6*1 -> -156.6 | S6: =R6*1 -> -156.6 | T6: =S6*1 -> -156.6 | U6: =T6*1 -> -156.6 | V6: =U6*1 -> -156.6 | ... X6: =W6*1 -> -156.6
C7: EBITA | D7: =SUM(D4:D6) -> 146.957 | E7: =SUM(E4:E6) -> 212.384 | F7: =SUM(F4:F6) -> 286.93 | G7: =SUM(G4:G6) -> 321.071 | H7: =SUM(H4:H6) -> 318.077 | I7: =SUM(I4:I6) -> 333.312 | J7: =SUM(J4:J6) -> 437.905 | K7: =SUM(K4:K6) -> 596.475 | ... X7: =SUM(X4:X6) -> 388.80714
C8: Amort and write-downs on intangible assets | D8: -11.56 | E8: -11.8 | F8: -11.7 | G8: -11.9 | H8: -5 | I8: =-12.301+1.6 -> -10.701 | J8: -75.247 | K8: -149.331 | L8: -186.537 | M8: -166 | N8: =M8*1.01 -> -167.66 | O8: =N8*1 -> -167.66 | P8: =O8*1 -> -167.66 | Q8: =P8*1 -> -167.66 | R8: =Q8*1 -> -167.66 | S8: =R8*1 -> -167.66 | T8: =S8*1 -> -167.66 | U8: =T8*1 -> -167.66 | V8: =U8*1 -> -167.66 | ... X8: =W8*1 -> -167.66
C9: Operating income (EBIT) | D9: =SUM(D7:D8) -> 135.397 | E9: =SUM(E7:E8) -> 200.584 | F9: =SUM(F7:F8) -> 275.23 | G9: =SUM(G7:G8) -> 309.171 | H9: =SUM(H7:H8) -> 313.077 | I9: =SUM(I7:I8) -> 322.611 | J9: =SUM(J7:J8) -> 362.658 | K9: =SUM(K7:K8) -> 447.144 | ... X9: =SUM(X7:X8) -> 221.14714
C10: Financial income | D10: 1.1 | E10: 2.5 | F10: 0.612 | G10: 0.979 | H10: 15.518 | I10: 15.548 | J10: 20.607 | K10: 94.963 | L10: 76 | M10: 12.56 | N10: 0 | O10: 0 | P10: 0 | Q10: 0 | R10: 0 | S10: 0 | T10: 0 | U10: 0 | V10: 0 | W10: 0 | X10: 0
C11: Financial expense | D11: -20.177 | E11: -11.8 | F11: -9.8 | G11: -6.2 | H11: -15.4 | I11: -6.369 | J11: -13.77 | K11: -58.431 | L11: -81.725 | M11: -59.272 | N11: 0 | O11: 0 | P11: 0 | Q11: 0 | R11: 0 | S11: 0 | T11: 0 | U11: 0 | V11: 0 | W11: 0 | X11: 0
C12: PTP | D12: =SUM(D9:D11) -> 116.32 | E12: =SUM(E9:E11) -> 191.284 | F12: =SUM(F9:F11) -> 266.042 | G12: =SUM(G9:G11) -> 303.95 | H12: =SUM(H9:H11) -> 313.195 | I12: =SUM(I9:I11) -> 331.79 | J12: =SUM(J9:J11) -> 369.495 | K12: =SUM(K9:K11) -> 483.676 | ... X12: =SUM(X9:X11) -> 221.14714
C13: Tax | D13: -24 | E13: -47.2 | F13: -64.3 | G13: -71.7 | H13: -71.452 | I13: -74 | J13: -75.318 | K13: -91.489 | L13: -62.293 | M13: -42.668 | N13: =N12*-0.205 -> -45.335164 | O13: =O12*-0.205 -> -45.335164 | P13: =P12*-0.205 -> -45.335164 | Q13: =Q12*-0.205 -> -45.335164 | R13: =R12*-0.205 -> -45.335164 | S13: =S12*-0.205 -> -45.335164 | T13: =T12*-0.205 -> -45.335164 | U13: =U12*-0.205 -> -45.335164 | ... X13: =X12*-0.205 -> -45.335164
C14: Net income | D14: =SUM(D12:D13) -> 92.32 | E14: =SUM(E12:E13) -> 144.084 | F14: =SUM(F12:F13) -> 201.742 | G14: =SUM(G12:G13) -> 232.25 | H14: =SUM(H12:H13) -> 241.743 | I14: =SUM(I12:I13) -> 257.79 | J14: =SUM(J12:J13) -> 294.177 | K14: =SUM(K12:K13) -> 392.187 | ... X14: =SUM(X12:X13) -> 175.81198 | Y14: =X14*(1+$AA$18) -> 174.05386 | Z14: =Y14*(1+$AA$18) -> 172.31332 | AA14: =Z14*(1+$AA$18) -> 170.59018 | AB14: =AA14*(1+$AA$18) -> 168.88428 | AC14: =AB14*(1+$AA$18) -> 167.19544 | AD14: =AC14*(1+$AA$18) -> 165.52349 | AE14: =AD14*(1+$AA$18) -> 163.86825 | AF14: =AE14*(1+$AA$18) -> 162.22957 | ... DV14: =DU14*(1+$AA$18) -> 63.072247
C15: Share | D15: 18.389 | E15: 18.914 | F15: 19.139 | G15: 19.253 | H15: 19.254 | I15: 19.28 | J15: 23.726 | K15: 27.409 | L15: 27.307 | M15: 27.307 | N15: 27.307 | O15: 27.307 | P15: 27.307 | Q15: 27.307 | R15: 27.307 | S15: 27.307 | T15: 27.307 | U15: 27.307 | V15: 27.307 | W15: 27.307 | X15: 27.307
C16: EPS | D16: =D14/D15 -> 5.0203926 | E16: =E14/E15 -> 7.6178492 | F16: =F14/F15 -> 10.540885 | G16: =G14/G15 -> 12.063055 | H16: =H14/H15 -> 12.555469 | I16: =I14/I15 -> 13.370851 | J16: =J14/J15 -> 12.398929 | K16: =K14/K15 -> 14.308694 | ... X16: =X14/X15 -> 6.4383483
Z17: Discount | AA17: 0.08
C18: Revenue y/y | E18: =(E4-D4)/D4 -> 0.087990135 | F18: =(F4-E4)/E4 -> 0.12665103 | G18: =(G4-F4)/F4 -> 0.12796886 | H18: =(H4-G4)/G4 -> 0.081631912 | I18: =(I4-H4)/H4 -> 0.013193403 | J18: =(J4-I4)/I4 -> 0.42404232 | K18: =(K4-J4)/J4 -> 0.42019423 | L18: =(L4-K4)/K4 -> 0.040983964 | ... X18: =(X4-W4)/W4 -> 0 | Z18: TV | AA18: -0.01
C19: Operating costs y/y | E19: =(E5-D5)/D5 -> 0.072433745 | F19: =(F5-E5)/E5 -> 0.10784821 | G19: =(G5-F5)/F5 -> 0.1292006 | H19: =(H5-G5)/G5 -> 0.06798627 | I19: =(I5-H5)/H5 -> 0.0096490069 | J19: =(J5-I5)/I5 -> 0.43012468 | K19: =(K5-J5)/J5 -> 0.43246105 | L19: =(L5-K5)/K5 -> 0.057641499 | ... X19: =(X5-W5)/W5 -> 0 | Z19: NPV | AA19: =NPV(AA17,N14:DV14) -> 2084.4296
C20: EBITA margin | D20: =D7/D4 -> 0.0659 | E20: =E7/E4 -> 0.087537064 | F20: =F7/F4 -> 0.10496795 | G20: =G7/G4 -> 0.10413213 | H20: =H7/H4 -> 0.095375412 | I20: =I7/I4 -> 0.098642202 | J20: =J7/J4 -> 0.091005746 | K20: =K7/K4 -> 0.087283753 | ... X20: =X7/X4 -> 0.067335594 | Z20: S/O | AA20: 27.307
C21: EBIT margin | D21: =D9/D4 -> 0.060716143 | E21: =E9/E4 -> 0.082673527 | F21: =F9/F4 -> 0.10068773 | G21: =G9/G4 -> 0.10027263 | H21: =H9/H4 -> 0.093876162 | I21: =I9/I4 -> 0.095475289 | J21: =J9/J4 -> 0.075367858 | K21: =K9/K4 -> 0.065431756 | ... X21: =X9/X4 -> 0.038299384 | Z21: NPV/Share | AA21: =AA19/AA20 -> 76.333161
C22: ROE | D22: 0.119 | E22: 0.181 | F22: 0.225 | G22: 0.225 | H22: 0.206 | I22: 0.185 | J22: 0.108 | K22: 0.097 | L22: 0.058 | M22: 0.027 | Z22: Opp-/nedside | AA22: =(AA21-Modell!B4)/Modell!B4 -> -0.13356231
