Workbook

Sheet Info
Q1: Q325
A2: Nobia er en svensk kjøkken-produsent lokalisert i Sverige.
A3: De største markedene til Nobia er Norden og UK
A5: Nobia har sterke merkevarer i Norden og Tyskland med HTH.
A6: De har i tillegg Sigdal i Norge, Marbodal i Sverige, Novart Finland og Invita i Danmark.
A8: Fabrikken i Jönköping har de kjørt en sale-leaseback i 1.kvartal 2024
A9: Gjelden til Nobia har en maturity i juni 2027
A24: Press release:
A25: 14.01.26: Nobia henter inn 1,5 mrd til 1,78SEK
A26: 14.01.26: Nobia selge unna UK for å rendyrke selskapet til en Nordisk modell, selger til 0 kr, men kjøper tar over leasing på 746 m
A27: 02.09.25: Nobia ansetter Robert Belkic som midlertidig CFO
A28: 18.07.25: CFO går av, vil jobbe fremt til 4. nov eller til en ny er funnet
A29: 25.03.25: CFO Henrik Skogsfors går av, sitter frem til 4.nov eller til Nobia finner en ny CFO
... A40: 17.12.23: Jon Sintorn forlater Nobia som CEO

Sheet Modell
A3: Kapitalstruktur | C3: SEK million | D3: Q122 | E3: Q222 | F3: Q322 | G3: Q422 | H3: Q123 | I3: Q223 | J3: Q323 | K3: Q423 | L3: Q124 | M3: Q224 | N3: Q324 | O3: Q424 | P3: Q125 | Q3: Q225 | R3: Q325 | S3: Q425 | T3: Q126 | U3: Q226 | V3: Q326 | W3: Q426 | Y3: FY 2015 | Z3: FY 2016 | AA3: FY 2017 | AB3: FY 2018 | AC3: FY 2019 | AD3: FY 2020 | AE3: FY 2021 | AF3: FY 2022 | AG3: FY 2023 | AH3: FY 2024 | AI3: FY 2025 | AJ3: FY 2026 | AK3: FY 2027 | AL3: FY 2028 | AM3: FY 2029 | AN3: FY 2030 | AO3: FY 2031 | AP3: FY 2032 | AQ3: FY 2033 | AR3: FY 2034 | AS3: FY 2035
A4: Price | B4: 1.828 | C4: Nordic region | D4: 2040 | E4: 2155 | F4: 1778 | G4: 2057 | H4: 1959 | I4: 1869 | J4: 1490 | K4: 1569 | L4: 1464 | M4: 1614 | N4: 1283 | O4: 1404 | P4: 1446 | Q4: 1514 | R4: 1262 | S4: 1400 | T4: 1424 | AF4: =SUM(H4:K4) -> 6887 | AG4: =SUM(H4:K4) -> 6887 | AH4: =SUM(L4:O4) -> 5765 | AI4: 5622 | AJ4: =AI4*1.02 -> 5734.44 | AK4: =AJ4*1.05 -> 6021.162 | AL4: =AK4*1.05 -> 6322.2201 | AM4: =AL4*1.05 -> 6638.3311 | AN4: =AM4*1.05 -> 6970.2477 | AO4: =AN4*1.05 -> 7318.76 | AP4: =AO4*1.05 -> 7684.698 | AQ4: =AP4*1.05 -> 8068.9329 | AR4: =AQ4*1.05 -> 8472.3796 | AS4: =AR4*1.05 -> 8895.9986
A5: S/O | B5: 1516.316 | C5: UK region | D5: 1279 | E5: 1286 | F5: 1240 | G5: 1196 | H5: 1282 | I5: 1223 | J5: 1208 | K5: 1001 | L5: 1151 | M5: 1319 | N5: 1195 | O5: 1108 | P5: 1028 | Q5: 1181 | R5: 1046 | S5: 0 | T5: 0 | AF5: =SUM(D5:G5) -> 5001 | AG5: =SUM(H5:K5) -> 4714 | AH5: =SUM(L5:O5) -> 4773 | AI5: 3255 | AJ5: 0 | AK5: 0 | AL5: 0 | AM5: 0 | AN5: 0 | AO5: 0 | AP5: 0 | AQ5: 0 | AR5: 0 | AS5: 0
A6: MC SEKm | B6: =B4*B5 -> 2771.8257 | C6: Revenues | D6: 3779 | E6: 3890 | F6: 3480 | G6: 3780 | H6: =H4+H5 -> 3241 | I6: =I4+I5 -> 3092 | J6: =J4+J5 -> 2698 | K6: 2642 | L6: =L4+L5 -> 2615 | M6: =M4+M5 -> 2933 | N6: =N4+N5 -> 2478 | O6: =O4+O5 -> 2512 | P6: =P4+P5 -> 2474 | Q6: =Q4+Q5 -> 2695 | R6: =R4+R5 -> 2308 | S6: =S4+S5 -> 1400 | T6: =T4+T5 -> 1424 | Y6: 12266 | Z6: 12648 | AA6: 12744 | AB6: 13209 | AC6: 13930 | AD6: 12741 | AE6: 13719 | AF6: =SUM(D6:G6) -> 14929 | AG6: 13373 | AH6: =AH4+AH5 -> 10538 | AI6: =AI4+AI5 -> 8877 | AJ6: =AJ4+AJ5 -> 5734.44 | AK6: =AK4+AK5 -> 6021.162 | AL6: =AL4+AL5 -> 6322.2201 | AM6: =AM4+AM5 -> 6638.3311 | AN6: =AN4+AN5 -> 6970.2477 | AO6: =AO4+AO5 -> 7318.76 | ... AS6: =AS4+AS5 -> 8895.9986
A7: Cash SEKm | B7: =T45 -> 31 | C7: COGS | D7: -2333 | E7: -2476 | F7: -2238 | G7: -2519 | H7: -2167 | I7: -1979 | J7: -1711 | K7: -1703 | L7: -1657 | M7: -1889 | N7: -1580 | O7: -1569 | P7: -1540 | Q7: -1716 | R7: -1450 | S7: -930 | T7: -933 | AF7: =SUM(D7:G7) -> -9566 | AG7: -8729 | AH7: =SUM(L7:O7) -> -6695 | AI7: -5636 | AJ7: =AJ6*-0.65 -> -3727.386 | AK7: =AK6*-0.65 -> -3913.7553 | AL7: =AL6*-0.65 -> -4109.4431 | AM7: =AM6*-0.65 -> -4314.9152 | AN7: =AN6*-0.65 -> -4530.661 | AO7: =AO6*-0.65 -> -4757.194 | AP7: =AP6*-0.65 -> -4995.0537 | AQ7: =AQ6*-0.65 -> -5244.8064 | ... AS7: =AS6*-0.65 -> -5782.3991
A8: Debt SEKm | B8: =T57 -> 1751 | C8: Gross profit | D8: =SUM(D6:D7) -> 1446 | E8: =SUM(E6:E7) -> 1414 | F8: =SUM(F6:F7) -> 1242 | G8: =SUM(G6:G7) -> 1261 | H8: =SUM(H6:H7) -> 1074 | I8: =SUM(I6:I7) -> 1113 | J8: =SUM(J6:J7) -> 987 | K8: =SUM(K6:K7) -> 939 | ... T8: =SUM(T6:T7) -> 491 | Y8: =Y6*0.4 -> 4906.4 | Z8: =Z6*0.39 -> 4932.72 | AA8: 5014 | AB8: 5090 | AC8: 5305 | AD8: 4444 | AE8: 5278 | AF8: =SUM(AF6:AF7) -> 5363 | AG8: =SUM(AG6:AG7) -> 4644 | AH8: =SUM(AH6:AH7) -> 3843 | AI8: =SUM(AI6:AI7) -> 3241 | AJ8: =SUM(AJ6:AJ7) -> 2007.054 | AK8: =SUM(AK6:AK7) -> 2107.4067 | AL8: =SUM(AL6:AL7) -> 2212.777 | AM8: =SUM(AM6:AM7) -> 2323.4159 | ... AS8: =SUM(AS6:AS7) -> 3113.5995
A9: EV SEKm | B9: =B6-B7+B8 -> 4491.8257 | C9: Selling/admin expense | D9: -1287 | E9: -1386 | F9: -1202 | G9: -1441 | H9: -1349 | I9: -1160 | J9: -1050 | K9: -1082 | L9: -1014 | M9: -1225 | N9: -955 | O9: -1053 | P9: -939 | Q9: -999 | R9: -857 | S9: -567 | T9: -478 | AF9: =SUM(D9:G9) -> -5316 | AG9: =-4040-989 -> -5029 | AH9: =-3434-813 -> -4247 | AI9: -3362 | AJ9: -1720 | AK9: =AJ9*1.02 -> -1754.4 | AL9: =AK9*1.02 -> -1789.488 | AM9: =AL9*1.02 -> -1825.2778 | AN9: =AM9*1.02 -> -1861.7833 | AO9: =AN9*1.02 -> -1899.019 | AP9: =AO9*1.02 -> -1936.9994 | AQ9: =AP9*1.02 -> -1975.7393 | AR9: =AQ9*1.02 -> -2015.2541 | AS9: =AR9*1.02 -> -2055.5592
C10: Other Income/expense | D10: 23 | E10: 34 | F10: 38 | G10: 49 | H10: 29 | I10: 61 | J10: 163 | K10: 33 | L10: 12 | M10: 10 | N10: 20 | O10: -465 | P10: -1 | Q10: 8 | R10: -1883 | S10: 46 | T10: 15 | AF10: =SUM(D10:G10) -> 144 | AG10: =664-378 -> 286 | AH10: =-786+363 -> -423 | AI10: 0 | AJ10: 0 | AK10: 0 | AL10: 0 | AM10: 0 | AN10: 0 | AO10: 0 | AP10: 0 | AQ10: 0 | AR10: 0 | AS10: 0
A11: P/B | C11: Operating profit (EBIT) | D11: =SUM(D8:D10) -> 182 | E11: =SUM(E8:E10) -> 62 | F11: =SUM(F8:F10) -> 78 | G11: =SUM(G8:G10) -> -131 | H11: =SUM(H8:H10) -> -246 | I11: =SUM(I8:I10) -> 14 | J11: =SUM(J8:J10) -> 100 | K11: =SUM(K8:K10) -> -110 | ... T11: =SUM(T8:T10) -> 28 | Y11: 1189 | Z11: 1298 | AA11: 1286 | AB11: 1018 | AC11: 1132 | AD11: 437 | AE11: 1009 | AF11: =SUM(AF8:AF10) -> 191 | AG11: =SUM(AG8:AG10) -> -99 | AH11: =SUM(AH8:AH10) -> -827 | AI11: =SUM(AI8:AI10) -> -121 | AJ11: =SUM(AJ8:AJ10) -> 287.054 | AK11: =SUM(AK8:AK10) -> 353.0067 | AL11: =SUM(AL8:AL10) -> 423.28904 | AM11: =SUM(AM8:AM10) -> 498.13813 | ... AS11: =SUM(AS8:AS10) -> 1058.0403
A12: =B6/T52 -> 1.2952457 | C12: Net financials items | D12: -21 | E12: -40 | F12: -47 | G12: -53 | H12: -53 | I12: -59 | J12: -80 | K12: -80 | L12: -123 | M12: -92 | N12: -67 | O12: -74 | P12: -77 | Q12: -89 | R12: -90 | S12: -81 | T12: -70 | AF12: =SUM(D12:G12) -> -161 | AG12: =28-302 -> -274 | AH12: =-327+35 -> -292 | AI12: -337 | AJ12: -150 | AK12: -150 | AL12: -150 | AM12: -150 | AN12: -150 | AO12: -150 | AP12: -150 | AQ12: -150 | AR12: -150 | AS12: -150
C13: PTP | D13: =SUM(D11:D12) -> 161 | E13: =SUM(E11:E12) -> 22 | F13: =SUM(F11:F12) -> 31 | G13: =SUM(G11:G12) -> -184 | H13: =SUM(H11:H12) -> -299 | I13: =SUM(I11:I12) -> -45 | J13: =SUM(J11:J12) -> 20 | K13: =SUM(K11:K12) -> -190 | ... T13: =SUM(T11:T12) -> -42 | AF13: =SUM(AF11:AF12) -> 30 | AG13: =SUM(AG11:AG12) -> -373 | AH13: =SUM(AH11:AH12) -> -1119 | AI13: =SUM(AI11:AI12) -> -458 | AJ13: =SUM(AJ11:AJ12) -> 137.054 | AK13: =SUM(AK11:AK12) -> 203.0067 | AL13: =SUM(AL11:AL12) -> 273.28904 | AM13: =SUM(AM11:AM12) -> 348.13813 | ... AS13: =SUM(AS11:AS12) -> 908.04028
C14: Tax | D14: -33 | E14: -5 | F14: -12 | G14: 18 | H14: 63 | I14: 11 | J14: -2 | K14: -12 | L14: 69 | M14: 54 | N14: 21 | O14: -207 | P14: -41 | Q14: -2 | R14: 61 | S14: -97 | T14: -30 | AF14: =SUM(D14:G14) -> -32 | AG14: 26 | AH14: -76 | AI14: -79 | AJ14: =AJ13*-0.22 -> -30.15188 | AK14: =AK13*-0.22 -> -44.661474 | AL14: =AL13*-0.22 -> -60.123588 | AM14: =AM13*-0.22 -> -76.590388 | AN14: =AN13*-0.22 -> -94.11674 | AO14: =AO13*-0.22 -> -112.76035 | AP14: =AP13*-0.22 -> -132.58189 | AQ14: =AQ13*-0.22 -> -153.64518 | ... AS14: =AS13*-0.22 -> -199.76886
A15: Leverage | C15: Net income | D15: =SUM(D13:D14) -> 128 | E15: =SUM(E13:E14) -> 17 | F15: =SUM(F13:F14) -> 19 | G15: =SUM(G13:G14) -> -166 | H15: =SUM(H13:H14) -> -236 | I15: =SUM(I13:I14) -> -34 | J15: =SUM(J13:J14) -> 18 | K15: =SUM(K13:K14) -> -202 | ... T15: =SUM(T13:T14) -> -72 | Y15: 828 | Z15: 455 | AA15: 1015 | AB15: 753 | AC15: 810 | AD15: 253 | AE15: 706 | AF15: =SUM(AF13:AF14) -> -2 | AG15: =SUM(AG13:AG14) -> -347 | AH15: =SUM(AH13:AH14) -> -1195 | AI15: =SUM(AI13:AI14) -> -537 | AJ15: =SUM(AJ13:AJ14) -> 106.90212 | AK15: =SUM(AK13:AK14) -> 158.34523 | AL15: =SUM(AL13:AL14) -> 213.16545 | AM15: =SUM(AM13:AM14) -> 271.54774 | ... AS15: =SUM(AS13:AS14) -> 708.27142 | AT15: =AS15*(1+$AV$20) -> 701.18871 | AU15: =AT15*(1+$AV$20) -> 694.17682 | AV15: =AU15*(1+$AV$20) -> 687.23505 | AW15: =AV15*(1+$AV$20) -> 680.3627 | AX15: =AW15*(1+$AV$20) -> 673.55907 | AY15: =AX15*(1+$AV$20) -> 666.82348 | AZ15: =AY15*(1+$AV$20) -> 660.15525 | BA15: =AZ15*(1+$AV$20) -> 653.5537 | ... DZ15: =DY15*(1+$AV$20) -> 301.43332
A16: =(T57-T45)/T26 -> 4.2892768 | C16: Shares | D16: 370 | E16: 370 | F16: 370 | G16: 370 | H16: 370 | I16: 370 | J16: 370 | K16: 370 | L16: 370 | M16: 675.05192 | N16: 675.05192 | O16: 675.05192 | P16: 675.05192 | Q16: 675.05192 | R16: 675.05192 | S16: 675.05192 | T16: 1516.6026 | Y16: 168.28131 | Z16: 168.47347 | AA16: 168.25282 | AB16: 168.25282 | AC16: 168.25282 | AD16: 168.25282 | AE16: 168.25282 | AF16: 168.25282 | AG16: 168.25282 | AH16: 675.05192 | AI16: 675.05192 | AJ16: 1516.316 | AK16: 1516.316 | AL16: 1516.316 | AM16: 1516.316 | AN16: 1516.316 | AO16: 1516.316 | AP16: 1516.316 | AQ16: 1516.316 | AR16: 1516.316 | AS16: 1516.316
C17: EPS | D17: =D15/D16 -> 0.34594595 | E17: =E15/E16 -> 0.045945946 | F17: =F15/F16 -> 0.051351351 | G17: =G15/G16 -> -0.44864865 | H17: =H15/H16 -> -0.63783784 | I17: =I15/I16 -> -0.091891892 | J17: =J15/J16 -> 0.048648649 | K17: =K15/K16 -> -0.54594595 | ... T17: =T15/T16 -> -0.047474533 | Y17: =Y15/Y16 -> 4.9203327 | Z17: =Z15/Z16 -> 2.700722 | AA17: =AA15/AA16 -> 6.0325883 | AB17: =AB15/AB16 -> 4.4754079 | AC17: =AC15/AC16 -> 4.8141838 | AD17: =AD15/AD16 -> 1.5036895 | AE17: =AE15/AE16 -> 4.1960663 | AF17: =AF15/AF16 -> -0.011886874 | ... AS17: =AS15/AS16 -> 0.46710014
C19: Revenue y/y | H19: =(H6-D6)/D6 -> -0.14236571 | I19: =(I6-E6)/E6 -> -0.20514139 | J19: =(J6-F6)/F6 -> -0.22471264 | K19: =(K6-G6)/G6 -> -0.3010582 | L19: =(L6-H6)/H6 -> -0.19315026 | M19: =(M6-I6)/I6 -> -0.051423027 | N19: =(N6-J6)/J6 -> -0.081541883 | O19: =(O6-K6)/K6 -> -0.049205148 | ... T19: =(T6-P6)/P6 -> -0.4244139 | Z19: =(Z6-Y6)/Y6 -> 0.031142997 | AA19: =(AA6-Z6)/Z6 -> 0.0075901328 | AB19: =(AB6-AA6)/AA6 -> 0.036487759 | AC19: =(AC6-AB6)/AB6 -> 0.054583996 | AD19: =(AD6-AC6)/AC6 -> -0.085355348 | AE19: =(AE6-AD6)/AD6 -> 0.076760066 | AF19: =(AF6-AE6)/AE6 -> 0.088198848 | AG19: =(AG6-AF6)/AF6 -> -0.10422667 | ... AS19: =(AS6-AR6)/AR6 -> 0.05 | AU19: Discount | AV19: 0.08
C20: Organic growth | N20: 0.06 | R20: -0.03 | S20: 0.03 | T20: 0.02 | AU20: TV | AV20: -0.01
C21: Gross margin | D21: =D8/D6 -> 0.38264091 | E21: =E8/E6 -> 0.36349614 | F21: =F8/F6 -> 0.35689655 | G21: =G8/G6 -> 0.33359788 | H21: =H8/H6 -> 0.3313792 | I21: =I8/I6 -> 0.35996119 | J21: =J8/J6 -> 0.36582654 | K21: =K8/K6 -> 0.35541257 | ... T21: =T8/T6 -> 0.34480337 | Y21: =Y8/Y6 -> 0.4 | Z21: =Z8/Z6 -> 0.39 | AA21: =AA8/AA6 -> 0.39344005 | AB21: =AB8/AB6 -> 0.38534333 | AC21: =AC8/AC6 -> 0.38083274 | AD21: =AD8/AD6 -> 0.34879523 | AE21: =AE8/AE6 -> 0.38472192 | AF21: =AF8/AF6 -> 0.35923371 | ... AS21: =AS8/AS6 -> 0.35 | AU21: NPV | AV21: =NPV(AV19,AI15:DZ15) -> 4963.8365
C22: EBIT margin | D22: =D11/D6 -> 0.048160889 | E22: =E11/E6 -> 0.015938303 | F22: =F11/F6 -> 0.022413793 | G22: =G11/G6 -> -0.034656085 | H22: =H11/H6 -> -0.075902499 | I22: =I11/I6 -> 0.0045278137 | J22: =J11/J6 -> 0.037064492 | K22: =K11/K6 -> -0.041635125 | ... T22: =T11/T6 -> 0.019662921 | Y22: =Y11/Y6 -> 0.096934616 | Z22: =Z11/Z6 -> 0.10262492 | AA22: =AA11/AA6 -> 0.10091023 | AB22: =AB11/AB6 -> 0.077068665 | AC22: =AC11/AC6 -> 0.08126346 | AD22: =AD11/AD6 -> 0.034298721 | AE22: =AE11/AE6 -> 0.073547635 | AF22: =AF11/AF6 -> 0.012793891 | ... AS22: =AS11/AS6 -> 0.1189344 | AU22: S/O | AV22: 1516.316
AU23: NPV/Share | AV23: =AV21/AV22 -> 3.2736161
C24: EBITDA | D24: -18 | E24: 254 | F24: 336 | G24: 431 | H24: 386 | I24: 303 | J24: 272 | K24: 97 | L24: 169 | M24: 176 | N24: 207 | O24: 107 | P24: 143 | Q24: 76 | R24: 154 | S24: 48 | T24: 123 | Y24: 1486 | Z24: 1585 | AA24: 1573 | AB24: 1344 | AC24: 1967 | AD24: 1426 | AE24: 1809 | AF24: 1090 | AG24: 549 | AH24: 470 | AI24: 421 | AU24: Opp-/nedside | AV24: =(AV23-B4)/B4 -> 0.79081843
C25: EBITDA % | D25: -0.005 | E25: 0.071 | F25: 0.108 | G25: 0.123 | H25: 0.102 | I25: 0.078 | J25: 0.078 | K25: 0.039 | L25: 0.068 | M25: 0.065 | N25: 0.09 | O25: 0.04 | P25: 0.055 | Q25: 0.026 | R25: 0.062 | S25: 0.034 | T25: 0.034 | Y25: 0.121 | Z25: 0.125 | AA25: 0.123 | AB25: 0.102 | AC25: 0.141 | AD25: 0.112 | AE25: 0.132 | AF25: 0.073 | AG25: 0.047 | AH25: 0.045 | AI25: =AI24/AI6 -> 0.047425932
C26: EBITDA LTM | G26: =SUM(D24:G24) -> 1003 | H26: =SUM(E24:H24) -> 1407 | I26: =SUM(F24:I24) -> 1456 | J26: =SUM(G24:J24) -> 1392 | K26: =SUM(H24:K24) -> 1058 | L26: =SUM(I24:L24) -> 841 | M26: =SUM(J24:M24) -> 714 | N26: =SUM(K24:N24) -> 649 | ... T26: =SUM(Q24:T24) -> 401
C28: Nordic y/y | H28: =(H4-D4)/D4 -> -0.039705882 | I28: =(I4-E4)/E4 -> -0.13271462 | J28: =(J4-F4)/F4 -> -0.16197975 | K28: =(K4-G4)/G4 -> -0.2372387 | L28: =(L4-H4)/H4 -> -0.25267994 | M28: =(M4-I4)/I4 -> -0.1364366 | N28: =(N4-J4)/J4 -> -0.13892617 | O28: =(O4-K4)/K4 -> -0.10516252 | ... T28: =(T4-P4)/P4 -> -0.015214385
C29: UK y/y | H29: =(H5-D5)/D5 -> 0.0023455825 | I29: =(I5-E5)/E5 -> -0.048989114 | J29: =(J5-F5)/F5 -> -0.025806452 | K29: =(K5-G5)/G5 -> -0.16304348 | L29: =(L5-H5)/H5 -> -0.10218409 | M29: =(M5-I5)/I5 -> 0.078495503 | N29: =(N5-J5)/J5 -> -0.010761589 | O29: =(O5-K5)/K5 -> 0.10689311 | ... S29: =(S5-O5)/O5 -> -1
C31: ROE | Y31: 0.241 | Z31: 0.13 | AA31: 0.278 | AB31: 0.202 | AC31: 0.204 | AD31: 0.061 | AE31: 0.151 | AF31: 0 | AG31: -0.077 | AH31: -0.31
C33: Balanse SEKm
C34: Goodwill | D34: 3093 | E34: 3160 | F34: 3187 | G34: 3232 | H34: 3275 | I34: 3461 | J34: 3366 | K34: 3247 | L34: 2631 | M34: 2617 | N34: 2626 | O34: 2190 | P34: 2069 | Q34: 2085 | R34: 687 | S34: 674 | T34: 685
C35: Other intangible fix assets | D35: 409 | E35: 400 | F35: 390 | G35: 418 | H35: 421 | I35: 478 | J35: 524 | K35: 560 | L35: 633 | M35: 672 | N35: 652 | O35: 684 | P35: 706 | Q35: 735 | R35: 508 | S35: 520 | T35: 534
C36: Tangible fixed assets | D36: 2119 | E36: 2435 | F36: 2786 | G36: 3131 | H36: 3406 | I36: 3661 | J36: 3983 | K36: 3189 | L36: 3121 | M36: 3172 | N36: 3367 | O36: 3569 | P36: 3575 | Q36: 3633 | R36: 3613 | S36: 3062 | T36: 3083
C37: Right-of-use assets | D37: 1795 | E37: 1733 | F37: 1732 | G37: 1826 | H37: 1808 | I37: 1778 | J37: 1748 | K37: 1627 | L37: 2507 | M37: 2463 | N37: 2482 | O37: 2433 | P37: 2234 | Q37: 2310 | R37: 1955 | S37: 1452 | T37: 1369
C38: Long-term receivabls (IB) | D38: 0 | E38: 0 | F38: 0 | G38: 0 | H38: 0 | I38: 0 | J38: 0 | K38: 0 | L38: 56 | M38: 59 | N38: 59 | O38: 61 | P38: 58 | Q38: 62 | R38: 62 | S38: 87 | T38: 77
C39: Long-term receivables | D39: 83 | E39: 87 | F39: 85 | G39: 86 | H39: 92 | I39: 87 | J39: 85 | K39: 79 | L39: 77 | M39: 74 | N39: 71 | O39: 90 | P39: 79 | Q39: 80 | R39: 78 | S39: 38 | T39: 38
C40: Deferred tax assets | D40: 70 | E40: 68 | F40: 137 | G40: 240 | H40: 330 | I40: 364 | J40: 378 | K40: 390 | L40: 511 | M40: 547 | N40: 577 | O40: 472 | P40: 445 | Q40: 449 | R40: 503 | S40: 200 | T40: 203
C41: Inventories | D41: 1302 | E41: 1437 | F41: 1516 | G41: 1478 | H41: 1429 | I41: 1417 | J41: 1347 | K41: 1218 | L41: 1189 | M41: 1164 | N41: 1126 | O41: 1068 | P41: 1065 | Q41: 1043 | R41: 998 | S41: 399 | T41: 421
C42: Accounts receivable | D42: 1701 | E42: 1694 | F42: 1791 | G42: 1495 | H42: 1697 | I42: 1684 | J42: 1505 | K42: 1160 | L42: 1270 | M42: 1263 | N42: 1191 | O42: 940 | P42: 1054 | Q42: 1065 | R42: 991 | S42: 486 | T42: 681
C43: Current receivables (IB) | D43: 2 | E43: 1 | F43: 1 | G43: 2 | H43: 2 | I43: 1 | J43: 8 | K43: 3 | L43: 4 | M43: 7 | N43: 6 | O43: 17 | P43: 11 | Q43: 11 | R43: 0 | S43: 16 | T43: 17
C44: Other receivables | D44: 505 | E44: 584 | F44: 598 | G44: 524 | H44: 599 | I44: 619 | J44: 852 | K44: 596 | L44: 963 | M44: 870 | N44: 883 | O44: 503 | P44: 599 | Q44: 570 | R44: 481 | S44: 339 | T44: 358
C45: Cash | D45: 1394 | E45: 905 | F45: 387 | G45: 340 | H45: 715 | I45: 667 | J45: 330 | K45: 412 | L45: 244 | M45: 0 | N45: 129 | O45: 270 | P45: 86 | Q45: 50 | R45: 0 | S45: 39 | T45: 31
C46: Assets held for sale | D46: 0 | E46: 0 | F46: 0 | G46: 0 | H46: 0 | I46: 57 | J46: 0 | K46: 1134 | L46: 0 | M46: 0 | N46: 0 | O46: 0 | P46: 0 | Q46: 0 | R46: 0 | S46: 1724 | T46: 0
...

Sheet Markets
B5: SEKm | C5: Q122 | D5: Q222 | E5: Q322 | F5: Q422 | G5: 2022 | H5: Q123 | I5: Q223 | J5: Q323 | K5: Q423 | L5: 2023 | M5: Q124 | N5: Q224 | O5: Q324 | P5: Q424 | Q5: 2024 | R5: Q125 | S5: Q225 | T5: Q325 | U5: Q425 | V5: 2025 | W5: Q126 | X5: Q226 | Y5: Q326 | Z5: Q426 | AA5: 2026
B6: Nordic
B7: Net sales | C7: 2040 | D7: 2155 | E7: 1778 | F7: 2057 | G7: =SUM(C7:F7) -> 8030 | H7: 1959 | I7: 1869 | J7: 1490 | K7: 1579 | L7: =SUM(H7:K7) -> 6897 | M7: 1464 | N7: 1614 | O7: 1283 | P7: 1404 | Q7: =SUM(M7:P7) -> 5765 | R7: 1446 | S7: 1514 | T7: 1262 | U7: 1400 | V7: =SUM(R7:U7) -> 5622 | AA7: =SUM(W7:Z7) -> 0
B8: Growth % | H8: =(H7-C7)/C7 -> -0.039705882 | I8: =(I7-D7)/D7 -> -0.13271462 | J8: =(J7-E7)/E7 -> -0.16197975 | K8: =(K7-F7)/F7 -> -0.23237725 | L8: =(L7-G7)/G7 -> -0.14109589 | M8: =(M7-H7)/H7 -> -0.25267994 | N8: =(N7-I7)/I7 -> -0.1364366 | O8: =(O7-J7)/J7 -> -0.13892617 | ... AA8: =(AA7-V7)/V7 -> -1
B9: Gross profit | C9: 737 | D9: 767 | E9: 561 | F9: 632 | G9: =SUM(C9:F9) -> 2697 | H9: 596 | I9: 596 | J9: 491 | K9: 463 | L9: =SUM(H9:K9) -> 2146 | M9: 480 | N9: 583 | O9: 441 | P9: 488 | Q9: =SUM(M9:P9) -> 1992 | R9: 507 | S9: 483 | T9: 429 | U9: 470 | V9: =SUM(R9:U9) -> 1889 | AA9: =SUM(W9:Z9) -> 0
B10: gross margin | C10: 0.361 | D10: 0.356 | E10: 0.316 | F10: 0.307 | G10: =G9/G7 -> 0.3358655 | H10: 0.304 | I10: 0.319 | J10: 0.33 | K10: 0.293 | L10: =L9/L7 -> 0.31114978 | M10: 0.328 | N10: 0.361 | O10: 0.344 | P10: 0.348 | Q10: =Q9/Q7 -> 0.34553339 | R10: =R9/R7 -> 0.35062241 | S10: =S9/S7 -> 0.31902246 | T10: =T9/T7 -> 0.33993661 | U10: =U9/U7 -> 0.33571429 | V10: =V9/V7 -> 0.33600142 | W10: =W9/W7 -> #DIV/0! | X10: =X9/X7 -> #DIV/0! | ... AA10: =AA9/AA7 -> #DIV/0!
B11: Operating profit | C11: 213 | D11: 242 | E11: 97 | F11: 43 | G11: =SUM(C11:F11) -> 595 | H11: 13 | I11: 82 | J11: 65 | K11: -34 | L11: =SUM(H11:K11) -> 126 | M11: 6 | N11: 79 | O11: 61 | P11: 79 | Q11: =SUM(M11:P11) -> 225 | R11: 87 | S11: 54 | T11: 60 | U11: 0 | V11: =SUM(R11:U11) -> 201 | AA11: =SUM(W11:Z11) -> 0
B12: Operating margin % | C12: =C11/C7 -> 0.10441176 | D12: =D11/D7 -> 0.11229698 | E12: =E11/E7 -> 0.054555681 | F12: =F11/F7 -> 0.020904229 | G12: =G11/G7 -> 0.074097136 | H12: =H11/H7 -> 0.0066360388 | I12: =I11/I7 -> 0.043873729 | J12: =J11/J7 -> 0.043624161 | ... AA12: =AA11/AA7 -> #DIV/0!
B13: UK
B14: Net sales | C14: 1279 | D14: 1286 | E14: 1240 | F14: 1196 | G14: =SUM(C14:F14) -> 5001 | H14: 1282 | I14: 1223 | J14: 1208 | K14: 1063 | L14: =SUM(H14:K14) -> 4776 | M14: 1151 | N14: 1319 | O14: 1195 | P14: 1108 | Q14: =SUM(M14:P14) -> 4773 | R14: 1028 | S14: 1181 | T14: 1046 | V14: =SUM(R14:U14) -> 3255
B15: Growth % | H15: =(H14-C14)/C14 -> 0.0023455825 | I15: =(I14-D14)/D14 -> -0.048989114 | J15: =(J14-E14)/E14 -> -0.025806452 | K15: =(K14-F14)/F14 -> -0.11120401 | L15: =(L14-G14)/G14 -> -0.044991002 | M15: =(M14-H14)/H14 -> -0.10218409 | N15: =(N14-I14)/I14 -> 0.078495503 | O15: =(O14-J14)/J14 -> -0.010761589 | ... V15: =(V14-Q14)/Q14 -> -0.31803897
B16: Gross profit | C16: 558 | D16: 530 | E16: 533 | F16: 481 | G16: =SUM(C16:F16) -> 2102 | H16: 458 | I16: 500 | J16: 477 | K16: 457 | L16: =SUM(H16:K16) -> 1892 | M16: 471 | N16: 458 | O16: 454 | P16: 452 | Q16: =SUM(M16:P16) -> 1835 | R16: 425 | S16: 491 | T16: 427 | V16: =SUM(R16:U16) -> 1343
B17: gross margin | C17: 0.436 | D17: 0.412 | E17: 0.43 | F17: 0.402 | G17: =G16/G14 -> 0.42031594 | H17: 0.357 | I17: 0.409 | J17: 0.395 | K17: 0.43 | L17: =L16/L14 -> 0.3961474 | M17: 0.409 | N17: 0.347 | O17: 0.38 | P17: 0.408 | Q17: =Q16/Q14 -> 0.38445422 | R17: =R16/R14 -> 0.41342412 | S17: =S16/S14 -> 0.41574936 | T17: =T16/T14 -> 0.4082218 | U17: =U16/U14 -> #DIV/0! | V17: =V16/V14 -> 0.41259601
B18: Operating profit | C18: 0 | D18: -101 | E18: -11 | F18: -72 | G18: =SUM(C18:F18) -> -184 | H18: -216 | I18: -28 | J18: 65 | K18: -38 | L18: =SUM(H18:K18) -> -217 | M18: -11 | N18: -211 | O18: -58 | P18: -145 | Q18: =SUM(M18:P18) -> -425 | R18: -53 | S18: -21 | T18: -261 | V18: =SUM(R18:U18) -> -335
B19: Operating margin % | C19: =C18/C14 -> 0 | D19: =D18/D14 -> -0.078538103 | E19: =E18/E14 -> -0.0088709677 | F19: =F18/F14 -> -0.060200669 | G19: =G18/G14 -> -0.036792641 | H19: =H18/H14 -> -0.16848674 | I19: =I18/I14 -> -0.022894522 | J19: =J18/J14 -> 0.053807947 | ... V19: =V18/V14 -> -0.10291859
B20: Number of stores | O20: 172 | T20: 168

Sheet Nøkkeltall
F6: 2026 | G6: 2027 | H6: 2028
E7: EV/EBIT | F7: =Modell!$B$9/Modell!AJ11 -> 15.648016 | G7: =Modell!$B$9/Modell!AK11 -> 12.724477 | H7: =Modell!$B$9/Modell!AL11 -> 10.611722
E8: P/E | F8: =Modell!$B$4/Modell!AJ17 -> 25.928632 | G8: =Modell!$B$4/Modell!AK17 -> 17.504953 | H8: =Modell!$B$4/Modell!AL17 -> 13.003166
