Workbook

Sheet Info
A2: Er markedsleder innenfor produksjon av halvledere for bluetooth - komponenter | P2: Press releases:
A3: Nordic Semiconductor er et norsk "fabless" halvlederselskap som spesialiserer seg på trådløs kommunikasjonsteknologi som driver tingenes internett (IoT) | P3: 25.08.26: EVP Short range Øyvind Strøm kjøper 2000 aksjer 160,80kr
A4: Porteføljen deres inkluderer Bluetooth low energy, ANT+, Thread Wi-Fi og Zigbee. | P4: 19.08.26: CEO Wollan kjøper 5000 aksjer til 160,87kr
A5: Short-range: Bluetooth og Zigbee | P5: 07.08.26: Kvalitetsdirektør kjøper 1 100 aksjer og styremedlem har kjøpt 1 200 aksjer
A6: Long-range: Trådløs kommunikasjon over lange distanser, hovedsaklig via mobilnett (Cellular IoT) (Satser på lønnsomhet ila 28) | P6: 26.05.26: Styreleder kjøper 1 500 aksjer på 201,3kr
A7: Other (Wi-Fi, PMIC): Wi-Fi innebærer companion chips som gir Wi-Fi når de kobles sammen med en hovedprosessor (nRF52/53/54). | P7: 12.05.26: Styreleder kjøper 1 500 aksjer på 193,3kr
A8: PMIC (Power management integrated circuit styrer strømforsyning, lading og batteridrift i IoT-enheter. (Satser på lønnsomhet ila 28) | P8: 29.04.26: EVP supply chain selger 11 000 aksjer på 185,7
P9: 20.03.26: EVP BU Long-range kjøper 1 250 aksjer på 150,6
P10: 18.02.26: Styreleder kjøper 2 500 aksjer på 140,24 kr
P11: 05.02.26: CFO selger 10 000 aksjer på 149,05 kr
P12: 07.11.25: EVP og BU head kjøper 4 000 aksjer på 133,6 kr
P13: 04.09.25: NOD henter 100 USDm for å refinansierer ved å tilbakebetale brolån på 100 USDm
J14: Segment | K14: Brikke | L14: Teknologi | M14: Status
J15: Short-Range | K15: nRF52 | L15: BLE, ANT, Thread, Zigbee | M15: Moden, høyt volum
J16: Short-Range | K16: nRF53 | L16: BLE 5.2/5.3, LE Audio, Thread, Zigbee | M16: Aktiv
J17: Short-Range | K17: nRF54 | L17: BLE 6.0, Thread, Zigbee, Matter, Wi-Fi | M17: Ny generasjon, 22nm | N17: Axon NPU | O17: EDGE
J18: Long-Range | K18: nRF91 | L18: LTE-M, NB-IoT, GPS, NTN | M18: Eksisterende, oppdatert
J19: Long-Range | K19: nRF93 | L19: LTE Cat 1 bis | M19: General availability mid-2026
J20: Long-Range | K20: nRF92 | L20: LTE-M, NB-IoT, NTN, 5G eRedCap + Axon NPU (edge AI) | M20: General availability tidlig 2027 | N20: Axon NPU | O20: EDGE
J21: Other | K21: nRF70 | L21: Wi-Fi 6 (companion chip) | M21: Aktiv, ikke lønnsom ennå
A22: nRF52 - serie: | J22: Other | K22: nPM Family | L22: Strømstyring / PMIC | M22: Aktiv, ikke lønnsom ennå
A23: Lansert: 2015
A24: Tekonlogi: Bluetooth low energy (BLE), ANT, Thread, Zigbee, 2.4 GHz
A25: Bruksområder: Smarthus (lysbrytrere, sensorer), Wearables (fitnessklokker (Garmin), sportenheter), HID (Mus, Tastatur, fjernkontroller)
A26: Funkjson: Balanse mellom ytelse og lavt strømforbruk.
A28: nRF53 - serie:
A29: Lansert: 2020
A30: Teknologi: BLE 5.2/5.3, LE audio, Thread, Zigbee
A31: Bruksområder: Avansert lyd (LE audio, høreapparater), Mesh-nettverker (Matter, Zigbee)
A32: Funksjon: Første dual-core fra Nordic. Høy ytelse, større for ny lydstandard (LE audio) | K32: CMD 2024
A34: nRF54 - serie: | B34: Modest growth in 25, set to accelerate from 26 onwards (CMD)
A35: lansert 2024 (54H), 24/25 (54L) | Z35: Topp 10 største kunder står for 57% av inntektene
A36: Teknologier: BLE 6.0, Thread, Zigbee, Matter, sidewalk, Wi-Fi
A37: Bruksomårder: Fremtidens wearables, smarthelse, AI/ML på enhet, Kompleks trådløs kommunikasjon med lavt strømforbuk
A38: Funksjon: Ny 22nm arkitektur. Kombinerere Arm Cortex-m33 + RISC-V. Svært lavt strømforbuk, fremtidens serie
A40: nRF70 - serie:
A41: lansert: 2022
A42: Teknologi: Wi-Fi 6 (2.4 GHz)
A43: Bruksområder: Smarthus, industrielle gateways, IoT-enheter med behov for høy båndbredde
A44: Funksjon: Companion chip som kobles sammen med nRF52/53/54 for å gi Wi-Fi-tilgang. Ikke en SoC alene.
...

Sheet Modell
A3: Kapitalstruktur | C3: USDm | D3: Q122 | E3: Q222 | F3: Q322 | G3: Q422 | H3: Q123 | I3: Q223 | J3: Q323 | K3: Q423 | L3: Q124 | M3: Q224 | N3: Q324 | O3: Q424 | P3: Q125 | Q3: Q225 | R3: Q325 | S3: Q425 | T3: Q126 | U3: Q226 | V3: Q326 | W3: Q426 | Y3: FY 2019 | Z3: FY 2020 | AA3: FY 2021 | AB3: FY 2022 | AC3: FY 2023 | AD3: FY 2024 | AE3: FY 2025 | AF3: FY 2026 | AG3: FY 2027 | AH3: FY 2028 | AI3: FY 2029 | AJ3: FY 2030 | AK3: FY 2031 | AL3: FY 2032 | AM3: FY 2033 | AN3: FY 2034 | AO3: FY 2035
A4: price | B4: 177 | C4: Revenue | D4: 183.086 | E4: 200.187 | F4: 202.087 | G4: 191.374 | H4: 145.428 | I4: 154.217 | J4: 135.031 | K4: 108.193 | L4: 74.498 | M4: 127.949 | N4: 158.773 | O4: 150.2 | P4: 155.068 | Q4: 164 | R4: 179 | S4: 169.509 | T4: 192.443 | U4: 218.566 | Y4: 288.395 | Z4: 405.217 | AA4: 610.528 | AB4: =SUM(D4:G4) -> 776.734 | AC4: =SUM(H4:K4) -> 542.869 | AD4: =SUM(L4:O4) -> 511.42 | AE4: 668 | AF4: =AE4*1.25 -> 835 | AG4: =AF4*1.2 -> 1002 | AH4: =AG4*1.2 -> 1202.4 | AI4: =AH4*1.2 -> 1442.88 | AJ4: =AI4*1.2 -> 1731.456 | AK4: =AJ4*1.2 -> 2077.7472 | AL4: =AK4*1.2 -> 2493.2966 | AM4: =AL4*1.2 -> 2991.956 | AN4: =AM4*1.2 -> 3590.3472 | AO4: =AN4*1.2 -> 4308.4166
A5: S/O (m) | B5: 199.8 | C5: COGS | D5: -73.763 | E5: -89.347 | F5: -86.35 | G5: -90.48 | H5: -67.874 | I5: -72.473 | J5: -66.875 | K5: -51.936 | L5: -38.748 | M5: -74.178 | N5: -80.115 | O5: -76.406 | P5: -78.234 | Q5: -80.789 | R5: -86 | S5: -76 | T5: -92.155 | U5: -102.484 | Y5: -141.29 | Z5: -190.69 | AA5: -283.415 | AB5: =SUM(D5:G5) -> -339.94 | AC5: =SUM(H5:K5) -> -259.158 | AD5: =SUM(L5:O5) -> -269.447 | AE5: -321 | AF5: =AF4*-0.48 -> -400.8 | AG5: =AG4*-0.48 -> -480.96 | AH5: =AH4*-0.48 -> -577.152 | AI5: =AI4*-0.48 -> -692.5824 | AJ5: =AJ4*-0.48 -> -831.09888 | AK5: =AK4*-0.48 -> -997.31866 | AL5: =AL4*-0.48 -> -1196.7824 | AM5: =AM4*-0.48 -> -1436.1389 | ... AO5: =AO4*-0.48 -> -2068.04
A6: MC (NOKm) | B6: =B4*B5 -> 35364.6 | C6: Gross profit | D6: =SUM(D4:D5) -> 109.323 | E6: =SUM(E4:E5) -> 110.84 | F6: =SUM(F4:F5) -> 115.737 | G6: =SUM(G4:G5) -> 100.894 | H6: =SUM(H4:H5) -> 77.554 | I6: =SUM(I4:I5) -> 81.744 | J6: =SUM(J4:J5) -> 68.156 | K6: =SUM(K4:K5) -> 56.257 | ... U6: =SUM(U4:U5) -> 116.082 | Y6: =SUM(Y4:Y5) -> 147.105 | Z6: =SUM(Z4:Z5) -> 214.527 | AA6: =SUM(AA4:AA5) -> 327.113 | AB6: =SUM(AB4:AB5) -> 436.794 | AC6: =SUM(AC4:AC5) -> 283.711 | AD6: =SUM(AD4:AD5) -> 241.973 | AE6: =SUM(AE4:AE5) -> 347 | AF6: =SUM(AF4:AF5) -> 434.2 | ... AO6: =SUM(AO4:AO5) -> 2240.3766
A7: Cash (NOKm) | B7: 5798.2116 | C7: Payroll expense | D7: -40.084 | E7: -39.071 | F7: -39.479 | G7: -42.806 | H7: -43.7 | I7: -33.452 | J7: -35.447 | K7: -40.391 | L7: -40.432 | M7: -42.207 | N7: -43.934 | O7: -43.749 | P7: -43.137 | Q7: -41.446 | R7: -56.361 | S7: -53.063 | T7: -56.157 | U7: -56.905 | Y7: -80.281 | Z7: -101.211 | AA7: -149.824 | AB7: =SUM(D7:G7) -> -161.44 | AC7: =SUM(H7:K7) -> -152.99 | AD7: =SUM(L7:O7) -> -170.322 | AE7: -194 | AF7: =AE7*1.17 -> -226.98 | AG7: =AF7*1.16 -> -263.2968 | AH7: =AG7*1.16 -> -305.42429 | AI7: =AH7*1.16 -> -354.29217 | AJ7: =AI7*1.16 -> -410.97892 | AK7: =AJ7*1.16 -> -476.73555 | AL7: =AK7*1.16 -> -553.01324 | AM7: =AL7*1.16 -> -641.49536 | AN7: =AM7*1.16 -> -744.13461 | AO7: =AN7*1.16 -> -863.19615
A8: Debt (NOKm) | B8: 1012.6356 | C8: Other opex | D8: -14.506 | E8: -19.84 | F8: -16.123 | G8: -19.215 | H8: -19.298 | I8: -19.775 | J8: -19.863 | K8: -22.754 | L8: -18.149 | M8: -18.796 | N8: -18.559 | O8: -21.376 | P8: -18.955 | Q8: -20.945 | R8: -21 | S8: -25 | T8: -22.868 | U8: -25.511 | Y8: -33.665 | Z8: -35.954 | AA8: -52 | AB8: =SUM(D8:G8) -> -69.684 | AC8: =SUM(H8:K8) -> -81.69 | AD8: =SUM(L8:O8) -> -76.88 | AE8: -86 | AF8: =AE8*1.18 -> -101.48 | AG8: =AF8*1.05 -> -106.554 | AH8: =AG8*1.05 -> -111.8817 | AI8: =AH8*1.05 -> -117.47579 | AJ8: =AI8*1.05 -> -123.34957 | AK8: =AJ8*1.05 -> -129.51705 | AL8: =AK8*1.05 -> -135.99291 | AM8: =AL8*1.05 -> -142.79255 | AN8: =AM8*1.05 -> -149.93218 | AO8: =AN8*1.05 -> -157.42879
A9: EV (NOKm) | B9: =B6-B7+B8 -> 30579.024 | C9: EBITDA | D9: =SUM(D6:D8) -> 54.733 | E9: =SUM(E6:E8) -> 51.929 | F9: =SUM(F6:F8) -> 60.135 | G9: =SUM(G6:G8) -> 38.873 | H9: =SUM(H6:H8) -> 14.556 | I9: =SUM(I6:I8) -> 28.517 | J9: =SUM(J6:J8) -> 12.846 | K9: =SUM(K6:K8) -> -6.888 | ... U9: =SUM(U6:U8) -> 33.666 | Y9: =SUM(Y6:Y8) -> 33.159 | Z9: =SUM(Z6:Z8) -> 77.362 | AA9: =SUM(AA6:AA8) -> 125.289 | AB9: =SUM(AB6:AB8) -> 205.67 | AC9: =SUM(AC6:AC8) -> 49.031 | AD9: =SUM(AD6:AD8) -> -5.229 | AE9: =SUM(AE6:AE8) -> 67 | AF9: =SUM(AF6:AF8) -> 105.74 | ... AO9: =SUM(AO6:AO8) -> 1219.7517
C10: D/A | D10: -10.038 | E10: -10.55 | F10: -11.627 | G10: -11.852 | H10: -11.509 | I10: -10.935 | J10: -10.747 | K10: -11.137 | L10: -10.655 | M10: -9.562 | N10: -9.98 | O10: -10.377 | P10: -9.03 | Q10: -9.361 | R10: -11.2 | S10: -13.441 | T10: -11.17 | U10: -11.36 | Y10: -23.535 | Z10: -31 | AA10: -37.798 | AB10: =SUM(D10:G10) -> -44.067 | AC10: =SUM(H10:K10) -> -44.328 | AD10: =SUM(L10:O10) -> -40.574 | AE10: -43 | AF10: -40 | AG10: -40 | AH10: -40 | AI10: -40 | AJ10: -40 | AK10: -40 | AL10: -40 | AM10: -40 | AN10: -40 | AO10: -40
A11: USD/NOK | B11: 9.8 | C11: operating profit (EBIT) | D11: =SUM(D9:D10) -> 44.695 | E11: =SUM(E9:E10) -> 41.379 | F11: =SUM(F9:F10) -> 48.508 | G11: =SUM(G9:G10) -> 27.021 | H11: =SUM(H9:H10) -> 3.047 | I11: =SUM(I9:I10) -> 17.582 | J11: =SUM(J9:J10) -> 2.099 | K11: =SUM(K9:K10) -> -18.025 | ... U11: =SUM(U9:U10) -> 22.306 | Y11: =SUM(Y9:Y10) -> 9.624 | Z11: =SUM(Z9:Z10) -> 46.362 | AA11: =SUM(AA9:AA10) -> 87.491 | AB11: =SUM(AB9:AB10) -> 161.603 | AC11: =SUM(AC9:AC10) -> 4.703 | AD11: =SUM(AD9:AD10) -> -45.803 | AE11: =SUM(AE9:AE10) -> 24 | AF11: =SUM(AF9:AF10) -> 65.74 | ... AO11: =SUM(AO9:AO10) -> 1179.7517
C12: Share of profit from associates | D12: 0 | E12: 0 | F12: 0 | G12: 0 | H12: 0 | I12: 0 | J12: 0 | K12: 0 | L12: 0 | M12: -0.116 | N12: -0.116 | O12: -0.028 | P12: -0.131 | Q12: -0.128 | R12: 0 | S12: 0 | T12: 0 | U12: 0 | Y12: 0 | Z12: =0 -> 0 | AA12: 0 | AB12: 0 | AC12: 0 | AD12: 0 | AE12: 0 | AF12: 0 | AG12: 0 | AH12: 0 | AI12: 0 | AJ12: 0 | AK12: 0 | AL12: 0 | AM12: 0 | AN12: 0 | AO12: 0
A13: Gearing | B13: =(T51-T42)/AF9 -> -1.6832325 | C13: Net interest income | D13: -0.056 | E13: 0.158 | F13: 0.782 | G13: 4.05 | H13: 1.494 | I13: 1.578 | J13: 0.521 | K13: 2.443 | L13: 0.496 | M13: 0.433 | N13: -1.143 | O13: -0.729 | P13: -0.525 | Q13: -0.333 | R13: -1.7 | S13: -0.69 | T13: -1.195 | U13: -0.636 | Y13: =1.9-1.1 -> 0.8 | Z13: =0.642-1.416 -> -0.774 | AA13: =0.73-1.129 -> -0.399 | AB13: =SUM(D13:G13) -> 4.934 | AC13: =SUM(H13:K13) -> 6.036 | AD13: =SUM(L13:O13) -> -0.943 | AE13: -3 | AF13: 0 | AG13: 0 | AH13: 0 | AI13: 0 | AJ13: 0 | AK13: 0 | AL13: 0 | AM13: 0 | AN13: 0 | AO13: 0
C14: Net foreign exhange | D14: -0.19 | E14: 5.112 | F14: 1.985 | G14: -6.287 | H14: 3.853 | I14: 0.42 | J14: -0.915 | K14: -2.001 | L14: 2.356 | M14: -1.501 | N14: 0.575 | O14: 2.389 | P14: -3 | Q14: -0.926 | R14: -1.875 | S14: -1.117 | T14: 0.679 | U14: 0 | Y14: -0.375 | Z14: -2 | AA14: 0.739 | AB14: =SUM(D14:G14) -> 0.62 | AC14: =SUM(H14:K14) -> 1.357 | AD14: =SUM(L14:O14) -> 3.819 | AE14: -7 | AF14: 0 | AG14: 0 | AH14: 0 | AI14: 0 | AJ14: 0 | AK14: 0 | AL14: 0 | AM14: 0 | AN14: 0 | AO14: 0
C15: PTP | D15: =SUM(D11:D14) -> 44.449 | E15: =SUM(E11:E14) -> 46.649 | F15: =SUM(F11:F14) -> 51.275 | G15: =SUM(G11:G14) -> 24.784 | H15: =SUM(H11:H14) -> 8.394 | I15: =SUM(I11:I14) -> 19.58 | J15: =SUM(J11:J14) -> 1.705 | K15: =SUM(K11:K14) -> -17.583 | ... U15: =SUM(U11:U14) -> 21.67 | Y15: =SUM(Y11:Y14) -> 10.049 | Z15: =SUM(Z11:Z14) -> 43.588 | AA15: =SUM(AA11:AA14) -> 87.831 | AB15: =SUM(AB11:AB14) -> 167.157 | AC15: =SUM(AC11:AC14) -> 12.096 | AD15: =SUM(AD11:AD14) -> -42.927 | AE15: =SUM(AE11:AE14) -> 14 | AF15: =SUM(AF11:AF14) -> 65.74 | ... AO15: =SUM(AO11:AO14) -> 1179.7517
C16: tax | D16: -10.711 | E16: -13.645 | F16: -27.113 | G16: 6.652 | H16: -5.354 | I16: -3.726 | J16: -0.527 | K16: 5.16 | L16: 4.902 | M16: 2.927 | N16: 0.671 | O16: -3.815 | P16: -0.886 | Q16: 0.092 | R16: 0.085 | S16: 4.449 | T16: 1 | U16: -5.217 | Y16: -2.3 | Z16: -4.5 | AA16: -16.089 | AB16: =SUM(D16:G16) -> -44.817 | AC16: =SUM(H16:K16) -> -4.447 | AD16: =SUM(L16:O16) -> 4.685 | AE16: 4 | AF16: =AF15*-0.22 -> -14.4628 | AG16: =AG15*-0.22 -> -24.461624 | AH16: =AH15*-0.22 -> -36.947243 | AI16: =AI15*-0.22 -> -52.476521 | AJ16: =AJ15*-0.22 -> -71.726297 | AK16: =AK15*-0.22 -> -95.518707 | AL16: =AL15*-0.22 -> -124.85178 | AM16: =AM15*-0.22 -> -160.93642 | ... AO16: =AO15*-0.22 -> -259.54537
C17: Net income | D17: =SUM(D15:D16) -> 33.738 | E17: =SUM(E15:E16) -> 33.004 | F17: =SUM(F15:F16) -> 24.162 | G17: =SUM(G15:G16) -> 31.436 | H17: =SUM(H15:H16) -> 3.04 | I17: =SUM(I15:I16) -> 15.854 | J17: =SUM(J15:J16) -> 1.178 | K17: =SUM(K15:K16) -> -12.423 | ... U17: =SUM(U15:U16) -> 16.453 | Y17: =SUM(Y15:Y16) -> 7.749 | Z17: =SUM(Z15:Z16) -> 39.088 | AA17: =SUM(AA15:AA16) -> 71.742 | AB17: =SUM(AB15:AB16) -> 122.34 | AC17: =SUM(AC15:AC16) -> 7.649 | AD17: =SUM(AD15:AD16) -> -38.242 | AE17: =SUM(AE15:AE16) -> 18 | AF17: =SUM(AF15:AF16) -> 51.2772 | ... AO17: =SUM(AO15:AO16) -> 920.20632 | AP17: =AO17*(1+$AR$23) -> 911.00426 | AQ17: =AP17*(1+$AR$23) -> 901.89421 | AR17: =AQ17*(1+$AR$23) -> 892.87527 | AS17: =AR17*(1+$AR$23) -> 883.94652 | AT17: =AS17*(1+$AR$23) -> 875.10705 | AU17: =AT17*(1+$AR$23) -> 866.35598 | AV17: =AU17*(1+$AR$23) -> 857.69242 | AW17: =AV17*(1+$AR$23) -> 849.1155 | ... JO17: =JN17*(1+$AR$23) -> 87.603357
C18: EPS (NOK) | D18: =(D17*$B$11)/D19 -> 1.7149873 | E18: =(E17*$B$11)/E19 -> 1.6776762 | F18: =(F17*$B$11)/F19 -> 1.2282152 | G18: =(G17*$B$11)/G19 -> 1.5979708 | H18: =(H17*$B$11)/H19 -> 0.15453084 | I18: =(I17*$B$11)/I19 -> 0.80589865 | J18: =(J17*$B$11)/J19 -> 0.059880699 | K18: =(K17*$B$11)/K19 -> -0.6314923 | ... M18: =(M17*$B$11)/M19 -> -0.76508014 | N18: =(N17*B11)/N19 -> 0.31373826 | O18: =(O17*$B$11)/O19 -> -0.1977893 | P18: =(P17*$B$11)/P19 -> 0.059474039 | Q18: =(Q17*$B$11)/Q19 -> 0.51666165 | R18: =(R17*$B$11)/R19 -> 0.046551835 | S18: =(S17*$B$11)/S19 -> 0.22795192 | T18: =(T17*$B$11)/T19 -> 0.51883957 | U18: =(U17*$B$11)/U19 -> 0.80707833 | Y18: =(Y17*$B$11)/Y19 -> 0.43051464 | Z18: =(Z17*$B$11)/Z19 -> 1.967409 | AA18: =(AA17*$B$11)/AA19 -> 3.6420655 | AB18: =(AB17*$B$11)/AB19 -> 6.2651582 | AC18: =(AC17*$B$11)/AC19 -> 0.38499569 | AD18: =(AD17*$B$11)/AD19 -> -1.9248274 | AE18: =(AE17*$B$11)/AE19 -> 0.90599063 | AF18: =(AF17*$B$11)/AF19 -> 2.5153295 | ... AO18: =(AO17*$B$11)/AO19 -> 45.139402
C19: Shares | D19: 192.79 | E19: 192.79 | F19: 192.79 | G19: 192.79 | H19: 192.79 | I19: 192.79 | J19: 192.79 | K19: 192.79 | L19: 192.79 | M19: 192.79 | N19: 192.79 | O19: 192.79 | P19: 192.79 | Q19: 192.79 | R19: 199.7816 | S19: 199.7816 | T19: 199.7816 | U19: 199.7816 | Y19: 176.394 | Z19: 194.704 | AA19: 193.042 | AB19: 191.365 | AC19: 194.704 | AD19: 194.704 | AE19: 194.704 | AF19: 199.7816 | AG19: 199.7816 | AH19: 199.7816 | AI19: 199.7816 | AJ19: 199.7816 | AK19: 199.7816 | AL19: 199.7816 | AM19: 199.7816 | AN19: 199.7816 | AO19: 199.7816
C21: Revenue y/y | D21: 0.28 | E21: 0.36 | F21: 0.36 | G21: 0.12 | H21: =(H4-D4)/D4 -> -0.20568476 | I21: =(I4-E4)/E4 -> -0.22963529 | J21: =(J4-F4)/F4 -> -0.33181748 | K21: =(K4-G4)/G4 -> -0.43465152 | L21: =(L4-H4)/H4 -> -0.48773276 | M21: =(M4-I4)/I4 -> -0.17033142 | N21: =(N4-J4)/J4 -> 0.17582629 | O21: =(O4-K4)/K4 -> 0.38825987 | ... U21: =(U4-Q4)/Q4 -> 0.33271951 | Z21: =(Z4-Y4)/Y4 -> 0.40507637 | AA21: =(AA4-Z4)/Z4 -> 0.50666927 | AB21: =(AB4-AA4)/AA4 -> 0.27223321 | AC21: =(AC4-AB4)/AB4 -> -0.30108763 | AD21: =(AD4-AC4)/AC4 -> -0.057931103 | AE21: =(AE4-AD4)/AD4 -> 0.30616714 | AF21: =(AF4-AE4)/AE4 -> 0.25 | AG21: =(AG4-AF4)/AF4 -> 0.2 | ... AO21: =(AO4-AN4)/AN4 -> 0.2
C22: Revenue Q/Q | E22: =(E4-D4)/D4 -> 0.093404193 | F22: =(F4-E4)/E4 -> 0.0094911258 | G22: =(G4-F4)/F4 -> -0.053011822 | H22: =(H4-G4)/G4 -> -0.24008486 | I22: =(I4-H4)/H4 -> 0.060435404 | J22: =(J4-I4)/I4 -> -0.12440911 | K22: =(K4-J4)/J4 -> -0.19875436 | L22: =(L4-K4)/K4 -> -0.3114342 | ... U22: =(U4-T4)/T4 -> 0.13574409 | AQ22: Discount | AR22: 0.08
C23: Gross margin | D23: =D6/D4 -> 0.59711283 | E23: =E6/E4 -> 0.55368231 | F23: =F6/F4 -> 0.57270878 | G23: =G6/G4 -> 0.5272085 | H23: =H6/H4 -> 0.53328107 | I23: =I6/I4 -> 0.53005829 | J23: =J6/J4 -> 0.50474336 | K23: =K6/K4 -> 0.51996894 | ... U23: =U6/U4 -> 0.53110731 | Y23: =Y6/Y4 -> 0.51008166 | Z23: =Z6/Z4 -> 0.52941264 | AA23: =AA6/AA4 -> 0.53578706 | AB23: =AB6/AB4 -> 0.56234696 | AC23: =AC6/AC4 -> 0.52261411 | AD23: =AD6/AD4 -> 0.47313949 | AE23: =AE6/AE4 -> 0.51946108 | AF23: =AF6/AF4 -> 0.52 | ... AO23: =AO6/AO4 -> 0.52 | AQ23: TV | AR23: -0.01
C24: EBITDA margin | D24: =D9/D4 -> 0.29894694 | E24: =E9/E4 -> 0.25940246 | F24: =F9/F4 -> 0.29756986 | G24: =G9/G4 -> 0.20312582 | H24: =H9/H4 -> 0.10009077 | I24: =I9/I4 -> 0.18491476 | J24: =J9/J4 -> 0.09513371 | K24: =K9/K4 -> -0.063664008 | ... U24: =U9/U4 -> 0.15403128 | Y24: =Y9/Y4 -> 0.11497772 | Z24: =Z9/Z4 -> 0.19091499 | AA24: =AA9/AA4 -> 0.20521418 | AB24: =AB9/AB4 -> 0.2647882 | AC24: =AC9/AC4 -> 0.09031829 | AD24: =AD9/AD4 -> -0.010224473 | AE24: =AE9/AE4 -> 0.1002994 | AF24: =AF9/AF4 -> 0.12663473 | ... AO24: =AO9/AO4 -> 0.28310904 | AQ24: NPV USD | AR24: =NPV(AR22,AE17:JO17) -> 6307.816
C25: EBIT margin | D25: =D11/D4 -> 0.24412025 | E25: =E11/E4 -> 0.20670173 | F25: =F11/F4 -> 0.24003523 | G25: =G11/G4 -> 0.14119473 | H25: =H11/H4 -> 0.020951949 | I25: =I11/I4 -> 0.11400818 | J25: =J11/J4 -> 0.015544579 | K25: =K11/K4 -> -0.16660043 | ... U25: =U11/U4 -> 0.10205613 | Y25: =Y11/Y4 -> 0.033370898 | Z25: =Z11/Z4 -> 0.11441277 | AA25: =AA11/AA4 -> 0.14330383 | AB25: =AB11/AB4 -> 0.20805449 | AC25: =AC11/AC4 -> 0.0086632318 | AD25: =AD11/AD4 -> -0.08956044 | AE25: =AE11/AE4 -> 0.035928144 | AF25: =AF11/AF4 -> 0.078730539 | ... AO25: =AO11/AO4 -> 0.27382489 | AQ25: NPV NOK | AR25: =AR24*B11 -> 61816.597
AQ26: S/O | AR26: 199.7816
AQ27: NPV/Share | AR27: =AR25/AR26 -> 309.42087
C28: Balanse (USD million) | AQ28: Opp-/nedside | AR28: =(AR27-B4)/B4 -> 0.74814053
C30: Goodwill | D30: 2.2 | E30: 2 | F30: 2.2 | G30: 2.2 | H30: 10 | I30: 11 | J30: 10 | K30: 11 | L30: 11 | M30: 11 | N30: 10.934 | O30: 10.88 | P30: 10.906 | Q30: 11 | R30: 102.5 | S30: 101 | T30: 101.296 | U30: 101.294 | Y30: 0 | Z30: 0.249 | AA30: 0.249 | AB30: 2.2 | AC30: 11 | AD30: 10.88 | AE30: 101
C31: Capitalized dev expenses | D31: 26.6 | E31: 29.9 | F31: 26.6 | G31: 26.6 | H31: 26.9 | I31: 38.9 | J31: 34.5 | K31: 38.9 | L31: 50 | M31: 42 | N31: 44.269 | O31: 50.076 | P31: 50.486 | Q31: 52.449 | R31: 52 | S31: 52.9 | T31: 53.219 | U31: 52.892 | Y31: 33.99 | Z31: 34.563 | AA31: 31.542 | AB31: 26.6 | AC31: 38.9 | AD31: 50.076 | AE31: 52.9
C32: Software | D32: 11.65 | E32: 13.7 | F32: 11.6 | G32: 11.65 | H32: 12.6 | I32: 19 | J32: 10.9 | K32: 19 | L32: 13 | M32: 16.9 | N32: 14.506 | O32: 13.762 | P32: 12.512 | Q32: 11.5 | R32: 56.458 | S32: 54 | T32: 52.5 | U32: 51.793 | Y32: 11.408 | Z32: 19.286 | AA32: 15.232 | AB32: 11.65 | AC32: 19 | AD32: 13.762 | AE32: 54
C33: Deferred tax assets | D33: 4.5 | E33: 5.5 | F33: 4.55 | G33: 4.5 | H33: 3.7 | I33: 5.8 | J33: 3.6 | K33: 5.8 | L33: 15 | M33: 15 | N33: 16.942 | O33: 13.097 | P33: 14.729 | Q33: 16.863 | R33: 19.2 | S33: 23 | T33: 27.475 | U33: 22.947 | Y33: 2.813 | Z33: 3.029 | AA33: 5.748 | AB33: 4.5 | AC33: 5.8 | AD33: 13.097 | AE33: 23
C34: fixed assets | D34: 35.6 | E34: 31.45 | F34: 35.6 | G34: 35.6 | H34: 35.4 | I34: 29 | J34: 30.7 | K34: 29 | L34: 20 | M34: 23 | N34: 23.624 | O34: 21.955 | P34: 20.279 | Q34: 25.691 | R34: 27.537 | S34: 28.805 | T34: 34.078 | U34: 36.956 | Y34: 26.625 | Z34: 24.96 | AA34: 28.82 | AB34: 35.6 | AC34: 29 | AD34: 21.955 | AE34: 28.805
C35: Right-of-use assets | D35: 21.4 | E35: 18 | F35: 21.4 | G35: 21.4 | H35: 20.7 | I35: 54.6 | J35: 34.8 | K35: 54.6 | L35: 53 | M35: 56.5 | N35: 55.453 | O35: 52.358 | P35: 52.804 | Q35: 51.312 | R35: 49.257 | S35: 49.66 | T35: 49.507 | U35: 47.403 | Y35: 23.934 | Z35: 20.616 | AA35: 14.923 | AB35: 21.4 | AC35: 54.6 | AD35: 52.358 | AE35: 49.66
C36: Investments in JV | D36: 0 | E36: 0 | F36: 0 | G36: 0 | H36: 0 | I36: 0 | J36: 0 | K36: 0 | L36: 1 | M36: 0.321 | N36: 0.205 | O36: 0.177 | P36: 0.561 | Q36: 0.434 | R36: 0.337 | S36: 0 | T36: 0 | U36: 0 | Y36: 0 | Z36: 1.59 | AA36: 6.696 | AB36: 0 | AC36: 0 | AD36: 0.177 | AE36: 0
C37: Other long term assets | D37: 0 | E37: 0 | F37: 0 | G37: 0 | H37: 100 | I37: 94.4 | J37: 100 | K37: 94.4 | L37: 90 | M37: 94.4 | N37: 93.067 | O37: 91.14 | P37: 90.348 | Q37: 93.662 | R37: 92.612 | S37: 90.711 | T37: 90.417 | U37: 86.985 | Y37: 0 | Z37: 0 | AA37: 0 | AB37: 0 | AC37: 94.4 | AD37: 91.14 | AE37: 90.711
C38: Total non-current assets | D38: =SUM(D30:D37) -> 101.95 | E38: =SUM(E30:E37) -> 100.55 | F38: =SUM(F30:F37) -> 101.95 | G38: =SUM(G30:G37) -> 101.95 | H38: =SUM(H30:H37) -> 209.3 | I38: =SUM(I30:I37) -> 252.7 | J38: =SUM(J30:J37) -> 224.5 | K38: =SUM(K30:K37) -> 252.7 | ... U38: =SUM(U30:U37) -> 400.27 | Y38: =SUM(Y30:Y37) -> 98.77 | Z38: =SUM(Z30:Z37) -> 104.293 | AA38: =SUM(AA30:AA37) -> 103.21 | AB38: =SUM(AB30:AB37) -> 101.95 | AC38: =SUM(AC30:AC37) -> 252.7 | AD38: =SUM(AD30:AD37) -> 253.445 | AE38: =SUM(AE30:AE37) -> 400.076
C39: Inventory | D39: 102 | E39: 63.9 | F39: 102 | G39: 102 | H39: 126.914 | I39: 163 | J39: 158.2 | K39: 163 | L39: 144 | M39: 170.441 | N39: 181.475 | O39: 171.907 | P39: 144.088 | Q39: 135.85 | R39: 133.358 | S39: 154.994 | T39: 183.674 | U39: 217.294 | Y39: 53.067 | Z39: 61.955 | AA39: 54.943 | AB39: 102 | AC39: 163 | AD39: 171.907 | AE39: 154.994
C40: AR | D40: 175.12 | E40: 186.6 | F40: 175 | G40: 175 | H40: 176.1 | I40: 133.3 | J40: 160.45 | K40: 133.3 | L40: 73 | M40: 106.3 | N40: 110.595 | O40: 66.412 | P40: 72.85 | Q40: 66 | R40: 99 | S40: 93.488 | T40: 107.156 | U40: 115.653 | Y40: 64.519 | Z40: 88.034 | AA40: 141.748 | AB40: 175 | AC40: 133.3 | AD40: 66.412 | AE40: 93.488
C41: Other Current receivables | D41: 17.5 | E41: 15.2 | F41: 17.5 | G41: 17.5 | H41: 18 | I41: 21.8 | J41: 18 | K41: 21.8 | L41: 27 | M41: 23.4 | N41: 19.7 | O41: 27.029 | P41: 27.324 | Q41: 29.253 | R41: 27.2 | S41: 26.957 | T41: 29.55 | U41: 32.024 | Y41: 11.359 | Z41: 10.062 | AA41: 11.283 | AB41: 17.5 | AC41: 21.8 | AD41: 27.029 | AE41: 26.957
C42: Cash | D42: 379 | E42: 319.85 | F42: 379 | G42: 379 | H42: 233.26 | I42: 290.9 | J42: 228.7 | K42: 290.9 | L42: 307 | M42: 257.9 | N42: 260.85 | O42: 287.914 | P42: 307.454 | Q42: 335.473 | R42: 308.9 | S42: 307.402 | T42: 279.665 | U42: 276.106 | Y42: 90.645 | Z42: 238.615 | AA42: 273.43 | AB42: 379 | AC42: 290.9 | AD42: 287.914 | AE42: 307.402
C43: Total current assets | D43: =SUM(D39:D42) -> 673.62 | E43: =SUM(E39:E42) -> 585.55 | F43: =SUM(F39:F42) -> 673.5 | G43: =SUM(G39:G42) -> 673.5 | H43: =SUM(H39:H42) -> 554.274 | I43: =SUM(I39:I42) -> 609 | J43: =SUM(J39:J42) -> 565.35 | K43: =SUM(K39:K42) -> 609 | ... U43: =SUM(U39:U42) -> 641.077 | Y43: =SUM(Y39:Y42) -> 219.59 | Z43: =SUM(Z39:Z42) -> 398.666 | AA43: =SUM(AA39:AA42) -> 481.404 | AB43: =SUM(AB39:AB42) -> 673.5 | AC43: =SUM(AC39:AC42) -> 609 | AD43: =SUM(AD39:AD42) -> 553.262 | AE43: =SUM(AE39:AE42) -> 582.841
C44: Total Assets | D44: =D43+D38 -> 775.57 | E44: =E43+E38 -> 686.1 | F44: =F43+F38 -> 775.45 | G44: =G43+G38 -> 775.45 | H44: =H43+H38 -> 763.574 | I44: =I43+I38 -> 861.7 | J44: =J43+J38 -> 789.85 | K44: =K43+K38 -> 861.7 | ... U44: =U43+U38 -> 1041.347 | Y44: =Y43+Y38 -> 318.36 | Z44: =Z43+Z38 -> 502.959 | AA44: =AA43+AA38 -> 584.614 | AB44: =AB43+AB38 -> 775.45 | AC44: =AC43+AC38 -> 861.7 | AD44: =AD43+AD38 -> 806.707 | AE44: =AE43+AE38 -> 982.917
...

Sheet Segmenter
B3: USD million | C3: Q122 | D3: Q222 | E3: Q322 | F3: Q422 | G3: 2022 | H3: Q123 | I3: Q223 | J3: Q323 | K3: Q423 | L3: 2023 | M3: Q124 | N3: Q224 | O3: Q324 | P3: Q424 | Q3: 2024 | R3: Q125 | S3: Q225 | T3: Q325 | U3: Q425 | V3: 2025 | W3: Q126 | X3: Q226 | Y3: Q326 | Z3: Q426 | AA3: 2026 | AB3: Q127 | AC3: Q227 | AD3: Q327 | AE3: Q427 | AF3: 2027 | AG3: Q128 | AH3: Q228 | AI3: Q328 | AJ3: Q428 | AK3: 2028
B4: Short range
B5: Revenue | C5: 175.522 | D5: 193.249 | E5: 192.05 | F5: 183.992 | G5: =SUM(C5:F5) -> 744.813 | H5: 138.77 | I5: 149.616 | J5: 130 | K5: 99.898 | L5: =SUM(H5:K5) -> 518.284 | M5: 69.025 | N5: 122.918 | O5: 155.166 | P5: 140.227 | Q5: =SUM(M5:P5) -> 487.336 | R5: 146.043 | S5: 154.3 | T5: 166.709 | U5: 158.305 | V5: =SUM(R5:U5) -> 625.357 | W5: 177.535 | X5: 199.788 | AA5: =SUM(W5:Z5) -> 377.323 | AF5: =SUM(AB5:AE5) -> 0 | AK5: =SUM(AG5:AJ5) -> 0
B6: Growth % | H6: =(H5-C5)/C5 -> -0.20938686 | I6: =(I5-D5)/D5 -> -0.22578642 | J6: =(J5-E5)/E5 -> -0.32309294 | K6: =(K5-F5)/F5 -> -0.45705248 | L6: =(L5-G5)/G5 -> -0.30414211 | M6: =(M5-H5)/H5 -> -0.50259422 | N6: =(N5-I5)/I5 -> -0.17844348 | O6: =(O5-J5)/J5 -> 0.19358462 | ... AK6: =(AK5-AF5)/AF5 -> #DIV/0!
B7: Long-range
B8: Revenue | C8: =6.553+1 -> 7.553 | D8: =5.1+1 -> 6.1 | E8: =8.6+0.714 -> 9.314 | F8: =5+1.8 -> 6.8 | G8: =SUM(C8:F8) -> 29.767 | H8: =4.7+1.1 -> 5.8 | I8: =2.588+1.7 -> 4.288 | J8: 4.7 | K8: =6+1.2 -> 7.2 | L8: =SUM(H8:K8) -> 21.988 | M8: 3.778 | N8: =3.743+0.545 -> 4.288 | O8: =2.476+0.094 -> 2.57 | P8: 7.8 | Q8: =SUM(M8:P8) -> 18.436 | R8: 7.537 | S8: 7.5 | T8: 9.798 | U8: 8.722 | V8: =SUM(R8:U8) -> 33.557 | W8: 12.487 | X8: 14.625 | AA8: =SUM(W8:Z8) -> 27.112 | AF8: =SUM(AB8:AE8) -> 0 | AK8: =SUM(AG8:AJ8) -> 0
B9: Growth % | H9: =(H8-C8)/C8 -> -0.23209321 | I9: =(I8-D8)/D8 -> -0.29704918 | J9: =(J8-E8)/E8 -> -0.49538329 | K9: =(K8-F8)/F8 -> 0.058823529 | L9: =(L8-G8)/G8 -> -0.26132966 | M9: =(M8-H8)/H8 -> -0.34862069 | N9: =(N8-I8)/I8 -> 0 | O9: =(O8-J8)/J8 -> -0.45319149 | ... AK9: =(AK8-AF8)/AF8 -> #DIV/0!
B10: Other
B11: Revenue | C11: 0 | D11: 0.751 | E11: 0.718 | F11: 0.482 | G11: =SUM(C11:F11) -> 1.951 | H11: 0.787 | I11: 0.287 | J11: 0.243 | K11: 0.984 | L11: =SUM(H11:K11) -> 2.301 | M11: 1.695 | N11: 0.743 | O11: 1 | P11: 2 | Q11: =SUM(M11:P11) -> 5.438 | R11: 1.487 | S11: 2.2 | T11: 2.45 | U11: 2.481 | V11: =SUM(R11:U11) -> 8.618 | W11: 2.421 | X11: 4 | AA11: =SUM(W11:Z11) -> 6.421 | AF11: =SUM(AB11:AE11) -> 0 | AK11: =SUM(AG11:AJ11) -> 0
B12: Growth % | I12: =(I11-D11)/D11 -> -0.61784288 | J12: =(J11-E11)/E11 -> -0.66155989 | K12: =(K11-F11)/F11 -> 1.0414938 | L12: =(L11-G11)/G11 -> 0.17939518 | M12: =(M11-H11)/H11 -> 1.1537484 | N12: =(N11-I11)/I11 -> 1.5888502 | O12: =(O11-J11)/J11 -> 3.1152263 | P12: =(P11-K11)/K11 -> 1.0325203 | ... AK12: =(AK11-AF11)/AF11 -> #DIV/0!
A14: Revenue by end-user market
B16: USD million | C16: Q122 | D16: Q222 | E16: Q322 | F16: Q422 | G16: 2022 | H16: Q123 | I16: Q223 | J16: Q323 | K16: Q423 | L16: 2023 | M16: Q124 | N16: Q224 | O16: Q324 | P16: Q424 | Q16: 2024 | R16: Q125 | S16: Q225 | T16: Q325 | U16: Q425 | V16: 2025 | W16: Q126 | X16: Q226 | Y16: Q326 | Z16: Q426 | AA16: 2026 | AB16: Q127 | AC16: Q227 | AD16: Q327 | AE16: Q427 | AF16: 2027 | AG16: Q128 | AH16: Q228 | AI16: Q328 | AJ16: Q428 | AK16: 2028
B17: Consumer
B18: Revenue | C18: 122.246 | D18: 126.404 | E18: 126.242 | F18: 108.906 | G18: =SUM(C18:F18) -> 483.798 | H18: 69.75 | I18: 84.358 | J18: 80 | K18: 67.411 | L18: =SUM(H18:K18) -> 301.519 | M18: 54.198 | N18: 83 | O18: 108.96 | P18: 94.312 | Q18: =SUM(M18:P18) -> 340.47 | R18: 88.476 | S18: 100 | T18: 112 | U18: 100 | V18: =SUM(R18:U18) -> 400.476 | W18: 115.142 | X18: 125.227 | AA18: =SUM(W18:Z18) -> 240.369 | AF18: =SUM(AB18:AE18) -> 0 | AK18: =SUM(AG18:AJ18) -> 0
B19: Growth % | H19: =(H18-C18)/C18 -> -0.42942918 | I19: =(I18-D18)/D18 -> -0.33263188 | J19: =(J18-E18)/E18 -> -0.36629648 | K19: =(K18-F18)/F18 -> -0.38101666 | L19: =(L18-G18)/G18 -> -0.37676675 | M19: =(M18-H18)/H18 -> -0.22296774 | N19: =(N18-I18)/I18 -> -0.016098058 | O19: =(O18-J18)/J18 -> 0.362 | ... AK19: =(AK18-AF18)/AF18 -> #DIV/0!
B20: Industrial and healthcare
B21: Revenue | C21: =39.783+14.192 -> 53.975 | D21: =48.205+16.755 -> 64.96 | E21: =51.815+14.374 -> 66.189 | F21: =51.739+22.3 -> 74.039 | G21: =SUM(C21:F21) -> 259.163 | H21: =45.362+23.56 -> 68.922 | I21: =29.873+34.522 -> 64.395 | J21: =23.709+26.491 -> 50.2 | K21: =18.26+18.752 -> 37.012 | L21: =SUM(H21:K21) -> 220.529 | M21: 17.273 | N21: =26.565+14.899 -> 41.464 | O21: 44 | P21: 48 | Q21: =SUM(M21:P21) -> 150.737 | R21: 60.362 | S21: 59 | T21: 62 | U21: 63 | V21: =SUM(R21:U21) -> 244.362 | W21: 72.17 | X21: 86.052 | AA21: =SUM(W21:Z21) -> 158.222 | AF21: =SUM(AB21:AE21) -> 0 | AK21: =SUM(AG21:AJ21) -> 0
B22: Growth % | H22: =(H21-C21)/C21 -> 0.2769245 | I22: =(I21-D21)/D21 -> -0.0086976601 | J22: =(J21-E21)/E21 -> -0.24156582 | K22: =(K21-F21)/F21 -> -0.5001013 | L22: =(L21-G21)/G21 -> -0.14907221 | M22: =(M21-H21)/H21 -> -0.74938336 | N22: =(N21-I21)/I21 -> -0.35609908 | O22: =(O21-J21)/J21 -> -0.12350598 | ... AK22: =(AK21-AF21)/AF21 -> #DIV/0!
B23: Other
B24: Revenue | C24: 5.8 | D24: 7.7 | E24: 8.9 | F24: 6.5 | G24: =SUM(C24:F24) -> 28.9 | H24: 5.6 | I24: 3.7 | J24: 3.3 | K24: 2.4 | L24: =SUM(H24:K24) -> 15 | M24: 2 | N24: 2.891 | O24: 3 | P24: 4.4 | Q24: =SUM(M24:P24) -> 12.291 | R24: 5.651 | S24: 4 | T24: 5 | U24: 6 | V24: =SUM(R24:U24) -> 20.651 | W24: 4.978 | X24: 7.22 | AA24: =SUM(W24:Z24) -> 12.198 | AF24: =SUM(AB24:AE24) -> 0 | AK24: =SUM(AG24:AJ24) -> 0
B25: Growth % | H25: =(H24-C24)/C24 -> -0.034482759 | I25: =(I24-D24)/D24 -> -0.51948052 | J25: =(J24-E24)/E24 -> -0.62921348 | K25: =(K24-F24)/F24 -> -0.63076923 | L25: =(L24-G24)/G24 -> -0.48096886 | M25: =(M24-H24)/H24 -> -0.64285714 | N25: =(N24-I24)/I24 -> -0.21864865 | O25: =(O24-J24)/J24 -> -0.090909091 | ... AK25: =(AK24-AF24)/AF24 -> #DIV/0!

Sheet Nøkkeltall
D5: 2026 | E5: 2027 | F5: 2028
C6: EV/Sales | D6: =Modell!$B$9/(Modell!AG4*Modell!$B$11) -> 3.1140804 | E6: =Modell!$B$9/(Modell!AH4*Modell!$B$11) -> 2.595067 | F6: =Modell!$B$9/(Modell!AI4*Modell!$B$11) -> 2.1625558
C7: EV/EBITDA | D7: =Modell!$B$9/(Modell!$B$11*Modell!AF9) -> 29.509255 | E7: =Modell!$B$9/(Modell!$B$11*Modell!AG9) -> 20.638436 | F7: =Modell!$B$9/(Modell!$B$11*Modell!AH9) -> 15.005667
C8: EV/EBIT | D8: =Modell!$B$9/(Modell!$B$11*Modell!AF11) -> 47.464384 | E8: =Modell!$B$9/(Modell!$B$11*Modell!AG11) -> 28.063054 | F8: =Modell!$B$9/(Modell!$B$11*Modell!AH11) -> 18.579678
C9: P/E | D9: =Modell!$B$4/Modell!AF18 -> 70.368513 | E9: =Modell!$B$4/Modell!AG18 -> 41.604995 | F9: =Modell!$B$4/Modell!AH18 -> 27.545377

Sheet Kunder
B3: USDm | C3: Q122 | D3: Q222 | E3: Q322 | F3: Q422 | G3: Q123 | H3: Q223 | I3: Q323 | J3: Q423 | K3: Q124 | L3: Q224 | M3: Q324 | N3: Q424 | O3: Q125 | P3: Q225 | Q3: Q325 | R3: Q425 | S3: Q126 | T3: Q226 | U3: Q326 | V3: Q426 | Y3: FY 2016 | Z3: FY 2017 | AA3: FY 2018 | AB3: FY 2019 | AC3: FY 2020 | AD3: FY 2021 | AE3: FY 2022 | AF3: FY 2023 | AG3: FY 2024 | AH3: FY 2025 | AI3: FY 2026
B4: Logitech
B5: Revenue | C5: 1229.994 | D5: 1159.865 | E5: 1148.951 | F5: 1269.925 | G5: 960.07 | H5: 974.499 | I5: 1057.008 | J5: 1255.473 | K5: 1011.487 | L5: 1088.217 | M5: 1116 | N5: 1340.294 | O5: 1010.355 | P5: 1147.703 | Q5: 1186.056 | R5: 1421.479 | S5: 1085.523 | T5: 1227.234 | Y5: 2221.427 | Z5: 2566.863 | AA5: 2788.322 | AB5: 2975.851 | AC5: 5252.279 | AD5: 5481.101 | AE5: 4538.818 | AF5: 4298.467 | AG5: 4554.9 | AH5: 4840.761
B6: Gross profit | C6: 493.907 | D6: 459.603 | E6: 438.78 | F6: 477.268 | G6: 343.864 | H6: 375.642 | I6: 438.622 | J6: 526.78 | K6: 436.977 | L6: 466.258 | M6: 486.091 | N6: 574.441 | O6: 435.811 | P6: 478.962 | Q6: 514.456 | R6: 614.639 | S6: 483.28 | T6: 607.94 | Y6: 820.041 | Z6: 909.241 | AA6: 1037.011 | AB6: 1122.381 | AC6: 2335.735 | AD6: 2263.006 | AE6: 1719.515 | AF6: 1778.021 | AG6: 1962.601 | AH6: 2091.337
B7: Operating profit | C7: 128.769 | D7: 115.479 | E7: 127.401 | F7: 176.745 | G7: 38.844 | H7: 78.405 | I7: 156.639 | J7: 222.075 | K7: 130.217 | L7: 153.499 | M7: 160.896 | N7: 234.556 | O7: 105.904 | P7: 162.094 | Q7: 191.291 | R7: 286.014 | S7: 135.795 | T7: 258.551 | Y7: 211.86 | Z7: 229.733 | AA7: 263.194 | AB7: 276.495 | AC7: 1148.125 | AD7: 774.012 | AE7: 458.469 | AF7: 587.336 | AG7: 654.855 | AH7: 775.194
B8: EPS | C8: 0.65 | D8: 0.61 | E8: 0.5 | F8: 0.87 | G8: 0.26 | H8: 0.39 | I8: 0.87 | J8: 1.57 | K8: 1.09 | L8: 0.93 | M8: 0.95 | N8: 1.33 | O8: 0.97 | P8: 0.99 | Q8: 1.16 | R8: 1.71 | S8: 0.99 | T8: 1.64 | Y8: 1.27 | Z8: 1.27 | AA8: 1.56 | AB8: 2.7 | AC8: 5.62 | AD8: 3.85 | AE8: 2.25 | AF8: 3.9 | AG8: 4.17 | AH8: 4.85
B10: Revenue y/y | G10: =(G5-C5)/C5 -> -0.21945148 | H10: =(H5-D5)/D5 -> -0.15981688 | I10: =(I5-E5)/E5 -> -0.08002343 | J10: =(J5-F5)/F5 -> -0.0113802 | K10: =(K5-G5)/G5 -> 0.05355547 | L10: =(L5-H5)/H5 -> 0.11669381 | M10: =(M5-I5)/I5 -> 0.055810363 | N10: =(N5-J5)/J5 -> 0.067560991 | ... T10: =(T5-P5)/P5 -> 0.069295802 | Z10: =(Z5-Y5)/Y5 -> 0.15550185 | AA10: =(AA5-Z5)/Z5 -> 0.086276128 | AB10: =(AB5-AA5)/AA5 -> 0.067255145 | AC10: =(AC5-AB5)/AB5 -> 0.76496706 | AD10: =(AD5-AC5)/AC5 -> 0.043566231 | AE10: =(AE5-AD5)/AD5 -> -0.17191491 | AF10: =(AF5-AE5)/AE5 -> -0.052954536 | AG10: =(AG5-AF5)/AF5 -> 0.05965685 | AH10: =(AH5-AG5)/AG5 -> 0.062759007
B11: Gross margin | C11: =C6/C5 -> 0.40155237 | D11: =D6/D5 -> 0.3962556 | E11: =E6/E5 -> 0.38189618 | F11: =F6/F5 -> 0.37582377 | G11: =G6/G5 -> 0.35816555 | H11: =H6/H5 -> 0.38547192 | I11: =I6/I5 -> 0.41496564 | J11: =J6/J5 -> 0.41958688 | ... T11: =T6/T5 -> 0.49537415 | Y11: =Y6/Y5 -> 0.36915055 | Z11: =Z6/Z5 -> 0.35422264 | AA11: =AA6/AA5 -> 0.37191221 | AB11: =AB6/AB5 -> 0.37716304 | AC11: =AC6/AC5 -> 0.44470886 | AD11: =AD6/AD5 -> 0.41287435 | AE11: =AE6/AE5 -> 0.37884643 | AF11: =AF6/AF5 -> 0.41364072 | ... AH11: =AH6/AH5 -> 0.43202649
B12: Operating margin | C12: =C7/C5 -> 0.10469075 | D12: =D7/D5 -> 0.099562449 | E12: =E7/E5 -> 0.11088462 | F12: =F7/F5 -> 0.13917751 | G12: =G7/G5 -> 0.04045955 | H12: =H7/H5 -> 0.080456727 | I12: =I7/I5 -> 0.14819093 | J12: =J7/J5 -> 0.17688552 | ... T12: =T7/T5 -> 0.21067783 | Y12: =Y7/Y5 -> 0.095371129 | Z12: =Z7/Z5 -> 0.089499518 | AA12: =AA7/AA5 -> 0.094391537 | AB12: =AB7/AB5 -> 0.092912918 | AC12: =AC7/AC5 -> 0.21859558 | AD12: =AD7/AD5 -> 0.14121469 | AE12: =AE7/AE5 -> 0.10101066 | AF12: =AF7/AF5 -> 0.13663848 | ... AH12: =AH7/AH5 -> 0.16013887
B14: Inventory | C14: 933.124 | D14: 682.893 | E14: 682.893 | F14: 682.893 | G14: 682.893 | H14: 572.344 | I14: 532.943 | J14: 447.262 | K14: 422.513 | L14: 459.582 | M14: 503.747 | N14: 503.747 | O14: 503.747 | P14: 489.948 | Q14: 517.673 | R14: 449.544 | S14: 489.948 | T14: 491.743 | Y14: 253.401 | Z14: 259.906 | AA14: 293.495 | AB14: 229.249 | AC14: 661.116 | AD14: 933.124 | AE14: 682.893 | AF14: 422.513 | AG14: 503.747 | AH14: 489.948
B15: y/y | G15: =(G14-C14)/C14 -> -0.26816479 | H15: =(H14-D14)/D14 -> -0.16188334 | I15: =(I14-E14)/E14 -> -0.21958052 | J15: =(J14-F14)/F14 -> -0.3450482 | K15: =(K14-G14)/G14 -> -0.3812896 | L15: =(L14-H14)/H14 -> -0.19701788 | M15: =(M14-I14)/I14 -> -0.054782594 | N15: =(N14-J14)/J14 -> 0.12629063 | ... T15: =(T14-P14)/P14 -> 0.0036636541 | Z15: =(Z14-Y14)/Y14 -> 0.025670775 | AA15: =(AA14-Z14)/Z14 -> 0.12923519 | AB15: =(AB14-AA14)/AA14 -> -0.21889981 | AC15: =(AC14-AB14)/AB14 -> 1.8838337 | AD15: =(AD14-AC14)/AC14 -> 0.41143763 | AE15: =(AE14-AD14)/AD14 -> -0.26816479 | AF15: =(AF14-AE14)/AE14 -> -0.3812896 | AG15: =(AG14-AF14)/AF14 -> 0.19226391 | AH15: =(AH14-AG14)/AG14 -> -0.027392719
B17: Accounts receivables | C17: 164.848 | D17: -44.572 | E17: -77.337 | F17: -1.638 | G17: 174.732 | H17: 65.39 | I17: -100.752 | J17: -11.424 | K17: 138.305 | L17: -53.952 | M17: -27.616 | N17: -46.366 | O17: 197.913 | P17: -166.767 | Q17: -69.092 | R17: 22.044 | S17: 174.379 | T17: -162.667 | Y17: -46.553 | Z17: -26.363 | AA17: -58.798 | AB17: -15.768 | AC17: -201.22 | AD17: -71.51 | AE17: 51.185 | AF17: 91.519 | AG17: 69.976 | AH17: -39.436
B18: Inventories | C18: -98.812 | D18: -0.324 | E18: 22.114 | F18: 104.519 | G18: 121 | H18: 110.44 | I18: 35.929 | J18: 91.6 | K18: 21.827 | L18: -39 | M18: -54.814 | N18: 26.353 | O18: -12.947 | P18: 17.304 | Q18: -19 | R18: 68.701 | S18: -44.039 | T18: -0.707 | Y18: -15.428 | Z18: 16 | AA18: -21.551 | AB18: 60.388 | AC18: -427.501 | AD18: -276.64 | AE18: 247.309 | AF18: 259.796 | AG18: -80.501 | AH18: 22.882
B19: Other assets | C19: 2.4 | D19: 4.932 | E19: -0.175 | F19: 16.161 | G19: -15.284 | H19: 34.342 | I19: -22.343 | J19: -8.3 | K19: 7 | L19: 4.907 | M19: -2.66 | N19: 7.175 | O19: 14.554 | P19: -19.817 | Q19: 2.3 | R19: -12.939 | S19: -6.136 | T19: -29.789 | Y19: -5.3 | Z19: -16.9 | AA19: -8.8 | AB19: 18.319 | AC19: -67.708 | AD19: -18.169 | AE19: 5.634 | AF19: 10.76 | AG19: 23.97 | AH19: -36.559
B20: Account payable | C20: -100.666 | D20: -70 | E20: -8.32 | F20: -56.494 | G20: -84.203 | H20: -18.42 | I20: 106.442 | J20: 32.361 | K20: -81.047 | L20: 109.028 | M20: -0.652 | N20: 28.472 | O20: -168.475 | P20: 135.003 | Q20: 30.416 | R20: 6.548 | S20: -62.793 | T20: 56.21 | Y20: 24.459 | Z20: 17.695 | AA20: -19.134 | AB20: -24.25 | AC20: 553.96 | AD20: -181.303 | AE20: -219.051 | AF20: 39.336 | AG20: -31.627 | AH20: 109.174
B21: Accured and other liabilities | C21: -26.628 | D21: -63.835 | E21: -8.322 | F21: 12.097 | G21: -68.647 | H21: -74.329 | I21: 14.476 | J21: 73.389 | K21: -25.514 | L21: -42.506 | M21: 54.786 | N21: 106.379 | O21: -117.819 | P21: -51.861 | Q21: 53.211 | R21: 118.558 | S21: -70.257 | T21: 6 | Y21: 49.917 | Z21: 44.655 | AA21: 51.278 | AB21: -15.48 | AC21: 440.935 | AD21: -44.24 | AE21: -128.707 | AF21: -11.978 | AG21: 0.84 | AH21: 49.651
B22: WC | C22: =SUM(C17:C21) -> -58.858 | D22: =SUM(D17:D21) -> -173.799 | E22: =SUM(E17:E21) -> -72.04 | F22: =SUM(F17:F21) -> 74.645 | G22: =SUM(G17:G21) -> 127.598 | H22: =SUM(H17:H21) -> 117.423 | I22: =SUM(I17:I21) -> 33.752 | J22: =SUM(J17:J21) -> 177.626 | ... T22: =SUM(T17:T21) -> -130.953 | Y22: =SUM(Y17:Y21) -> 7.095 | Z22: =SUM(Z17:Z21) -> 35.087 | AA22: =SUM(AA17:AA21) -> -57.005 | AB22: =SUM(AB17:AB21) -> 23.209 | AC22: =SUM(AC17:AC21) -> 298.466 | AD22: =SUM(AD17:AD21) -> -591.862 | AE22: =SUM(AE17:AE21) -> -43.63 | AF22: =SUM(AF17:AF21) -> 389.433 | ... AH22: =SUM(AH17:AH21) -> 105.712
B25: Garmin
B26: Revenue | C26: 1147.424 | D26: 1240.833 | E26: 1140.434 | F26: 1306.356 | G26: 1147.424 | H26: 1320.795 | I26: 1277.531 | J26: 1482.501 | K26: 1381.649 | L26: 1506.671 | M26: 1586.022 | N26: 1822.56 | O26: 1535.099 | P26: 1814.564 | Q26: 1770.901 | R26: 2124.955 | S26: 1753.489 | T26: 2022.092 | Y26: 3045.797 | Z26: 3121.56 | AA26: 3347.444 | AB26: 3757.505 | AC26: 4186.573 | AD26: 4982.795 | AE26: 4860.286 | AF26: 5228.252 | AG26: 6296.903 | AH26: 7245.519
B27: Gross profit | C27: 652.794 | D27: 728.826 | E27: 670.499 | F27: 744.97 | G27: 652.794 | H27: 759.442 | I27: 728.569 | J27: 864.149 | K27: 802.139 | L27: 862.891 | M27: 951.599 | N27: 1079.926 | O27: 884.545 | P27: 1067.012 | Q27: 1046.487 | R27: 1258.26 | S27: 1042.289 | T27: 1262.022 | Y27: 1688.525 | Z27: 1797.941 | AA27: 1979.719 | AB27: 2233.976 | AC27: 2481.336 | AD27: 2890.459 | AE27: 2806.775 | AF27: 3004.955 | AG27: 3696.555 | AH27: 4256.303
B28: Operating profit | C28: 196.982 | D28: 292.74 | E28: 239.373 | F28: 267.175 | G28: 196.983 | H28: 284.355 | I28: 270.369 | J28: 340.454 | K28: 298.41 | L28: 342.027 | M28: 437.475 | N28: 516.082 | O28: 332.824 | P28: 472.295 | Q28: 456.803 | R28: 614.154 | S28: 431.665 | T28: 615.508 | Y28: 632.864 | Z28: 683.637 | AA28: 778.343 | AB28: 945.586 | AC28: 1054.24 | AD28: 1218.62 | AE28: 1027.845 | AF28: 1092.16 | AG28: 1593.994 | AH28: 1876.076
B29: EPS | C29: 1.06 | D29: 1.34 | E29: 1.09 | F29: 1.53 | G29: 1.05 | H29: 1.51 | I29: 1.34 | J29: 2.83 | K29: 1.44 | L29: 1.57 | M29: 2.08 | N29: 2.27 | O29: 1.73 | P29: 2.08 | Q29: 2.09 | R29: 2.75 | S29: 2.1 | T29: 2.8 | Y29: 2.73 | Z29: 3.76 | AA29: 3.66 | AB29: 4.99 | AC29: 5.17 | AD29: 5.63 | AE29: 5.06 | AF29: 6.74 | AG29: 7.35 | AH29: 8.65
B31: Revenue y/y | G31: =(G26-C26)/C26 -> 0 | H31: =(H26-D26)/D26 -> 0.064442193 | I31: =(I26-E26)/E26 -> 0.12021476 | J31: =(J26-F26)/F26 -> 0.13483691 | K31: =(K26-G26)/G26 -> 0.20413117 | L31: =(L26-H26)/H26 -> 0.14073039 | M31: =(M26-I26)/I26 -> 0.24147438 | N31: =(N26-J26)/J26 -> 0.22938197 | ... T31: =(T26-P26)/P26 -> 0.11436797 | Z31: =(Z26-Y26)/Y26 -> 0.024874606 | AA31: =(AA26-Z26)/Z26 -> 0.072362537 | AB31: =(AB26-AA26)/AA26 -> 0.12249973 | AC31: =(AC26-AB26)/AB26 -> 0.1141896 | AD31: =(AD26-AC26)/AC26 -> 0.19018467 | AE31: =(AE26-AD26)/AD26 -> -0.024586402 | AF31: =(AF26-AE26)/AE26 -> 0.075708713 | AG31: =(AG26-AF26)/AF26 -> 0.20439929 | AH31: =(AH26-AG26)/AG26 -> 0.15064802
B32: Gross margin | C32: =C27/C26 -> 0.56892134 | D32: =D27/D26 -> 0.58736832 | E32: =E27/E26 -> 0.58793319 | F32: =F27/F26 -> 0.57026569 | G32: =G27/G26 -> 0.56892134 | H32: =H27/H26 -> 0.57498855 | I32: =I27/I26 -> 0.57029458 | J32: =J27/J26 -> 0.58289944 | ... T32: =T27/T26 -> 0.624117 | Y32: =Y27/Y26 -> 0.55437871 | Z32: =Z27/Z26 -> 0.57597515 | AA32: =AA27/AA26 -> 0.59141213 | AB32: =AB27/AB26 -> 0.59453707 | AC32: =AC27/AC26 -> 0.59268906 | AD32: =AD27/AD26 -> 0.58008788 | AE32: =AE27/AE26 -> 0.57749174 | AF32: =AF27/AF26 -> 0.57475328 | ... AH32: =AH27/AH26 -> 0.58743935
B33: Operating margin | C33: =C28/C26 -> 0.17167324 | D33: =D28/D26 -> 0.23592216 | E33: =E28/E26 -> 0.20989641 | F33: =F28/F26 -> 0.20451929 | G33: =G28/G26 -> 0.17167412 | H33: =H28/H26 -> 0.21529079 | I33: =I28/I26 -> 0.211634 | J33: =J28/J26 -> 0.22964841 | ... T33: =T28/T26 -> 0.30439169 | Y33: =Y28/Y26 -> 0.20778272 | Z33: =Z28/Z26 -> 0.21900492 | AA33: =AA28/AA26 -> 0.2325186 | AB33: =AB28/AB26 -> 0.25165263 | AC33: =AC28/AC26 -> 0.25181455 | AD33: =AD28/AD26 -> 0.24456555 | AE33: =AE28/AE26 -> 0.2114783 | AF33: =AF28/AF26 -> 0.20889582 | ... AH33: =AH28/AH26 -> 0.25892914
B35: Inventory | C35: 1478.997 | D35: 1454.868 | E35: 1533.271 | F35: 1515.045 | G35: 1478.997 | H35: 1402.225 | I35: 1439.894 | J35: 1345.955 | K35: 1302.23 | L35: 1473.978 | M35: 1473.978 | N35: 1473.978 | O35: 1772.257 | P35: 1788.02 | Q35: 1887.93 | R35: 1772.257 | S35: 1850.282 | T35: 1966.061 | Y35: 484.821 | Z35: 517.644 | AA35: 561.84 | AB35: 752.908 | AC35: 762.084 | AD35: 1227.609 | AE35: 1515.045 | AF35: 1345.955 | AG35: 1473.978 | AH35: 1772.257
B36: y/y | G36: =(G35-C35)/C35 -> 0 | H36: =(H35-D35)/D35 -> -0.036184039 | I36: =(I35-E35)/E35 -> -0.060900519 | J36: =(J35-F35)/F35 -> -0.11160725 | K36: =(K35-G35)/G35 -> -0.11951816 | L36: =(L35-H35)/H35 -> 0.051170818 | M36: =(M35-I35)/I35 -> 0.023671187 | N36: =(N35-J35)/J35 -> 0.09511685 | ... T36: =(T35-P35)/P35 -> 0.09957439 | Z36: =(Z35-Y35)/Y35 -> 0.067701275 | AA36: =(AA35-Z35)/Z35 -> 0.085379141 | AB36: =(AB35-AA35)/AA35 -> 0.34007547 | AC36: =(AC35-AB35)/AB35 -> 0.012187412 | AD36: =(AD35-AC35)/AC35 -> 0.61085786 | AE36: =(AE35-AD35)/AD35 -> 0.23414296 | AF36: =(AF35-AE35)/AE35 -> -0.11160725 | AG36: =(AG35-AF35)/AF35 -> 0.09511685 | AH36: =(AH35-AG35)/AG35 -> 0.20236326
B38: Accounts receivables | C38: 46.873 | D38: 122.428 | E38: 156.666 | F38: 167.336 | G38: 46.873 | H38: -62.832 | I38: -54.756 | J38: -129.12 | K38: 108.453 | L38: -8.6 | M38: -103.567 | N38: -196.256 | O38: 213.089 | P38: 17.902 | Q38: 68.818 | R38: -222.809 | S38: 301.791 | T38: 84.187 | Y38: 9 | Z38: -40.088 | AA38: 7.29 | AB38: -123.401 | AC38: -108.859 | AD38: -19.106 | AE38: 167.336 | AF38: -129.12 | AG38: -196.256 | AH38: -222.809
B39: Inventories | C39: 43.712 | D39: -294.766 | E39: -442.312 | F39: -363.327 | G39: 43.712 | H39: 111.531 | I39: 111.459 | J39: 244.506 | K39: 16.545 | L39: -11.368 | M39: -163.865 | N39: -178.815 | O39: -102.239 | P39: -206.276 | Q39: -324.88 | R39: -218.063 | S39: -95.064 | T39: -209.361 | Y39: -2.455 | Z39: -38.575 | AA39: -57.737 | AB39: -170.169 | AC39: 28.726 | AD39: -476.454 | AE39: -363.327 | AF39: 244.506 | AG39: -178.815 | AH39: -218.063
B40: Other current and noncurrent assets | C40: 4.78 | D40: 0.775 | E40: 29.299 | F40: 72.185 | G40: 4.78 | H40: 2.769 | I40: 28.288 | J40: 7.887 | K40: 2.117 | L40: -39.759 | M40: -47.413 | N40: -42.13 | O40: -17.5 | P40: -37.092 | Q40: -18.466 | R40: 1.921 | S40: -29.068 | T40: -44.687 | Y40: 2.2 | Z40: -21.608 | AA40: 7.358 | AB40: -86.073 | AC40: -33.69 | AD40: -38 | AE40: 72.185 | AF40: 7.887 | AG40: -42.13 | AH40: 1.921
B41: Account payable | C41: -4.2 | D41: -29.829 | E41: -64.199 | F41: -131.268 | G41: -4.2 | H41: 45.206 | I41: 55.34 | J41: 28.503 | K41: -1.281 | L41: 92.065 | M41: 124.315 | N41: 120.637 | O41: -12.629 | P41: -2.591 | Q41: -7.531 | R41: -30.518 | S41: 3.4 | T41: 59.547 | Y41: -11.496 | Z41: -17.24 | AA41: 40.628 | AB41: 26.192 | AC41: 1.4 | AD41: 108.946 | AE41: -131.268 | AF41: 28.503 | AG41: 120.637 | AH41: -30.518
B42: Other current and noncurrent liab | C42: -67.405 | D42: -74.273 | E42: -84.287 | F42: -71.756 | G42: -67.405 | H42: -39.484 | I42: 0.43 | J42: 52.188 | K42: -64.699 | L42: -62.099 | M42: -6.987 | N42: 24.546 | O42: -57.3189 | P42: 2.408 | Q42: 1.944 | R42: 85.206 | S42: -90.378 | T42: -68.307 | Y42: 44.766 | Z42: 5.627 | AA42: -1.323 | AB42: 36.66 | AC42: 87.761 | AD42: 70 | AE42: -71.756 | AF42: 52.188 | AG42: 24.546 | AH42: 85.206
B43: WC | C43: =SUM(C38:C42) -> 23.76 | D43: =SUM(D38:D42) -> -275.665 | E43: =SUM(E38:E42) -> -404.833 | F43: =SUM(F38:F42) -> -326.83 | G43: =SUM(G38:G42) -> 23.76 | H43: =SUM(H38:H42) -> 57.19 | I43: =SUM(I38:I42) -> 140.761 | J43: =SUM(J38:J42) -> 203.964 | ... T43: =SUM(T38:T42) -> -178.621 | Y43: =SUM(Y38:Y42) -> 42.015 | Z43: =SUM(Z38:Z42) -> -111.884 | AA43: =SUM(AA38:AA42) -> -3.784 | AB43: =SUM(AB38:AB42) -> -316.791 | AC43: =SUM(AC38:AC42) -> -24.662 | AD43: =SUM(AD38:AD42) -> -354.614 | AE43: =SUM(AE38:AE42) -> -326.83 | AF43: =SUM(AF38:AF42) -> 203.964 | ... AI43: =SUM(AI38:AI42) -> 0

Sheet Nedsideberegning
D3: FY 2019 | E3: FY 2020 | F3: FY 2021 | G3: FY 2022 | H3: FY 2023 | I3: FY 2024 | J3: FY 2025 | K3: FY 2026 | L3: FY 2027 | M3: FY 2028 | N3: FY 2029 | O3: FY 2030 | P3: FY 2031 | Q3: FY 2032 | R3: FY 2033 | S3: FY 2034 | T3: FY 2035
A4: 10% vekst | C4: Revenue | D4: 288.395 | E4: 405.217 | F4: 610.528 | G4: 777 | H4: 543 | I4: 511 | J4: =I4*1.26 -> 643.86 | K4: =J4*1.1 -> 708.246 | L4: =K4*1.1 -> 779.0706 | M4: =L4*1.1 -> 856.97766 | N4: =M4*1.1 -> 942.67543 | O4: =N4*1.1 -> 1036.943 | P4: =O4*1.1 -> 1140.6373 | Q4: =P4*1.1 -> 1254.701 | R4: =Q4*1.1 -> 1380.1711 | ... T4: =S4*1.1 -> 1670.007
A5: =W27 -> 121.96478 | C5: COGS | D5: -141.29 | E5: -190.69 | F5: -283.415 | G5: -340 | H5: -259 | I5: -269 | J5: =J4*-0.5 -> -321.93 | K5: =K4*-0.5 -> -354.123 | L5: =L4*-0.5 -> -389.5353 | M5: =M4*-0.5 -> -428.48883 | N5: =N4*-0.5 -> -471.33771 | O5: =O4*-0.5 -> -518.47148 | P5: =P4*-0.5 -> -570.31863 | Q5: =Q4*-0.5 -> -627.3505 | ... T5: =T4*-0.5 -> -835.00351
A6: =W28 -> -0.31093344 | C6: Gross profit | D6: =SUM(D4:D5) -> 147.105 | E6: =SUM(E4:E5) -> 214.527 | F6: =SUM(F4:F5) -> 327.113 | G6: =SUM(G4:G5) -> 437 | H6: =SUM(H4:H5) -> 284 | I6: =SUM(I4:I5) -> 242 | J6: =SUM(J4:J5) -> 321.93 | K6: =SUM(K4:K5) -> 354.123 | ... T6: =SUM(T4:T5) -> 835.00351
C7: Payroll expense | D7: -80.281 | E7: -101.211 | F7: -149.824 | G7: -161 | H7: -153 | I7: -170 | J7: =I7*1.05 -> -178.5 | K7: =J7*1.05 -> -187.425 | L7: =K7*1.05 -> -196.79625 | M7: =L7*1.05 -> -206.63606 | N7: =M7*1.05 -> -216.96787 | O7: =N7*1.05 -> -227.81626 | P7: =O7*1.05 -> -239.20707 | Q7: =P7*1.05 -> -251.16743 | ... T7: =S7*1.05 -> -290.75769
C8: Other opex | D8: -33.665 | E8: -35.954 | F8: -52 | G8: -70 | H8: -82 | I8: -77 | J8: =I8*1 -> -77 | K8: =J8*1.05 -> -80.85 | L8: =K8*1.05 -> -84.8925 | M8: =L8*1.05 -> -89.137125 | N8: =M8*1.05 -> -93.593981 | O8: =N8*1.05 -> -98.27368 | P8: =O8*1.05 -> -103.18736 | Q8: =P8*1.05 -> -108.34673 | R8: =Q8*1.05 -> -113.76407 | ... T8: =S8*1.05 -> -125.42489
C9: EBITDA | D9: =SUM(D6:D8) -> 33.159 | E9: =SUM(E6:E8) -> 77.362 | F9: =SUM(F6:F8) -> 125.289 | G9: =SUM(G6:G8) -> 206 | H9: =SUM(H6:H8) -> 49 | I9: =SUM(I6:I8) -> -5 | J9: =SUM(J6:J8) -> 66.43 | K9: =SUM(K6:K8) -> 85.848 | ... T9: =SUM(T6:T8) -> 418.82093
C10: D/A | D10: -23.535 | E10: -31 | F10: -37.798 | G10: -44 | H10: -44 | I10: -41 | J10: -40 | K10: -40 | L10: -40 | M10: -40 | N10: -40 | O10: -40 | P10: -40 | Q10: -40 | R10: -40 | S10: -40 | T10: -40
C11: operating profit (EBIT) | D11: =SUM(D9:D10) -> 9.624 | E11: =SUM(E9:E10) -> 46.362 | F11: =SUM(F9:F10) -> 87.491 | G11: =SUM(G9:G10) -> 162 | H11: =SUM(H9:H10) -> 5 | I11: =SUM(I9:I10) -> -46 | J11: =SUM(J9:J10) -> 26.43 | K11: =SUM(K9:K10) -> 45.848 | ... T11: =SUM(T9:T10) -> 378.82093
C12: Share of profit from associates | D12: 0 | E12: =0 -> 0 | F12: 0 | G12: 0 | H12: 0 | I12: 0 | J12: 0 | K12: 0 | L12: 0 | M12: 0 | N12: 0 | O12: 0 | P12: 0 | Q12: 0 | R12: 0 | S12: 0 | T12: 0
C13: Net interest income | D13: =1.9-1.1 -> 0.8 | E13: =0.642-1.416 -> -0.774 | F13: =0.73-1.129 -> -0.399 | G13: 5 | H13: 6 | I13: -1 | J13: 0 | K13: 0 | L13: 0 | M13: 0 | N13: 0 | O13: 0 | P13: 0 | Q13: 0 | R13: 0 | S13: 0 | T13: 0
C14: Net foreign exhange | D14: -0.375 | E14: -2 | F14: 0.739 | G14: 1 | H14: 1 | I14: 4 | J14: 0 | K14: 0 | L14: 0 | M14: 0 | N14: 0 | O14: 0 | P14: 0 | Q14: 0 | R14: 0 | S14: 0 | T14: 0
C15: PTP | D15: =SUM(D11:D14) -> 10.049 | E15: =SUM(E11:E14) -> 43.588 | F15: =SUM(F11:F14) -> 87.831 | G15: =SUM(G11:G14) -> 168 | H15: =SUM(H11:H14) -> 12 | I15: =SUM(I11:I14) -> -43 | J15: =SUM(J11:J14) -> 26.43 | K15: =SUM(K11:K14) -> 45.848 | ... T15: =SUM(T11:T14) -> 378.82093
C16: tax | D16: -2.3 | E16: -4.5 | F16: -16.089 | G16: -45 | H16: -4 | I16: 5 | J16: =J15*-0.22 -> -5.8146 | K16: =K15*-0.22 -> -10.08656 | L16: =L15*-0.22 -> -14.926241 | M16: =M15*-0.22 -> -20.397441 | N16: =N15*-0.22 -> -26.570691 | O16: =O15*-0.22 -> -33.52394 | P16: =P15*-0.22 -> -41.343323 | Q16: =Q15*-0.22 -> -50.123994 | ... T16: =T15*-0.22 -> -83.340605
C17: Net income | D17: =SUM(D15:D16) -> 7.749 | E17: =SUM(E15:E16) -> 39.088 | F17: =SUM(F15:F16) -> 71.742 | G17: =SUM(G15:G16) -> 123 | H17: =SUM(H15:H16) -> 8 | I17: =SUM(I15:I16) -> -38 | J17: =SUM(J15:J16) -> 20.6154 | K17: =SUM(K15:K16) -> 35.76144 | ... T17: =SUM(T15:T16) -> 295.48033 | U17: =T17*(1+$AR$23) -> 295.48033 | V17: =U17*(1+$AR$23) -> 295.48033 | W17: =V17*(1+$AR$23) -> 295.48033 | X17: =W17*(1+$AR$23) -> 295.48033 | Y17: =X17*(1+$AR$23) -> 295.48033 | Z17: =Y17*(1+$AR$23) -> 295.48033 | AA17: =Z17*(1+$AR$23) -> 295.48033 | AB17: =AA17*(1+$AR$23) -> 295.48033 | ... IT17: =IS17*(1+$AR$23) -> 295.48033
C18: EPS (NOK) | D18: =(D17*$B$11)/D19 -> 0 | E18: =(E17*$B$11)/E19 -> 0 | F18: =(F17*$B$11)/F19 -> 0 | G18: =(G17*$B$11)/G19 -> 0 | H18: =(H17*$B$11)/H19 -> 0 | I18: =(I17*$B$11)/I19 -> 0 | J18: =(J17*$B$11)/J19 -> 0 | K18: =(K17*$B$11)/K19 -> 0 | ... T18: =(T17*$B$11)/T19 -> 0
C19: Shares | D19: 176.394 | E19: 194.704 | F19: 193.042 | G19: 191.365 | H19: 194.704 | I19: 194.704 | J19: 194.704 | K19: 194.704 | L19: 194.704 | M19: 194.704 | N19: 194.704 | O19: 194.704 | P19: 194.704 | Q19: 194.704 | R19: 194.704 | S19: 194.704 | T19: 194.704
C21: Revenue y/y | E21: =(E4-D4)/D4 -> 0.40507637 | F21: =(F4-E4)/E4 -> 0.50666927 | G21: =(G4-F4)/F4 -> 0.2726689 | H21: =(H4-G4)/G4 -> -0.3011583 | I21: =(I4-H4)/H4 -> -0.05893186 | J21: =(J4-I4)/I4 -> 0.26 | K21: =(K4-J4)/J4 -> 0.1 | L21: =(L4-K4)/K4 -> 0.1 | ... T21: =(T4-S4)/S4 -> 0.1
C22: Revenue Q/Q | V22: Discount | W22: =Modell!AR22 -> 0.08
C23: Gross profit | D23: =D6/D4 -> 0.51008166 | E23: =E6/E4 -> 0.52941264 | F23: =F6/F4 -> 0.53578706 | G23: =G6/G4 -> 0.56241956 | H23: =H6/H4 -> 0.52302026 | I23: =I6/I4 -> 0.47358121 | J23: =J6/J4 -> 0.5 | K23: =K6/K4 -> 0.5 | ... T23: =T6/T4 -> 0.5 | V23: TV | W23: -0.01
C24: EBITDA margin | D24: =D9/D4 -> 0.11497772 | E24: =E9/E4 -> 0.19091499 | F24: =F9/F4 -> 0.20521418 | G24: =G9/G4 -> 0.26512227 | H24: =H9/H4 -> 0.090239411 | I24: =I9/I4 -> -0.0097847358 | J24: =J9/J4 -> 0.1031746 | K24: =K9/K4 -> 0.12121212 | ... T24: =T9/T4 -> 0.25078992 | V24: NPV USD | W24: =NPV(W22,J17:IT17) -> 2399.2414
V25: NPV/NOK | W25: =W24*Modell!B11 -> 23512.566
V26: S/O | W26: 192.7816
V27: NPV/Share | W27: =W25/W26 -> 121.96478
V28: Opp-/nedside | W28: =(W27-Modell!B4)/Modell!B4 -> -0.31093344
