Workbook

Sheet Info
A2: Orange book kan brukes for å søke opp patenter | I2: Pris pille (05.01.26)
I3: 1,5mg = 5$day/(149$month) | O3: Dividends | Q3: Buyback
A4: ADA: American Diabetes Association | I4: 4mg = 149$month through April 15 26, then 199$/month | O4: 2026 | Q4: =R4/Modell!B5 -> 3.3757173 | R4: 15000 | T4: Tilbakekjøpsprogram
I5: 25mg = 299$/month | O5: 2025 | P5: 11.7 | T5: Dato kjøp | U5: Antall aksjer | V5: Akummelert antall aksjer | W5: Kjøp DKK | X5: Akkumelert kjøp DKK
O6: 2024 | P6: 11.4 | T6: 46062 | U6: 750000 | V6: =U6 -> 750000 | W6: 222297903 | X6: =W6 -> 222297903
A7: GLP-1: | I7: Kan kjøpes i 1,5, 4, 9 og 25 mg doser | O7: 2023 | P7: 9.4 | T7: 46069 | U7: 1000000 | V7: =SUM(U6:U7) -> 1750000 | W7: =533796640-W6 -> 311498737 | X7: =SUM(W6:W7) -> 533796640
A8: Dette er medisiner som etterligner kroppens eget GLP-1 hormon: | O8: 2022 | P8: 6.2 | T8: 46076 | U8: 1000000 | V8: =SUM(U6:U8) -> 2750000 | W8: =841997435-X7 -> 308200795 | X8: =SUM(W6:W8) -> 841997435
A9: Øker insulinutskillelse når blodsukkeret er høyt | O9: 2021 | P9: 5.2 | T9: 46083 | U9: 1295000 | V9: =SUM(U6:U9) -> 4045000 | W9: =1160693639-X8 -> 318696204 | X9: =SUM(W6:W9) -> 1160693639
A10: Senker appetitten | J10: Q126 oppjusterre | O10: 2020 | P10: 4.55 | T10: 46090 | U10: 1289992 | V10: =SUM(U6:U10) -> 5334992 | W10: =1472797094-X9 -> 312103455 | X10: =SUM(W6:W10) -> 1472797094
T11: 46097 | U11: 1243000 | V11: =SUM(U6:U11) -> 6577992 | W11: =1783540174-X10 -> 310743080 | X11: =SUM(W6:W11) -> 1783540174
A12: Produktene her: | T12: 46104 | U12: 1270000 | V12: =SUM(U6:U12) -> 7847992 | W12: =2091696255-X11 -> 308156081 | X12: =SUM(W6:W12) -> 2091696255
A13: Ozempic: Brukes primært mot type 2-diabetes, men også kjent for å gi vekttap som bieffekt | T13: 46111 | U13: 1315000 | V13: =SUM(U6:U13) -> 9162992 | W13: =2399878368-X12 -> 308182113 | X13: =SUM(W6:W13) -> 2399878368
A14: Victoza: Også en GLP-1 medisin mot type 2, men en litt eldre versjon | T14: 46119 | U14: =9967992-9162992 -> 805000 | V14: =SUM(U6:U14) -> 9967992 | W14: =2586404548-2399878368 -> 186526180 | X14: =SUM(W6:W14) -> 2586404548
A15: Rybelsus: Dette er en tablettversjon av semaglutid | T15: 46125 | U15: =11007992-9967992 -> 1040000 | V15: =SUM(U$6:U15) -> 11007992 | W15: =2835176799-2586404548 -> 248772251 | X15: =SUM(W$6:W15) -> 2835176799
T16: 46132 | U16: =12257992-11007992 -> 1250000 | V16: =SUM(U$6:U16) -> 12257992 | W16: =3148710807-2835176799 -> 313534008 | X16: =SUM(W$6:W16) -> 3148710807
A17: Insulin: | T17: 46139 | U17: =13407992-12257992 -> 1150000 | V17: =SUM(U$6:U17) -> 13407992 | W17: =3438932195-3148710807 -> 290221388 | X17: =SUM(W$6:W17) -> 3438932195
A18: Dette er tradisjonelle insulinprodukter for folk med diabetes | T18: 46147 | U18: =14759179-13407992 -> 1351187 | V18: =SUM(U$6:U18) -> 14759179 | W18: =3799999990-3438931195 -> 361068795 | X18: =SUM(W$6:W18) -> 3800000990
A19: Long-acting insulin: Gir en jevn insulinfrigjøring hele døgnet (Levemir, Tresiba) | T19: 46160 | U19: 1239849 | V19: =SUM(U$6:U19) -> 15999028 | W19: 369728627 | X19: =SUM(W$6:W19) -> 4169729617
A20: Premix insulin: Blanding av rask- og langtidsvirkende insulin i en sprøyte, for enklere behandling | T20: 46168 | U20: 1060000 | V20: =SUM(U$6:U20) -> 17059028 | W20: =670560306-W19 -> 300831679 | X20: =SUM(W$6:W20) -> 4470561296
A21: Fast-acting insulin: tas rett før måltider for å håndtere blodsukkerstigningen som skjer når dub spsier | T21: 46174 | U21: 840151 | V21: =SUM(U$6:U21) -> 17899179 | W21: =913270696-670560306 -> 242710390 | X21: =SUM(W$6:W21) -> 4713271686
A22: Human insulin: Insulin som er identisk med det naturlige menneskeinsulinet, brukt før de nyere insulin-typene | T22: 46181 | U22: 840000 | V22: =SUM(U$6:U22) -> 18739179 | W22: =1158452492-913270696 -> 245181796 | X22: =SUM(W$6:W22) -> 4958453482
N23: Q226 oppjusterer | T23: 46188 | U23: 1125000 | V23: =SUM(U$6:U23) -> 19864179 | W23: =1469055829-1158452492 -> 310603337 | X23: =SUM(W$6:W23) -> 5269056819
A24: Obesity care: | N24: Adjusted sales growth: 0 to -6% at CER | T24: 46195 | U24: 1075000 | V24: =SUM(U$6:U24) -> 20939179 | W24: =1777005178-1469055829 -> 307949349 | X24: =SUM(W$6:W24) -> 5577006168
A25: Her handler alt om fedmebehandling, altså medisiner laget for vekttap | N25: Adjusted operating profit growth: 0 to -6% at CER | T25: 46202 | U25: 1050000 | V25: =SUM(U$6:U25) -> 21989179 | W25: =2098848921-1777005178 -> 321843743 | X25: =SUM(W$6:W25) -> 5898849911
T26: 46209 | U26: 1000000 | V26: =SUM(U$6:U26) -> 22989179 | W26: =2419775981-2098848921 -> 320927060 | X26: =SUM(W$6:W26) -> 6219776971
A27: Produktene her: | N27: LLY guider Revenues på 85-87 USDb | T27: 46216 | U27: 975000 | V27: =SUM(U$6:U27) -> 23964179 | W27: =2734545468-2419775981 -> 314769487 | X27: =SUM(W$6:W27) -> 6534546458
A28: Wegovy: Brukes spesifikt for fedmebehanling - inneholder semaglutid | N28: Oppjustert Q226 | T28: 46223 | U28: 975000 | V28: =SUM(U$6:U28) -> 24939179 | W28: =3053177399-2374545468 -> 678631931 | X28: =SUM(W$6:W28) -> 7213178389
A29: Saxenda: Et eldre vekttapsmiddel basert på et annet GLP-1 hormon (liraglutid) | T29: 46230 | U29: 960000 | V29: =SUM(U$6:U29) -> 25899179 | W29: =3362368903-3053177399 -> 309191504 | X29: =SUM(W$6:W29) -> 7522369893
T30: 46238 | U30: 1450000 | V30: =SUM(U6:U30) -> 27349179 | W30: =3733256468-3362368903 -> 370887565 | X30: =SUM(W6:W30) -> 7893257458
A31: Viktige medisiner: | E31: Hims and Hers | T31: 46244 | U31: 820000 | V31: =SUM(U6:U31) -> 28169179 | W31: =3980067920-3733256468 -> 246811452 | X31: =SUM(W6:W31) -> 8140068910
A32: CagriSema | E32: 07.02.26: Hims dropper å lanserer sine kopier | T32: 46251 | U32: 1000000 | V32: =SUM(U6:U32) -> 29169179 | W32: =4281660830-3980067920 -> 301592910 | X32: =SUM(W6:W32) -> 8441661820
A33: Amycretin | E33: 05.02.26: Lanserer egne compounded Semaglutide Pills til 49 USD/Month | T33: 46258 | U33: 1045000 | V33: =SUM(U6:U33) -> 30214179 | W33: =4590476842-4281660830 -> 308816012 | X33: =SUM(W6:W33) -> 8750477832
T34: 46265 | U34: 1050000 | V34: =SUM(U6:U34) -> 31264179 | W34: =4907673815-4590476842 -> 317196973 | X34: =SUM(W6:W34) -> 9067674805
T35: 46272 | U35: 1055000 | V35: =SUM(U6:U35) -> 32319179 | W35: =5221774293-4907673815 -> 314100478 | X35: =SUM(W6:W35) -> 9381775283
A36: Press release: | T36: 46279 | U36: 1050000 | V36: =SUM(U6:U36) -> 33369179 | W36: =5526186488-5221774293 -> 304412195 | X36: =SUM(W6:W36) -> 9686187478
A37: 21.09.26: Novo kjøper tilbake 1 090 000 B-aksjer | T37: 46286 | U37: 1090000 | V37: =SUM(U6:U37) -> 34459179 | W37: =5829922946-5526186488 -> 303736458 | X37: =SUM(W6:W37) -> 9989923936
A38: 14.09.26: Novo kjøper tilbake 1 050 00 B-aksjer
A39: 07.09.26: Novo kjøper tilbake 1 055 000 B-aksjer
A40: 31.08.26: Novo kjøper tilbake 1 050 000 B-aksjer
A41: 24.08.26: Novo kjøper tilbake 1 045 000 B-aksjer
...

Sheet Modell
A3: Kapitalstruktur | C3: DKK million | D3: Q122 | E3: Q222 | F3: Q322 | G3: Q422 | H3: Q123 | I3: Q223 | J3: Q323 | K3: Q423 | L3: Q124 | M3: Q224 | N3: Q324 | O3: Q424 | P3: Q125 | Q3: Q225 | R3: Q325 | S3: Q425 | T3: Q126 | U3: Q226 | V3: Q326 | W3: Q426 | AA3: FY 2015 | AB3: FY 2016 | AC3: FY 2017 | AD3: FY 2018 | AE3: FY 2019 | AF3: FY 2020 | AG3: FY 2021 | AH3: FY 2022 | AI3: FY 2023 | AJ3: FY 2024 | AK3: FY 2025 | AL3: FY 2026 | AM3: FY 2027 | AN3: FY 2028 | AO3: FY 2029 | AP3: FY 2030 | AQ3: FY 2031 | AR3: FY 2032 | AS3: FY 2033 | AT3: FY 2034 | AU3: FY 2035
A4: Price | B4: 246.7 | C4: GLP - 1 class | D4: =SUM(D5:D11) -> 26576.668 | E4: =SUM(E5:E11) -> 29861.684 | F4: =SUM(F5:F11) -> 33517.772 | G4: =SUM(G5:G11) -> 37666.304 | H4: =SUM(H5:H11) -> 44749.016 | I4: =SUM(I5:I11) -> 51365.392 | J4: =SUM(J5:J11) -> 57663.244 | K4: =SUM(K5:K11) -> 65199.072 | ... S4: =SUM(S5:S11) -> 133213.2 | T4: =SUM(T5:T12) -> 134692.36 | U4: =SUM(U5:U12) -> 156154.43 | V4: =SUM(V5:V12) -> 0 | W4: =SUM(W5:W12) -> 0
A5: S/O (m) | B5: 4443.5 | C5: Mounjaro | D5: 0 | E5: 0 | F5: =187.3*6.36 -> 1191.228 | G5: =3068.7-1191 -> 1877.7 | H5: =568.5*6.36 -> 3615.66 | I5: =979.7*6.36 -> 6230.892 | J5: =1409.3*6.36 -> 8963.148 | K5: =32837.3-H5-I5-J5 -> 14027.6 | L5: =1806.5*6.36 -> 11489.34 | M5: 19860 | N5: 20001 | O5: 22680 | P5: 24685 | Q5: 33404 | R5: 41861 | S5: =7409*6.36 -> 47121.24 | T5: 55263.56 | U5: 64331.21
A6: MC DKKm | B6: =B4*B5 -> 1096211.4 | C6: Zepbound | D6: 0 | E6: 0 | F6: 0 | G6: 0 | H6: 0 | I6: 0 | J6: 0 | K6: =175.8*6.36 -> 1118.088 | L6: =517.4*6.36 -> 3290.664 | M6: 7986 | N6: 8083 | O6: 12252 | P6: 14855 | Q6: 21723 | R6: 23053 | S6: =4261*6.36 -> 27099.96 | T6: 26540.8 | U6: 31884.16
A7: Cash DKKm | B7: =S92 -> 26464 | C7: Trulicity | D7: =1741.3*6.36 -> 11074.668 | E7: =1911.9*6.36 -> 12159.684 | F7: =1850.4*6.36 -> 11768.544 | G7: =47316.5-D7-E7-F7 -> 12313.604 | H7: =1977.1*6.36 -> 12574.356 | I7: =1812.5*6.36 -> 11527.5 | J7: =1673.6*6.36 -> 10644.096 | K7: =45363.336-H7-I7-J7 -> 10617.384 | L7: =1456.3*6.36 -> 9262.068 | M7: 8006 | N7: 8359 | O7: 8031 | P7: 7035 | Q7: 7016 | R7: 6759 | S7: 0 | T7: 0 | U7: 0
A8: Debt DKKm | B8: =S99+S105 -> 130958 | C8: Foundayo (Orfo pill) | D8: 0 | E8: 0 | F8: 0 | G8: 0 | H8: 0 | I8: 0 | J8: 0 | K8: 0 | L8: 0 | M8: 0 | N8: 0 | O8: 0 | P8: 0 | Q8: 0 | R8: 0 | S8: 0 | T8: 0 | U8: 634.06
A9: EV DKKm | B9: =B6-B7+B8 -> 1200705.4 | C9: Ozempic | D9: 12035 | E9: 14349 | F9: 16390 | G9: 16976 | H9: 19640 | I9: 22101 | J9: 23912 | K9: 23912 | L9: 27810 | M9: 28875 | N9: 29804 | O9: 33853 | P9: 32721 | Q9: 31799 | R9: 30744 | S9: 31825 | T9: 27825 | U9: 31375
C10: Rybelsus | D10: 2063 | E10: 2172 | F10: 3011 | G10: 4053 | H10: 4356 | I10: 3988 | J10: 4496 | K10: 5910 | L10: 5013 | M10: 5918 | N10: 5453 | O10: 6917 | P10: 5695 | Q10: 5653 | R10: 5442 | S10: 5303 | T10: 4572 | U10: 5228
A11: Gearing | C11: Wegovy injectable | D11: 1404 | E11: 1181 | F11: 1157 | G11: 2446 | H11: 4563 | I11: 7518 | J11: 9648 | K11: 9614 | L11: 9377 | M11: 11659 | N11: 17304 | O11: 19866 | P11: 17360 | Q11: 19528 | R11: 20354 | S11: 21864 | T11: 18235 | U11: 19484
A12: =(B8-B7)/U76 -> 0.73331181 | C12: Wegovy pill | D12: 0 | E12: 0 | F12: 0 | G12: 0 | H12: 0 | I12: 0 | J12: 0 | K12: 0 | L12: 0 | M12: 0 | N12: 0 | O12: 0 | P12: 0 | Q12: 0 | R12: 0 | S12: 0 | T12: 2256 | U12: 3218
C13: Class growth | H13: =(H4-D4)/D4 -> 0.68377074 | I13: =(I4-E4)/E4 -> 0.72011036 | J13: =(J4-F4)/F4 -> 0.72037819 | K13: =(K4-G4)/G4 -> 0.73096548 | L13: =(L4-H4)/H4 -> 0.48030232 | M13: =(M4-I4)/I4 -> 0.60232399 | N13: =(N4-J4)/J4 -> 0.54351358 | O13: =(O4-K4)/K4 -> 0.58896433 | ... W13: =(W4-S4)/S4 -> -1
C14: LLY growth | H14: =(SUM(H5:H7)-SUM(D5:D7))/SUM(D5:D7) -> 0.46189628 | I14: =(SUM(I5:I7)-SUM(E5:E7))/SUM(E5:E7) -> 0.46043203 | J14: =(SUM(J5:J7)-SUM(F5:F7))/SUM(F5:F7) -> 0.51293125 | K14: =(SUM(K5:K7)-SUM(G5:G7))/SUM(G5:G7) -> 0.81541259 | L14: =(SUM(L5:L7)-SUM(H5:H7))/SUM(H5:H7) -> 0.48499371 | M14: =(SUM(M5:M7)-SUM(I5:I7))/SUM(I5:I7) -> 1.0188765 | N14: =(SUM(N5:N7)-SUM(J5:J7))/SUM(J5:J7) -> 0.85864979 | O14: =(SUM(O5:O7)-SUM(K5:K7))/SUM(K5:K7) -> 0.66761945 | ... T14: =(SUM(T5:T7)-SUM(P5:P7))/SUM(P5:P7) -> 0.75640064 | U14: =(SUM(U5:U8)-SUM(Q5:Q7))/SUM(Q5:Q7) -> 0.55849299 | V14: =(SUM(V5:V8)-SUM(R5:R7))/SUM(R5:R7) -> -1 | W14: =(SUM(W5:W8)-SUM(S5:S7))/SUM(S5:S7) -> -1
C15: Novo growth | H15: =(SUM(H9:H11)-SUM(D9:D11))/SUM(D9:D11) -> 0.84227842 | I15: =(SUM(I9:I11)-SUM(E9:E11))/SUM(E9:E11) -> 0.89848605 | J15: =(SUM(J9:J11)-SUM(F9:F11))/SUM(F9:F11) -> 0.85115284 | K15: =(SUM(K9:K11)-SUM(G9:G11))/SUM(G9:G11) -> 0.6799148 | L15: =(SUM(L9:L11)-SUM(H9:H11))/SUM(H9:H11) -> 0.47764277 | M15: =(SUM(M9:M11)-SUM(I9:I11))/SUM(I9:I11) -> 0.38221204 | N15: =(SUM(N9:N11)-SUM(J9:J11))/SUM(J9:J11) -> 0.38114883 | O15: =(SUM(O9:O11)-SUM(K9:K11))/SUM(K9:K11) -> 0.53757988 | ... S15: =(SUM(S9:S11)-SUM(O9:O11))/SUM(O9:O11) -> -0.027112606 | T15: =(SUM(T9:T12)-SUM(P9:P11))/SUM(P9:P11) -> -0.051778543 | U15: =(SUM(U9:U12)-SUM(Q9:Q11))/SUM(Q9:Q11) -> 0.040803791 | V15: =(SUM(V9:V12)-SUM(R9:R11))/SUM(R9:R11) -> -1 | W15: =(SUM(W9:W12)-SUM(S9:S11))/SUM(S9:S11) -> -1
A17: USD/DKK | C17: Injectable GLP-1 | D17: =D18+D19 -> 15357 | E17: =E18+E19 -> 17059 | F17: =F18+F19 -> 19357 | G17: =G18+G19 -> 20299 | H17: =H18+H19 -> 22455 | I17: =I18+I19 -> 23937 | J17: =J18+J19 -> 26139 | K17: =K18+K19 -> 31851 | ... W17: =W18+W19 -> 0 | AA17: =AA18+AA19 -> 18027 | AB17: =AB18+AB19 -> 20046 | AC17: =AC18+AC19 -> 23173 | AD17: =AD18+AD19 -> 26129 | AE17: =AE18+AE19 -> 33171 | AF17: =AF18+AF19 -> 39958 | AG17: =AG18+AG19 -> 48759 | AH17: =AH18+AH19 -> 72072 | ... AK17: =AK18+AK19 -> 130109
A18: 6.47 | C18: Ozempic | D18: 12035 | E18: 14349 | F18: 16390 | G18: 16976 | H18: 19640 | I18: 22101 | J18: 23912 | K18: 30065 | L18: 27810 | M18: 28875 | N18: 29804 | O18: 33853 | P18: 32721 | Q18: 31799 | R18: 30744 | S18: 31825 | T18: 27825 | U18: 31375 | AA18: 0 | AB18: 0 | AC18: 0 | AD18: 1796 | AE18: 11237 | AF18: 21211 | AG18: 33705 | AH18: =SUM(D18:G18) -> 59750 | AI18: =SUM(H18:K18) -> 95718 | AJ18: =SUM(L18:O18) -> 120342 | AK18: =SUM(P18:S18) -> 127089
C19: Victoza | D19: 3322 | E19: 2710 | F19: 2967 | G19: 3323 | H19: 2815 | I19: 1836 | J19: 2227 | K19: 1786 | L19: 2159 | M19: 2242 | N19: -322 | O19: 1403 | P19: 1158 | Q19: 914 | R19: 549 | S19: 399 | T19: 334 | U19: 181 | AA19: 18027 | AB19: 20046 | AC19: 23173 | AD19: 24333 | AE19: 21934 | AF19: 18747 | AG19: 15054 | AH19: =SUM(D19:G19) -> 12322 | AI19: =SUM(H19:K19) -> 8664 | AJ19: =SUM(L19:O19) -> 5482 | AK19: =SUM(P19:S19) -> 3020
C20: Rybelsus | D20: 2063 | E20: 2172 | F20: 3011 | G20: 4053 | H20: 4356 | I20: 3988 | J20: 4496 | K20: 5910 | L20: 5013 | M20: 5918 | N20: 5453 | O20: 6917 | P20: 5695 | Q20: 5653 | R20: 5442 | S20: 5303 | T20: 4572 | U20: 5228 | AA20: 0 | AB20: 0 | AC20: 0 | AD20: 0 | AE20: 50 | AF20: 1873 | AG20: 4838 | AH20: =SUM(D20:G20) -> 11299 | AI20: =SUM(H20:K20) -> 18750 | AJ20: =SUM(L20:O20) -> 23301 | AK20: =SUM(P20:S20) -> 22093
C21: Total GLP-1 | D21: =D17+D20 -> 17420 | E21: =E17+E20 -> 19231 | F21: =F17+F20 -> 22368 | G21: =G17+G20 -> 24352 | H21: =H17+H20 -> 26811 | I21: =I17+I20 -> 27925 | J21: =J17+J20 -> 30635 | K21: =K17+K20 -> 37761 | ... W21: =W17+W20 -> 0 | AA21: =AA17+AA20 -> 18027 | AB21: =AB17+AB20 -> 20046 | AC21: =AC17+AC20 -> 23173 | AD21: =AD17+AD20 -> 26129 | AE21: =AE17+AE20 -> 33221 | AF21: =AF17+AF20 -> 41831 | AG21: =AG17+AG20 -> 53597 | AH21: =AH17+AH20 -> 83371 | ... AK21: =AK17+AK20 -> 152202
C22: Long-acting insulin | D22: =SUM(D23:D26) -> 4796 | E22: =SUM(E23:E26) -> 4104 | F22: =SUM(F23:F26) -> 3939 | G22: =SUM(G23:G26) -> 3902 | H22: =SUM(H23:H26) -> 4133 | I22: =SUM(I23:I26) -> 3354 | J22: =SUM(J23:J26) -> 3692 | K22: =SUM(K23:K26) -> 3726 | ... S22: =SUM(S23:S26) -> 4700 | T22: 4232 | U22: 4412 | V22: =SUM(V23:V26) -> 0 | W22: =SUM(W23:W26) -> 0 | AA22: =SUM(AA23:AA26) -> 19738 | AB22: =SUM(AB23:AB26) -> 21542 | AC22: =SUM(AC23:AC26) -> 22174 | AD22: =SUM(AD23:AD26) -> 20844 | AE22: =SUM(AE23:AE26) -> 20776 | AF22: =SUM(AF23:AF26) -> 18439 | AG22: =SUM(AG23:AG26) -> 18064 | AH22: =SUM(AH23:AH26) -> 16741 | ... AK22: =SUM(AK23:AK26) -> 18755
C23: Tresiba | D23: 2564 | E23: 2269 | F23: 2273 | G23: 2247 | H23: 2179 | I23: 1747 | J23: 1910 | K23: 1916 | L23: 2763 | M23: 2297 | N23: 2110 | O23: 2735 | P23: 3577 | Q23: 2800 | R23: 2624 | S23: 3048 | AA23: 1438 | AB23: 4459 | AC23: 7327 | AD23: 8035 | AE23: 9259 | AF23: 8968 | AG23: 9729 | AH23: =SUM(D23:G23) -> 9353 | AI23: =SUM(H23:K23) -> 7752 | AJ23: =SUM(L23:O23) -> 9905 | AK23: =SUM(P23:S23) -> 12049
C24: Xultophy | D24: 717 | E24: 691 | F24: 705 | G24: 696 | H24: 781 | I24: 854 | J24: 798 | K24: 786 | L24: 1123 | M24: 1067 | N24: 1039 | O24: 1274 | P24: 1209 | Q24: 1132 | R24: 1120 | S24: 1158 | AA24: 0 | AB24: 0 | AC24: 729 | AD24: 1614 | AE24: 2210 | AF24: 2444 | AG24: 2657 | AH24: =SUM(D24:G24) -> 2809 | AI24: =SUM(H24:K24) -> 3219 | AJ24: =SUM(L24:O24) -> 4503 | AK24: =SUM(P24:S24) -> 4619
C25: Levemir | D25: 1515 | E25: 1144 | F25: 961 | G25: 959 | H25: 1173 | I25: 753 | J25: 984 | K25: 1024 | L25: 1279 | M25: 1371 | N25: 879 | O25: 1139 | P25: 543 | Q25: 475 | R25: 314 | S25: 345 | AA25: 18300 | AB25: 17083 | AC25: 14118 | AD25: 11195 | AE25: 9307 | AF25: 7027 | AG25: 5678 | AH25: =SUM(D25:G25) -> 4579 | AI25: =SUM(H25:K25) -> 3934 | AJ25: =SUM(L25:O25) -> 4668 | AK25: =SUM(P25:S25) -> 1677
C26: Awiqli | M26: 2 | N26: 7 | O26: 10 | P26: 59 | Q26: 60 | R26: 142 | S26: 149 | AA26: 0 | AB26: 0 | AC26: 0 | AD26: 0 | AE26: 0 | AF26: 0 | AG26: 0 | AH26: =SUM(D26:G26) -> 0 | AI26: =SUM(H26:K26) -> 0 | AJ26: =SUM(L26:O26) -> 19 | AK26: =SUM(P26:S26) -> 410
C27: Premix insulin | D27: =SUM(D28:D29) -> 3012 | E27: =SUM(E28:E29) -> 2501 | F27: =SUM(F28:F29) -> 2706 | G27: =SUM(G28:G29) -> 2343 | H27: =SUM(H28:H29) -> 2776 | I27: =SUM(I28:I29) -> 2456 | J27: =SUM(J28:J29) -> 2219 | K27: =SUM(K28:K29) -> 2123 | ... S27: =SUM(S28:S29) -> 2509 | T27: 2395 | U27: 2790 | V27: =SUM(V28:V29) -> 0 | W27: =SUM(W28:W29) -> 0 | AA27: =SUM(AA28:AA29) -> 11144 | AB27: =SUM(AB28:AB29) -> 10482 | AC27: =SUM(AC28:AC29) -> 10749 | AD27: =SUM(AD28:AD29) -> 10194 | AE27: =SUM(AE28:AE29) -> 10578 | AF27: =SUM(AF28:AF29) -> 10925 | AG27: =SUM(AG28:AG29) -> 11203 | AH27: =SUM(AH28:AH29) -> 10562 | ... AK27: =SUM(AK28:AK29) -> 10315
C28: Ryzodeg | D28: 637 | E28: 715 | F28: 807 | G28: 730 | H28: 971 | I28: 986 | J28: 864 | K28: 909 | L28: 1267 | M28: 1163 | N28: 1153 | O28: 1346 | P28: 1432 | Q28: 1363 | R28: 1289 | S28: 1298 | AA28: 0 | AB28: 0 | AC28: 492 | AD28: 714 | AE28: 993 | AF28: 1291 | AG28: 1711 | AH28: =SUM(D28:G28) -> 2889 | AI28: =SUM(H28:K28) -> 3730 | AJ28: =SUM(L28:O28) -> 4929 | AK28: =SUM(P28:S28) -> 5382
C29: Novomix | D29: 2375 | E29: 1786 | F29: 1899 | G29: 1613 | H29: 1805 | I29: 1470 | J29: 1355 | K29: 1214 | L29: 1701 | M29: 1273 | N29: 1365 | O29: 1521 | P29: 1381 | Q29: 1273 | R29: 1068 | S29: 1211 | AA29: 11144 | AB29: 10482 | AC29: 10257 | AD29: 9480 | AE29: 9585 | AF29: 9634 | AG29: 9492 | AH29: =SUM(D29:G29) -> 7673 | AI29: =SUM(H29:K29) -> 5844 | AJ29: =SUM(L29:O29) -> 5860 | AK29: =SUM(P29:S29) -> 4933
C30: Fast-acting insulin | D30: =SUM(D31:D32) -> 4842 | E30: =SUM(E31:E32) -> 3887 | F30: =SUM(F31:F32) -> 4263 | G30: =SUM(G31:G32) -> 4471 | H30: =SUM(H31:H32) -> 4488 | I30: =SUM(I31:I32) -> 3511 | J30: =SUM(J31:J32) -> 3808 | K30: =SUM(K31:K32) -> 4142 | ... S30: =SUM(S31:S32) -> 4880 | T30: 3955 | U30: 4691 | V30: =SUM(V31:V32) -> 0 | W30: =SUM(W31:W32) -> 0 | AA30: =SUM(AA31:AA32) -> 20720 | AB30: =SUM(AB31:AB32) -> 19945 | AC30: =SUM(AC31:AC32) -> 20124 | AD30: =SUM(AD31:AD32) -> 19353 | AE30: =SUM(AE31:AE32) -> 19303 | AF30: =SUM(AF31:AF32) -> 18313 | AG30: =SUM(AG31:AG32) -> 17687 | AH30: =SUM(AH31:AH32) -> 17463 | ... AK30: =SUM(AK31:AK32) -> 18583
C31: Fiasp | D31: 497 | E31: 516 | F31: 485 | G31: 505 | H31: 518 | I31: 447 | J31: 574 | K31: 634 | L31: 567 | M31: 565 | N31: 394 | O31: 343 | P31: 834 | Q31: 515 | R31: 632 | S31: 837 | AB31: 0 | AC31: 99 | AD31: 590 | AE31: 1243 | AF31: 1385 | AG31: 1748 | AH31: =SUM(D31:G31) -> 2003 | AI31: =SUM(H31:K31) -> 2173 | AJ31: =SUM(L31:O31) -> 1869 | AK31: =SUM(P31:S31) -> 2818
C32: NovoRapid | D32: 4345 | E32: 3371 | F32: 3778 | G32: 3966 | H32: 3970 | I32: 3064 | J32: 3234 | K32: 3508 | L32: 3920 | M32: 3303 | N32: 3756 | O32: 5674 | P32: 4218 | Q32: 4027 | R32: 3477 | S32: 4043 | AA32: 20720 | AB32: 19945 | AC32: 20025 | AD32: 18763 | AE32: 18060 | AF32: 16928 | AG32: 15939 | AH32: =SUM(D32:G32) -> 15460 | AI32: =SUM(H32:K32) -> 13776 | AJ32: =SUM(L32:O32) -> 16653 | AK32: =SUM(P32:S32) -> 15765
C33: Human insulin | D33: 2312 | E33: 1851 | F33: 2053 | G33: 1970 | H33: 2012 | I33: 1967 | J33: 1626 | K33: 1989 | L33: 1745 | M33: 1571 | N33: 1806 | O33: 1845 | P33: 1744 | Q33: 1101 | R33: 1327 | S33: 1312 | T33: 1063 | U33: 1048 | AA33: 11231 | AB33: 11090 | AC33: 9793 | AD33: 9265 | AE33: 9036 | AF33: 0 | AG33: 9052 | AH33: =SUM(D33:G33) -> 8186 | AI33: =SUM(H33:K33) -> 7594 | AJ33: =SUM(L33:O33) -> 6967 | AK33: =SUM(P33:S33) -> 5484
C34: Total insulin | D34: =D22+D27+D30+D33 -> 14962 | E34: =E22+E27+E30+E33 -> 12343 | F34: =F22+F27+F30+F33 -> 12961 | G34: =G22+G27+G30+G33 -> 12686 | H34: =H22+H27+H30+H33 -> 13409 | I34: =I22+I27+I30+I33 -> 11288 | J34: =J22+J27+J30+J33 -> 11345 | K34: =K22+K27+K30+K33 -> 11980 | ... W34: =W22+W27+W30+W33 -> 0 | AA34: =AA22+AA27+AA30+AA33 -> 62833 | AB34: =AB22+AB27+AB30+AB33 -> 63059 | AC34: =AC22+AC27+AC30+AC33 -> 62840 | AD34: =AD22+AD27+AD30+AD33 -> 59656 | AE34: =AE22+AE27+AE30+AE33 -> 59693 | AF34: =AF22+AF27+AF30+AF33 -> 47677 | AG34: =AG22+AG27+AG30+AG33 -> 56006 | AH34: =AH22+AH27+AH30+AH33 -> 52952 | ... AK34: =AK22+AK27+AK30+AK33 -> 53137
C35: Other diabetes care | D35: 884 | E35: 830 | F35: 798 | G35: 713 | H35: 729 | I35: 667 | J35: 594 | K35: 322 | L35: 583 | M35: 533 | N35: 492 | O35: 512 | P35: 473 | Q35: 454 | R35: 421 | S35: 422 | T35: 560 | U35: 704 | AA35: 4270 | AB35: 4267 | AC35: 4302 | AD35: 4250 | AE35: 4247 | AF35: 4031 | AG35: 3594 | AH35: =SUM(D35:G35) -> 3225 | AI35: =SUM(H35:K35) -> 2312 | AJ35: =SUM(L35:O35) -> 2120 | AK35: =SUM(P35:S35) -> 1770
C36: Total diabetes care | D36: =D21+D34+D35 -> 33266 | E36: =E21+E34+E35 -> 32404 | F36: =F21+F34+F35 -> 36127 | G36: =G21+G34+G35 -> 37751 | H36: =H21+H34+H35 -> 40949 | I36: =I21+I34+I35 -> 39880 | J36: =J21+J34+J35 -> 42574 | K36: =K21+K34+K35 -> 50063 | ... W36: =W21+W34+W35 -> 0 | AA36: =AA21+AA34+AA35 -> 85130 | AB36: =AB21+AB34+AB35 -> 87372 | AC36: =AC21+AC34+AC35 -> 90315 | AD36: =AD21+AD34+AD35 -> 90035 | AE36: =AE21+AE34+AE35 -> 97161 | AF36: =AF21+AF34+AF35 -> 93539 | AG36: =AG21+AG34+AG35 -> 113197 | AH36: =AH21+AH34+AH35 -> 139548 | ... AK36: =AK21+AK34+AK35 -> 207109
C37: Wegovy injectable | D37: 1404 | E37: 1181 | F37: 1157 | G37: 2446 | H37: 4563 | I37: 7518 | J37: 9648 | K37: 9614 | L37: 9377 | M37: 11659 | N37: 17304 | O37: 19866 | P37: 17360 | Q37: 19528 | R37: 20354 | S37: 21864 | T37: 18235 | U37: 19484 | AA37: 0 | AB37: 0 | AC37: 0 | AD37: 0 | AE37: 0 | AF37: 0 | AG37: 0 | AH37: =SUM(D37:G37) -> 6188 | AI37: =SUM(H37:K37) -> 31343 | AJ37: =SUM(L37:O37) -> 58206 | AK37: =SUM(P37:S37) -> 79106
C38: Wegovy pill | T38: 2256 | U38: 3218
C39: Saxenda | D39: 1998 | E39: 2462 | F39: 3174 | G39: 3042 | H39: 3279 | I39: 2788 | J39: 2607 | K39: 1615 | L39: 1658 | M39: 2245 | N39: 1497 | O39: 1540 | P39: 1064 | Q39: 844 | R39: 752 | S39: 581 | T39: 421 | U39: 450 | AA39: 460 | AB39: 1577 | AC39: 2562 | AD39: 3869 | AE39: 5679 | AF39: 5608 | AG39: 8400 | AH39: =SUM(D39:G39) -> 10676 | AI39: =SUM(H39:K39) -> 10289 | AJ39: =SUM(L39:O39) -> 6940 | AK39: =SUM(P39:S39) -> 3241
C40: Total obesity care | D40: =SUM(D37:D39) -> 3402 | E40: =SUM(E37:E39) -> 3643 | F40: =SUM(F37:F39) -> 4331 | G40: =SUM(G37:G39) -> 5488 | H40: =SUM(H37:H39) -> 7842 | I40: =SUM(I37:I39) -> 10306 | J40: =SUM(J37:J39) -> 12255 | K40: =SUM(K37:K39) -> 11229 | ... W40: =SUM(W37:W39) -> 0 | AA40: =SUM(AA37:AA39) -> 460 | AB40: =SUM(AB37:AB39) -> 1577 | AC40: =SUM(AC37:AC39) -> 2562 | AD40: =SUM(AD37:AD39) -> 3869 | AE40: =SUM(AE37:AE39) -> 5679 | AF40: =SUM(AF37:AF39) -> 5608 | AG40: =SUM(AG37:AG39) -> 8400 | AH40: =SUM(AH37:AH39) -> 16864 | ... AK40: =SUM(AK37:AK39) -> 82347
C41: Diabetes and obesity care total | D41: =D36+D40 -> 36668 | E41: =E36+E40 -> 36047 | F41: =F36+F40 -> 40458 | G41: =G36+G40 -> 43239 | H41: =H36+H40 -> 48791 | I41: =I36+I40 -> 50186 | J41: =J36+J40 -> 54829 | K41: =K36+K40 -> 61292 | ... W41: =W36+W40 -> 0 | AA41: =AA36+AA40 -> 85590 | AB41: =AB36+AB40 -> 88949 | AC41: =AC36+AC40 -> 92877 | AD41: =AD36+AD40 -> 93904 | AE41: =AE36+AE40 -> 102840 | AF41: =AF36+AF40 -> 99147 | AG41: =AG36+AG40 -> 121597 | AH41: =AH36+AH40 -> 156412 | ... AK41: =AK36+AK40 -> 289456
C42: Rare blood disorders | D42: =SUM(D43:D46) -> 3077 | E42: =SUM(E43:E46) -> 2863 | F42: =SUM(F43:F46) -> 2885 | G42: =SUM(G43:G46) -> 2881 | H42: =SUM(H43:H46) -> 3049 | I42: =SUM(I43:I46) -> 2836 | J42: =SUM(J43:J46) -> 2957 | K42: =SUM(K43:K46) -> 2934 | ... S42: =SUM(S43:S46) -> 3293 | T42: 2633 | U42: 2896 | V42: =SUM(V43:V46) -> 0 | W42: =SUM(W43:W46) -> 0 | AA42: =SUM(AA43:AA46) -> 22337 | AB42: =SUM(AB43:AB46) -> 22831 | AC42: =SUM(AC43:AC46) -> 12164 | AD42: =SUM(AD43:AD46) -> 11093 | AE42: =SUM(AE43:AE46) -> 11906 | AF42: =SUM(AF43:AF46) -> 9662 | AG42: =SUM(AG43:AG46) -> 10217 | AH42: =SUM(AH43:AH46) -> 11706 | ... AK42: =SUM(AK43:AK46) -> 12386
C43: Haemophilia A | D43: 565 | E43: 619 | F43: 512 | G43: 642 | H43: 660 | I43: 688 | J43: 549 | K43: 525 | L43: 603 | M43: 613 | N43: 568 | O43: 670 | P43: 554 | Q43: 584 | R43: 638 | S43: 638 | AA43: 10647 | AB43: 10472 | AC43: 160 | AD43: 341 | AE43: 3687 | AF43: 0 | AG43: 2112 | AH43: =SUM(D43:G43) -> 2338 | AI43: =SUM(H43:K43) -> 2422 | AJ43: =SUM(L43:O43) -> 2454 | AK43: =SUM(P43:S43) -> 2414
...

Sheet Salg geografisk
B4: DKK million | C4: Q122 | D4: Q222 | E4: Q322 | F4: Q422 | G4: 2022 | H4: Q123 | I4: Q223 | J4: Q323 | K4: Q423 | L4: 2023 | M4: Q124 | N4: Q224 | O4: Q324 | P4: Q424 | Q4: 2024 | R4: Q125 | S4: Q225 | T4: Q325 | U4: Q425 | V4: 2025 | W4: Q126 | X4: Q226 | Y4: Q326 | Z4: Q426 | AA4: 2026
B5: US operations | G5: =SUM(C5:F5) -> 0 | L5: =SUM(H5:K5) -> 0 | Q5: =SUM(M5:P5) -> 0 | R5: 44316 | S5: 42963 | T5: 41144 | U5: 44743 | V5: =SUM(R5:U5) -> 173166 | W5: 35385 | X5: 40869 | AA5: =SUM(W5:Z5) -> 76254
B6: y/y | R6: 0.2 | S6: 0.12 | T6: 0.03 | U6: -0.15 | W6: -0.2 | X6: 0.01
B7: y/y CER | R7: 0.17 | S7: 0.18 | T7: 0.1 | U7: -0.07 | W7: -0.11 | X7: 0.04
B8: International operations | C8: =C9+C12+C15+C18 -> 0 | D8: =D9+D12+D15+D18 -> 0 | E8: =E9+E12+E15+E18 -> 0 | F8: =F9+F12+F15+F18 -> 0 | G8: =G9+G12+G15+G18 -> 0 | H8: =H9+H12+H15+H18 -> 0 | I8: =I9+I12+I15+I18 -> 0 | J8: =J9+J12+J15+J18 -> 0 | ... AA8: =AA9+AA12+AA15+AA18 -> 72297
B9: EUCAN | G9: =SUM(C9:F9) -> 0 | L9: =SUM(H9:K9) -> 0 | Q9: =SUM(M9:P9) -> 0 | R9: 14765 | S9: 16447 | T9: 16767 | U9: 18112 | V9: =SUM(R9:U9) -> 66091 | W9: 17918 | X9: 19206 | AA9: =SUM(W9:Z9) -> 37124
B10: y/y | R10: 0.13 | S10: 0.18 | T10: 0.19 | U10: 0.1 | W10: 0.21 | X10: 0.17
B11: y/y CER | R11: 0.13 | S11: 0.2 | T11: 0.21 | U11: 0.12 | W11: 0.23 | X11: 0.17
B12: Emerging markets | G12: =SUM(C12:F12) -> 0 | L12: =SUM(H12:K12) -> 0 | Q12: =SUM(M12:P12) -> 0 | R12: 8790 | S12: 7544 | T12: 6635 | U12: 7467 | V12: =SUM(R12:U12) -> 30436 | W12: 6861 | X12: 8413 | AA12: =SUM(W12:Z12) -> 15274
B13: y/y | R13: 0.21 | S13: 0.12 | T13: -0.2 | U13: 0.04 | W13: -0.22 | X13: 0.12
B14: y/y CER | R14: 0.24 | S14: 0.2 | T14: -0.15 | U14: 0.09 | W14: -0.18 | X14: 0.05
B15: APAC | G15: =SUM(C15:F15) -> 0 | L15: =SUM(H15:K15) -> 0 | Q15: =SUM(M15:P15) -> 0 | R15: 4594 | S15: 5615 | T15: 5466 | U15: 5038 | V15: =SUM(R15:U15) -> 20713 | W15: 5125 | X15: 5030 | AA15: =SUM(W15:Z15) -> 10155
B16: y/y | R16: 0.24 | S16: 0.4 | T16: 0.26 | U16: -0.06 | W16: 0.12 | X16: -0.1
B17: y/y CER | R17: 0.25 | S17: 0.45 | T17: 0.35 | U17: 0.03 | W17: 0.22 | X17: -0.06
B18: Region China | G18: =SUM(C18:F18) -> 0 | L18: =SUM(H18:K18) -> 0 | Q18: =SUM(M18:P18) -> 0 | R18: 5622 | S18: 4288 | T18: 4964 | U18: 3784 | V18: =SUM(R18:U18) -> 18658 | W18: 4774 | X18: 4970 | AA18: =SUM(W18:Z18) -> 9744
B19: y/y | R19: 0.25 | S19: -0.14 | T19: 0.05 | U19: -0.01 | W19: -0.15 | X19: 0.16
B20: y/y CER | R20: 0.22 | S20: -0.09 | T20: 0.12 | U20: -0.06 | W20: -0.1 | X20: 0.13
B21: Total | G21: =G5+G8 -> 0 | L21: =L5+L8 -> 0 | Q21: =Q5+Q8 -> 0 | R21: =R5+R8 -> 78087 | S21: =S5+S8 -> 76857 | T21: =T5+T8 -> 74976 | U21: =U5+U8 -> 79144 | V21: =V5+V8 -> 309064 | W21: =W5+W8 -> 70063 | X21: =X5+X8 -> 78488 | ... AA21: =AA5+AA8 -> 148551

Sheet Nøkkeltall
D4: 2026 | E4: 2027 | F4: 2028
C5: EV/EBIT | D5: =Modell!$B$9/Modell!AL56 -> 9.8745203 | E5: =Modell!$B$9/Modell!AM56 -> 8.9288521 | F5: =Modell!$B$9/Modell!AN56 -> 8.3447216
C6: P/E | D6: =Modell!$B$4/Modell!AL62 -> 11.000414 | E6: =Modell!$B$4/Modell!AM62 -> 9.9632184 | F6: =Modell!$B$4/Modell!AN62 -> 9.319164

Sheet Nedsidebergning
A3: Nedside | D3: FY 2019 | E3: FY 2020 | F3: FY 2021 | G3: FY 2022 | H3: FY 2023 | I3: FY 2024 | J3: FY 2025 | K3: FY 2026 | L3: FY 2027 | M3: FY 2028 | N3: FY 2029 | O3: FY 2030 | P3: FY 2031 | Q3: FY 2032 | R3: FY 2033 | S3: FY 2034 | T3: FY 2035
A4: Nullvekst og konstante marginer | C4: Revenue | D4: 122021 | E4: 126946 | F4: 140800 | G4: 176954 | H4: 232261 | I4: 290403 | J4: 309064 | K4: =J4*0.94 -> 290520.16 | L4: =K4*1 -> 290520.16 | M4: =L4*1 -> 290520.16 | N4: =M4*1 -> 290520.16 | O4: =N4*1 -> 290520.16 | P4: =O4*1 -> 290520.16 | Q4: =P4*1 -> 290520.16 | R4: =Q4*1 -> 290520.16 | S4: =R4*1 -> 290520.16 | T4: =S4*1 -> 290520.16
A5: =W25 -> 260.40482 | C5: COGS | D5: -20088 | E5: -20932 | F5: -23658 | G5: -28448 | H5: -35765 | I5: -44522 | J5: -58788 | K5: =K6-K4 -> -61009.234 | L5: =L6-L4 -> -61009.234 | M5: =M6-M4 -> -61009.234 | N5: =N6-N4 -> -61009.234 | O5: =O6-O4 -> -61009.234 | P5: =P6-P4 -> -61009.234 | Q5: =Q6-Q4 -> -61009.234 | R5: =R6-R4 -> -61009.234 | ... T5: =T6-T4 -> -61009.234
A6: =W26 -> 0.055552561 | C6: Gross profit | D6: =SUM(D4:D5) -> 101933 | E6: =SUM(E4:E5) -> 106014 | F6: =SUM(F4:F5) -> 117142 | G6: =SUM(G4:G5) -> 148506 | H6: =SUM(H4:H5) -> 196496 | I6: =SUM(I4:I5) -> 245881 | J6: =SUM(J4:J5) -> 250276 | K6: =K4*0.79 -> 229510.93 | L6: =L4*0.79 -> 229510.93 | M6: =M4*0.79 -> 229510.93 | N6: =N4*0.79 -> 229510.93 | O6: =O4*0.79 -> 229510.93 | P6: =P4*0.79 -> 229510.93 | Q6: =Q4*0.79 -> 229510.93 | R6: =R4*0.79 -> 229510.93 | ... T6: =T4*0.79 -> 229510.93
C7: Sales and distribution costs | D7: -31823 | E7: -32928 | F7: -37008 | G7: -46217 | H7: -56743 | I7: -62101 | J7: -64310 | K7: =J7*0.88 -> -56592.8 | L7: =K7 -> -56592.8 | M7: =L7 -> -56592.8 | N7: =M7 -> -56592.8 | O7: =N7 -> -56592.8 | P7: =O7 -> -56592.8 | Q7: =P7 -> -56592.8 | R7: =Q7 -> -56592.8 | S7: =R7 -> -56592.8 | T7: =S7 -> -56592.8
C8: R&D | D8: -14220 | E8: -15462 | F8: -17772 | G8: -24047 | H8: -32443 | I8: -48062 | J8: -52039 | K8: =J8*0.88 -> -45794.32 | L8: =K8 -> -45794.32 | M8: =L8 -> -45794.32 | N8: =M8 -> -45794.32 | O8: =N8 -> -45794.32 | P8: =O8 -> -45794.32 | Q8: =P8 -> -45794.32 | R8: =Q8 -> -45794.32 | S8: =R8 -> -45794.32 | T8: =S8 -> -45794.32
C9: Admin cost | D9: -4007 | E9: -3958 | F9: -4050 | G9: -4467 | H9: -4855 | I9: -5276 | J9: -5969 | K9: =J9*0.88 -> -5252.72 | L9: =K9 -> -5252.72 | M9: =L9 -> -5252.72 | N9: =M9 -> -5252.72 | O9: =N9 -> -5252.72 | P9: =O9 -> -5252.72 | Q9: =P9 -> -5252.72 | R9: =Q9 -> -5252.72 | S9: =R9 -> -5252.72 | T9: =S9 -> -5252.72
C10: Other operating income/expense | D10: 600 | E10: 460 | F10: 332 | G10: 1034 | H10: 119 | I10: -2103 | J10: -300 | K10: =J10*0.88 -> -264 | L10: =K10 -> -264 | M10: =L10 -> -264 | N10: =M10 -> -264 | O10: =N10 -> -264 | P10: =O10 -> -264 | Q10: =P10 -> -264 | R10: =Q10 -> -264 | S10: =R10 -> -264 | T10: =S10 -> -264
C11: Operating profit EBIT | D11: =SUM(D6:D10) -> 52483 | E11: =SUM(E6:E10) -> 54126 | F11: =SUM(F6:F10) -> 58644 | G11: =SUM(G6:G10) -> 74809 | H11: =SUM(H6:H10) -> 102574 | I11: =SUM(I6:I10) -> 128339 | J11: =SUM(J6:J10) -> 127658 | K11: =SUM(K6:K10) -> 121607.09 | ... T11: =SUM(T6:T10) -> 121607.09
C12: Financial income | D12: 65 | E12: 1628 | F12: 2887 | G12: 239 | H12: 2945 | I12: 6198 | J12: 9660 | K12: =J12*1.03 -> 9949.8 | L12: 0 | M12: 0 | N12: 0 | O12: 0 | P12: 0 | Q12: 0 | R12: 0 | S12: 0 | T12: 0
C13: Financial expense | D13: -3995 | E13: -2624 | F13: -2451 | G13: -5986 | H13: -845 | I13: -7346 | J13: -6778 | K13: =J13*1.03 -> -6981.34 | L13: 0 | M13: 0 | N13: 0 | O13: 0 | P13: 0 | Q13: 0 | R13: 0 | S13: 0 | T13: 0
C14: PTP | D14: =SUM(D11:D13) -> 48553 | E14: =SUM(E11:E13) -> 53130 | F14: =SUM(F11:F13) -> 59080 | G14: =SUM(G11:G13) -> 69062 | H14: =SUM(H11:H13) -> 104674 | I14: =SUM(I11:I13) -> 127191 | J14: =SUM(J11:J13) -> 130540 | K14: =SUM(K11:K13) -> 124575.55 | ... T14: =SUM(T11:T13) -> 121607.09
C15: Tax | D15: -9602 | E15: -10992 | F15: -11323 | G15: -13537 | H15: -20991 | I15: -26203 | J15: -28106 | K15: =K14*-0.2 -> -24915.109 | L15: =L14*-0.2 -> -24321.417 | M15: =M14*-0.2 -> -24321.417 | N15: =N14*-0.2 -> -24321.417 | O15: =O14*-0.2 -> -24321.417 | P15: =P14*-0.2 -> -24321.417 | Q15: =Q14*-0.2 -> -24321.417 | R15: =R14*-0.2 -> -24321.417 | ... T15: =T14*-0.2 -> -24321.417
C16: Net income | D16: =SUM(D14:D15) -> 38951 | E16: =SUM(E14:E15) -> 42138 | F16: =SUM(F14:F15) -> 47757 | G16: =SUM(G14:G15) -> 55525 | H16: =SUM(H14:H15) -> 83683 | I16: =SUM(I14:I15) -> 100988 | J16: =SUM(J14:J15) -> 102434 | K16: =SUM(K14:K15) -> 99660.437 | ... T16: =SUM(T14:T15) -> 97285.669 | U16: =T16*(1+$W$22) -> 96312.812 | V16: =U16*(1+$W$22) -> 95349.684 | W16: =V16*(1+$W$22) -> 94396.187 | X16: =W16*(1+$W$22) -> 93452.226 | Y16: =X16*(1+$W$22) -> 92517.703 | Z16: =Y16*(1+$W$22) -> 91592.526 | AA16: =Z16*(1+$W$22) -> 90676.601 | AB16: =AA16*(1+$W$22) -> 89769.835 | ... DT16: =DS16*(1+$W$22) -> 34206.537
C17: EPS | D17: =D16/D18 -> 16.374911 | E17: =E16/E18 -> 18.007692 | F17: =F16/F18 -> 20.735965 | G17: =G16/G18 -> 12.441183 | H17: =H16/H18 -> 18.750392 | I17: =I16/I18 -> 22.627829 | J17: =J16/J18 -> 23.052549 | K17: =K16/K18 -> 22.428364 | ... T17: =T16/T18 -> 21.744673
C18: Shares | D18: 2378.7 | E18: 2340 | F18: 2303.1 | G18: 4463 | H18: 4463 | I18: 4463 | J18: 4443.5 | K18: 4443.5 | L18: 4466 | M18: 4467 | N18: 4468 | O18: 4469 | P18: 4470 | Q18: 4471 | R18: 4472 | S18: 4473 | T18: 4474
C20: Revenue y/y | E20: =(E4-D4)/D4 -> 0.040361905 | F20: =(F4-E4)/E4 -> 0.10913302 | G20: =(G4-F4)/F4 -> 0.25677557 | H20: =(H4-G4)/G4 -> 0.31255015 | I20: =(I4-H4)/H4 -> 0.25033045 | J20: =(J4-I4)/I4 -> 0.064258978 | K20: =(K4-J4)/J4 -> -0.06 | L20: =(L4-K4)/K4 -> 0 | ... T20: =(T4-S4)/S4 -> 0
C21: Revenue LC | D21: 0.056 | E21: 0.067 | F21: 0.138 | G21: 0.164 | H21: 0.356 | I21: 0.25 | J21: 0.1 | K21: -0.06 | V21: Discount | W21: 0.08
C22: Ozempic y/y | V22: TV | W22: -0.01
C23: GLP y/y | V23: NPV | W23: =NPV(W21,J16:DT16) -> 1160233.7
C24: Insulin y/y | V24: S/O | W24: 4455.5
C25: Gross margin | D25: =D6/D4 -> 0.8353726 | E25: =E6/E4 -> 0.83511099 | F25: =F6/F4 -> 0.83197443 | G25: =G6/G4 -> 0.83923506 | H25: =H6/H4 -> 0.84601375 | I25: =I6/I4 -> 0.84668891 | J25: =J6/J4 -> 0.80978697 | K25: =K6/K4 -> 0.79 | ... T25: =T6/T4 -> 0.79 | V25: NPV/Share | W25: =W23/W24 -> 260.40482
A26: Nedside | C26: EBIT margin | D26: =D11/D4 -> 0.43011449 | E26: =E11/E4 -> 0.42637027 | F26: =F11/F4 -> 0.41650568 | G26: =G11/G4 -> 0.42275959 | H26: =H11/H4 -> 0.44163247 | I26: =I11/I4 -> 0.44193414 | J26: =J11/J4 -> 0.41304714 | K26: =K11/K4 -> 0.41858399 | ... T26: =T11/T4 -> 0.41858399 | V26: Opp/nedside | W26: =(W25-Modell!$B$4)/Modell!$B$4 -> 0.055552561
A27: 5% vekst og konstante marginer
A28: =W50 -> 357.58316 | D28: FY 2019 | E28: FY 2020 | F28: FY 2021 | G28: FY 2022 | H28: FY 2023 | I28: FY 2024 | J28: FY 2025 | K28: FY 2026 | L28: FY 2027 | M28: FY 2028 | N28: FY 2029 | O28: FY 2030 | P28: FY 2031 | Q28: FY 2032 | R28: FY 2033 | S28: FY 2034 | T28: FY 2035
A29: =W51 -> 0.44946559 | C29: Revenue | D29: 122021 | E29: 126946 | F29: 140800 | G29: 176954 | H29: 232261 | I29: 290403 | J29: 309064 | K29: =J29*0.94 -> 290520.16 | L29: =K29*1.05 -> 305046.17 | M29: =L29*1.05 -> 320298.48 | N29: =M29*1.05 -> 336313.4 | O29: =N29*1.05 -> 353129.07 | P29: =O29*1.05 -> 370785.52 | Q29: =P29*1.05 -> 389324.8 | R29: =Q29*1.05 -> 408791.04 | S29: =R29*1.05 -> 429230.59 | T29: =S29*1.05 -> 450692.12
C30: COGS | D30: -20088 | E30: -20932 | F30: -23658 | G30: -28448 | H30: -35765 | I30: -44522 | J30: -58788 | K30: =K31-K29 -> -61009.234 | L30: =L31-L29 -> -61009.234 | M30: =M31-M29 -> -64059.695 | N30: =N31-N29 -> -67262.68 | O30: =O31-O29 -> -70625.814 | P30: =P31-P29 -> -74157.105 | Q30: =Q31-Q29 -> -77864.96 | R30: =R31-R29 -> -81758.208 | ... T30: =T31-T29 -> -90138.424
C31: Gross profit | D31: =SUM(D29:D30) -> 101933 | E31: =SUM(E29:E30) -> 106014 | F31: =SUM(F29:F30) -> 117142 | G31: =SUM(G29:G30) -> 148506 | H31: =SUM(H29:H30) -> 196496 | I31: =SUM(I29:I30) -> 245881 | J31: =SUM(J29:J30) -> 250276 | K31: =K29*0.79 -> 229510.93 | L31: =L29*0.8 -> 244036.93 | M31: =M29*0.8 -> 256238.78 | N31: =N29*0.8 -> 269050.72 | O31: =O29*0.8 -> 282503.26 | P31: =P29*0.8 -> 296628.42 | Q31: =Q29*0.8 -> 311459.84 | R31: =R29*0.8 -> 327032.83 | S31: =S29*0.8 -> 343384.47 | T31: =T29*0.8 -> 360553.7
C32: Sales and distribution costs | D32: -31823 | E32: -32928 | F32: -37008 | G32: -46217 | H32: -56743 | I32: -62101 | J32: -64310 | K32: =J32*0.87 -> -55949.7 | L32: =K32*1.05 -> -58747.185 | M32: =L32*1.05 -> -61684.544 | N32: =M32*1.05 -> -64768.771 | O32: =N32*1.05 -> -68007.21 | P32: =O32*1.05 -> -71407.571 | Q32: =P32*1.05 -> -74977.949 | R32: =Q32*1.05 -> -78726.847 | S32: =R32*1.05 -> -82663.189 | T32: =S32*1.05 -> -86796.348
C33: R&D | D33: -14220 | E33: -15462 | F33: -17772 | G33: -24047 | H33: -32443 | I33: -48062 | J33: -52039 | K33: =J33*0.87 -> -45273.93 | L33: =K33*1.05 -> -47537.627 | M33: =L33*1.05 -> -49914.508 | N33: =M33*1.05 -> -52410.233 | O33: =N33*1.05 -> -55030.745 | P33: =O33*1.05 -> -57782.282 | Q33: =P33*1.05 -> -60671.396 | R33: =Q33*1.05 -> -63704.966 | S33: =R33*1.05 -> -66890.214 | T33: =S33*1.05 -> -70234.725
C34: Admin cost | D34: -4007 | E34: -3958 | F34: -4050 | G34: -4467 | H34: -4855 | I34: -5276 | J34: -5969 | K34: =J34*0.87 -> -5193.03 | L34: =K34*1.05 -> -5452.6815 | M34: =L34*1.05 -> -5725.3156 | N34: =M34*1.05 -> -6011.5814 | O34: =N34*1.05 -> -6312.1604 | P34: =O34*1.05 -> -6627.7684 | Q34: =P34*1.05 -> -6959.1569 | R34: =Q34*1.05 -> -7307.1147 | S34: =R34*1.05 -> -7672.4704 | T34: =S34*1.05 -> -8056.094
C35: Other operating income/expense | D35: 600 | E35: 460 | F35: 332 | G35: 1034 | H35: 119 | I35: -2103 | J35: -300 | K35: =J35*0.87 -> -261 | L35: =K35*1.05 -> -274.05 | M35: =L35*1.05 -> -287.7525 | N35: =M35*1.05 -> -302.14013 | O35: =N35*1.05 -> -317.24713 | P35: =O35*1.05 -> -333.10949 | Q35: =P35*1.05 -> -349.76496 | R35: =Q35*1.05 -> -367.25321 | S35: =R35*1.05 -> -385.61587 | T35: =S35*1.05 -> -404.89666
C36: Operating profit EBIT | D36: =SUM(D31:D35) -> 52483 | E36: =SUM(E31:E35) -> 54126 | F36: =SUM(F31:F35) -> 58644 | G36: =SUM(G31:G35) -> 74809 | H36: =SUM(H31:H35) -> 102574 | I36: =SUM(I31:I35) -> 128339 | J36: =SUM(J31:J35) -> 127658 | K36: =SUM(K31:K35) -> 122833.27 | ... T36: =SUM(T31:T35) -> 195061.63
C37: Financial income | D37: 65 | E37: 1628 | F37: 2887 | G37: 239 | H37: 2945 | I37: 6198 | J37: 9660 | K37: =J37*1.03 -> 9949.8 | L37: 0 | M37: 0 | N37: 0 | O37: 0 | P37: 0 | Q37: 0 | R37: 0 | S37: 0 | T37: 0
C38: Financial expense | D38: -3995 | E38: -2624 | F38: -2451 | G38: -5986 | H38: -845 | I38: -7346 | J38: -6778 | K38: =J38*1.03 -> -6981.34 | L38: 0 | M38: 0 | N38: 0 | O38: 0 | P38: 0 | Q38: 0 | R38: 0 | S38: 0 | T38: 0
C39: PTP | D39: =SUM(D36:D38) -> 48553 | E39: =SUM(E36:E38) -> 53130 | F39: =SUM(F36:F38) -> 59080 | G39: =SUM(G36:G38) -> 69062 | H39: =SUM(H36:H38) -> 104674 | I39: =SUM(I36:I38) -> 127191 | J39: =SUM(J36:J38) -> 130540 | K39: =SUM(K36:K38) -> 125801.73 | ... T39: =SUM(T36:T38) -> 195061.63
C40: Tax | D40: -9602 | E40: -10992 | F40: -11323 | G40: -13537 | H40: -20991 | I40: -26203 | J40: -28106 | K40: =K39*-0.2 -> -25160.345 | L40: =L39*-0.2 -> -26405.078 | M40: =M39*-0.2 -> -27725.332 | N40: =N39*-0.2 -> -29111.599 | O40: =O39*-0.2 -> -30567.179 | P40: =P39*-0.2 -> -32095.538 | Q40: =Q39*-0.2 -> -33700.315 | R40: =R39*-0.2 -> -35385.33 | ... T40: =T39*-0.2 -> -39012.327
C41: Net income | D41: =SUM(D39:D40) -> 38951 | E41: =SUM(E39:E40) -> 42138 | F41: =SUM(F39:F40) -> 47757 | G41: =SUM(G39:G40) -> 55525 | H41: =SUM(H39:H40) -> 83683 | I41: =SUM(I39:I40) -> 100988 | J41: =SUM(J39:J40) -> 102434 | K41: =SUM(K39:K40) -> 100641.38 | ... T41: =SUM(T39:T40) -> 156049.31 | U41: =T41*(1+$W$22) -> 154488.81 | V41: =U41*(1+$W$22) -> 152943.93 | W41: =V41*(1+$W$22) -> 151414.49 | X41: =W41*(1+$W$22) -> 149900.34 | Y41: =X41*(1+$W$22) -> 148401.34 | Z41: =Y41*(1+$W$22) -> 146917.32 | AA41: =Z41*(1+$W$22) -> 145448.15 | AB41: =AA41*(1+$W$22) -> 143993.67 | ... DT41: =DS41*(1+$W$22) -> 54868.373
C42: EPS | D42: =D41/D43 -> 16.374911 | E42: =E41/E43 -> 18.007692 | F42: =F41/F43 -> 20.735965 | G42: =G41/G43 -> 12.441183 | H42: =H41/H43 -> 18.750392 | I42: =I41/I43 -> 22.627829 | J42: =J41/J43 -> 23.052549 | K42: =K41/K43 -> 22.649124 | ... T42: =T41/T43 -> 34.879148
C43: Shares | D43: 2378.7 | E43: 2340 | F43: 2303.1 | G43: 4463 | H43: 4463 | I43: 4463 | J43: 4443.5 | K43: 4443.5 | L43: 4466 | M43: 4467 | N43: 4468 | O43: 4469 | P43: 4470 | Q43: 4471 | R43: 4472 | S43: 4473 | T43: 4474
...

Sheet Ozempic
A1: Info
B3: Brand | C3: Ozempic, fka NN9535
B4: Generic | C4: semaglutide
B5: IP | C5: 7762994 needle delivery expires 2024
C6: 8114833 formulation expires 2025
C7: 8129343 acylated GLP-1 expires 2031
C8: 8536122 acylated GLP-1 expires 2026
C9: 8579869 needle mounting expired 2023
C10: 8684969 injection device expires 2025
C11: 8920383 injection device expires 2026
C12: 9108002 injection device expires 2026
C13: 9132239 injection device expires 2032
C14: 9457154 injection device expires 2027
C15: 9616180 injection device expires 2026
C16: 9687611 injection device expires 2027
C17: 10335462 MOU 2033

Sheet Wegovy
A1: Info
BB3: Brand | BC3: Wegovy, fka NN9535
BB4: Generic | BC4: semaglutide
BB5: Administration | BC5: subcutaneous once-weekly
BB6: Dosage | BC6: 0.25mg, 0.5mg, 1.0mg, 1.7mg, 2.4mg
BB7: Indication | BC7: Obesity, CVOT in overweight/obese with established CV disease
BB8: MOA | BC8: GLP-1 agonist
BB9: Approval | BC9: 6/24/2021 FDA
BC10: 3/2023 Japan
BC11: 6/2024: China
BC12: 15 countries in International as of Q324
BC13: 9/2024: EU label update receives positive CHMP opinion on STEP-HFpEF and STEP-HFpEF-DM
BB14: IP | BC14: Q124: ANDA filed
BB15: Manufacturing | BC15: Second CM in April 2023.
BB16: Clinical Trials
BC17: Phase III "SELECT" CVOT
BC18: 2.4mg subcut reduced MACE by 20%
BC19: Positive CHMP opinion
I21: 15.08.25: | R21: 45884 | AA21: 29.07.25: (dunka ned 23%) | AJ21: 08.07.25: | AS21: 21.06.25:
A22: 22.12.25: | J22: 12.12.25: | BC22: Phase III "STEP" 52-week trial n=616 HFpEF, obesity, T2D
BC23: Dosage: 2.4mg qw
BC24: November 2023 results: KCCQ 16.6 vs 8.7 for placebo
BC25: -13.3% weight loss vs. -2.6% for placebo
BC26: submitted results 1/24 in EU+US, will resubmit in US in 2025 with FLOW data
BC28: Phase III "STEP 9" n=407 obesity in knee OA - 68-weeks
BC29: Dosing: 2.4mg qw
BC30: met WOMAC and weight loss primary endpoints
J60: Gjennomsnittlig vekttap: 20,7% (72 uker)
J61: 1/3 deltakerer gikk ned > 25%

Sheet Rybelsus
A1: Info
B17: 29.03.25:

Sheet Cagrisema
A1: Info
Y2: Målet er å nå et vekttap på mer enn 25% for CagriSema
Y3: Redefine 1 er den viktigste phase 3 studien for den sjekker
Y4: fedme, ikke bare folk med diabetes
V12: Main result (68 uker) | X12: Placebo | AC12: Main result (68 uker) | AE12: Placebo
V13: Subcutaneous (injisert) | W13: -0.137 | X13: -0.034 | AC13: Subcutaneous (injisert) | AD13: -0.204 | AE13: -0.0009
A14: 23.02.26: | I14: 18.12.25:
I15: Forventer svar innen 2026 | O15: 22.06.25: | V15: 45726 | AC15: 20.12.24: Her falt Novo 20%
AC49: Adherent population | AE49: Placebo
V50: Adherent population | X50: Placebo | AC50: Subcutaneous (injisert) | AD50: -0.227 | AE50: -0.003
V51: Subcutaneous (injisert) | W51: -0.157 | X51: -0.031
AC52: Kraftig vekttap 25%>= | AE52: Placebo
V53: Kraftig vekttap 5%>= | X53: Placebo | AC53: populasjon | AD53: 0.404 | AE53: 0.01
V54: populasjon | W54: 0.897 | X54: 0.303
AC55: Enkelte komponeneter
AC56: Cagrilientide | AD56: -0.116
AC57: Semaglutid | AD57: -0.149
AC58: Cagrisema (kombi) | AD58: -0.204
V65: Halvparten i testgruppen opplevde svimmelhet og 25% opplevde oppkast

Sheet Amycretin
A1: Info
H2: Phase 3 will commence in 2026
B22: Weightloss (25.11.25)
D23: Placebo
B24: Subcutaneous (injisert) | C24: -0.145 | D24: -0.025
B25: Oral | C25: -0.101 | D25: -0.026
A28: 25.11.25: | H28: 21.06.25: | N28: 12.06.25: | U28: 24.01.25:
