Workbook

Sheet Info
M2: Guidance for 2025 (Q325):
A3: Produksjon i Thailand, tarfiff på 19% til USA
M4: Organic growth: | N4: 7-8%
A5: Gull og sølv-priser er viktig innsatsfaktor | M5: LFL: | N5: 3-4%
M6: EBIT margin: | N6: around 24%
M10: Hedging
M11: USD/OZ | P11: Q124 | Q11: Q224 | R11: Q324 | S11: Q424 | T11: Q125 | U11: Q225 | V11: Q325 | W11: Q425 | X11: Q126 | Y11: Q226 | Z11: Q326 | AA11: Q426
M12: Silver price | P12: 23.83 | Q12: 24.87 | R12: 24.89 | S12: 24.71 | T12: 24.78 | U12: 30.6 | V12: 32.3 | W12: 32 | X12: 30.3 | Y12: 29.8 | Z12: 0
A13: Update on CMD targets Q325 | M13: Gold price | P13: 2030 | Q13: 2023 | R13: 2093 | S13: 2155 | T13: 2225 | U13: 2739 | V13: 2932 | W13: 2988 | X13: 3238 | Y13: 3604 | Z13: 3935
A14: I 2023 kunngjorde Pandora at de skal ha EBIT-margin rundt 26-27% innen 26. | M14: Commodity hedge ratio % | P14: 70-100% | Q14: 70-100% | R14: 0.92 | S14: 0.59 | T14: 0.38 | U14: 70-90% | V14: 70-100% | W14: 70-100% | X14: 70-90% | Y14: 50-70% | Z14: 30-50%
A15: Siden CMD har det oppstått headwinds fra råvarer og FX på 380 basispoint.
A16: Samtidig er det også 120 bp fra tariffer | M16: 46003
A17: I Q125 nedjusterte de 26-27 til "Around 25%". Nedjusterte igjen i Q225 til "Around 24%" | M17: Gulpris: | N17: 4493 | O17: USD/oz
A18: Q325, Pandora nedjuster en gang til "around 23%" | M18: Sølvpris: | N18: 75.3 | O18: USD/oz
A35: De har også et kostnadsprogram som heter "Silverstone" hvor besparelser er forevntet å sees fra Q126
A37: Press release:
A38: 05.01.26: Pandora kjøper tilbake 47 240 aksjer
A39: 29.12.25: Pandora kjøper tilbake 36 000 aksjer
A40: 22.12.25: Pandora kjøper tilbake 90 000 aksjer
A41: 15.12.25: Berta De Pablos-Barbier tar over 1. januar istendfor i mars. Hun går fra CMO til CEO. Jennie Farmer blir ny CMO
A42: 15.12.25: pandora kjøper tilbake 92 000 aksjer
A43: 08.12.25: Pandora kjøper tilbake 95 000 aksjer
A44: 03.12.25: Avtroppende CEO Alexander Lacik har solgt 25 000 aksjer, holder 248 189 aksjer etter salget
A45: 01.12.25: pandora kjøper tilbake 93 000 aksjer
A46: 24.11.25: Pandora kjøper tilbake 123 000 aksjer
A47: 21.11.25 Pandora flagger 5% av aksjene
... A62: 06.05.25: Pamela Naderson and Tyla wear Pandora jewellery at the Met gala

Sheet Modell
A3: Kapitalstruktur | C3: DKKm | D3: Q122 | E3: Q222 | F3: Q322 | G3: Q422 | H3: Q123 | I3: Q223 | J3: Q323 | K3: Q423 | L3: Q124 | M3: Q224 | N3: Q324 | O3: Q424 | P3: Q125 | Q3: Q225 | R3: Q325 | S3: Q425 | T3: Q126 | U3: Q226 | V3: Q326 | W3: Q426 | Y3: FY 2015 | Z3: FY 2016 | AA3: FY 2017 | AB3: FY 2018 | AC3: FY 2019 | AD3: FY 2020 | AE3: FY 2021 | AF3: FY 2022 | AG3: FY 2023 | AH3: FY 2024 | AI3: FY 2025 | AJ3: FY 2026 | AK3: FY 2027 | AL3: FY 2028 | AM3: FY 2029 | AN3: FY 2030 | AO3: FY 2031 | AP3: FY 2032 | AQ3: FY 2033 | AR3: FY 2034 | AS3: FY 2035
A4: Price | B4: 480 | C4: Revenue | D4: 5689 | E4: 5655 | F4: 5263 | G4: 9856 | H4: 5850 | I4: 5894 | J4: 5572 | K4: 10820 | L4: 6834 | M4: 6771 | N4: 6103 | O4: 11973 | P4: 7347 | Q4: 7075 | R4: 6269 | S4: 11900 | T4: 7109 | Y4: 16737 | Z4: 20281 | AA4: 22781 | AB4: 22806 | AC4: 21868 | AD4: 19009 | AE4: 23394 | AF4: 26463 | AG4: 28136 | AH4: 31680 | AI4: 32591 | AJ4: =AI4*1.02 -> 33242.82 | AK4: =AJ4*1.035 -> 34406.319 | AL4: =AK4*1.05 -> 36126.635 | AM4: =AL4*1.05 -> 37932.966 | AN4: =AM4*1.05 -> 39829.615 | AO4: =AN4*1.05 -> 41821.095 | AP4: =AO4*1.05 -> 43912.15 | AQ4: =AP4*1.05 -> 46107.758 | AR4: =AQ4*1.05 -> 48413.146 | AS4: =AR4*1.05 -> 50833.803
A5: S/O | B5: 75 | C5: Cost of sales | D5: -1365 | E5: -1337 | F5: -1227 | G5: -2345 | H5: -1315 | I5: -1289 | J5: -1168 | K5: -2241 | L5: -1410 | M5: -1342 | N5: -1217 | O5: -2422 | P5: -1436 | Q5: -1468 | R5: -1300 | S5: -2700 | T5: -1458 | Y5: -4544 | Z5: -5058 | AA5: -5815 | AB5: -5864 | AC5: -5966 | AD5: -4634 | AE5: -5590 | AF5: -6273 | AG5: -6012 | AH5: -6391 | AI5: =AI4*-0.213 -> -6941.883 | AJ5: =AJ4*-0.215 -> -7147.2063 | AK5: =AK4*-0.215 -> -7397.3585 | AL5: =AL4*-0.215 -> -7767.2264 | AM5: =AM4*-0.215 -> -8155.5878 | AN5: =AN4*-0.215 -> -8563.3672 | AO5: =AO4*-0.215 -> -8991.5355 | AP5: =AP4*-0.215 -> -9441.1123 | AQ5: =AQ4*-0.215 -> -9913.1679 | ... AS5: =AS4*-0.215 -> -10929.268
A6: MC DKKm | B6: =B4*B5 -> 36000 | C6: Gross profit | D6: =SUM(D4:D5) -> 4324 | E6: =SUM(E4:E5) -> 4318 | F6: =SUM(F4:F5) -> 4036 | G6: =SUM(G4:G5) -> 7511 | H6: =SUM(H4:H5) -> 4535 | I6: =SUM(I4:I5) -> 4605 | J6: =SUM(J4:J5) -> 4404 | K6: =SUM(K4:K5) -> 8579 | ... T6: =SUM(T4:T5) -> 5651 | Y6: =SUM(Y4:Y5) -> 12193 | Z6: =SUM(Z4:Z5) -> 15223 | AA6: =SUM(AA4:AA5) -> 16966 | AB6: =SUM(AB4:AB5) -> 16942 | AC6: =SUM(AC4:AC5) -> 15902 | AD6: =SUM(AD4:AD5) -> 14375 | AE6: =SUM(AE4:AE5) -> 17804 | AF6: =SUM(AF4:AF5) -> 20190 | ... AS6: =SUM(AS4:AS5) -> 39904.535
A7: Cash DKKm | B7: =S40 -> 1305 | C7: Sales, distribution and marketing ex | D7: -2505 | E7: -2615 | F7: -2483 | G7: -3720 | H7: -2718 | I7: -2839 | J7: -2913 | K7: -4237 | L7: -3325 | M7: -3504 | N7: -3352 | O7: -4664 | P7: -3657 | Q7: -3680 | R7: -3494 | S7: -4500 | T7: -3621 | Y7: -4722 | Z7: -5838 | AA7: -7045 | AB7: -8222 | AC7: -9305 | AD7: -9155 | AE7: -9939 | AF7: -11322 | AG7: -12707 | AH7: -14844 | AI7: =AH7*1.035 -> -15363.54 | AJ7: =AI7*1.08 -> -16592.623 | AK7: =AJ7*1.02 -> -16924.476 | AL7: =AK7*1.045 -> -17686.077 | AM7: =AL7*1.045 -> -18481.951 | AN7: =AM7*1.045 -> -19313.638 | AO7: =AN7*1.045 -> -20182.752 | AP7: =AO7*1.045 -> -21090.976 | AQ7: =AP7*1.045 -> -22040.07 | AR7: =AQ7*1.045 -> -23031.873 | AS7: =AR7*1.045 -> -24068.307
A8: Debt DKKm | B8: =S49+S55 -> 15024 | C8: Adminstrative expenses | D8: -509 | E8: -454 | F8: -576 | G8: -586 | H8: -562 | I8: -578 | J8: -571 | K8: -668 | L8: -592 | M8: -588 | N8: -553 | O8: -738 | P8: -613 | Q8: -640 | R8: -596 | S8: -700 | T8: -543 | Y8: -1657 | Z8: -1981 | AA8: -2137 | AB8: -2289 | AC8: -2770 | AD8: -2536 | AE8: -2026 | AF8: -2125 | AG8: -2379 | AH8: -2471 | AI8: =AH8*1.03 -> -2545.13 | AJ8: =AI8*1.05 -> -2672.3865 | AK8: =AJ8*1.04 -> -2779.282 | AL8: =AK8*1.05 -> -2918.2461 | AM8: =AL8*1.05 -> -3064.1584 | AN8: =AM8*1.05 -> -3217.3663 | AO8: =AN8*1.05 -> -3378.2346 | AP8: =AO8*1.05 -> -3547.1463 | AQ8: =AP8*1.05 -> -3724.5036 | AR8: =AQ8*1.05 -> -3910.7288 | AS8: =AR8*1.05 -> -4106.2653
A9: EV DKKm | B9: =B6-B7+B8 -> 49719 | C9: Operating profit (EBIT) | D9: =SUM(D6:D8) -> 1310 | E9: =SUM(E6:E8) -> 1249 | F9: =SUM(F6:F8) -> 977 | G9: =SUM(G6:G8) -> 3205 | H9: =SUM(H6:H8) -> 1255 | I9: =SUM(I6:I8) -> 1188 | J9: =SUM(J6:J8) -> 920 | K9: =SUM(K6:K8) -> 3674 | ... T9: =SUM(T6:T8) -> 1487 | Y9: =SUM(Y6:Y8) -> 5814 | Z9: =SUM(Z6:Z8) -> 7404 | AA9: =SUM(AA6:AA8) -> 7784 | AB9: =SUM(AB6:AB8) -> 6431 | AC9: =SUM(AC6:AC8) -> 3827 | AD9: =SUM(AD6:AD8) -> 2684 | AE9: =SUM(AE6:AE8) -> 5839 | AF9: =SUM(AF6:AF8) -> 6743 | ... AS9: =SUM(AS6:AS8) -> 11729.963
C10: Finance income | D10: 88 | E10: 132 | F10: 91 | G10: 101 | H10: 92 | I10: 67 | J10: 49 | K10: 42 | L10: 47 | M10: 47 | N10: 111 | O10: 43 | P10: 38 | Q10: 77 | R10: 42 | S10: 121 | T10: 55 | Y10: 84 | Z10: 328 | AA10: 198 | AB10: 533 | AC10: 351 | AD10: 316 | AE10: 152 | AF10: 412 | AG10: 251 | AH10: 248 | AI10: 230 | AJ10: =AI10*1.02 -> 234.6 | AK10: =AJ10*1.02 -> 239.292 | AL10: =AK10*1.02 -> 244.07784 | AM10: =AL10*1.02 -> 248.9594 | AN10: =AM10*1.02 -> 253.93858 | AO10: =AN10*1.02 -> 259.01736 | AP10: =AO10*1.02 -> 264.1977 | AQ10: =AP10*1.02 -> 269.48166 | ... AS10: =AR10*1.02 -> 280.36872
C11: Finance expense | D11: -98 | E11: -160 | F11: -109 | G11: -255 | H11: -186 | I11: -239 | J11: -259 | K11: -372 | L11: -276 | M11: -327 | N11: -304 | O11: -390 | P11: -276 | Q11: -301 | R11: -274 | S11: -298 | T11: -279 | Y11: -553 | Z11: -82 | AA11: -315 | AB11: -382 | AC11: -351 | AD11: -507 | AE11: -613 | AF11: -622 | AG11: -1056 | AH11: -1297 | AI11: -1154 | AJ11: =AI11*1.02 -> -1177.08 | AK11: =AJ11*1.02 -> -1200.6216 | AL11: =AK11*1.02 -> -1224.634 | AM11: =AL11*1.02 -> -1249.1267 | AN11: =AM11*1.02 -> -1274.1092 | AO11: =AN11*1.02 -> -1299.5914 | AP11: =AO11*1.02 -> -1325.5833 | AQ11: =AP11*1.02 -> -1352.0949 | ... AS11: =AR11*1.02 -> -1406.7196
C12: PTP | D12: =SUM(D9:D11) -> 1300 | E12: =SUM(E9:E11) -> 1221 | F12: =SUM(F9:F11) -> 959 | G12: =SUM(G9:G11) -> 3051 | H12: =SUM(H9:H11) -> 1161 | I12: =SUM(I9:I11) -> 1016 | J12: =SUM(J9:J11) -> 710 | K12: =SUM(K9:K11) -> 3344 | ... T12: =SUM(T9:T11) -> 1263 | Y12: =SUM(Y9:Y11) -> 5345 | Z12: =SUM(Z9:Z11) -> 7650 | AA12: =SUM(AA9:AA11) -> 7667 | AB12: =SUM(AB9:AB11) -> 6582 | AC12: =SUM(AC9:AC11) -> 3827 | AD12: =SUM(AD9:AD11) -> 2493 | AE12: =SUM(AE9:AE11) -> 5378 | AF12: =SUM(AF9:AF11) -> 6533 | ... AS12: =SUM(AS9:AS11) -> 10603.612
C13: Tax | D13: -306 | E13: -287 | F13: -226 | G13: -686 | H13: -273 | I13: -239 | J13: -167 | K13: -815 | L13: -313 | M13: -260 | N13: -193 | O13: -933 | P13: -302 | Q13: -261 | R13: -159 | S13: -900 | T13: -321 | Y13: -1671 | Z13: -1625 | AA13: -1899 | AB13: -1537 | AC13: -884 | AD13: -556 | AE13: -1218 | AF13: -1504 | AG13: -1494 | AH13: -1699 | AI13: =AI12*-0.24 -> -1635.9473 | AJ13: =AJ12*-0.24 -> -1413.1498 | AK13: =AK12*-0.24 -> -1522.5295 | AL13: =AL12*-0.24 -> -1625.8869 | AM13: =AM12*-0.24 -> -1735.4646 | AN13: =AN12*-0.24 -> -1851.6173 | AO13: =AO12*-0.24 -> -1974.7198 | AP13: =AP12*-0.24 -> -2105.1672 | ... AS13: =AS12*-0.24 -> -2544.8669
C14: Net income | D14: =SUM(D12:D13) -> 994 | E14: =SUM(E12:E13) -> 934 | F14: =SUM(F12:F13) -> 733 | G14: =SUM(G12:G13) -> 2365 | H14: =SUM(H12:H13) -> 888 | I14: =SUM(I12:I13) -> 777 | J14: =SUM(J12:J13) -> 543 | K14: =SUM(K12:K13) -> 2529 | ... T14: =SUM(T12:T13) -> 942 | Y14: =SUM(Y12:Y13) -> 3674 | Z14: =SUM(Z12:Z13) -> 6025 | AA14: =SUM(AA12:AA13) -> 5768 | AB14: =SUM(AB12:AB13) -> 5045 | AC14: =SUM(AC12:AC13) -> 2943 | AD14: =SUM(AD12:AD13) -> 1937 | AE14: =SUM(AE12:AE13) -> 4160 | AF14: =SUM(AF12:AF13) -> 5029 | ... AS14: =SUM(AS12:AS13) -> 8058.7451 | AT14: =AS14*(1+$AV$18) -> 7978.1576 | AU14: =AT14*(1+$AV$18) -> 7898.376 | AV14: =AU14*(1+$AV$18) -> 7819.3923 | AW14: =AV14*(1+$AV$18) -> 7741.1984 | AX14: =AW14*(1+$AV$18) -> 7663.7864 | AY14: =AX14*(1+$AV$18) -> 7587.1485 | AZ14: =AY14*(1+$AV$18) -> 7511.277 | BA14: =AZ14*(1+$AV$18) -> 7436.1643 | ... IB14: =IA14*(1+$AV$18) -> 1181.9241
C15: Share | D15: 93 | E15: 93 | F15: 93 | G15: 93 | H15: 85 | I15: 85 | J15: 85 | K15: 85 | L15: 81 | M15: 81 | N15: 81 | O15: 81 | P15: 79 | Q15: 79 | R15: 79 | S15: 79 | T15: 75 | Y15: 119 | Z15: 114 | AA15: 111 | AB15: 107 | AC15: 97 | AD15: 97 | AE15: 99 | AF15: 93 | AG15: 85 | AH15: 81 | AI15: 79 | AJ15: 79 | AK15: 79 | AL15: 79 | AM15: 79 | AN15: 79 | AO15: 79 | AP15: 79 | AQ15: 79 | AR15: 79 | AS15: 79
C16: EPS | D16: =D14/D15 -> 10.688172 | E16: =E14/E15 -> 10.043011 | F16: =F14/F15 -> 7.8817204 | G16: =G14/G15 -> 25.430108 | H16: =H14/H15 -> 10.447059 | I16: =I14/I15 -> 9.1411765 | J16: =J14/J15 -> 6.3882353 | K16: =K14/K15 -> 29.752941 | ... T16: =T14/T15 -> 12.56 | Y16: =Y14/Y15 -> 30.87395 | Z16: =Z14/Z15 -> 52.850877 | AA16: =AA14/AA15 -> 51.963964 | AB16: =AB14/AB15 -> 47.149533 | AC16: =AC14/AC15 -> 30.340206 | AD16: =AD14/AD15 -> 19.969072 | AE16: =AE14/AE15 -> 42.020202 | AF16: =AF14/AF15 -> 54.075269 | ... AS16: =AS14/AS15 -> 102.00943
AU17: Discount | AV17: 0.08
C18: Revenue y/y | H18: =(H4-D4)/D4 -> 0.028300229 | I18: =(I4-E4)/E4 -> 0.042263484 | J18: =(J4-F4)/F4 -> 0.058711761 | K18: =(K4-G4)/G4 -> 0.097808442 | L18: =(L4-H4)/H4 -> 0.16820513 | M18: =(M4-I4)/I4 -> 0.14879539 | N18: =(N4-J4)/J4 -> 0.095297918 | O18: =(O4-K4)/K4 -> 0.10656192 | ... T18: =(T4-P4)/P4 -> -0.032394174 | Z18: =(Z4-Y4)/Y4 -> 0.21174643 | AA18: =(AA4-Z4)/Z4 -> 0.12326808 | AB18: =(AB4-AA4)/AA4 -> 0.0010974057 | AC18: =(AC4-AB4)/AB4 -> -0.041129527 | AD18: =(AD4-AC4)/AC4 -> -0.13073898 | AE18: =(AE4-AD4)/AD4 -> 0.2306802 | AF18: =(AF4-AE4)/AE4 -> 0.13118748 | AG18: =(AG4-AF4)/AF4 -> 0.063220345 | ... AS18: =(AS4-AR4)/AR4 -> 0.05 | AU18: TV | AV18: -0.01
C19: Organic growth | D19: 0.21 | E19: 0.03 | F19: 0.03 | G19: 0.04 | H19: 0.01 | I19: 0.05 | J19: 0.11 | K19: 0.12 | L19: 0.18 | M19: 0.15 | N19: 0.11 | O19: 0.11 | P19: 0.07 | Q19: 0.08 | R19: 0.06 | S19: 0.04 | T19: 0.02 | AA19: 0.11 | AB19: -0.02 | AC19: -0.08 | AD19: -0.11 | AE19: 0.23 | AF19: 0.07 | AG19: 0.08 | AH19: 0.13 | AI19: 0.06 | AU19: NPV | AV19: =NPV(AV17,AJ14:IB14) -> 80641.486
C20: Like-for-Like | D20: 0.17 | E20: 0.02 | F20: 0.01 | G20: -0.01 | H20: 0 | I20: 0.02 | J20: 0.09 | K20: 0.07 | L20: 0.11 | M20: 0.08 | N20: 0.07 | O20: 0.06 | P20: 0.06 | Q20: 0.03 | R20: 0.02 | S20: 0 | T20: 0 | Y20: 0.15 | Z20: 0.08 | AA20: 0 | AB20: -0.04 | AC20: -0.08 | AD20: -0.12 | AE20: 0.2 | AF20: 0.04 | AG20: 0.06 | AH20: 0.07 | AI20: 0.02 | AU20: S/O | AV20: 79
C21: Gross margin | D21: =D6/D4 -> 0.76006328 | E21: =E6/E4 -> 0.76357206 | F21: =F6/F4 -> 0.76686301 | G21: =G6/G4 -> 0.76207386 | H21: =H6/H4 -> 0.77521368 | I21: =I6/I4 -> 0.78130302 | J21: =J6/J4 -> 0.79038047 | K21: =K6/K4 -> 0.79288355 | ... T21: =T6/T4 -> 0.79490786 | Y21: =Y6/Y4 -> 0.72850571 | Z21: =Z6/Z4 -> 0.75060401 | AA21: =AA6/AA4 -> 0.74474343 | AB21: =AB6/AB4 -> 0.74287468 | AC21: =AC6/AC4 -> 0.72718127 | AD21: =AD6/AD4 -> 0.75622074 | AE21: =AE6/AE4 -> 0.76104984 | AF21: =AF6/AF4 -> 0.76295205 | ... AS21: =AS6/AS4 -> 0.785 | AU21: NPV/Share | AV21: =AV19/AV20 -> 1020.7783
C22: EBIT margin | D22: =D9/D4 -> 0.23026894 | E22: =E9/E4 -> 0.22086649 | F22: =F9/F4 -> 0.18563557 | G22: =G9/G4 -> 0.32518263 | H22: =H9/H4 -> 0.21452991 | I22: =I9/I4 -> 0.20156091 | J22: =J9/J4 -> 0.16511127 | K22: =K9/K4 -> 0.33955638 | ... T22: =T9/T4 -> 0.20917147 | Y22: =Y9/Y4 -> 0.34737408 | Z22: =Z9/Z4 -> 0.36507076 | AA22: =AA9/AA4 -> 0.34168825 | AB22: =AB9/AB4 -> 0.2819872 | AC22: =AC9/AC4 -> 0.17500457 | AD22: =AD9/AD4 -> 0.14119628 | AE22: =AE9/AE4 -> 0.24959391 | AF22: =AF9/AF4 -> 0.2548086 | ... AS22: =AS9/AS4 -> 0.23075123 | AU22: Opp/nedside | AV22: =(AV21-B4)/B4 -> 1.1266215
C23: ROIC | Y23: 0.72 | Z23: 0.8 | AA23: 0.68 | AB23: 0.53 | AC23: 0.27 | AD23: 0.2 | AE23: 0.52 | AF23: 0.49 | AG23: 0.45 | AH23: 0.46
C25: Balanse DKKm
C26: Goodwill | D26: 4660 | E26: 4743 | F26: 4995 | G26: 4822 | H26: 4798 | I26: 4882 | J26: 4977 | K26: 4914 | L26: 5017 | M26: 5070 | N26: 5003 | O26: 5126 | P26: 5124 | Q26: 5027 | R26: 5014 | S26: 5020 | T26: 5088
C27: Brand | D27: 1057 | E27: 1057 | F27: 1057 | G27: 1057 | H27: 1057 | I27: 1057 | J27: 1057 | K27: 1057 | L27: 1057 | M27: 1057 | N27: 1057 | O27: 1057 | P27: 1057 | Q27: 1057 | R27: 1057 | S27: 1057 | T27: 1057
C28: Distribution | D28: 1072 | E28: 1064 | F28: 1055 | G28: 1047 | H28: 1041 | I28: 1040 | J28: 1040 | K28: 1039 | L28: 1038 | M28: 1034 | N28: 1034 | O28: 1034 | P28: 1034 | Q28: 1034 | R28: 1034 | S28: 1034 | T28: 1034
C29: Other intangiable assets | D29: 559 | E29: 568 | F29: 605 | G29: 642 | H29: 679 | I29: 687 | J29: 678 | K29: 790 | L29: 872 | M29: 949 | N29: 969 | O29: 1015 | P29: 1046 | Q29: 1126 | R29: 1223 | S29: 1252 | T29: 1266
C30: PP&E | D30: 1823 | E30: 1937 | F30: 2076 | G30: 2226 | H30: 2247 | I30: 2382 | J30: 2550 | K30: 2746 | L30: 2818 | M30: 2955 | N30: 3169 | O30: 3475 | P30: 3506 | Q30: 3598 | R30: 3754 | S30: 3817 | T30: 3883
C31: Right-of-use assets | D31: 2610 | E31: 2704 | F31: 2825 | G31: 2978 | H31: 3109 | I31: 3367 | J31: 3541 | K31: 3779 | L31: 3966 | M31: 4454 | N31: 4698 | O31: 4997 | P31: 5009 | Q31: 5105 | R31: 5368 | S31: 5335 | T31: 5583
C32: Deferred tax assets | D32: 1030 | E32: 1174 | F32: 1426 | G32: 1261 | H32: 1273 | I32: 1299 | J32: 1317 | K32: 1260 | L32: 1347 | M32: 1417 | N32: 1632 | O32: 1530 | P32: 1787 | Q32: 1675 | R32: 1806 | S32: 1566 | T32: 1638
C33: Other financial assets | D33: 216 | E33: 221 | F33: 243 | G33: 249 | H33: 240 | I33: 214 | J33: 225 | K33: 215 | L33: 249 | M33: 267 | N33: 280 | O33: 298 | P33: 286 | Q33: 291 | R33: 301 | S33: 296 | T33: 300
C34: Inventories | D34: 3534 | E34: 4239 | F34: 5155 | G34: 4211 | H34: 4327 | I34: 4460 | J34: 4824 | K34: 4166 | L34: 4425 | M34: 4459 | N34: 4898 | O34: 4426 | P34: 4604 | Q34: 4735 | R34: 5369 | S34: 4883 | T34: 5283
C35: Trade receivables | D35: 790 | E35: 663 | F35: 880 | G35: 1262 | H35: 840 | I35: 791 | J35: 931 | K35: 1342 | L35: 1104 | M35: 854 | N35: 757 | O35: 1217 | P35: 719 | Q35: 661 | R35: 695 | S35: 1163 | T35: 813
C36: Contract assets | D36: 52 | E36: 52 | F36: 42 | G36: 54 | H36: 39 | I36: 39 | J36: 37 | K36: 55 | L36: 48 | M36: 53 | N36: 51 | O36: 91 | P36: 70 | Q36: 60 | R36: 65 | S36: 72 | T36: 60
C37: Derivative financial instruments | D37: 206 | E37: 124 | F37: 174 | G37: 231 | H37: 253 | I37: 117 | J37: 43 | K37: 87 | L37: 127 | M37: 283 | N37: 369 | O37: 162 | P37: 325 | Q37: 629 | R37: 922 | S37: 1709 | T37: 976
... C40: Cash | D40: 716 | E40: 1005 | F40: 260 | G40: 794 | H40: 541 | I40: 855 | J40: 848 | K40: 1397 | L40: 934 | M40: 897 | N40: 676 | O40: 2394 | P40: 744 | Q40: 817 | R40: 765 | S40: 1305 | T40: 826
C41: Total assets | D41: =SUM(D26:D40) -> 19417 | E41: =SUM(E26:E40) -> 20502 | F41: =SUM(F26:F40) -> 21774 | G41: =SUM(G26:G40) -> 22013 | H41: =SUM(H26:H40) -> 21520 | I41: =SUM(I26:I40) -> 22110 | J41: =SUM(J26:J40) -> 23125 | K41: =SUM(K26:K40) -> 23799 | ... T41: =SUM(T26:T40) -> 28953
C42: Share capital | D42: 100 | E42: 96 | F42: 96 | G42: 96 | H42: 96 | I42: 89 | J42: 89 | K42: 89 | L42: 89 | M42: 82 | N42: 82 | O42: 82 | P42: 82 | Q42: 79 | R42: 79 | S42: 79 | T42: 79
C43: Treasury shares | D43: -4458 | E43: -1690 | F43: -2485 | G43: -3320 | H43: -4489 | I43: -2337 | J43: -3647 | K43: -4353 | L43: -5184 | M43: -1092 | N43: -2189 | O43: -3228 | P43: -4123 | Q43: -1868 | R43: -3329 | S43: -4236 | T43: -4026
C44: Reserves | D44: 1043 | E44: 911 | F44: 1011 | G44: 918 | H44: 914 | I44: 650 | J44: 657 | K44: 610 | L44: 678 | M44: 818 | N44: 750 | O44: 858 | P44: 703 | Q44: 492 | R44: 792 | S44: 1263 | T44: 731
C45: Proposed dividends | D45: 0 | E45: 0 | F45: 0 | G45: 1430 | H45: 0 | I45: 0 | J45: 0 | K45: 1480 | L45: 0 | M45: 0 | N45: 0 | O45: 1576 | P45: 0 | Q45: 0 | R45: 0 | S45: 1641 | T45: 0
...

Sheet Segementer
B4: DKK million | C4: Q122 | D4: Q222 | E4: Q322 | F4: Q422 | G4: 2022 | H4: Q123 | I4: Q223 | J4: Q323 | K4: Q423 | L4: 2023 | M4: Q124 | N4: Q224 | O4: Q324 | P4: Q424 | Q4: 2024 | R4: Q125 | S4: Q225 | T4: Q325 | U4: Q425 | V4: 2025
B5: CORE
B6: Moments
B7: Revenue | C7: 3863 | D7: 3916 | E7: 3479 | F7: 6045 | G7: =SUM(C7:F7) -> 17303 | H7: 3859 | I7: 4025 | J7: 3604 | K7: 6880 | L7: =SUM(H7:K7) -> 18368 | M7: 4231 | N7: 4346 | O7: 3895 | P7: 7462 | Q7: =SUM(M7:P7) -> 19934 | R7: 4376 | S7: 4413 | T7: 3861 | V7: =SUM(R7:U7) -> 12650
B8: Like-for-like | D8: 0.01 | E8: -0.01 | F8: 0 | G8: 0.03 | H8: -0.03 | I8: 0 | J8: 0.07 | K8: 0.04 | L8: 0.02 | M8: 0.05 | N8: 0.03 | O8: 0.02 | P8: 0.03 | Q8: 0.03 | R8: 0 | S8: -0.01 | T8: -0.02
B9: Collabs
B10: Revenue | C10: 595 | D10: 543 | E10: 492 | F10: 983 | G10: =SUM(C10:F10) -> 2613 | H10: 610 | I10: 545 | J10: 561 | K10: 965 | L10: =SUM(H10:K10) -> 2681 | M10: 560 | N10: 526 | O10: 514 | P10: 964 | Q10: =SUM(M10:P10) -> 2564 | R10: 672 | S10: 643 | T10: 614 | V10: =SUM(R10:U10) -> 1929
B11: Like-for-like | D11: 0.34 | E11: 0.24 | F11: 0.02 | G11: 0.2 | H11: -0.04 | I11: 0.01 | J11: 0.1 | K11: 0.01 | L11: 0.01 | M11: -0.14 | N11: -0.14 | O11: -0.06 | P11: -0.05 | Q11: -0.09 | R11: 0.19 | S11: 0.19 | T11: 0.11
B12: ME
B13: Revenue | C13: 142 | D13: 159 | E13: 199 | F13: 314 | G13: =SUM(C13:F13) -> 814 | H13: 169 | I13: 194 | J13: 202 | K13: 335 | L13: =SUM(H13:K13) -> 900 | M13: 224 | N13: 236 | O13: 226 | P13: 358 | Q13: =SUM(M13:P13) -> 1044 | R13: 249 | S13: 258 | T13: 313 | V13: =SUM(R13:U13) -> 820
B14: Like-for-like | D14: 0.72 | E14: 1.25 | F14: -0.04 | G14: 0.4 | H14: 0.21 | I14: 0.17 | J14: 0.12 | K14: 0.06 | L14: 0.12 | M14: 0.26 | N14: 0.14 | O14: 0.21 | P14: 0.02 | Q14: 0.13 | R14: 0.06 | S14: 0.06 | T14: 0.34
B15: Total CORE
B16: Revenue | C16: =C7+C10+C13 -> 4600 | D16: =D7+D10+D13 -> 4618 | E16: =E7+E10+E13 -> 4170 | F16: =F7+F10+F13 -> 7342 | G16: =SUM(C16:F16) -> 20730 | H16: =H7+H10+H13 -> 4638 | I16: =I7+I10+I13 -> 4764 | J16: =J7+J10+J13 -> 4367 | K16: =K7+K10+K13 -> 8180 | L16: =SUM(H16:K16) -> 21949 | M16: =M7+M10+M13 -> 5015 | N16: =N7+N10+N13 -> 5108 | O16: =O7+O10+O13 -> 4635 | P16: =P7+P10+P13 -> 8784 | Q16: =SUM(M16:P16) -> 23542 | R16: =R7+R10+R13 -> 5297 | S16: =S7+S10+S13 -> 5314 | T16: =T7+T10+T13 -> 4788 | U16: =U7+U10+U13 -> 0 | V16: =SUM(R16:U16) -> 15399
B17: Like-for-like | D17: 0.04 | E17: 0.02 | F17: 0 | G17: 0.05 | H17: -0.03 | I17: 0 | J17: 0.07 | K17: 0.04 | L17: 0.02 | M17: 0.03 | N17: 0.01 | O17: 0.02 | P17: 0.02 | Q17: 0.02 | R17: 0.02 | S17: 0.01 | T17: 0.02 | U17: 0
B19: Fuel with more
B20: Timeless
B21: Revenue | C21: 829 | D21: 788 | E21: 664 | F21: 1773 | G21: =SUM(C21:F21) -> 4054 | H21: 949 | I21: 880 | J21: 843 | K21: 2117 | L21: =SUM(H21:K21) -> 4789 | M21: 1523 | N21: 1225 | O21: 1065 | P21: 2527 | Q21: =SUM(M21:P21) -> 6340 | R21: 1636 | S21: 1299 | T21: 1114 | V21: =SUM(R21:U21) -> 4049
B22: Like-for-like | D22: -0.07 | E22: -0.02 | F22: -0.03 | G22: -0.02 | H22: 0.11 | I22: 0.07 | J22: 0.21 | K22: 0.31 | L22: 0.2 | M22: 0.43 | N22: 0.29 | O22: 0.18 | P22: 0.11 | Q22: 0.22 | R22: 0.07 | S22: 0.02 | T22: 0.04 | U22: 0
B23: Signature
B24: Revenue | C24: 251 | D24: 240 | E24: 316 | F24: 660 | G24: =SUM(C24:F24) -> 1467 | H24: 229 | I24: 218 | J24: 275 | K24: 407 | L24: =SUM(H24:K24) -> 1129 | M24: 232 | N24: 205 | O24: 170 | P24: 304 | Q24: =SUM(M24:P24) -> 911 | R24: 172 | S24: 147 | T24: 114 | V24: =SUM(R24:U24) -> 433
B25: Like-for-like | D25: -0.13 | E25: -0.2 | F25: -0.14 | G25: -0.12 | H25: -0.12 | I25: -0.06 | J25: -0.12 | K25: -0.11 | L25: -0.11 | M25: -0.08 | N25: -0.13 | O25: -0.32 | P25: -0.27 | Q25: -0.21 | R25: -0.24 | S25: -0.27 | T25: -0.31
B26: PANDORA ESSENCE
B27: Revenue | C27: 0 | D27: 0 | E27: 0 | F27: 0 | G27: 0 | H27: 0 | I27: 0 | J27: 0 | K27: 2 | L27: =SUM(H27:K27) -> 2 | M27: 1 | N27: 172 | O27: 169 | P27: 232 | Q27: =SUM(M27:P27) -> 574 | R27: 151 | S27: 230 | T27: 178 | V27: =SUM(R27:U27) -> 559
B28: Like-for-like | C28: 0 | D28: 0 | E28: 0 | F28: 0 | G28: 0 | H28: 0 | I28: 0 | J28: 0 | K28: 0 | L28: 0 | M28: 0 | N28: 0 | O28: 0 | P28: 0 | Q28: 0 | R28: 0 | S28: 1.02 | T28: 0.13 | U28: 0.15
B29: Pandora Lab-grown diamonds
B30: Revenue | C30: 9 | D30: 10 | E30: 113 | F30: 81 | G30: =SUM(C30:F30) -> 213 | H30: 34 | I30: 32 | J30: 86 | K30: 113 | L30: =SUM(H30:K30) -> 265 | M30: 63 | N30: 61 | O30: 64 | P30: 127 | Q30: =SUM(M30:P30) -> 315 | R30: 90 | S30: 85 | T30: 75 | V30: =SUM(R30:U30) -> 250
B31: Like-for-like | D31: -0.22 | E31: 0.97 | F31: 1.96 | G31: 1.3 | H31: 2.47 | I31: 2.91 | J31: 0.84 | K31: 0.83 | L31: 1.16 | M31: 0.87 | N31: 0.88 | O31: 0.34 | P31: 0.18 | Q31: 0.43 | R31: 0.43 | S31: 0.36 | T31: 0.19
B32: Total Fuel with more
B33: Revenue | C33: =C21+C24+C27+C30 -> 1089 | D33: =D21+D24+D27+D30 -> 1038 | E33: =E21+E24+E27+E30 -> 1093 | F33: =F21+F24+F27+F30 -> 2514 | G33: =SUM(C33:F33) -> 5734 | H33: =H21+H24+H27+H30 -> 1212 | I33: =I21+I24+I27+I30 -> 1130 | J33: =J21+J24+J27+J30 -> 1204 | K33: =K21+K24+K27+K30 -> 2639 | L33: =SUM(H33:K33) -> 6185 | M33: =M21+M24+M27+M30 -> 1819 | N33: =N21+N24+N27+N30 -> 1663 | O33: =O21+O24+O27+O30 -> 1468 | P33: =P21+P24+P27+P30 -> 3190 | Q33: =SUM(M33:P33) -> 8140 | R33: =R21+R24+R27+R30 -> 2049 | S33: =S21+S24+S27+S30 -> 1761 | T33: =T21+T24+T27+T30 -> 1481 | V33: =SUM(R33:U33) -> 5291
B34: Like-for-like | D34: -0.04 | E34: -0.02 | F34: -0.04 | G34: -0.01 | H34: 0.09 | I34: 0.08 | J34: 0.14 | K34: 0.23 | L34: 0.14 | M34: 0.34 | N34: 0.29 | O34: 0.21 | P34: 0.13 | Q34: 0.22 | R34: 0.12 | S34: 0.05 | T34: 0.02 | U34: -0.03

Sheet Land
A4: DKK million | B4: Q122 | C4: Q222 | D4: Q322 | E4: Q422 | F4: 2022 | G4: Q123 | H4: Q223 | I4: Q323 | J4: Q423 | K4: 2023 | L4: Q124 | M4: Q224 | N4: Q324 | O4: Q424 | P4: 2024 | Q4: Q125 | R4: Q225 | S4: Q325 | T4: Q425 | U4: 2025 | V4: Q126 | W4: Q226 | X4: Q326 | Y4: Q426 | Z4: 2026
A5: Key market
A6: US
A7: Revenue | B7: 1650 | C7: 1841 | D7: 1597 | E7: 2820 | F7: =SUM(B7:E7) -> 7908 | G7: 1716 | H7: 1834 | I7: 1566 | J7: 3190 | K7: =SUM(G7:J7) -> 8306 | L7: 2027 | M7: 2173 | N7: 1796 | O7: 3713 | P7: =SUM(L7:O7) -> 9709 | Q7: 2368 | R7: 2374 | S7: 1896 | T7: 3700 | U7: =SUM(Q7:T7) -> 10338 | Z7: =SUM(V7:Y7) -> 0
A8: Like-for-like | D8: -0.09 | E8: -0.07 | F8: -0.07 | G8: -0.07 | H8: -0.04 | I8: 0.05 | J8: 0.1 | K8: 0.02 | L8: 0.09 | M8: 0.05 | N8: 0.06 | O8: 0.09 | P8: 0.08 | Q8: 0.11 | R8: 0.08 | S8: 0.06 | T8: 0.02
A9: Organic growth | D9: -0.03 | E9: -0.03 | F9: -0.03 | G9: -0.04 | H9: 0 | I9: 0.04 | J9: 0.15 | K9: 0.05 | L9: 0.16 | M9: 0.14 | N9: 0.14 | O9: 0.13 | P9: 0.14 | Q9: 0.12 | R9: 0.12 | S9: 0.09 | T9: 0.09
A10: China
A11: Revenue | B11: 254 | C11: 179 | D11: 162 | E11: 143 | F11: =SUM(B11:E11) -> 738 | G11: 161 | H11: 156 | I11: 132 | J11: 116 | K11: =SUM(G11:J11) -> 565 | L11: 110 | M11: 118 | N11: 84 | O11: 104 | P11: =SUM(L11:O11) -> 416 | Q11: 96 | R11: 95 | S11: 68 | T11: 100 | U11: =SUM(Q11:T11) -> 359 | Z11: =SUM(V11:Y11) -> 0
A12: Like-for-like | D12: -0.46 | E12: -0.41 | F12: -0.47 | G12: -0.26 | H12: 0.05 | I12: 0 | J12: -0.11 | K12: -0.09 | L12: -0.17 | M12: -0.23 | N12: -0.33 | O12: -0.1 | P12: -0.21 | Q12: -0.11 | R12: -0.15 | S12: -0.06 | T12: -0.1
A13: Organic growth | D13: -0.37 | E13: -0.36 | F13: -0.39 | G13: -0.35 | H13: -0.06 | I13: -0.07 | J13: -0.13 | K13: -0.18 | L13: -0.27 | M13: -0.23 | N13: -0.36 | O13: -0.12 | P13: -0.25 | Q13: -0.15 | R13: -0.15 | S13: -0.14 | T13: -0.21
A14: UK
A15: Revenue | B15: 808 | C15: 665 | D15: 717 | E15: 1613 | F15: =SUM(B15:E15) -> 3803 | G15: 809 | H15: 656 | I15: 729 | J15: 1627 | K15: =SUM(G15:J15) -> 3821 | L15: 854 | M15: 694 | N15: 740 | O15: 1640 | P15: =SUM(L15:O15) -> 3928 | Q15: 864 | R15: 659 | S15: 685 | T15: 1500 | U15: =SUM(Q15:T15) -> 3708 | Z15: =SUM(V15:Y15) -> 0
A16: Like-for-like | D16: 0.05 | E16: 0.01 | F16: 0.1 | G16: 0.01 | H16: 0 | I16: -0.01 | J16: -0.02 | K16: -0.01 | L16: -0.01 | M16: 0.01 | N16: -0.02 | O16: -0.03 | P16: -0.02 | Q16: 0.02 | R16: -0.09 | S16: -0.08 | T16: -0.04
A17: Organic growth | D17: 0.13 | E17: 0.09 | F17: 0.15 | G17: 0.06 | H17: 0.01 | I17: 0.02 | J17: 0 | K17: 0.02 | L17: 0.02 | M17: 0.04 | N17: 0 | O17: -0.03 | P17: 0 | Q17: -0.01 | R17: -0.05 | S17: -0.05 | T17: -0.02
A18: Italy
A19: Revenue | B19: 586 | C19: 595 | D19: 486 | E19: 913 | F19: =SUM(B19:E19) -> 2580 | G19: 539 | H19: 584 | I19: 496 | J19: 921 | K19: =SUM(G19:J19) -> 2540 | L19: 565 | M19: 568 | N19: 466 | O19: 879 | P19: =SUM(L19:O19) -> 2478 | Q19: 508 | R19: 529 | S19: 448 | T19: 800 | U19: =SUM(Q19:T19) -> 2285 | Z19: =SUM(V19:Y19) -> 0
A20: Like-for-like | D20: -0.05 | E20: -0.09 | F20: 0.05 | G20: -0.05 | H20: -0.05 | I20: -0.01 | J20: -0.01 | K20: -0.03 | L20: -0.02 | M20: -0.06 | N20: -0.08 | O20: -0.1 | P20: -0.07 | Q20: -0.09 | R20: -0.08 | S20: -0.04 | T20: -0.12
A21: Organic growth | D21: -0.08 | E21: -0.05 | F21: 0.06 | G21: -0.08 | H21: -0.02 | I21: 0.02 | J21: 0.01 | K21: -0.02 | L21: 0.05 | M21: -0.03 | N21: -0.07 | O21: -0.05 | P21: -0.03 | Q21: -0.11 | R21: -0.07 | S21: -0.04 | T21: -0.1
A22: Australia
A23: Revenue | B23: 245 | C23: 246 | D23: 246 | E23: 535 | F23: =SUM(B23:E23) -> 1272 | G23: 220 | H23: 218 | I23: 221 | J23: 502 | K23: =SUM(G23:J23) -> 1161 | L23: 203 | M23: 211 | N23: 195 | O23: 486 | P23: =SUM(L23:O23) -> 1095 | Q23: 234 | R23: 229 | S23: 212 | T23: 500 | U23: =SUM(Q23:T23) -> 1175 | Z23: =SUM(V23:Y23) -> 0
A24: Like-for-like | D24: 0.4 | E24: 0.01 | F24: 0.06 | G24: -0.05 | H24: -0.05 | I24: -0.08 | J24: -0.06 | K24: -0.06 | L24: -0.03 | M24: -0.08 | N24: -0.02 | O24: -0.04 | P24: -0.04 | Q24: 0.02 | R24: 0.07 | S24: 0.04 | T24: -0.03
A25: Organic growth | D25: 0.33 | E25: 0.08 | F25: 0.09 | G25: -0.09 | H25: -0.03 | I25: 0.01 | J25: -0.09 | K25: -0.06 | L25: -0.03 | M25: -0.03 | N25: -0.13 | O25: 0.05 | P25: -0.02 | Q25: 0.17 | R25: 0.18 | S25: 0.18 | T25: 0.01
A26: France
A27: Revenue | B27: 262 | C27: 237 | D27: 217 | E27: 475 | F27: =SUM(B27:E27) -> 1191 | G27: 243 | H27: 231 | I27: 220 | J27: 502 | K27: =SUM(G27:J27) -> 1196 | L27: 274 | M27: 261 | N27: 227 | O27: 456 | P27: =SUM(L27:O27) -> 1218 | Q27: 255 | R27: 256 | S27: 215 | T27: 400 | U27: =SUM(Q27:T27) -> 1126 | Z27: =SUM(V27:Y27) -> 0
A28: Like-for-like | D28: -0.01 | E28: -0.09 | F28: 0.04 | G28: -0.05 | H28: -0.05 | I28: 0.05 | J28: 0.06 | K28: 0.01 | L28: 0.02 | M28: 0 | N28: -0.01 | O28: -0.14 | P28: -0.05 | Q28: -0.06 | R28: -0.07 | S28: -0.07 | T28: -0.04
A29: Organic growth | D29: -0.02 | E29: -0.05 | F29: 0.06 | G29: -0.07 | H29: -0.03 | I29: 0.01 | J29: 0.06 | K29: 0 | L29: 0.12 | M29: 0.13 | N29: 0.03 | O29: -0.09 | P29: 0.02 | Q29: -0.07 | R29: -0.02 | S29: -0.05 | T29: -0.05
A30: Germany
A31: Revenue | B31: 273 | C31: 285 | D31: 254 | E31: 494 | F31: =SUM(B31:E31) -> 1306 | G31: 269 | H31: 295 | I31: 301 | J31: 662 | K31: =SUM(G31:J31) -> 1527 | L31: 472 | M31: 464 | N31: 431 | O31: 839 | P31: =SUM(L31:O31) -> 2206 | Q31: 499 | R31: 472 | S31: 402 | T31: 800 | U31: =SUM(Q31:T31) -> 2173 | Z31: =SUM(V31:Y31) -> 0
A32: Like-for-like | D32: 0.03 | E32: -0.03 | F32: 0.18 | G32: 0.11 | H32: 0.11 | I32: 0.31 | J32: 0.39 | K32: 0.26 | L32: 0.67 | M32: 0.65 | N32: 0.42 | O32: 0.28 | P32: 0.45 | Q32: 0.01 | R32: -0.06 | S32: -0.09 | T32: -0.06
A33: Organic growth | D33: -0.09 | E33: -0.03 | F33: 0.1 | G33: -0.02 | H33: 0.03 | I33: 0.18 | J33: 0.34 | K33: 0.17 | L33: 0.75 | M33: 0.57 | N33: 0.43 | O33: 0.27 | P33: 0.44 | Q33: 0.06 | R33: 0.02 | S33: -0.07 | T33: -0.04
A34: Total key market
A35: Revenue | B35: =B7+B11+B15+B19+B23+B27+B31 -> 4078 | C35: =C7+C11+C15+C19+C23+C27+C31 -> 4048 | D35: =D7+D11+D15+D19+D23+D27+D31 -> 3679 | E35: =E7+E11+E15+E19+E23+E27+E31 -> 6993 | F35: =SUM(B35:E35) -> 18798 | G35: =G7+G11+G15+G19+G23+G27+G31 -> 3957 | H35: =H7+H11+H15+H19+H23+H27+H31 -> 3974 | I35: =I7+I11+I15+I19+I23+I27+I31 -> 3665 | J35: =J7+J11+J15+J19+J23+J27+J31 -> 7520 | K35: =SUM(G35:J35) -> 19116 | L35: =L7+L11+L15+L19+L23+L27+L31 -> 4505 | M35: =M7+M11+M15+M19+M23+M27+M31 -> 4489 | N35: =N7+N11+N15+N19+N23+N27+N31 -> 3939 | O35: =O7+O11+O15+O19+O23+O27+O31 -> 8117 | P35: =SUM(L35:O35) -> 21050 | Q35: =Q7+Q11+Q15+Q19+Q23+Q27+Q31 -> 4824 | R35: =R7+R11+R15+R19+R23+R27+R31 -> 4614 | S35: =S7+S11+S15+S19+S23+S27+S31 -> 3926 | T35: =T7+T11+T15+T19+T23+T27+T31 -> 7800 | U35: =SUM(Q35:T35) -> 21164 | V35: =V7+V11+V15+V19+V23+V27+V31 -> 0 | W35: =W7+W11+W15+W19+W23+W27+W31 -> 0 | X35: =X7+X11+X15+X19+X23+X27+X31 -> 0 | Y35: =Y7+Y11+Y15+Y19+Y23+Y27+Y31 -> 0 | Z35: =SUM(V35:Y35) -> 0
A36: Like-for-like | D36: -0.04 | E36: -0.05 | F36: -0.02 | G36: -0.05 | H36: -0.02 | I36: 0.03 | J36: 0.06 | K36: 0.01 | L36: 0.07 | M36: 0.05 | N36: 0.03 | O36: 0.03 | P36: 0.04 | Q36: 0.04 | R36: 0.01 | S36: 0 | T36: -0.02
A37: Organic growth | D37: -0.02 | E37: -0.01 | F37: 0.01 | G37: -0.05 | H37: -0.01 | I37: 0.04 | J37: 0.08 | K37: 0.02 | L37: 0.13 | M37: 0.11 | N37: 0.07 | O37: 0.06 | P37: 0.09 | Q37: 0.04 | R37: 0.05 | S37: 0.02 | T37: 0.02
A38: Rest of Pandora
A39: Revenue | B39: 1612 | C39: 1607 | D39: 1585 | E39: 2865 | F39: =SUM(B39:E39) -> 7669 | G39: 1892 | H39: 1922 | I39: 1906 | J39: 3341 | K39: =SUM(G39:J39) -> 9061 | L39: 2328 | M39: 2281 | N39: 2165 | O39: 3856 | P39: =SUM(L39:O39) -> 10630 | Q39: 2523 | R39: 2460 | S39: 2344 | T39: 4000 | U39: =SUM(Q39:T39) -> 11327 | Z39: =SUM(V39:Y39) -> 0
A40: Like-for-like | D40: 0.17 | E40: 0.14 | F40: 0.21 | G40: 0.12 | H40: 0.12 | I40: 0.22 | J40: 0.16 | K40: 0.16 | L40: 0.18 | M40: 0.13 | N40: 0.14 | O40: 0.11 | P40: 0.13 | Q40: 0.08 | R40: 0.06 | S40: 0.06 | T40: 0.04
A41: Organic growth | D41: 0.15 | E41: 0.18 | F41: 0.23 | G41: 0.15 | H41: 0.21 | I41: 0.27 | J41: 0.2 | K41: 0.21 | L41: 0.29 | M41: 0.24 | N41: 0.19 | O41: 0.21 | P41: 0.23 | Q41: 0.11 | R41: 0.13 | S41: 0.13 | T41: 0.08
A42: Total
A43: Revenue | B43: =B35+B39 -> 5690 | C43: =C35+C39 -> 5655 | D43: =D35+D39 -> 5264 | E43: =E35+E39 -> 9858 | F43: =SUM(B43:E43) -> 26467 | G43: =G35+G39 -> 5849 | H43: =H35+H39 -> 5896 | I43: =I35+I39 -> 5571 | J43: =J35+J39 -> 10861 | K43: =SUM(G43:J43) -> 28177 | L43: =L35+L39 -> 6833 | M43: =M35+M39 -> 6770 | N43: =N35+N39 -> 6104 | O43: =O35+O39 -> 11973 | P43: =SUM(L43:O43) -> 31680 | Q43: =Q35+Q39 -> 7347 | R43: =R35+R39 -> 7074 | S43: =S35+S39 -> 6270 | T43: =T35+T39 -> 11800 | U43: =SUM(Q43:T43) -> 32491 | V43: =V35+V39 -> 0 | W43: =W35+W39 -> 0 | X43: =X35+X39 -> 0 | Y43: =Y35+Y39 -> 0 | Z43: =SUM(V43:Y43) -> 0
...

Sheet Nøkkeltall
D4: 2026 | E4: 2027 | F4: 2028
C5: EV/EBIT | D5: =Modell!$B$9/Modell!AJ9 -> 7.2788585 | E5: =Modell!$B$9/Modell!AK9 -> 6.8059714 | F5: =Modell!$B$9/Modell!AL9 -> 6.4111482
C6: P/E | D6: =Modell!$B$4/Modell!AJ16 -> 8.4737918 | E6: =Modell!$B$4/Modell!AK16 -> 7.8650278 | F6: =Modell!$B$4/Modell!AL16 -> 7.365049

Sheet Nedsideberegning
A3: Nedside | D3: FY 2015 | E3: FY 2016 | F3: FY 2017 | G3: FY 2018 | H3: FY 2019 | I3: FY 2020 | J3: FY 2021 | K3: FY 2022 | L3: FY 2023 | M3: FY 2024 | N3: FY 2025 | O3: FY 2026 | P3: FY 2027 | Q3: FY 2028 | R3: FY 2029 | S3: FY 2030 | T3: FY 2031 | U3: FY 2032 | V3: FY 2033 | W3: FY 2034 | X3: FY 2035
A4: Nullvekst og nedgang i marginer | C4: Revenue | D4: 16737 | E4: 20281 | F4: 22781 | G4: 22806 | H4: 21868 | I4: 19009 | J4: 23394 | K4: 26463 | L4: 28136 | M4: 31680 | N4: =M4*1.06 -> 33580.8 | O4: =N4 -> 33580.8 | P4: =O4 -> 33580.8 | Q4: =P4 -> 33580.8 | R4: =Q4 -> 33580.8 | S4: =R4 -> 33580.8 | T4: =S4 -> 33580.8 | U4: =T4 -> 33580.8 | V4: =U4 -> 33580.8 | ... X4: =W4 -> 33580.8
A5: =AA21 -> 557.23601 | C5: Cost of sales | D5: -4544 | E5: -5058 | F5: -5815 | G5: -5864 | H5: -5966 | I5: -4634 | J5: -5590 | K5: -6273 | L5: -6012 | M5: -6391 | N5: =N4*-0.205 -> -6884.064 | O5: =O4*-0.28 -> -9402.624 | P5: =P4*-0.28 -> -9402.624 | Q5: =Q4*-0.28 -> -9402.624 | R5: =R4*-0.28 -> -9402.624 | S5: =S4*-0.28 -> -9402.624 | T5: =T4*-0.28 -> -9402.624 | U5: =U4*-0.28 -> -9402.624 | V5: =V4*-0.28 -> -9402.624 | ... X5: =X4*-0.28 -> -9402.624
A6: =AA22 -> 0.16090835 | C6: Gross profit | D6: =SUM(D4:D5) -> 12193 | E6: =SUM(E4:E5) -> 15223 | F6: =SUM(F4:F5) -> 16966 | G6: =SUM(G4:G5) -> 16942 | H6: =SUM(H4:H5) -> 15902 | I6: =SUM(I4:I5) -> 14375 | J6: =SUM(J4:J5) -> 17804 | K6: =SUM(K4:K5) -> 20190 | ... X6: =SUM(X4:X5) -> 24178.176
C7: Sales, distribution and marketing ex | D7: -4722 | E7: -5838 | F7: -7045 | G7: -8222 | H7: -9305 | I7: -9155 | J7: -9939 | K7: -11322 | L7: -12707 | M7: -14844 | N7: =M7*1.06 -> -15734.64 | O7: =N7*1.05 -> -16521.372 | P7: =O7 -> -16521.372 | Q7: =P7 -> -16521.372 | R7: =Q7 -> -16521.372 | S7: =R7 -> -16521.372 | T7: =S7 -> -16521.372 | U7: =T7 -> -16521.372 | V7: =U7 -> -16521.372 | W7: =V7 -> -16521.372 | X7: =W7 -> -16521.372
C8: Adminstrative expenses | D8: -1657 | E8: -1981 | F8: -2137 | G8: -2289 | H8: -2770 | I8: -2536 | J8: -2026 | K8: -2125 | L8: -2379 | M8: -2471 | N8: =M8*1.06 -> -2619.26 | O8: =N8*1.05 -> -2750.223 | P8: =O8 -> -2750.223 | Q8: =P8 -> -2750.223 | R8: =Q8 -> -2750.223 | S8: =R8 -> -2750.223 | T8: =S8 -> -2750.223 | U8: =T8 -> -2750.223 | V8: =U8 -> -2750.223 | W8: =V8 -> -2750.223 | X8: =W8 -> -2750.223
C9: Operating profit (EBIT) | D9: =SUM(D6:D8) -> 5814 | E9: =SUM(E6:E8) -> 7404 | F9: =SUM(F6:F8) -> 7784 | G9: =SUM(G6:G8) -> 6431 | H9: =SUM(H6:H8) -> 3827 | I9: =SUM(I6:I8) -> 2684 | J9: =SUM(J6:J8) -> 5839 | K9: =SUM(K6:K8) -> 6743 | ... X9: =SUM(X6:X8) -> 4906.581
C10: Finance income | D10: 84 | E10: 328 | F10: 198 | G10: 533 | H10: 351 | I10: 316 | J10: 152 | K10: 412 | L10: 251 | M10: 248 | N10: 230 | O10: 0 | P10: 0 | Q10: 0 | R10: 0 | S10: 0 | T10: 0 | U10: 0 | V10: 0 | W10: 0 | X10: 0
C11: Finance expense | D11: -553 | E11: -82 | F11: -315 | G11: -382 | H11: -351 | I11: -507 | J11: -613 | K11: -622 | L11: -1056 | M11: -1297 | N11: -1154 | O11: 0 | P11: 0 | Q11: 0 | R11: 0 | S11: 0 | T11: 0 | U11: 0 | V11: 0 | W11: 0 | X11: 0
C12: PTP | D12: =SUM(D9:D11) -> 5345 | E12: =SUM(E9:E11) -> 7650 | F12: =SUM(F9:F11) -> 7667 | G12: =SUM(G9:G11) -> 6582 | H12: =SUM(H9:H11) -> 3827 | I12: =SUM(I9:I11) -> 2493 | J12: =SUM(J9:J11) -> 5378 | K12: =SUM(K9:K11) -> 6533 | ... X12: =SUM(X9:X11) -> 4906.581
C13: Tax | D13: -1671 | E13: -1625 | F13: -1899 | G13: -1537 | H13: -884 | I13: -556 | J13: -1218 | K13: -1504 | L13: -1494 | M13: -1699 | N13: =N12*-0.24 -> -1780.5206 | O13: =O12*-0.24 -> -1177.5794 | P13: =P12*-0.24 -> -1177.5794 | Q13: =Q12*-0.24 -> -1177.5794 | R13: =R12*-0.24 -> -1177.5794 | S13: =S12*-0.24 -> -1177.5794 | T13: =T12*-0.24 -> -1177.5794 | U13: =U12*-0.24 -> -1177.5794 | ... X13: =X12*-0.24 -> -1177.5794
C14: Net income | D14: =SUM(D12:D13) -> 3674 | E14: =SUM(E12:E13) -> 6025 | F14: =SUM(F12:F13) -> 5768 | G14: =SUM(G12:G13) -> 5045 | H14: =SUM(H12:H13) -> 2943 | I14: =SUM(I12:I13) -> 1937 | J14: =SUM(J12:J13) -> 4160 | K14: =SUM(K12:K13) -> 5029 | ... X14: =SUM(X12:X13) -> 3729.0016 | Y14: =X14*(1+$AA$18) -> 3691.7115 | Z14: =Y14*(1+$AA$18) -> 3654.7944 | AA14: =Z14*(1+$AA$18) -> 3618.2465 | AB14: =AA14*(1+$AA$18) -> 3582.064 | AC14: =AB14*(1+$AA$18) -> 3546.2434 | AD14: =AC14*(1+$AA$18) -> 3510.7809 | AE14: =AD14*(1+$AA$18) -> 3475.6731 | AF14: =AE14*(1+$AA$18) -> 3440.9164 | ... HG14: =HF14*(1+$AA$18) -> 546.90858
C15: Share | D15: 119 | E15: 114 | F15: 111 | G15: 107 | H15: 97 | I15: 97 | J15: 99 | K15: 93 | L15: 85 | M15: 81 | N15: 79 | O15: 79 | P15: 79 | Q15: 79 | R15: 79 | S15: 79 | T15: 79 | U15: 79 | V15: 79 | W15: 79 | X15: 79
C16: EPS | D16: =D14/D15 -> 30.87395 | E16: =E14/E15 -> 52.850877 | F16: =F14/F15 -> 51.963964 | G16: =G14/G15 -> 47.149533 | H16: =H14/H15 -> 30.340206 | I16: =I14/I15 -> 19.969072 | J16: =J14/J15 -> 42.020202 | K16: =K14/K15 -> 54.075269 | ... X16: =X14/X15 -> 47.202551
Z17: Discount | AA17: 0.08
C18: Revenue y/y | E18: =(E4-D4)/D4 -> 0.21174643 | F18: =(F4-E4)/E4 -> 0.12326808 | G18: =(G4-F4)/F4 -> 0.0010974057 | H18: =(H4-G4)/G4 -> -0.041129527 | I18: =(I4-H4)/H4 -> -0.13073898 | J18: =(J4-I4)/I4 -> 0.2306802 | K18: =(K4-J4)/J4 -> 0.13118748 | L18: =(L4-K4)/K4 -> 0.063220345 | ... X18: =(X4-W4)/W4 -> 0 | Z18: TV | AA18: -0.01
C19: Like-for-Like | D19: 0.15 | E19: 0.08 | F19: 0 | G19: -0.04 | H19: -0.08 | I19: -0.12 | J19: 0.2 | K19: 0.04 | L19: 0.06 | M19: 0.07 | Z19: NPV | AA19: =NPV(AA17,O14:HG14) -> 44021.644
C20: Gross margin | D20: =D6/D4 -> 0.72850571 | E20: =E6/E4 -> 0.75060401 | F20: =F6/F4 -> 0.74474343 | G20: =G6/G4 -> 0.74287468 | H20: =H6/H4 -> 0.72718127 | I20: =I6/I4 -> 0.75622074 | J20: =J6/J4 -> 0.76104984 | K20: =K6/K4 -> 0.76295205 | ... X20: =X6/X4 -> 0.72 | Z20: S/O | AA20: 79
C21: EBIT margin | D21: =D9/D4 -> 0.34737408 | E21: =E9/E4 -> 0.36507076 | F21: =F9/F4 -> 0.34168825 | G21: =G9/G4 -> 0.2819872 | H21: =H9/H4 -> 0.17500457 | I21: =I9/I4 -> 0.14119628 | J21: =J9/J4 -> 0.24959391 | K21: =K9/K4 -> 0.2548086 | ... X21: =X9/X4 -> 0.14611269 | Z21: NPV/Share | AA21: =AA19/AA20 -> 557.23601
Z22: Opp/nedside | AA22: =(AA21-Modell!B4)/Modell!B4 -> 0.16090835
