Workbook

Sheet Info
A42: D2C = Direct to consumer
A43: Selger direkte til sine kunder uten fordyrende mellomledd som sportsbutikker
A45: 19 unike webshops som gir en lokal følelse, disse nettbutikkene er tilpasset ulike markeder
A46: 3PL = tredjepartslogistikk: RVRC leier inn profesjonelle logistikkselskaper til å drifte lagrene sine i stedet for å drifte de selv som gir fleksibilitet. RVRC har sitt i Stocholm
A48: Har produksjon i Asia
A49: ICIW har prudksjon i Asia, shippes til varehuset i Borås, Sverige som opereres av en 3 part veldig likt RVRC allerede har.
A51: Selger til:
A52: Nordics
A53: DACH: Deutchsland, Austria, Confoederatio Helvetica (Sveits)
A54: Rest of world
A57: Press releases:
A58: 26.08.26: ICIWL åpner første pioner butikk i Helsinki som er et viktig marked for selskapet
... A61: 08.07.26: RVRC gjør sitt første oppkjøp som er av ICANIWILL. Prisen er 700 SEKm i tillegg til earn-out påm 175 SEKm 100SEKm knyttet til 26 EBIT og 75 SEKm knyttet til 27 EBIT. EV/EBIT 9,5, 7,8 hvis earn outs blir oppnådd

Sheet Modell
D1: Jul-Sep | E1: Oct-Dec | F1: Jan-Mar | G1: Apr-Jun | H1: Jul-Sep | I1: Oct-Dec | J1: Jan-Mar | K1: Apr-Jun | L1: Jul-Sep | M1: Oct-Dec | N1: Jan-Mar | O1: Apr-Jun | P1: Jul-Sep | Q1: Oct-Dec | R1: Jan-Mar | S1: Apr-Jun | T1: Jul-Sep | U1: Oct-Dec | V1: Jan-Mar | W1: Apr-Jun
A3: Kapitalstruktur | C3: SEKm | D3: Q1 22/23 | E3: Q2 22/23 | F3: Q3 22/23 | G3: Q4 22/23 | H3: Q1 23/24 | I3: Q2 23/24 | J3: Q3 23/24 | K3: Q4 23/24 | L3: Q1 24/25 | M3: Q2 24/25 | N3: Q3 24/25 | O3: Q4 24/25 | P3: Q1 25/26 | Q3: Q2 25/26 | R3: Q3 25/26 | S3: Q4 25/26 | T3: Q1 26/27 | U3: Q2 26/27 | V3: Q3 26/27 | W3: Q4 26/27 | Y3: FY 19/20 | Z3: FY 20/21 | AA3: FY 21/22 | AB3: FY 22/23 | AC3: FY 23/24 | AD3: FY 24/25 | AE3: FY 25/26 | AF3: FY 26/27 | AG3: FY 27/28 | AH3: FY 28/29 | AI3: FY 29/30 | AJ3: FY 30/31 | AK3: FY 31/32 | AL3: FY 32/33 | AM3: FY 33/34 | AN3: FY 34/35
A4: Price | B4: 49 | C4: RVRC | P4: 392 | Q4: 726 | R4: 487 | S4: 414
A5: S/O | B5: 105.75545 | C5: ICIW | P5: 104 | Q5: 124 | R5: 118 | S5: 123
A6: MC SEKm | B6: =B4*B5 -> 5182.017 | C6: Revenue | D6: 287 | E6: 509 | F6: 414 | G6: 362 | H6: 342 | I6: 613 | J6: 484 | K6: 407 | L6: 350 | M6: 689 | N6: 486 | O6: 405 | P6: 392 | Q6: 726 | R6: 487 | S6: 414 | T6: =SUM(T4:T5) -> 0 | Y6: 387.507 | Z6: 912.735 | AA6: 1356 | AB6: 1562 | AC6: 1842 | AD6: 1925 | AE6: 2019 | AF6: =AE6*1.37 -> 2766.03 | AG6: =AF6*1.08 -> 2987.3124 | AH6: =AG6*1.08 -> 3226.2974 | AI6: =AH6*1.08 -> 3484.4012 | AJ6: =AI6*1.08 -> 3763.1533 | AK6: =AJ6*1.08 -> 4064.2055 | AL6: =AK6*1.08 -> 4389.342 | AM6: =AL6*1.08 -> 4740.4893 | AN6: =AM6*1.08 -> 5119.7285
A7: Cash SEKm | B7: =S54 -> 328 | C7: Goods for resale | D7: -79 | E7: -149 | F7: -113 | G7: -92 | H7: -95 | I7: -183 | J7: -136 | K7: -114 | L7: -105 | M7: -203 | N7: -149 | O7: -124 | P7: -119 | Q7: -219 | R7: -141 | S7: -115 | Y7: -115.72 | Z7: -248.804 | AA7: -369 | AB7: -434 | AC7: -528 | AD7: -581 | AE7: -594 | AF7: =AF6*-0.3 -> -829.809 | AG7: =AG6*-0.3 -> -896.19372 | AH7: =AH6*-0.3 -> -967.88922 | AI7: =AI6*-0.3 -> -1045.3204 | AJ7: =AJ6*-0.3 -> -1128.946 | AK7: =AK6*-0.3 -> -1219.2617 | AL7: =AL6*-0.3 -> -1316.8026 | AM7: =AM6*-0.3 -> -1422.1468 | AN7: =AN6*-0.3 -> -1535.9185
A8: Debt SEKm | B8: 0 | C8: Gross profit | D8: =SUM(D6:D7) -> 208 | E8: =SUM(E6:E7) -> 360 | F8: =SUM(F6:F7) -> 301 | G8: =SUM(G6:G7) -> 270 | H8: =SUM(H6:H7) -> 247 | I8: =SUM(I6:I7) -> 430 | J8: =SUM(J6:J7) -> 348 | K8: =SUM(K6:K7) -> 293 | ... S8: =SUM(S6:S7) -> 299 | Y8: =SUM(Y6:Y7) -> 271.787 | Z8: =SUM(Z6:Z7) -> 663.931 | AA8: =SUM(AA6:AA7) -> 987 | AB8: =SUM(AB6:AB7) -> 1128 | AC8: =SUM(AC6:AC7) -> 1314 | AD8: =SUM(AD6:AD7) -> 1344 | AE8: =SUM(AE6:AE7) -> 1425 | AF8: =SUM(AF6:AF7) -> 1936.221 | ... AN8: =SUM(AN6:AN7) -> 3583.8099
A9: EV SEKm | B9: =B6-B7+B8 -> 4854.017 | C9: Other external expenses | D9: -136 | E9: -207 | F9: -186 | G9: -174 | H9: -154 | I9: -252 | J9: -216 | K9: -185 | L9: -158 | M9: -290 | N9: -200 | O9: -183 | P9: -169 | Q9: -287 | R9: -204 | S9: -191 | Y9: -156.999 | Z9: -363.697 | AA9: -539 | AB9: -701 | AC9: -805 | AD9: -831 | AE9: -851 | AF9: =AE9*1.42 -> -1208.42 | AG9: =AF9*1.065 -> -1286.9673 | AH9: =AG9*1.065 -> -1370.6202 | AI9: =AH9*1.065 -> -1459.7105 | AJ9: =AI9*1.065 -> -1554.5917 | AK9: =AJ9*1.065 -> -1655.6401 | AL9: =AK9*1.065 -> -1763.2567 | AM9: =AL9*1.065 -> -1877.8684 | AN9: =AM9*1.065 -> -1999.9299
C10: Personnel expenses | D10: -21 | E10: -41 | F10: -22 | G10: -25 | H10: -24 | I10: -31 | J10: -28 | K10: -31 | L10: -25 | M10: -36 | N10: -51 | O10: -31 | P10: -27 | Q10: -38 | R10: -35 | S10: -38 | Y10: -29.635 | Z10: -48.595 | AA10: -77 | AB10: -110 | AC10: -114 | AD10: -143 | AE10: -138 | AF10: =AE10*1.42 -> -195.96 | AG10: =AF10*1.055 -> -206.7378 | AH10: =AG10*1.055 -> -218.10838 | AI10: =AH10*1.055 -> -230.10434 | AJ10: =AI10*1.055 -> -242.76008 | AK10: =AJ10*1.055 -> -256.11188 | AL10: =AK10*1.055 -> -270.19804 | AM10: =AL10*1.055 -> -285.05893 | AN10: =AM10*1.055 -> -300.73717
C11: D/A | D11: -1 | E11: -2 | F11: -2 | G11: -2 | H11: -2 | I11: -2 | J11: -2 | K11: -2 | L11: -2 | M11: -2 | N11: -2 | O11: -2 | P11: -3 | Q11: -3 | R11: -3 | S11: -3 | Y11: -1.982 | Z11: -3.871 | AA11: -5 | AB11: -7 | AC11: -9 | AD11: -9 | AE11: -12 | AF11: =AE11*1.42 -> -17.04 | AG11: =AF11*1.055 -> -17.9772 | AH11: =AG11*1.055 -> -18.965946 | AI11: =AH11*1.055 -> -20.009073 | AJ11: =AI11*1.055 -> -21.109572 | AK11: =AJ11*1.055 -> -22.270599 | AL11: =AK11*1.055 -> -23.495481 | AM11: =AL11*1.055 -> -24.787733 | AN11: =AM11*1.055 -> -26.151058
A12: Gearing | B12: =(B8-B7)/S32 -> -0.75576037 | C12: Other operating expenses | D12: 0 | E12: -5 | F12: -4 | G12: -1 | H12: 0 | I12: -2 | J12: 0 | K12: -1 | L12: -3 | M12: 0 | N12: -4 | O12: -2 | P12: 0 | Q12: -1 | R12: 0 | S12: -1 | T12: -21 | Y12: 0 | Z12: -17.3 | AA12: 0 | AB12: 0 | AC12: 0 | AD12: -4 | AE12: -2 | AF12: =AE12*1.42 -> -2.84 | AG12: =AF12*1.055 -> -2.9962 | AH12: =AG12*1.055 -> -3.160991 | AI12: =AH12*1.055 -> -3.3348455 | AJ12: =AI12*1.055 -> -3.518262 | AK12: =AJ12*1.055 -> -3.7117664 | AL12: =AK12*1.055 -> -3.9159136 | AM12: =AL12*1.055 -> -4.1312888 | AN12: =AM12*1.055 -> -4.3585097
C13: Operating profit (EBIT) | D13: =SUM(D8:D12) -> 50 | E13: =SUM(E8:E12) -> 105 | F13: =SUM(F8:F12) -> 87 | G13: =SUM(G8:G12) -> 68 | H13: =SUM(H8:H12) -> 67 | I13: =SUM(I8:I12) -> 143 | J13: =SUM(J8:J12) -> 102 | K13: =SUM(K8:K12) -> 74 | ... S13: =SUM(S8:S12) -> 66 | Y13: =SUM(Y8:Y12) -> 83.171 | Z13: =SUM(Z8:Z12) -> 230.468 | AA13: =SUM(AA8:AA12) -> 366 | AB13: =SUM(AB8:AB12) -> 310 | AC13: =SUM(AC8:AC12) -> 386 | AD13: =SUM(AD8:AD12) -> 357 | AE13: =SUM(AE8:AE12) -> 422 | AF13: =SUM(AF8:AF12) -> 511.961 | ... AN13: =SUM(AN8:AN12) -> 1252.6333
C14: Fincial income | D14: 0 | E14: 0 | F14: 0 | G14: 1 | H14: 1 | I14: 2 | J14: 2 | K14: 2 | L14: 2 | M14: 1 | N14: 0 | O14: 1 | P14: 0 | Q14: 1 | R14: 1 | S14: 1 | Y14: 0 | Z14: 0 | AA14: 0 | AB14: 1 | AC14: 8 | AD14: 4 | AE14: 3 | AF14: 0 | AG14: 0 | AH14: 0 | AI14: 0 | AJ14: 0 | AK14: 0 | AL14: 0 | AM14: 0 | AN14: 0
C15: Financial expense | D15: -1 | E15: -2 | F15: -2 | G15: -1 | H15: -1 | I15: -1 | J15: -1 | K15: -1 | L15: -1 | M15: -1 | N15: -1 | O15: -1 | P15: -1 | Q15: -1 | R15: -1 | S15: -1 | Y15: -7 | Z15: -12 | AA15: -3 | AB15: -5 | AC15: -4 | AD15: -4 | AE15: -4 | AF15: 0 | AG15: 0 | AH15: 0 | AI15: 0 | AJ15: 0 | AK15: 0 | AL15: 0 | AM15: 0 | AN15: 0
C16: PTP | D16: =SUM(D13:D15) -> 49 | E16: =SUM(E13:E15) -> 103 | F16: =SUM(F13:F15) -> 85 | G16: =SUM(G13:G15) -> 68 | H16: =SUM(H13:H15) -> 67 | I16: =SUM(I13:I15) -> 144 | J16: =SUM(J13:J15) -> 103 | K16: =SUM(K13:K15) -> 75 | ... S16: =SUM(S13:S15) -> 66 | Y16: =SUM(Y13:Y15) -> 76.171 | Z16: =SUM(Z13:Z15) -> 218.468 | AA16: =SUM(AA13:AA15) -> 363 | AB16: =SUM(AB13:AB15) -> 306 | AC16: =SUM(AC13:AC15) -> 390 | AD16: =SUM(AD13:AD15) -> 357 | AE16: =SUM(AE13:AE15) -> 421 | AF16: =SUM(AF13:AF15) -> 511.961 | ... AN16: =SUM(AN13:AN15) -> 1252.6333
C17: Tax | D17: -10 | E17: -21 | F17: -18 | G17: -14 | H17: -14 | I17: -30 | J17: -22 | K17: -15 | L17: -12 | M17: -33 | N17: -17 | O17: -12 | P17: -16 | Q17: -37 | R17: -22 | S17: -13 | Y17: -16.5 | Z17: -46.835 | AA17: -75 | AB17: -63 | AC17: -81 | AD17: -74 | AE17: -88 | AF17: =AF16*-0.2 -> -102.3922 | AG17: =AG16*-0.2 -> -115.28804 | AH17: =AH16*-0.2 -> -129.51054 | AI17: =AI16*-0.2 -> -145.18442 | AJ17: =AJ16*-0.2 -> -162.44554 | AK17: =AK16*-0.2 -> -181.4419 | AL17: =AL16*-0.2 -> -202.33464 | AM17: =AM16*-0.2 -> -225.29923 | AN17: =AN16*-0.2 -> -250.52667
C18: Net income | D18: =SUM(D16:D17) -> 39 | E18: =SUM(E16:E17) -> 82 | F18: =SUM(F16:F17) -> 67 | G18: =SUM(G16:G17) -> 54 | H18: =SUM(H16:H17) -> 53 | I18: =SUM(I16:I17) -> 114 | J18: =SUM(J16:J17) -> 81 | K18: =SUM(K16:K17) -> 60 | ... S18: =SUM(S16:S17) -> 53 | Y18: =SUM(Y16:Y17) -> 59.671 | Z18: =SUM(Z16:Z17) -> 171.633 | AA18: =SUM(AA16:AA17) -> 288 | AB18: =SUM(AB16:AB17) -> 243 | AC18: =SUM(AC16:AC17) -> 309 | AD18: =SUM(AD16:AD17) -> 283 | AE18: =SUM(AE16:AE17) -> 333 | AF18: =SUM(AF16:AF17) -> 409.5688 | ... AN18: =SUM(AN16:AN17) -> 1002.1067 | AO18: =AN18*(1+$AQ$22) -> 992.0856 | AP18: =AO18*(1+$AQ$22) -> 982.16475 | AQ18: =AP18*(1+$AQ$22) -> 972.3431 | AR18: =AQ18*(1+$AQ$22) -> 962.61967 | AS18: =AR18*(1+$AQ$22) -> 952.99347 | AT18: =AS18*(1+$AQ$22) -> 943.46354 | AU18: =AT18*(1+$AQ$22) -> 934.0289 | AV18: =AU18*(1+$AQ$22) -> 924.68861 | ... EK18: =EJ18*(1+$AQ$22) -> 363.13542
C19: Shares | D19: 111.06566 | E19: 111.06566 | F19: 111.06566 | G19: 111.06566 | H19: 111.06566 | I19: 111.06566 | J19: 111.06566 | K19: 111.06566 | L19: 111.06566 | M19: 111.06566 | N19: 105.75545 | O19: 105.75545 | P19: 105.75545 | Q19: 105.75545 | R19: 105.75545 | S19: 105.75545 | Y19: 107.767 | Z19: 107.767 | AA19: 112.91892 | AB19: 112.91892 | AC19: 112.91892 | AD19: 111.06566 | AE19: 105.75545 | AF19: 105.75545 | AG19: 105.75545 | AH19: 105.75545 | AI19: 105.75545 | AJ19: 105.75545 | AK19: 105.75545 | AL19: 105.75545 | AM19: 105.75545 | AN19: 105.75545
C20: EPS | D20: =D18/D19 -> 0.35114365 | E20: =E18/E19 -> 0.73830203 | F20: =F18/F19 -> 0.60324678 | G20: =G18/G19 -> 0.4861989 | H20: =H18/H19 -> 0.47719521 | I20: =I18/I19 -> 1.0264199 | J20: =J18/J19 -> 0.72929835 | K20: =K18/K19 -> 0.540221 | ... S20: =S18/S19 -> 0.50115621 | Y20: =Y18/Y19 -> 0.55370382 | Z20: =Z18/Z19 -> 1.5926304 | AA20: =AA18/AA19 -> 2.5505027 | AB20: =AB18/AB19 -> 2.1519866 | AC20: =AC18/AC19 -> 2.7364768 | AD20: =AD18/AD19 -> 2.5480424 | AE20: =AE18/AE19 -> 3.1487739 | AF20: =AF18/AF19 -> 3.8727914 | ... AN20: =AN18/AN19 -> 9.4756976
AP21: Disocunt | AQ21: 0.08
C22: Revenue y/y | H22: =(H6-D6)/D6 -> 0.19163763 | I22: =(I6-E6)/E6 -> 0.2043222 | J22: =(J6-F6)/F6 -> 0.16908213 | K22: =(K6-G6)/G6 -> 0.12430939 | L22: =(L6-H6)/H6 -> 0.023391813 | M22: =(M6-I6)/I6 -> 0.12398042 | N22: =(N6-J6)/J6 -> 0.0041322314 | O22: =(O6-K6)/K6 -> -0.0049140049 | ... S22: =(S6-O6)/O6 -> 0.022222222 | Z22: =(Z6-Y6)/Y6 -> 1.3554026 | AA22: =(AA6-Z6)/Z6 -> 0.48564479 | AB22: =(AB6-AA6)/AA6 -> 0.1519174 | AC22: =(AC6-AB6)/AB6 -> 0.17925736 | AD22: =(AD6-AC6)/AC6 -> 0.045059718 | AE22: =(AE6-AD6)/AD6 -> 0.048831169 | AF22: =(AF6-AE6)/AE6 -> 0.37 | AG22: =(AG6-AF6)/AF6 -> 0.08 | ... AN22: =(AN6-AM6)/AM6 -> 0.08 | AP22: TV | AQ22: -0.01
C23: RVRC y/y | AP23: NPV | AQ23: =NPV(AQ21,AE18:EK18) -> 9091.8541
C24: ICIW y/y | AP24: S/O | AQ24: 105.75545
C25: Organic growth | E25: 0.3 | F25: 0.13 | G25: 0.14 | H25: 0.24 | I25: 0.21 | J25: 0.16 | K25: 0.13 | L25: 0.05 | M25: 0.11 | N25: 0.02 | O25: 0.04 | P25: 0.15 | Q25: 0.11 | R25: 0.05 | S25: 0.03 | AD25: 0.06 | AE25: 0.08 | AP25: NPV/Share | AQ25: =AQ23/AQ24 -> 85.970549
C26: Gross margin | D26: =D8/D6 -> 0.72473868 | E26: =E8/E6 -> 0.70726916 | F26: =F8/F6 -> 0.72705314 | G26: =G8/G6 -> 0.74585635 | H26: =H8/H6 -> 0.72222222 | I26: =I8/I6 -> 0.70146819 | J26: =J8/J6 -> 0.71900826 | K26: =K8/K6 -> 0.71990172 | ... S26: =S8/S6 -> 0.72222222 | Y26: =Y8/Y6 -> 0.70137314 | Z26: =Z8/Z6 -> 0.72740828 | AA26: =AA8/AA6 -> 0.72787611 | AB26: =AB8/AB6 -> 0.72215109 | AC26: =AC8/AC6 -> 0.71335505 | AD26: =AD8/AD6 -> 0.69818182 | AE26: =AE8/AE6 -> 0.70579495 | AF26: =AF8/AF6 -> 0.7 | ... AN26: =AN8/AN6 -> 0.7 | AP26: Opp/nedside | AQ26: =(AQ25-B4)/B4 -> 0.75450099
C27: EBIT margin | D27: =D13/D6 -> 0.17421603 | E27: =E13/E6 -> 0.20628684 | F27: =F13/F6 -> 0.21014493 | G27: =G13/G6 -> 0.1878453 | H27: =H13/H6 -> 0.19590643 | I27: =I13/I6 -> 0.23327896 | J27: =J13/J6 -> 0.2107438 | K27: =K13/K6 -> 0.18181818 | ... S27: =S13/S6 -> 0.15942029 | Y27: =Y13/Y6 -> 0.21463096 | Z27: =Z13/Z6 -> 0.25250264 | AA27: =AA13/AA6 -> 0.2699115 | AB27: =AB13/AB6 -> 0.19846351 | AC27: =AC13/AC6 -> 0.20955483 | AD27: =AD13/AD6 -> 0.18545455 | AE27: =AE13/AE6 -> 0.20901436 | AF27: =AF13/AF6 -> 0.18508874 | ... AN27: =AN13/AN6 -> 0.24466792
C28: ROE | Y28: =Y18/Y61 -> 0.095158435 | Z28: =Z18/Z61 -> 0.22598157 | AA28: =AA18/AA61 -> 0.29553617 | AB28: =AB18/AB61 -> 0.21353251 | AC28: =AC18/AC61 -> 0.24680511 | AD28: =AD18/AD61 -> 0.23196721 | AE28: =AE18/AE61 -> 0.26199843
C30: EBITDA | D30: =D13-D11 -> 51 | E30: =E13-E11 -> 107 | F30: =F13-F11 -> 89 | G30: =G13-G11 -> 70 | H30: =H13-H11 -> 69 | I30: =I13-I11 -> 145 | J30: =J13-J11 -> 104 | K30: =K13-K11 -> 76 | ... S30: =S13-S11 -> 69 | Y30: =Y13-Y11 -> 85.153 | Z30: =Z13-Z11 -> 234.339 | AA30: =AA13-AA11 -> 371 | AB30: =AB13-AB11 -> 317 | AC30: =AC13-AC11 -> 395 | AD30: =AD13-AD11 -> 366 | AE30: =AE13-AE11 -> 434 | AF30: =AF13-AF11 -> 529.001 | ... AN30: =AN13-AN11 -> 1278.7844
C31: EBITDA margin | D31: =D30/D6 -> 0.17770035 | E31: =E30/E6 -> 0.21021611 | F31: =F30/F6 -> 0.21497585 | G31: =G30/G6 -> 0.19337017 | H31: =H30/H6 -> 0.20175439 | I31: =I30/I6 -> 0.2365416 | J31: =J30/J6 -> 0.21487603 | K31: =K30/K6 -> 0.18673219 | ... S31: =S30/S6 -> 0.16666667 | Y31: =Y30/Y6 -> 0.21974571 | Z31: =Z30/Z6 -> 0.25674374 | AA31: =AA30/AA6 -> 0.27359882 | AB31: =AB30/AB6 -> 0.20294494 | AC31: =AC30/AC6 -> 0.21444083 | AD31: =AD30/AD6 -> 0.19012987 | AE31: =AE30/AE6 -> 0.2149579 | AF31: =AF30/AF6 -> 0.19124919 | ... AN31: =AN30/AN6 -> 0.24977582
C32: EBITDA LTM | G32: =SUM(D30:G30) -> 317 | H32: =SUM(E30:H30) -> 335 | I32: =SUM(F30:I30) -> 373 | J32: =SUM(G30:J30) -> 388 | K32: =SUM(H30:K30) -> 394 | L32: =SUM(I30:L30) -> 384 | M32: =SUM(J30:M30) -> 399 | N32: =SUM(K30:N30) -> 377 | ... S32: =SUM(P30:S30) -> 434
C34: Averange order value (AOV) | D34: 835 | E34: 876 | F34: 930 | G34: 842 | H34: 887 | I34: 957 | J34: 969 | K34: 939 | L34: 937 | M34: 1004 | N34: 1018 | O34: 930 | P34: 944 | Q34: 1007 | R34: 932 | S34: 904
C37: Balanse SEKm
C38: Capitalised expenditure for dev work | D38: 9 | E38: 9 | F38: 9 | G38: 9 | H38: 9 | I38: 8 | J38: 7 | K38: 6 | L38: 6 | M38: 5 | N38: 4 | O38: 3 | P38: 3 | Q38: 2 | R38: 2 | S38: 1 | Y38: 7.67 | Z38: 8.8 | AA38: 9.3 | AB38: 9 | AC38: 6 | AD38: 3 | AE38: 1
C39: Trademark | D39: 171 | E39: 171 | F39: 171 | G39: 171 | H39: 171 | I39: 171 | J39: 171 | K39: 171 | L39: 171 | M39: 171 | N39: 171 | O39: 171 | P39: 171 | Q39: 171 | R39: 171 | S39: 171 | Y39: 171.2 | Z39: 171.2 | AA39: 171.2 | AB39: 171 | AC39: 171 | AD39: 171 | AE39: 171
C40: Goodwill | D40: 617 | E40: 617 | F40: 617 | G40: 617 | H40: 617 | I40: 617 | J40: 617 | K40: 617 | L40: 617 | M40: 617 | N40: 617 | O40: 617 | P40: 617 | Q40: 617 | R40: 617 | S40: 617 | Y40: 616.83 | Z40: 616.8 | AA40: 616.8 | AB40: 617 | AC40: 617 | AD40: 617 | AE40: 617
C41: Other intangible assets | D41: 0 | E41: 0 | F41: 1 | G41: 2 | H41: 2 | I41: 8 | J41: 8 | K41: 8 | L41: 8 | M41: 8 | N41: 9 | O41: 9 | P41: 9 | Q41: 10 | R41: 10 | S41: 10 | Y41: 0 | Z41: 0 | AA41: 0 | AB41: 2 | AC41: 8 | AD41: 9 | AE41: 10
C42: Expenditures on thir-party property | D42: 1 | E42: 1 | F42: 1 | G42: 1 | H42: 1 | I42: 2 | J42: 2 | K42: 2 | L42: 2 | M42: 2 | N42: 2 | O42: 2 | P42: 2 | Q42: 2 | R42: 3 | S42: 3 | Y42: 0.43 | Z42: 0.4 | AA42: 0.3 | AB42: 1 | AC42: 2 | AD42: 2 | AE42: 3
C43: Equipment, tools and installations | D43: 7 | E43: 1 | F43: 15 | G43: 14 | H43: 13 | I43: 1 | J43: 1 | K43: 1 | L43: 1 | M43: 1 | N43: 1 | O43: 2 | P43: 2 | Q43: 2 | R43: 2 | S43: 2 | Y43: 1.47 | Z43: 1.1 | AA43: 1 | AB43: 14 | AC43: 1 | AD43: 2 | AE43: 2
C44: Right of use assets | D44: 1 | E44: 15 | F44: 2 | G44: 2 | H44: 2 | I44: 12 | J44: 12 | K44: 11 | L44: 10 | M44: 9 | N44: 11 | O44: 11 | P44: 18 | Q44: 17 | R44: 16 | S44: 15 | Y44: 6.04 | Z44: 5.5 | AA44: 7.5 | AB44: 2 | AC44: 11 | AD44: 11 | AE44: 15
C45: Other long-term assets | D45: 0 | E45: 0 | F45: 0 | G45: 0 | H45: 0 | I45: 0 | J45: 0 | K45: 0 | L45: 0 | M45: 0 | N45: 0 | O45: 0 | P45: 3 | Q45: 0 | R45: 0 | S45: 0 | Y45: 0 | Z45: 2.1 | AA45: 7.9 | AB45: 0 | AC45: 0 | AD45: 0 | AE45: 0
...

Sheet SOTP
A2: EBIT 26/27
A3: =Modell!AF13 -> 511.961
C5: SEKm | D5: EBIT 26/27 | E5: EV/EBIT | F5: Value | G5: Value/share
C6: RVRC | D6: 440 | E6: 12.5 | F6: =D6*E6 -> 5500 | G6: =F6/Modell!$B$5 -> 52.006776
C7: ICIW | D7: 70 | E7: 10 | F7: =D7*E7 -> 700 | G7: =F7/Modell!$B$5 -> 6.6190442
C8: Enterprise value | D8: =SUM(D6:D7) -> 510 | F8: =SUM(F6:F7) -> 6200 | G8: =SUM(G6:G7) -> 58.62582
C10: Cash | F10: =Modell!B7 -> 328 | G10: =F10/Modell!$B$5 -> 3.101495
C11: Debt | F11: =Modell!B8 -> 0 | G11: =F11/Modell!$B$5 -> 0
C13: Equity value | G13: =G8+G10-G11 -> 61.727315

Sheet Salg region
C3: Jul-Sep | D3: Oct-Dec | E3: Jan-Mar | F3: Apr-Jun | H3: Jul-Sep | I3: Oct-Dec | J3: Jan-Mar | K3: Apr-Jun | M3: Jul-Sep | N3: Oct-Dec | O3: Jan-Mar | P3: Apr-Jun | R3: Jul-Sep | S3: Oct-Dec | T3: Jan-Mar | U3: Apr-Jun | W3: Jul-Sep | X3: Oct-Dec | Y3: Jan-Mar | Z3: Apr-Jun
B4: RVRC
B5: Region | C5: Q1 22/23 | D5: Q2 22/23 | E5: Q3 22/23 | F5: Q4 22/23 | G5: 22/23 | H5: Q1 23/24 | I5: Q2 23/24 | J5: Q3 23/24 | K5: Q4 23/24 | L5: 23/24 | M5: Q1 24/25 | N5: Q2 24/25 | O5: Q3 24/25 | P5: Q4 24/25 | Q5: 24/25 | R5: Q1 25/26 | S5: Q2 25/26 | T5: Q3 25/26 | U5: Q4 25/26 | V5: 25/26 | W5: Q1 26/27 | X5: Q2 26/27 | Y5: Q3 26/27 | Z5: Q4 26/27 | AA5: 26/27
B6: Nordics | C6: 84 | D6: 129 | E6: 91 | F6: 84 | G6: =SUM(C6:F6) -> 388 | H6: 95 | I6: 139 | J6: 95 | K6: 90 | L6: =SUM(H6:K6) -> 419 | M6: 90 | N6: 151 | O6: 104 | P6: 101 | Q6: =SUM(M6:P6) -> 446 | R6: 105 | S6: 157 | T6: 109 | U6: 108 | V6: =SUM(R6:U6) -> 479 | AA6: =SUM(W6:Z6) -> 0
B7: y/y | H7: =(H6-C6)/C6 -> 0.13095238 | I7: =(I6-D6)/D6 -> 0.07751938 | J7: =(J6-E6)/E6 -> 0.043956044 | K7: =(K6-F6)/F6 -> 0.071428571 | L7: =(L6-G6)/G6 -> 0.079896907 | M7: =(M6-H6)/H6 -> -0.052631579 | N7: =(N6-I6)/I6 -> 0.086330935 | O7: =(O6-J6)/J6 -> 0.094736842 | ... AA7: =(AA6-V6)/V6 -> -1
B8: y/y Local curr | M8: -0.04 | N8: 0.09 | O8: 0.1 | P8: 0.15 | R8: 0.19 | S8: 0.06 | T8: 0.06 | U8: 0.07 | V8: 0.09
B9: DACH | C9: 146 | D9: 277 | E9: 235 | F9: 205 | G9: =SUM(C9:F9) -> 863 | H9: 180 | I9: 347 | J9: 277 | K9: 231 | L9: =SUM(H9:K9) -> 1035 | M9: 188 | N9: 399 | O9: 279 | P9: 226 | Q9: =SUM(M9:P9) -> 1092 | R9: 216 | S9: 434 | T9: 285 | U9: 231 | V9: =SUM(R9:U9) -> 1166 | AA9: =SUM(W9:Z9) -> 0
B10: y/y | H10: =(H9-C9)/C9 -> 0.23287671 | I10: =(I9-D9)/D9 -> 0.25270758 | J10: =(J9-E9)/E9 -> 0.1787234 | K10: =(K9-F9)/F9 -> 0.12682927 | L10: =(L9-G9)/G9 -> 0.19930475 | M10: =(M9-H9)/H9 -> 0.044444444 | N10: =(N9-I9)/I9 -> 0.14985591 | O10: =(O9-J9)/J9 -> 0.0072202166 | ... AA10: =(AA9-V9)/V9 -> -1
B11: y/y Local Curr | M11: 0.08 | N11: 0.15 | O11: 0.01 | P11: 0.03 | R11: 0.18 | S11: 0.14 | T11: 0.07 | U11: 0.03 | V11: 0.1
B12: RoW | C12: 46 | D12: 103 | E12: 88 | F12: 73 | G12: =SUM(C12:F12) -> 310 | H12: 66 | I12: 127 | J12: 106 | K12: 86 | L12: =SUM(H12:K12) -> 385 | M12: 72 | N12: 134 | O12: 103 | P12: 78 | Q12: =SUM(M12:P12) -> 387 | R12: 71 | S12: 135 | T12: 93 | U12: 75 | V12: =SUM(R12:U12) -> 374 | AA12: =SUM(W12:Z12) -> 0
B13: y/y | H13: =(H12-C12)/C12 -> 0.43478261 | I13: =(I12-D12)/D12 -> 0.23300971 | J13: =(J12-E12)/E12 -> 0.20454545 | K13: =(K12-F12)/F12 -> 0.17808219 | L13: =(L12-G12)/G12 -> 0.24193548 | M13: =(M12-H12)/H12 -> 0.090909091 | N13: =(N12-I12)/I12 -> 0.05511811 | O13: =(O12-J12)/J12 -> -0.028301887 | ... AA13: =(AA12-V12)/V12 -> -1
B14: y/y Local curr | M14: 0.11 | N14: 0.04 | O14: -0.03 | P14: -0.05 | R14: 0.02 | S14: 0.06 | T14: -0.04 | U14: -0.03 | V14: 0.01
C16: Q1 22/23 | D16: Q2 22/23 | E16: Q3 22/23 | F16: Q4 22/23 | G16: 22/23 | H16: Q1 23/24 | I16: Q2 23/24 | J16: Q3 23/24 | K16: Q4 23/24 | L16: 23/24 | M16: Q1 24/25 | N16: Q2 24/25 | O16: Q3 24/25 | P16: Q4 24/25 | Q16: 24/25 | R16: Q1 25/26 | S16: Q2 25/26 | T16: Q3 25/26 | U16: Q4 25/26 | V16: 25/26 | W16: Q1 26/27 | X16: Q2 26/27 | Y16: Q3 26/27 | Z16: Q4 26/27 | AA16: 26/27
B17: Germany | C17: 126 | D17: 235 | E17: 206 | F17: 177 | G17: =SUM(C17:F17) -> 744 | H17: 158 | I17: 301 | J17: 242 | K17: 204 | L17: =SUM(H17:K17) -> 905 | M17: 165 | N17: 339 | O17: 239 | P17: 193 | Q17: =SUM(M17:P17) -> 936 | R17: 183 | S17: 359 | T17: 239 | U17: 193 | V17: =SUM(R17:U17) -> 974 | AA17: =SUM(W17:Z17) -> 0
B18: y/y | H18: =(H17-C17)/C17 -> 0.25396825 | I18: =(I17-D17)/D17 -> 0.28085106 | J18: =(J17-E17)/E17 -> 0.17475728 | K18: =(K17-F17)/F17 -> 0.15254237 | L18: =(L17-G17)/G17 -> 0.21639785 | M18: =(M17-H17)/H17 -> 0.044303797 | N18: =(N17-I17)/I17 -> 0.12624585 | O18: =(O17-J17)/J17 -> -0.012396694 | ... AA18: =(AA17-V17)/V17 -> -1
B19: y/y Local curr | M19: 0.07 | N19: 0.12 | O19: -0.01 | P19: -0.01 | R19: 0.14 | S19: 0.11 | T19: 0.05 | U19: 0.01
B20: Sweden | C20: 37 | D20: 61 | E20: 44 | F20: 41 | G20: =SUM(C20:F20) -> 183 | H20: 43 | I20: 64 | J20: 47 | K20: 45 | L20: =SUM(H20:K20) -> 199 | M20: 44 | N20: 74 | O20: 52 | P20: 51 | Q20: =SUM(M20:P20) -> 221 | R20: 52 | S20: 76 | T20: 58 | U20: 57 | V20: =SUM(R20:U20) -> 243 | AA20: =SUM(W20:Z20) -> 0
B21: y/y | H21: =(H20-C20)/C20 -> 0.16216216 | I21: =(I20-D20)/D20 -> 0.049180328 | J21: =(J20-E20)/E20 -> 0.068181818 | K21: =(K20-F20)/F20 -> 0.097560976 | L21: =(L20-G20)/G20 -> 0.087431694 | M21: =(M20-H20)/H20 -> 0.023255814 | N21: =(N20-I20)/I20 -> 0.15625 | O21: =(O20-J20)/J20 -> 0.10638298 | ... AA21: =(AA20-V20)/V20 -> -1
B22: y/y Local curr | M22: 0.02 | N22: 0.15 | O22: 0.1 | P22: 0.13 | R22: 0.18 | S22: 0.02 | T22: 0.12 | U22: 0.12
B23: Other | C23: 85 | D23: 181 | E23: 143 | F23: 123 | G23: =SUM(C23:F23) -> 532 | H23: 110 | I23: 214 | J23: 168 | K23: 139 | L23: =SUM(H23:K23) -> 631 | M23: 141 | N23: 271 | O23: 195 | P23: 161 | Q23: =SUM(M23:P23) -> 768 | R23: 158 | S23: 291 | T23: 190 | U23: 164 | V23: =SUM(R23:U23) -> 803 | AA23: =SUM(W23:Z23) -> 0
B24: y/y | H24: =(H23-C23)/C23 -> 0.29411765 | I24: =(I23-D23)/D23 -> 0.18232044 | J24: =(J23-E23)/E23 -> 0.17482517 | K24: =(K23-F23)/F23 -> 0.1300813 | L24: =(L23-G23)/G23 -> 0.18609023 | M24: =(M23-H23)/H23 -> 0.28181818 | N24: =(N23-I23)/I23 -> 0.26635514 | O24: =(O23-J23)/J23 -> 0.16071429 | ... AA24: =(AA23-V23)/V23 -> -1
B25: y/y Local curr | M25: 0.04 | N25: 0.08 | O25: 0.03 | P25: 0.07 | R25: 0.15 | S25: 0.13 | T25: 0.02 | U25: 0.03
R27: Jul-Sep | S27: Oct-Dec | T27: Jan-Mar | U27: Apr-Jun | W27: Jul-Sep | X27: Oct-Dec | Y27: Jan-Mar | Z27: Apr-Jun
B28: ICIW
B29: Region | R29: Q1 25/26 | S29: Q2 25/26 | T29: Q3 25/26 | U29: Q4 25/26 | V29: 25/26 | W29: Q1 26/27 | X29: Q2 26/27 | Y29: Q3 26/27 | Z29: Q4 26/27 | AA29: 26/27
B30: Nordics | R30: 88 | S30: 103 | T30: 98 | U30: 98 | V30: =SUM(R30:U30) -> 387 | AA30: =SUM(W30:Z30) -> 0
B31: y/y | W31: =(W30-R30)/R30 -> -1 | X31: =(X30-S30)/S30 -> -1 | Y31: =(Y30-T30)/T30 -> -1 | Z31: =(Z30-U30)/U30 -> -1 | AA31: =(AA30-V30)/V30 -> -1
B32: y/y Local curr
B33: DACH | R33: 13 | S33: 16 | T33: 15 | U33: 20 | V33: =SUM(R33:U33) -> 64 | AA33: =SUM(W33:Z33) -> 0
B34: y/y | W34: =(W33-R33)/R33 -> -1 | X34: =(X33-S33)/S33 -> -1 | Y34: =(Y33-T33)/T33 -> -1 | Z34: =(Z33-U33)/U33 -> -1 | AA34: =(AA33-V33)/V33 -> -1
B35: y/y Local Curr
B36: RoW | R36: 3 | S36: 5 | T36: 5 | U36: 6 | V36: =SUM(R36:U36) -> 19 | AA36: =SUM(W36:Z36) -> 0
B37: y/y | W37: =(W36-R36)/R36 -> -1 | X37: =(X36-S36)/S36 -> -1 | Y37: =(Y36-T36)/T36 -> -1 | Z37: =(Z36-U36)/U36 -> -1 | AA37: =(AA36-V36)/V36 -> -1
B38: y/y Local curr
R40: Q1 25/26 | S40: Q2 25/26 | T40: Q3 25/26 | U40: Q4 25/26 | V40: 25/26 | W40: Q1 26/27 | X40: Q2 26/27 | Y40: Q3 26/27 | Z40: Q4 26/27 | AA40: 26/27
B41: Germany | V41: =SUM(R41:U41) -> 0 | AA41: =SUM(W41:Z41) -> 0
B42: y/y | R42: =(R41-M41)/M41 -> #DIV/0! | S42: =(S41-N41)/N41 -> #DIV/0! | T42: =(T41-O41)/O41 -> #DIV/0! | U42: =(U41-P41)/P41 -> #DIV/0! | V42: =(V41-Q41)/Q41 -> #DIV/0! | W42: =(W41-R41)/R41 -> #DIV/0! | X42: =(X41-S41)/S41 -> #DIV/0! | Y42: =(Y41-T41)/T41 -> #DIV/0! | ... AA42: =(AA41-V41)/V41 -> #DIV/0!
B43: y/y Local curr
B44: Sweden | V44: =SUM(R44:U44) -> 0 | AA44: =SUM(W44:Z44) -> 0
B45: y/y | R45: =(R44-M44)/M44 -> #DIV/0! | S45: =(S44-N44)/N44 -> #DIV/0! | T45: =(T44-O44)/O44 -> #DIV/0! | U45: =(U44-P44)/P44 -> #DIV/0! | V45: =(V44-Q44)/Q44 -> #DIV/0! | W45: =(W44-R44)/R44 -> #DIV/0! | X45: =(X44-S44)/S44 -> #DIV/0! | Y45: =(Y44-T44)/T44 -> #DIV/0! | ... AA45: =(AA44-V44)/V44 -> #DIV/0!
...

Sheet Resultat per business
C2: Jul-Sep | D2: Oct-Dec | E2: Jan-Mar | F2: Apr-Jun | H2: Jul-Sep | I2: Oct-Dec | J2: Jan-Mar | K2: Apr-Jun
B4: SEKm | C4: Q1 25/26 | D4: Q2 25/26 | E4: Q3 25/26 | F4: Q4 25/26 | G4: 25/26 | H4: Q1 26/27 | I4: Q2 26/27 | J4: Q3 26/27 | K4: Q4 26/27 | L4: 26/27
B5: RVRC
B6: Revenue | C6: 392 | D6: 726 | E6: 487 | F6: 414 | G6: =SUM(C6:F6) -> 2019 | L6: =SUM(H6:K6) -> 0
B7: y/y | H7: =(H6-C6)/C6 -> -1 | I7: =(I6-D6)/D6 -> -1 | J7: =(J6-E6)/E6 -> -1 | K7: =(K6-F6)/F6 -> -1 | L7: =(L6-G6)/G6 -> -1
B8: Gross profit | C8: 273 | D8: 506 | E8: 345 | F8: 299 | G8: =SUM(C8:F8) -> 1423 | L8: =SUM(H8:K8) -> 0
B9: Gross margin | C9: =C8/C6 -> 0.69642857 | D9: =D8/D6 -> 0.6969697 | E9: =E8/E6 -> 0.70841889 | F9: =F8/F6 -> 0.72222222 | G9: =G8/G6 -> 0.70480436 | H9: =H8/H6 -> #DIV/0! | I9: =I8/I6 -> #DIV/0! | J9: =J8/J6 -> #DIV/0! | ... L9: =L8/L6 -> #DIV/0!
B10: Operating profit (EBIT) | C10: 77 | D10: 181 | E10: 108 | F10: 69 | G10: =SUM(C10:F10) -> 435 | L10: =SUM(H10:K10) -> 0
B11: EBIT margin | C11: =C10/C6 -> 0.19642857 | D11: =D10/D6 -> 0.24931129 | E11: =E10/E6 -> 0.22176591 | F11: =F10/F6 -> 0.16666667 | G11: =G10/G6 -> 0.21545319 | H11: =H10/H6 -> #DIV/0! | I11: =I10/I6 -> #DIV/0! | J11: =J10/J6 -> #DIV/0! | ... L11: =L10/L6 -> #DIV/0!
B12: ICIW
B13: Revenue | C13: 104 | D13: 124 | E13: 118 | F13: 123 | G13: =SUM(C13:F13) -> 469 | L13: =SUM(H13:K13) -> 0
B14: y/y | H14: =(H13-C13)/C13 -> -1 | I14: =(I13-D13)/D13 -> -1 | J14: =(J13-E13)/E13 -> -1 | K14: =(K13-F13)/F13 -> -1 | L14: =(L13-G13)/G13 -> -1
B15: Gross profit | C15: 73 | D15: 88 | E15: 84 | F15: 93 | G15: =SUM(C15:F15) -> 338 | L15: =SUM(H15:K15) -> 0
B16: Gross margin | C16: =C15/C13 -> 0.70192308 | D16: =D15/D13 -> 0.70967742 | E16: =E15/E13 -> 0.71186441 | F16: =F15/F13 -> 0.75609756 | G16: =G15/G13 -> 0.7206823 | H16: =H15/H13 -> #DIV/0! | I16: =I15/I13 -> #DIV/0! | J16: =J15/J13 -> #DIV/0! | ... L16: =L15/L13 -> #DIV/0!
B17: Operating profit (EBIT) | C17: 14 | D17: 18 | E17: 18 | F17: 19 | G17: =SUM(C17:F17) -> 69 | L17: =SUM(H17:K17) -> 0
B18: EBIT margin | C18: =C17/C13 -> 0.13461538 | D18: =D17/D13 -> 0.14516129 | E18: =E17/E13 -> 0.15254237 | F18: =F17/F13 -> 0.15447154 | G18: =G17/G13 -> 0.14712154 | H18: =H17/H13 -> #DIV/0! | I18: =I17/I13 -> #DIV/0! | J18: =J17/J13 -> #DIV/0! | ... L18: =L17/L13 -> #DIV/0!

Sheet Nøkkeltall
D4: 26/27 | E4: 27/28 | F4: 28/29
C5: EV/EBIT | D5: =Modell!$B$9/Modell!AF13 -> 9.4812243 | E5: =Modell!$B$9/Modell!AG13 -> 8.4206778 | F5: =Modell!$B$9/Modell!AH13 -> 7.4959415
C6: P/E | D6: =Modell!$B$4/Modell!AF20 -> 12.652373 | E6: =Modell!$B$4/Modell!AG20 -> 11.237109 | F6: =Modell!$B$4/Modell!AH20 -> 10.00308

Sheet Nedsideberegning
A3: Nedside | D3: FY 19/20 | E3: FY 20/21 | F3: FY 21/22 | G3: FY 22/23 | H3: FY 23/24 | I3: FY 24/25 | J3: FY 25/26 | K3: FY 26/27 | L3: FY 27/28 | M3: FY 28/29 | N3: FY 29/30 | O3: FY 30/31 | P3: FY 31/32 | Q3: FY 32/33 | R3: FY 33/34 | S3: FY 34/35
A4: Nullvekst og dårligste marginer | C4: Revenue | D4: 387.507 | E4: 912.735 | F4: 1356 | G4: 1562 | H4: 1842 | I4: 1925 | J4: =I4*1.06 -> 2040.5 | K4: =J4 -> 2040.5 | L4: =K4 -> 2040.5 | M4: =L4 -> 2040.5 | N4: =M4 -> 2040.5 | O4: =N4 -> 2040.5 | P4: =O4 -> 2040.5 | Q4: =P4 -> 2040.5 | R4: =Q4 -> 2040.5 | S4: =R4 -> 2040.5
A5: =V23 -> 33.408436 | C5: Goods for resale | D5: -115.72 | E5: -248.804 | F5: -369 | G5: -434 | H5: -528 | I5: -581 | J5: =J4*-0.3 -> -612.15 | K5: =K4*-0.32 -> -652.96 | L5: =L4*-0.32 -> -652.96 | M5: =M4*-0.32 -> -652.96 | N5: =N4*-0.32 -> -652.96 | O5: =O4*-0.32 -> -652.96 | P5: =P4*-0.32 -> -652.96 | Q5: =Q4*-0.32 -> -652.96 | R5: =R4*-0.32 -> -652.96 | S5: =S4*-0.32 -> -652.96
A6: =V24 -> -0.31819518 | C6: Gross profit | D6: =SUM(D4:D5) -> 271.787 | E6: =SUM(E4:E5) -> 663.931 | F6: =SUM(F4:F5) -> 987 | G6: =SUM(G4:G5) -> 1128 | H6: =SUM(H4:H5) -> 1314 | I6: =SUM(I4:I5) -> 1344 | J6: =SUM(J4:J5) -> 1428.35 | K6: =SUM(K4:K5) -> 1387.54 | ... S6: =SUM(S4:S5) -> 1387.54
C7: Other external expenses | D7: -156.999 | E7: -363.697 | F7: -539 | G7: -701 | H7: -805 | I7: -831 | J7: =I7*1.03 -> -855.93 | K7: =J7*1 -> -855.93 | L7: =K7 -> -855.93 | M7: =L7 -> -855.93 | N7: =M7 -> -855.93 | O7: =N7 -> -855.93 | P7: =O7 -> -855.93 | Q7: =P7 -> -855.93 | R7: =Q7 -> -855.93 | S7: =R7 -> -855.93
C8: Personnel expenses | D8: -29.635 | E8: -48.595 | F8: -77 | G8: -110 | H8: -114 | I8: -143 | J8: =I8*1.03 -> -147.29 | K8: =J8*1 -> -147.29 | L8: =K8 -> -147.29 | M8: =L8 -> -147.29 | N8: =M8 -> -147.29 | O8: =N8 -> -147.29 | P8: =O8 -> -147.29 | Q8: =P8 -> -147.29 | R8: =Q8 -> -147.29 | S8: =R8 -> -147.29
C9: D/A | D9: -1.982 | E9: -3.871 | F9: -5 | G9: -7 | H9: -9 | I9: -9 | J9: =I9*1.03 -> -9.27 | K9: =J9*1 -> -9.27 | L9: =K9 -> -9.27 | M9: =L9 -> -9.27 | N9: =M9 -> -9.27 | O9: =N9 -> -9.27 | P9: =O9 -> -9.27 | Q9: =P9 -> -9.27 | R9: =Q9 -> -9.27 | S9: =R9 -> -9.27
C10: Other operating expenses | D10: 0 | E10: -17.3 | F10: 0 | G10: 0 | H10: 0 | I10: -4 | J10: =I10*1.03 -> -4.12 | K10: =J10*1 -> -4.12 | L10: =K10 -> -4.12 | M10: =L10 -> -4.12 | N10: =M10 -> -4.12 | O10: =N10 -> -4.12 | P10: =O10 -> -4.12 | Q10: =P10 -> -4.12 | R10: =Q10 -> -4.12 | S10: =R10 -> -4.12
C11: Operating profit (EBIT) | D11: =SUM(D6:D10) -> 83.171 | E11: =SUM(E6:E10) -> 230.468 | F11: =SUM(F6:F10) -> 366 | G11: =SUM(G6:G10) -> 310 | H11: =SUM(H6:H10) -> 386 | I11: =SUM(I6:I10) -> 357 | J11: =SUM(J6:J10) -> 411.74 | K11: =SUM(K6:K10) -> 370.93 | ... S11: =SUM(S6:S10) -> 370.93
C12: Fincial income | D12: 0 | E12: 0 | F12: 0 | G12: 1 | H12: 8 | I12: 4 | J12: 0 | K12: 0 | L12: 0 | M12: 0 | N12: 0 | O12: 0 | P12: 0 | Q12: 0 | R12: 0 | S12: 0
C13: Financial expense | D13: -7 | E13: -12 | F13: -3 | G13: -5 | H13: -4 | I13: -4 | J13: 0 | K13: 0 | L13: 0 | M13: 0 | N13: 0 | O13: 0 | P13: 0 | Q13: 0 | R13: 0 | S13: 0
C14: PTP | D14: =SUM(D11:D13) -> 76.171 | E14: =SUM(E11:E13) -> 218.468 | F14: =SUM(F11:F13) -> 363 | G14: =SUM(G11:G13) -> 306 | H14: =SUM(H11:H13) -> 390 | I14: =SUM(I11:I13) -> 357 | J14: =SUM(J11:J13) -> 411.74 | K14: =SUM(K11:K13) -> 370.93 | ... S14: =SUM(S11:S13) -> 370.93
C15: Tax | D15: -16.5 | E15: -46.835 | F15: -75 | G15: -63 | H15: -81 | I15: -74 | J15: =J14*-0.2 -> -82.348 | K15: =K14*-0.2 -> -74.186 | L15: =L14*-0.2 -> -74.186 | M15: =M14*-0.2 -> -74.186 | N15: =N14*-0.2 -> -74.186 | O15: =O14*-0.2 -> -74.186 | P15: =P14*-0.2 -> -74.186 | Q15: =Q14*-0.2 -> -74.186 | ... S15: =S14*-0.2 -> -74.186
C16: Net income | D16: =SUM(D14:D15) -> 59.671 | E16: =SUM(E14:E15) -> 171.633 | F16: =SUM(F14:F15) -> 288 | G16: =SUM(G14:G15) -> 243 | H16: =SUM(H14:H15) -> 309 | I16: =SUM(I14:I15) -> 283 | J16: =SUM(J14:J15) -> 329.392 | K16: =SUM(K14:K15) -> 296.744 | ... S16: =SUM(S14:S15) -> 296.744 | T16: =S16*(1+$V$20) -> 293.77656 | U16: =T16*(1+$V$20) -> 290.83879 | V16: =U16*(1+$V$20) -> 287.93041 | W16: =V16*(1+$V$20) -> 285.0511 | X16: =W16*(1+$V$20) -> 282.20059 | Y16: =X16*(1+$V$20) -> 279.37859 | Z16: =Y16*(1+$V$20) -> 276.5848 | AA16: =Z16*(1+$V$20) -> 273.81895 | ... DP16: =DO16*(1+$V$20) -> 107.53172
C17: Shares | D17: 107.767 | E17: 107.767 | F17: 112.91892 | G17: 112.91892 | H17: 112.91892 | I17: 111.06566 | J17: 105.75545 | K17: 105.75545 | L17: 105.75545 | M17: 105.75545 | N17: 105.75545 | O17: 105.75545 | P17: 105.75545 | Q17: 105.75545 | R17: 105.75545 | S17: 105.75545
C18: EPS | D18: =D16/D17 -> 0.55370382 | E18: =E16/E17 -> 1.5926304 | F18: =F16/F17 -> 2.5505027 | G18: =G16/G17 -> 2.1519866 | H18: =H16/H17 -> 2.7364768 | I18: =I16/I17 -> 2.5480424 | J18: =J16/J17 -> 3.1146574 | K18: =K16/K17 -> 2.8059452 | ... S18: =S16/S17 -> 2.8059452
U19: Disocunt | V19: 0.08
C20: Revenue y/y | E20: =(E4-D4)/D4 -> 1.3554026 | F20: =(F4-E4)/E4 -> 0.48564479 | G20: =(G4-F4)/F4 -> 0.1519174 | H20: =(H4-G4)/G4 -> 0.17925736 | I20: =(I4-H4)/H4 -> 0.045059718 | J20: =(J4-I4)/I4 -> 0.06 | K20: =(K4-J4)/J4 -> 0 | L20: =(L4-K4)/K4 -> 0 | ... S20: =(S4-R4)/R4 -> 0 | U20: TV | V20: -0.01
C21: Gross margin | D21: =D6/D4 -> 0.70137314 | E21: =E6/E4 -> 0.72740828 | F21: =F6/F4 -> 0.72787611 | G21: =G6/G4 -> 0.72215109 | H21: =H6/H4 -> 0.71335505 | I21: =I6/I4 -> 0.69818182 | J21: =J6/J4 -> 0.7 | K21: =K6/K4 -> 0.68 | ... S21: =S6/S4 -> 0.68 | U21: NPV | V21: =NPV(V19,J16:DP16) -> 3533.1242
C22: EBIT margin | D22: =D11/D4 -> 0.21463096 | E22: =E11/E4 -> 0.25250264 | F22: =F11/F4 -> 0.2699115 | G22: =G11/G4 -> 0.19846351 | H22: =H11/H4 -> 0.20955483 | I22: =I11/I4 -> 0.18545455 | J22: =J11/J4 -> 0.20178388 | K22: =K11/K4 -> 0.18178388 | ... S22: =S11/S4 -> 0.18178388 | U22: S/O | V22: 105.75545
U23: NPV/Share | V23: =V21/V22 -> 33.408436
U24: Opp/nedside | V24: =(V23-Modell!B4)/Modell!B4 -> -0.31819518
