Workbook

Sheet Info
N8: Tilbakekjøpsprogram
N9: Dato kjøp | O9: Antall aksjer | P9: Akummelert antall aksjer | Q9: Kjøp | R9: Akkumelert kjøp
N16: 46168 | O16: 1189859 | P16: =O16 -> 1189859 | Q16: 52395060 | R16: =Q16 -> 52395060
N17: 46185 | O17: 1101253 | P17: =SUM(O16:O17) -> 2291112 | Q17: =99999986-Q16 -> 47604926 | R17: =SUM(Q16:Q17) -> 99999986
N18: 46185 | O18: 1217425 | P18: =SUM(O16:O18) -> 3508537 | Q18: =149999967-R17 -> 49999981 | R18: =SUM(Q16:Q18) -> 149999967
N19: 46202 | O19: 1200054 | P19: =SUM(O16:O19) -> 4708591 | Q19: =199999953-R18 -> 49999986 | R19: =SUM(Q16:Q19) -> 199999953
A22: Press releases:
A23: 14.08.26: Sats starter nytt tilbakekjøpsprogram på 100 mill / 3,5mill akskjer
A24: 29.06.26: Sats kjøper tilbake 1 200 054
A25: 24.06.26: Alfred berg flagger 5%
A26: 12.06.26: Sats kjøper tilbake 1 217 425 aksjer
A27: 12.06.26: Sats kjøper tilbake 1 101 253 aksjer
A28: 26.05.26: Sats kjøper tilbake 1 189 857 aksjer
A29: 12.05.26: Sats starter tilbakekjøpsprogram på 200 mill/7 mill aksjer

Sheet Modell
A3: Kapitalstruktur | C3: NOK million | D3: Q122 | E3: Q222 | F3: Q322 | G3: Q422 | H3: Q123 | I3: Q223 | J3: Q323 | K3: Q423 | L3: Q124 | M3: Q224 | N3: Q324 | O3: Q424 | P3: Q125 | Q3: Q225 | R3: Q325 | S3: Q425 | T3: Q126 | U3: Q226 | V3: Q326 | W3: Q426 | Z3: FY 2018 | AA3: FY 2019 | AB3: FY 2020 | AC3: FY 2021 | AD3: FY 2022 | AE3: FY 2023 | AF3: FY 2024 | AG3: FY 2025 | AH3: FY 2026 | AI3: FY 2027 | AJ3: FY 2028 | AK3: FY 2029 | AL3: FY 2030 | AM3: FY 2031 | AN3: FY 2032 | AO3: FY 2033 | AP3: FY 2034 | AQ3: FY 2035
A4: Price | B4: 44.4 | C4: Revenue | D4: 1011 | E4: 1022 | F4: 967 | G4: 1082 | H4: 1201 | I4: 1200 | J4: 1106 | K4: 1227 | L4: 1294 | M4: 1266 | N4: 1194 | O4: 1311 | P4: 1395 | Q4: 1393 | R4: 1293 | S4: 1428 | T4: 1483 | U4: 1442 | Z4: 3259 | AA4: 3987 | AB4: 3534 | AC4: 3247 | AD4: =SUM(D4:G4) -> 4082 | AE4: =SUM(H4:K4) -> 4734 | AF4: =SUM(L4:O4) -> 5065 | AG4: 5509 | AH4: =AG4*1.06 -> 5839.54 | AI4: =AH4*1.05 -> 6131.517 | AJ4: =AI4*1.05 -> 6438.0928 | AK4: =AJ4*1.05 -> 6759.9975 | AL4: =AK4*1.05 -> 7097.9974 | AM4: =AL4*1.05 -> 7452.8972 | AN4: =AM4*1.05 -> 7825.5421 | AO4: =AN4*1.05 -> 8216.8192 | AP4: =AO4*1.05 -> 8627.6602 | AQ4: =AP4*1.05 -> 9059.0432
A5: S/O | B5: 204.69459 | C5: COGS | D5: -38 | E5: -29 | F5: -33 | G5: -47 | H5: -36 | I5: -35 | J5: -31 | K5: -35 | L5: -40 | M5: -30 | N5: -33 | O5: -40 | P5: -38 | Q5: -36 | R5: -35 | S5: -37 | T5: -38 | U5: -37 | Z5: -80 | AA5: -115 | AB5: -122 | AC5: -106 | AD5: =SUM(D5:G5) -> -147 | AE5: =SUM(H5:K5) -> -137 | AF5: =SUM(L5:O5) -> -143 | AG5: -146 | AH5: =AH4*-0.026 -> -151.82804 | AI5: =AI4*-0.026 -> -159.41944 | AJ5: =AJ4*-0.026 -> -167.39041 | AK5: =AK4*-0.026 -> -175.75993 | AL5: =AL4*-0.026 -> -184.54793 | AM5: =AM4*-0.026 -> -193.77533 | AN5: =AN4*-0.026 -> -203.46409 | AO5: =AO4*-0.026 -> -213.6373 | ... AQ5: =AQ4*-0.026 -> -235.53512
A6: MC NOKm | B6: =B4*B5 -> 9088.4397 | C6: Gross profit | D6: =D4+D5 -> 973 | E6: =E4+E5 -> 993 | F6: =F4+F5 -> 934 | G6: =G4+G5 -> 1035 | H6: =H4+H5 -> 1165 | I6: =I4+I5 -> 1165 | J6: =J4+J5 -> 1075 | K6: =K4+K5 -> 1192 | ... U6: =U4+U5 -> 1405 | Z6: =Z4+Z5 -> 3179 | AA6: =AA4+AA5 -> 3872 | AB6: =AB4+AB5 -> 3412 | AC6: =AC4+AC5 -> 3141 | AD6: =AD4+AD5 -> 3935 | AE6: =AE4+AE5 -> 4597 | AF6: =AF4+AF5 -> 4922 | AG6: =AG4+AG5 -> 5363 | ... AQ6: =AQ4+AQ5 -> 8823.508
A7: Cash NOKm | B7: =U48 -> 326 | C7: Personel expenses | D7: -403 | E7: -382 | F7: -357 | G7: -446 | H7: -436 | I7: -398 | J7: -367 | K7: -476 | L7: -486 | M7: -446 | N7: -418 | O7: -511 | P7: -538 | Q7: -491 | R7: -461 | S7: -565 | T7: -587 | U7: -498 | Z7: -1224 | AA7: -1463 | AB7: -1352 | AC7: -1399 | AD7: =SUM(D7:G7) -> -1588 | AE7: =SUM(H7:K7) -> -1677 | AF7: =SUM(L7:O7) -> -1861 | AG7: -2055 | AH7: =AG7*1.03 -> -2116.65 | AI7: =AH7*1.035 -> -2190.7328 | AJ7: =AI7*1.035 -> -2267.4084 | AK7: =AJ7*1.035 -> -2346.7677 | AL7: =AK7*1.035 -> -2428.9046 | AM7: =AL7*1.035 -> -2513.9162 | AN7: =AM7*1.035 -> -2601.9033 | AO7: =AN7*1.035 -> -2692.9699 | AP7: =AO7*1.035 -> -2787.2238 | AQ7: =AP7*1.035 -> -2884.7767
A8: Debt NOKm | B8: =U57+U60 -> 1403 | C8: Other opex | D8: -283 | E8: -268 | F8: -297 | G8: -359 | H8: -305 | I8: -276 | J8: -263 | K8: -291 | L8: -293 | M8: -269 | N8: -272 | O8: -286 | P8: -326 | Q8: -287 | R8: -295 | S8: -291 | T8: -331 | U8: -292 | Z8: -688 | AA8: -925 | AB8: -925 | AC8: -925 | AD8: =SUM(D8:G8) -> -1207 | AE8: =SUM(H8:K8) -> -1135 | AF8: =SUM(L8:O8) -> -1120 | AG8: -1199 | AH8: =AG8*1.03 -> -1234.97 | AI8: =AH8*1.03 -> -1272.0191 | AJ8: =AI8*1.03 -> -1310.1797 | AK8: =AJ8*1.03 -> -1349.4851 | AL8: =AK8*1.03 -> -1389.9696 | AM8: =AL8*1.03 -> -1431.6687 | AN8: =AM8*1.03 -> -1474.6188 | AO8: =AN8*1.03 -> -1518.8573 | ... AQ8: =AP8*1.03 -> -1611.3557
A9: EV NOKm | B9: =B6-B7+B8 -> 10165.44 | C9: D/A | D9: -274 | E9: -275 | F9: -276 | G9: -296 | H9: -298 | I9: -289 | J9: -289 | K9: -302 | L9: -303 | M9: -305 | N9: -296 | O9: -294 | P9: -300 | Q9: -306 | R9: -304 | S9: -307 | T9: -306 | U9: -297 | Z9: =-739-265 -> -1004 | AA9: -972 | AB9: =-1045-70 -> -1115 | AC9: -1042 | AD9: =SUM(D9:G9) -> -1121 | AE9: =SUM(H9:K9) -> -1178 | AF9: =SUM(L9:O9) -> -1198 | AG9: -1217 | AH9: =AG9*1.03 -> -1253.51 | AI9: =AH9*1.04 -> -1303.6504 | AJ9: =AI9*1.04 -> -1355.7964 | AK9: =AJ9*1.04 -> -1410.0283 | AL9: =AK9*1.04 -> -1466.4294 | AM9: =AL9*1.04 -> -1525.0866 | AN9: =AM9*1.04 -> -1586.09 | AO9: =AN9*1.04 -> -1649.5336 | AP9: =AO9*1.04 -> -1715.515 | AQ9: =AP9*1.04 -> -1784.1356
C10: Operating profit (EBIT) | D10: =SUM(D6:D9) -> 13 | E10: =SUM(E6:E9) -> 68 | F10: =SUM(F6:F9) -> 4 | G10: =SUM(G6:G9) -> -66 | H10: =SUM(H6:H9) -> 126 | I10: =SUM(I6:I9) -> 202 | J10: =SUM(J6:J9) -> 156 | K10: =SUM(K6:K9) -> 123 | ... U10: =SUM(U6:U9) -> 318 | Z10: =SUM(Z6:Z9) -> 263 | AA10: =SUM(AA6:AA9) -> 512 | AB10: =SUM(AB6:AB9) -> 20 | AC10: =SUM(AC6:AC9) -> -225 | AD10: =SUM(AD6:AD9) -> 19 | AE10: =SUM(AE6:AE9) -> 607 | AF10: =SUM(AF6:AF9) -> 743 | AG10: =SUM(AG6:AG9) -> 892 | ... AQ10: =SUM(AQ6:AQ9) -> 2543.24
C11: Net financials | D11: -67 | E11: -46 | F11: -59 | G11: -109 | H11: -42 | I11: -78 | J11: -107 | K11: -67 | L11: -72 | M11: -82 | N11: -79 | O11: -77 | P11: -70 | Q11: -68 | R11: -70 | S11: -69 | T11: -84 | U11: -69 | Z11: -240 | AA11: -265 | AB11: -267 | AC11: -298 | AD11: =SUM(D11:G11) -> -281 | AE11: =SUM(H11:K11) -> -294 | AF11: =SUM(L11:O11) -> -310 | AG11: -277 | AH11: =AG11*1.01 -> -279.77 | AI11: =AH11*1.01 -> -282.5677 | AJ11: =AI11*1.01 -> -285.39338 | AK11: =AJ11*1.01 -> -288.24731 | AL11: =AK11*1.01 -> -291.12978 | AM11: =AL11*1.01 -> -294.04108 | AN11: =AM11*1.01 -> -296.98149 | AO11: =AN11*1.01 -> -299.95131 | ... AQ11: =AP11*1.01 -> -305.98033
C12: PTP | D12: =SUM(D10:D11) -> -54 | E12: =SUM(E10:E11) -> 22 | F12: =SUM(F10:F11) -> -55 | G12: =SUM(G10:G11) -> -175 | H12: =SUM(H10:H11) -> 84 | I12: =SUM(I10:I11) -> 124 | J12: =SUM(J10:J11) -> 49 | K12: =SUM(K10:K11) -> 56 | ... U12: =SUM(U10:U11) -> 249 | Z12: =SUM(Z10:Z11) -> 23 | AA12: =SUM(AA10:AA11) -> 247 | AB12: =SUM(AB10:AB11) -> -247 | AC12: =SUM(AC10:AC11) -> -523 | AD12: =SUM(AD10:AD11) -> -262 | AE12: =SUM(AE10:AE11) -> 313 | AF12: =SUM(AF10:AF11) -> 433 | AG12: =SUM(AG10:AG11) -> 615 | ... AQ12: =SUM(AQ10:AQ11) -> 2237.2597
A13: Gearing | B13: =(B8-B7)/U25 -> 1.1384778 | C13: tax | D13: -2 | E13: -10 | F13: 2 | G13: 25 | H13: -21 | I13: -30 | J13: -18 | K13: -21 | L13: -23 | M13: -32 | N13: -25 | O13: -28 | P13: -29 | Q13: -44 | R13: -30 | S13: -38 | T13: -30 | U13: -53 | Z13: -28 | AA13: -60 | AB13: -69 | AC13: 70 | AD13: =SUM(D13:G13) -> 15 | AE13: =SUM(H13:K13) -> -90 | AF13: =SUM(L13:O13) -> -108 | AG13: -141 | AH13: =AH12*-0.22 -> -176.61863 | AI13: =AI12*-0.22 -> -203.08807 | AJ13: =AJ12*-0.22 -> -231.42341 | AK13: =AK12*-0.22 -> -261.73603 | AL13: =AL12*-0.22 -> -294.14354 | AM13: =AM12*-0.22 -> -328.77005 | AN13: =AN12*-0.22 -> -365.74657 | AO13: =AO12*-0.22 -> -405.21134 | ... AQ13: =AQ12*-0.22 -> -492.19714
C14: Net income | D14: =SUM(D12:D13) -> -56 | E14: =SUM(E12:E13) -> 12 | F14: =SUM(F12:F13) -> -53 | G14: =SUM(G12:G13) -> -150 | H14: =SUM(H12:H13) -> 63 | I14: =SUM(I12:I13) -> 94 | J14: =SUM(J12:J13) -> 31 | K14: =SUM(K12:K13) -> 35 | ... U14: =SUM(U12:U13) -> 196 | Z14: =SUM(Z12:Z13) -> -5 | AA14: =SUM(AA12:AA13) -> 187 | AB14: =SUM(AB12:AB13) -> -316 | AC14: =SUM(AC12:AC13) -> -453 | AD14: =SUM(AD12:AD13) -> -247 | AE14: =SUM(AE12:AE13) -> 223 | AF14: =SUM(AF12:AF13) -> 325 | AG14: =SUM(AG12:AG13) -> 474 | ... AQ14: =SUM(AQ12:AQ13) -> 1745.0626 | AR14: =AQ14*(1+$AT$17) -> 1727.6119 | AS14: =AR14*(1+$AT$17) -> 1710.3358 | AT14: =AS14*(1+$AT$17) -> 1693.2325 | AU14: =AT14*(1+$AT$17) -> 1676.3001 | AV14: =AU14*(1+$AT$17) -> 1659.5371 | AW14: =AV14*(1+$AT$17) -> 1642.9418 | AX14: =AW14*(1+$AT$17) -> 1626.5124 | AY14: =AX14*(1+$AT$17) -> 1610.2472 | ... DU14: =DT14*(1+$AT$17) -> 765.41499
C15: Shares | D15: 204.69459 | E15: 204.69459 | F15: 204.69459 | G15: 204.69459 | H15: 204.69459 | I15: 204.69459 | J15: 204.69459 | K15: 204.69459 | L15: 204.69459 | M15: 204.69459 | N15: 204.46047 | O15: 205.49301 | P15: 204.43395 | Q15: 202.31017 | R15: 202.08393 | S15: 201.05593 | T15: 199.17283 | U15: 195.42422 | Z15: 170 | AA15: 170 | AB15: 204.69459 | AC15: 204.69459 | AD15: 204.69459 | AE15: 204.69459 | AF15: 204.69459 | AG15: 204.69459 | AH15: 204.69459 | AI15: 204.69459 | AJ15: 204.69459 | AK15: 204.69459 | AL15: 204.69459 | AM15: 204.69459 | AN15: 204.69459 | AO15: 204.69459 | AP15: 204.69459 | AQ15: 204.69459
C16: EPS | D16: =D14/D15 -> -0.27357831 | E16: =E14/E15 -> 0.058623924 | F16: =F14/F15 -> -0.25892233 | G16: =G14/G15 -> -0.73279905 | H16: =H14/H15 -> 0.3077756 | I16: =I14/I15 -> 0.45922074 | J16: =J14/J15 -> 0.15144514 | K16: =K14/K15 -> 0.17098645 | ... U16: =U14/U15 -> 1.0029463 | Z16: =Z14/Z15 -> -0.029411765 | AA16: =AA14/AA15 -> 1.1 | AB16: =AB14/AB15 -> -1.5437633 | AC16: =AC14/AC15 -> -2.2130531 | AD16: =AD14/AD15 -> -1.2066758 | AE16: =AE14/AE15 -> 1.0894279 | AF16: =AF14/AF15 -> 1.5877313 | AG16: =AG14/AG15 -> 2.315645 | ... AQ16: =AQ14/AQ15 -> 8.5252013 | AS16: Discount | AT16: 0.08
AS17: TV | AT17: -0.01
C18: Revenue y/y | H18: =(H4-D4)/D4 -> 0.18793274 | I18: =(I4-E4)/E4 -> 0.1741683 | J18: =(J4-F4)/F4 -> 0.14374354 | K18: =(K4-G4)/G4 -> 0.13401109 | L18: =(L4-H4)/H4 -> 0.07743547 | M18: =(M4-I4)/I4 -> 0.055 | N18: =(N4-J4)/J4 -> 0.079566004 | O18: =(O4-K4)/K4 -> 0.068459658 | ... U18: =(U4-Q4)/Q4 -> 0.035175879 | AA18: =(AA4-Z4)/Z4 -> 0.22338141 | AB18: =(AB4-AA4)/AA4 -> -0.11361926 | AC18: =(AC4-AB4)/AB4 -> -0.081211092 | AD18: =(AD4-AC4)/AC4 -> 0.25716046 | AE18: =(AE4-AD4)/AD4 -> 0.15972562 | AF18: =(AF4-AE4)/AE4 -> 0.06991973 | AG18: =(AG4-AF4)/AF4 -> 0.087660415 | AH18: =(AH4-AG4)/AG4 -> 0.06 | ... AQ18: =(AQ4-AP4)/AP4 -> 0.05 | AS18: NPV | AT18: =NPV(AT16,AG14:DU14) -> 15247.751
C19: Revenue Contant currency | U19: 0.07
C20: Gross margin | D20: =D6/D4 -> 0.96241345 | E20: =E6/E4 -> 0.97162427 | F20: =F6/F4 -> 0.96587384 | G20: =G6/G4 -> 0.95656192 | H20: =H6/H4 -> 0.97002498 | I20: =I6/I4 -> 0.97083333 | J20: =J6/J4 -> 0.97197107 | K20: =K6/K4 -> 0.97147514 | ... U20: =U6/U4 -> 0.97434119 | Z20: =Z6/Z4 -> 0.97545259 | AA20: =AA6/AA4 -> 0.97115626 | AB20: =AB6/AB4 -> 0.96547821 | AC20: =AC6/AC4 -> 0.96735448 | AD20: =AD6/AD4 -> 0.96398824 | AE20: =AE6/AE4 -> 0.97106041 | AF20: =AF6/AF4 -> 0.97176703 | AG20: =AG6/AG4 -> 0.97349791 | ... AQ20: =AQ6/AQ4 -> 0.974 | AS20: S/O | AT20: 204.69459
C21: EBIT margin | D21: =D10/D4 -> 0.012858556 | E21: =E10/E4 -> 0.066536204 | F21: =F10/F4 -> 0.0041365047 | G21: =G10/G4 -> -0.060998152 | H21: =H10/H4 -> 0.10491257 | I21: =I10/I4 -> 0.16833333 | J21: =J10/J4 -> 0.14104882 | K21: =K10/K4 -> 0.1002445 | ... U21: =U10/U4 -> 0.22052705 | Z21: =Z10/Z4 -> 0.080699601 | AA21: =AA10/AA4 -> 0.12841736 | AB21: =AB10/AB4 -> 0.0056593096 | AC21: =AC10/AC4 -> -0.069294734 | AD21: =AD10/AD4 -> 0.0046545811 | AE21: =AE10/AE4 -> 0.12822138 | AF21: =AF10/AF4 -> 0.14669299 | AG21: =AG10/AG4 -> 0.16191686 | ... AQ21: =AQ10/AQ4 -> 0.28074047 | AS21: NPV/Share | AT21: =AT18/AT20 -> 74.490252
C22: ROE | Z22: =Z14/761 -> -0.0065703022 | AA22: =AA14/1223 -> 0.1529027 | AB22: =AB14/885 -> -0.35706215 | AC22: =AC14/483 -> -0.9378882 | AD22: =AD14/G55 -> -0.2872093 | AE22: =AE14/K55 -> 0.218842 | AF22: =AF14/O55 -> 0.24181548 | AG22: =AG14/AG55 -> 0.3257732 | AS22: Opp-/nedside | AT22: =(AT21-B4)/B4 -> 0.67770838
C24: EBITDA | D24: 30 | E24: 83 | F24: 20 | G24: 12 | H24: 137 | I24: 194 | J24: 155 | K24: 128 | L24: 174 | M24: 219 | N24: 170 | O24: 175 | P24: 186 | Q24: 269 | R24: 192 | S24: 224 | T24: 217 | U24: 313 | Z24: 573 | AA24: 617 | AB24: 146 | AC24: -170 | AD24: 99 | AE24: 614 | AF24: 738 | AG24: 871
C25: EBITDA LTM | G25: =SUM(D24:G24) -> 145 | H25: =SUM(E24:H24) -> 252 | I25: =SUM(F24:I24) -> 363 | J25: =SUM(G24:J24) -> 498 | K25: =SUM(H24:K24) -> 614 | L25: =SUM(I24:L24) -> 651 | M25: =SUM(J24:M24) -> 676 | N25: =SUM(K24:N24) -> 691 | ... U25: =SUM(R24:U24) -> 946
C26: EBITDA margin | D26: =D24/D4 -> 0.029673591 | E26: =E24/E4 -> 0.081213307 | F26: =F24/F4 -> 0.020682523 | G26: =G24/G4 -> 0.011090573 | H26: =H24/H4 -> 0.11407161 | I26: =I24/I4 -> 0.16166667 | J26: =J24/J4 -> 0.14014467 | K26: =K24/K4 -> 0.10431948 | ... U26: =U24/U4 -> 0.21705964 | Z26: =Z24/Z4 -> 0.1758208 | AA26: =AA24/AA4 -> 0.15475295 | AB26: =AB24/AB4 -> 0.04131296 | AC26: =AC24/AC4 -> -0.052356021 | AD26: =AD24/AD4 -> 0.024252817 | AE26: =AE24/AE4 -> 0.12970004 | AF26: =AF24/AF4 -> 0.14570582 | AG26: =AG24/AG4 -> 0.15810492
C28: Members ('000) | D28: =Segementer!C16+Segementer!C29+Segementer!C42+Segementer!C55 -> 685 | E28: =Segementer!D16+Segementer!D29+Segementer!D42+Segementer!D55 -> 671 | F28: =Segementer!E16+Segementer!E29+Segementer!E42+Segementer!E55 -> 708 | G28: =Segementer!F16+Segementer!F29+Segementer!F42+Segementer!F55 -> 721 | H28: =Segementer!H16+Segementer!H29+Segementer!H42+Segementer!H55 -> 735 | I28: =Segementer!I16+Segementer!I29+Segementer!I42+Segementer!I55 -> 715 | J28: =Segementer!J16+Segementer!J29+Segementer!J42+Segementer!J55 -> 731 | K28: =Segementer!K16+Segementer!K29+Segementer!K42+Segementer!K55 -> 731 | L28: =Segementer!M16+Segementer!M29+Segementer!M42+Segementer!M55 -> 735 | M28: =Segementer!N16+Segementer!N29+Segementer!N42+Segementer!N55 -> 719 | N28: =Segementer!O16+Segementer!O29+Segementer!O42+Segementer!O55 -> 728 | O28: =Segementer!P16+Segementer!P29+Segementer!P42+Segementer!P55 -> 733 | P28: =Segementer!R16+Segementer!R29+Segementer!R42+Segementer!R55 -> 757 | Q28: =Segementer!S16+Segementer!S29+Segementer!S42+Segementer!S55 -> 740 | R28: =Segementer!T16+Segementer!T29+Segementer!T42+Segementer!T55 -> 756 | S28: =Segementer!U16+Segementer!U29+Segementer!U42+Segementer!U55 -> 755 | T28: =Segementer!W16+Segementer!W29+Segementer!W42+Segementer!W55 -> 769 | U28: =Segementer!X16+Segementer!X29+Segementer!X42+Segementer!X55 -> 744 | Z28: 569 | AA28: 687 | AB28: 628 | AC28: 669 | AD28: 721 | AE28: 731 | AF28: 733 | AG28: 755
C29: y/y | H29: =(H28-D28)/D28 -> 0.072992701 | I29: =(I28-E28)/E28 -> 0.06557377 | J29: =(J28-F28)/F28 -> 0.032485876 | K29: =(K28-G28)/G28 -> 0.013869626 | L29: =(L28-H28)/H28 -> 0 | M29: =(M28-I28)/I28 -> 0.0055944056 | N29: =(N28-J28)/J28 -> -0.0041039672 | O29: =(O28-K28)/K28 -> 0.0027359781 | ... U29: =(U28-Q28)/Q28 -> 0.0054054054 | AA29: =(AA28-Z28)/Z28 -> 0.20738137 | AB29: =(AB28-AA28)/AA28 -> -0.08588064 | AC29: =(AC28-AB28)/AB28 -> 0.065286624 | AD29: =(AD28-AC28)/AC28 -> 0.077727952 | AE29: =(AE28-AD28)/AD28 -> 0.013869626 | AF29: =(AF28-AE28)/AE28 -> 0.0027359781 | AG29: =(AG28-AF28)/AF28 -> 0.030013643
C30: Clubs | D30: =Segementer!C15+Segementer!C28+Segementer!C41+Segementer!C54 -> 267 | E30: =Segementer!D15+Segementer!D28+Segementer!D41+Segementer!D54 -> 267 | F30: =Segementer!E15+Segementer!E28+Segementer!E41+Segementer!E54 -> 276 | G30: =Segementer!F15+Segementer!F28+Segementer!F41+Segementer!F54 -> 275 | H30: =Segementer!H15+Segementer!H28+Segementer!H41+Segementer!H54 -> 274 | I30: =Segementer!I15+Segementer!I28+Segementer!I41+Segementer!I54 -> 273 | J30: =Segementer!J15+Segementer!J28+Segementer!J41+Segementer!J54 -> 275 | K30: =Segementer!K15+Segementer!K28+Segementer!K41+Segementer!K54 -> 276 | L30: =Segementer!M15+Segementer!M28+Segementer!M41+Segementer!M54 -> 276 | M30: =Segementer!N15+Segementer!N28+Segementer!N41+Segementer!N54 -> 274 | N30: =Segementer!O15+Segementer!O28+Segementer!O41+Segementer!O54 -> 273 | O30: =Segementer!P15+Segementer!P28+Segementer!P41+Segementer!P54 -> 272 | P30: =Segementer!R15+Segementer!R28+Segementer!R41+Segementer!R54 -> 273 | Q30: =Segementer!S15+Segementer!S28+Segementer!S41+Segementer!S54 -> 273 | R30: =Segementer!T15+Segementer!T28+Segementer!T41+Segementer!T54 -> 274 | S30: =Segementer!U15+Segementer!U28+Segementer!U41+Segementer!U54 -> 273 | T30: =Segementer!W15+Segementer!W28+Segementer!W41+Segementer!W54 -> 272 | U30: =Segementer!X15+Segementer!X28+Segementer!X41+Segementer!X54 -> 270 | Z30: 203 | AA30: 248 | AB30: 253 | AC30: 262 | AD30: 275 | AE30: 276 | AF30: 272 | AG30: 273
C31: y/y | H31: =(H30-D30)/D30 -> 0.026217228 | I31: =(I30-E30)/E30 -> 0.02247191 | J31: =(J30-F30)/F30 -> -0.0036231884 | K31: =(K30-G30)/G30 -> 0.0036363636 | L31: =(L30-H30)/H30 -> 0.0072992701 | M31: =(M30-I30)/I30 -> 0.0036630037 | N31: =(N30-J30)/J30 -> -0.0072727273 | O31: =(O30-K30)/K30 -> -0.014492754 | ... U31: =(U30-Q30)/Q30 -> -0.010989011 | AA31: =(AA30-Z30)/Z30 -> 0.22167488 | AB31: =(AB30-AA30)/AA30 -> 0.02016129 | AC31: =(AC30-AB30)/AB30 -> 0.035573123 | AD31: =(AD30-AC30)/AC30 -> 0.049618321 | AE31: =(AE30-AD30)/AD30 -> 0.0036363636 | AF31: =(AF30-AE30)/AE30 -> -0.014492754 | AG31: =(AG30-AF30)/AF30 -> 0.0036764706
C33: ARPM (NOK/month) | D33: 498 | E33: 502 | F33: 468 | G33: 505 | H33: 550 | I33: 552 | J33: 510 | K33: 559 | L33: 588 | M33: 580 | N33: 550 | O33: 598 | P33: 624 | Q33: 621 | R33: 576 | S33: 630 | T33: 649 | U33: 635 | Z33: 504 | AA33: 523 | AB33: 416 | AC33: 391 | AD33: 515 | AE33: 543 | AF33: 573 | AG33: 608
C34: y/y | H34: =(H33-D33)/D33 -> 0.10441767 | I34: =(I33-E33)/E33 -> 0.099601594 | J34: =(J33-F33)/F33 -> 0.08974359 | K34: =(K33-G33)/G33 -> 0.10693069 | L34: =(L33-H33)/H33 -> 0.069090909 | M34: =(M33-I33)/I33 -> 0.050724638 | N34: =(N33-J33)/J33 -> 0.078431373 | O34: =(O33-K33)/K33 -> 0.069767442 | ... U34: =(U33-Q33)/Q33 -> 0.022544283 | AA34: =(AA33-Z33)/Z33 -> 0.037698413 | AB34: =(AB33-AA33)/AA33 -> -0.20458891 | AC34: =(AC33-AB33)/AB33 -> -0.060096154 | AD34: =(AD33-AC33)/AC33 -> 0.31713555 | AE34: =(AE33-AD33)/AD33 -> 0.054368932 | AF34: =(AF33-AE33)/AE33 -> 0.055248619 | AG34: =(AG33-AF33)/AF33 -> 0.061082024
C36: Balanse NOKm
C37: Intangible assets | D37: 2588 | E37: 2576 | F37: 2615 | G37: 2588 | H37: 2628 | I37: 2660 | J37: 2621 | K37: 2628 | L37: 2654 | M37: 2635 | N37: 2664 | O37: 2661 | P37: 2644 | Q37: 2665 | R37: 2655 | S37: 2667 | T37: 2607 | U37: 2605 | Z37: 2372 | AA37: 2464 | AB37: 2578 | AC37: 2569 | AD37: 2588 | AE37: 2628 | AF37: 2661 | AG37: 2667
C38: Right-of-use assets | D38: 4161 | E38: 4165 | F38: 4179 | G38: 4161 | H38: 4570 | I38: 4452 | J38: 4423 | K38: 4570 | L38: 4680 | M38: 4575 | N38: 4679 | O38: 4657 | P38: 4675 | Q38: 4765 | R38: 4688 | S38: 4769 | T38: 4515 | U38: 4569 | Z38: 3229 | AA38: 3912 | AB38: 4568 | AC38: 4077 | AD38: 4161 | AE38: 4570 | AF38: 4657 | AG38: 4769
C39: PP&E | D39: 723 | E39: 684 | F39: 719 | G39: 723 | H39: 705 | I39: 702 | J39: 674 | K39: 705 | L39: 685 | M39: 649 | N39: 682 | O39: 792 | P39: 800 | Q39: 835 | R39: 859 | S39: 916 | T39: 863 | U39: 875 | Z39: 599 | AA39: 739 | AB39: 758 | AC39: 692 | AD39: 723 | AE39: 705 | AF39: 792 | AG39: 916
C40: other non-current receivables | D40: 50 | E40: 35 | F40: 39 | G40: 50 | H40: 63 | I40: 62 | J40: 64 | K40: 63 | L40: 65 | M40: 63 | N40: 58 | O40: 56 | P40: 53 | Q40: 69 | R40: 69 | S40: 72 | T40: 70 | U40: 80 | Z40: 131 | AA40: 41 | AB40: 38 | AC40: 34 | AD40: 50 | AE40: 63 | AF40: 56 | AG40: 72
C41: Derivate financial instruemtns | D41: 47 | E41: 46 | F41: 54 | G41: 47 | H41: 36 | I41: 66 | J41: 64 | K41: 36 | L41: 42 | M41: 40 | N41: 30 | O41: 33 | P41: 30 | Q41: 22 | R41: 20 | S41: 0 | T41: 0 | U41: 0 | Z41: 3 | AA41: 5 | AB41: 0 | AC41: 1 | AD41: 47 | AE41: 36 | AF41: 33 | AG41: 0
C42: Deferred tax assets | D42: 239 | E42: 213 | F42: 222 | G42: 239 | H42: 178 | I42: 245 | J42: 243 | K42: 178 | L42: 121 | M42: 177 | N42: 181 | O42: 185 | P42: 135 | Q42: 136 | R42: 136 | S42: 141 | T42: 134 | U42: 134 | Z42: 149 | AA42: 192 | AB42: 166 | AC42: 213 | AD42: 239 | AE42: 178 | AF42: 185 | AG42: 141
C43: Inventories | D43: 57 | E43: 65 | F43: 69 | G43: 57 | H43: 55 | I43: 57 | J43: 57 | K43: 55 | L43: 56 | M43: 53 | N43: 55 | O43: 54 | P43: 54 | Q43: 59 | R43: 59 | S43: 61 | T43: 66 | U43: 63 | Z43: 28 | AA43: 41 | AB43: 48 | AC43: 57 | AD43: 57 | AE43: 55 | AF43: 54 | AG43: 61
C44: Accounts receivables | D44: 126 | E44: 92 | F44: 119 | G44: 126 | H44: 136 | I44: 105 | J44: 118 | K44: 136 | L44: 134 | M44: 117 | N44: 136 | O44: 159 | P44: 142 | Q44: 135 | R44: 136 | S44: 161 | T44: 127 | U44: 110 | Z44: 119 | AA44: 136 | AB44: 120 | AC44: 117 | AD44: 126 | AE44: 136 | AF44: 159 | AG44: 161
C45: other current receivables | D45: 54 | E45: 72 | F45: 68 | G45: 54 | H45: 86 | I45: 53 | J45: 69 | K45: 86 | L45: 105 | M45: 80 | N45: 101 | O45: 131 | P45: 122 | Q45: 108 | R45: 88 | S45: 108 | T45: 208 | U45: 175 | Z45: 119 | AA45: 70 | AB45: 85 | AC45: 59 | AD45: 54 | AE45: 86 | AF45: 131 | AG45: 108
C46: Prepaid expenses and accured income | D46: 287 | E46: 231 | F46: 223 | G46: 287 | H46: 237 | I46: 274 | J46: 234 | K46: 237 | L46: 213 | M46: 166 | N46: 171 | O46: 237 | P46: 228 | Q46: 249 | R46: 224 | S46: 214 | T46: 81 | U46: 112 | Z46: 174 | AA46: 222 | AB46: 274 | AC46: 237 | AD46: 287 | AE46: 237 | AF46: 237 | AG46: 214
...

Sheet Segementer
B4: NOKm | C4: Q122 | D4: Q222 | E4: Q322 | F4: Q422 | G4: 2022 | H4: Q123 | I4: Q223 | J4: Q323 | K4: Q423 | L4: 2023 | M4: Q124 | N4: Q224 | O4: Q324 | P4: Q424 | Q4: 2024 | R4: Q125 | S4: Q225 | T4: Q325 | U4: Q425 | V4: 2025 | W4: Q126 | X4: Q226 | Y4: Q326 | Z4: Q426 | AA4: 2026
B5: Norway
B6: Membership revenue | C6: 372 | D6: 379 | E6: 384 | F6: 407 | G6: =SUM(C6:F6) -> 1542 | H6: 445 | I6: 443 | J6: 429 | K6: 446 | L6: =SUM(H6:K6) -> 1763 | M6: 472 | N6: 473 | O6: 459 | P6: 484 | Q6: =SUM(M6:P6) -> 1888 | R6: 552 | S6: 524 | T6: 501 | U6: 525 | V6: =SUM(R6:U6) -> 2102 | W6: 567 | X6: 569 | AA6: =SUM(W6:Z6) -> 1136
B7: Other rev | C7: 110 | D7: 102 | E7: 80 | F7: 105 | G7: =SUM(C7:F7) -> 397 | H7: 111 | I7: 96 | J7: 85 | K7: 96 | L7: =SUM(H7:K7) -> 388 | M7: 103 | N7: 100 | O7: 74 | P7: 100 | Q7: =SUM(M7:P7) -> 377 | R7: 111 | S7: 102 | T7: 81 | U7: 106 | V7: =SUM(R7:U7) -> 400 | W7: 114 | X7: 108 | AA7: =SUM(W7:Z7) -> 222
B8: Total revenue | C8: =SUM(C6:C7) -> 482 | D8: =SUM(D6:D7) -> 481 | E8: =SUM(E6:E7) -> 464 | F8: =SUM(F6:F7) -> 512 | G8: =SUM(C8:F8) -> 1939 | H8: =SUM(H6:H7) -> 556 | I8: =SUM(I6:I7) -> 539 | J8: =SUM(J6:J7) -> 514 | K8: =SUM(K6:K7) -> 542 | L8: =SUM(H8:K8) -> 2151 | M8: =SUM(M6:M7) -> 575 | N8: =SUM(N6:N7) -> 573 | O8: =SUM(O6:O7) -> 533 | P8: =SUM(P6:P7) -> 584 | Q8: =SUM(M8:P8) -> 2265 | R8: =SUM(R6:R7) -> 663 | S8: =SUM(S6:S7) -> 626 | T8: =SUM(T6:T7) -> 582 | U8: =SUM(U6:U7) -> 631 | V8: =SUM(R8:U8) -> 2502 | W8: =SUM(W6:W7) -> 681 | X8: =SUM(X6:X7) -> 677 | Y8: =SUM(Y6:Y7) -> 0 | Z8: =SUM(Z6:Z7) -> 0 | AA8: =SUM(W8:Z8) -> 1358
B9: Growth % | H9: =(H8-C8)/C8 -> 0.15352697 | I9: =(I8-D8)/D8 -> 0.12058212 | J9: =(J8-E8)/E8 -> 0.10775862 | K9: =(K8-F8)/F8 -> 0.05859375 | L9: =(L8-G8)/G8 -> 0.10933471 | M9: =(M8-H8)/H8 -> 0.034172662 | N9: =(N8-I8)/I8 -> 0.063079777 | O9: =(O8-J8)/J8 -> 0.036964981 | ... AA9: =(AA8-V8)/V8 -> -0.45723421
B10: EBITDA | C10: 82 | D10: 114 | E10: 72 | F10: 70 | G10: =SUM(C10:F10) -> 338 | H10: 124 | I10: 160 | J10: 146 | K10: 129 | L10: =SUM(H10:K10) -> 559 | M10: 156 | N10: 185 | O10: 161 | P10: 165 | Q10: =SUM(M10:P10) -> 667 | R10: 180 | S10: 222 | T10: 172 | U10: 184 | V10: =SUM(R10:U10) -> 758 | W10: 198 | X10: 248 | AA10: =SUM(W10:Z10) -> 446
B11: margin % | C11: 0.17 | D11: 0.24 | E11: 0.15 | F11: 0.14 | G11: =G10/G8 -> 0.17431666 | H11: 0.22 | I11: 0.3 | J11: 0.28 | K11: 0.24 | L11: =L10/L8 -> 0.25987913 | M11: 0.27 | N11: 0.32 | O11: 0.3 | P11: 0.28 | Q11: =Q10/Q8 -> 0.29448124 | R11: 0.29 | S11: 0.35 | T11: 0.3 | U11: 0.29 | V11: =V10/V8 -> 0.30295763 | W11: 0.29 | X11: 0.37 | AA11: =AA10/AA8 -> 0.32842415
B12: Operating profit | C12: 40 | D12: 74 | E12: 31 | F12: -9 | G12: =SUM(C12:F12) -> 136 | H12: 89 | I12: 140 | J12: 117 | K12: 91 | L12: =SUM(H12:K12) -> 437 | M12: 119 | N12: 157 | O12: 131 | P12: 131 | Q12: =SUM(M12:P12) -> 538 | R12: 145 | S12: 189 | T12: 137 | U12: 148 | V12: =SUM(R12:U12) -> 619 | W12: 160 | X12: 213 | AA12: =SUM(W12:Z12) -> 373
B13: Operating profit % | C13: =C12/C6 -> 0.10752688 | D13: =D12/D6 -> 0.19525066 | E13: =E12/E6 -> 0.080729167 | F13: =F12/F6 -> -0.022113022 | G13: =G12/G6 -> 0.088197147 | H13: =H12/H6 -> 0.2 | I13: =I12/I6 -> 0.31602709 | J13: =J12/J6 -> 0.27272727 | ... Z13: =Z12/Z6 -> #DIV/0!
B14: Net income | C14: 12 | D14: 38 | E14: 5 | F14: -29 | G14: =SUM(C14:F14) -> 26 | H14: 50 | I14: 91 | J14: 74 | K14: 85 | L14: =SUM(H14:K14) -> 300 | M14: 76 | N14: 108 | O14: 84 | P14: 108 | Q14: =SUM(M14:P14) -> 376 | R14: 97 | S14: 131 | T14: 92 | U14: 93 | V14: =SUM(R14:U14) -> 413 | W14: 130 | X14: 157 | AA14: =SUM(W14:Z14) -> 287
B15: Clubs | C15: 115 | D15: 115 | E15: 122 | F15: 122 | H15: 121 | I15: 118 | J15: 119 | K15: 119 | M15: 118 | N15: 117 | O15: 117 | P15: 117 | R15: 118 | S15: 119 | T15: 119 | U15: 120 | W15: 119 | X15: 118
B16: members ('000) | C16: 310 | D16: 302 | E16: 322 | F16: 325 | H16: 330 | I16: 319 | J16: 326 | K16: 326 | M16: 331 | N16: 324 | O16: 329 | P16: 332 | R16: 346 | S16: 339 | T16: 347 | U16: 345 | W16: 351 | X16: 341
B17: ARPM (NOK/month) | C17: 525 | D17: 524 | E17: 496 | F17: 528 | H17: 566 | I17: 554 | J17: 531 | K17: 555 | M17: 583 | N17: 583 | O17: 544 | P17: 589 | R17: 622 | S17: 609 | T17: 566 | U17: 607 | W17: 653 | X17: 652
B18: Sweden
B19: Membership revenue | C19: 269 | D19: 272 | E19: 264 | F19: 282 | G19: =SUM(C19:F19) -> 1087 | H19: 315 | I19: 326 | J19: 303 | K19: 337 | L19: =SUM(H19:K19) -> 1281 | M19: 348 | N19: 346 | O19: 344 | P19: 359 | Q19: =SUM(M19:P19) -> 1397 | R19: 377 | S19: 390 | T19: 374 | U19: 399 | V19: =SUM(R19:U19) -> 1540 | W19: 410 | X19: 394 | AA19: =SUM(W19:Z19) -> 804
B20: Other rev | C20: 78 | D20: 78 | E20: 55 | F20: 78 | G20: =SUM(C20:F20) -> 289 | H20: 85 | I20: 83 | J20: 63 | K20: 85 | L20: =SUM(H20:K20) -> 316 | M20: 85 | N20: 80 | O20: 60 | P20: 86 | Q20: =SUM(M20:P20) -> 311 | R20: 92 | S20: 93 | T20: 70 | U20: 101 | V20: =SUM(R20:U20) -> 356 | W20: 98 | X20: 96 | AA20: =SUM(W20:Z20) -> 194
B21: Total revenue | C21: =SUM(C19:C20) -> 347 | D21: =SUM(D19:D20) -> 350 | E21: =SUM(E19:E20) -> 319 | F21: =SUM(F19:F20) -> 360 | G21: =SUM(C21:F21) -> 1376 | H21: =SUM(H19:H20) -> 400 | I21: =SUM(I19:I20) -> 409 | J21: =SUM(J19:J20) -> 366 | K21: =SUM(K19:K20) -> 422 | L21: =SUM(H21:K21) -> 1597 | M21: =SUM(M19:M20) -> 433 | N21: =SUM(N19:N20) -> 426 | O21: 404 | P21: =SUM(P19:P20) -> 445 | Q21: =SUM(M21:P21) -> 1708 | R21: =SUM(R19:R20) -> 469 | S21: =SUM(S19:S20) -> 483 | T21: =SUM(T19:T20) -> 444 | U21: =SUM(U19:U20) -> 500 | V21: =SUM(R21:U21) -> 1896 | W21: =SUM(W19:W20) -> 508 | X21: =SUM(X19:X20) -> 490 | Y21: =SUM(Y19:Y20) -> 0 | Z21: =SUM(Z19:Z20) -> 0 | AA21: =SUM(W21:Z21) -> 998
B22: Growth % | H22: =(H21-C21)/C21 -> 0.15273775 | I22: =(I21-D21)/D21 -> 0.16857143 | J22: =(J21-E21)/E21 -> 0.14733542 | K22: =(K21-F21)/F21 -> 0.17222222 | L22: =(L21-G21)/G21 -> 0.16061047 | M22: =(M21-H21)/H21 -> 0.0825 | N22: =(N21-I21)/I21 -> 0.041564792 | O22: =(O21-J21)/J21 -> 0.10382514 | ... AA22: =(AA21-V21)/V21 -> -0.47362869
B23: EBITDA | C23: 51 | D23: 58 | E23: 46 | F23: 37 | G23: =SUM(C23:F23) -> 192 | H23: 81 | I23: 83 | J23: 83 | K23: 83 | L23: =SUM(H23:K23) -> 330 | M23: 72 | N23: 81 | O23: 75 | P23: 74 | Q23: =SUM(M23:P23) -> 302 | R23: 74 | S23: 99 | T23: 89 | U23: 92 | V23: =SUM(R23:U23) -> 354 | W23: 82 | X23: 120 | AA23: =SUM(W23:Z23) -> 202
B24: margin % | C24: 0.15 | D24: 0.16 | E24: 0.14 | F24: 0.1 | G24: =G23/G21 -> 0.13953488 | H24: 0.2 | I24: 0.2 | J24: 0.23 | K24: 0.2 | L24: =L23/L21 -> 0.20663745 | M24: 0.17 | N24: 0.19 | O24: 0.19 | P24: 0.17 | Q24: =Q23/Q21 -> 0.17681499 | R24: 0.16 | S24: 0.2 | T24: 0.2 | U24: 0.18 | V24: =V23/V21 -> 0.18670886 | W24: 0.16 | X24: 0.25 | AA24: =AA23/AA21 -> 0.20240481
B25: Operating profit | C25: 9 | D25: 18 | E25: 6 | F25: -22 | G25: =SUM(C25:F25) -> 11 | H25: 45 | I25: 56 | J25: 49 | K25: 44 | L25: =SUM(H25:K25) -> 194 | M25: 39 | N25: 51 | O25: 43 | P25: 38 | Q25: =SUM(M25:P25) -> 171 | R25: 42 | S25: 68 | T25: 56 | U25: 56 | V25: =SUM(R25:U25) -> 222 | W25: 44 | X25: 86 | AA25: =SUM(W25:Z25) -> 130
B26: Operating profit % | C26: =C25/C19 -> 0.033457249 | D26: =D25/D19 -> 0.066176471 | E26: =E25/E19 -> 0.022727273 | F26: =F25/F19 -> -0.078014184 | G26: =G25/G19 -> 0.010119595 | H26: =H25/H19 -> 0.14285714 | I26: =I25/I19 -> 0.17177914 | J26: =J25/J19 -> 0.16171617 | ... Z26: =Z25/Z19 -> #DIV/0!
B27: Net income | C27: -2 | D27: -1 | E27: -6 | F27: -32 | G27: =SUM(C27:F27) -> -41 | H27: 24 | I27: 25 | J27: 23 | K27: 23 | L27: =SUM(H27:K27) -> 95 | M27: 13 | N27: 20 | O27: 20 | P27: 4 | Q27: =SUM(M27:P27) -> 57 | R27: 18 | S27: 34 | T27: 21 | U27: 32 | V27: =SUM(R27:U27) -> 105 | W27: -9 | X27: 45 | AA27: =SUM(W27:Z27) -> 36
B28: Clubs | C28: 90 | D28: 92 | E28: 94 | F28: 92 | H28: 92 | I28: 94 | J28: 95 | K28: 95 | M28: 96 | N28: 96 | O28: 96 | P28: 95 | R28: 95 | S28: 95 | T28: 95 | U28: 93 | W28: 93 | X28: 92
B29: members ('000) | C29: 231 | D29: 228 | E29: 238 | F29: 244 | H29: 249 | I29: 245 | J29: 250 | K29: 249 | M29: 248 | N29: 244 | O29: 246 | P29: 248 | R29: 254 | S29: 250 | T29: 256 | U29: 256 | W29: 262 | X29: 254
B30: ARPM (NOK/month) | C30: 503 | D30: 508 | E30: 457 | F30: 499 | H30: 541 | I30: 552 | J30: 492 | K30: 564 | M30: 581 | N30: 578 | O30: 550 | P30: 600 | R30: 623 | S30: 641 | T30: 585 | U30: 651 | W30: 654 | X30: 634
B31: Finland
B32: Membership revenue | C32: 53 | D32: 73 | E32: 72 | F32: 83 | G32: =SUM(C32:F32) -> 281 | H32: 94 | I32: 100 | J32: 93 | K32: 102 | L32: =SUM(H32:K32) -> 389 | M32: 105 | N32: 106 | O32: 101 | P32: 110 | Q32: =SUM(M32:P32) -> 422 | R32: 109 | S32: 108 | T32: 103 | U32: 113 | V32: =SUM(R32:U32) -> 433 | W32: 113 | X32: 107 | AA32: =SUM(W32:Z32) -> 220
B33: Other rev | C33: 31 | D33: 18 | E33: 14 | F33: 18 | G33: =SUM(C33:F33) -> 81 | H33: 23 | I33: 19 | J33: 15 | K33: 19 | L33: =SUM(H33:K33) -> 76 | M33: 21 | N33: 19 | O33: 17 | P33: 22 | Q33: =SUM(M33:P33) -> 79 | R33: 24 | S33: 21 | T33: 18 | U33: 22 | V33: =SUM(R33:U33) -> 85 | W33: 23 | X33: 22 | AA33: =SUM(W33:Z33) -> 45
B34: Total revenue | C34: 83 | D34: 91 | E34: 86 | F34: 101 | G34: =SUM(C34:F34) -> 361 | H34: 117 | I34: 119 | J34: 109 | K34: 121 | L34: =SUM(H34:K34) -> 466 | M34: 126 | N34: 125 | O34: =SUM(O32:O33) -> 118 | P34: =SUM(P32:P33) -> 132 | Q34: =SUM(M34:P34) -> 501 | R34: =SUM(R32:R33) -> 133 | S34: =SUM(S32:S33) -> 129 | T34: =SUM(T32:T33) -> 121 | U34: =SUM(U32:U33) -> 135 | V34: =SUM(R34:U34) -> 518 | W34: =SUM(W32:W33) -> 136 | X34: =SUM(X32:X33) -> 129 | Y34: =SUM(Y32:Y33) -> 0 | Z34: =SUM(Z32:Z33) -> 0 | AA34: =SUM(W34:Z34) -> 265
B35: Growth % | H35: =(H34-C34)/C34 -> 0.40963855 | I35: =(I34-D34)/D34 -> 0.30769231 | J35: =(J34-E34)/E34 -> 0.26744186 | K35: =(K34-F34)/F34 -> 0.1980198 | L35: =(L34-G34)/G34 -> 0.29085873 | M35: =(M34-H34)/H34 -> 0.076923077 | N35: =(N34-I34)/I34 -> 0.050420168 | O35: =(O34-J34)/J34 -> 0.082568807 | ... AA35: =(AA34-V34)/V34 -> -0.48841699
B36: EBITDA | C36: -3 | D36: 2 | E36: -1 | F36: 4 | G36: =SUM(C36:F36) -> 2 | H36: 15 | I36: 16 | J36: 16 | K36: 2 | L36: =SUM(H36:K36) -> 49 | M36: 9 | N36: 15 | O36: 11 | P36: 17 | Q36: =SUM(M36:P36) -> 52 | R36: 11 | S36: 19 | T36: 12 | U36: 16 | V36: =SUM(R36:U36) -> 58 | W36: 11 | X36: 19 | AA36: =SUM(W36:Z36) -> 30
B37: margin % | C37: -0.03 | D37: 0.02 | E37: -0.02 | F37: 0.03 | G37: =G36/G34 -> 0.0055401662 | H37: 0.13 | I37: 0.13 | J37: 0.14 | K37: 0.02 | L37: =L36/L34 -> 0.10515021 | M37: 0.07 | N37: 0.12 | O37: 0.09 | P37: 0.13 | Q37: =Q36/Q34 -> 0.10379242 | R37: 0.08 | S37: 0.15 | T37: 0.1 | U37: 0.12 | V37: =V36/V34 -> 0.11196911 | W37: 0.08 | X37: 0.15 | AA37: =AA36/AA34 -> 0.11320755
B38: Operating profit | C38: -9 | D38: -4 | E38: -7 | F38: -2 | G38: =SUM(C38:F38) -> -22 | H38: 10 | I38: 11 | J38: 11 | K38: -5 | L38: =SUM(H38:K38) -> 27 | M38: 4 | N38: 11 | O38: 2 | P38: 12 | Q38: =SUM(M38:P38) -> 29 | R38: 6 | S38: 16 | T38: 7 | U38: 11 | V38: =SUM(R38:U38) -> 40 | W38: 5 | X38: 14 | AA38: =SUM(W38:Z38) -> 19
B39: Operating profit % | C39: =C38/C32 -> -0.16981132 | D39: =D38/D32 -> -0.054794521 | E39: =E38/E32 -> -0.097222222 | F39: =F38/F32 -> -0.024096386 | G39: =G38/G32 -> -0.078291815 | H39: =H38/H32 -> 0.10638298 | I39: =I38/I32 -> 0.11 | J39: =J38/J32 -> 0.11827957 | ... Z39: =Z38/Z32 -> #DIV/0!
B40: Net income | C40: -14 | D40: -10 | E40: -12 | F40: -7 | G40: =SUM(C40:F40) -> -43 | H40: 4 | I40: 5 | J40: 5 | K40: -11 | L40: =SUM(H40:K40) -> 3 | M40: -2 | N40: 5 | O40: -4 | P40: 5 | Q40: =SUM(M40:P40) -> 4 | R40: 0 | S40: 9 | T40: 1 | U40: 4 | V40: =SUM(R40:U40) -> 14 | W40: -1 | X40: 8 | AA40: =SUM(W40:Z40) -> 7
B41: Clubs | C41: 32 | D41: 31 | E41: 31 | F41: 32 | H41: 32 | I41: 32 | J41: 32 | K41: 33 | M41: 33 | N41: 32 | O41: 31 | P41: 31 | R41: 31 | S41: 31 | T41: 32 | U41: 32 | W41: 32 | X41: 32
B42: members ('000) | C42: 64 | D42: 63 | E42: 67 | F42: 70 | H42: 72 | I42: 70 | J42: 71 | K42: 71 | M42: 72 | N42: 70 | O42: 70 | P42: 71 | R42: 71 | S42: 69 | T42: 71 | U42: 71 | W42: 72 | X42: 70
B43: ARPM (NOK/month) | C43: 431 | D43: 474 | E43: 439 | F43: 490 | H43: 553 | I43: 560 | J43: 515 | K43: 570 | M43: 586 | N43: 584 | O43: 560 | P43: 623 | R43: 626 | S43: 611 | T43: 575 | U43: 634 | W43: 635 | X43: 606
...

Sheet SOTP
A2: EBIT 26E
A3: =Modell!AH10 -> 1082.582
C5: NOKm | D5: EBIT | E5: EV/EBIT | F5: Value | G5: NOK/Share
C6: Norge | D6: 740 | E6: 13 | F6: =D6*E6 -> 9620 | G6: =F6/Modell!$B$5 -> 46.996846
C7: Sverige | D7: 260 | E7: 10 | F7: =D7*E7 -> 2600 | G7: =F7/Modell!$B$5 -> 12.70185
C8: Finland | D8: 38 | E8: 5 | F8: =D8*E8 -> 190 | G8: =F8/Modell!$B$5 -> 0.92821213
C9: Danmark | D9: 46 | E9: 5 | F9: =D9*E9 -> 230 | G9: =F9/Modell!$B$5 -> 1.1236252
C10: Enterprise value | D10: =SUM(D6:D9) -> 1084 | F10: =SUM(F6:F9) -> 12640 | G10: =SUM(G6:G9) -> 61.750533
C12: Cash | F12: =Modell!B7 -> 326 | G12: =F12/Modell!$B$5 -> 1.5926166
C13: Debt | F13: =Modell!B8 -> 1403 | G13: =-F13/Modell!$B$5 -> -6.8541138
C15: Equity value | F15: =F10+F12-F13 -> 11563 | G15: =SUM(G10:G13) -> 56.489036

Sheet Nøkkeltall
F5: 2026 | G5: 2027 | H5: 2028
E6: EV/EBIT | F6: =Modell!$B$9/Modell!AH10 -> 9.3899955 | G6: =Modell!$B$9/Modell!AI10 -> 8.4311846 | H6: =Modell!$B$9/Modell!AJ10 -> 7.6013634
E7: P/E | F7: =Modell!$B$4/Modell!AH16 -> 14.513792 | G7: =Modell!$B$4/Modell!AI16 -> 12.62214 | H7: =Modell!$B$4/Modell!AJ16 -> 11.076693

Sheet Nedsideberegning
A3: Nedside | D3: FY 2018 | E3: FY 2019 | F3: FY 2020 | G3: FY 2021 | H3: FY 2022 | I3: FY 2023 | J3: FY 2024 | K3: FY 2025 | L3: FY 2026 | M3: FY 2027 | N3: FY 2028 | O3: FY 2029 | P3: FY 2030 | Q3: FY 2031 | R3: FY 2032 | S3: FY 2033 | T3: FY 2034 | U3: FY 2035
A4: Nullvekst og konstante marginer | C4: Revenue | D4: 3259 | E4: 3987 | F4: 3534 | G4: 3247 | H4: 4082 | I4: 4734 | J4: 5065 | K4: =J4*1.1 -> 5571.5 | L4: =K4*1 -> 5571.5 | M4: =L4*1 -> 5571.5 | N4: =M4*1 -> 5571.5 | O4: =N4*1 -> 5571.5 | P4: =O4*1 -> 5571.5 | Q4: =P4*1 -> 5571.5 | R4: =Q4*1 -> 5571.5 | S4: =R4*1 -> 5571.5 | ... U4: =T4*1 -> 5571.5
A5: =X20 -> 23.753413 | C5: COGS | D5: -80 | E5: -115 | F5: -122 | G5: -106 | H5: -147 | I5: -137 | J5: -143 | K5: =J5*1.03 -> -147.29 | L5: =K5*1.03 -> -151.7087 | M5: =L5*1.03 -> -156.25996 | N5: =M5*1.03 -> -160.94776 | O5: =N5*1.03 -> -165.77619 | P5: =O5*1.03 -> -170.74948 | Q5: =P5*1.03 -> -175.87196 | R5: =Q5*1.03 -> -181.14812 | ... U5: =T5*1.03 -> -197.94544
A6: =X21 -> -0.46501323 | C6: Gross profit | D6: =D4+D5 -> 3179 | E6: =E4+E5 -> 3872 | F6: =F4+F5 -> 3412 | G6: =G4+G5 -> 3141 | H6: =SUM(H4:H5) -> 3935 | I6: =I4+I5 -> 4597 | J6: =J4+J5 -> 4922 | K6: =K4+K5 -> 5424.21 | L6: =L4+L5 -> 5419.7913 | M6: =M4+M5 -> 5415.24 | N6: =N4+N5 -> 5410.5522 | O6: =O4+O5 -> 5405.7238 | P6: =P4+P5 -> 5400.7505 | ... U6: =U4+U5 -> 5373.5546
C7: Personel expenses | D7: -1224 | E7: -1463 | F7: -1352 | G7: -1399 | H7: -1588 | I7: -1677 | J7: -1861 | K7: =J7*1.08 -> -2009.88 | L7: =K7*1.01 -> -2029.9788 | M7: =L7*1 -> -2029.9788 | N7: =M7*1 -> -2029.9788 | O7: =N7*1 -> -2029.9788 | P7: =O7*1 -> -2029.9788 | Q7: =P7*1 -> -2029.9788 | R7: =Q7*1 -> -2029.9788 | S7: =R7*1 -> -2029.9788 | T7: =S7*1 -> -2029.9788 | U7: =T7*1 -> -2029.9788
C8: Other opex | D8: -688 | E8: -925 | F8: -925 | G8: -925 | H8: -1207 | I8: -1135 | J8: -1120 | K8: =J8*1.07 -> -1198.4 | L8: =K8*1.01 -> -1210.384 | M8: =L8*1 -> -1210.384 | N8: =M8*1 -> -1210.384 | O8: =N8*1 -> -1210.384 | P8: =O8*1 -> -1210.384 | Q8: =P8*1 -> -1210.384 | R8: =Q8*1 -> -1210.384 | S8: =R8*1 -> -1210.384 | T8: =S8*1 -> -1210.384 | U8: =T8*1 -> -1210.384
C9: D/A | D9: =-739-265 -> -1004 | E9: -972 | F9: =-1045-70 -> -1115 | G9: -1042 | H9: -1121 | I9: -1178 | J9: -1198 | K9: =J9*1.07 -> -1281.86 | L9: =K9*1.01 -> -1294.6786 | M9: =L9*1 -> -1294.6786 | N9: =M9*1 -> -1294.6786 | O9: =N9*1 -> -1294.6786 | P9: =O9*1 -> -1294.6786 | Q9: =P9*1 -> -1294.6786 | R9: =Q9*1 -> -1294.6786 | S9: =R9*1 -> -1294.6786 | T9: =S9*1 -> -1294.6786 | U9: =T9*1 -> -1294.6786
C10: Operating profit (EBIT) | D10: =SUM(D6:D9) -> 263 | E10: =SUM(E6:E9) -> 512 | F10: =SUM(F6:F9) -> 20 | G10: =SUM(G6:G9) -> -225 | H10: =SUM(H6:H9) -> 19 | I10: =SUM(I6:I9) -> 607 | J10: =SUM(J6:J9) -> 743 | K10: =SUM(K6:K9) -> 934.07 | ... U10: =SUM(U6:U9) -> 838.51316
C11: Net financials | D11: -240 | E11: -265 | F11: -267 | G11: -298 | H11: -281 | I11: -294 | J11: -310 | K11: =J11*1.01 -> -313.1 | L11: =K11*1.01 -> -316.231 | M11: =L11*1.01 -> -319.39331 | N11: =M11*1.01 -> -322.58724 | O11: =N11*1.01 -> -325.81312 | P11: =O11*1.01 -> -329.07125 | Q11: =P11*1.01 -> -332.36196 | R11: =Q11*1.01 -> -335.68558 | ... U11: =T11*1.01 -> -345.85719
C12: PTP | D12: =SUM(D10:D11) -> 23 | E12: =SUM(E10:E11) -> 247 | F12: =SUM(F10:F11) -> -247 | G12: =SUM(G10:G11) -> -523 | H12: =SUM(H10:H11) -> -262 | I12: =SUM(I10:I11) -> 313 | J12: =SUM(J10:J11) -> 433 | K12: =SUM(K10:K11) -> 620.97 | ... U12: =SUM(U10:U11) -> 492.65597
C13: tax | D13: -28 | E13: -60 | F13: -69 | G13: 70 | H13: 15 | I13: -90 | J13: -108 | K13: =K12*-0.22 -> -136.6134 | L13: =L12*-0.22 -> -125.07416 | M13: =M12*-0.22 -> -123.37717 | N13: =N12*-0.22 -> -121.64319 | O13: =O12*-0.22 -> -119.87124 | P13: =P12*-0.22 -> -118.06033 | Q13: =Q12*-0.22 -> -116.20943 | R13: =R12*-0.22 -> -114.31748 | ... U13: =U12*-0.22 -> -108.38431
C14: Net income | D14: =SUM(D12:D13) -> -5 | E14: =SUM(E12:E13) -> 187 | F14: =SUM(F12:F13) -> -316 | G14: =SUM(G12:G13) -> -453 | H14: =SUM(H12:H13) -> -247 | I14: =SUM(I12:I13) -> 223 | J14: =SUM(J12:J13) -> 325 | K14: =SUM(K12:K13) -> 484.3566 | ... U14: =SUM(U12:U13) -> 384.27166 | V14: =U14*(1+$X$17) -> 380.42894 | W14: =V14*(1+$X$17) -> 376.62465 | X14: =W14*(1+$X$17) -> 372.8584 | Y14: =X14*(1+$X$17) -> 369.12982 | Z14: =Y14*(1+$X$17) -> 365.43852 | AA14: =Z14*(1+$X$17) -> 361.78414 | AB14: =AA14*(1+$X$17) -> 358.16629 | AC14: =AB14*(1+$X$17) -> 354.58463 | ... CY14: =CX14*(1+$X$17) -> 168.54827
C15: Shares | D15: 170 | E15: 170 | F15: 204.69459 | G15: 204.69459 | H15: 204.69459 | I15: 204.69459 | J15: 204.69459 | K15: 204.69459 | L15: 204.69459 | M15: 204.69459 | N15: 204.69459 | O15: 204.69459 | P15: 204.69459 | Q15: 204.69459 | R15: 204.69459 | S15: 204.69459 | T15: 204.69459 | U15: 204.69459
C16: EPS | D16: =D14/D15 -> -0.029411765 | E16: =E14/E15 -> 1.1 | F16: =F14/F15 -> -1.5437633 | G16: =G14/G15 -> -2.2130531 | H16: =H14/H15 -> -1.2066758 | I16: =I14/I15 -> 1.0894279 | J16: =J14/J15 -> 1.5877313 | K16: =K14/K15 -> 2.3662404 | ... U16: =U14/U15 -> 1.8772927 | W16: Discount | X16: 0.08
W17: TV | X17: -0.01
C18: Revenue y/y | E18: =(E4-D4)/D4 -> 0.22338141 | F18: =(F4-E4)/E4 -> -0.11361926 | G18: =(G4-F4)/F4 -> -0.081211092 | H18: =(H4-G4)/G4 -> 0.25716046 | I18: =(I4-H4)/H4 -> 0.15972562 | J18: =(J4-I4)/I4 -> 0.06991973 | K18: =(K4-J4)/J4 -> 0.1 | L18: =(L4-K4)/K4 -> 0 | ... U18: =(U4-T4)/T4 -> 0 | W18: NPV | X18: =NPV(X16,K14:CY14) -> 4862.195
C19: Gross margin | D19: =D6/D4 -> 0.97545259 | E19: =E6/E4 -> 0.97115626 | F19: =F6/F4 -> 0.96547821 | G19: =G6/G4 -> 0.96735448 | H19: =H6/H4 -> 0.96398824 | I19: =I6/I4 -> 0.97106041 | J19: =J6/J4 -> 0.97176703 | K19: =K6/K4 -> 0.97356367 | ... U19: =U6/U4 -> 0.96447179 | W19: S/O | X19: 204.69459
C20: EBIT margin | D20: =D10/D4 -> 0.080699601 | E20: =E10/E4 -> 0.12841736 | F20: =F10/F4 -> 0.0056593096 | G20: =G10/G4 -> -0.069294734 | H20: =H10/H4 -> 0.0046545811 | I20: =I10/I4 -> 0.12822138 | J20: =J10/J4 -> 0.14669299 | K20: =K10/K4 -> 0.16765144 | ... U20: =U10/U4 -> 0.15050043 | W20: NPV/Share | X20: =X18/X19 -> 23.753413
W21: Opp-/nedside | X21: =(X20-Modell!B4)/Modell!B4 -> -0.46501323
