Workbook

Sheet Info
A2: Scandic er store i Sverige, Norge og Finland. De har også et segment som heter other Europe. Dette innebærer Danmark, Tyskland og Polen.
A4: Sesongvariasjoner: Q1, påsken og julen er ofte trege tider på året
A6: "Scandic's operating model"
A7: Scandic operer primært med langtidsleieavtaler og har fullt ansavr for merkevare, drift og distribusjon.
A9: Scandic strukurerer sine leieavtaler ulike avtaler.
A10: "Contingent rent" = rommene har fullt variable avtaler som er basert på omsetning
A11: "Contingent rent with fixed minimum" = Rommene har varaible leieavtaler med et fast minimum
A12: "Fixed rent" = Rommene er under faste leieavtaler
E14: (Q226)
G25: Denne grafen viser hvor mange rom Scandic har under leieavtale
G26: og hvor lenge disse avtalene varer (gjenværende leietid).
A42: Press releases:
A43: 06.07.26: Scandic sikrer ny finansiering på 7,5 SEKmrd som skal bidra til Dalata carve out. Avtalen går 3 år med opsjon om 2 nye år
A44: 25.06.26: Scandic utvider sitt GO til Finland
A45: 03.03.26: Scandic lanserer GO i Norge
A46: 07.11.25: Scandic tar over ansvaret for Dalata sine hotel som resultat av carve-iut fra Dalata. Hotellene drives i Irland og SB. Før de kjøper hotellene får de 4% av overskuddet. De vil kjøpe hotellene for 500 EURm EV/EBITDA 6. Forventer ferdigstillelse i H226
A47: 15.07.25: Scandic har inngått avtale med Pandox/Eiendomsspar om å kjøpe hotelldelen av Dalata. Transaksjonen legger til 12 000 rom og 56 nye hoteller og Scandic sin inntreden til UK markedet
A52: 09.12.24: Scandic initierer tilbakekjøpsprogram på 300 SEKm som ble fullført 01.04.25

Sheet Modell
A3: Kapitalstruktur | C3: SEK million | D3: Q122 | E3: Q222 | F3: Q322 | G3: Q422 | H3: Q123 | I3: Q223 | J3: Q323 | K3: Q423 | L3: Q124 | M3: Q224 | N3: Q324 | O3: Q424 | P3: Q125 | Q3: Q225 | R3: Q325 | S3: Q425 | T3: Q126 | U3: Q226 | V3: Q326 | W3: Q426 | Z3: FY 2015 | AA3: FY 2016 | AB3: FY 2017 | AC3: FY 2018 | AD3: FY 2019 | AE3: FY 2020 | AF3: FY 2021 | AG3: FY 2022 | AH3: FY 2023 | AI3: FY 2024 | AJ3: FY 2025 | AK3: FY 2026 | AL3: FY 2027 | AM3: FY 2028 | AN3: FY 2029 | AO3: FY 2030 | AP3: FY 2031 | AQ3: FY 2032 | AR3: FY 2033 | AS3: FY 2034 | AT3: FY 2035
A4: Price | B4: 87.5 | C4: Net sales | D4: 2733 | E4: 5276 | F4: 5994 | G4: 5228 | H4: 4526 | I4: 5693 | J4: 6307 | K4: 5410 | L4: 4419 | M4: 5871 | N4: 6182 | O4: 5487 | P4: 4546 | Q4: 5795 | R4: 6372 | S4: 5575 | T4: 4689 | U4: 5998 | AD4: 18945 | AE4: 7470 | AF4: 10086 | AG4: 19230 | AH4: 21935 | AI4: 21959 | AJ4: 22288 | AK4: =AJ4*1.04 -> 23179.52 | AL4: =AK4*1.04+8000 -> 32106.701 | AM4: =AL4*1.055 -> 33872.569 | AN4: =AM4*1.055 -> 35735.561 | AO4: =AN4*1.055 -> 37701.016 | AP4: =AO4*1.055 -> 39774.572 | AQ4: =AP4*1.055 -> 41962.174 | AR4: =AQ4*1.055 -> 44270.093 | AS4: =AR4*1.055 -> 46704.949 | AT4: =AS4*1.055 -> 49273.721
A5: S/O | B5: 216.58652 | C5: Other income | D5: 0 | E5: 3 | F5: 0 | G5: 0 | H5: 0 | I5: 0 | J5: 20 | K5: 0 | L5: 0 | M5: 0 | N5: 0 | O5: 0 | P5: 0 | Q5: 0 | R5: 0 | S5: 0 | T5: 0 | U5: 0 | AD5: 0 | AE5: 0 | AF5: 44 | AG5: 3 | AH5: 20 | AI5: 0 | AJ5: 0 | AK5: 0 | AL5: 0 | AM5: 0 | AN5: 0 | AO5: 0 | AP5: 0 | AQ5: 0 | AR5: 0 | AS5: 0 | AT5: 0
A6: MC NOKm | B6: =B4*B5 -> 18951.321 | C6: Total income | D6: =SUM(D4:D5) -> 2733 | E6: =SUM(E4:E5) -> 5279 | F6: =SUM(F4:F5) -> 5994 | G6: =SUM(G4:G5) -> 5228 | H6: =SUM(H4:H5) -> 4526 | I6: =SUM(I4:I5) -> 5693 | J6: =SUM(J4:J5) -> 6327 | K6: =SUM(K4:K5) -> 5410 | ... U6: =SUM(U4:U5) -> 5998 | Z6: 12208 | AA6: 13095 | AB6: 14583 | AC6: 18007 | AD6: =SUM(AD4:AD5) -> 18945 | AE6: =SUM(AE4:AE5) -> 7470 | AF6: =SUM(AF4:AF5) -> 10130 | AG6: =SUM(AG4:AG5) -> 19233 | AH6: =SUM(AH4:AH5) -> 21955 | AI6: =SUM(AI4:AI5) -> 21959 | AJ6: =SUM(AJ4:AJ5) -> 22288 | AK6: =SUM(AK4:AK5) -> 23179.52 | ... AT6: =SUM(AT4:AT5) -> 49273.721
A7: Cash NOKm | B7: =U49 -> 719 | C7: Raw materials and consumables | D7: -214 | E7: -392 | F7: -449 | G7: -440 | H7: -362 | I7: -426 | J7: -472 | K7: -438 | L7: -349 | M7: -415 | N7: -443 | O7: -429 | P7: -356 | Q7: -405 | R7: -452 | S7: -424 | T7: -346 | U7: -397 | AD7: -1634 | AE7: -611 | AF7: -839 | AG7: -1495 | AH7: -1698 | AI7: -1634 | AJ7: -1637 | AK7: =AJ7*1.02 -> -1669.74 | AL7: =AK7*1.38 -> -2304.2412 | AM7: =AL7*1.055 -> -2430.9745 | AN7: =AM7*1.055 -> -2564.6781 | AO7: =AN7*1.055 -> -2705.7354 | AP7: =AO7*1.055 -> -2854.5508 | AQ7: =AP7*1.055 -> -3011.5511 | AR7: =AQ7*1.055 -> -3177.1864 | AS7: =AR7*1.055 -> -3351.9317 | AT7: =AS7*1.055 -> -3536.2879
A8: Debt NOKm | B8: =U54 -> 990 | C8: Other external costs | D8: -706 | E8: -854 | F8: -1105 | G8: -1189 | H8: -1041 | I8: -1120 | J8: -1140 | K8: -1236 | L8: -1030 | M8: -1136 | N8: -1171 | O8: -1197 | P8: -1007 | Q8: -1159 | R8: -1230 | S8: -1218 | T8: -1128 | U8: -1183 | AD8: -4335 | AE8: -1751 | AF8: -2248 | AG8: -3854 | AH8: -4538 | AI8: -4454 | AJ8: -4614 | AK8: =AJ8*1.02 -> -4706.28 | AL8: =AK8*1.38 -> -6494.6664 | AM8: =AL8*1.055 -> -6851.8731 | AN8: =AM8*1.055 -> -7228.7261 | AO8: =AN8*1.055 -> -7626.306 | AP8: =AO8*1.055 -> -8045.7528 | AQ8: =AP8*1.055 -> -8488.2692 | AR8: =AQ8*1.055 -> -8955.124 | AS8: =AR8*1.055 -> -9447.6559 | AT8: =AS8*1.055 -> -9967.2769
A9: EV NOKm | B9: =B6-B7+B8 -> 19222.321 | C9: Staff costs | D9: -1056 | E9: -1577 | F9: -1649 | G9: -1674 | H9: -1582 | I9: -1770 | J9: -1778 | K9: -1752 | L9: -1614 | M9: -1795 | N9: -1703 | O9: -1756 | P9: -1650 | Q9: -1810 | R9: -1760 | S9: -1805 | T9: -1645 | U9: -1857 | AD9: -5869 | AE9: -3489 | AF9: -3597 | AG9: -5957 | AH9: -6882 | AI9: -6948 | AJ9: -7025 | AK9: =AJ9*1.02 -> -7165.5 | AL9: =AK9*1.38 -> -9888.39 | AM9: =AL9*1.055 -> -10432.251 | AN9: =AM9*1.055 -> -11006.025 | AO9: =AN9*1.055 -> -11611.357 | AP9: =AO9*1.055 -> -12249.981 | AQ9: =AP9*1.055 -> -12923.73 | AR9: =AQ9*1.055 -> -13634.535 | AS9: =AR9*1.055 -> -14384.435 | AT9: =AS9*1.055 -> -15175.579
C10: Rental costs | D10: -188 | E10: =-35-506 -> -541 | F10: =-59-630 -> -689 | G10: =-52-482 -> -534 | H10: -388 | I10: -598 | J10: -717 | K10: -507 | L10: -343 | M10: -612 | N10: -716 | O10: -486 | P10: -346 | Q10: -625 | R10: -744 | S10: -515 | T10: -368 | U10: -641 | AD10: =-74-1696 -> -1770 | AE10: =492-424 -> 68 | AF10: =79-780 -> -701 | AG10: =-159-1792 -> -1951 | AH10: -2209 | AI10: -2157 | AJ10: -2230 | AK10: =AJ10*1.02 -> -2274.6 | AL10: =AK10*1.38 -> -3138.948 | AM10: =AL10*1.055 -> -3311.5901 | AN10: =AM10*1.055 -> -3493.7276 | AO10: =AN10*1.055 -> -3685.8826 | AP10: =AO10*1.055 -> -3888.6062 | AQ10: =AP10*1.055 -> -4102.4795 | AR10: =AQ10*1.055 -> -4328.1159 | AS10: =AR10*1.055 -> -4566.1622 | AT10: =AS10*1.055 -> -4817.3012
C11: Pre-opening costs | D11: -27 | E11: -75 | F11: -20 | G11: -9 | H11: -14 | I11: -2 | J11: 0 | K11: -1 | L11: -2 | M11: -11 | N11: -9 | O11: -6 | P11: -28 | Q11: -21 | R11: -11 | S11: -15 | T11: -15 | U11: -23 | AA11: =SUM(AJ4:AJ5)+AG15 -> 24745 | AD11: -81 | AE11: -32 | AF11: -52 | AG11: -131 | AH11: -17 | AI11: -28 | AJ11: -75 | AK11: =AJ11*1.02 -> -76.5 | AL11: =AK11*1.38 -> -105.57 | AM11: =AL11*1.055 -> -111.37635 | AN11: =AM11*1.055 -> -117.50205 | AO11: =AN11*1.055 -> -123.96466 | AP11: =AO11*1.055 -> -130.78272 | AQ11: =AP11*1.055 -> -137.97577 | AR11: =AQ11*1.055 -> -145.56444 | AS11: =AR11*1.055 -> -153.57048 | AT11: =AS11*1.055 -> -162.01686
A12: Gearing | B12: =(B8-B7)/U31 -> 0.10831335 | C12: Items affecting comparability | D12: 0 | E12: 0 | F12: 0 | G12: -16 | H12: -3 | I12: 0 | J12: 0 | K12: -12 | L12: 0 | M12: 0 | N12: -18 | O12: 0 | P12: 0 | Q12: 0 | R12: -20 | S12: -31 | T12: -2 | U12: -3 | AD12: 169 | AE12: -269 | AF12: 7 | AG12: -16 | AH12: -14 | AI12: -18 | AJ12: -51 | AK12: =AJ12*1.02 -> -52.02 | AL12: =AK12*1.38 -> -71.7876 | AM12: =AL12*1.055 -> -75.735918 | AN12: =AM12*1.055 -> -79.901393 | AO12: =AN12*1.055 -> -84.29597 | AP12: =AO12*1.055 -> -88.932248 | AQ12: =AP12*1.055 -> -93.823522 | AR12: =AQ12*1.055 -> -98.983816 | AS12: =AR12*1.055 -> -104.42793 | AT12: =AS12*1.055 -> -110.17146
C13: A/D/I | D13: -820 | E13: -825 | F13: -849 | G13: -878 | H13: -938 | I13: -943 | J13: -970 | K13: -962 | L13: -955 | M13: -975 | N13: -967 | O13: -987 | P13: -966 | Q13: -959 | R13: -981 | S13: -1090 | T13: -973 | U13: -994 | AD13: -3281 | AE13: -6187 | AF13: -3139 | AG13: -3372 | AH13: -3812 | AI13: -3884 | AJ13: -3996 | AK13: =AJ13*1.02 -> -4075.92 | AL13: =AK13*1.38 -> -5624.7696 | AM13: =AL13*1.055 -> -5934.1319 | AN13: =AM13*1.055 -> -6260.5092 | AO13: =AN13*1.055 -> -6604.8372 | AP13: =AO13*1.055 -> -6968.1032 | AQ13: =AP13*1.055 -> -7351.3489 | AR13: =AQ13*1.055 -> -7755.6731 | AS13: =AR13*1.055 -> -8182.2351 | AT13: =AS13*1.055 -> -8632.2581
C14: Total Opex | D14: =SUM(D7:D13) -> -3011 | E14: =SUM(E7:E13) -> -4264 | F14: =SUM(F7:F13) -> -4761 | G14: =SUM(G7:G13) -> -4740 | H14: =SUM(H7:H13) -> -4328 | I14: =SUM(I7:I13) -> -4859 | J14: =SUM(J7:J13) -> -5077 | K14: =SUM(K7:K13) -> -4908 | ... U14: =SUM(U7:U13) -> -5098 | Z14: =Z15-Z6 -> -11595 | AA14: =AA15-AA6 -> -12170 | AB14: =AB15-AB6 -> -13658 | AC14: =AC15-AC6 -> -17024 | AD14: =SUM(AD7:AD13) -> -16801 | AE14: =SUM(AE7:AE13) -> -12271 | AF14: =SUM(AF7:AF13) -> -10569 | AG14: =SUM(AG7:AG13) -> -16776 | AH14: =SUM(AH7:AH13) -> -19170 | AI14: =SUM(AI7:AI13) -> -19123 | AJ14: =SUM(AJ7:AJ13) -> -19628 | AK14: =SUM(AK7:AK13) -> -20020.56 | ... AT14: =SUM(AT7:AT13) -> -42400.891
C15: Operating profit EBIT | D15: =D6+D14 -> -278 | E15: =E6+E14 -> 1015 | F15: =F6+F14 -> 1233 | G15: =G6+G14 -> 488 | H15: =H6+H14 -> 198 | I15: =I6+I14 -> 834 | J15: =J6+J14 -> 1250 | K15: =K6+K14 -> 502 | ... U15: =U6+U14 -> 900 | Z15: 613 | AA15: 925 | AB15: 925 | AC15: 983 | AD15: =AD6+AD14 -> 2144 | AE15: =AE6+AE14 -> -4801 | AF15: =AF6+AF14 -> -439 | AG15: =AG6+AG14 -> 2457 | AH15: =AH6+AH14 -> 2785 | AI15: =AI6+AI14 -> 2836 | AJ15: =SUM(AJ6:AJ13) -> 2660 | AK15: =SUM(AK6:AK13) -> 3158.96 | AL15: =SUM(AL6:AL13) -> 4478.328 | AM15: =SUM(AM6:AM13) -> 4724.636 | AN15: =SUM(AN6:AN13) -> 4984.491 | AO15: =SUM(AO6:AO13) -> 5258.638 | AP15: =SUM(AP6:AP13) -> 5547.8631 | AQ15: =SUM(AQ6:AQ13) -> 5852.9956 | ... AT15: =SUM(AT6:AT13) -> 6872.8296
C16: Net financial items | D16: -453 | E16: -479 | F16: -436 | G16: -438 | H16: -522 | I16: -503 | J16: -510 | K16: -528 | L16: -504 | M16: -519 | N16: -473 | O16: -479 | P16: -454 | Q16: -454 | R16: -466 | S16: -479 | T16: -441 | U16: -456 | AD16: -1242 | AE16: -1281 | AF16: -1606 | AG16: -1808 | AH16: -2064 | AI16: -1975 | AJ16: -1853 | AK16: =AJ16*1.01 -> -1871.53 | AL16: =AK16*1.2 -> -2245.836 | AM16: =AL16*1.05 -> -2358.1278 | AN16: =AM16*1.05 -> -2476.0342 | AO16: =AN16*1.05 -> -2599.8359 | AP16: =AO16*1.05 -> -2729.8277 | AQ16: =AP16*1.05 -> -2866.3191 | AR16: =AQ16*1.05 -> -3009.635 | AS16: =AR16*1.05 -> -3160.1168 | AT16: =AS16*1.05 -> -3318.1226
C17: PTP | D17: =SUM(D15:D16) -> -731 | E17: =SUM(E15:E16) -> 536 | F17: =SUM(F15:F16) -> 797 | G17: =SUM(G15:G16) -> 50 | H17: =SUM(H15:H16) -> -324 | I17: =SUM(I15:I16) -> 331 | J17: =SUM(J15:J16) -> 740 | K17: =SUM(K15:K16) -> -26 | ... U17: =SUM(U15:U16) -> 444 | Z17: 115 | AA17: 1057 | AB17: 800 | AC17: 810 | AD17: =SUM(AD15:AD16) -> 902 | AE17: =SUM(AE15:AE16) -> -6082 | AF17: =SUM(AF15:AF16) -> -2045 | AG17: =SUM(AG15:AG16) -> 649 | AH17: =SUM(AH15:AH16) -> 721 | AI17: =SUM(AI15:AI16) -> 861 | AJ17: =SUM(AJ15:AJ16) -> 807 | AK17: =SUM(AK15:AK16) -> 1287.43 | ... AT17: =SUM(AT15:AT16) -> 3554.707
C18: Tax | D18: 93 | E18: -104 | F18: -163 | G18: -48 | H18: 21 | I18: -59 | J18: -182 | K18: 67 | L18: 51 | M18: -98 | N18: -146 | O18: -15 | P18: 43 | Q18: -94 | R18: -151 | S18: 17 | T18: 33 | U18: -92 | Z18: 5 | AA18: -175 | AB18: -90 | AC18: -131 | AD18: -177 | AE18: 130 | AF18: 367 | AG18: -221 | AH18: -152 | AI18: -209 | AJ18: -185 | AK18: =AK17*-0.2 -> -257.486 | AL18: =AL17*-0.2 -> -446.4984 | AM18: =AM17*-0.2 -> -473.30165 | AN18: =AN17*-0.2 -> -501.69137 | AO18: =AO17*-0.2 -> -531.76043 | AP18: =AP17*-0.2 -> -563.60709 | AQ18: =AQ17*-0.2 -> -597.3353 | AR18: =AR17*-0.2 -> -633.05506 | ... AT18: =AT17*-0.2 -> -710.94139
C19: Net income | D19: =SUM(D17:D18) -> -638 | E19: =SUM(E17:E18) -> 432 | F19: =SUM(F17:F18) -> 634 | G19: =SUM(G17:G18) -> 2 | H19: =SUM(H17:H18) -> -303 | I19: =SUM(I17:I18) -> 272 | J19: =SUM(J17:J18) -> 558 | K19: =SUM(K17:K18) -> 41 | ... U19: =SUM(U17:U18) -> 352 | Z19: 120 | AA19: 882 | AB19: 711 | AC19: 678 | AD19: =SUM(AD17:AD18) -> 725 | AE19: =SUM(AE17:AE18) -> -5952 | AF19: =SUM(AF17:AF18) -> -1678 | AG19: =SUM(AG17:AG18) -> 428 | AH19: =SUM(AH17:AH18) -> 569 | AI19: =SUM(AI17:AI18) -> 652 | AJ19: =SUM(AJ17:AJ18) -> 622 | AK19: =SUM(AK17:AK18) -> 1029.944 | ... AT19: =SUM(AT17:AT18) -> 2843.7656 | AU19: =AT19*(1+$AW$22) -> 2815.3279 | AV19: =AU19*(1+$AW$22) -> 2787.1746 | AW19: =AV19*(1+$AW$22) -> 2759.3029 | AX19: =AW19*(1+$AW$22) -> 2731.7099 | AY19: =AX19*(1+$AW$22) -> 2704.3928 | AZ19: =AY19*(1+$AW$22) -> 2677.3488 | BA19: =AZ19*(1+$AW$22) -> 2650.5753 | BB19: =BA19*(1+$AW$22) -> 2624.0696 | ... EY19: =EX19*(1+$AW$22) -> 950.88939
C20: Shares | D20: 191.25069 | E20: 232.7689 | F20: 232.7689 | G20: 191.30412 | H20: 191.30412 | I20: 232.7689 | J20: 232.7689 | K20: 225.81547 | L20: 191.30412 | M20: 219.15794 | N20: 219.15793 | O20: 218.95407 | P20: 216.58652 | Q20: 215.1273 | R20: 215.1273 | S20: 215.1273 | T20: 215.1273 | U20: 215.1273 | Z20: 103.00627 | AA20: 103.00627 | AB20: 103.00627 | AC20: 103.00627 | AD20: 103.00627 | AE20: 148.61881 | AF20: 191.25069 | AG20: 191.27707 | AH20: 191.30412 | AI20: 203.61442 | AJ20: 215.1273 | AK20: 215.1273 | AL20: 215.1273 | AM20: 215.1273 | AN20: 215.1273 | AO20: 215.1273 | AP20: 215.1273 | AQ20: 215.1273 | AR20: 215.1273 | AS20: 215.1273 | AT20: 215.1273
C21: EPS | D21: =D19/D20 -> -3.3359357 | E21: =E19/E20 -> 1.855918 | F21: =F19/F20 -> 2.7237315 | G21: =G19/G20 -> 0.010454558 | H21: =H19/H20 -> -1.5838656 | I21: =I19/I20 -> 1.168541 | J21: =J19/J20 -> 2.3972274 | K21: =K19/K20 -> 0.18156417 | ... U21: =U19/U20 -> 1.6362405 | Z21: =Z19/Z20 -> 1.1649777 | AA21: =AA19/AA20 -> 8.5625858 | AB21: =AB19/AB20 -> 6.9024926 | AC21: =AC19/AC20 -> 6.5821238 | AD21: =AD19/AD20 -> 7.0384067 | AE21: =AE19/AE20 -> -40.048768 | AF21: =AF19/AF20 -> -8.7738247 | AG21: =AG19/AG20 -> 2.2375917 | ... AT21: =AT19/AT20 -> 13.21899 | AV21: Discount | AW21: 0.08
AV22: TV | AW22: -0.01
C23: Revenue y/y | H23: =(H6-D6)/D6 -> 0.65605562 | I23: =(I6-E6)/E6 -> 0.078423944 | J23: =(J6-F6)/F6 -> 0.055555556 | K23: =(K6-G6)/G6 -> 0.034812548 | L23: =(L6-H6)/H6 -> -0.023641184 | M23: =(M6-I6)/I6 -> 0.031266468 | N23: =(N6-J6)/J6 -> -0.022917654 | O23: =(O6-K6)/K6 -> 0.014232902 | ... U23: =(U6-Q6)/Q6 -> 0.035030198 | AA23: =(AA6-Z6)/Z6 -> 0.072657274 | AB23: =(AB6-AA6)/AA6 -> 0.11363116 | AC23: =(AC6-AB6)/AB6 -> 0.23479394 | AD23: =(AD6-AC6)/AC6 -> 0.052090854 | AE23: =(AE6-AD6)/AD6 -> -0.60570071 | AF23: =(AF6-AE6)/AE6 -> 0.35609103 | AG23: =(AG6-AF6)/AF6 -> 0.89861797 | AH23: =(AH6-AG6)/AG6 -> 0.14152758 | ... AT23: =(AT6-AS6)/AS6 -> 0.055 | AV23: NPV | AW23: =NPV(AW21,AJ19:EY19) -> 26725.194
C24: Organic y/y | J24: 0.01 | K24: 0.032 | L24: 0.02 | M24: 0.051 | N24: 0.005 | O24: 0.015 | P24: 0.038 | Q24: 0.02 | R24: 0.053 | S24: 0.042 | T24: 0.047 | U24: 0.012 | AJ24: 0.04 | AV24: S/O | AW24: 216.58652
C25: Opex y/y | H25: =(H14-D14)/D14 -> 0.43739621 | I25: =(I14-E14)/E14 -> 0.13954034 | J25: =(J14-F14)/F14 -> 0.066372611 | K25: =(K14-G14)/G14 -> 0.035443038 | L25: =(L14-H14)/H14 -> -0.0080868762 | M25: =(M14-I14)/I14 -> 0.017493311 | N25: =(N14-J14)/J14 -> -0.0098483356 | O25: =(O14-K14)/K14 -> -0.0095762021 | ... U25: =(U14-Q14)/Q14 -> 0.023900382 | AA25: =(AA14-Z14)/Z14 -> 0.049590341 | AB25: =(AB14-AA14)/AA14 -> 0.12226787 | AC25: =(AC14-AB14)/AB14 -> 0.24644897 | AD25: =(AD14-AC14)/AC14 -> -0.013099154 | AE25: =(AE14-AD14)/AD14 -> -0.26962681 | AF25: =(AF14-AE14)/AE14 -> -0.138701 | AG25: =(AG14-AF14)/AF14 -> 0.58728357 | AH25: =(AH14-AG14)/AG14 -> 0.14270386 | ... AT25: =(AT14-AS14)/AS14 -> 0.055 | AV25: NPV/Share | AW25: =AW23/AW24 -> 123.39269
C26: EBIT margin | D26: =D15/D6 -> -0.10171972 | E26: =E15/E6 -> 0.19227126 | F26: =F15/F6 -> 0.20570571 | G26: =G15/G6 -> 0.093343535 | H26: =H15/H6 -> 0.043747238 | I26: =I15/I6 -> 0.1464957 | J26: =J15/J6 -> 0.19756599 | K26: =K15/K6 -> 0.092791128 | ... U26: =U15/U6 -> 0.15005002 | Z26: =Z15/Z6 -> 0.050212975 | AA26: =AA15/AA6 -> 0.070637648 | AB26: =AB15/AB6 -> 0.063430021 | AC26: =AC15/AC6 -> 0.054589882 | AD26: =AD15/AD6 -> 0.1131697 | AE26: =AE15/AE6 -> -0.64270415 | AF26: =AF15/AF6 -> -0.043336624 | AG26: =AG15/AG6 -> 0.12774918 | ... AT26: =AT15/AT6 -> 0.13948266 | AV26: Opp-/nedside | AW26: =(AW25-B4)/B4 -> 0.41020216
C27: ROE | Z27: =Z19/6205 -> 0.019339243 | AA27: =AA19/7103 -> 0.12417288 | AB27: =AB19/7356 -> 0.096655791 | AC27: =AC19/7805 -> 0.086867393 | AD27: =AD19/6601 -> 0.10983184 | AE27: =AE19/2071 -> -2.8739739 | AF27: =AF19/1155 -> -1.4528139 | AG27: =AG19/AG53 -> 0.1882146 | AH27: =AH19/K53 -> 0.26269621 | AI27: =AI19/Q53 -> 0.23944179 | AJ27: =AJ19/AJ53 -> 0.20956873
C29: Adjusted EBITDA | D29: -237 | E29: 1083 | F29: 1213 | G29: 476 | H29: 170 | I29: 772 | J29: 1173 | K29: 451 | L29: 33 | M29: 841 | N29: 1077 | O29: 544 | P29: 101 | Q29: 723 | R29: 1088 | S29: 513 | T29: 105 | U29: 796 | Z29: 4406 | AA29: 4896 | AB29: 5535 | AC29: 1957 | AD29: 2046 | AE29: -1503 | AF29: 6 | AG29: 2536 | AH29: 2566 | AI29: 2495 | AJ29: 2425
C30: Adjusted EBITDA margin | D30: =D29/D6 -> -0.086717892 | E30: =E29/E6 -> 0.20515249 | F30: =F29/F6 -> 0.20236904 | G30: =G29/G6 -> 0.091048202 | H30: =H29/H6 -> 0.03756076 | I30: =I29/I6 -> 0.13560513 | J30: =J29/J6 -> 0.18539592 | K30: =K29/K6 -> 0.08336414 | ... U30: =U29/U6 -> 0.1327109 | Z30: =Z29/Z6 -> 0.36091088 | AA30: =AA29/AA6 -> 0.37388316 | AB30: =AB29/AB6 -> 0.37955153 | AC30: =AC29/AC6 -> 0.10867996 | AD30: =AD29/AD6 -> 0.10799683 | AE30: =AE29/AE6 -> -0.20120482 | AF30: =AF29/AF6 -> 0.0005923001 | AG30: =AG29/AG6 -> 0.1318567 | ... AJ30: =AJ29/AJ6 -> 0.10880294
C31: Adjusted EBITDA LTM | G31: =SUM(D29:G29) -> 2535 | H31: =SUM(E29:H29) -> 2942 | I31: =SUM(F29:I29) -> 2631 | J31: =SUM(G29:J29) -> 2591 | K31: =SUM(H29:K29) -> 2566 | L31: =SUM(I29:L29) -> 2429 | M31: =SUM(J29:M29) -> 2498 | N31: =SUM(K29:N29) -> 2402 | ... U31: =SUM(R29:U29) -> 2502
C33: RevPAR | D33: 395 | E33: 749 | F33: 875 | G33: 695 | H33: 626 | I33: 828 | J33: 933 | K33: 734 | L33: 619 | M33: 871 | N33: 941 | O33: 762 | P33: 655 | Q33: 879 | R33: 966 | S33: 773 | T33: 665 | U33: 882 | Z33: 601.3 | AA33: 643 | AB33: 680 | AC33: 683 | AD33: 707 | AE33: 271 | AF33: 364 | AG33: 683 | AH33: 782 | AI33: 799 | AJ33: 816
C34: y/y | H34: =(H33-D33)/D33 -> 0.58481013 | I34: =(I33-E33)/E33 -> 0.10547397 | J34: =(J33-F33)/F33 -> 0.066285714 | K34: =(K33-G33)/G33 -> 0.056115108 | L34: =(L33-H33)/H33 -> -0.011182109 | M34: =(M33-I33)/I33 -> 0.051932367 | N34: =(N33-J33)/J33 -> 0.0085744909 | O34: =(O33-K33)/K33 -> 0.038147139 | ... U34: =(U33-Q33)/Q33 -> 0.0034129693 | AA34: =(AA33-Z33)/Z33 -> 0.069349742 | AB34: =(AB33-AA33)/AA33 -> 0.057542768 | AC34: =(AC33-AB33)/AB33 -> 0.0044117647 | AD34: =(AD33-AC33)/AC33 -> 0.035139092 | AE34: =(AE33-AD33)/AD33 -> -0.61669024 | AF34: =(AF33-AE33)/AE33 -> 0.34317343 | AG34: =(AG33-AF33)/AF33 -> 0.87637363 | AH34: =(AH33-AG33)/AG33 -> 0.14494876 | ... AJ34: =(AJ33-AI33)/AI33 -> 0.021276596
C35: ARR | D35: 1011 | E35: 1185 | F35: 1243 | G35: 1219 | H35: 1169 | I35: 1315 | J35: 1313 | K35: 1268 | L35: 1193 | M35: 1360 | N35: 1317 | O35: 1279 | P35: 1188 | Q35: 1334 | R35: 1302 | S35: 1270 | T35: 1191 | U35: 1345 | Z35: 933.9 | AA35: 976 | AB35: 1012 | AC35: 1045 | AD35: 1071 | AE35: 945 | AF35: 957 | AG35: 1183 | AH35: 1272 | AI35: 1294 | AJ35: 1274
C36: y/y | H36: =(H35-D35)/D35 -> 0.15628091 | I36: =(I35-E35)/E35 -> 0.10970464 | J36: =(J35-F35)/F35 -> 0.056315366 | K36: =(K35-G35)/G35 -> 0.040196883 | L36: =(L35-H35)/H35 -> 0.020530368 | M36: =(M35-I35)/I35 -> 0.034220532 | N36: =(N35-J35)/J35 -> 0.0030464585 | O36: =(O35-K35)/K35 -> 0.0086750789 | ... U36: =(U35-Q35)/Q35 -> 0.0082458771 | AA36: =(AA35-Z35)/Z35 -> 0.045079773 | AB36: =(AB35-AA35)/AA35 -> 0.036885246 | AC36: =(AC35-AB35)/AB35 -> 0.032608696 | AD36: =(AD35-AC35)/AC35 -> 0.024880383 | AE36: =(AE35-AD35)/AD35 -> -0.11764706 | AF36: =(AF35-AE35)/AE35 -> 0.012698413 | AG36: =(AG35-AF35)/AF35 -> 0.23615465 | AH36: =(AH35-AG35)/AG35 -> 0.07523246 | ... AJ36: =(AJ35-AI35)/AI35 -> -0.015455951
C37: Occupancy | D37: 0.391 | E37: 0.632 | F37: 0.705 | G37: 0.57 | H37: 0.535 | I37: 0.63 | J37: 0.71 | K37: 0.579 | L37: 0.519 | M37: 0.64 | N37: 0.714 | O37: 0.596 | P37: 0.551 | Q37: 0.659 | R37: 0.742 | S37: 0.608 | T37: 0.558 | U37: 0.656 | Z37: 0.644 | AA37: 0.659 | AB37: 0.671 | AC37: 0.653 | AD37: 0.66 | AE37: 0.287 | AF37: 0.38 | AG37: 0.577 | AH37: 0.614 | AI37: 0.618 | AJ37: 0.641
C39: Antall hotellrom | D39: 54002 | E39: 55572 | F39: 55977 | G39: 55977 | H39: 56059 | I39: 55930 | J39: 55969 | K39: 55642 | L39: 55657 | M39: 55566 | N39: 55452 | O39: 55319 | P39: 55603 | Q39: 55987 | R39: 55868 | S39: 68592 | T39: 68315 | U39: 68495 | Z39: 41000 | AA39: 41572 | AB39: 55958 | AC39: 51693 | AD39: 52755 | AE39: 53000 | AF39: 54000 | AG39: 55831 | AH39: 55642 | AI39: 55319 | AJ39: 68592
C40: Antall hotell | D40: 266 | E40: 270 | F40: 271 | G40: 271 | H40: 270 | I40: 269 | J40: 269 | K40: 267 | L40: 266 | M40: 264 | N40: 264 | O40: 263 | P40: 264 | Q40: 265 | R40: 264 | S40: 323 | T40: 322 | U40: 324 | Z40: 221 | AA40: 223 | AB40: 280 | AC40: 268 | AD40: 268 | AE40: 265 | AF40: 268 | AG40: 271 | AH40: 267 | AI40: 263 | AJ40: 323
C42: Balanse SEKm
C43: Intangible assets | D43: 7049 | E43: 7021 | F43: 7115 | G43: 7189 | H43: 7129 | I43: 7276 | J43: 7214 | K43: 7010 | L43: 7062 | M43: 7043 | N43: 7002 | O43: 7101 | P43: 6848 | Q43: 6962 | R43: 6955 | S43: 6825 | T43: 6861 | U43: 6888 | Z43: =5575+3151+181 -> 8907 | AA43: =5793+3145+165 -> 9103 | AB43: =6303+3153+213 -> 9669 | AC43: =6560+3156+184 -> 9900 | AD43: =6641+3147+153 -> 9941 | AE43: =3737+2835+115 -> 6687 | AF43: =3914+2843+128 -> 6885 | AG43: =4180+2855+154 -> 7189 | AH43: 7010 | AI43: 7101 | AJ43: 6825
C44: Building and land | D44: 709 | E44: 35501 | F44: 36101 | G44: 36725 | H44: 294 | I44: 77 | J44: 78 | K44: 75 | L44: 74 | M44: 74 | N44: 71 | O44: 71 | P44: 69 | Q44: 68 | R44: 68 | S44: 65 | T44: 69 | U44: 69 | Z44: 89 | AA44: 95 | AB44: 1764 | AC44: 1676 | AD44: 26759 | AE44: 25762 | AF44: 31251 | AG44: 36725 | AH44: 75 | AI44: 71 | AJ44: 65
C45: Right of use assets | D45: 32738 | E45: 0 | F45: 0 | G45: 0 | H45: 40610 | I45: 41138 | J45: 39914 | K45: 39389 | L45: 41421 | M45: 40565 | N45: 39685 | O45: 39707 | P45: 38625 | Q45: 38790 | R45: 38212 | S45: 38659 | T45: 39123 | U45: 38841 | Z45: 0 | AA45: 0 | AB45: 0 | AC45: 0 | AD45: 0 | AE45: 0 | AF45: 0 | AG45: 0 | AH45: 39389 | AI45: 39707 | AJ45: 38659
C46: Equipments, fixtures and fittings | D46: 3767 | E46: 4519 | F46: 4442 | G46: 4406 | H46: 3921 | I46: 4154 | J46: 4012 | K46: 3958 | L46: 4102 | M46: 4118 | N46: 4006 | O46: 4142 | P46: 4100 | Q46: 4189 | R46: 4121 | S46: 4237 | T46: 4349 | U46: 4478 | Z46: 2549 | AA46: 2882 | AB46: 3835 | AC46: 4359 | AD46: 4865 | AE46: 4625 | AF46: 4497 | AG46: 4406 | AH46: 3958 | AI46: 4142 | AJ46: 4237
...

Sheet Segementer
AD2: Antall rom (Q226)
B3: SEKm | C3: Q122 | D3: Q222 | E3: Q322 | F3: Q422 | G3: 2022 | H3: Q123 | I3: Q223 | J3: Q323 | K3: Q423 | L3: 2023 | M3: Q124 | N3: Q224 | O3: Q324 | P3: Q424 | Q3: 2024 | R3: Q125 | S3: Q225 | T3: Q325 | U3: Q425 | V3: 2025 | W3: Q126 | X3: Q226 | Y3: Q326 | Z3: Q426 | AA3: 2026
B4: Sweden | AD4: Sweden | AE4: =AF4/$AF$9 -> 0.27701091 | AF4: 18924
B5: Net sales | C5: 827 | D5: 1686 | E5: 1882 | F5: 1658 | G5: =SUM(C5:F5) -> 6053 | H5: 1388 | I5: 1751 | J5: 1862 | K5: 1641 | L5: =SUM(H5:K5) -> 6642 | M5: 1325 | N5: 1755 | O5: 1873 | P5: 1654 | Q5: =SUM(M5:P5) -> 6607 | R5: 1343 | S5: 1810 | T5: 2023 | U5: 1788 | V5: =SUM(R5:U5) -> 6964 | W5: 1433 | X5: 1946 | AA5: =SUM(W5:Z5) -> 3379 | AD5: Norway | AE5: =AF5/$AF$9 -> 0.23805899 | AF5: 16263
B6: y/y | H6: =(H5-C5)/C5 -> 0.6783555 | I6: =(I5-D5)/D5 -> 0.038552788 | J6: =(J5-E5)/E5 -> -0.010626993 | K6: =(K5-F5)/F5 -> -0.010253317 | L6: =(L5-G5)/G5 -> 0.09730712 | M6: =(M5-H5)/H5 -> -0.045389049 | N6: =(N5-I5)/I5 -> 0.0022844089 | O6: =(O5-J5)/J5 -> 0.0059076262 | ... AA6: =(AA5-V5)/V5 -> -0.51479035 | AD6: Finland | AE6: =AF6/$AF$9 -> 0.18050209 | AF6: 12331
B7: Organic growth | C7: 507 | D7: 1225 | E7: 810 | F7: 433 | H7: 561 | I7: 65 | J7: -20 | K7: -17 | M7: -63 | N7: 4 | O7: 11 | P7: 13 | R7: 18 | S7: 55 | T7: 150 | U7: 134 | W7: 90 | X7: 137 | AD7: Denmark | AE7: =AF7/$AF$9 -> 0.082514821 | AF7: 5637
B8: New hotels | C8: 11 | D8: 77 | E8: 159 | F8: 120 | H8: 95 | I8: 68 | J8: 11 | K8: 10 | M8: 4 | N8: 19 | O8: 38 | P8: 33 | R8: 9 | S8: 18 | T8: 19 | U8: 4 | W8: 2 | X8: 7 | AD8: other Europe | AE8: =AF8/$AF$9 -> 0.2219132 | AF8: 15160
B9: Temporarliy closed hotels | C9: 0 | D9: 0 | E9: 0 | F9: 0 | H9: 0 | I9: 0 | J9: 0 | K9: 0 | M9: 0 | N9: 0 | O9: 0 | P9: 0 | R9: 15 | S9: 52 | T9: 34 | U9: 29 | W9: 11 | X9: -5 | AD9: Total | AE9: =SUM(AE4:AE8) -> 1 | AF9: =SUM(AF4:AF8) -> 68315
B10: Exits | C10: 8 | D10: -7 | E10: -15 | F10: -18 | H10: -33 | I10: -40 | J10: -52 | K10: -45 | M10: -23 | N10: -32 | O10: -24 | P10: -8 | R10: 0 | S10: 0 | T10: 0 | U10: 0 | W10: 0 | X10: 4
B11: LFL | C11: 488 | D11: 1155 | E11: 667 | F11: 330 | H11: 499 | I11: 36 | J11: 22 | K11: 18 | M11: -44 | N11: 18 | O11: -3 | P11: -11 | R11: -6 | S11: -16 | T11: 97 | U11: 100 | W11: 77 | X11: 130
B12: Adjusted EBITDA | C12: -80 | D12: 333 | E12: 401 | F12: 221 | G12: =SUM(C12:F12) -> 875 | H12: 95 | I12: 270 | J12: 405 | K12: 225 | L12: =SUM(H12:K12) -> 995 | M12: 66 | N12: 288 | O12: 406 | P12: 220 | Q12: =SUM(M12:P12) -> 980 | R12: 59 | S12: 283 | T12: 438 | U12: 252 | V12: =SUM(R12:U12) -> 1032 | W12: 71 | X12: 354 | AA12: =SUM(W12:Z12) -> 425
B13: Margin % | C13: -0.097 | D13: 0.197 | E13: 0.212 | F13: 0.132 | H13: 0.068 | I13: 0.154 | J13: 0.217 | K13: 0.137 | L13: =(L12-G12)/G12 -> 0.13714286 | M13: 0.05 | N13: 0.164 | O13: 0.217 | P13: 0.133 | Q13: =(Q12-L12)/L12 -> -0.015075377 | R13: 0.044 | S13: 0.156 | T13: 0.216 | U13: 0.141 | V13: =(V12-Q12)/Q12 -> 0.053061224 | W13: =W12/W5 -> 0.049546406 | X13: =X12/X5 -> 0.18191161 | AA13: =(AA12-V12)/V12 -> -0.58817829
B14: RevPAR (SEK) | C14: 379 | D14: 756 | E14: 867 | F14: 705 | H14: 616 | I14: 823 | J14: 886 | K14: 730 | M14: 605 | N14: 843 | O14: 892 | P14: 728 | R14: 607 | S14: 832 | T14: 925 | U14: 759 | W14: 628 | X14: 896
B15: y/y | H15: =(H14-C14)/C14 -> 0.62532982 | I15: =(I14-D14)/D14 -> 0.088624339 | J15: =(J14-E14)/E14 -> 0.021914648 | K15: =(K14-F14)/F14 -> 0.035460993 | M15: =(M14-H14)/H14 -> -0.017857143 | N15: =(N14-I14)/I14 -> 0.024301337 | O15: =(O14-J14)/J14 -> 0.006772009 | P15: =(P14-K14)/K14 -> -0.002739726 | R15: =(R14-M14)/M14 -> 0.0033057851 | S15: =(S14-N14)/N14 -> -0.013048636 | T15: =(T14-O14)/O14 -> 0.036995516 | U15: =(U14-P14)/P14 -> 0.042582418 | W15: =(W14-R14)/R14 -> 0.034596376 | X15: =(X14-S14)/S14 -> 0.076923077 | Y15: =(Y14-T14)/T14 -> -1 | Z15: =(Z14-U14)/U14 -> -1
B16: New hotels/Temporarily closed /exits | C16: 2 | D16: 0 | E16: 13 | F16: 3 | H16: 4 | I16: 8 | J16: 8 | K16: 5 | M16: 3 | N16: 5 | O16: 5 | P16: -1 | R16: -7 | S16: 4 | T16: 2 | U16: 7 | W16: 1 | X16: 2
B17: LFL | C17: 218 | D17: 533 | E17: 350 | F17: 160 | H17: 233 | I17: 58 | J17: 11 | K17: 20 | M17: -13 | N17: 16 | O17: 1 | P17: 1 | R17: 9 | S17: -15 | T17: 32 | U17: 24 | W17: 19 | X17: 62
B18: ARR (SEK) | C18: 964 | D18: 1164 | E18: 1228 | F18: 1192 | H18: 1120 | I18: 1277 | J18: 1239 | K18: 1223 | M18: 1135 | N18: 1313 | O18: 1238 | P18: 1232 | R18: 1141 | S18: 1289 | T18: 1240 | U18: 1217 | W18: 1130 | X18: 1318
B19: y/y | H19: =(H18-C18)/C18 -> 0.16182573 | I19: =(I18-D18)/D18 -> 0.097079038 | J19: =(J18-E18)/E18 -> 0.0089576547 | K19: =(K18-F18)/F18 -> 0.026006711 | M19: =(M18-H18)/H18 -> 0.013392857 | N19: =(N18-I18)/I18 -> 0.028191073 | O19: =(O18-J18)/J18 -> -0.0008071025 | P19: =(P18-K18)/K18 -> 0.0073589534 | R19: =(R18-M18)/M18 -> 0.0052863436 | S19: =(S18-N18)/N18 -> -0.018278751 | T19: =(T18-O18)/O18 -> 0.0016155089 | U19: =(U18-P18)/P18 -> -0.012175325 | W19: =(W18-R18)/R18 -> -0.0096406661 | X19: =(X18-S18)/S18 -> 0.022498061 | Y19: =(Y18-T18)/T18 -> -1 | Z19: =(Z18-U18)/U18 -> -1
B20: OCC% | C20: 0.394 | D20: 0.65 | E20: 0.706 | F20: 0.592 | H20: 0.55 | I20: 0.644 | J20: 0.715 | K20: 0.597 | M20: 0.533 | N20: 0.642 | O20: 0.721 | P20: 0.591 | R20: 0.532 | S20: 0.646 | T20: 0.746 | U20: 0.623 | W20: 0.555 | X20: 0.68
B22: Norway
B23: Net sales | C23: 961 | D23: 1699 | E23: 1876 | F23: 1503 | G23: =SUM(C23:F23) -> 6039 | H23: 1313 | I23: 1548 | J23: 1851 | K23: 1469 | L23: =SUM(H23:K23) -> 6181 | M23: 1248 | N23: 1636 | O23: 1783 | P23: 1461 | Q23: =SUM(M23:P23) -> 6128 | R23: 1340 | S23: 1647 | T23: 1897 | U23: 1502 | V23: =SUM(R23:U23) -> 6386 | W23: 1372 | X23: 1734 | AA23: =SUM(W23:Z23) -> 3106
B24: y/y | H24: =(H23-C23)/C23 -> 0.36628512 | I24: =(I23-D23)/D23 -> -0.088875809 | J24: =(J23-E23)/E23 -> -0.013326226 | K24: =(K23-F23)/F23 -> -0.022621424 | L24: =(L23-G23)/G23 -> 0.023513827 | M24: =(M23-H23)/H23 -> -0.04950495 | N24: =(N23-I23)/I23 -> 0.056847545 | O24: =(O23-J23)/J23 -> -0.036736899 | ... AA24: =(AA23-V23)/V23 -> -0.51362355
B25: Currency effect | C25: 63 | D25: 76 | E25: 116 | F25: 60 | H25: -47 | I25: -93 | J25: -49 | K25: -101 | M25: -41 | N25: 9 | O25: -97 | P25: -10 | R25: -33 | S25: -89 | T25: -66 | U25: -74 | W25: -34 | X25: 82
B26: Organic growth | C26: 579 | D26: 980 | E26: 329 | F26: 307 | H26: 398 | I26: -59 | J26: 25 | K26: 68 | M26: -24 | N26: 79 | O26: 28 | P26: 1 | R26: 126 | S26: 100 | T26: 179 | U26: 115 | W26: 66 | X26: 5
B27: New hotels | C27: 8 | D27: 17 | E27: 53 | F27: 45 | H27: 53 | I27: 44 | J27: 16 | K27: 4 | M27: 0 | N27: 0 | O27: 0 | P27: 0 | R27: 0 | S27: 0 | T27: 16 | U27: 64 | W27: 91 | X27: 36
B28: Temporarliy closed hotels | C28: 0 | D28: 0 | E28: 0 | F28: 0 | H28: 0 | I28: 0 | J28: 0 | K28: 0 | M28: 0 | N28: 0 | O28: 0 | P28: 0 | R28: -19 | S28: -8 | T28: 14 | U28: 25 | W28: 14 | X28: 6
B29: Exits | C29: -2 | D29: -4 | E29: -7 | F29: 0 | H29: 0 | I29: -87 | J29: -20 | K29: 11 | M29: -33 | N29: -35 | O29: -77 | P29: -71 | R29: -3 | S29: -7 | T29: 0 | U29: 1 | W29: -7 | X29: -11
B30: LFL | C30: 573 | D30: 966 | E30: 283 | F30: 263 | H30: 345 | I30: -16 | J30: 29 | K30: 53 | M30: 9 | N30: 114 | O30: 105 | P30: 72 | R30: 148 | S30: 116 | T30: 150 | U30: 25 | W30: -33 | X30: 26
B31: Adjusted EBITDA | C31: 135 | D31: 417 | E31: 425 | F31: 194 | G31: =SUM(C31:F31) -> 1171 | H31: 152 | I31: 285 | J31: 404 | K31: 170 | L31: =SUM(H31:K31) -> 1011 | M31: 92 | N31: 288 | O31: 353 | P31: 176 | Q31: =SUM(M31:P31) -> 909 | R31: 141 | S31: 270 | T31: 406 | U31: 183 | V31: =SUM(R31:U31) -> 1000 | W31: 134 | X31: 305 | AA31: =SUM(W31:Z31) -> 439 | AD31: RevPAR: | AE31: Average revenue per room
B32: Margin % | C32: 0.14 | D32: 0.245 | E32: 0.227 | F32: 0.129 | H32: 0.115 | I32: 0.184 | J32: 0.218 | K32: 0.116 | M32: 0.074 | N32: 0.176 | O32: 0.198 | P32: 0.12 | R32: 0.105 | S32: 0.164 | T32: 0.214 | U32: 0.122 | W32: =W31/W23 -> 0.097667638 | X32: =X31/X23 -> 0.17589389 | Y32: =Y31/Y23 -> #DIV/0! | Z32: =Z31/Z23 -> #DIV/0!
B33: RevPAR (SEK) | C33: 482 | D33: 783 | E33: 914 | F33: 679 | H33: 635 | I33: 779 | J33: 947 | K33: 686 | M33: 622 | N33: 860 | O33: 973 | P33: 731 | R33: 709 | S33: 911 | T33: 1029 | U33: 753 | W33: 735 | X33: 912
B34: y/y | H34: =(H33-C33)/C33 -> 0.31742739 | I34: =(I33-D33)/D33 -> -0.0051085568 | J34: =(J33-E33)/E33 -> 0.036105033 | K34: =(K33-F33)/F33 -> 0.010309278 | M34: =(M33-H33)/H33 -> -0.020472441 | N34: =(N33-I33)/I33 -> 0.10397946 | O34: =(O33-J33)/J33 -> 0.027455121 | P34: =(P33-K33)/K33 -> 0.065597668 | R34: =(R33-M33)/M33 -> 0.13987138 | S34: =(S33-N33)/N33 -> 0.059302326 | T34: =(T33-O33)/O33 -> 0.057553957 | U34: =(U33-P33)/P33 -> 0.030095759 | W34: =(W33-R33)/R33 -> 0.036671368 | X34: =(X33-S33)/S33 -> 0.0010976948 | Y34: =(Y33-T33)/T33 -> -1 | Z34: =(Z33-U33)/U33 -> -1
B35: Currency effect | C35: 32 | D35: 35 | E35: 56 | F35: 26 | H35: -23 | I35: -46 | J35: -25 | K35: -48 | M35: -20 | N35: 4 | O35: -51 | P35: -4 | R35: -18 | S35: -38 | T35: -40 | U35: -31 | W35: -18 | X35: 43
B36: New hotels/Temporarily closed /exits | C36: 0 | D36: 2 | E36: -1 | F36: -4 | H36: 0 | I36: 24 | J36: 27 | K36: 10 | M36: 2 | N36: 0 | O36: -9 | P36: 6 | R36: -4 | S36: -4 | T36: -12 | U36: 13 | W36: 45 | X36: -1
B37: LFL | C37: 274 | D37: 418 | E37: 184 | F37: 155 | H37: 176 | I37: 19 | J37: 31 | K37: 45 | M37: 5 | N37: 77 | O37: 86 | P37: 43 | R37: 102 | S37: 88 | T37: 99 | U37: 39 | W37: -2 | X37: -42
B38: ARR (SEK) | C38: 1070 | D38: 1230 | E38: 1289 | F38: 1248 | H38: 1197 | I38: 1283 | J38: 1329 | K38: 1241 | M38: 1204 | N38: 1350 | O38: 1351 | P38: 1258 | R38: 1227 | S38: 1375 | T38: 1375 | U38: 1300 | W38: 1295 | X38: 1446
B39: y/y | H39: =(H38-C38)/C38 -> 0.11869159 | I39: =(I38-D38)/D38 -> 0.043089431 | J39: =(J38-E38)/E38 -> 0.031031808 | K39: =(K38-F38)/F38 -> -0.0056089744 | M39: =(M38-H38)/H38 -> 0.0058479532 | N39: =(N38-I38)/I38 -> 0.052221356 | O39: =(O38-J38)/J38 -> 0.0165538 | P39: =(P38-K38)/K38 -> 0.01369863 | R39: =(R38-M38)/M38 -> 0.01910299 | S39: =(S38-N38)/N38 -> 0.018518519 | T39: =(T38-O38)/O38 -> 0.017764619 | U39: =(U38-P38)/P38 -> 0.033386328 | W39: =(W38-R38)/R38 -> 0.055419723 | X39: =(X38-S38)/S38 -> 0.051636364 | Y39: =(Y38-T38)/T38 -> -1 | Z39: =(Z38-U38)/U38 -> -1
B40: OCC% | C40: 0.45 | D40: 0.636 | E40: 0.709 | F40: 0.544 | H40: 0.531 | I40: 0.607 | J40: 0.713 | K40: 0.553 | M40: 0.516 | N40: 0.637 | O40: 0.721 | P40: 0.581 | R40: 0.578 | S40: 0.663 | T40: 0.748 | U40: 0.579 | W40: 0.568 | X40: 0.63
B42: Finland | AD42: ARR: | AE42: Average roomrate
B43: Net sales | C43: 562 | D43: 1074 | E43: 1257 | F43: 1196 | G43: =SUM(C43:F43) -> 4089 | H43: 1053 | I43: 1264 | J43: 1397 | K43: 1283 | L43: =SUM(H43:K43) -> 4997 | M43: 1061 | N43: 1246 | O43: 1311 | P43: 1265 | Q43: =SUM(M43:P43) -> 4883 | R43: 1037 | S43: 1156 | T43: 1212 | U43: 1147 | V43: =SUM(R43:U43) -> 4552 | W43: 986 | X43: 1051 | AA43: =SUM(W43:Z43) -> 2037
...

Sheet Nøkkeltall
D4: 2026 | E4: 2027 | F4: 2028
C5: EV/EBIT | D5: =Modell!$B$9/Modell!AK15 -> 6.0850156 | E5: =Modell!$B$9/Modell!AL15 -> 4.2922986 | F5: =Modell!$B$9/Modell!AM15 -> 4.0685294
C6: P/E | D6: =Modell!$B$4/Modell!AK21 -> 18.276371 | E6: =Modell!$B$4/Modell!AL21 -> 10.539589 | F6: =Modell!$B$4/Modell!AM21 -> 9.9427283

Sheet Nedsidebergning
A3: Nedside | D3: FY 2015 | E3: FY 2016 | F3: FY 2017 | G3: FY 2018 | H3: FY 2019 | I3: FY 2020 | J3: FY 2021 | K3: FY 2022 | L3: FY 2023 | M3: FY 2024 | N3: FY 2025 | O3: FY 2026 | P3: FY 2027 | Q3: FY 2028 | R3: FY 2029 | S3: FY 2030 | T3: FY 2031 | U3: FY 2032 | V3: FY 2033 | W3: FY 2034 | X3: FY 2035
A4: Nullvekst og konstante marginer | C4: Net sales | H4: 18945 | I4: 7470 | J4: 10086 | K4: 19230 | L4: 21935 | M4: 21959 | N4: 22288 | O4: =N4*1 -> 22288 | P4: =O4*1 -> 22288 | Q4: =P4*1 -> 22288 | R4: =Q4*1 -> 22288 | S4: =R4*1 -> 22288 | T4: =S4*1 -> 22288 | U4: =T4*1 -> 22288 | V4: =U4*1 -> 22288 | ... X4: =W4*1 -> 22288
A5: =AA25 -> 34.425825 | C5: Other income | H5: 0 | I5: 0 | J5: 44 | K5: 3 | L5: 20 | M5: 0 | N5: 0 | O5: 0 | P5: 0 | Q5: 0 | R5: 0 | S5: 0 | T5: 0 | U5: 0 | V5: 0 | W5: 0 | X5: 0
A6: =AA26 -> -0.60656199 | C6: Total income | D6: 12208 | E6: 13095 | F6: 14583 | G6: 18007 | H6: =SUM(H4:H5) -> 18945 | I6: =SUM(I4:I5) -> 7470 | J6: =SUM(J4:J5) -> 10130 | K6: =SUM(K4:K5) -> 19233 | L6: =SUM(L4:L5) -> 21955 | M6: =SUM(M4:M5) -> 21959 | N6: =SUM(N4:N5) -> 22288 | O6: =SUM(O4:O5) -> 22288 | ... X6: =SUM(X4:X5) -> 22288
C7: Raw materials and consumables | H7: -1634 | I7: -611 | J7: -839 | K7: -1495 | L7: -1698 | M7: -1634 | N7: -1637 | O7: =N7*1 -> -1637 | P7: =O7*1 -> -1637 | Q7: =P7*1 -> -1637 | R7: =Q7*1 -> -1637 | S7: =R7*1 -> -1637 | T7: =S7*1 -> -1637 | U7: =T7*1 -> -1637 | V7: =U7*1 -> -1637 | ... X7: =W7*1 -> -1637
C8: Other external costs | H8: -4335 | I8: -1751 | J8: -2248 | K8: -3854 | L8: -4538 | M8: -4454 | N8: -4614 | O8: =N8*1 -> -4614 | P8: =O8*1 -> -4614 | Q8: =P8*1 -> -4614 | R8: =Q8*1 -> -4614 | S8: =R8*1 -> -4614 | T8: =S8*1 -> -4614 | U8: =T8*1 -> -4614 | V8: =U8*1 -> -4614 | ... X8: =W8*1 -> -4614
C9: Staff costs | H9: -5869 | I9: -3489 | J9: -3597 | K9: -5957 | L9: -6882 | M9: -6948 | N9: -7025 | O9: =N9*1 -> -7025 | P9: =O9*1 -> -7025 | Q9: =P9*1 -> -7025 | R9: =Q9*1 -> -7025 | S9: =R9*1 -> -7025 | T9: =S9*1 -> -7025 | U9: =T9*1 -> -7025 | V9: =U9*1 -> -7025 | ... X9: =W9*1 -> -7025
C10: Rental costs | H10: =-74-1696 -> -1770 | I10: =492-424 -> 68 | J10: =79-780 -> -701 | K10: =-159-1792 -> -1951 | L10: -2209 | M10: -2157 | N10: -2230 | O10: =N10*1 -> -2230 | P10: =O10*1 -> -2230 | Q10: =P10*1 -> -2230 | R10: =Q10*1 -> -2230 | S10: =R10*1 -> -2230 | T10: =S10*1 -> -2230 | U10: =T10*1 -> -2230 | V10: =U10*1 -> -2230 | ... X10: =W10*1 -> -2230
C11: Pre-opening costs | H11: -81 | I11: -32 | J11: -52 | K11: -131 | L11: -17 | M11: -28 | N11: -75 | O11: =N11*1 -> -75 | P11: =O11*1 -> -75 | Q11: =P11*1 -> -75 | R11: =Q11*1 -> -75 | S11: =R11*1 -> -75 | T11: =S11*1 -> -75 | U11: =T11*1 -> -75 | V11: =U11*1 -> -75 | ... X11: =W11*1 -> -75
C12: Items affecting comparability | H12: 169 | I12: -269 | J12: 7 | K12: -16 | L12: -14 | M12: -18 | N12: -51 | O12: =N12*1 -> -51 | P12: =O12*1 -> -51 | Q12: =P12*1 -> -51 | R12: =Q12*1 -> -51 | S12: =R12*1 -> -51 | T12: =S12*1 -> -51 | U12: =T12*1 -> -51 | V12: =U12*1 -> -51 | ... X12: =W12*1 -> -51
C13: A/D/I | H13: -3281 | I13: -6187 | J13: -3139 | K13: -3372 | L13: -3812 | M13: -3884 | N13: -3996 | O13: =N13*1 -> -3996 | P13: =O13*1 -> -3996 | Q13: =P13*1 -> -3996 | R13: =Q13*1 -> -3996 | S13: =R13*1 -> -3996 | T13: =S13*1 -> -3996 | U13: =T13*1 -> -3996 | V13: =U13*1 -> -3996 | ... X13: =W13*1 -> -3996
C14: Total Opex | D14: =D15-D6 -> -11595 | E14: =E15-E6 -> -12170 | F14: =F15-F6 -> -13658 | G14: =G15-G6 -> -17024 | H14: =SUM(H7:H13) -> -16801 | I14: =SUM(I7:I13) -> -12271 | J14: =SUM(J7:J13) -> -10569 | K14: =SUM(K7:K13) -> -16776 | L14: =SUM(L7:L13) -> -19170 | M14: =SUM(M7:M13) -> -19123 | N14: =SUM(N7:N13) -> -19628 | O14: =SUM(O7:O13) -> -19628 | ... X14: =SUM(X7:X13) -> -19628
C15: Operating profit EBIT | D15: 613 | E15: 925 | F15: 925 | G15: 983 | H15: =H6+H14 -> 2144 | I15: =I6+I14 -> -4801 | J15: =J6+J14 -> -439 | K15: =K6+K14 -> 2457 | L15: =L6+L14 -> 2785 | M15: =M6+M14 -> 2836 | N15: =SUM(N6:N13) -> 2660 | O15: =SUM(O6:O13) -> 2660 | P15: =SUM(P6:P13) -> 2660 | Q15: =SUM(Q6:Q13) -> 2660 | R15: =SUM(R6:R13) -> 2660 | S15: =SUM(S6:S13) -> 2660 | T15: =SUM(T6:T13) -> 2660 | U15: =SUM(U6:U13) -> 2660 | ... X15: =SUM(X6:X13) -> 2660
C16: Net financial items | H16: -1242 | I16: -1281 | J16: -1606 | K16: -1808 | L16: -2064 | M16: -1975 | N16: -1853 | O16: =N16 -> -1853 | P16: =O16 -> -1853 | Q16: =P16 -> -1853 | R16: =Q16 -> -1853 | S16: =R16 -> -1853 | T16: =S16 -> -1853 | U16: =T16 -> -1853 | V16: =U16 -> -1853 | ... X16: =W16 -> -1853
C17: PTP | D17: 115 | E17: 1057 | F17: 800 | G17: 810 | H17: =SUM(H15:H16) -> 902 | I17: =SUM(I15:I16) -> -6082 | J17: =SUM(J15:J16) -> -2045 | K17: =SUM(K15:K16) -> 649 | L17: =SUM(L15:L16) -> 721 | M17: =SUM(M15:M16) -> 861 | N17: =SUM(N15:N16) -> 807 | O17: =SUM(O15:O16) -> 807 | ... X17: =SUM(X15:X16) -> 807
C18: Tax | D18: 5 | E18: -175 | F18: -90 | G18: -131 | H18: -177 | I18: 130 | J18: 367 | K18: -221 | L18: -152 | M18: -209 | N18: -185 | O18: =O17*-0.22 -> -177.54 | P18: =P17*-0.22 -> -177.54 | Q18: =Q17*-0.22 -> -177.54 | R18: =R17*-0.22 -> -177.54 | S18: =S17*-0.22 -> -177.54 | T18: =T17*-0.22 -> -177.54 | U18: =U17*-0.22 -> -177.54 | V18: =V17*-0.22 -> -177.54 | ... X18: =X17*-0.22 -> -177.54
C19: Net income | D19: 120 | E19: 882 | F19: 711 | G19: 678 | H19: =SUM(H17:H18) -> 725 | I19: =SUM(I17:I18) -> -5952 | J19: =SUM(J17:J18) -> -1678 | K19: =SUM(K17:K18) -> 428 | L19: =SUM(L17:L18) -> 569 | M19: =SUM(M17:M18) -> 652 | N19: =SUM(N17:N18) -> 622 | O19: =SUM(O17:O18) -> 629.46 | ... X19: =SUM(X17:X18) -> 629.46 | Y19: =X19*(1+$AA$22) -> 623.1654 | Z19: =Y19*(1+$AA$22) -> 616.93375 | AA19: =Z19*(1+$AA$22) -> 610.76441 | AB19: =AA19*(1+$AA$22) -> 604.65676 | AC19: =AB19*(1+$AA$22) -> 598.6102 | AD19: =AC19*(1+$AA$22) -> 592.62409 | AE19: =AD19*(1+$AA$22) -> 586.69785 | AF19: =AE19*(1+$AA$22) -> 580.83088 | ... EC19: =EB19*(1+$AA$22) -> 210.47686
C20: Shares | D20: 103.00627 | E20: 103.00627 | F20: 103.00627 | G20: 103.00627 | H20: 103.00627 | I20: 148.61881 | J20: 191.25069 | K20: 191.27707 | L20: 191.30412 | M20: 203.61442 | N20: 215.1273 | O20: 215.1273 | P20: 215.1273 | Q20: 215.1273 | R20: 215.1273 | S20: 215.1273 | T20: 215.1273 | U20: 215.1273 | V20: 215.1273 | W20: 215.1273 | X20: 215.1273
C21: EPS | D21: =D19/D20 -> 1.1649777 | E21: =E19/E20 -> 8.5625858 | F21: =F19/F20 -> 6.9024926 | G21: =G19/G20 -> 6.5821238 | H21: =H19/H20 -> 7.0384067 | I21: =I19/I20 -> -40.048768 | J21: =J19/J20 -> -8.7738247 | K21: =K19/K20 -> 2.2375917 | ... X21: =X19/X20 -> 2.9259885 | Z21: Discount | AA21: 0.08
Z22: TV | AA22: -0.01
C23: Revenue y/y | E23: =(E6-D6)/D6 -> 0.072657274 | F23: =(F6-E6)/E6 -> 0.11363116 | G23: =(G6-F6)/F6 -> 0.23479394 | H23: =(H6-G6)/G6 -> 0.052090854 | I23: =(I6-H6)/H6 -> -0.60570071 | J23: =(J6-I6)/I6 -> 0.35609103 | K23: =(K6-J6)/J6 -> 0.89861797 | L23: =(L6-K6)/K6 -> 0.14152758 | ... X23: =(X6-W6)/W6 -> 0 | Z23: NPV | AA23: =NPV(AA21,N19:EC19) -> 7456.1699
C24: Opex y/y | D24: =(D14-C14)/C14 -> #VALUE! | E24: =(E14-D14)/D14 -> 0.049590341 | F24: =(F14-E14)/E14 -> 0.12226787 | G24: =(G14-F14)/F14 -> 0.24644897 | H24: =(H14-G14)/G14 -> -0.013099154 | I24: =(I14-H14)/H14 -> -0.26962681 | J24: =(J14-I14)/I14 -> -0.138701 | K24: =(K14-J14)/J14 -> 0.58728357 | ... X24: =(X14-W14)/W14 -> 0 | Z24: S/O | AA24: 216.58652
C25: EBIT margin | D25: =D15/D6 -> 0.050212975 | E25: =E15/E6 -> 0.070637648 | F25: =F15/F6 -> 0.063430021 | G25: =G15/G6 -> 0.054589882 | H25: =H15/H6 -> 0.1131697 | I25: =I15/I6 -> -0.64270415 | J25: =J15/J6 -> -0.043336624 | K25: =K15/K6 -> 0.12774918 | ... X25: =X15/X6 -> 0.11934673 | Z25: NPV/Share | AA25: =AA23/AA24 -> 34.425825
C26: ROE | D26: =D19/6205 -> 0.019339243 | E26: =E19/7103 -> 0.12417288 | F26: =F19/7356 -> 0.096655791 | G26: =G19/7805 -> 0.086867393 | H26: =H19/6601 -> 0.10983184 | I26: =I19/2071 -> -2.8739739 | J26: =J19/1155 -> -1.4528139 | Z26: Opp-/nedside | AA26: =(AA25-Modell!B4)/Modell!B4 -> -0.60656199
