Workbook

Sheet Info
H1: Norge:
H2: FINN: En av norges største markedsplasser. Brukes til kjøp og salg av eiendom, jobbannonser, biler, småting (recommerce) osv
H3: Nettbil: Salg av bruktbil. Brukeren registrerer bilen, og bilforhandlere byr på den
H4: Wheelaway: Fleksibelt bilabonnementsløsning
H6: Sverige: | N6: Danmark: | U6: Tilbakekjøpsprogram
H7: Blocket: Svensk FINN | N7: dba (Den blå avis): Danmarks største markedsplass for bruktvarer. Dansk FINN? | U7: Dato kjøp | V7: Antall aksjer | W7: Akummelert antall aksjer | X7: Kjøp | Y7: Akkumelert kjøp
H8: Qasa: Leie av bolig | N8: Bilbasen: Danmarks ledende markedsplass for kjøp og salg av nye og ubrukte biler | U8: 45993 | V8: 285500 | W8: =V8 -> 285500 | X8: 80545390 | Y8: =X8 -> 80545390
H9: HomeQ: Søke og leie boliger fra profesjonelle utleiere | U9: 45999 | V9: 337500 | W9: =SUM(V8:V9) -> 623000 | X9: =184167334-X8 -> 103621944 | Y9: =SUM(X8:X9) -> 184167334
U10: 46006 | V10: 311000 | W10: =SUM(V8:V10) -> 934000 | X10: =272941684-Y9 -> 88774350 | Y10: =SUM(X8:X10) -> 272941684
H11: Finland: | U11: 46011 | V11: 499000 | W11: =SUM(V8:V11) -> 1433000 | X11: =407677083-Y10 -> 134735399 | Y11: =SUM(X8:X11) -> 407677083
H12: Tori: Finsk FINN | U12: 46020 | V12: 167000 | W12: =SUM(V8:V12) -> 1600000 | X12: =452156033-Y11 -> 44478950 | Y12: =SUM(X8:X12) -> 452156033
H13: Oikotie: Markedsplass for jobb og eiendom | U13: 46027 | V13: 69503 | W13: =SUM(V8:V13) -> 1669503 | X13: =471443676-Y12 -> 19287643 | Y13: =SUM(X8:X13) -> 471443676
H14: Autovex: Kjøp og salg av bruktbil | U14: 46034 | V14: 215459 | W14: =SUM(V8:V149) -> 18750530 | X14: =532167563-Y13 -> 60723887 | Y14: =SUM(X8:X14) -> 532167563
A15: Etter at Schibsted solgte ut news media i 2024, har de begynt ferden | U15: 46041 | V15: 389822 | W15: =SUM(V8:V15) -> 2274784 | X15: =645088863-Y14 -> 112921300 | Y15: =SUM(X8:X15) -> 645088863
A16: mot et rendyrket marketplace selskap. | U16: 46048 | V16: 379473 | W16: =SUM(V8:V16) -> 2654257 | X16: =752136480-Y15 -> 107047617 | Y16: =SUM(X8:X16) -> 752136480
U17: 46055 | V17: 460917 | W17: =SUM(V8:V17) -> 3115174 | X17: =879219174-Y16 -> 127082694 | Y17: =SUM(X8:X17) -> 879219174
A18: Mobility: Kobler kjøpere og selgere av brukte biler gjennom ledende digitale markedsplasser for å gjøre mobilitetsvalg enklere og mer transaprente | N18: Mobility | O18: Jobs | P18: Real estate | Q18: Recommerce | R18: Delivery | U18: 46062 | V18: 487000 | W18: =SUM(V8:V18) -> 3602174 | X18: =1003542299-Y17 -> 124323125 | Y18: =SUM(X8:X18) -> 1003542299
A19: Jobs: Matcher arbeidstakere med givere, og støtter rekutterere med innovative løsninger. | N19: FINN | O19: FINN | P19: FINN | Q19: FINN | R19: Helthjem | U19: 46069 | V19: 495753 | W19: =SUM(V8:V19) -> 4097927 | X19: =1131670018-Y18 -> 128127719 | Y19: =SUM(X8:X19) -> 1131670018
A20: Real estate: Smarte boligvalg gjennom digitale plattformer for kjøp, salg og utleie av eiendom. | N20: Blocket | O20: Blocket | P20: Oikotie | Q20: Blocket | U20: 46076 | V20: 510000 | W20: =SUM(V8:V20) -> 4607927 | X20: =1251319546-Y19 -> 119649528 | Y20: =SUM(X8:X20) -> 1251319546
A21: Recommerce: Fremmer gjenbruk hvor folk kan kjøpe og selge brukte varer på en bærekraftig og enkel måte. | N21: Nettbil | P21: Qasa | Q21: Tori | U21: 46083 | V21: 525000 | W21: =SUM(V8:V21) -> 5132927 | X21: =1373166827-Y20 -> 121847281 | Y21: =SUM(X8:X21) -> 1373166827
A22: Delivery: Distribusjon og netthandel-levering med fokus på dør-til-dør tjenester for både medier og varer | N22: Bilbasen | P22: HomeQ | Q22: DBA | U22: 46090 | V22: 560000 | W22: =SUM(V8:V22) -> 5692927 | X22: =1510767923-Y21 -> 137601096 | Y22: =SUM(X8:X22) -> 1510767923
N23: AutoVex | U23: 46097 | V23: 458492 | W23: =SUM(V8:V23) -> 6151419 | X23: =1629012853-Y22 -> 118244930 | Y23: =SUM(X8:X23) -> 1629012853
N24: dba | U24: 46104 | V24: 529856 | W24: =SUM(V8:V24) -> 6681275 | X24: =1761497962-Y23 -> 132485109 | Y24: =SUM(X8:X24) -> 1761497962
N25: Bilinfo | U25: 46111 | V25: 521708 | W25: =SUM(V8:V25) -> 7202983 | X25: =1885232872-Y24 -> 123734910 | Y25: =SUM(X8:X25) -> 1885232872
A26: Press releases: | N26: bytbil | U26: 46119 | V26: 300000 | W26: =SUM(V8:V26) -> 7502983 | X26: =1956441444-Y25 -> 71208572 | Y26: =SUM(X8:X26) -> 1956441444
A27: 28.09.26: Vend kjøper tilbake 500 000 aksjer | N27: Carweb
A28: 21.09.26: Vend kjøper tilbake 420 000 aksjer | T28: Transje 1 | U28: 46153 | V28: 770000 | W28: =V28 -> 770000 | X28: 192208337 | Y28: =X28 -> 192208337
A29: 14.09.26: Vend kjøper tilbake 328 000 aksjer | U29: 46160 | V29: 619000 | W29: =SUM(V28:V29) -> 1389000 | X29: =341582292-Y28 -> 149373955 | Y29: =SUM(X28:X29) -> 341582292
A30: 07.09.26. Vend kjøper tilbake 286 000 aksjer | U30: 46168 | V30: 725000 | W30: =SUM(V28:V30) -> 2114000 | X30: 177335022 | Y30: =SUM(X28:X30) -> 518917314
A31: 31.08.26: Vend kjøper tilbake 210 000 aksjer | U31: 46174 | V31: 500000 | W31: =SUM(V28:V31) -> 2614000 | X31: 120735826 | Y31: =SUM(X28:X31) -> 639653140
A32: 24.08.26: Vend kjøper tilbake 400 000 aksjer | U32: 46181 | V32: 677000 | W32: =SUM(V28:V32) -> 3291000 | X32: 160627648 | Y32: =SUM(X28:X32) -> 800280788
A33: 17.08.26: Vend kjøper tilbake 591 000 aksjer | U33: 46188 | V33: 677000 | W33: =SUM(V28:V33) -> 3968000 | X33: 163700945 | Y33: =SUM(X28:X33) -> 963981733
A34: 11.08.26: Vend kjøper tilbake 263 000 aksjer | U34: 46195 | V34: 614000 | W34: =SUM(V29:V34) -> 3812000 | X34: 148378751 | Y34: =SUM(X28:X34) -> 1112360484
A35: 06.08.26: Vend starter andre transje av tilbakekjøpsprogrammet | U35: 46202 | V35: 631000 | W35: =SUM(V28:V35) -> 5213000 | X35: 151084102 | Y35: =SUM(X28:X35) -> 1263444586
A36: 06.08.26: Vend kjøper tilbake 175 547 aksjer og fullfører første transje av tilbakekjøpsprogrammet | U36: 46209 | V36: 637000 | W36: =SUM(V28:V36) -> 5850000 | X36: 154597651 | Y36: =SUM(X28:X36) -> 1418042237
A37: 03.08.26: Vend kjøper tilbake 560 000 aksjer | U37: 46216 | V37: 682000 | W37: =SUM(V28:V37) -> 6532000 | X37: 166493018 | Y37: =SUM(X28:X37) -> 1584535255
A38: 27.07.26: Vend kjøper tilbake 603 000 aksjer | U38: 46223 | V38: 397000 | W38: =SUM(V28:V38) -> 6929000 | X38: 96960234 | Y38: =SUM(X28:X38) -> 1681495489
A39: 20.07.26: Vend kjøper tilbake 397 000 aksjer | U39: 46230 | V39: 603000 | W39: =SUM(V28:V39) -> 7532000 | X39: 142546014 | Y39: =SUM(X28:X39) -> 1824041503
A40: 13.07.26: Vend kjøper tilbake 682 000 aksjer | U40: 46237 | V40: 560000 | W40: =SUM(V28:V40) -> 8092000 | X40: 133057783 | Y40: =SUM(X28:X40) -> 1957099286
A41: 06.07.26: Vend kjøper tilbake 637 000 aksjer | U41: 46240 | V41: 175547 | W41: =SUM(V28:V41) -> 8267547 | X41: 42900586 | Y41: =SUM(X28:X41) -> 1999999872
...

Sheet Modell
A3: Kapitalstruktur | C3: NOK million | D3: Q122 | E3: Q222 | F3: Q322 | G3: Q422 | H3: Q123 | I3: Q223 | J3: Q323 | K3: Q423 | L3: Q124 | M3: Q224 | N3: Q324 | O3: Q424 | P3: Q125 | Q3: Q225 | R3: Q325 | S3: Q425 | T3: Q126 | U3: Q226 | V3: Q326 | W3: Q426 | Z3: FY 2019 | AA3: FY 2020 | AB3: FY 2021 | AC3: FY 2022 | AD3: FY 2023 | AE3: FY 2024 | AF3: FY 2025 | AG3: FY 2026 | AH3: FY 2027 | AI3: FY 2028 | AJ3: FY 2029 | AK3: FY 2030 | AL3: FY 2031 | AM3: FY 2032 | AN3: FY 2033 | AO3: FY 2034 | AP3: FY 2035
A4: Price | B4: 205 | C4: Mobility | D4: 427 | E4: 493 | F4: 500 | G4: 475 | H4: 485 | I4: 599 | J4: 572 | K4: 550 | L4: 551 | M4: 633 | N4: 620 | O4: 559 | P4: 556 | Q4: 676 | R4: 678 | S4: 627 | T4: 573 | U4: 682 | AF4: 2537 | AG4: =AF4*1.02 -> 2587.74 | AH4: =AG4*1.05 -> 2717.127 | AI4: =AH4*1.08 -> 2934.4972
A5: S/O (m) | B5: 195.9 | C5: Real estate | D5: 177 | E5: 226 | F5: 221 | G5: 206 | H5: 216 | I5: 295 | J5: 280 | K5: 236 | L5: 250 | M5: 341 | N5: 316 | O5: 263 | P5: 301 | Q5: 379 | R5: 345 | S5: 302 | T5: 341 | U5: 431 | AF5: 1327 | AG5: =AF5*1.13 -> 1499.51 | AH5: =AG5*1.14 -> 1709.4414 | AI5: =AH5*1.14 -> 1948.7632
A6: MC NOKm | B6: =B4*B5 -> 40159.5 | C6: Jobs | D6: 397 | E6: 367 | F6: 312 | G6: 324 | H6: 375 | I6: 329 | J6: 288 | K6: 296 | L6: 349 | M6: 321 | N6: 281 | O6: 270 | P6: 314 | Q6: 286 | R6: 247 | S6: 271 | T6: 340 | U6: 301 | AF6: 1118 | AG6: =AF6*1.06 -> 1185.08 | AH6: =AG6*1.1 -> 1303.588 | AI6: =AH6*1.1 -> 1433.9468
A7: Cash NOKm | B7: =U59 -> 4222 | C7: Recommerce | D7: 131 | E7: 134 | F7: 125 | G7: 158 | H7: 155 | I7: 173 | J7: 180 | K7: 208 | L7: 190 | M7: 201 | N7: 210 | O7: 224 | P7: 180 | Q7: 192 | R7: 207 | S7: 234 | T7: 223 | U7: 237 | AF7: 813 | AG7: =AF7*1.23 -> 999.99 | AH7: =AG7*1.2 -> 1199.988 | AI7: =AH7*1.2 -> 1439.9856
A8: Debt NOKm | B8: =U68+U71 -> 2244 | C8: Delivery | D8: 477 | E8: 413 | F8: 425 | G8: 506 | H8: 471 | I8: 428 | J8: 410 | K8: 443 | L8: 430 | M8: 469 | N8: 599 | O8: 625 | P8: 535 | Q8: 0 | R8: 0 | S8: 0 | T8: 0 | U8: 0 | V8: 0 | W8: 0 | AG8: 0 | AH8: 0 | AI8: 0 | AJ8: 0 | AK8: 0 | AL8: 0 | AM8: 0 | AN8: 0 | AO8: 0 | AP8: 0
A9: EV NOKm | B9: =B6-B7+B8 -> 38181.5 | C9: Other/HQ | D9: 450 | E9: 487 | F9: 537 | G9: 562 | H9: 458 | I9: 523 | J9: 496 | K9: 302 | L9: 299 | M9: 453 | N9: 496 | O9: 334 | P9: 171 | Q9: 170 | R9: 123 | S9: 83 | T9: 63 | U9: 45 | AF9: 546 | AG9: 0 | AH9: 0 | AI9: 0
C10: Eliminations | D10: 1489 | E10: 1760 | F10: 1636 | G10: 1757 | H10: 1634 | I10: 109 | J10: 133 | K10: -146 | L10: -153 | M10: 107 | N10: 85 | O10: -171 | P10: -42 | Q10: -8 | R10: -6 | S10: -6 | T10: 0 | AF10: -24 | AG10: -20 | AH10: -10 | AI10: -10 | AJ10: -10 | AK10: -10 | AL10: -10 | AM10: -10 | AN10: -10 | AO10: -10 | AP10: -10
C11: Operating revenue | D11: =SUM(D4:D10) -> 3548 | E11: =SUM(E4:E10) -> 3880 | F11: =SUM(F4:F10) -> 3756 | G11: =SUM(G4:G10) -> 3988 | H11: =SUM(H4:H10) -> 3794 | I11: =SUM(I4:I10) -> 2456 | J11: =SUM(J4:J10) -> 2359 | K11: =SUM(K4:K10) -> 1889 | ... S11: =SUM(S4:S10) -> 1511 | T11: 1543 | U11: 1696 | V11: =SUM(V4:V10) -> 0 | W11: =SUM(W4:W10) -> 0 | Z11: 12653 | AA11: 12908 | AB11: 14623 | AC11: 15272 | AD11: 7617 | AE11: 8325 | AF11: =SUM(AF4:AF10) -> 6317 | AG11: =SUM(AG4:AG10) -> 6252.32 | AH11: =SUM(AH4:AH10) -> 6920.1444 | AI11: =SUM(AI4:AI10) -> 7747.1928 | AJ11: =AI11*1.14 -> 8831.7997 | AK11: =AJ11*1.14 -> 10068.252 | AL11: =AK11*1.14 -> 11477.807 | AM11: =AL11*1.14 -> 13084.7 | AN11: =AM11*1.14 -> 14916.558 | AO11: =AN11*1.14 -> 17004.876 | AP11: =AO11*1.14 -> 19385.559
A12: P/B | B12: =B4/(U65/B5) -> 2.4432378 | C12: COGS | D12: -148 | E12: -138 | F12: -125 | G12: -139 | H12: -125 | I12: -23 | J12: -23 | K12: -139 | L12: -137 | M12: -20 | N12: -19 | O12: -173 | P12: -157 | Q12: -139 | R12: -145 | S12: -166 | T12: -136 | U12: -144 | Z12: -416 | AA12: -454 | AB12: -531 | AC12: -549 | AD12: -493 | AE12: -599 | AF12: -595 | AG12: =AG11*-0.09 -> -562.7088 | AH12: =AH11*-0.09 -> -622.813 | AI12: =AI11*-0.09 -> -697.24735 | AJ12: =AJ11*-0.09 -> -794.86198 | AK12: =AK11*-0.09 -> -906.14265 | AL12: =AL11*-0.09 -> -1033.0026 | AM12: =AM11*-0.09 -> -1177.623 | AN12: =AN11*-0.09 -> -1342.4902 | ... AP12: =AP11*-0.09 -> -1744.7003
C13: Gross profit | D13: =SUM(D11:D12) -> 3400 | E13: =SUM(E11:E12) -> 3742 | F13: =SUM(F11:F12) -> 3631 | G13: =SUM(G11:G12) -> 3849 | H13: =SUM(H11:H12) -> 3669 | I13: =SUM(I11:I12) -> 2433 | J13: =SUM(J11:J12) -> 2336 | K13: =SUM(K11:K12) -> 1750 | ... U13: =SUM(U11:U12) -> 1552 | Z13: =SUM(Z11:Z12) -> 12237 | AA13: =SUM(AA11:AA12) -> 12454 | AB13: =SUM(AB11:AB12) -> 14092 | AC13: =SUM(AC11:AC12) -> 14723 | AD13: =SUM(AD11:AD12) -> 7124 | AE13: =SUM(AE11:AE12) -> 7726 | AF13: =SUM(AF11:AF12) -> 5722 | AG13: =SUM(AG11:AG12) -> 5689.6112 | ... AP13: =SUM(AP11:AP12) -> 17640.858
A14: Gearing | B14: =(B8-B7)/AG17 -> -0.8179769 | C14: Personnel expenses | D14: -1453 | E14: -1534 | F14: -1389 | G14: -1554 | H14: -1572 | I14: -839 | J14: -750 | K14: -703 | L14: -731 | M14: -866 | N14: -797 | O14: -755 | P14: -715 | Q14: -483 | R14: -394 | S14: -463 | T14: -486 | U14: -493 | Z14: -4793 | AA14: -4905 | AB14: -5486 | AC14: -5929 | AD14: -2669 | AE14: -2859 | AF14: -1819 | AG14: =AF14*0.91 -> -1655.29 | AH14: =AG14*1.015 -> -1680.1193 | AI14: =AH14*1 -> -1680.1193 | AJ14: =AI14*1 -> -1680.1193 | AK14: =AJ14*1.1 -> -1848.1313 | AL14: =AK14*1.1 -> -2032.9444 | AM14: =AL14*1.1 -> -2236.2389 | AN14: =AM14*1.1 -> -2459.8627 | AO14: =AN14*1.1 -> -2705.849 | AP14: =AO14*1.1 -> -2976.4339
C15: Marketing expenses | D15: -1566 | E15: -1589 | F15: -1587 | G15: -1645 | H15: -1656 | I15: -1056 | J15: -1013 | K15: -105 | L15: -126 | M15: -1093 | N15: -1121 | O15: -112 | P15: -98 | Q15: -102 | R15: -117 | S15: -90 | T15: -101 | U15: -125 | Z15: -5467 | AA15: -5422 | AB15: -5865 | AC15: -6387 | AD15: -447 | AE15: -513 | AF15: -401 | AG15: =AF15*0.91 -> -364.91 | AH15: =AG15*1.015 -> -370.38365 | AI15: =AH15*1 -> -370.38365 | AJ15: =AI15*1 -> -370.38365 | AK15: =AJ15*1.1 -> -407.42202 | AL15: =AK15*1.1 -> -448.16422 | AM15: =AL15*1.1 -> -492.98064 | AN15: =AM15*1.1 -> -542.2787 | AO15: =AN15*1.1 -> -596.50657 | AP15: =AO15*1.1 -> -656.15723
C16: Other opex | D16: 0 | E16: 0 | F16: 0 | G16: 0 | H16: 0 | I16: 0 | J16: 0 | K16: -616 | L16: -589 | M16: 0 | N16: 0 | O16: -727 | P16: -650 | Q16: -386 | R16: -299 | S16: -300 | T16: -258 | U16: -260 | Z16: 0 | AA16: 0 | AB16: 0 | AC16: 0 | AD16: -2419 | AE16: -2657 | AF16: -1375 | AG16: =AF16*0.91 -> -1251.25 | AH16: =AG16*1.015 -> -1270.0187 | AI16: =AH16*1 -> -1270.0187 | AJ16: =AI16*1 -> -1270.0187 | AK16: =AJ16*1.1 -> -1397.0206 | AL16: =AK16*1.1 -> -1536.7227 | AM16: =AL16*1.1 -> -1690.395 | AN16: =AM16*1.1 -> -1859.4345 | AO16: =AN16*1.1 -> -2045.3779 | AP16: =AO16*1.1 -> -2249.9157
C17: EBITDA | D17: =SUM(D13:D16) -> 381 | E17: =SUM(E13:E16) -> 619 | F17: =SUM(F13:F16) -> 655 | G17: =SUM(G13:G16) -> 650 | H17: =SUM(H13:H16) -> 441 | I17: =SUM(I13:I16) -> 538 | J17: =SUM(J13:J16) -> 573 | K17: =SUM(K13:K16) -> 326 | ... U17: =SUM(U13:U16) -> 674 | V17: =R17*1.14 -> 728.46 | W17: =S17*1.14 -> 560.88 | Z17: =SUM(Z13:Z16) -> 1977 | AA17: =SUM(AA13:AA16) -> 2127 | AB17: =SUM(AB13:AB16) -> 2741 | AC17: =SUM(AC13:AC16) -> 2407 | AD17: =SUM(AD13:AD16) -> 1589 | AE17: =SUM(AE13:AE16) -> 1697 | AF17: =SUM(AF13:AF16) -> 2127 | AG17: =SUM(AG13:AG16) -> 2418.1612 | ... AP17: =SUM(AP13:AP16) -> 11758.352
C18: D/A | D18: -263 | E18: -278 | F18: -283 | G18: -292 | H18: -314 | I18: -183 | J18: -181 | K18: -176 | L18: -157 | M18: -199 | N18: -234 | O18: -198 | P18: -143 | Q18: -134 | R18: -149 | S18: -142 | T18: -146 | U18: -129 | Z18: -813 | AA18: -829 | AB18: -984 | AC18: -1117 | AD18: -607 | AE18: -702 | AF18: -549 | AG18: =AF18 -> -549 | AH18: =AG18*1 -> -549 | AI18: =AH18*1.09 -> -598.41 | AJ18: =AI18*1.09 -> -652.2669 | AK18: =AJ18*1.09 -> -710.97092 | AL18: =AK18*1.09 -> -774.9583 | AM18: =AL18*1.09 -> -844.70455 | AN18: =AM18*1.09 -> -920.72796 | AO18: =AN18*1.09 -> -1003.5935 | AP18: =AO18*1.09 -> -1093.9169
C19: Impairment | D19: -2 | E19: -6 | F19: 0 | G19: -23 | H19: -9 | I19: 0 | J19: -22 | K19: -16 | L19: 0 | M19: -2 | N19: 0 | O19: -1336 | P19: -9 | Q19: -7 | R19: -4 | S19: -46 | T19: 0 | U19: -4 | Z19: -35 | AA19: -61 | AB19: -119 | AC19: -31 | AD19: -38 | AE19: -1337 | AF19: -66 | AG19: =AF19 -> -66 | AH19: =AG19*1 -> -66 | AI19: =AH19*1.09 -> -71.94 | AJ19: =AI19*1.09 -> -78.4146 | AK19: =AJ19*1.09 -> -85.471914 | AL19: =AK19*1.09 -> -93.164386 | AM19: =AL19*1.09 -> -101.54918 | AN19: =AM19*1.09 -> -110.68861 | AO19: =AN19*1.09 -> -120.65058 | AP19: =AO19*1.09 -> -131.50913
C20: Other income | D20: 0 | E20: 10 | F20: 2 | G20: 1 | H20: 36 | I20: 17 | J20: 12 | K20: 3 | L20: 0 | M20: 0 | N20: 5 | O20: 8 | P20: 0 | Q20: 8 | R20: 13 | S20: 4 | T20: 2 | U20: 14 | Z20: 11 | AA20: 146 | AB20: 181 | AC20: 13 | AD20: 55 | AE20: 9 | AF20: 0 | AG20: =AF20 -> 0 | AH20: =AG20*1 -> 0 | AI20: =AH20*1.09 -> 0 | AJ20: =AI20*1.09 -> 0 | AK20: =AJ20*1.09 -> 0 | AL20: =AK20*1.09 -> 0 | AM20: =AL20*1.09 -> 0 | AN20: =AM20*1.09 -> 0 | AO20: =AN20*1.09 -> 0 | AP20: =AO20*1.09 -> 0
C21: other expenses | D21: -32 | E21: -57 | F21: -32 | G21: -52 | H21: -116 | I21: -15 | J21: -4 | K21: -68 | L21: -103 | M21: -128 | N21: -97 | O21: -196 | P21: -58 | Q21: -121 | R21: -60 | S21: -73 | T21: -88 | U21: -108 | Z21: =-162-58 -> -220 | AA21: =-237-44 -> -281 | AB21: -172 | AC21: -173 | AD21: -111 | AE21: -518 | AF21: -285 | AG21: =AF21 -> -285 | AH21: =AG21*1 -> -285 | AI21: =AH21*1.09 -> -310.65 | AJ21: =AI21*1.09 -> -338.6085 | AK21: =AJ21*1.09 -> -369.08327 | AL21: =AK21*1.09 -> -402.30076 | AM21: =AL21*1.09 -> -438.50783 | AN21: =AM21*1.09 -> -477.97353 | AO21: =AN21*1.09 -> -520.99115 | AP21: =AO21*1.09 -> -567.88035
C22: Operating profit (EBIT) | D22: =SUM(D17:D21) -> 84 | E22: =SUM(E17:E21) -> 288 | F22: =SUM(F17:F21) -> 342 | G22: =SUM(G17:G21) -> 284 | H22: =SUM(H17:H21) -> 38 | I22: =SUM(I17:I21) -> 357 | J22: =SUM(J17:J21) -> 378 | K22: =SUM(K17:K21) -> 69 | ... U22: =SUM(U17:U21) -> 447 | Z22: =SUM(Z17:Z21) -> 920 | AA22: =SUM(AA17:AA21) -> 1102 | AB22: =SUM(AB17:AB21) -> 1647 | AC22: =SUM(AC17:AC21) -> 1099 | AD22: =SUM(AD17:AD21) -> 888 | AE22: =SUM(AE17:AE21) -> -851 | AF22: =SUM(AF17:AF21) -> 1227 | AG22: =SUM(AG17:AG21) -> 1518.1612 | ... AP22: =SUM(AP17:AP21) -> 9965.0452
C23: Share of JV | D23: -53 | E23: 11 | F23: -170 | G23: -270 | H23: -5295 | I23: -1 | J23: -23 | K23: -24 | L23: -17 | M23: -26 | N23: -13 | O23: -28 | P23: -15 | Q23: -8 | R23: -11 | S23: -11 | T23: -10 | U23: 10 | Z23: 89 | AA23: 37 | AB23: -193 | AC23: -482 | AD23: -70 | AE23: -83 | AF23: -47 | AG23: 0 | AH23: 0 | AI23: 0 | AJ23: 0 | AK23: 0 | AL23: 0 | AM23: 0 | AN23: 0 | AO23: 0 | AP23: 0
C24: Impairment on JV | D24: -13531 | E24: -6564 | F24: -3153 | G24: 424 | H24: 7281 | I24: -6 | J24: -34 | K24: -38 | L24: -43 | M24: -3 | N24: -49 | O24: -32 | P24: -14 | Q24: -11 | R24: 0 | S24: -9 | T24: 0 | U24: -7 | Z24: -179 | AA24: -197 | AB24: -20000 | AC24: -22823 | AD24: -88 | AE24: -127 | AF24: -33 | AG24: 0 | AH24: 0 | AI24: 0 | AJ24: 0 | AK24: 0 | AL24: 0 | AM24: 0 | AN24: 0 | AO24: 0 | AP24: 0
C25: Gains/losses on JV | D25: 1 | E25: 1 | F25: 16 | G25: 657 | H25: 0 | I25: 0 | J25: 1 | K25: 1 | L25: -2 | M25: 0 | N25: 0 | O25: -8 | P25: 6 | Q25: 0 | R25: 44 | S25: 152 | T25: 6 | U25: 3 | Z25: 0 | AA25: 0 | AB25: 148 | AC25: 675 | AD25: 2 | AE25: -10 | AF25: 202 | AG25: 0 | AH25: 0 | AI25: 0 | AJ25: 0 | AK25: 0 | AL25: 0 | AM25: 0 | AN25: 0 | AO25: 0 | AP25: 0
C26: Financial income | D26: 83 | E26: 13 | F26: 4 | G26: 17 | H26: 321 | I26: 47 | J26: 1297 | K26: 222 | L26: 27 | M26: 116 | N26: 5125 | O26: 1180 | P26: 78 | Q26: 4671 | R26: 50 | S26: 61 | T26: 69 | U26: 113 | Z26: 0 | AA26: 0 | AB26: 28 | AC26: 117 | AD26: 1729 | AE26: 6436 | AF26: 291 | AG26: 0 | AH26: 0 | AI26: 0 | AJ26: 0 | AK26: 0 | AL26: 0 | AM26: 0 | AN26: 0 | AO26: 0 | AP26: 0
C27: Financial expenses | D27: -73 | E27: -100 | F27: -101 | G27: -553 | H27: -148 | I27: -394 | J27: -125 | K27: -128 | L27: -121 | M27: -119 | N27: -268 | O27: -76 | P27: -2502 | Q27: -71 | R27: -1158 | S27: -2880 | T27: -5862 | U27: -51 | Z27: 0 | AA27: 0 | AB27: -248 | AC27: -830 | AD27: -622 | AE27: -565 | AF27: -2036 | AG27: 0 | AH27: 0 | AI27: 0 | AJ27: 0 | AK27: 0 | AL27: 0 | AM27: 0 | AN27: 0 | AO27: 0 | AP27: 0
C28: PTP | D28: =SUM(D22:D27) -> -13489 | E28: =SUM(E22:E27) -> -6351 | F28: =SUM(F22:F27) -> -3062 | G28: =SUM(G22:G27) -> 559 | H28: =SUM(H22:H27) -> 2197 | I28: =SUM(I22:I27) -> 3 | J28: =SUM(J22:J27) -> 1494 | K28: =SUM(K22:K27) -> 102 | ... U28: =SUM(U22:U27) -> 515 | Z28: =SUM(Z22:Z27) -> 830 | AA28: =SUM(AA22:AA27) -> 942 | AB28: =SUM(AB22:AB27) -> -18618 | AC28: =SUM(AC22:AC27) -> -22244 | AD28: =SUM(AD22:AD27) -> 1839 | AE28: =SUM(AE22:AE27) -> 4800 | AF28: =SUM(AF22:AF27) -> -396 | AG28: =SUM(AG22:AG27) -> 1518.1612 | ... AP28: =SUM(AP22:AP27) -> 9965.0452
C29: Taxes | D29: -45 | E29: -62 | F29: -75 | G29: -72 | H29: -9 | I29: -78 | J29: -88 | K29: -24 | L29: -31 | M29: -65 | N29: -106 | O29: 31 | P29: -25 | Q29: -46 | R29: -106 | S29: -66 | T29: -77 | U29: -104 | Z29: -275 | AA29: 128 | AB29: -280 | AC29: -254 | AD29: -205 | AE29: -149 | AF29: -283 | AG29: =AG28*-0.22 -> -333.99546 | AH29: =AH28*-0.22 -> -456.89812 | AI29: =AI28*-0.22 -> -604.6532 | AJ29: =AJ28*-0.22 -> -802.36772 | AK29: =AK28*-0.22 -> -955.68199 | AL29: =AL28*-0.22 -> -1134.4409 | AM29: =AM28*-0.22 -> -1342.5942 | AN29: =AN28*-0.22 -> -1584.6824 | ... AP29: =AP28*-0.22 -> -2192.3099
C30: Net income | D30: =SUM(D28:D29) -> -13534 | E30: =SUM(E28:E29) -> -6413 | F30: =SUM(F28:F29) -> -3137 | G30: =SUM(G28:G29) -> 487 | H30: =SUM(H28:H29) -> 2188 | I30: =SUM(I28:I29) -> -75 | J30: =SUM(J28:J29) -> 1406 | K30: =SUM(K28:K29) -> 78 | ... U30: =SUM(U28:U29) -> 411 | Z30: =SUM(Z28:Z29) -> 555 | AA30: =SUM(AA28:AA29) -> 1070 | AB30: =SUM(AB28:AB29) -> -18898 | AC30: =SUM(AC28:AC29) -> -22498 | AD30: =SUM(AD28:AD29) -> 1634 | AE30: =SUM(AE28:AE29) -> 4651 | AF30: =SUM(AF28:AF29) -> -679 | AG30: =SUM(AG28:AG29) -> 1184.1657 | ... AP30: =SUM(AP28:AP29) -> 7772.7352 | AQ30: =AP30*(1+$AS$34) -> 7695.0079 | AR30: =AQ30*(1+$AS$34) -> 7618.0578 | AS30: =AR30*(1+$AS$34) -> 7541.8772 | AT30: =AS30*(1+$AS$34) -> 7466.4584 | AU30: =AT30*(1+$AS$34) -> 7391.7939 | AV30: =AU30*(1+$AS$34) -> 7317.8759 | AW30: =AV30*(1+$AS$34) -> 7244.6972 | AX30: =AW30*(1+$AS$34) -> 7172.2502 | ... FC30: =FB30*(1+$AS$34) -> 2398.2345
C31: EPS | D31: =D30/D32 -> -56.627615 | E31: =E30/E32 -> -26.832636 | F31: =F30/F32 -> -13.125523 | G31: =G30/G32 -> 2.0376569 | H31: =H30/H32 -> 9.1548117 | I31: =I30/I32 -> -0.31380753 | J31: =J30/J32 -> 5.8828452 | K31: =K30/K32 -> 0.32635983 | ... U31: =U30/U32 -> 2.0357923 | Z31: =Z30/Z32 -> 2.3345162 | AA31: =AA30/AA32 -> 4.5653196 | AB31: =AB30/AB32 -> -80.636126 | AC31: =AC30/AC32 -> -96.06118 | AD31: =AD30/AD32 -> 6.8368201 | AE31: =AE30/AE32 -> 19.460251 | AF31: =AF30/AF32 -> -2.8410042 | AG31: =AG30/AG32 -> 5.8654878 | ... AP31: =AP30/AP32 -> 39.677056
C32: Shares | D32: 239 | E32: 239 | F32: 239 | G32: 239 | H32: 239 | I32: 239 | J32: 239 | K32: 239 | L32: 239 | M32: 239 | N32: 239 | O32: 239 | P32: 239 | Q32: 239 | R32: 239 | S32: 213 | T32: 207.4 | U32: 201.887 | V32: 195.9 | Z32: 237.73662 | AA32: 234.3757 | AB32: 234.36146 | AC32: 234.20491 | AD32: 239 | AE32: 239 | AF32: 239 | AG32: 201.887 | AH32: 195.9 | AI32: 195.9 | AJ32: 195.9 | AK32: 195.9 | AL32: 195.9 | AM32: 195.9 | AN32: 195.9 | AO32: 195.9 | AP32: 195.9
AR33: Discount | AS33: 0.08
C34: Revenue y/y | H34: =(H11-D11)/D11 -> 0.069334837 | I34: =(I11-E11)/E11 -> -0.36701031 | J34: =(J11-F11)/F11 -> -0.37193823 | K34: =(K11-G11)/G11 -> -0.52632899 | L34: =(L11-H11)/H11 -> -0.49499209 | M34: =(M11-I11)/I11 -> 0.028094463 | N34: =(N11-J11)/J11 -> 0.10512929 | O34: =(O11-K11)/K11 -> 0.11381683 | ... W34: =(W11-S11)/S11 -> -1 | AA34: =(AA11-Z11)/Z11 -> 0.020153323 | AB34: =(AB11-AA11)/AA11 -> 0.13286334 | AC34: =(AC11-AB11)/AB11 -> 0.044382138 | AD34: =(AD11-AC11)/AC11 -> -0.50124411 | AE34: =(AE11-AD11)/AD11 -> 0.09294998 | AF34: =(AF11-AE11)/AE11 -> -0.2412012 | AG34: =(AG11-AF11)/AF11 -> -0.010239038 | AH34: =(AH11-AG11)/AG11 -> 0.10681226 | ... AP34: =(AP11-AO11)/AO11 -> 0.14 | AR34: TV | AS34: -0.01
C35: Gross profit | D35: =D13/D11 -> 0.95828636 | E35: =E13/E11 -> 0.96443299 | F35: =F13/F11 -> 0.96671991 | G35: =G13/G11 -> 0.96514544 | H35: =H13/H11 -> 0.96705324 | I35: =I13/I11 -> 0.99063518 | J35: =J13/J11 -> 0.99025011 | K35: =K13/K11 -> 0.92641609 | ... W35: =W13/W11 -> #DIV/0! | Z35: =Z13/Z11 -> 0.96712242 | AA35: =AA13/AA11 -> 0.96482801 | AB35: =AB13/AB11 -> 0.96368734 | AC35: =AC13/AC11 -> 0.96405186 | AD35: =AD13/AD11 -> 0.93527636 | AE35: =AE13/AE11 -> 0.92804805 | AF35: =AF13/AF11 -> 0.90580972 | AG35: =AG13/AG11 -> 0.91 | ... AP35: =AP13/AP11 -> 0.91 | AR35: NPV | AS35: =NPV(AS33,AF30:FC30) -> 58114.726
C36: EBITDA margin | D36: =D17/D11 -> 0.10738444 | E36: =E17/E11 -> 0.15953608 | F36: =F17/F11 -> 0.17438765 | G36: =G17/G11 -> 0.16298897 | H36: =H17/H11 -> 0.11623616 | I36: =I17/I11 -> 0.21905537 | J36: =J17/J11 -> 0.24289953 | K36: =K17/K11 -> 0.17257808 | ... W36: =W17/W11 -> #DIV/0! | Z36: =Z17/Z11 -> 0.15624753 | AA36: =AA17/AA11 -> 0.16478153 | AB36: =AB17/AB11 -> 0.18744444 | AC36: =AC17/AC11 -> 0.1576087 | AD36: =AD17/AD11 -> 0.20861231 | AE36: =AE17/AE11 -> 0.20384384 | AF36: =AF17/AF11 -> 0.33671046 | AG36: =AG17/AG11 -> 0.38676223 | ... AP36: =AP17/AP11 -> 0.60655211 | AR36: S/O | AS36: 195.9
C37: EBIT margin | D37: =D22/D11 -> 0.02367531 | E37: =E22/E11 -> 0.074226804 | F37: =F22/F11 -> 0.091054313 | G37: =G22/G11 -> 0.071213641 | H37: =H22/H11 -> 0.010015814 | I37: =I22/I11 -> 0.14535831 | J37: =J22/J11 -> 0.16023739 | K37: =K22/K11 -> 0.036527263 | ... W37: =W22/W11 -> #DIV/0! | Z37: =Z22/Z11 -> 0.072710029 | AA37: =AA22/AA11 -> 0.085373412 | AB37: =AB22/AB11 -> 0.11263079 | AC37: =AC22/AC11 -> 0.07196176 | AD37: =AD22/AD11 -> 0.11658133 | AE37: =AE22/AE11 -> -0.10222222 | AF37: =AF22/AF11 -> 0.19423777 | AG37: =AG22/AG11 -> 0.24281566 | ... AP37: =AP22/AP11 -> 0.51404478 | AR37: NPV/Share | AS37: =AS35/AS36 -> 296.65506
AR38: Opp/nedside | AS38: =(AS37-B4)/B4 -> 0.44709786
C39: Mobility y/y | H39: =(H4-D4)/D4 -> 0.13583138 | I39: =(I4-E4)/E4 -> 0.21501014 | J39: =(J4-F4)/F4 -> 0.144 | K39: =(K4-G4)/G4 -> 0.15789474 | L39: =(L4-H4)/H4 -> 0.13608247 | M39: =(M4-I4)/I4 -> 0.056761269 | N39: =(N4-J4)/J4 -> 0.083916084 | O39: =(O4-K4)/K4 -> 0.016363636 | ... W39: =(W4-S4)/S4 -> -1 | AG39: =(AG4-AF4)/AF4 -> 0.02 | AH39: =(AH4-AG4)/AG4 -> 0.05 | AI39: =(AI4-AH4)/AH4 -> 0.08 | AJ39: =(AJ4-AI4)/AI4 -> -1 | AK39: =(AK4-AJ4)/AJ4 -> #DIV/0! | AL39: =(AL4-AK4)/AK4 -> #DIV/0! | AM39: =(AM4-AL4)/AL4 -> #DIV/0! | AN39: =(AN4-AM4)/AM4 -> #DIV/0! | ... AP39: =(AP4-AO4)/AO4 -> #DIV/0!
C40: Real estate y/y | H40: =(H5-D5)/D5 -> 0.22033898 | I40: =(I5-E5)/E5 -> 0.30530973 | J40: =(J5-F5)/F5 -> 0.26696833 | K40: =(K5-G5)/G5 -> 0.14563107 | L40: =(L5-H5)/H5 -> 0.15740741 | M40: =(M5-I5)/I5 -> 0.1559322 | N40: =(N5-J5)/J5 -> 0.12857143 | O40: =(O5-K5)/K5 -> 0.11440678 | ... W40: =(W5-S5)/S5 -> -1 | AG40: =(AG5-AF5)/AF5 -> 0.13 | AH40: =(AH5-AG5)/AG5 -> 0.14 | AI40: =(AI5-AH5)/AH5 -> 0.14 | AJ40: =(AJ5-AI5)/AI5 -> -1 | AK40: =(AK5-AJ5)/AJ5 -> #DIV/0! | AL40: =(AL5-AK5)/AK5 -> #DIV/0! | AM40: =(AM5-AL5)/AL5 -> #DIV/0! | AN40: =(AN5-AM5)/AM5 -> #DIV/0! | ... AP40: =(AP5-AO5)/AO5 -> #DIV/0!
C41: Jobs y/y | H41: =(H6-D6)/D6 -> -0.055415617 | I41: =(I6-E6)/E6 -> -0.10354223 | J41: =(J6-F6)/F6 -> -0.076923077 | K41: =(K6-G6)/G6 -> -0.086419753 | L41: =(L6-H6)/H6 -> -0.069333333 | M41: =(M6-I6)/I6 -> -0.024316109 | N41: =(N6-J6)/J6 -> -0.024305556 | O41: =(O6-K6)/K6 -> -0.087837838 | ... W41: =(W6-S6)/S6 -> -1 | AG41: =(AG6-AF6)/AF6 -> 0.06 | AH41: =(AH6-AG6)/AG6 -> 0.1 | AI41: =(AI6-AH6)/AH6 -> 0.1 | AJ41: =(AJ6-AI6)/AI6 -> -1 | AK41: =(AK6-AJ6)/AJ6 -> #DIV/0! | AL41: =(AL6-AK6)/AK6 -> #DIV/0! | AM41: =(AM6-AL6)/AL6 -> #DIV/0! | AN41: =(AN6-AM6)/AM6 -> #DIV/0! | ... AP41: =(AP6-AO6)/AO6 -> #DIV/0!
C42: Recommerce y/y | H42: =(H7-D7)/D7 -> 0.18320611 | I42: =(I7-E7)/E7 -> 0.29104478 | J42: =(J7-F7)/F7 -> 0.44 | K42: =(K7-G7)/G7 -> 0.3164557 | L42: =(L7-H7)/H7 -> 0.22580645 | M42: =(M7-I7)/I7 -> 0.16184971 | N42: =(N7-J7)/J7 -> 0.16666667 | O42: =(O7-K7)/K7 -> 0.076923077 | ... W42: =(W7-S7)/S7 -> -1 | AG42: =(AG7-AF7)/AF7 -> 0.23 | AH42: =(AH7-AG7)/AG7 -> 0.2 | AI42: =(AI7-AH7)/AH7 -> 0.2 | AJ42: =(AJ7-AI7)/AI7 -> -1 | AK42: =(AK7-AJ7)/AJ7 -> #DIV/0! | AL42: =(AL7-AK7)/AK7 -> #DIV/0! | AM42: =(AM7-AL7)/AL7 -> #DIV/0! | AN42: =(AN7-AM7)/AM7 -> #DIV/0! | ... AP42: =(AP7-AO7)/AO7 -> #DIV/0!
...

Sheet SOTP
A2: EBITDA 26E
A3: =Modell!AG17 -> 2418.1612
B5: NOKm | C5: EBITDA 26E | D5: EV/EBITDA | E5: Value | F5: Value/Share
B6: Mobility | C6: 1400 | D6: 18.5 | E6: =D6*C6 -> 25900 | F6: =E6/Modell!$B$5 -> 132.21031
B7: Real estate | C7: 739 | D7: 18 | E7: =D7*C7 -> 13302 | F7: =E7/Modell!$B$5 -> 67.901991
B8: Jobs | C8: 740 | D8: 18 | E8: =D8*C8 -> 13320 | F8: =E8/Modell!$B$5 -> 67.993874
B9: Recommerce | C9: -160 | D9: 5 | E9: =D9*C9 -> -800 | F9: =E9/Modell!$B$5 -> -4.0837162
B10: Other/HQ | C10: -300 | D10: 11.4 | E10: =D10*C10 -> -3420 | F10: =E10/Modell!$B$5 -> -17.457887
B11: Marketplaces | C11: =SUM(C6:C10) -> 2419 | D11: =E11/C11 -> 19.967755 | E11: =SUM(E6:E10) -> 48302 | F11: =SUM(F6:F10) -> 246.56457
B13: Adevinta | C13: 12000 | D13: 18.5 | E13: =(C13*D13)*0.14 -> 31080 | F13: =E13/Modell!B5 -> 158.65237
B14: Net debt | E14: -5000 | F14: =E14/Modell!B5 -> -25.523226
B15: Adevinta equity V | E15: =SUM(E13:E14) -> 26080 | F15: =SUM(F13:F14) -> 133.12915
B17: Cash | E17: =Modell!B7 -> 4222 | F17: =E17/Modell!B5 -> 21.551812
B18: Debt | E18: =Modell!B8 -> 2244 | F18: =E18/(Modell!B5*-1) -> -11.454824
B20: Equity value | E20: =E11+E15+E17-E18 -> 76360 | F20: =F11+F15+F17+F18 -> 389.79071
A87: Mobility | B87: =F6 -> 132.21031
A88: Real estate | B88: =F7 -> 67.901991
A89: Jobs | B89: =F8 -> 67.993874
A90: Recommerce | B90: =F9 -> -4.0837162
A91: Other/HQ | B91: =F10 -> -17.457887
A92: Marketplaces | B92: =F11 -> 246.56457
A94: Adevinta | B94: =F13 -> 158.65237
A95: Net debt | B95: =F14 -> -25.523226
A96: Adevinta equity V | B96: =F15 -> 133.12915
A98: Cash | B98: =F17 -> 21.551812
A99: Debt | B99: =F18 -> -11.454824
A101: Equity value | B101: =F20 -> 389.79071
C1048576: =C1048548*1.2 -> 0

Sheet Segmenter
B4: NOKm | C4: Q122 | D4: Q222 | E4: Q322 | F4: Q422 | G4: 2022 | H4: Q123 | I4: Q223 | J4: Q323 | K4: Q423 | L4: 2023 | M4: Q124 | N4: Q224 | O4: Q324 | P4: Q424 | Q4: 2024 | R4: Q125 | S4: Q225 | T4: Q325 | U4: Q425 | V4: 2025 | W4: Q126 | X4: Q226 | Y4: Q326 | Z4: Q426 | AA4: 2026
B5: Mobility
B6: Classified revenues | C6: =SUM(C7:C8) -> 319 | D6: =SUM(D7:D8) -> 366 | E6: =SUM(E7:E8) -> 391 | F6: =SUM(F7:F8) -> 369 | G6: =SUM(G7:G8) -> 1445 | H6: =SUM(H7:H8) -> 383 | I6: =SUM(I7:I8) -> 459 | J6: =SUM(J7:J8) -> 466 | ... R6: =SUM(R7:R8) -> 413 | S6: 496 | T6: 484 | U6: 446 | V6: =SUM(V7:V8) -> 1839 | W6: 418 | X6: 497 | AA6: =SUM(AA7:AA8) -> 914
B7: Of which professional | C7: 319 | D7: 366 | E7: 391 | F7: 369 | G7: =SUM(C7:F7) -> 1445 | H7: 383 | I7: 459 | J7: 466 | K7: 291 | L7: =SUM(H7:K7) -> 1599 | M7: 312 | N7: 524 | O7: 525 | P7: 312 | Q7: =SUM(M7:P7) -> 1673 | R7: 322 | S7: 337 | T7: 338 | U7: 352 | V7: =SUM(R7:U7) -> 1349 | W7: 338 | X7: 353 | AA7: =SUM(W7:Z7) -> 691
B8: Of which Private | C8: 0 | D8: 0 | E8: 0 | F8: 0 | G8: =SUM(C8:F8) -> 0 | H8: 0 | I8: 0 | J8: 0 | K8: 80 | L8: =SUM(H8:K8) -> 80 | M8: 79 | N8: 0 | O8: 0 | P8: 89 | Q8: =SUM(M8:P8) -> 168 | R8: 91 | S8: 158 | T8: 147 | U8: 94 | V8: =SUM(R8:U8) -> 490 | W8: 80 | X8: 143 | AA8: =SUM(W8:Z8) -> 223
B9: Transactional revenue | C9: 0 | D9: 0 | E9: 0 | F9: 0 | G9: =SUM(C9:F9) -> 0 | H9: 0 | I9: 0 | J9: 0 | K9: 86 | L9: =SUM(H9:K9) -> 86 | M9: 73 | N9: 0 | O9: 0 | P9: 91 | Q9: =SUM(M9:P9) -> 164 | R9: 86 | S9: 103 | T9: 123 | U9: 117 | V9: =SUM(R9:U9) -> 429 | W9: 99 | X9: 116 | AA9: =SUM(W9:Z9) -> 215
B10: Advertising revenues | C10: 58 | D10: 69 | E10: 57 | F10: 61 | G10: =SUM(C10:F10) -> 245 | H10: 54 | I10: 70 | J10: 59 | K10: 76 | L10: =SUM(H10:K10) -> 259 | M10: 68 | N10: 59 | O10: 49 | P10: 55 | Q10: =SUM(M10:P10) -> 231 | R10: 48 | S10: 69 | T10: 63 | U10: 57 | V10: =SUM(R10:U10) -> 237 | W10: 51 | X10: 61 | AA10: =SUM(W10:Z10) -> 112
B11: Other operating revenues | C11: 49 | D11: 58 | E11: 52 | F11: 44 | G11: =SUM(C11:F11) -> 203 | H11: 49 | I11: 70 | J11: 47 | K11: 18 | L11: =SUM(H11:K11) -> 184 | M11: 19 | N11: 50 | O11: 45 | P11: 13 | Q11: =SUM(M11:P11) -> 127 | R11: 10 | S11: 8 | T11: 8 | U11: 8 | V11: =SUM(R11:U11) -> 34 | W11: 7 | X11: 8 | AA11: =SUM(W11:Z11) -> 15
B12: Operating revenues | C12: =C6+C9+C10+C11 -> 426 | D12: =D6+D9+D10+D11 -> 493 | E12: =E6+E9+E10+E11 -> 500 | F12: =F6+F9+F10+F11 -> 474 | G12: =G6+G9+G10+G11 -> 1893 | H12: =H6+H9+H10+H11 -> 486 | I12: =I6+I9+I10+I11 -> 599 | J12: =J6+J9+J10+J11 -> 572 | ... AA12: =AA6+AA9+AA10+AA11 -> 1256
B13: y/y | H13: =(H12-C12)/C12 -> 0.14084507 | I13: =(I12-D12)/D12 -> 0.21501014 | J13: =(J12-E12)/E12 -> 0.144 | K13: =(K12-F12)/F12 -> 0.16244726 | L13: =(L12-G12)/G12 -> 0.16640254 | M13: =(M12-H12)/H12 -> 0.13374486 | N13: =(N12-I12)/I12 -> 0.056761269 | O13: =(O12-J12)/J12 -> 0.082167832 | ... AA13: =(AA12-V12)/V12 -> -0.50531705
B14: EBITDA | C14: 209 | D14: 272 | E14: 275 | F14: 235 | G14: =SUM(C14:F14) -> 991 | H14: 220 | I14: 315 | J14: 304 | K14: 270 | L14: =SUM(H14:K14) -> 1109 | M14: 268 | N14: 342 | O14: 336 | P14: 278 | Q14: =SUM(M14:P14) -> 1224 | R14: 275 | S14: 391 | T14: 389 | U14: 336 | V14: =SUM(R14:U14) -> 1391 | W14: 274 | X14: 365 | AA14: =SUM(W14:Z14) -> 639
B15: EBITDA margin | C15: =C14/C12 -> 0.49061033 | D15: =D14/D12 -> 0.55172414 | E15: =E14/E12 -> 0.55 | F15: =F14/F12 -> 0.49578059 | G15: =G14/G12 -> 0.52350766 | H15: =H14/H12 -> 0.4526749 | I15: =I14/I12 -> 0.52587646 | J15: =J14/J12 -> 0.53146853 | ... AA15: =AA14/AA12 -> 0.50875796
B16: Real estate
B17: Classified revenues | C17: =SUM(C18:C19) -> 147 | D17: =SUM(D18:D19) -> 193 | E17: =SUM(E18:E19) -> 192 | F17: =SUM(F18:F19) -> 178 | G17: =SUM(G18:G19) -> 710 | H17: =SUM(H18:H19) -> 190 | I17: =SUM(I18:I19) -> 261 | J17: =SUM(J18:J19) -> 249 | ... R17: =SUM(R18:R19) -> 245 | S17: 324 | T17: 283 | U17: 241 | V17: =SUM(V18:V19) -> 1093 | W17: 272 | X17: 365 | AA17: =SUM(AA18:AA19) -> 637
B18: Of which professional | C18: 147 | D18: 193 | E18: 192 | F18: 178 | G18: =SUM(C18:F18) -> 710 | H18: 190 | I18: 261 | J18: 249 | K18: 164 | L18: =SUM(H18:K18) -> 864 | M18: 177 | N18: 319 | O18: 295 | P18: 182 | Q18: =SUM(M18:P18) -> 973 | R18: 212 | S18: 287 | T18: 247 | U18: 213 | V18: =SUM(R18:U18) -> 959 | W18: 241 | X18: 330 | AA18: =SUM(W18:Z18) -> 571
B19: Of which Private | C19: 0 | D19: 0 | E19: 0 | F19: 0 | G19: =SUM(C19:F19) -> 0 | H19: 0 | I19: 0 | J19: 0 | K19: 29 | L19: =SUM(H19:K19) -> 29 | M19: 30 | N19: 0 | O19: 0 | P19: 29 | Q19: =SUM(M19:P19) -> 59 | R19: 33 | S19: 37 | T19: 36 | U19: 28 | V19: =SUM(R19:U19) -> 134 | W19: 31 | X19: 35 | AA19: =SUM(W19:Z19) -> 66
B20: Transactional revenue | C20: 0 | D20: 0 | E20: 0 | F20: 0 | G20: =SUM(C20:F20) -> 0 | H20: 0 | I20: 0 | J20: 0 | K20: 17 | L20: =SUM(H20:K20) -> 17 | M20: 20 | N20: 0 | O20: 0 | P20: 35 | Q20: =SUM(M20:P20) -> 55 | R20: 40 | S20: 38 | T20: 45 | U20: 46 | V20: =SUM(R20:U20) -> 169 | W20: 48 | X20: 45 | AA20: =SUM(W20:Z20) -> 93
B21: Advertising revenues | C21: 18 | D21: 20 | E21: 17 | F21: 18 | G21: =SUM(C21:F21) -> 73 | H21: 14 | I21: 17 | J21: 16 | K21: 18 | L21: =SUM(H21:K21) -> 65 | M21: 16 | N21: 14 | O21: 13 | P21: 15 | Q21: =SUM(M21:P21) -> 58 | R21: 13 | S21: 15 | T21: 15 | U21: 15 | V21: =SUM(R21:U21) -> 58 | W21: 17 | X21: 19 | AA21: =SUM(W21:Z21) -> 36
B22: Other operating revenues | C22: 11 | D22: 13 | E22: 12 | F22: 10 | G22: =SUM(C22:F22) -> 46 | H22: 12 | I22: 17 | J22: 15 | K22: 8 | L22: =SUM(H22:K22) -> 52 | M22: 6 | N22: 8 | O22: 8 | P22: 3 | Q22: =SUM(M22:P22) -> 25 | R22: 4 | S22: 1 | T22: 2 | U22: 0 | V22: =SUM(R22:U22) -> 7 | W22: 4 | X22: 4 | AA22: =SUM(W22:Z22) -> 8
B23: Operating revenues | C23: =C17+C20+C21+C22 -> 176 | D23: =D17+D20+D21+D22 -> 226 | E23: =E17+E20+E21+E22 -> 221 | F23: =F17+F20+F21+F22 -> 206 | G23: =G17+G20+G21+G22 -> 829 | H23: =H17+H20+H21+H22 -> 216 | I23: =I17+I20+I21+I22 -> 295 | J23: =J17+J20+J21+J22 -> 280 | ... AA23: =AA17+AA20+AA21+AA22 -> 774
B24: y/y | H24: =(H23-C23)/C23 -> 0.22727273 | I24: =(I23-D23)/D23 -> 0.30530973 | J24: =(J23-E23)/E23 -> 0.26696833 | K24: =(K23-F23)/F23 -> 0.14563107 | L24: =(L23-G23)/G23 -> 0.23884198 | M24: =(M23-H23)/H23 -> 0.15277778 | N24: =(N23-I23)/I23 -> 0.1559322 | O24: =(O23-J23)/J23 -> 0.12857143 | ... AA24: =(AA23-V23)/V23 -> -0.41672946
B25: EBITDA | C25: 48 | D25: 97 | E25: 93 | F25: 74 | G25: =SUM(C25:F25) -> 312 | H25: 64 | I25: 128 | J25: 120 | K25: 80 | L25: =SUM(H25:K25) -> 392 | M25: 64 | N25: 153 | O25: 144 | P25: 77 | Q25: =SUM(M25:P25) -> 438 | R25: 126 | S25: 200 | T25: 167 | U25: 123 | V25: =SUM(R25:U25) -> 616 | W25: 164 | X25: 248 | AA25: =SUM(W25:Z25) -> 412
B26: EBITDA margin | C26: =C25/C23 -> 0.27272727 | D26: =D25/D23 -> 0.42920354 | E26: =E25/E23 -> 0.42081448 | F26: =F25/F23 -> 0.3592233 | G26: =G25/G23 -> 0.37635706 | H26: =H25/H23 -> 0.2962963 | I26: =I25/I23 -> 0.43389831 | J26: =J25/J23 -> 0.42857143 | ... AA26: =AA25/AA23 -> 0.53229974
B27: Jobs
B28: Classified revenues | C28: =SUM(C29:C30) -> 392 | D28: =SUM(D29:D30) -> 363 | E28: =SUM(E29:E30) -> 309 | F28: =SUM(F29:F30) -> 320 | G28: =SUM(G29:G30) -> 1384 | H28: =SUM(H29:H30) -> 369 | I28: =SUM(I29:I30) -> 261 | J28: =SUM(J29:J30) -> 283 | ... R28: =SUM(R29:R30) -> 314 | S28: 286 | T28: 247 | U28: 271 | V28: =SUM(V29:V30) -> 1118 | W28: 340 | X28: 301 | AA28: =SUM(AA29:AA30) -> 301
B29: Of which professional | C29: 392 | D29: 363 | E29: 309 | F29: 320 | G29: =SUM(C29:F29) -> 1384 | H29: 369 | I29: 261 | J29: 283 | K29: 291 | L29: =SUM(H29:K29) -> 1204 | M29: 345 | N29: 319 | O29: 278 | P29: 268 | Q29: =SUM(M29:P29) -> 1210 | R29: 314 | S29: 286 | T29: 247 | U29: 271 | V29: =SUM(R29:U29) -> 1118 | W29: 0 | X29: 301 | AA29: =SUM(W29:Z29) -> 301
B30: Of which Private | C30: 0 | D30: 0 | E30: 0 | F30: 0 | G30: =SUM(C30:F30) -> 0 | H30: 0 | I30: 0 | J30: 0 | K30: 0 | L30: =SUM(H30:K30) -> 0 | M30: 0 | N30: 0 | O30: 0 | P30: 0 | Q30: =SUM(M30:P30) -> 0 | R30: 0 | S30: 0 | T30: 0 | U30: 0 | V30: =SUM(R30:U30) -> 0 | W30: 0 | X30: 0 | AA30: =SUM(W30:Z30) -> 0
B31: Transactional revenue | C31: 0 | D31: 0 | E31: 0 | F31: 0 | G31: =SUM(C31:F31) -> 0 | H31: 0 | I31: 0 | J31: 0 | K31: 0 | L31: =SUM(H31:K31) -> 0 | M31: 0 | N31: 0 | O31: 0 | P31: 0 | Q31: =SUM(M31:P31) -> 0 | R31: 0 | S31: 0 | T31: 0 | U31: 0 | V31: =SUM(R31:U31) -> 0 | W31: 0 | X31: 0 | AA31: =SUM(W31:Z31) -> 0
B32: Advertising revenues | C32: 2 | D32: 2 | E32: 1 | F32: 2 | G32: =SUM(C32:F32) -> 7 | H32: 2 | I32: 17 | J32: 1 | K32: 2 | L32: =SUM(H32:K32) -> 22 | M32: 0 | N32: 14 | O32: 0 | P32: 0 | Q32: =SUM(M32:P32) -> 14 | R32: 0 | S32: 0 | T32: 0 | U32: 0 | V32: =SUM(R32:U32) -> 0 | W32: 0 | X32: 0 | AA32: =SUM(W32:Z32) -> 0
B33: Other operating revenues | C33: 3 | D33: 3 | E33: 2 | F33: 3 | G33: =SUM(C33:F33) -> 11 | H33: 3 | I33: 17 | J33: 4 | K33: 3 | L33: =SUM(H33:K33) -> 27 | M33: 0 | N33: 8 | O33: 3 | P33: 2 | Q33: =SUM(M33:P33) -> 13 | R33: 0 | S33: 0 | T33: 0 | U33: 0 | V33: =SUM(R33:U33) -> 0 | W33: 0 | X33: 0 | AA33: =SUM(W33:Z33) -> 0
B34: Operating revenues | C34: =C28+C31+C32+C33 -> 397 | D34: =D28+D31+D32+D33 -> 368 | E34: =E28+E31+E32+E33 -> 312 | F34: =F28+F31+F32+F33 -> 325 | G34: =G28+G31+G32+G33 -> 1402 | H34: =H28+H31+H32+H33 -> 374 | I34: =I28+I31+I32+I33 -> 295 | J34: =J28+J31+J32+J33 -> 288 | ... AA34: =AA28+AA31+AA32+AA33 -> 301
B35: y/y | H35: =(H34-C34)/C34 -> -0.057934509 | I35: =(I34-D34)/D34 -> -0.19836957 | J35: =(J34-E34)/E34 -> -0.076923077 | K35: =(K34-F34)/F34 -> -0.089230769 | L35: =(L34-G34)/G34 -> -0.10627675 | M35: =(M34-H34)/H34 -> -0.077540107 | N35: =(N34-I34)/I34 -> 0.1559322 | O35: =(O34-J34)/J34 -> -0.024305556 | ... AA35: =(AA34-V34)/V34 -> -0.73076923
B36: EBITDA | C36: 231 | D36: 222 | E36: 161 | F36: 168 | G36: =SUM(C36:F36) -> 782 | H36: 198 | I36: 128 | J36: 127 | K36: 125 | L36: =SUM(H36:K36) -> 578 | M36: 158 | N36: 153 | O36: 123 | P36: 113 | Q36: =SUM(M36:P36) -> 547 | R36: 185 | S36: 172 | T36: 136 | U36: 151 | V36: =SUM(R36:U36) -> 644 | W36: 218 | X36: 175 | AA36: =SUM(W36:Z36) -> 393
B37: EBITDA margin | C37: =C36/C34 -> 0.58186398 | D37: =D36/D34 -> 0.60326087 | E37: =E36/E34 -> 0.51602564 | F37: =F36/F34 -> 0.51692308 | G37: =G36/G34 -> 0.55777461 | H37: =H36/H34 -> 0.52941176 | I37: =I36/I34 -> 0.43389831 | J37: =J36/J34 -> 0.44097222 | ... AA37: =AA36/AA34 -> 1.3056478
B38: Recommerce
B39: Classified revenues | C39: =SUM(C40:C41) -> 75 | D39: =SUM(D40:D41) -> 73 | E39: =SUM(E40:E41) -> 74 | F39: =SUM(F40:F41) -> 94 | G39: =SUM(G40:G41) -> 316 | H39: =SUM(H40:H41) -> 102 | I39: =SUM(I40:I41) -> 115 | J39: =SUM(J40:J41) -> 125 | ... R39: =SUM(R40:R41) -> 46 | S39: 50 | T39: 51 | U39: 56 | V39: =SUM(V40:V41) -> 203 | W39: 56 | X39: 68 | AA39: =SUM(AA40:AA41) -> 122
B40: Of which professional | C40: 75 | D40: 73 | E40: 74 | F40: 94 | G40: =SUM(C40:F40) -> 316 | H40: 102 | I40: 115 | J40: 125 | K40: 37 | L40: =SUM(H40:K40) -> 379 | M40: 39 | N40: 148 | O40: 158 | P40: 38 | Q40: =SUM(M40:P40) -> 383 | R40: 36 | S40: 37 | T40: 35 | U40: 37 | V40: =SUM(R40:U40) -> 145 | W40: 31 | X40: 33 | AA40: =SUM(W40:Z40) -> 64
B41: Of which Private | C41: 0 | D41: 0 | E41: 0 | F41: 0 | G41: =SUM(C41:F41) -> 0 | H41: 0 | I41: 0 | J41: 0 | K41: 15 | L41: =SUM(H41:K41) -> 15 | M41: 15 | N41: 0 | O41: 0 | P41: 14 | Q41: =SUM(M41:P41) -> 29 | R41: 10 | S41: 13 | T41: 16 | U41: 19 | V41: =SUM(R41:U41) -> 58 | W41: 24 | X41: 34 | AA41: =SUM(W41:Z41) -> 58
B42: Transactional revenue | C42: 0 | D42: 0 | E42: 0 | F42: 0 | G42: =SUM(C42:F42) -> 0 | H42: 0 | I42: 0 | J42: 0 | K42: 90 | L42: =SUM(H42:K42) -> 90 | M42: 87 | N42: 0 | O42: 0 | P42: 118 | Q42: =SUM(M42:P42) -> 205 | R42: 113 | S42: 115 | T42: 126 | U42: 145 | V42: =SUM(R42:U42) -> 499 | W42: 140 | X42: 139 | AA42: =SUM(W42:Z42) -> 279
B43: Advertising revenues | C43: 50 | D43: 54 | E43: 44 | F43: 53 | G43: =SUM(C43:F43) -> 201 | H43: 43 | I43: 49 | J43: 42 | K43: 50 | L43: =SUM(H43:K43) -> 184 | M43: 36 | N43: 44 | O43: 38 | P43: 40 | Q43: =SUM(M43:P43) -> 158 | R43: 21 | S43: 26 | T43: 29 | U43: 33 | V43: =SUM(R43:U43) -> 109 | W43: 28 | X43: 31 | AA43: =SUM(W43:Z43) -> 59
...

Sheet ARPA
B4: Vertical | C4: Country | D4: Category | E4: Q122 | F4: Q222 | G4: Q322 | H4: Q422 | I4: Q123 | J4: Q223 | K4: Q323 | L4: Q423 | M4: Q124 | N4: Q224 | O4: Q324 | P4: Q424 | Q4: Q125 | R4: Q225 | S4: Q325 | T4: Q425 | U4: Q126 | V4: Q226 | W4: Q326 | X4: Q426
B5: Mobility | C5: Norway | D5: Professional | M5: 438 | N5: 439 | O5: 428 | P5: 434 | Q5: 461 | R5: 497 | S5: 518 | T5: 540 | U5: 586 | V5: 592
D6: y/y | Q6: =(Q5-M5)/M5 -> 0.052511416 | R6: =(R5-N5)/N5 -> 0.13211845 | S6: =(S5-O5)/O5 -> 0.21028037 | T6: =(T5-P5)/P5 -> 0.24423963 | U6: =(U5-Q5)/Q5 -> 0.27114967 | V6: =(V5-R5)/R5 -> 0.19114688
C7: Norway | D7: Private | M7: 622 | N7: 596 | O7: 653 | P7: 698 | Q7: 704 | R7: 715 | S7: 734 | T7: 766 | U7: 793 | V7: 805
D8: y/y | Q8: =(Q7-M7)/M7 -> 0.1318328 | R8: =(R7-N7)/N7 -> 0.19966443 | S8: =(S7-O7)/O7 -> 0.12404288 | T8: =(T7-P7)/P7 -> 0.097421203 | U8: =(U7-Q7)/Q7 -> 0.12642045 | V8: =(V7-R7)/R7 -> 0.12587413
C9: Sweden | D9: Professional | M9: 309 | N9: 309 | O9: 585 | P9: 624 | Q9: 718 | R9: 720 | S9: 702 | T9: 720 | U9: 715 | V9: 745
D10: y/y | Q10: =(Q9-M9)/M9 -> 1.3236246 | R10: =(R9-N9)/N9 -> 1.3300971 | S10: =(S9-O9)/O9 -> 0.2 | T10: =(T9-P9)/P9 -> 0.15384615 | U10: =(U9-Q9)/Q9 -> -0.004178273 | V10: =(V9-R9)/R9 -> 0.034722222
C11: Sweden | D11: Private | M11: 171 | N11: 177 | O11: 194 | P11: 234 | Q11: 246 | R11: 304 | S11: 301 | T11: 298 | U11: 267 | V11: 286
D12: y/y | Q12: =(Q11-M11)/M11 -> 0.43859649 | R12: =(R11-N11)/N11 -> 0.71751412 | S12: =(S11-O11)/O11 -> 0.55154639 | T12: =(T11-P11)/P11 -> 0.27350427 | U12: =(U11-Q11)/Q11 -> 0.085365854 | V12: =(V11-R11)/R11 -> -0.059210526
C13: Denmark | D13: Professional | M13: 4645 | N13: 4585 | O13: 313 | P13: 316 | Q13: 341 | R13: 349 | S13: 375 | T13: 382 | U13: 644 | V13: 771
D14: y/y | Q14: =(Q13-M13)/M13 -> -0.92658773 | R14: =(R13-N13)/N13 -> -0.92388222 | S14: =(S13-O13)/O13 -> 0.19808307 | T14: =(T13-P13)/P13 -> 0.20886076 | U14: =(U13-Q13)/Q13 -> 0.88856305 | V14: =(V13-R13)/R13 -> 1.2091691
C15: Denmark | D15: Private | M15: 146 | N15: 161 | O15: 168 | P15: 167 | Q15: 179 | R15: 266 | S15: 262 | T15: 198 | U15: 157 | V15: 181
D16: y/y | Q16: =(Q15-M15)/M15 -> 0.2260274 | R16: =(R15-N15)/N15 -> 0.65217391 | S16: =(S15-O15)/O15 -> 0.55952381 | T16: =(T15-P15)/P15 -> 0.18562874 | U16: =(U15-Q15)/Q15 -> -0.12290503 | V16: =(V15-R15)/R15 -> -0.31954887
B18: Real Estate | C18: Norway | D18: Total | M18: 2925 | N18: 3200 | O18: 3026 | P18: 3153 | Q18: 3148 | R18: 3511 | S18: 3454 | T18: 3718 | U18: 3782 | V18: 4081
D19: y/y | Q19: =(Q18-M18)/M18 -> 0.076239316 | R19: =(R18-N18)/N18 -> 0.0971875 | S19: =(S18-O18)/O18 -> 0.14144085 | T19: =(T18-P18)/P18 -> 0.17919442 | U19: =(U18-Q18)/Q18 -> 0.20139771 | V19: =(V18-R18)/R18 -> 0.16234691
C20: Norway | D20: Residential for sale | M20: 4645 | N20: 4585 | O20: 4385 | P20: 4361 | Q20: 4943 | R20: 4912 | S20: 5153 | T20: 5262 | U20: 5866 | V20: 5746
D21: y/y | Q21: =(Q20-M20)/M20 -> 0.064155005 | R21: =(R20-N20)/N20 -> 0.07131952 | S21: =(S20-O20)/O20 -> 0.17514253 | T21: =(T20-P20)/P20 -> 0.20660399 | U21: =(U20-Q20)/Q20 -> 0.18672871 | V21: =(V20-R20)/R20 -> 0.16978827
C22: Finland | D22: Total | M22: 19 | N22: 19 | O22: 20 | P22: 24 | Q22: 21 | R22: 22 | S22: 24 | T22: 26 | U22: 430 | V22: 453
D23: y/y | Q23: =(Q22-M22)/M22 -> 0.10526316 | R23: =(R22-N22)/N22 -> 0.15789474 | S23: =(S22-O22)/O22 -> 0.2 | T23: =(T22-P22)/P22 -> 0.083333333 | U23: =(U22-Q22)/Q22 -> 19.47619 | V23: =(V22-R22)/R22 -> 19.590909
B25: Jobs | C25: Norway | D25: Total | M25: 6685 | N25: 6763 | O25: 6967 | P25: 7303 | Q25: 7891 | R25: 8229 | S25: 8185 | T25: 8856 | U25: 8899 | V25: 9454
D26: y/y | Q26: =(Q25-M25)/M25 -> 0.18040389 | R26: =(R25-N25)/N25 -> 0.21676771 | S26: =(S25-O25)/O25 -> 0.17482417 | T26: =(T25-P25)/P25 -> 0.21265233 | U26: =(U25-Q25)/Q25 -> 0.12774046 | V26: =(V25-R25)/R25 -> 0.14886377
B32: Liten øker 15%
B33: Medium øker 20%
B34: Stor øker 5%
B35: Antar 60/40 mellom med og stor
B37: Innebører en arpa vekst på 11% i 2027

Sheet NAA
B2: Tallene er i tusen
AA3: QTD
B4: Vertical | C4: Country | D4: Category | E4: Q122 | F4: Q222 | G4: Q322 | H4: Q422 | I4: Q123 | J4: Q223 | K4: Q323 | L4: Q423 | M4: Q124 | N4: Q224 | O4: Q324 | P4: Q424 | Q4: Q125 | R4: Q225 | S4: Q325 | T4: Q425 | U4: Q126 | V4: Q226 | W4: Q326 | X4: Q426 | AA4: Q1 | AB4: Q2 | AC4: Q3 | AD4: Q4
B5: Mobility | C5: Norway | D5: Professional | M5: 149 | N5: 156 | O5: 158 | P5: 162 | Q5: 156 | R5: 152 | S5: 148 | T5: 154 | U5: 159 | V5: 159
D6: y/y | Q6: =(Q5-M5)/M5 -> 0.046979866 | R6: =(R5-N5)/N5 -> -0.025641026 | S6: =(S5-O5)/O5 -> -0.063291139 | T6: =(T5-P5)/P5 -> -0.049382716 | U6: =(U5-Q5)/Q5 -> 0.019230769 | V6: =(V5-R5)/R5 -> 0.046052632 | AA6: 0 | AB6: 0.03 | AC6: 0.04
C7: Norway | D7: Private | M7: 61 | N7: 118 | O7: 106 | P7: 62 | Q7: 67 | R7: 116 | S7: 106 | T7: 67 | U7: 64 | V7: 113
D8: y/y | Q8: =(Q7-M7)/M7 -> 0.098360656 | R8: =(R7-N7)/N7 -> -0.016949153 | S8: =(S7-O7)/O7 -> 0 | T8: =(T7-P7)/P7 -> 0.080645161 | U8: =(U7-Q7)/Q7 -> -0.044776119 | V8: =(V7-R7)/R7 -> -0.025862069 | AA8: -0.06 | AB8: -0.02 | AC8: -0.02
C9: Sweden | D9: Professional | M9: 251 | N9: 255 | O9: 242 | P9: 240 | Q9: 217 | R9: 226 | S9: 225 | T9: 221 | U9: 205 | V9: 227
D10: y/y | Q10: =(Q9-M9)/M9 -> -0.13545817 | R10: =(R9-N9)/N9 -> -0.11372549 | S10: =(S9-O9)/O9 -> -0.070247934 | T10: =(T9-P9)/P9 -> -0.079166667 | U10: =(U9-Q9)/Q9 -> -0.055299539 | V10: =(V9-R9)/R9 -> 0.0044247788 | AA10: -0.07 | AB10: -0.05 | AC10: -0.02
C11: Sweden | D11: Private | M11: 165 | N11: 265 | O11: 181 | P11: 107 | Q11: 112 | R11: 171 | S11: 158 | T11: 90 | U11: 81 | V11: 148
D12: y/y | Q12: =(Q11-M11)/M11 -> -0.32121212 | R12: =(R11-N11)/N11 -> -0.35471698 | S12: =(S11-O11)/O11 -> -0.12707182 | T12: =(T11-P11)/P11 -> -0.1588785 | U12: =(U11-Q11)/Q11 -> -0.27678571 | V12: =(V11-R11)/R11 -> -0.13450292 | AA12: -0.35 | AB12: -0.13 | AC12: -0.14
C13: Denmark | D13: Professional | M13: 58 | N13: 55 | O13: 55 | P13: 57 | Q13: 53 | R13: 52 | S13: 51 | T13: 53 | U13: 65 | V13: 69
D14: y/y | Q14: =(Q13-M13)/M13 -> -0.086206897 | R14: =(R13-N13)/N13 -> -0.054545455 | S14: =(S13-O13)/O13 -> -0.072727273 | T14: =(T13-P13)/P13 -> -0.070175439 | U14: =(U13-Q13)/Q13 -> 0.22641509 | V14: =(V13-R13)/R13 -> 0.32692308
C15: Denmark | D15: Private | M15: 51 | N15: 62 | O15: 58 | P15: 45 | Q15: 36 | R15: 30 | S15: 28 | T15: 27 | U15: 27 | V15: 38
D16: y/y | Q16: =(Q15-M15)/M15 -> -0.29411765 | R16: =(R15-N15)/N15 -> -0.51612903 | S16: =(S15-O15)/O15 -> -0.51724138 | T16: =(T15-P15)/P15 -> -0.4 | U16: =(U15-Q15)/Q15 -> -0.25 | V16: =(V15-R15)/R15 -> 0.26666667 | AA16: -0.37 | AB16: 0.23 | AC16: 0.43
B18: Real Estate | C18: Norway | D18: Total | M18: 51 | N18: 74 | O18: 67 | P18: 49 | Q18: 55 | R18: 70 | S18: 61 | T18: 45 | U18: 52 | V18: 68
D19: y/y | Q19: =(Q18-M18)/M18 -> 0.078431373 | R19: =(R18-N18)/N18 -> -0.054054054 | S19: =(S18-O18)/O18 -> -0.089552239 | T19: =(T18-P18)/P18 -> -0.081632653 | U19: =(U18-Q18)/Q18 -> -0.054545455 | V19: =(V18-R18)/R18 -> -0.028571429 | AA19: 0 | AB19: -0.03 | AC19: -0.05
C20: Norway | D20: Residential for sale | M20: 23 | N20: 38 | O20: 31 | P20: 21 | Q20: 29 | R20: 40 | S20: 30 | T20: 21 | U20: 27 | V20: 40
D21: y/y | Q21: =(Q20-M20)/M20 -> 0.26086957 | R21: =(R20-N20)/N20 -> 0.052631579 | S21: =(S20-O20)/O20 -> -0.032258065 | T21: =(T20-P20)/P20 -> 0 | U21: =(U20-Q20)/Q20 -> -0.068965517 | V21: =(V20-R20)/R20 -> 0 | AA21: 0.05 | AB21: -0.02 | AC21: -0.04
C22: Finland | D22: Total | M22: 104 | N22: 111 | O22: 107 | P22: 91 | Q22: 103 | R22: 108 | S22: 97 | T22: 88 | U22: 1569 | V22: 1562
D23: y/y | Q23: =(Q22-M22)/M22 -> -0.0096153846 | R23: =(R22-N22)/N22 -> -0.027027027 | S23: =(S22-O22)/O22 -> -0.093457944 | T23: =(T22-P22)/P22 -> -0.032967033 | U23: =(U22-Q22)/Q22 -> 14.23301 | V23: =(V22-R22)/R22 -> 13.462963
B25: Jobs | C25: Norway | D25: Total | M25: 44 | N25: 41 | O25: 35 | P25: 34 | Q25: 40 | R25: 35 | S25: 30 | T25: 31 | U25: 38 | V25: 32
D26: y/y | Q26: =(Q25-M25)/M25 -> -0.090909091 | R26: =(R25-N25)/N25 -> -0.14634146 | S26: =(S25-O25)/O25 -> -0.14285714 | T26: =(T25-P25)/P25 -> -0.088235294 | U26: =(U25-Q25)/Q25 -> -0.05 | V26: =(V25-R25)/R25 -> -0.085714286 | AA26: -0.08 | AB26: -0.13 | AC26: -0.04

Sheet Recommerce
A2: GMV = Gross merchandise value
A3: Torget
Z4: QTD
B5: Vertical | C5: Country | D5: Category | E5: Q122 | F5: Q222 | G5: Q322 | H5: Q422 | I5: Q123 | J5: Q223 | K5: Q323 | L5: Q423 | M5: Q124 | N5: Q224 | O5: Q324 | P5: Q424 | Q5: Q125 | R5: Q225 | S5: Q325 | T5: Q425 | U5: Q126 | V5: Q226 | W5: Q326 | X5: Q426 | Z5: Q1 | AA5: Q2 | AB5: Q3 | AC5: Q4
B6: Recommerce | C6: Norway | D6: Transacted GMV (million) | O6: 481 | P6: 540 | Q6: 531 | R6: 549 | S6: 569 | T6: 620 | U6: 634 | V6: 664
D7: y/y | S7: =(S6-O6)/O6 -> 0.18295218 | T7: =(T6-P6)/P6 -> 0.14814815 | U7: =(U6-Q6)/Q6 -> 0.19397363 | V7: =(V6-R6)/R6 -> 0.20947177 | Z7: 0.19 | AA7: 0.18 | AB7: 0.21
C8: Norway | D8: Take rate | O8: 0.16 | P8: 0.16 | Q8: 0.16 | R8: 0.15 | S8: 0.16 | T8: 0.17 | U8: 0.16 | V8: 0.16
C9: Sweden | D9: Transacted GMV (million) | O9: 173 | P9: 177 | Q9: 201 | R9: 191 | S9: 198 | T9: 176 | U9: 180 | V9: 195
D10: y/y | S10: =(S9-O9)/O9 -> 0.14450867 | T10: =(T9-P9)/P9 -> -0.0056497175 | U10: =(U9-Q9)/Q9 -> -0.10447761 | V10: =(V9-R9)/R9 -> 0.020942408 | Z10: -0.14 | AA10: 0 | AB10: 0.1
C11: Sweden | D11: Take rate | O11: 0.1 | P11: 0.1 | Q11: 0.1 | R11: 0.1 | S11: 0.1 | T11: 0.11 | U11: 0.11 | V11: 0.1
C12: Finland | D12: Transacted GMV (million) | O12: 8 | P12: 12 | Q12: 12 | R12: 13 | S12: 16 | T12: 18 | U12: 17 | V12: 17
D13: y/y | S13: =(S12-O12)/O12 -> 1 | T13: =(T12-P12)/P12 -> 0.5 | U13: =(U12-Q12)/Q12 -> 0.41666667 | V13: =(V12-R12)/R12 -> 0.30769231 | Z13: 0.46 | AA13: 0.35 | AB13: 0.31
C14: Finland | D14: Take rate | O14: 0.15 | P14: 0.16 | Q14: 0.17 | R14: 0.16 | S14: 0.16 | T14: 0.17 | U14: 0.17 | V14: 0.17
C15: Denmark | D15: Transacted GMV (million) | Q15: 16 | R15: 33 | S15: 40 | T15: 51 | U15: 57 | V15: 56
D16: y/y | U16: =(U15-Q15)/Q15 -> 2.5625 | V16: =(V15-R15)/R15 -> 0.6969697 | AA16: 0.73 | AB16: 0.47
C17: Denmark | D17: Take rate | Q17: 0.14 | R17: 0.15 | S17: 0.15 | T17: 0.15 | U17: 0.15 | V17: 0.15

Sheet Nøkkeltall
D4: 2026 | E4: 2027 | F4: 2028
C5: EV/EBITDA | D5: =Modell!$B$9/Modell!AG17 -> 15.789477 | E5: =Modell!$B$9/Modell!AH17 -> 12.826316 | F5: =Modell!$B$9/Modell!AI17 -> 10.237909
C6: EV/EBIT | D6: =Modell!$B$9/Modell!AG22 -> 25.149833 | E6: =Modell!$B$9/Modell!AH22 -> 18.384689 | F6: =Modell!$B$9/Modell!AI22 -> 13.892145
C7: P/E | D7: =Modell!$B$4/Modell!AG31 -> 34.950205 | E7: =Modell!$B$4/Modell!AH31 -> 24.791169 | F7: =Modell!$B$4/Modell!AI31 -> 18.733116

Sheet Nedsideberegning
A1: Nedsideberegning – EV/EBITDA sensitivitet
A3: Inputs
A4: EBITDA 2027e (NOKm) | B4: =Modell!AH17 -> 2976.8097
A5: Antall aksjer (m) | B5: 201.887
A6: Nåværende EV (NOKm) | B6: =Modell!B9 -> 38181.5
A8: EV/EBITDA | B8: Implisitt EV (NOKm) | C8: Pris/aksje (NOK) | D8: vs. nåv. EV
A9: 10,0x | B9: =$B$4*10 -> 29768.097 | C9: =B9/$B$5 -> 147.4493 | D9: =B9/$B$6-1 -> -0.22035288
A10: 11,0x | B10: =$B$4*11 -> 32744.906 | C10: =B10/$B$5 -> 162.19423 | D10: =B10/$B$6-1 -> -0.14238817
A11: 12,0x | B11: =$B$4*12 -> 35721.716 | C11: =B11/$B$5 -> 176.93916 | D11: =B11/$B$6-1 -> -0.064423455
A12: 13,0x | B12: =$B$4*13 -> 38698.526 | C12: =B12/$B$5 -> 191.68409 | D12: =B12/$B$6-1 -> 0.013541257
A13: 14,0x | B13: =$B$4*14 -> 41675.335 | C13: =B13/$B$5 -> 206.42902 | D13: =B13/$B$6-1 -> 0.091505969
A14: 15,0x | B14: =$B$4*15 -> 44652.145 | C14: =B14/$B$5 -> 221.17395 | D14: =B14/$B$6-1 -> 0.16947068
A15: 16,0x | B15: =$B$4*16 -> 47628.954 | C15: =B15/$B$5 -> 235.91888 | D15: =B15/$B$6-1 -> 0.24743539
A16: 17,0x | B16: =$B$4*17 -> 50605.764 | C16: =B16/$B$5 -> 250.66381 | D16: =B16/$B$6-1 -> 0.32540011
A17: 18,0x | B17: =$B$4*18 -> 53582.574 | C17: =B17/$B$5 -> 265.40874 | D17: =B17/$B$6-1 -> 0.40336482
A18: 19,0x | B18: =$B$4*19 -> 56559.383 | C18: =B18/$B$5 -> 280.15367 | D18: =B18/$B$6-1 -> 0.48132953
A19: 20,0x | B19: =$B$4*20 -> 59536.193 | C19: =B19/$B$5 -> 294.8986 | D19: =B19/$B$6-1 -> 0.55929424
A20: 21,0x | B20: =$B$4*21 -> 62513.003 | C20: =B20/$B$5 -> 309.64353 | D20: =B20/$B$6-1 -> 0.63725895
A21: 22,0x | B21: =$B$4*22 -> 65489.812 | C21: =B21/$B$5 -> 324.38846 | D21: =B21/$B$6-1 -> 0.71522367
A22: 23,0x | B22: =$B$4*23 -> 68466.622 | C22: =B22/$B$5 -> 339.13339 | D22: =B22/$B$6-1 -> 0.79318838
A23: 24,0x | B23: =$B$4*24 -> 71443.432 | C23: =B23/$B$5 -> 353.87832 | D23: =B23/$B$6-1 -> 0.87115309
A24: 25,0x | B24: =$B$4*25 -> 74420.241 | C24: =B24/$B$5 -> 368.62325 | D24: =B24/$B$6-1 -> 0.9491178
A25: 26,0x | B25: =$B$4*26 -> 77397.051 | C25: =B25/$B$5 -> 383.36818 | D25: =B25/$B$6-1 -> 1.0270825
A26: 27,0x | B26: =$B$4*27 -> 80373.861 | C26: =B26/$B$5 -> 398.11311 | D26: =B26/$B$6-1 -> 1.1050472
A27: 28,0x | B27: =$B$4*28 -> 83350.67 | C27: =B27/$B$5 -> 412.85804 | D27: =B27/$B$6-1 -> 1.1830119
A28: 29,0x | B28: =$B$4*29 -> 86327.48 | C28: =B28/$B$5 -> 427.60297 | D28: =B28/$B$6-1 -> 1.2609767
A29: 30,0x | B29: =$B$4*30 -> 89304.29 | C29: =B29/$B$5 -> 442.3479 | D29: =B29/$B$6-1 -> 1.3389414
