Workbook

Sheet Info
G3: Synsam lifestyle: Brilleabonnement som kunden betaler fast hver måned.
G4: Du får tilgang til 3 par briller, styrke, solbriller og sportsbriller
G5: Gratis synstest hvert år
G6: Mulighet til å bytte ett åar briller årlig
G7: Linser inkludert ved synsendring
N8: Tilbakekjøpsprogram
G9: Synsam EyeView: Synsams svar på optikermangel i Sverige og Norge | N9: Dato kjøp | O9: Antall aksjer | P9: Akummelert antall aksjer | Q9: Kjøp | R9: Akkumelert kjøp
G10: optiker kan gjennomføre synsundersøkelse delvus eller fullt ut på distanse. | N10: 45901 | O10: 100000 | P10: =O10 -> 100000 | Q10: =1147566+1117700+1136668+1149502+1167842 -> 5719278 | R10: =Q10 -> 5719278
G11: En tekniker er fysisk tilstede i butikken med pasienten og betjener utstyret, | N11: 45908 | O11: 100000 | P11: =SUM(O10:O11) -> 200000
G12: mens kvalifiserte optiker kan sitte et annet sted og tolke resultat digitalt.
G15: Finne info om egen prod og egne merker
G17: Tar 2 år for en nyetablert butikk til å bli like lønnsom som en etablert butikk
A26: Press releases:
A27: 28.09.26: Synsam kjøper tilbake 100 000 akskjer
A28: 21.09.26: Synsam kjøper tilbake 100 000 aksjer
A29: 14.09.26: Synsam inngår samarbeid med Carola og blir en ambasadør for Synsam. Hennes egen kolleksjon vil bli tilgjengligjort for salg tidlig 2027
A30: 14.09.26: Synsam kjøper tilbake 100 000 aksjer
A31: 07.09.26: Synsam kjøper tilbake 100 000 aksjer
A32: 31.08.26: Synsam kjøper tilbake 100 000 aksjer
A33: 24.08.26: Synsam kjøper tilbale 95 000 aksjer
A34: 17.08.26: Synsam kjøper tilbake 100 000 aksjer
A35: 10.08.26: Synsam kjøper tilbake 104 000 aksjer
A36: 03.08.26: Synsam kjøper tilbake 122 000 aksjer
A37: 27.07.26: Synsam kjøper tilbake 50 000 aksjer
... A78: 21.08.25: Synsam starter tilbakekjøpsprgram for å justerer kapitalstrukturen sin 160 SEKm

Sheet Modell
A3: Kapitalstruktur | C3: SEKm | D3: Q122 | E3: Q222 | F3: Q322 | G3: Q422 | H3: Q123 | I3: Q223 | J3: Q323 | K3: Q423 | L3: Q124 | M3: Q224 | N3: Q324 | O3: Q424 | P3: Q125 | Q3: Q225 | R3: Q325 | S3: Q425 | T3: Q126 | U3: Q226 | V3: Q326 | W3: Q426 | Z3: FY 2020 | AA3: FY 2021 | AB3: FY 2022 | AC3: FY 2023 | AD3: FY 2024 | AE3: FY 2025 | AF3: FY 2026 | AG3: FY 2027 | AH3: FY 2028 | AI3: FY 2029 | AJ3: FY 2030 | AK3: FY 2031 | AL3: FY 2032 | AM3: FY 2033 | AN3: FY 2034 | AO3: FY 2035
A4: Price | B4: 53 | C4: Revenue | D4: 1204 | E4: 1415 | F4: 1335 | G4: 1395 | H4: 1425 | I4: 1584 | J4: 1479 | K4: 1497 | L4: 1536 | M4: 1744 | N4: 1583 | O4: 1659 | P4: 1735 | Q4: 1877 | R4: 1753 | S4: 1834 | T4: 1801 | U4: 2081 | Z4: 3860 | AA4: 4728 | AB4: 5349 | AC4: 5985 | AD4: 6522 | AE4: 7200 | AF4: =AE4*1.073 -> 7725.6 | AG4: =AF4*1.06 -> 8189.136 | AH4: =AG4*1.06 -> 8680.4842 | AI4: =AH4*1.06 -> 9201.3132 | AJ4: =AI4*1.06 -> 9753.392 | AK4: =AJ4*1.06 -> 10338.596 | AL4: =AK4*1.06 -> 10958.911 | AM4: =AL4*1.06 -> 11616.446 | AN4: =AM4*1.06 -> 12313.433 | AO4: =AN4*1.06 -> 13052.239
A5: S/O | B5: 142.81814 | C5: Goods for resale | D5: -246 | E5: -368 | F5: -345 | G5: -319 | H5: -331 | I5: -407 | J5: -364 | K5: -345 | L5: -369 | M5: -443 | N5: -407 | O5: -371 | P5: -442 | Q5: -495 | R5: -465 | S5: -419 | T5: -429 | U5: -541 | Z5: -953 | AA5: -1088 | AB5: -1279 | AC5: -1447 | AD5: -1591 | AE5: -1821 | AF5: =AF4*-0.25 -> -1931.4 | AG5: =AG4*-0.25 -> -2047.284 | AH5: =AH4*-0.25 -> -2170.121 | AI5: =AI4*-0.25 -> -2300.3283 | AJ5: =AJ4*-0.25 -> -2438.348 | AK5: =AK4*-0.25 -> -2584.6489 | AL5: =AL4*-0.25 -> -2739.7278 | AM5: =AM4*-0.25 -> -2904.1115 | ... AO5: =AO4*-0.25 -> -3263.0597
A6: MC SEKm | B6: =B4*B5 -> 7569.3614 | C6: Gross profit | D6: =SUM(D4:D5) -> 958 | E6: =SUM(E4:E5) -> 1047 | F6: =SUM(F4:F5) -> 990 | G6: =SUM(G4:G5) -> 1076 | H6: =SUM(H4:H5) -> 1094 | I6: =SUM(I4:I5) -> 1177 | J6: =SUM(J4:J5) -> 1115 | K6: =SUM(K4:K5) -> 1152 | ... U6: =SUM(U4:U5) -> 1540 | Z6: =SUM(Z4:Z5) -> 2907 | AA6: =SUM(AA4:AA5) -> 3640 | AB6: =SUM(AB4:AB5) -> 4070 | AC6: =SUM(AC4:AC5) -> 4538 | AD6: =SUM(AD4:AD5) -> 4931 | AE6: =SUM(AE4:AE5) -> 5379 | AF6: =SUM(AF4:AF5) -> 5794.2 | AG6: =SUM(AG4:AG5) -> 6141.852 | ... AO6: =SUM(AO4:AO5) -> 9789.179
A7: Cash SEKm | B7: =U53 -> 648 | C7: Other external expenses | D7: -153 | E7: -168 | F7: -168 | G7: -179 | H7: -176 | I7: -169 | J7: -164 | K7: -173 | L7: -174 | M7: -178 | N7: -174 | O7: -186 | P7: -191 | Q7: -204 | R7: -188 | S7: -221 | T7: -210 | U7: -243 | Z7: -468 | AA7: -629 | AB7: -667 | AC7: -682 | AD7: -711 | AE7: -805 | AF7: =AE7*1.07 -> -861.35 | AG7: =AF7*1.055 -> -908.72425 | AH7: =AG7*1.055 -> -958.70408 | AI7: =AH7*1.06 -> -1016.2263 | AJ7: =AI7*1.06 -> -1077.1999 | AK7: =AJ7*1.06 -> -1141.8319 | AL7: =AK7*1.06 -> -1210.3418 | AM7: =AL7*1.06 -> -1282.9623 | AN7: =AM7*1.06 -> -1359.9401 | AO7: =AN7*1.06 -> -1441.5365
A8: Debt SEKm | B8: =U56+U61+U57+U62 -> 3653 | C8: Persnonnel costs | D8: -512 | E8: -531 | F8: -520 | G8: -624 | H8: -600 | I8: -607 | J8: -577 | K8: -631 | L8: -634 | M8: -654 | N8: -621 | O8: -715 | P8: -727 | Q8: -708 | R8: -682 | S8: -768 | T8: -762 | U8: -784 | Z8: -1505 | AA8: -1823 | AB8: -2186 | AC8: -2415 | AD8: -2624 | AE8: -2886 | AF8: =AE8*1.07 -> -3088.02 | AG8: =AF8*1.055 -> -3257.8611 | AH8: =AG8*1.055 -> -3437.0435 | AI8: =AH8*1.06 -> -3643.2661 | AJ8: =AI8*1.06 -> -3861.862 | AK8: =AJ8*1.06 -> -4093.5738 | AL8: =AK8*1.06 -> -4339.1882 | AM8: =AL8*1.06 -> -4599.5395 | AN8: =AM8*1.06 -> -4875.5118 | AO8: =AN8*1.06 -> -5168.0425
A9: EV SEKm | B9: =B6-B7+B8 -> 10574.361 | C9: EBITDA | D9: =SUM(D6:D8) -> 293 | E9: =SUM(E6:E8) -> 348 | F9: =SUM(F6:F8) -> 302 | G9: =SUM(G6:G8) -> 273 | H9: =SUM(H6:H8) -> 318 | I9: =SUM(I6:I8) -> 401 | J9: =SUM(J6:J8) -> 374 | K9: =SUM(K6:K8) -> 348 | ... U9: =SUM(U6:U8) -> 513 | Z9: =SUM(Z6:Z8) -> 934 | AA9: =SUM(AA6:AA8) -> 1188 | AB9: =SUM(AB6:AB8) -> 1217 | AC9: =SUM(AC6:AC8) -> 1441 | AD9: =SUM(AD6:AD8) -> 1596 | AE9: =SUM(AE6:AE8) -> 1688 | AF9: =SUM(AF6:AF8) -> 1844.83 | AG9: =SUM(AG6:AG8) -> 1975.2667 | ... AO9: =SUM(AO6:AO8) -> 3179.6
C10: Depreciation | D10: -116 | E10: -123 | F10: -134 | G10: -146 | H10: -147 | I10: -144 | J10: -151 | K10: -148 | L10: -153 | M10: -157 | N10: -161 | O10: -168 | P10: -168 | Q10: -171 | R10: -179 | S10: -180 | T10: -182 | U10: -187 | Z10: -445 | AA10: -464 | AB10: -556 | AC10: -622 | AD10: -649 | AE10: -702 | AF10: -740 | AG10: =AF10*1.06 -> -784.4 | AH10: =AG10*1.01 -> -792.244 | AI10: =AH10*1.01 -> -800.16644 | AJ10: =AI10*1.01 -> -808.1681 | AK10: =AJ10*1.01 -> -816.24979 | AL10: =AK10*1.01 -> -824.41228 | AM10: =AL10*1.01 -> -832.65641 | AN10: =AM10*1.01 -> -840.98297 | AO10: =AN10*1.01 -> -849.3928
C11: EBITA | D11: =SUM(D9:D10) -> 177 | E11: =SUM(E9:E10) -> 225 | F11: =SUM(F9:F10) -> 168 | G11: =SUM(G9:G10) -> 127 | H11: =SUM(H9:H10) -> 171 | I11: =SUM(I9:I10) -> 257 | J11: =SUM(J9:J10) -> 223 | K11: =SUM(K9:K10) -> 200 | ... U11: =SUM(U9:U10) -> 326 | Z11: =SUM(Z9:Z10) -> 489 | AA11: =SUM(AA9:AA10) -> 724 | AB11: =SUM(AB9:AB10) -> 661 | AC11: =SUM(AC9:AC10) -> 819 | AD11: =SUM(AD9:AD10) -> 947 | AE11: =SUM(AE9:AE10) -> 986 | AF11: =SUM(AF9:AF10) -> 1104.83 | AG11: =SUM(AG9:AG10) -> 1190.8666 | ... AO11: =SUM(AO9:AO10) -> 2330.2072
C12: Amortization | D12: -36 | E12: -36 | F12: -36 | G12: -37 | H12: -38 | I12: -38 | J12: -39 | K12: -39 | L12: -35 | M12: -37 | N12: -33 | O12: -33 | P12: -33 | Q12: -32 | R12: -32 | S12: -32 | T12: -32 | U12: -36 | Z12: -87 | AA12: -91 | AB12: -109 | AC12: -123 | AD12: -128 | AE12: -124 | AF12: -128 | AG12: =AF12*1.04 -> -133.12 | AH12: =AG12*1.01 -> -134.4512 | AI12: =AH12*1.01 -> -135.79571 | AJ12: =AI12*1.01 -> -137.15367 | AK12: =AJ12*1.01 -> -138.52521 | AL12: =AK12*1.01 -> -139.91046 | AM12: =AL12*1.01 -> -141.30956 | AN12: =AM12*1.01 -> -142.72266 | AO12: =AN12*1.01 -> -144.14988
A13: Gearing | B13: =(B8-B7)/AF9 -> 1.6288764 | C13: EBIT | D13: =SUM(D11:D12) -> 141 | E13: =SUM(E11:E12) -> 189 | F13: =SUM(F11:F12) -> 132 | G13: =SUM(G11:G12) -> 90 | H13: =SUM(H11:H12) -> 133 | I13: =SUM(I11:I12) -> 219 | J13: =SUM(J11:J12) -> 184 | K13: =SUM(K11:K12) -> 161 | ... U13: =SUM(U11:U12) -> 290 | Z13: =SUM(Z11:Z12) -> 402 | AA13: =SUM(AA11:AA12) -> 633 | AB13: =SUM(AB11:AB12) -> 552 | AC13: =SUM(AC11:AC12) -> 696 | AD13: =SUM(AD11:AD12) -> 819 | AE13: =SUM(AE11:AE12) -> 862 | AF13: =SUM(AF11:AF12) -> 976.83 | AG13: =SUM(AG11:AG12) -> 1057.7467 | ... AO13: =SUM(AO11:AO12) -> 2186.0573
C14: Fincial income | D14: 53 | E14: 19 | F14: 52 | G14: 60 | H14: 60 | I14: 69 | J14: 69 | K14: 75 | L14: 79 | M14: 84 | N14: 76 | O14: 87 | P14: 87 | Q14: 84 | R14: 77 | S14: 95 | T14: 120 | U14: 74 | Z14: 98 | AA14: 148 | AB14: 185 | AC14: 273 | AD14: 326 | AE14: 321 | AF14: =AE14*1.02 -> 327.42 | AG14: =AF14*1.02 -> 333.9684 | AH14: =AG14*1.02 -> 340.64777 | AI14: =AH14*1.02 -> 347.46072 | AJ14: =AI14*1.02 -> 354.40994 | AK14: =AJ14*1.02 -> 361.49814 | AL14: =AK14*1.02 -> 368.7281 | AM14: =AL14*1.02 -> 376.10266 | ... AO14: =AN14*1.02 -> 391.29721
A15: P/B | B15: =B6/+T55 -> 2.90459 | C15: Financial expenses | D15: -66 | E15: -79 | F15: -87 | G15: -91 | H15: -149 | I15: -124 | J15: -137 | K15: -144 | L15: -172 | M15: -147 | N15: -172 | O15: -160 | P15: -146 | Q15: -204 | R15: -119 | S15: -147 | T15: -142 | U15: -164 | Z15: -636 | AA15: -618 | AB15: -322 | AC15: -554 | AD15: -652 | AE15: -593 | AF15: =AE15*1.02 -> -604.86 | AG15: =AF15*1.02 -> -616.9572 | AH15: =AG15*1.02 -> -629.29634 | AI15: =AH15*1.02 -> -641.88227 | AJ15: =AI15*1.02 -> -654.71992 | AK15: =AJ15*1.02 -> -667.81431 | AL15: =AK15*1.02 -> -681.1706 | AM15: =AL15*1.02 -> -694.79401 | ... AO15: =AN15*1.02 -> -722.86369
C16: PTP | D16: =SUM(D13:D15) -> 128 | E16: =SUM(E13:E15) -> 129 | F16: =SUM(F13:F15) -> 97 | G16: =SUM(G13:G15) -> 59 | H16: =SUM(H13:H15) -> 44 | I16: =SUM(I13:I15) -> 164 | J16: =SUM(J13:J15) -> 116 | K16: =SUM(K13:K15) -> 92 | ... U16: =SUM(U13:U15) -> 200 | Z16: =SUM(Z13:Z15) -> -136 | AA16: =SUM(AA13:AA15) -> 163 | AB16: =SUM(AB13:AB15) -> 415 | AC16: =SUM(AC13:AC15) -> 415 | AD16: =SUM(AD13:AD15) -> 493 | AE16: =SUM(AE13:AE15) -> 590 | AF16: =SUM(AF13:AF15) -> 699.39 | AG16: =SUM(AG13:AG15) -> 774.75785 | ... AO16: =SUM(AO13:AO15) -> 1854.4908
C17: Tax | D17: -30 | E17: -31 | F17: -18 | G17: -8 | H17: -25 | I17: -24 | J17: -25 | K17: -30 | L17: -21 | M17: -44 | N17: -25 | O17: -37 | P17: -28 | Q17: -33 | R17: -35 | S17: -40 | T17: -34 | U17: -8 | Z17: -59 | AA17: -112 | AB17: -87 | AC17: -104 | AD17: -127 | AE17: -136 | AF17: =AF16*-0.2 -> -139.878 | AG17: =AG16*-0.2 -> -154.95157 | AH17: =AH16*-0.2 -> -179.85436 | AI17: =AI16*-0.2 -> -202.22176 | AJ17: =AJ16*-0.2 -> -226.07006 | AK17: =AK16*-0.2 -> -251.48996 | AL17: =AL16*-0.2 -> -278.57764 | AM17: =AM16*-0.2 -> -307.43507 | ... AO17: =AO16*-0.2 -> -370.89816
C18: Net income | D18: =SUM(D16:D17) -> 98 | E18: =SUM(E16:E17) -> 98 | F18: =SUM(F16:F17) -> 79 | G18: =SUM(G16:G17) -> 51 | H18: =SUM(H16:H17) -> 19 | I18: =SUM(I16:I17) -> 140 | J18: =SUM(J16:J17) -> 91 | K18: =SUM(K16:K17) -> 62 | ... U18: =SUM(U16:U17) -> 192 | Z18: =SUM(Z16:Z17) -> -195 | AA18: =SUM(AA16:AA17) -> 51 | AB18: =SUM(AB16:AB17) -> 328 | AC18: =SUM(AC16:AC17) -> 311 | AD18: =SUM(AD16:AD17) -> 366 | AE18: =SUM(AE16:AE17) -> 454 | AF18: =SUM(AF16:AF17) -> 559.512 | AG18: =SUM(AG16:AG17) -> 619.80628 | ... AO18: =SUM(AO16:AO17) -> 1483.5926 | AP18: =AO18*(1+$AR$22) -> 1468.7567 | AQ18: =AP18*(1+$AR$22) -> 1454.0691 | AR18: =AQ18*(1+$AR$22) -> 1439.5285 | AS18: =AR18*(1+$AR$22) -> 1425.1332 | AT18: =AS18*(1+$AR$22) -> 1410.8818 | AU18: =AT18*(1+$AR$22) -> 1396.773 | AV18: =AU18*(1+$AR$22) -> 1382.8053 | AW18: =AV18*(1+$AR$22) -> 1368.9772 | ... GW18: =GV18*(1+$AR$22) -> 285.42143
C19: Share | L19: 147.6 | M19: 146.64875 | N19: 147.82345 | O19: 146.64875 | P19: 144.51324 | Q19: 142.81814 | R19: 143.9736 | S19: 142.81814 | T19: 141.96249 | U19: 141.96249 | Z19: 37.181942 | AA19: 150 | AB19: 149.055 | AC19: 147.42368 | AD19: 146.64875 | AE19: 142.81814 | AF19: 141.96249 | AG19: 141.96249 | AH19: 141.96249 | AI19: 141.96249 | AJ19: 141.96249 | AK19: 141.96249 | AL19: 141.96249 | AM19: 141.96249 | AN19: 141.96249 | AO19: 141.96249
C20: EPS | D20: =D18/D19 -> #DIV/0! | E20: =E18/E19 -> #DIV/0! | F20: =F18/F19 -> #DIV/0! | G20: =G18/G19 -> #DIV/0! | H20: =H18/H19 -> #DIV/0! | I20: =I18/I19 -> #DIV/0! | J20: =J18/J19 -> #DIV/0! | K20: =K18/K19 -> #DIV/0! | ... U20: =U18/U19 -> 1.3524699 | Z20: =Z18/Z19 -> -5.2444813 | AA20: =AA18/AA19 -> 0.34 | AB20: =AB18/AB19 -> 2.20053 | AC20: =AC18/AC19 -> 2.1095662 | AD20: =AD18/AD19 -> 2.4957595 | AE20: =AE18/AE19 -> 3.1788679 | AF20: =AF18/AF19 -> 3.9412663 | AG20: =AG18/AG19 -> 4.3659861 | ... AO20: =AO18/AO19 -> 10.450596
AQ21: Discount | AR21: 0.08
C22: Revenue y/y | H22: =(H4-D4)/D4 -> 0.18355482 | I22: =(I4-E4)/E4 -> 0.11943463 | J22: =(J4-F4)/F4 -> 0.10786517 | K22: =(K4-G4)/G4 -> 0.07311828 | L22: =(L4-H4)/H4 -> 0.077894737 | M22: =(M4-I4)/I4 -> 0.1010101 | N22: =(N4-J4)/J4 -> 0.070317782 | O22: =(O4-K4)/K4 -> 0.10821643 | ... U22: =(U4-Q4)/Q4 -> 0.10868407 | AA22: =(AA4-Z4)/Z4 -> 0.22487047 | AB22: =(AB4-AA4)/AA4 -> 0.13134518 | AC22: =(AC4-AB4)/AB4 -> 0.11890073 | AD22: =(AD4-AC4)/AC4 -> 0.089724311 | AE22: =(AE4-AD4)/AD4 -> 0.10395584 | AF22: =(AF4-AE4)/AE4 -> 0.073 | AG22: =(AG4-AF4)/AF4 -> 0.06 | AH22: =(AH4-AG4)/AG4 -> 0.06 | ... AO22: =(AO4-AN4)/AN4 -> 0.06 | AQ22: TV | AR22: -0.01
C23: Organic growth | D23: 0.123 | E23: 0.137 | F23: 0.096 | G23: 0.068 | H23: 0.175 | I23: 0.102 | J23: 0.07 | K23: 0.074 | L23: 0.077 | M23: 0.095 | N23: 0.094 | O23: 0.101 | P23: 0.128 | Q23: 0.091 | R23: 0.124 | S23: 0.114 | T23: 0.056 | U23: 0.098 | Z23: 0.032 | AA23: 0.232 | AB23: 0.106 | AC23: 0.103 | AD23: 0.092 | AE23: 0.114 | AQ23: NPV | AR23: =NPV(AR21,AF18:GW18) -> 13702.005
C24: Like-for-like | D24: 0.081 | E24: 0.095 | F24: 0.055 | G24: 0.04 | H24: 0.14 | I24: 0.07 | J24: 0.039 | K24: 0.043 | L24: 0.051 | M24: 0.068 | N24: 0.063 | O24: 0.061 | P24: 0.089 | Q24: 0.056 | R24: 0.091 | S24: 0.091 | T24: 0.038 | U24: 0.08 | AQ24: S/O | AR24: 141.96249
AQ25: NPV/Share | AR25: =AR23/AR24 -> 96.518485
C26: Gross margin | D26: =D6/D4 -> 0.79568106 | E26: =E6/E4 -> 0.73992933 | F26: =F6/F4 -> 0.74157303 | G26: =G6/G4 -> 0.77132616 | H26: =H6/H4 -> 0.7677193 | I26: =I6/I4 -> 0.74305556 | J26: =J6/J4 -> 0.75388776 | K26: =K6/K4 -> 0.76953908 | ... U26: =U6/U4 -> 0.74002883 | Z26: =Z6/Z4 -> 0.75310881 | AA26: =AA6/AA4 -> 0.76988156 | AB26: =AB6/AB4 -> 0.76088989 | AC26: =AC6/AC4 -> 0.75822891 | AD26: =AD6/AD4 -> 0.75605642 | AE26: =AE6/AE4 -> 0.74708333 | AF26: =AF6/AF4 -> 0.75 | AG26: =AG6/AG4 -> 0.75 | ... AO26: =AO6/AO4 -> 0.75 | AQ26: Opp/nedside | AR26: =(AR25-B4)/B4 -> 0.82110349
C27: EBITDA margin | D27: =D9/D4 -> 0.24335548 | E27: =E9/E4 -> 0.2459364 | F27: =F9/F4 -> 0.22621723 | G27: =G9/G4 -> 0.19569892 | H27: =H9/H4 -> 0.22315789 | I27: =I9/I4 -> 0.25315657 | J27: =J9/J4 -> 0.25287356 | K27: =K9/K4 -> 0.23246493 | ... U27: =U9/U4 -> 0.2465161 | Z27: =Z9/Z4 -> 0.24196891 | AA27: =AA9/AA4 -> 0.25126904 | AB27: =AB9/AB4 -> 0.22751916 | AC27: =AC9/AC4 -> 0.24076859 | AD27: =AD9/AD4 -> 0.24471021 | AE27: =AE9/AE4 -> 0.23444444 | AF27: =AF9/AF4 -> 0.2387944 | AG27: =AG9/AG4 -> 0.24120575 | ... AO27: =AO9/AO4 -> 0.24360572
C28: EBITA margin | D28: =D11/D4 -> 0.14700997 | E28: =E11/E4 -> 0.1590106 | F28: =F11/F4 -> 0.1258427 | G28: =G11/G4 -> 0.091039427 | H28: =H11/H4 -> 0.12 | I28: =I11/I4 -> 0.16224747 | J28: =J11/J4 -> 0.15077755 | K28: =K11/K4 -> 0.13360053 | ... U28: =U11/U4 -> 0.15665545 | Z28: =Z11/Z4 -> 0.12668394 | AA28: =AA11/AA4 -> 0.15313029 | AB28: =AB11/AB4 -> 0.1235745 | AC28: =AC11/AC4 -> 0.13684211 | AD28: =AD11/AD4 -> 0.14520086 | AE28: =AE11/AE4 -> 0.13694444 | AF28: =AF11/AF4 -> 0.14300896 | AG28: =AG11/AG4 -> 0.1454203 | ... AO28: =AO11/AO4 -> 0.17852931
C29: EBIT margin | D29: =D13/D4 -> 0.11710963 | E29: =E13/E4 -> 0.1335689 | F29: =F13/F4 -> 0.098876404 | G29: =G13/G4 -> 0.064516129 | H29: =H13/H4 -> 0.093333333 | I29: =I13/I4 -> 0.13825758 | J29: =J13/J4 -> 0.12440838 | K29: =K13/K4 -> 0.10754843 | ... U29: =U13/U4 -> 0.13935608 | Z29: =Z13/Z4 -> 0.10414508 | AA29: =AA13/AA4 -> 0.13388325 | AB29: =AB13/AB4 -> 0.10319686 | AC29: =AC13/AC4 -> 0.11629073 | AD29: =AD13/AD4 -> 0.12557498 | AE29: =AE13/AE4 -> 0.11972222 | AF29: =AF13/AF4 -> 0.12644066 | AG29: =AG13/AG4 -> 0.12916462 | ... AO29: =AO13/AO4 -> 0.16748524
C30: ROE | AA30: =AA18/AA55 -> 0.020572812 | AB30: 0.129 | AC30: 0.122 | AD30: 0.145 | AE30: 0.184
C32: Active customers Synsam Lifestyle (thousand) | D32: 419 | E32: 449 | F32: 478 | G32: 511 | H32: 542 | I32: 572 | J32: 595 | K32: 620 | L32: 645 | M32: 667 | N32: 683 | O32: 703 | P32: 718 | Q32: 730 | R32: 741 | S32: 756 | T32: 770 | U32: 782 | AB32: 511 | AC32: 620 | AD32: 703 | AE32: 756
C33: q/q | E33: =(E32-D32)/D32 -> 0.071599045 | F33: =(F32-E32)/E32 -> 0.064587973 | G33: =(G32-F32)/F32 -> 0.069037657 | H33: =(H32-G32)/G32 -> 0.060665362 | I33: =(I32-H32)/H32 -> 0.055350554 | J33: =(J32-I32)/I32 -> 0.04020979 | K33: =(K32-J32)/J32 -> 0.042016807 | L33: =(L32-K32)/K32 -> 0.040322581 | ... U33: =(U32-T32)/T32 -> 0.015584416
C34: Churn | D34: 0.022 | E34: 0.0212 | F34: 0.0217 | G34: 0.0211 | H34: 0.0217 | I34: 0.0186 | J34: 0.0204 | K34: 0.0228 | L34: 0.0233 | M34: 0.0251 | N34: 0.026 | O34: 0.0269 | P34: 0.0284 | Q34: 0.0291 | R34: 0.0288 | S34: 0.0297 | T34: 0.0304 | U34: 0.0305 | AC34: =(AC32-AB32)/AB32 -> 0.21330724 | AD34: =(AD32-AC32)/AC32 -> 0.13387097 | AE34: =(AE32-AD32)/AD32 -> 0.075391181
C35: → Churnet (est.) | E35: =-E34*D32 -> -8.8828 | F35: =-F34*E32 -> -9.7433 | G35: =-G34*F32 -> -10.0858 | H35: =-H34*G32 -> -11.0887 | I35: =-I34*H32 -> -10.0812 | J35: =-J34*I32 -> -11.6688 | K35: =-K34*J32 -> -13.566 | L35: =-L34*K32 -> -14.446 | ... U35: =-U34*T32 -> -23.485
C36: → Brutto nye (est.) | E36: =E32-D32-E35 -> 38.8828 | F36: =F32-E32-F35 -> 38.7433 | G36: =G32-F32-G35 -> 43.0858 | H36: =H32-G32-H35 -> 42.0887 | I36: =I32-H32-I35 -> 40.0812 | J36: =J32-I32-J35 -> 34.6688 | K36: =K32-J32-K35 -> 38.566 | L36: =L32-K32-L35 -> 39.446 | ... U36: =U32-T32-U35 -> 35.485
C37: → Churn ex. Denmark | H37: 0.0197 | I37: 0.0184 | J37: 0.0185 | K37: 0.0207 | L37: 0.0213 | M37: 0.0231 | N37: 0.0237 | O37: 0.0258 | P37: 0.0267 | Q37: 0.0268 | R37: 0.0267 | S37: 0.0274 | T37: 0.0264 | U37: 0.0271
C38: Share of sales Synsam lifestyle | U38: 0.54
C40: Number of stores | D40: 509 | E40: 520 | F40: 520 | G40: 536 | H40: 537 | I40: 536 | J40: 542 | K40: 547 | L40: 553 | M40: 565 | N40: 574 | O40: 586 | P40: 588 | Q40: 598 | R40: 601 | S40: 603 | T40: 602 | U40: 604
C41: Directly owned | D41: 476 | E41: 487 | F41: 487 | G41: 503 | H41: 504 | I41: 504 | J41: 511 | K41: 517 | L41: 526 | M41: 538 | N41: 547 | O41: 560 | P41: 562 | Q41: 573 | R41: 576 | S41: 578 | T41: 579 | U41: 584
C42: Fanchised | D42: =D40-D41 -> 33 | E42: =E40-E41 -> 33 | F42: =F40-F41 -> 33 | G42: =G40-G41 -> 33 | H42: =H40-H41 -> 33 | I42: =I40-I41 -> 32 | J42: =J40-J41 -> 31 | K42: =K40-K41 -> 30 | ... U42: =U40-U41 -> 20
C44: Balanse SEKm
C45: Intangible non-current assets | D45: 4697 | E45: 4683 | F45: 4695 | G45: 4712 | H45: 4647 | I45: 4719 | J45: 4652 | K45: 4541 | L45: 4581 | M45: 4548 | N45: 4482 | O45: 4498 | P45: 4372 | Q45: 4385 | R45: 4351 | S45: 4273 | T45: 4319 | U45: 4376 | Z45: 4666 | AA45: 4665 | AB45: 4712 | AC45: 4541 | AD45: 4498 | AE45: 4273
...

Sheet Segementer
B4: SEKm | C4: Q122 | D4: Q222 | E4: Q322 | F4: Q422 | G4: 2022 | H4: Q123 | I4: Q223 | J4: Q323 | K4: Q423 | L4: 2023 | M4: Q124 | N4: Q224 | O4: Q324 | P4: Q424 | Q4: 2024 | R4: Q125 | S4: Q225 | T4: Q325 | U4: Q425 | V4: 2025 | W4: Q126 | X4: Q226 | Y4: Q326 | Z4: Q426 | AA4: 2026
B5: Sweden
B6: Synsam Lifestyle | C6: 298 | D6: 359 | E6: 321 | F6: 396 | G6: =SUM(C6:F6) -> 1374 | H6: 378 | I6: 403 | J6: 370 | K6: 435 | L6: =SUM(H6:K6) -> 1586 | M6: 452 | N6: 468 | O6: 395 | P6: 484 | Q6: =SUM(M6:P6) -> 1799 | R6: 488 | S6: 536 | T6: 477 | U6: 556 | V6: =SUM(R6:U6) -> 2057 | W6: 532 | X6: 597 | AA6: =SUM(W6:Z6) -> 1129
B7: y/y | H7: =(H6-C6)/C6 -> 0.26845638 | I7: =(I6-D6)/D6 -> 0.12256267 | J7: =(J6-E6)/E6 -> 0.15264798 | K7: =(K6-F6)/F6 -> 0.098484848 | L7: =(L6-G6)/G6 -> 0.15429403 | M7: =(M6-H6)/H6 -> 0.1957672 | N7: =(N6-I6)/I6 -> 0.16129032 | O7: =(O6-J6)/J6 -> 0.067567568 | ... AA7: =(AA6-V6)/V6 -> -0.45114244
B8: Non-recurring rev | C8: 263 | D8: 323 | E8: 288 | F8: 286 | G8: =SUM(C8:F8) -> 1160 | H8: 292 | I8: 348 | J8: 306 | K8: 304 | L8: =SUM(H8:K8) -> 1250 | M8: 298 | N8: 352 | O8: 320 | P8: 323 | Q8: =SUM(M8:P8) -> 1293 | R8: 330 | S8: 379 | T8: 352 | U8: 349 | V8: =SUM(R8:U8) -> 1410 | W8: 340 | X8: 412 | AA8: =SUM(W8:Z8) -> 752
B9: y/y | H9: =(H8-C8)/C8 -> 0.11026616 | I9: =(I8-D8)/D8 -> 0.077399381 | J9: =(J8-E8)/E8 -> 0.0625 | K9: =(K8-F8)/F8 -> 0.062937063 | L9: =(L8-G8)/G8 -> 0.077586207 | M9: =(M8-H8)/H8 -> 0.020547945 | N9: =(N8-I8)/I8 -> 0.011494253 | O9: =(O8-J8)/J8 -> 0.045751634 | ... AA9: =(AA8-V8)/V8 -> -0.46666667
B10: Total revenue | C10: =C6+C8 -> 561 | D10: =D6+D8 -> 682 | E10: =E6+E8 -> 609 | F10: =F6+F8 -> 682 | G10: =G6+G8 -> 2534 | H10: =H6+H8 -> 670 | I10: =I6+I8 -> 751 | J10: =J6+J8 -> 676 | ... AA10: =AA6+AA8 -> 1881
B11: y/y | H11: =(H10-C10)/C10 -> 0.1942959 | I11: =(I10-D10)/D10 -> 0.10117302 | J11: =(J10-E10)/E10 -> 0.11001642 | K11: =(K10-F10)/F10 -> 0.083577713 | L11: =(L10-G10)/G10 -> 0.11917916 | M11: =(M10-H10)/H10 -> 0.11940299 | N11: =(N10-I10)/I10 -> 0.091877497 | O11: =(O10-J10)/J10 -> 0.057692308 | ... AA11: =(AA10-V10)/V10 -> -0.45745601
B12: Organic growth | C12: 0.106 | D12: 0.166 | E12: 0.107 | F12: 0.087 | H12: 0.194 | I12: 0.097 | J12: 0.104 | K12: 0.078 | L12: 0.115 | M12: 0.108 | N12: 0.084 | O12: 0.05 | P12: 0.088 | Q12: 0.083 | R12: 0.086 | S12: 0.109 | T12: 0.151 | U12: 0.112 | V12: 0.114 | W12: 0.065 | X12: 0.089
B13: Like-for-like | H13: 0.162 | I13: 0.069 | J13: 0.08 | K13: 0.056 | M13: 0.087 | N13: 0.065 | O13: 0.023 | P13: 0.059 | R13: 0.058 | S13: 0.086 | T13: 0.128 | U13: 0.094 | V13: 0.091 | W13: 0.047 | X13: 0.072
B14: Gross profit | C14: 444 | D14: 510 | E14: 473 | F14: 550 | G14: =SUM(C14:F14) -> 1977 | H14: 525 | I14: 570 | J14: 518 | K14: 580 | L14: =SUM(H14:K14) -> 2193 | M14: 588 | N14: 604 | O14: 543 | P14: 628 | Q14: =SUM(M14:P14) -> 2363 | R14: 610 | S14: 691 | T14: 622 | U14: 709 | V14: =SUM(R14:U14) -> 2632 | W14: 679 | X14: 773 | AA14: =SUM(W14:Z14) -> 1452
B15: Gross margin | C15: 0.785 | D15: 0.744 | E15: 0.771 | F15: 0.803 | G15: =G14/G10 -> 0.78018942 | H15: 0.78 | I15: 0.755 | J15: 0.763 | K15: 0.782 | L15: =L14/L10 -> 0.77327221 | M15: 0.78 | N15: 0.735 | O15: 0.75 | P15: 0.775 | Q15: =Q14/Q10 -> 0.76423027 | R15: 0.742 | S15: 0.751 | T15: 0.747 | U15: 0.78 | V15: =V14/V10 -> 0.75915777 | W15: 0.775 | X15: 0.763 | AA15: =AA14/AA10 -> 0.77192982
B16: EBITDA | C16: 152 | D16: 202 | E16: 191 | F16: 213 | G16: =SUM(C16:F16) -> 758 | H16: 196 | I16: 224 | J16: 223 | K16: 252 | L16: =SUM(H16:K16) -> 895 | M16: 257 | N16: 241 | O16: 222 | P16: 259 | Q16: =SUM(M16:P16) -> 979 | R16: 240 | S16: 276 | T16: 258 | U16: 286 | V16: =SUM(R16:U16) -> 1060 | W16: 267 | X16: 323 | AA16: =SUM(W16:Z16) -> 590
B17: EBITDA margin | C17: 0.269 | D17: 0.295 | E17: 0.312 | F17: 0.312 | G17: =G16/G10 -> 0.29913181 | H17: 0.292 | I17: 0.297 | J17: 0.328 | K17: 0.341 | L17: =L16/L10 -> 0.31558533 | M17: 0.341 | N17: 0.294 | O17: 0.308 | P17: 0.32 | Q17: =Q16/Q10 -> 0.31662354 | R17: 0.292 | S17: 0.301 | T17: 0.31 | U17: 0.315 | V17: =V16/V10 -> 0.30573983 | W17: 0.305 | X17: 0.319 | AA17: =AA16/AA10 -> 0.31366295
B18: EBIT | G18: =SUM(C18:F18) -> 0 | L18: =SUM(H18:K18) -> 0 | M18: 191 | N18: 175 | O18: 155 | P18: 189 | Q18: =SUM(M18:P18) -> 710 | R18: 168 | S18: 204 | T18: 182 | U18: 206 | V18: =SUM(R18:U18) -> 760 | W18: 185 | X18: 240 | AA18: =SUM(W18:Z18) -> 425
B19: EBIT margin | G19: =G18/G10 -> 0 | L19: =L18/L10 -> 0 | M19: =M18/M10 -> 0.25466667 | N19: =N18/N10 -> 0.21341463 | O19: 0.214 | P19: 0.234 | Q19: =Q18/Q10 -> 0.22962484 | R19: 0.205 | S19: =S18/S10 -> 0.22295082 | T19: 0.219 | U19: 0.227 | V19: =V18/V10 -> 0.21920969 | W19: 0.212 | X19: 0.237 | AA19: =AA18/AA10 -> 0.22594365
B20: Number of stores | C20: 231 | D20: 238 | E20: 238 | F20: 246 | H20: 245 | I20: 244 | J20: 246 | K20: 250 | M20: 251 | N20: 257 | O20: 258 | P20: 262 | R20: 263 | S20: 268 | T20: 269 | U20: 270 | W20: 269 | X20: 273
B21: Eyeview % | X21: 0.2
B22: Demark
B23: Synsam Lifestyle | C23: 118 | D23: 125 | E23: 125 | F23: 126 | G23: =SUM(C23:F23) -> 494 | H23: 152 | I23: 150 | J23: 133 | K23: 123 | L23: =SUM(H23:K23) -> 558 | M23: 141 | N23: 144 | O23: 139 | P23: 133 | Q23: =SUM(M23:P23) -> 557 | R23: 130 | S23: 113 | T23: 117 | U23: 105 | V23: =SUM(R23:U23) -> 465 | W23: 132 | X23: 146 | AA23: =SUM(W23:Z23) -> 278
B24: y/y | H24: =(H23-C23)/C23 -> 0.28813559 | I24: =(I23-D23)/D23 -> 0.2 | J24: =(J23-E23)/E23 -> 0.064 | K24: =(K23-F23)/F23 -> -0.023809524 | L24: =(L23-G23)/G23 -> 0.12955466 | M24: =(M23-H23)/H23 -> -0.072368421 | N24: =(N23-I23)/I23 -> -0.04 | O24: =(O23-J23)/J23 -> 0.045112782 | ... AA24: =(AA23-V23)/V23 -> -0.40215054
B25: Non-recurring rev | C25: 139 | D25: 161 | E25: 157 | F25: 140 | G25: =SUM(C25:F25) -> 597 | H25: 146 | I25: 172 | J25: 150 | K25: 154 | L25: =SUM(H25:K25) -> 622 | M25: 151 | N25: 185 | O25: 152 | P25: 155 | Q25: =SUM(M25:P25) -> 643 | R25: 156 | S25: 189 | T25: 171 | U25: 162 | V25: =SUM(R25:U25) -> 678 | W25: 153 | X25: 179 | AA25: =SUM(W25:Z25) -> 332
B26: y/y | H26: =(H25-C25)/C25 -> 0.050359712 | I26: =(I25-D25)/D25 -> 0.068322981 | J26: =(J25-E25)/E25 -> -0.044585987 | K26: =(K25-F25)/F25 -> 0.1 | L26: =(L25-G25)/G25 -> 0.041876047 | M26: =(M25-H25)/H25 -> 0.034246575 | N26: =(N25-I25)/I25 -> 0.075581395 | O26: =(O25-J25)/J25 -> 0.013333333 | ... AA26: =(AA25-V25)/V25 -> -0.51032448
B27: Total revenue | C27: =C23+C25 -> 257 | D27: =D23+D25 -> 286 | E27: =E23+E25 -> 282 | F27: =F23+F25 -> 266 | G27: =G23+G25 -> 1091 | H27: =H23+H25 -> 298 | I27: =I23+I25 -> 322 | J27: =J23+J25 -> 283 | ... AA27: =AA23+AA25 -> 610
B28: y/y | H28: =(H27-C27)/C27 -> 0.15953307 | I28: =(I27-D27)/D27 -> 0.12587413 | J28: =(J27-E27)/E27 -> 0.0035460993 | K28: =(K27-F27)/F27 -> 0.041353383 | L28: =(L27-G27)/G27 -> 0.081576535 | M28: =(M27-H27)/H27 -> -0.020134228 | N28: =(N27-I27)/I27 -> 0.02173913 | O28: =(O27-J27)/J27 -> 0.028268551 | ... AA28: =(AA27-V27)/V27 -> -0.46631671
B29: Organic growth | C29: 0.168 | D29: 0.032 | E29: 0.032 | F29: -0.053 | H29: 0.086 | I29: 0.031 | J29: -0.096 | K29: -0.004 | L29: 0.003 | M29: -0.026 | N29: 0.018 | O29: 0.056 | P29: 0.035 | Q29: 0.02 | R29: -0.016 | S29: -0.039 | T29: 0.023 | U29: -0.021 | V29: -0.014 | W29: 0.048 | X29: 0.088
B30: Like-for-like | H30: 0.083 | I30: 0.031 | J30: -0.097 | K30: -0.004 | M30: -0.026 | N30: 0.018 | O30: 0.051 | P30: 0.021 | R30: -0.037 | S30: -0.064 | T30: 0.002 | U30: -0.034 | V30: -0.034 | W30: 0.045 | X30: 0.088
B31: Gross profit | C31: 197 | D31: 222 | E31: 213 | F31: 204 | G31: =SUM(C31:F31) -> 836 | H31: 230 | I31: 240 | J31: 214 | K31: 209 | L31: =SUM(H31:K31) -> 893 | M31: 225 | N31: 244 | O31: 219 | P31: 220 | Q31: =SUM(M31:P31) -> 908 | R31: 217 | S31: 226 | T31: 213 | U31: 204 | V31: =SUM(R31:U31) -> 860 | W31: 202 | X31: 232 | AA31: =SUM(W31:Z31) -> 434
B32: Gross margin | C32: 0.766 | D32: 0.773 | E32: 0.749 | F32: 0.763 | G32: =G31/G27 -> 0.76626948 | H32: 0.773 | I32: 0.744 | J32: 0.752 | K32: 0.751 | L32: =L31/L27 -> 0.75677966 | M32: 0.77 | N32: 0.739 | O32: 0.755 | P32: 0.766 | Q32: =Q31/Q27 -> 0.75666667 | R32: 0.762 | S32: 0.748 | T32: 0.739 | U32: 0.752 | V32: =V31/V27 -> 0.75240595 | W32: 0.711 | X32: 0.714 | AA32: =AA31/AA27 -> 0.71147541
B33: EBITDA | C33: 61 | D33: 78 | E33: 80 | F33: 58 | G33: =SUM(C33:F33) -> 277 | H33: 79 | I33: 81 | J33: 69 | K33: 51 | L33: =SUM(H33:K33) -> 280 | M33: 70 | N33: 89 | O33: 74 | P33: 61 | Q33: =SUM(M33:P33) -> 294 | R33: 52 | S33: 63 | T33: 72 | U33: 48 | V33: =SUM(R33:U33) -> 235 | W33: 45 | X33: 64 | AA33: =SUM(W33:Z33) -> 109
B34: EBITDA margin | C34: 0.237 | D34: 0.271 | E34: 0.282 | F34: 0.218 | G34: =G33/G27 -> 0.25389551 | H34: 0.265 | I34: 0.251 | J34: 0.245 | K34: 0.183 | L34: =L33/L27 -> 0.23728814 | M34: 0.239 | N34: 0.271 | O34: 0.255 | P34: 0.213 | Q34: =Q33/Q27 -> 0.245 | R34: 0.182 | S34: 0.21 | T34: 0.251 | U34: 0.179 | V34: =V33/V27 -> 0.2055993 | W34: 0.158 | X34: 0.199 | AA34: =AA33/AA27 -> 0.17868852
B35: EBIT | G35: =SUM(C35:F35) -> 0 | L35: =SUM(H35:K35) -> 0 | M35: 45 | N35: 64 | O35: 48 | P35: 33 | Q35: =SUM(M35:P35) -> 190 | R35: 24 | S35: 34 | T35: 43 | U35: 20 | V35: =SUM(R35:U35) -> 121 | W35: 17 | X35: 36 | AA35: =SUM(W35:Z35) -> 53
B36: EBIT margin | G36: =G35/G27 -> 0 | L36: =L35/L27 -> 0 | M36: =M35/M27 -> 0.15410959 | N36: =N35/N27 -> 0.19452888 | O36: 0.166 | P36: 0.115 | Q36: =Q35/Q27 -> 0.15833333 | R36: 0.083 | S36: =S35/S27 -> 0.11258278 | T36: 0.148 | U36: 0.073 | V36: =V35/V27 -> 0.10586177 | W36: 0.059 | X36: 0.111 | AA36: =AA35/AA27 -> 0.086885246
B37: Number of stores | C37: 116 | D37: 116 | E37: 116 | F37: 116 | H37: 116 | I37: 116 | J37: 115 | K37: 114 | M37: 114 | N37: 114 | O37: 115 | P37: 115 | R37: 116 | S37: 117 | T37: 117 | U37: 115 | W37: 114 | X37: 114
B38: Norway
B39: Synsam Lifestyle | C39: 111 | D39: 121 | E39: 131 | F39: 143 | G39: =SUM(C39:F39) -> 506 | H39: 135 | I39: 130 | J39: 142 | K39: 139 | L39: =SUM(H39:K39) -> 546 | M39: 143 | N39: 159 | O39: 152 | P39: 166 | Q39: =SUM(M39:P39) -> 620 | R39: 171 | S39: 168 | T39: 171 | U39: 177 | V39: =SUM(R39:U39) -> 687 | W39: 177 | X39: 204
B40: y/y | H40: =(H39-C39)/C39 -> 0.21621622 | I40: =(I39-D39)/D39 -> 0.074380165 | J40: =(J39-E39)/E39 -> 0.083969466 | K40: =(K39-F39)/F39 -> -0.027972028 | L40: =(L39-G39)/G39 -> 0.079051383 | M40: =(M39-H39)/H39 -> 0.059259259 | N40: =(N39-I39)/I39 -> 0.22307692 | O40: =(O39-J39)/J39 -> 0.070422535 | ... AA40: =(AA39-V39)/V39 -> -1
B41: Non-recurring rev | C41: 146 | D41: 174 | E41: 161 | F41: 141 | G41: =SUM(C41:F41) -> 622 | H41: 149 | I41: 177 | J41: 166 | K41: 137 | L41: =SUM(H41:K41) -> 629 | M41: 144 | N41: 182 | O41: 164 | P41: 149 | Q41: =SUM(M41:P41) -> 639 | R41: 166 | S41: 192 | T41: 172 | U41: 148 | V41: =SUM(R41:U41) -> 678 | W41: 166 | X41: 213
B42: y/y | H42: =(H41-C41)/C41 -> 0.020547945 | I42: =(I41-D41)/D41 -> 0.017241379 | J42: =(J41-E41)/E41 -> 0.031055901 | K42: =(K41-F41)/F41 -> -0.028368794 | L42: =(L41-G41)/G41 -> 0.011254019 | M42: =(M41-H41)/H41 -> -0.033557047 | N42: =(N41-I41)/I41 -> 0.028248588 | O42: =(O41-J41)/J41 -> -0.012048193 | ... AA42: =(AA41-V41)/V41 -> -1
B43: Total revenue | C43: =C39+C41 -> 257 | D43: =D39+D41 -> 295 | E43: =E39+E41 -> 292 | F43: =F39+F41 -> 284 | G43: =G39+G41 -> 1128 | H43: =H39+H41 -> 284 | I43: =I39+I41 -> 307 | J43: =J39+J41 -> 308 | ... AA43: =AA39+AA41 -> 0
...

Sheet SOTP
A2: EBIT 26E
A3: =Modell!AF13 -> 976.83
C4: SEKm | D4: EBIT 26E | E4: EV/EBIT | F4: Value | G4: Value/Share
C5: Sweden | D5: 850 | E5: 13 | F5: =D5*E5 -> 11050 | G5: =F5/Modell!$B$5 -> 77.371124
C6: Denmark | D6: 90 | E6: 6 | F6: =D6*E6 -> 540 | G6: =F6/Modell!$B$5 -> 3.7810323
C7: Norway | D7: 120 | E7: 7 | F7: =D7*E7 -> 840 | G7: =F7/Modell!$B$5 -> 5.8816058
C8: Finland | D8: -20 | E8: 5 | F8: =D8*E8 -> -100 | G8: =F8/Modell!$B$5 -> -0.70019117
C9: Enterprise value | D9: =SUM(D5:D8) -> 1040 | F9: =SUM(F5:F8) -> 12330 | G9: =SUM(G5:G8) -> 86.333571
C11: Cash | F11: =Modell!B7 -> 648 | G11: =F11/Modell!$B$5 -> 4.5372388
C12: Debt | F12: =Modell!B8 -> 3653 | G12: =-F12/Modell!$B$5 -> -25.577983
C14: Equity value | F14: =F9+F11-F12 -> 9325 | G14: =SUM(G9:G12) -> 65.292826

Sheet Nøkkeltall
D4: 2026 | E4: 2027 | F4: 2028
C5: EV/EBITDA | D5: =Modell!$B$9/Modell!AF9 -> 5.7318893 | E5: =Modell!$B$9/Modell!AG9 -> 5.3533843 | F5: =Modell!$B$9/Modell!AH9 -> 5.000607
C6: EV/EBIT | D6: =Modell!$B$9/Modell!AF13 -> 10.825181 | E6: =Modell!$B$9/Modell!AG13 -> 9.9970644 | F6: =Modell!$B$9/Modell!AH13 -> 8.9015742
C7: P/E | D7: =Modell!$B$4/Modell!AF20 -> 13.447455 | E7: =Modell!$B$4/Modell!AG20 -> 12.139296 | F7: =Modell!$B$4/Modell!AH20 -> 10.458479

Sheet Nedsideberegning
A3: Nedside | D3: FY 2020 | E3: FY 2021 | F3: FY 2022 | G3: FY 2023 | H3: FY 2024 | I3: FY 2025 | J3: FY 2026 | K3: FY 2027 | L3: FY 2028 | M3: FY 2029 | N3: FY 2030 | O3: FY 2031 | P3: FY 2032 | Q3: FY 2033 | R3: FY 2034 | S3: FY 2035
A4: Nullvekst og dårligste marginene | C4: Revenue | D4: 3860 | E4: 4728 | F4: 5349 | G4: 5985 | H4: 6522 | I4: 7200 | J4: =I4*1.06 -> 7632 | K4: =J4*1 -> 7632 | L4: =K4*1 -> 7632 | M4: =L4*1 -> 7632 | N4: =M4*1 -> 7632 | O4: =N4*1 -> 7632 | P4: =O4*1 -> 7632 | Q4: =P4*1 -> 7632 | R4: =Q4*1 -> 7632 | S4: =R4*1 -> 7632
A5: =V25 -> 35.854091 | C5: Goods for resale | D5: -953 | E5: -1088 | F5: -1279 | G5: -1447 | H5: -1591 | I5: -1821 | J5: =J4*-0.24 -> -1831.68 | K5: =K4*-0.26 -> -1984.32 | L5: =L4*-0.26 -> -1984.32 | M5: =M4*-0.26 -> -1984.32 | N5: =N4*-0.26 -> -1984.32 | O5: =O4*-0.26 -> -1984.32 | P5: =P4*-0.26 -> -1984.32 | Q5: =Q4*-0.26 -> -1984.32 | R5: =R4*-0.26 -> -1984.32 | S5: =S4*-0.26 -> -1984.32
A6: =V26 -> -0.32350772 | C6: Gross profit | D6: =SUM(D4:D5) -> 2907 | E6: =SUM(E4:E5) -> 3640 | F6: =SUM(F4:F5) -> 4070 | G6: =SUM(G4:G5) -> 4538 | H6: =SUM(H4:H5) -> 4931 | I6: =SUM(I4:I5) -> 5379 | J6: =SUM(J4:J5) -> 5800.32 | K6: =SUM(K4:K5) -> 5647.68 | ... S6: =SUM(S4:S5) -> 5647.68
C7: Other external expenses | D7: -468 | E7: -629 | F7: -667 | G7: -682 | H7: -711 | I7: -805 | J7: =I7*1.08 -> -869.4 | K7: =J7*1 -> -869.4 | L7: =K7 -> -869.4 | M7: =L7*0.99 -> -860.706 | N7: =M7*0.99 -> -852.09894 | O7: =N7*0.99 -> -843.57795 | P7: =O7*0.99 -> -835.14217 | Q7: =P7*0.99 -> -826.79075 | R7: =Q7*0.99 -> -818.52284 | S7: =R7*0.99 -> -810.33761
C8: Persnonnel costs | D8: -1505 | E8: -1823 | F8: -2186 | G8: -2415 | H8: -2624 | I8: -2886 | J8: =I8*1.08 -> -3116.88 | K8: =J8*1 -> -3116.88 | L8: =K8 -> -3116.88 | M8: =L8 -> -3116.88 | N8: =M8 -> -3116.88 | O8: =N8 -> -3116.88 | P8: =O8 -> -3116.88 | Q8: =P8 -> -3116.88 | R8: =Q8 -> -3116.88 | S8: =R8 -> -3116.88
C9: EBITDA | D9: =SUM(D6:D8) -> 934 | E9: =SUM(E6:E8) -> 1188 | F9: =SUM(F6:F8) -> 1217 | G9: =SUM(G6:G8) -> 1441 | H9: =SUM(H6:H8) -> 1596 | I9: =SUM(I6:I8) -> 1688 | J9: =SUM(J6:J8) -> 1814.04 | K9: =SUM(K6:K8) -> 1661.4 | ... S9: =SUM(S6:S8) -> 1720.4624
C10: Depreciation | D10: -445 | E10: -464 | F10: -556 | G10: -622 | H10: -649 | I10: -702 | J10: -728 | K10: =J10*1 -> -728 | L10: =K10*1 -> -728 | M10: =L10*1.01 -> -735.28 | N10: =M10*1.01 -> -742.6328 | O10: =N10*1.01 -> -750.05913 | P10: =O10*1.01 -> -757.55972 | Q10: =P10*1.01 -> -765.13532 | R10: =Q10*1.01 -> -772.78667 | S10: =R10*1.01 -> -780.51454
C11: EBITA | D11: =SUM(D9:D10) -> 489 | E11: =SUM(E9:E10) -> 724 | F11: =SUM(F9:F10) -> 661 | G11: =SUM(G9:G10) -> 819 | H11: =SUM(H9:H10) -> 947 | I11: =SUM(I9:I10) -> 986 | J11: =SUM(J9:J10) -> 1086.04 | K11: =SUM(K9:K10) -> 933.4 | ... S11: =SUM(S9:S10) -> 939.94785
C12: Amortization | D12: -87 | E12: -91 | F12: -109 | G12: -123 | H12: -128 | I12: -124 | J12: -130 | K12: =J12*1 -> -130 | L12: =K12*1 -> -130 | M12: =L12*1 -> -130 | N12: =M12*1 -> -130 | O12: =N12*1 -> -130 | P12: =O12*1 -> -130 | Q12: =P12*1 -> -130 | R12: =Q12*1 -> -130 | S12: =R12*1 -> -130
C13: EBIT | D13: =SUM(D11:D12) -> 402 | E13: =SUM(E11:E12) -> 633 | F13: =SUM(F11:F12) -> 552 | G13: =SUM(G11:G12) -> 696 | H13: =SUM(H11:H12) -> 819 | I13: =SUM(I11:I12) -> 862 | J13: =SUM(J11:J12) -> 956.04 | K13: =SUM(K11:K12) -> 803.4 | ... S13: =SUM(S11:S12) -> 809.94785
C14: Fincial income | D14: 98 | E14: 148 | F14: 185 | G14: 273 | H14: 326 | I14: 321 | J14: =I14*1.02 -> 327.42 | K14: =J14*1 -> 327.42 | L14: =K14*1 -> 327.42 | M14: =L14*1 -> 327.42 | N14: =M14*1 -> 327.42 | O14: =N14*1 -> 327.42 | P14: =O14*1 -> 327.42 | Q14: =P14*1 -> 327.42 | R14: =Q14*1 -> 327.42 | S14: =R14*1 -> 327.42
C15: Financial expenses | D15: -636 | E15: -618 | F15: -322 | G15: -554 | H15: -652 | I15: -593 | J15: =I15*1.02 -> -604.86 | K15: =J15*1 -> -604.86 | L15: =K15*1 -> -604.86 | M15: =L15*1 -> -604.86 | N15: =M15*1 -> -604.86 | O15: =N15*1 -> -604.86 | P15: =O15*1 -> -604.86 | Q15: =P15*1 -> -604.86 | R15: =Q15*1 -> -604.86 | S15: =R15*1 -> -604.86
C16: PTP | D16: =SUM(D13:D15) -> -136 | E16: =SUM(E13:E15) -> 163 | F16: =SUM(F13:F15) -> 415 | G16: =SUM(G13:G15) -> 415 | H16: =SUM(H13:H15) -> 493 | I16: =SUM(I13:I15) -> 590 | J16: =SUM(J13:J15) -> 678.6 | K16: =SUM(K13:K15) -> 525.96 | ... S16: =SUM(S13:S15) -> 532.50785
C17: Tax | D17: -59 | E17: -112 | F17: -87 | G17: -104 | H17: -127 | I17: -136 | J17: =J16*-0.2 -> -135.72 | K17: =K16*-0.2 -> -105.192 | L17: =L16*-0.2 -> -105.192 | M17: =M16*-0.2 -> -105.4748 | N17: =N16*-0.2 -> -105.72565 | O17: =O16*-0.2 -> -105.94458 | P17: =P16*-0.2 -> -106.13162 | Q17: =Q16*-0.2 -> -106.28679 | ... S17: =S16*-0.2 -> -106.50157
C18: Net income | D18: =SUM(D16:D17) -> -195 | E18: =SUM(E16:E17) -> 51 | F18: =SUM(F16:F17) -> 328 | G18: =SUM(G16:G17) -> 311 | H18: =SUM(H16:H17) -> 366 | I18: =SUM(I16:I17) -> 454 | J18: =SUM(J16:J17) -> 542.88 | K18: =SUM(K16:K17) -> 420.768 | ... S18: =SUM(S16:S17) -> 426.00628 | T18: =S18*(1+$V$22) -> 421.74622 | U18: =T18*(1+$V$22) -> 417.52876 | V18: =U18*(1+$V$22) -> 413.35347 | W18: =V18*(1+$V$22) -> 409.21993 | X18: =W18*(1+$V$22) -> 405.12773 | Y18: =X18*(1+$V$22) -> 401.07646 | Z18: =Y18*(1+$V$22) -> 397.06569 | AA18: =Z18*(1+$V$22) -> 393.09503 | ... GS18: =GR18*(1+$V$22) -> 68.394538
C19: Share | D19: 37.181942 | E19: 150 | F19: 149.055 | G19: 147.42368 | H19: 146.64875 | I19: 142.81814 | J19: 141.96249 | K19: 142.81814 | L19: 142.81814 | M19: 142.81814 | N19: 142.81814 | O19: 142.81814 | P19: 142.81814 | Q19: 142.81814 | R19: 142.81814 | S19: 142.81814
C20: EPS | D20: =D18/D19 -> -5.2444813 | E20: =E18/E19 -> 0.34 | F20: =F18/F19 -> 2.20053 | G20: =G18/G19 -> 2.1095662 | H20: =H18/H19 -> 2.4957595 | I20: =I18/I19 -> 3.1788679 | J20: =J18/J19 -> 3.8241086 | K20: =K18/K19 -> 2.9461804 | ... S20: =S18/S19 -> 2.9828583
U21: Discount | V21: 0.08
C22: Revenue y/y | E22: =(E4-D4)/D4 -> 0.22487047 | F22: =(F4-E4)/E4 -> 0.13134518 | G22: =(G4-F4)/F4 -> 0.11890073 | H22: =(H4-G4)/G4 -> 0.089724311 | I22: =(I4-H4)/H4 -> 0.10395584 | J22: =(J4-I4)/I4 -> 0.06 | K22: =(K4-J4)/J4 -> 0 | L22: =(L4-K4)/K4 -> 0 | ... S22: =(S4-R4)/R4 -> 0 | U22: TV | V22: -0.01
C23: Organic growth | D23: 0.032 | E23: 0.232 | F23: 0.106 | G23: 0.103 | H23: 0.092 | I23: 0.114 | U23: NPV | V23: =NPV(V21,J18:GS18) -> 5120.6146
C24: Like-for-like | U24: S/O | V24: 142.81814
U25: NPV/Share | V25: =V23/V24 -> 35.854091
C26: Gross margin | D26: =D6/D4 -> 0.75310881 | E26: =E6/E4 -> 0.76988156 | F26: =F6/F4 -> 0.76088989 | G26: =G6/G4 -> 0.75822891 | H26: =H6/H4 -> 0.75605642 | I26: =I6/I4 -> 0.74708333 | J26: =J6/J4 -> 0.76 | K26: =K6/K4 -> 0.74 | ... S26: =S6/S4 -> 0.74 | U26: Opp/nedside | V26: =(V25-Modell!B4)/Modell!B4 -> -0.32350772
C27: EBITDA margin | D27: =D9/D4 -> 0.24196891 | E27: =E9/E4 -> 0.25126904 | F27: =F9/F4 -> 0.22751916 | G27: =G9/G4 -> 0.24076859 | H27: =H9/H4 -> 0.24471021 | I27: =I9/I4 -> 0.23444444 | J27: =J9/J4 -> 0.23768868 | K27: =K9/K4 -> 0.21768868 | ... S27: =S9/S4 -> 0.22542746
C28: EBITA margin | D28: =D11/D4 -> 0.12668394 | E28: =E11/E4 -> 0.15313029 | F28: =F11/F4 -> 0.1235745 | G28: =G11/G4 -> 0.13684211 | H28: =H11/H4 -> 0.14520086 | I28: =I11/I4 -> 0.13694444 | J28: =J11/J4 -> 0.14230084 | K28: =K11/K4 -> 0.12230084 | ... S28: =S11/S4 -> 0.12315879
C29: EBIT margin | D29: =D13/D4 -> 0.10414508 | E29: =E13/E4 -> 0.13388325 | F29: =F13/F4 -> 0.10319686 | G29: =G13/G4 -> 0.11629073 | H29: =H13/H4 -> 0.12557498 | I29: =I13/I4 -> 0.11972222 | J29: =J13/J4 -> 0.1252673 | K29: =K13/K4 -> 0.1052673 | ... S29: =S13/S4 -> 0.10612524
