Workbook

Sheet Info
A24: Press releases:
A25: 29.06.26: Terranor vinner kontrakt i København verdt SEKm 115. Viktig for srategier til Terr å vinne flere municipalities i Danmark
A26: 18.05.26: Terranor vinner kontrakt i Falun verdt SEKm 36
A27: 11.05.26: Terranor vinner kontrakt i Falun verdt SEKm 37
A28: 01.05.26: Terranor vinner kontrakt i Ikast-Brande verdt SEKm 206
A29: 24.04.26: Terranor vinner vedlikeholdskontrakt i Järvenpää verdt SEKm 116
A30: 17.04.26: Terranor tildeles to-års opsjon verdt SEKm 175 i Gøteborg
A31: 17.04.26: Tendersesongen er ferdig og Terranor bekrefter at 6 kontrakter verdt SEKm 251 har utløpt og 6 nye kontrakter har blitt fornyet, verdt SEK 366. Økning på 45%
A32: 16.04.26: Terranor vinner kontrakt i Sør-øst Värmland verdt SEKm 214, går fra 1.sep 26 til 31.aug 30
A33: 16.04.26: Terranor vinner to kontrakter verdt SEKm 36 for drenering og ventilasjon på veien i sør-Sverige
A34: 08.04.26: Terranor vinner drifts. Og vedlikeholdskontrakt i Västby verdt 272 mill. Kontrakten løper fra 1.sep 26 til 31. aug 30
A35: 26.03.26: Mutares selger aksjer for 45 mill, eier nå under 50%
... A47: 24.10.25: Terranor wins public tender with Tønder municipality in Denmark worth 270 SEKM. Kontrakten begynner april 26 og går helt til mars 2030. 46 mill/året

Sheet Modell
A3: Kapitalstruktur | C3: SEKm | D3: Q122 | E3: Q222 | F3: Q322 | G3: Q422 | H3: Q123 | I3: Q223 | J3: Q323 | K3: Q423 | L3: Q124 | M3: Q224 | N3: Q324 | O3: Q424 | P3: Q125 | Q3: Q225 | R3: Q325 | S3: Q425 | T3: Q126 | U3: Q226 | V3: Q326 | W3: Q426 | Y3: FY 2022 | Z3: FY 2023 | AA3: FY 2024 | AB3: FY 2025 | AC3: FY 2026 | AD3: FY 2027 | AE3: FY 2028 | AF3: FY 2029 | AG3: FY 2030 | AH3: FY 2031 | AI3: FY 2032 | AJ3: FY 2033 | AK3: FY 2034 | AL3: FY 2035
A4: Price | B4: 34 | C4: Revenue | L4: 721 | M4: 755.795 | N4: 722.689 | O4: =3147-N4-M4-L4 -> 947.516 | P4: 736 | Q4: 848.969 | R4: 794.425 | S4: 1223.216 | T4: 904.825 | Y4: 2152.241 | Z4: 2758 | AA4: 3146.928 | AB4: 3603 | AC4: =AB4*1.11 -> 3999.33 | AD4: =AC4*1.1 -> 4399.263 | AE4: =AD4*1.1 -> 4839.1893 | AF4: =AE4*1.05 -> 5081.1488 | AG4: =AF4*1.05 -> 5335.2062 | AH4: =AG4*1.05 -> 5601.9665 | AI4: =AH4*1.05 -> 5882.0648 | AJ4: =AI4*1.05 -> 6176.1681 | AK4: =AJ4*1.05 -> 6484.9765 | AL4: =AK4*1.05 -> 6809.2253
A5: S/O | B5: 20 | C5: other operating income | L5: 0 | M5: 2.791 | N5: 2.6 | O5: 0 | P5: 2.66 | Q5: 2.6 | R5: 0 | S5: 2.113 | T5: 7 | Y5: 7.439 | Z5: 8.1 | AA5: 5.9 | AB5: 7 | AC5: 0 | AD5: 0 | AE5: 0 | AF5: 0 | AG5: 0 | AH5: 0 | AI5: 0 | AJ5: 0 | AK5: 0 | AL5: 0
A6: MC NOKm | B6: =B4*B5 -> 680 | C6: Raw material and consumables | L6: -551.515 | M6: -540.921 | N6: -492.714 | O6: =-2260-N6-M6-L6 -> -674.85 | P6: -496.482 | Q6: -593.628 | R6: -549.21 | S6: -888.886 | T6: -636.453 | Y6: -1483.843 | Z6: -1993.92 | AA6: -2259.514 | AB6: -2528 | AC6: =AC4*-0.7 -> -2799.531 | AD6: =AD4*-0.7 -> -3079.4841 | AE6: =AE4*-0.7 -> -3387.4325 | AF6: =AF4*-0.7 -> -3556.8041 | AG6: =AG4*-0.7 -> -3734.6443 | AH6: =AH4*-0.7 -> -3921.3766 | AI6: =AI4*-0.7 -> -4117.4454 | AJ6: =AJ4*-0.7 -> -4323.3177 | ... AL6: =AL4*-0.7 -> -4766.4577
A7: Cash NOKm | B7: =T41 -> 32.676 | C7: Gross profit | L7: =SUM(L4:L6) -> 169.485 | M7: =SUM(M4:M6) -> 217.665 | N7: =SUM(N4:N6) -> 232.575 | O7: =SUM(O4:O6) -> 272.666 | P7: =SUM(P4:P6) -> 242.178 | Q7: =SUM(Q4:Q6) -> 257.941 | R7: =SUM(R4:R6) -> 245.215 | S7: =SUM(S4:S6) -> 336.443 | T7: =SUM(T4:T6) -> 275.372 | Y7: =SUM(Y4:Y6) -> 675.837 | Z7: =SUM(Z4:Z6) -> 772.18 | AA7: =SUM(AA4:AA6) -> 893.314 | AB7: =SUM(AB4:AB6) -> 1082 | AC7: =SUM(AC4:AC6) -> 1199.799 | AD7: =SUM(AD4:AD6) -> 1319.7789 | AE7: =SUM(AE4:AE6) -> 1451.7568 | AF7: =SUM(AF4:AF6) -> 1524.3446 | ... AL7: =SUM(AL4:AL6) -> 2042.7676
A8: Debt NOKm | B8: =T48+T52 -> 82.243 | C8: Personnel expenses | L8: -109.214 | M8: -131.29 | N8: -128.425 | O8: =-518-N8-M8-L8 -> -149.071 | P8: -132.444 | Q8: -173.633 | R8: -148.748 | S8: -172.964 | T8: -161.673 | Y8: -378.166 | Z8: -453.904 | AA8: -517.531 | AB8: -628 | AC8: =AB8*1 -> -628 | AD8: =AC8*1.07 -> -671.96 | AE8: =AD8*1.07 -> -718.9972 | AF8: =AE8*1.05 -> -754.94706 | AG8: =AF8*1.05 -> -792.69441 | AH8: =AG8*1.05 -> -832.32913 | AI8: =AH8*1.05 -> -873.94559 | AJ8: =AI8*1.05 -> -917.64287 | AK8: =AJ8*1.05 -> -963.52501 | AL8: =AK8*1.05 -> -1011.7013
A9: EV NOKm | B9: =B6-B7+B8 -> 729.567 | C9: D/A/I | L9: -28.2 | M9: -28.533 | N9: -32.89 | O9: =-126-N9-M9-L9 -> -36.377 | P9: -36.947 | Q9: -37.633 | R9: -38.383 | S9: -48.217 | T9: -44.398 | Y9: -75.494 | Z9: -103.84 | AA9: -126 | AB9: -161 | AC9: =AB9*1 -> -161 | AD9: =AC9*1.07 -> -172.27 | AE9: =AD9*1.07 -> -184.3289 | AF9: =AE9*1.05 -> -193.54535 | AG9: =AF9*1.05 -> -203.22261 | AH9: =AG9*1.05 -> -213.38374 | AI9: =AH9*1.05 -> -224.05293 | AJ9: =AI9*1.05 -> -235.25558 | AK9: =AJ9*1.05 -> -247.01836 | AL9: =AK9*1.05 -> -259.36927
C10: Other opex | L10: -29.261 | M10: -55 | N10: -47.734 | O10: =-184-N10-M10-L10 -> -52.005 | P10: -67.667 | Q10: -63.921 | R10: -67.116 | S10: -78.723 | T10: -57.274 | Y10: -145.473 | Z10: -152 | AA10: -183.9 | AB10: -277 | AC10: =AB10*1 -> -277 | AD10: =AC10*1.07 -> -296.39 | AE10: =AD10*1.07 -> -317.1373 | AF10: =AE10*1.05 -> -332.99417 | AG10: =AF10*1.05 -> -349.64387 | AH10: =AG10*1.05 -> -367.12607 | AI10: =AH10*1.05 -> -385.48237 | AJ10: =AI10*1.05 -> -404.75649 | AK10: =AJ10*1.05 -> -424.99431 | AL10: =AK10*1.05 -> -446.24403
C11: Operating profit (EBIT) | L11: =SUM(L7:L10) -> 2.81 | M11: =SUM(M7:M10) -> 2.842 | N11: =SUM(N7:N10) -> 23.526 | O11: =SUM(O7:O10) -> 35.213 | P11: =SUM(P7:P10) -> 5.12 | Q11: =SUM(Q7:Q10) -> -17.246 | R11: =SUM(R7:R10) -> -9.032 | S11: =SUM(S7:S10) -> 36.539 | T11: =SUM(T7:T10) -> 12.027 | Y11: =SUM(Y7:Y10) -> 76.704 | Z11: =SUM(Z7:Z10) -> 62.436 | AA11: =SUM(AA7:AA10) -> 65.883 | AB11: =SUM(AB7:AB10) -> 16 | AC11: =SUM(AC7:AC10) -> 133.799 | AD11: =SUM(AD7:AD10) -> 179.1589 | AE11: =SUM(AE7:AE10) -> 231.29339 | AF11: =SUM(AF7:AF10) -> 242.85806 | ... AL11: =SUM(AL7:AL10) -> 325.45303
A12: Gearing | B12: =(B8-B7)/SUM(Q25:T25) -> 0.25943159 | C12: Financial income | L12: 0 | M12: 0 | N12: 0 | O12: 0 | P12: 0 | Q12: 0 | R12: 0 | S12: 0.02 | T12: 0 | Y12: 0 | Z12: 0 | AA12: 0 | AB12: 0 | AC12: 0 | AD12: 0 | AE12: 0 | AF12: 0 | AG12: 0 | AH12: 0 | AI12: 0 | AJ12: 0 | AK12: 0 | AL12: 0
C13: Financial expense | L13: -3.22 | M13: -3.5 | N13: -5.11 | O13: =-19-N13-M13-L13 -> -7.17 | P13: -4.1 | Q13: -4.4 | R13: -5.2 | S13: -7.493 | T13: -5.399 | Y13: -7 | Z13: -12.4 | AA13: -19 | AB13: -21 | AC13: -20 | AD13: -20 | AE13: -20 | AF13: -20 | AG13: -20 | AH13: -20 | AI13: -20 | AJ13: -20 | AK13: -20 | AL13: -20
C14: PTP | L14: =SUM(L11:L13) -> -0.41 | M14: =SUM(M11:M13) -> -0.658 | N14: =SUM(N11:N13) -> 18.416 | O14: =SUM(O11:O13) -> 28.043 | P14: =SUM(P11:P13) -> 1.02 | Q14: =SUM(Q11:Q13) -> -21.646 | R14: =SUM(R11:R13) -> -14.232 | S14: =SUM(S11:S13) -> 29.066 | T14: =SUM(T11:T13) -> 6.628 | Y14: =SUM(Y11:Y13) -> 69.704 | Z14: =SUM(Z11:Z13) -> 50.036 | AA14: =SUM(AA11:AA13) -> 46.883 | AB14: =SUM(AB11:AB13) -> -5 | AC14: =SUM(AC11:AC13) -> 113.799 | AD14: =SUM(AD11:AD13) -> 159.1589 | AE14: =SUM(AE11:AE13) -> 211.29339 | AF14: =SUM(AF11:AF13) -> 222.85806 | ... AL14: =SUM(AL11:AL13) -> 305.45303
C15: Tax | L15: 0 | M15: -2.6 | N15: 2.1 | O15: =15-N15-M15-L15 -> 15.5 | P15: -1.3 | Q15: 2.44 | R15: 2.8 | S15: -21.468 | T15: 0.388 | Y15: -1.58 | Z15: 7.4 | AA15: 14.7 | AB15: -18 | AC15: =AC14*-0.2 -> -22.7598 | AD15: =AD14*-0.2 -> -31.83178 | AE15: =AE14*-0.2 -> -42.258678 | AF15: =AF14*-0.2 -> -44.571612 | AG15: =AG14*-0.2 -> -47.000192 | AH15: =AH14*-0.2 -> -49.550202 | AI15: =AI14*-0.2 -> -52.227712 | AJ15: =AJ14*-0.2 -> -55.039098 | ... AL15: =AL14*-0.2 -> -61.090605
C16: Net income | L16: =SUM(L14:L15) -> -0.41 | M16: =SUM(M14:M15) -> -3.258 | N16: =SUM(N14:N15) -> 20.516 | O16: =SUM(O14:O15) -> 43.543 | P16: =SUM(P14:P15) -> -0.28 | Q16: =SUM(Q14:Q15) -> -19.206 | R16: =SUM(R14:R15) -> -11.432 | S16: =SUM(S14:S15) -> 7.598 | T16: =SUM(T14:T15) -> 7.016 | Y16: =SUM(Y14:Y15) -> 68.124 | Z16: =SUM(Z14:Z15) -> 57.436 | AA16: =SUM(AA14:AA15) -> 61.583 | AB16: =SUM(AB14:AB15) -> -23 | AC16: =SUM(AC14:AC15) -> 91.0392 | AD16: =SUM(AD14:AD15) -> 127.32712 | AE16: =SUM(AE14:AE15) -> 169.03471 | AF16: =SUM(AF14:AF15) -> 178.28645 | ... AL16: =SUM(AL14:AL15) -> 244.36242 | AM16: =AL16*(1+$AO$20) -> 241.9188 | AN16: =AM16*(1+$AO$20) -> 239.49961 | AO16: =AN16*(1+$AO$20) -> 237.10461 | AP16: =AO16*(1+$AO$20) -> 234.73357 | AQ16: =AP16*(1+$AO$20) -> 232.38623 | AR16: =AQ16*(1+$AO$20) -> 230.06237 | AS16: =AR16*(1+$AO$20) -> 227.76175 | AT16: =AS16*(1+$AO$20) -> 225.48413 | ... FJ16: =FI16*(1+$AO$20) -> 67.505526
C17: Share | D17: 20 | E17: 20 | F17: 20 | G17: 20 | H17: 20 | I17: 20 | J17: 20 | K17: 20 | L17: 20 | M17: 20 | N17: 20 | O17: 20 | P17: 20 | Q17: 20 | R17: 20 | S17: 20 | T17: 20 | Y17: 20 | Z17: 20 | AA17: 20 | AB17: 20 | AC17: 20 | AD17: 20 | AE17: 20 | AF17: 20 | AG17: 20 | AH17: 20 | AI17: 20 | AJ17: 20 | AK17: 20 | AL17: 20
C18: EPS | D18: =D16/D17 -> 0 | E18: =E16/E17 -> 0 | F18: =F16/F17 -> 0 | G18: =G16/G17 -> 0 | H18: =H16/H17 -> 0 | I18: =I16/I17 -> 0 | J18: =J16/J17 -> 0 | K18: =K16/K17 -> 0 | ... T18: =T16/T17 -> 0.3508 | Y18: =Y16/Y17 -> 3.4062 | Z18: =Z16/Z17 -> 2.8718 | AA18: =AA16/AA17 -> 3.07915 | AB18: =AB16/AB17 -> -1.15 | AC18: =AC16/AC17 -> 4.55196 | AD18: =AD16/AD17 -> 6.366356 | AE18: =AE16/AE17 -> 8.4517356 | AF18: =AF16/AF17 -> 8.9143224 | ... AL18: =AL16/AL17 -> 12.218121
AN19: Disocunt | AO19: 0.08
C20: Revenue y/y | H20: =(H4-D4)/D4 -> #DIV/0! | I20: =(I4-E4)/E4 -> #DIV/0! | J20: =(J4-F4)/F4 -> #DIV/0! | K20: =(K4-G4)/G4 -> #DIV/0! | L20: =(L4-H4)/H4 -> #DIV/0! | M20: =(M4-I4)/I4 -> #DIV/0! | N20: =(N4-J4)/J4 -> #DIV/0! | O20: =(O4-K4)/K4 -> #DIV/0! | ... T20: =(T4-P4)/P4 -> 0.22938179 | Z20: =(Z4-Y4)/Y4 -> 0.281455 | AA20: =(AA4-Z4)/Z4 -> 0.14101813 | AB20: =(AB4-AA4)/AA4 -> 0.1449261 | AC20: =(AC4-AB4)/AB4 -> 0.11 | AD20: =(AD4-AC4)/AC4 -> 0.1 | AE20: =(AE4-AD4)/AD4 -> 0.1 | AF20: =(AF4-AE4)/AE4 -> 0.05 | AG20: =(AG4-AF4)/AF4 -> 0.05 | ... AL20: =(AL4-AK4)/AK4 -> 0.05 | AN20: TV | AO20: -0.01
C21: Gross margin | D21: =D7/D4 -> #DIV/0! | E21: =E7/E4 -> #DIV/0! | F21: =F7/F4 -> #DIV/0! | G21: =G7/G4 -> #DIV/0! | H21: =H7/H4 -> #DIV/0! | I21: =I7/I4 -> #DIV/0! | J21: =J7/J4 -> #DIV/0! | K21: =K7/K4 -> #DIV/0! | ... T21: =T7/T4 -> 0.3043373 | Y21: =Y7/Y4 -> 0.31401548 | Z21: =Z7/Z4 -> 0.27997825 | AA21: =AA7/AA4 -> 0.28386859 | AB21: =AB7/AB4 -> 0.3003053 | AC21: =AC7/AC4 -> 0.3 | AD21: =AD7/AD4 -> 0.3 | AE21: =AE7/AE4 -> 0.3 | AF21: =AF7/AF4 -> 0.3 | ... AL21: =AL7/AL4 -> 0.3 | AN21: NPV | AO21: =NPV(AO19,AB16:FJ16) -> 2225.5993
C22: EBIT margin | D22: =D11/D4 -> #DIV/0! | E22: =E11/E4 -> #DIV/0! | F22: =F11/F4 -> #DIV/0! | G22: =G11/G4 -> #DIV/0! | H22: =H11/H4 -> #DIV/0! | I22: =I11/I4 -> #DIV/0! | J22: =J11/J4 -> #DIV/0! | K22: =K11/K4 -> #DIV/0! | ... T22: =T11/T4 -> 0.013292073 | Y22: =Y11/Y4 -> 0.035639131 | Z22: =Z11/Z4 -> 0.022638144 | AA22: =AA11/AA4 -> 0.020935655 | AB22: =AB11/AB4 -> 0.0044407438 | AC22: =AC11/AC4 -> 0.033455354 | AD22: =AD11/AD4 -> 0.040724753 | AE22: =AE11/AE4 -> 0.047795896 | AF22: =AF11/AF4 -> 0.047795896 | ... AL22: =AL11/AL4 -> 0.047795896 | AN22: S/O | AO22: 20
C23: ROCE | Y23: 0.33 | Z23: 0.15 | AA23: 0.14 | AB23: =AB16/AB47 -> -0.12209105 | AN23: NPV/Share | AO23: =AO21/AO22 -> 111.27996
AN24: Opp/nedside | AO24: =(AO23-B4)/B4 -> 2.2729401
C25: EBITDA | L25: 31.231 | M25: 31.295 | N25: 56.451 | O25: 72.967 | P25: 42.08 | Q25: 20.483 | R25: 29.323 | S25: 84.775 | T25: 56.479 | AA25: =SUM(L25:O25) -> 191.944 | AB25: =SUM(P25:S25) -> 176.661
C26: % | L26: =L25/L4 -> 0.043316227 | M26: =M25/M4 -> 0.041406731 | N26: =N25/N4 -> 0.078112438 | O26: =O25/O4 -> 0.077008726 | P26: =P25/P4 -> 0.057173913 | Q26: =Q25/Q4 -> 0.024126912 | R26: =R25/R4 -> 0.036910973 | S26: =S25/S4 -> 0.069305012 | T26: =T25/T4 -> 0.062419805 | AA26: =AA25/AA4 -> 0.060994087 | AB26: =AB25/AB4 -> 0.04903164
C28: Adjusted EBITA | M28: 7.422 | N28: 28.755 | O28: 45.906 | P28: 12.21 | Q28: 16.931 | R28: 20.696 | S28: 48.249 | T28: 19.842 | AA28: 89.5 | AB28: 98.1 | AC28: =AC4*AC29 -> 155.97387 | AD28: =AD4*AD29 -> 197.96684 | AE28: =AE4*AE29 -> 241.95947
C29: % | L29: =L28/L4 -> 0 | M29: =M28/M4 -> 0.0098201232 | N29: =N28/N4 -> 0.0397889 | O29: =O28/O4 -> 0.048448786 | P29: =P28/P4 -> 0.016589674 | Q29: =Q28/Q4 -> 0.019943013 | R29: =R28/R4 -> 0.026051547 | S29: =S28/S4 -> 0.039444383 | T29: =T28/T4 -> 0.021929102 | AA29: =AA28/AA4 -> 0.028440435 | AB29: =AB28/AB4 -> 0.027227311 | AC29: 0.039 | AD29: 0.045 | AE29: 0.05
C31: Balanse SEKm
C32: Goodwill | G32: 0 | K32: 0 | L32: 0 | M32: 0 | N32: 0 | O32: 18.6 | P32: 18.636 | Q32: 19 | R32: 18.626 | S32: 18.626 | T32: 18.626 | AA32: 18.6 | AB32: 18.626
C33: Other intangible assets | G33: 50.286 | K33: 40.09 | L33: 38.7 | M33: 35.525 | N33: 32.731 | O33: 30.5 | P33: 26.4 | Q33: 25.666 | R33: 23.971 | S33: 18.827 | T33: 17.024 | AA33: 30.5 | AB33: 18.827
C34: PP&E | G34: 76.4 | K34: 68.822 | L34: 65.77 | M34: 63.295 | N34: 109.241 | O34: 117.538 | P34: 117.193 | Q34: 115.358 | R34: 112.92 | S34: 105.441 | T34: 99.933 | AA34: 117.538 | AB34: 105.441
C35: Right of use assets | G35: 167.143 | K35: 213.879 | L35: 223.595 | M35: 221.3 | N35: 241.496 | O35: 288.166 | P35: 265.758 | Q35: 282.363 | R35: 298.261 | S35: 393.5552 | T35: 397.106 | AA35: 288.166 | AB35: 393.5552
C36: Deferred tax assets | G36: 0 | K36: 0 | L36: 0 | M36: 0 | N36: 0 | O36: 20.6 | P36: 22.6 | Q36: 26.851 | R36: 27.681 | S36: 11.711 | T36: 13.571 | AA36: 20.6 | AB36: 11.711
C37: Other non-current financial assets | G37: 4.655 | K37: 5.5 | L37: 5.9 | M37: 5.8 | N37: 5.322 | O37: 12.2 | P37: 4.1 | Q37: 4 | R37: 3.5 | S37: 4.167 | T37: 4.138 | AA37: 12.2 | AB37: 4.167
C38: Inventories | G38: 25.591 | K38: 26.21 | L38: 9.11 | M38: 7.4 | N38: 19.1 | O38: 21.38 | P38: 38.97 | Q38: 21.781 | R38: 32.5 | S38: 30.613 | T38: 28.868 | AA38: 21.38 | AB38: 30.613
C39: Trade receivables | G39: 256.641 | K39: 398.192 | L39: 248.178 | M39: 293.714 | N39: 290.19 | O39: 369.393 | P39: 237.9 | Q39: 293.445 | R39: 301.858 | S39: 407.068 | T39: 251.037 | AA39: 369.393 | AB39: 407.068
C40: Other current receivables | G40: 102.796 | K40: 133.496 | L40: 210.299 | M40: 228.263 | N40: 276.885 | O40: 166.1 | P40: 208.488 | Q40: 283.181 | R40: 326.717 | S40: 246.116 | T40: 342.729 | AA40: 166.1 | AB40: 246.116
C41: Cash | G41: 43.437 | K41: 29.334 | L41: 53.998 | M41: 24.829 | N41: 9 | O41: 45.292 | P41: 60.59 | Q41: 22.79 | R41: 17.779 | S41: 76.736 | T41: 32.676 | AA41: 45.292 | AB41: 76.736
C42: Total assets | D42: =SUM(D32:D41) -> 0 | E42: =SUM(E32:E41) -> 0 | F42: =SUM(F32:F41) -> 0 | G42: =SUM(G32:G41) -> 726.949 | H42: =SUM(H32:H41) -> 0 | I42: =SUM(I32:I41) -> 0 | J42: =SUM(J32:J41) -> 0 | K42: =SUM(K32:K41) -> 915.523 | ... T42: =SUM(T32:T41) -> 1205.708 | AA42: =SUM(AA32:AA41) -> 1089.769 | AB42: =SUM(AB32:AB41) -> 1312.8602
C43: Share capital | G43: 0 | K43: 0 | L43: 0.05 | M43: 0 | N43: 0 | O43: 0 | P43: 0.05 | Q43: 20 | R43: 20 | S43: 20 | T43: 20 | AA43: 0 | AB43: 20
C44: Other contributed capital | G44: 67.4 | K44: 67.4 | L44: 67.4 | M44: 67.4 | N44: 67.4 | O44: 67.4 | P44: 67.4 | Q44: 47.9 | R44: 47.9 | S44: 47.9 | T44: 47.9 | AA44: 67.4 | AB44: 47.9
...

Sheet Segementer
B4: SEKm | C4: Q122 | D4: Q222 | E4: Q322 | F4: Q422 | G4: 2022 | H4: Q123 | I4: Q223 | J4: Q323 | K4: Q423 | L4: 2023 | M4: Q124 | N4: Q224 | O4: Q324 | P4: Q424 | Q4: 2024 | R4: Q125 | S4: Q225 | T4: Q325 | U4: Q425 | V4: 2025 | W4: Q126 | X4: Q226 | Y4: Q326 | Z4: Q426 | AA4: 2026
B5: Sweden
B6: Revenue | N6: 426.398 | O6: 413.593 | P6: 533.469 | Q6: =SUM(M6:P6) -> 1373.46 | R6: 451.367 | S6: 506.907 | T6: 484.145 | U6: 788.683 | V6: =SUM(R6:U6) -> 2231.102 | W6: 619.146
B7: y/y | H7: =(H6-C6)/C6 -> #DIV/0! | I7: =(I6-D6)/D6 -> #DIV/0! | J7: =(J6-E6)/E6 -> #DIV/0! | K7: =(K6-F6)/F6 -> #DIV/0! | L7: =(L6-G6)/G6 -> #DIV/0! | M7: =(M6-H6)/H6 -> #DIV/0! | N7: =(N6-I6)/I6 -> #DIV/0! | O7: =(O6-J6)/J6 -> #DIV/0! | ... AA7: =(AA6-V6)/V6 -> -1
B8: Adjusted EBITA | N8: 7.6 | O8: 16.67 | P8: 24.823 | Q8: =SUM(M8:P8) -> 49.093 | R8: 16.6 | S8: 11.2 | T8: 18.817 | U8: 43.189 | V8: =SUM(R8:U8) -> 89.806 | W8: 22.775
B9: Adjusted EBITA margin | N9: 0.02 | O9: 0.04 | P9: 0.05 | Q9: =Q8/Q6 -> 0.035744033 | R9: 0.037 | S9: 0.02 | T9: 0.04 | U9: 0.05 | V9: =V8/V6 -> 0.040251858 | W9: 0.037
B10: Finland
B11: Revenue | N11: 131.138 | O11: 111.721 | P11: 205.786 | Q11: =SUM(M11:P11) -> 448.645 | R11: 147.566 | S11: 154.376 | T11: 124.32 | U11: 204.827 | V11: =SUM(R11:U11) -> 631.089 | W11: 144.561
B12: y/y | H12: =(H11-C11)/C11 -> #DIV/0! | I12: =(I11-D11)/D11 -> #DIV/0! | J12: =(J11-E11)/E11 -> #DIV/0! | K12: =(K11-F11)/F11 -> #DIV/0! | L12: =(L11-G11)/G11 -> #DIV/0! | M12: =(M11-H11)/H11 -> #DIV/0! | N12: =(N11-I11)/I11 -> #DIV/0! | O12: =(O11-J11)/J11 -> #DIV/0! | ... AA12: =(AA11-V11)/V11 -> -1
B13: Adjusted EBITA | N13: -3.2 | O13: -2.3 | P13: 7.65 | Q13: =SUM(M13:P13) -> 2.15 | R13: -0.919 | S13: 1 | T13: -1 | U13: 2.325 | V13: =SUM(R13:U13) -> 1.406 | W13: 0.388
B14: Adjusted EBITA margin | N14: -0.03 | O14: -0.02 | P14: 0.04 | Q14: =Q13/Q11 -> 0.0047922076 | R14: -0.006 | S14: 0.01 | T14: -0.01 | U14: 0.01 | V14: =V13/V11 -> 0.002227895 | W14: 0.003
B15: Denmark
B16: Revenue | N16: 198.259 | O16: 197.825 | P16: 208.588 | Q16: =SUM(M16:P16) -> 604.672 | R16: 137.843 | S16: 188.333 | T16: 186.617 | U16: 230.352 | V16: =SUM(R16:U16) -> 743.145 | W16: 141.952
B17: y/y | H17: =(H16-C16)/C16 -> #DIV/0! | I17: =(I16-D16)/D16 -> #DIV/0! | J17: =(J16-E16)/E16 -> #DIV/0! | K17: =(K16-F16)/F16 -> #DIV/0! | L17: =(L16-G16)/G16 -> #DIV/0! | M17: =(M16-H16)/H16 -> #DIV/0! | N17: =(N16-I16)/I16 -> #DIV/0! | O17: =(O16-J16)/J16 -> #DIV/0! | ... AA17: =(AA16-V16)/V16 -> -1
B18: Adjusted EBITA | N18: 3 | O18: 14.1 | P18: 13.215 | Q18: =SUM(M18:P18) -> 30.315 | R18: -3.291 | S18: 5 | T18: 3 | U18: 4.598 | V18: =SUM(R18:U18) -> 9.307 | W18: -2.472 | AC18: =9*1.35 -> 12.15
B19: Adjusted EBITA margin | N19: 0.02 | O19: 0.07 | P19: 0.06 | Q19: =Q18/Q16 -> 0.050134618 | R19: -0.024 | S19: 0.03 | T19: 0.02 | U19: 0.02 | V19: =V18/V16 -> 0.012523801 | W19: -0.017

Sheet SOTP
A3: EBITA 26E
A4: =Modell!AC28 -> 155.97387
D6: EBITA 26E | E6: EV/EBITA | F6: Value | G6: SEK/aksje
C7: Sverige | D7: 136 | E7: 6 | F7: =D7*E7 -> 816 | G7: =F7/Modell!$B$5 -> 40.8
C8: Danmark | D8: 15 | E8: 2 | F8: =D8*E8 -> 30 | G8: =F8/Modell!$B$5 -> 1.5
C9: Finland | D9: 5 | E9: 1 | F9: =D9*E9 -> 5 | G9: =F9/Modell!$B$5 -> 0.25
C10: Enterprise value | F10: =SUM(F7:F9) -> 851 | G10: =SUM(G7:G9) -> 42.55
C12: Debt | F12: =-Modell!B8 -> -82.243 | G12: =F12/Modell!B5 -> -4.11215
C13: Cash | F13: =Modell!B7 -> 32.676 | G13: =F13/Modell!B5 -> 1.6338
C15: Equity value | F15: =SUM(F10:F13) -> 801.433 | G15: =SUM(G10:G13) -> 40.07165

Sheet Nøkkeltall
D4: 2026 | E4: 2027 | F4: 2028
C5: EV/EBITA | D5: =Modell!$B$9/Modell!AC28 -> 4.677495 | E5: =Modell!$B$9/Modell!AD28 -> 3.6852991 | F5: =Modell!$B$9/Modell!AE28 -> 3.0152447
C6: EV/EBIT | D6: =Modell!$B$9/Modell!AC11 -> 5.4527089 | E6: =Modell!$B$9/Modell!AD11 -> 4.0721784 | F6: =Modell!$B$9/Modell!AE11 -> 3.1542925
C7: P/E | D7: =Modell!$B$4/Modell!AC18 -> 7.4693099 | E7: =Modell!$B$4/Modell!AD18 -> 5.3405747 | F7: =Modell!$B$4/Modell!AE18 -> 4.0228424

Sheet Nedsideberegning
A3: Nedside | D3: FY 2022 | E3: FY 2023 | F3: FY 2024 | G3: FY 2025 | H3: FY 2026 | I3: FY 2027 | J3: FY 2028 | K3: FY 2029 | L3: FY 2030 | M3: FY 2031 | N3: FY 2032 | O3: FY 2033 | P3: FY 2034 | Q3: FY 2035
A4: Nullvekst og dårligste marginer | C4: Revenue | D4: 2152.241 | E4: 2758 | F4: 3146.928 | G4: 3377 | H4: =G4*1 -> 3377 | I4: =H4*1 -> 3377 | J4: =I4*1 -> 3377 | K4: =J4*1 -> 3377 | L4: =K4*1 -> 3377 | M4: =L4*1 -> 3377 | N4: =M4*1 -> 3377 | O4: =N4*1 -> 3377 | ... Q4: =P4*1 -> 3377
A5: =T23 -> 19.830225 | C5: other operating income | D5: 7.439 | E5: 8.1 | F5: 5.9 | G5: 0 | H5: 0 | I5: 0 | J5: 0 | K5: 0 | L5: 0 | M5: 0 | N5: 0 | O5: 0 | P5: 0 | Q5: 0
A6: =T24 -> -0.41675809 | C6: Raw material and consumables | D6: -1483.843 | E6: -1993.92 | F6: -2259.514 | G6: -2400 | H6: =H4*-0.71 -> -2397.67 | I6: =I4*-0.71 -> -2397.67 | J6: =J4*-0.71 -> -2397.67 | K6: =K4*-0.71 -> -2397.67 | L6: =L4*-0.71 -> -2397.67 | M6: =M4*-0.71 -> -2397.67 | N6: =N4*-0.71 -> -2397.67 | O6: =O4*-0.71 -> -2397.67 | ... Q6: =Q4*-0.71 -> -2397.67
C7: Gross profit | D7: =SUM(D4:D6) -> 675.837 | E7: =SUM(E4:E6) -> 772.18 | F7: =SUM(F4:F6) -> 893.314 | G7: =SUM(G4:G6) -> 977 | H7: =SUM(H4:H6) -> 979.33 | I7: =SUM(I4:I6) -> 979.33 | J7: =SUM(J4:J6) -> 979.33 | K7: =SUM(K4:K6) -> 979.33 | ... Q7: =SUM(Q4:Q6) -> 979.33
C8: Personnel expenses | D8: -378.166 | E8: -453.904 | F8: -517.531 | G8: -600 | H8: -560 | I8: -560 | J8: -560 | K8: -560 | L8: -560 | M8: -560 | N8: -560 | O8: -560 | P8: -560 | Q8: -560
C9: D/A/I | D9: -75.494 | E9: -103.84 | F9: -126 | G9: -150 | H9: -150 | I9: -150 | J9: -150 | K9: -150 | L9: -150 | M9: -150 | N9: -150 | O9: -150 | P9: -150 | Q9: -150
C10: Other opex | D10: -145.473 | E10: -152 | F10: -183.9 | G10: -200 | H10: -200 | I10: -200 | J10: -200 | K10: -200 | L10: -200 | M10: -200 | N10: -200 | O10: -200 | P10: -200 | Q10: -200
C11: Operating profit (EBIT) | D11: =SUM(D7:D10) -> 76.704 | E11: =SUM(E7:E10) -> 62.436 | F11: =SUM(F7:F10) -> 65.883 | G11: =SUM(G7:G10) -> 27 | H11: =SUM(H7:H10) -> 69.33 | I11: =SUM(I7:I10) -> 69.33 | J11: =SUM(J7:J10) -> 69.33 | K11: =SUM(K7:K10) -> 69.33 | ... Q11: =SUM(Q7:Q10) -> 69.33
C12: Financial income | D12: 0 | E12: 0 | F12: 0 | G12: 0 | H12: 0 | I12: 0 | J12: 0 | K12: 0 | L12: 0 | M12: 0 | N12: 0 | O12: 0 | P12: 0 | Q12: 0
C13: Financial expense | D13: -7 | E13: -12.4 | F13: -19 | G13: -19 | H13: -20 | I13: -20 | J13: -20 | K13: -20 | L13: -20 | M13: -20 | N13: -20 | O13: -20 | P13: -20 | Q13: -20
C14: PTP | D14: =SUM(D11:D13) -> 69.704 | E14: =SUM(E11:E13) -> 50.036 | F14: =SUM(F11:F13) -> 46.883 | G14: =SUM(G11:G13) -> 8 | H14: =SUM(H11:H13) -> 49.33 | I14: =SUM(I11:I13) -> 49.33 | J14: =SUM(J11:J13) -> 49.33 | K14: =SUM(K11:K13) -> 49.33 | ... Q14: =SUM(Q11:Q13) -> 49.33
C15: Tax | D15: -1.58 | E15: 7.4 | F15: 14.7 | G15: 6 | H15: =H14*-0.2 -> -9.866 | I15: =I14*-0.2 -> -9.866 | J15: =J14*-0.2 -> -9.866 | K15: =K14*-0.2 -> -9.866 | L15: =L14*-0.2 -> -9.866 | M15: =M14*-0.2 -> -9.866 | N15: =N14*-0.2 -> -9.866 | O15: =O14*-0.2 -> -9.866 | ... Q15: =Q14*-0.2 -> -9.866
C16: Net income | D16: =SUM(D14:D15) -> 68.124 | E16: =SUM(E14:E15) -> 57.436 | F16: =SUM(F14:F15) -> 61.583 | G16: =SUM(G14:G15) -> 14 | H16: =SUM(H14:H15) -> 39.464 | I16: =SUM(I14:I15) -> 39.464 | J16: =SUM(J14:J15) -> 39.464 | K16: =SUM(K14:K15) -> 39.464 | ... Q16: =SUM(Q14:Q15) -> 39.464 | R16: =Q16*(1+$T$20) -> 39.06936 | S16: =R16*(1+$T$20) -> 38.678666 | T16: =S16*(1+$T$20) -> 38.29188 | U16: =T16*(1+$T$20) -> 37.908961 | V16: =U16*(1+$T$20) -> 37.529871 | W16: =V16*(1+$T$20) -> 37.154573 | X16: =W16*(1+$T$20) -> 36.783027 | Y16: =X16*(1+$T$20) -> 36.415197 | ... EO16: =EN16*(1+$T$20) -> 10.901996
C17: Share | D17: 20 | E17: 20 | F17: 20 | G17: 20 | H17: 20 | I17: 20 | J17: 20 | K17: 20 | L17: 20 | M17: 20 | N17: 20 | O17: 20 | P17: 20 | Q17: 20
C18: EPS | D18: =D16/D17 -> 3.4062 | E18: =E16/E17 -> 2.8718 | F18: =F16/F17 -> 3.07915 | G18: =G16/G17 -> 0.7 | H18: =H16/H17 -> 1.9732 | I18: =I16/I17 -> 1.9732 | J18: =J16/J17 -> 1.9732 | K18: =K16/K17 -> 1.9732 | ... Q18: =Q16/Q17 -> 1.9732
S19: Disocunt | T19: 0.09
C20: Revenue y/y | E20: =(E4-D4)/D4 -> 0.281455 | F20: =(F4-E4)/E4 -> 0.14101813 | G20: =(G4-F4)/F4 -> 0.07311003 | H20: =(H4-G4)/G4 -> 0 | I20: =(I4-H4)/H4 -> 0 | J20: =(J4-I4)/I4 -> 0 | K20: =(K4-J4)/J4 -> 0 | L20: =(L4-K4)/K4 -> 0 | ... Q20: =(Q4-P4)/P4 -> 0 | S20: TV | T20: -0.01
C21: Gross margin | D21: =D7/D4 -> 0.31401548 | E21: =E7/E4 -> 0.27997825 | F21: =F7/F4 -> 0.28386859 | G21: =G7/G4 -> 0.28931004 | H21: =H7/H4 -> 0.29 | I21: =I7/I4 -> 0.29 | J21: =J7/J4 -> 0.29 | K21: =K7/K4 -> 0.29 | ... Q21: =Q7/Q4 -> 0.29 | S21: NPV | T21: =NPV(T19,G16:EO16) -> 396.6045
C22: EBIT margin | D22: =D11/D4 -> 0.035639131 | E22: =E11/E4 -> 0.022638144 | F22: =F11/F4 -> 0.020935655 | G22: =G11/G4 -> 0.0079952621 | H22: =H11/H4 -> 0.020530056 | I22: =I11/I4 -> 0.020530056 | J22: =J11/J4 -> 0.020530056 | K22: =K11/K4 -> 0.020530056 | ... Q22: =Q11/Q4 -> 0.020530056 | S22: S/O | T22: 20
S23: NPV/Share | T23: =T21/T22 -> 19.830225
S24: Opp/nedisde | T24: =(T23-Modell!B4)/Modell!B4 -> -0.41675809
