Workbook

Sheet Info
A13: Press release:

Sheet Modell
A3: Kapitalstruktur | C3: SEK million | D3: Q122 | E3: Q222 | F3: Q322 | G3: Q422 | H3: Q123 | I3: Q223 | J3: Q323 | K3: Q423 | L3: Q124 | M3: Q224 | N3: Q324 | O3: Q424 | P3: Q125 | Q3: Q225 | R3: Q325 | S3: Q425 | T3: Q126 | U3: Q226 | V3: Q326 | W3: Q426 | Y3: FY 2015 | Z3: FY 2016 | AA3: FY 2017 | AB3: FY 2018 | AC3: FY 2019 | AD3: FY 2020 | AE3: FY 2021 | AF3: FY 2022 | AG3: FY 2023 | AH3: FY 2024 | AI3: FY 2025 | AJ3: FY 2026 | AK3: FY 2027 | AL3: FY 2028 | AM3: FY 2029 | AN3: FY 2030 | AO3: FY 2031 | AP3: FY 2032 | AQ3: FY 2033 | AR3: FY 2034 | AS3: FY 2035
A4: Price | B4: 306 | C4: Revenues | D4: 1155.5 | E4: 1141.3 | F4: 1091.6 | G4: 1191.5 | H4: 1399.9 | I4: 1450.2 | J4: 1439.9 | K4: 1449.9 | L4: 1535 | M4: 1494.3 | N4: 1272.9 | O4: 1276.6 | P4: 1351.3 | Q4: 1362.4 | R4: 1367.9 | S4: 1312.5 | T4: 1376.4 | U4: 1480.4 | Y4: 1315.3 | Z4: 1543.9 | AA4: 3002.045 | AB4: 3492.449 | AC4: 3725.442 | AD4: 3147.157 | AE4: 3611.224 | AF4: 4579.978 | AG4: 5739.756 | AH4: 5578.859 | AI4: 5394 | AJ4: =AI4*1.06 -> 5717.64 | AK4: =AJ4*1.05 -> 6003.522 | AL4: =AK4*1.05 -> 6303.6981 | AM4: =AL4*1.05 -> 6618.883 | AN4: =AM4*1.05 -> 6949.8272 | AO4: =AN4*1.05 -> 7297.3185 | AP4: =AO4*1.05 -> 7662.1844 | AQ4: =AP4*1.05 -> 8045.2937 | AR4: =AQ4*1.05 -> 8447.5583 | AS4: =AR4*1.05 -> 8869.9363
A5: S/O | B5: 25.003 | C5: COGS | D5: -794 | E5: -806.9 | F5: -787.1 | G5: -844.7 | H5: -973 | I5: -993.3 | J5: -1002.2 | K5: -984.7 | L5: -1034.5 | M5: -1001.5 | N5: -871.7 | O5: -859.1 | P5: -916 | Q5: -923.9 | R5: -940 | S5: -917.3 | T5: -930.8 | U5: -1051.1 | AA5: -1934.143 | AB5: -2301.572 | AC5: -2471.55 | AD5: -2083.607 | AE5: -2446.404 | AF5: -3232.691 | AG5: -3980.764 | AH5: -3773.182 | AI5: -3697 | AJ5: =AJ4*-0.69 -> -3945.1716 | AK5: =AK4*-0.69 -> -4142.4302 | AL5: =AL4*-0.69 -> -4349.5517 | AM5: =AM4*-0.69 -> -4567.0293 | AN5: =AN4*-0.69 -> -4795.3807 | AO5: =AO4*-0.69 -> -5035.1498 | AP5: =AP4*-0.69 -> -5286.9073 | AQ5: =AQ4*-0.69 -> -5551.2526 | ... AS5: =AS4*-0.69 -> -6120.256
A6: MC SEKm | B6: =B4*B5 -> 7650.918 | C6: Gross profit | D6: =SUM(D4:D5) -> 361.5 | E6: =SUM(E4:E5) -> 334.4 | F6: =SUM(F4:F5) -> 304.5 | G6: =SUM(G4:G5) -> 346.8 | H6: =SUM(H4:H5) -> 426.9 | I6: =SUM(I4:I5) -> 456.9 | J6: =SUM(J4:J5) -> 437.7 | K6: =SUM(K4:K5) -> 465.2 | ... U6: =SUM(U4:U5) -> 429.3 | AA6: =SUM(AA4:AA5) -> 1067.902 | AB6: =SUM(AB4:AB5) -> 1190.877 | AC6: =SUM(AC4:AC5) -> 1253.892 | AD6: =SUM(AD4:AD5) -> 1063.55 | AE6: =SUM(AE4:AE5) -> 1164.82 | AF6: =SUM(AF4:AF5) -> 1347.287 | AG6: =SUM(AG4:AG5) -> 1758.992 | AH6: =SUM(AH4:AH5) -> 1805.677 | ... AS6: =SUM(AS4:AS5) -> 2749.6802
A7: Cash SEKm | B7: =U46 -> 984 | C7: Selling expenses | D7: -94 | E7: -97.8 | F7: -97.8 | G7: -102.8 | H7: -102 | I7: -105.7 | J7: -102.9 | K7: -117.6 | L7: -105.9 | M7: -123.6 | N7: -105.9 | O7: -123.4 | P7: -116 | Q7: -115.3 | R7: -126.4 | S7: -123.5 | T7: -128.6 | U7: -126.6 | AA7: -332.082 | AB7: -381.68 | AC7: -380 | AD7: -321.72 | AE7: -315.243 | AF7: -392.509 | AG7: -428.405 | AH7: -458.871 | AI7: -481 | AJ7: =AI7*1.05 -> -505.05 | AK7: =AJ7*1.05 -> -530.3025 | AL7: =AK7*1.05 -> -556.81763 | AM7: =AL7*1.05 -> -584.65851 | AN7: =AM7*1.05 -> -613.89143 | AO7: =AN7*1.05 -> -644.586 | AP7: =AO7*1.05 -> -676.8153 | AQ7: =AP7*1.05 -> -710.65607 | ... AS7: =AR7*1.05 -> -783.49832
A8: Debt SEKm | B8: =U57 -> 1480.2 | C8: Adminstrative expenses | D8: -77.4 | E8: -85.9 | F8: -81.4 | G8: -92 | H8: -89.6 | I8: -98 | J8: -80.2 | K8: -102.1 | L8: -107.8 | M8: -109.6 | N8: -97.3 | O8: -105.4 | P8: -109 | Q8: -116.1 | R8: -106.2 | S8: -98.6 | T8: -120.4 | U8: -129.5 | AA8: -253.467 | AB8: -264.959 | AC8: -274.946 | AD8: -242.574 | AE8: -269.317 | AF8: -336.664 | AG8: -369.21 | AH8: -419.994 | AI8: -430 | AJ8: =AI8*1.05 -> -451.5 | AK8: =AJ8*1.05 -> -474.075 | AL8: =AK8*1.05 -> -497.77875 | AM8: =AL8*1.05 -> -522.66769 | AN8: =AM8*1.05 -> -548.80107 | AO8: =AN8*1.05 -> -576.24113 | AP8: =AO8*1.05 -> -605.05318 | AQ8: =AP8*1.05 -> -635.30584 | ... AS8: =AR8*1.05 -> -700.42469
A9: EV SEKm | B9: =B6-B7+B8 -> 8147.118 | C9: R&D | D9: -32 | E9: -34.7 | F9: -33.2 | G9: -34.5 | H9: -34.6 | I9: -37.2 | J9: -35.8 | K9: -34.6 | L9: -40.1 | M9: -44.8 | N9: -38.9 | O9: -39.1 | P9: -41.1 | Q9: -37.8 | R9: -38.8 | S9: -34.1 | T9: -37.5 | U9: -43 | AA9: -106.394 | AB9: -136.403 | AC9: -136.668 | AD9: -113.634 | AE9: -109.994 | AF9: -134.38 | AG9: -141.938 | AH9: -162.875 | AI9: -152 | AJ9: =AI9*1.05 -> -159.6 | AK9: =AJ9*1.05 -> -167.58 | AL9: =AK9*1.05 -> -175.959 | AM9: =AL9*1.05 -> -184.75695 | AN9: =AM9*1.05 -> -193.9948 | AO9: =AN9*1.05 -> -203.69454 | AP9: =AO9*1.05 -> -213.87926 | AQ9: =AP9*1.05 -> -224.57323 | ... AS9: =AR9*1.05 -> -247.59198
C10: Other operating inome | D10: 0 | E10: 23.3 | F10: 0 | G10: 0 | H10: 0 | I10: 0 | J10: 0 | K10: 0 | L10: 4.9 | M10: 0 | N10: 5 | O10: 21.6 | P10: 0 | Q10: 0 | R10: 1.8 | S10: 20.2 | T10: 2.7 | U10: 5.3 | AA10: 3.433 | AB10: 25.548 | AC10: 8.7 | AD10: 7.89 | AE10: 9.5 | AF10: 74.739 | AG10: 22.365 | AH10: 33 | AI10: 22 | AJ10: =AI10*1.05 -> 23.1 | AK10: =AJ10*1.05 -> 24.255 | AL10: =AK10*1.05 -> 25.46775 | AM10: =AL10*1.05 -> 26.741138 | AN10: =AM10*1.05 -> 28.078194 | AO10: =AN10*1.05 -> 29.482104 | AP10: =AO10*1.05 -> 30.956209 | AQ10: =AP10*1.05 -> 32.50402 | ... AS10: =AR10*1.05 -> 35.835682
C11: Other opex | D11: -1.7 | E11: 0 | F11: 12.4 | G11: 9.4 | H11: -6.1 | I11: -11.9 | J11: -1.7 | K11: -1.9 | L11: 0 | M11: -5.7 | N11: 0 | O11: 0 | P11: -3.5 | Q11: -2.2 | R11: 0 | S11: 0 | T11: 0 | U11: 0 | AA11: -28.296 | AB11: -15.836 | AC11: -35.938 | AD11: -40.14 | AE11: -23.81 | AF11: -31.255 | AG11: -14.245 | AH11: -1.1 | AI11: -6 | AJ11: =AI11*1.05 -> -6.3 | AK11: =AJ11*1.05 -> -6.615 | AL11: =AK11*1.05 -> -6.94575 | AM11: =AL11*1.05 -> -7.2930375 | AN11: =AM11*1.05 -> -7.6576894 | AO11: =AN11*1.05 -> -8.0405738 | AP11: =AO11*1.05 -> -8.4426025 | AQ11: =AP11*1.05 -> -8.8647327 | ... AS11: =AR11*1.05 -> -9.7733678
A12: P/B | B12: =B4/(S52/B5) -> 1.9293217 | C12: Total opex | D12: =D5+D7+D8+D9+D10+D11 -> -999.1 | E12: =E5+E7+E8+E9+E10+E11 -> -1002 | F12: =F5+F7+F8+F9+F10+F11 -> -987.1 | G12: =G5+G7+G8+G9+G10+G11 -> -1064.6 | H12: =H5+H7+H8+H9+H10+H11 -> -1205.3 | I12: =I5+I7+I8+I9+I10+I11 -> -1246.1 | J12: =J5+J7+J8+J9+J10+J11 -> -1222.8 | K12: =K5+K7+K8+K9+K10+K11 -> -1240.9 | ... U12: =U5+U7+U8+U9+U10+U11 -> -1344.9 | Y12: =Y13-Y4 -> -1180.6 | Z12: =Z13-Z4 -> -1347.7 | AA12: =AA5+AA7+AA8+AA9+AA10+AA11 -> -2650.949 | AB12: =AB5+AB7+AB8+AB9+AB10+AB11 -> -3074.902 | AC12: =AC5+AC7+AC8+AC9+AC10+AC11 -> -3290.402 | AD12: =AD5+AD7+AD8+AD9+AD10+AD11 -> -2793.785 | AE12: =AE5+AE7+AE8+AE9+AE10+AE11 -> -3155.268 | AF12: =AF5+AF7+AF8+AF9+AF10+AF11 -> -4052.76 | AG12: =AG5+AG7+AG8+AG9+AG10+AG11 -> -4912.197 | AH12: =AH5+AH7+AH8+AH9+AH10+AH11 -> -4783.022 | ... AS12: =AS5+AS7+AS8+AS9+AS10+AS11 -> -7825.7087
C13: Operating income (EBIT) | D13: =D4+D12 -> 156.4 | E13: =E4+E12 -> 139.3 | F13: =F4+F12 -> 104.5 | G13: =G4+G12 -> 126.9 | H13: =H4+H12 -> 194.6 | I13: =I4+I12 -> 204.1 | J13: =J4+J12 -> 217.1 | K13: =K4+K12 -> 209 | ... U13: =U4+U12 -> 135.5 | Y13: 134.7 | Z13: 196.2 | AA13: =AA4+AA12 -> 351.096 | AB13: =AB4+AB12 -> 417.547 | AC13: =AC4+AC12 -> 435.04 | AD13: =AD4+AD12 -> 353.372 | AE13: =AE4+AE12 -> 455.956 | AF13: =AF4+AF12 -> 527.218 | AG13: =AG4+AG12 -> 827.559 | AH13: =AH4+AH12 -> 795.837 | ... AS13: =AS4+AS12 -> 1044.2276
A14: Gearing | C14: Financial items | D14: -8.5 | E14: -6.3 | F14: -3.2 | G14: -21.4 | H14: -14.4 | I14: -22.9 | J14: -0.2 | K14: -25.5 | L14: -1.3 | M14: 2.5 | N14: -16.3 | O14: 1.3 | P14: -14.3 | Q14: -30.5 | R14: -18.8 | S14: -14 | T14: -14.1 | U14: -9.1 | AA14: -35.489 | AB14: -44.5 | AC14: -38.011 | AD14: -26.9 | AE14: -14.561 | AF14: -39.422 | AG14: -61.273 | AH14: -13.724 | AI14: -78 | AJ14: -50 | AK14: -50 | AL14: -50 | AM14: -50 | AN14: -50 | AO14: -50 | AP14: -50 | AQ14: -50 | AR14: -50 | AS14: -50
C15: PTP | D15: =SUM(D13:D14) -> 147.9 | E15: =SUM(E13:E14) -> 133 | F15: =SUM(F13:F14) -> 101.3 | G15: =SUM(G13:G14) -> 105.5 | H15: =SUM(H13:H14) -> 180.2 | I15: =SUM(I13:I14) -> 181.2 | J15: =SUM(J13:J14) -> 216.9 | K15: =SUM(K13:K14) -> 183.5 | ... U15: =SUM(U13:U14) -> 126.4 | AA15: =SUM(AA13:AA14) -> 315.607 | AB15: =SUM(AB13:AB14) -> 373.047 | AC15: =SUM(AC13:AC14) -> 397.029 | AD15: =SUM(AD13:AD14) -> 326.472 | AE15: =SUM(AE13:AE14) -> 441.395 | AF15: =SUM(AF13:AF14) -> 487.796 | AG15: =SUM(AG13:AG14) -> 766.286 | AH15: =SUM(AH13:AH14) -> 782.113 | ... AS15: =SUM(AS13:AS14) -> 994.22757
C16: Tax | D16: -33.5 | E16: -32.4 | F16: -38.7 | G16: -14.9 | H16: -38.4 | I16: -43 | J16: -58 | K16: -53.9 | L16: -54.5 | M16: -43.8 | N16: -35.5 | O16: -60.2 | P16: -37 | Q16: -36.6 | R16: -42.8 | S16: -34.4 | T16: -34.5 | U16: -36.8 | AA16: -95.115 | AB16: -100.177 | AC16: -97.489 | AD16: -99.759 | AE16: -104.324 | AF16: -119.523 | AG16: -194.211 | AH16: -194 | AI16: -151 | AJ16: =AJ15*-0.206 -> -128.36239 | AK16: =AK15*-0.206 -> -135.29551 | AL16: =AL15*-0.206 -> -142.57529 | AM16: =AM15*-0.206 -> -150.21905 | AN16: =AN15*-0.206 -> -158.245 | AO16: =AO15*-0.206 -> -166.67225 | AP16: =AP15*-0.206 -> -175.52086 | AQ16: =AQ15*-0.206 -> -184.81191 | ... AS16: =AS15*-0.206 -> -204.81088
C17: Net income | D17: =SUM(D15:D16) -> 114.4 | E17: =SUM(E15:E16) -> 100.6 | F17: =SUM(F15:F16) -> 62.6 | G17: =SUM(G15:G16) -> 90.6 | H17: =SUM(H15:H16) -> 141.8 | I17: =SUM(I15:I16) -> 138.2 | J17: =SUM(J15:J16) -> 158.9 | K17: =SUM(K15:K16) -> 129.6 | ... U17: =SUM(U15:U16) -> 89.6 | Y17: 95.5 | Z17: 120.8 | AA17: =SUM(AA15:AA16) -> 220.492 | AB17: =SUM(AB15:AB16) -> 272.87 | AC17: =SUM(AC15:AC16) -> 299.54 | AD17: =SUM(AD15:AD16) -> 226.713 | AE17: =SUM(AE15:AE16) -> 337.071 | AF17: =SUM(AF15:AF16) -> 368.273 | AG17: =SUM(AG15:AG16) -> 572.075 | AH17: =SUM(AH15:AH16) -> 588.113 | ... AS17: =SUM(AS15:AS16) -> 789.41669 | AT17: =AS17*(1+$AV$21) -> 781.52252 | AU17: =AT17*(1+$AV$21) -> 773.7073 | AV17: =AU17*(1+$AV$21) -> 765.97022 | AW17: =AV17*(1+$AV$21) -> 758.31052 | AX17: =AW17*(1+$AV$21) -> 750.72742 | AY17: =AX17*(1+$AV$21) -> 743.22014 | AZ17: =AY17*(1+$AV$21) -> 735.78794 | BA17: =AZ17*(1+$AV$21) -> 728.43006 | ... EA17: =DZ17*(1+$AV$21) -> 332.60827
C18: Share | D18: 25.004 | E18: 25.004 | F18: 25.004 | G18: 25.004 | H18: 25.004 | I18: 25.004 | J18: 25.004 | K18: 25.004 | L18: 25.004 | M18: 25.004 | N18: 25.004 | O18: 25.004 | P18: 25.004 | Q18: 25.004 | R18: 25.004 | S18: 25.004 | T18: 25.004 | U18: 25.004 | Y18: 12.502 | Z18: 12.502 | AA18: 25.004 | AB18: 25.004 | AC18: 25.004 | AD18: 25.004 | AE18: 25.004 | AF18: 25.004 | AG18: 25.004 | AH18: 25.004 | AI18: 25.004 | AJ18: 25.004 | AK18: 25.004 | AL18: 25.004 | AM18: 25.004 | AN18: 25.004 | AO18: 25.004 | AP18: 25.004 | AQ18: 25.004 | AR18: 25.004 | AS18: 25.004
C19: EPS | D19: =D17/D18 -> 4.575268 | E19: =E17/E18 -> 4.0233563 | F19: =F17/F18 -> 2.5035994 | G19: =G17/G18 -> 3.6234203 | H19: =H17/H18 -> 5.6710926 | I19: =I17/I18 -> 5.5271157 | J19: =J17/J18 -> 6.3549832 | K19: =K17/K18 -> 5.1831707 | ... U19: =U17/U18 -> 3.5834267 | Y19: =Y17/Y18 -> 7.6387778 | Z19: =Z17/Z18 -> 9.662454 | AA19: =AA17/AA18 -> 8.8182691 | AB19: =AB17/AB18 -> 10.913054 | AC19: =AC17/AC18 -> 11.979683 | AD19: =AD17/AD18 -> 9.0670693 | AE19: =AE17/AE18 -> 13.480683 | AF19: =AF17/AF18 -> 14.728563 | ... AS19: =AS17/AS18 -> 31.571616
AU20: Discount | AV20: 0.075
C21: Revenue y/y | H21: =(H4-D4)/D4 -> 0.21151017 | I21: =(I4-E4)/E4 -> 0.27065627 | J21: =(J4-F4)/F4 -> 0.31907292 | K21: =(K4-G4)/G4 -> 0.21686949 | L21: =(L4-H4)/H4 -> 0.096506893 | M21: =(M4-I4)/I4 -> 0.030409599 | N21: =(N4-J4)/J4 -> -0.11598028 | O21: =(O4-K4)/K4 -> -0.11952548 | ... U21: =(U4-Q4)/Q4 -> 0.086611861 | Z21: =(Z4-Y4)/Y4 -> 0.17380065 | AA21: =(AA4-Z4)/Z4 -> 0.9444556 | AB21: =(AB4-AA4)/AA4 -> 0.16335665 | AC21: =(AC4-AB4)/AB4 -> 0.066713358 | AD21: =(AD4-AC4)/AC4 -> -0.15522588 | AE21: =(AE4-AD4)/AD4 -> 0.14745594 | AF21: =(AF4-AE4)/AE4 -> 0.26826195 | AG21: =(AG4-AF4)/AF4 -> 0.25322785 | ... AS21: =(AS4-AR4)/AR4 -> 0.05 | AU21: TV | AV21: -0.01
C22: Organic growth | R22: 0.063 | S22: 0.046 | T22: 0.053 | U22: 0.087 | AU22: NPV | AV22: =NPV(AV20,AJ17:EA17) -> 8667.1943
C23: OPEX Y/Y | H23: =(H12-D12)/D12 -> 0.20638575 | I23: =(I12-E12)/E12 -> 0.24361277 | J23: =(J12-F12)/F12 -> 0.23878027 | K23: =(K12-G12)/G12 -> 0.1656021 | L23: =(L12-H12)/H12 -> 0.064797146 | M23: =(M12-I12)/I12 -> 0.031377899 | N23: =(N12-J12)/J12 -> -0.093228656 | O23: =(O12-K12)/K12 -> -0.10919494 | ... U23: =(U12-Q12)/Q12 -> 0.12515686 | Z23: =(Z12-Y12)/Y12 -> 0.1415382 | AA23: =(AA12-Z12)/Z12 -> 0.96701714 | AB23: =(AB12-AA12)/AA12 -> 0.15992499 | AC23: =(AC12-AB12)/AB12 -> 0.070083534 | AD23: =(AD12-AC12)/AC12 -> -0.15092897 | AE23: =(AE12-AD12)/AD12 -> 0.12938827 | AF23: =(AF12-AE12)/AE12 -> 0.2844424 | AG23: =(AG12-AF12)/AF12 -> 0.21206215 | ... AS23: =(AS12-AR12)/AR12 -> 0.05 | AU23: S/O | AV23: 25.003
C24: Gross margin | D24: =D6/D4 -> 0.31285158 | E24: =E6/E4 -> 0.29299921 | F24: =F6/F4 -> 0.27894833 | G24: =G6/G4 -> 0.29106169 | H24: =H6/H4 -> 0.30495035 | I24: =I6/I4 -> 0.31505999 | J24: =J6/J4 -> 0.30397944 | K24: =K6/K4 -> 0.32084971 | ... U24: =U6/U4 -> 0.28998919 | AA24: =AA6/AA4 -> 0.35572485 | AB24: =AB6/AB4 -> 0.34098622 | AC24: =AC6/AC4 -> 0.33657536 | AD24: =AD6/AD4 -> 0.33793992 | AE24: =AE6/AE4 -> 0.32255545 | AF24: =AF6/AF4 -> 0.29416888 | AG24: =AG6/AG4 -> 0.30645763 | AH24: =AH6/AH4 -> 0.32366421 | ... AS24: =AS6/AS4 -> 0.31 | AU24: NPV/Share | AV24: =AV22/AV23 -> 346.64618
C25: EBIT margin | D25: =D13/D4 -> 0.13535266 | E25: =E13/E4 -> 0.1220538 | F25: =F13/F4 -> 0.095731037 | G25: =G13/G4 -> 0.10650441 | H25: =H13/H4 -> 0.13900993 | I25: =I13/I4 -> 0.14073921 | J25: =J13/J4 -> 0.15077436 | K25: =K13/K4 -> 0.14414787 | ... U25: =U13/U4 -> 0.091529316 | Y25: =Y13/Y4 -> 0.1024101 | Z25: =Z13/Z4 -> 0.12708077 | AA25: =AA13/AA4 -> 0.11695228 | AB25: =AB13/AB4 -> 0.11955708 | AC25: =AC13/AC4 -> 0.11677541 | AD25: =AD13/AD4 -> 0.11228293 | AE25: =AE13/AE4 -> 0.12626079 | AF25: =AF13/AF4 -> 0.11511365 | ... AS25: =AS13/AS4 -> 0.11772661 | AU25: Opp/nedside | AV25: =(AV24-B4)/B4 -> 0.13283064
C26: ROE | Y26: 0.113 | Z26: 0.127 | AA26: 0.123 | AB26: 0.128 | AC26: 0.125 | AD26: 0.09 | AE26: 12.2% | AF26: 0.114 | AG26: 0.162 | AH26: 0.145
C28: Balanse SEKm
C29: Brands and other intangiable assets | D29: 840.5 | E29: 853.5 | F29: 821 | G29: 821.1 | H29: 814.5 | I29: 810.4 | J29: 802 | K29: 939.4 | L29: 932.1 | M29: 947.3 | N29: 927.1 | O29: 910.7 | P29: 877.3 | Q29: 856.9 | R29: 955.9 | S29: 935.9 | T29: 937 | U29: 934.9 | AF29: 821.1 | AG29: 939.4 | AH29: 910.7 | AI29: 935.9
C30: Goodwill | D30: 1188 | E30: 1206.8 | F30: 1229.8 | G30: 1226.8 | H30: 1234.8 | I30: 1257.8 | J30: 1244.6 | K30: 1291.3 | L30: 1312 | M30: 1303.3 | N30: 1311.7 | O30: 1322.9 | P30: 1513.2 | Q30: 1565.1 | R30: 1662.3 | S30: 1640.3 | T30: 1660.8 | U30: 1678 | AF30: 1226.8 | AG30: 1291.3 | AH30: 1322.9 | AI30: 1640.3
C31: Land and buildings | D31: 193.5 | E31: 187.7 | F31: 181.8 | G31: 198.3 | H31: 222.9 | I31: 232.4 | J31: 223.9 | K31: 251.7 | L31: 256.7 | M31: 258.8 | N31: 274.8 | O31: 697.5 | P31: 646.1 | Q31: 643.6 | R31: 653.5 | S31: 771.7 | T31: 821.5 | U31: 890.6 | AF31: 198.3 | AG31: 251.7 | AH31: 697.5 | AI31: 771.7
C32: Plant and machinery | D32: 137.3 | E32: 133.3 | F32: 131.2 | G32: 134.5 | H32: 137.7 | I32: 162.5 | J32: 157.5 | K32: 178.2 | L32: 178 | M32: 178.9 | N32: 190.9 | O32: 220.4 | P32: 210.4 | Q32: 234.4 | R32: 249.3 | S32: 291.4 | T32: 298.8 | U32: 295.5 | AF32: 134.5 | AG32: 178.2 | AH32: 220.4 | AI32: 291.4
C33: Equipment, tools, fixtures | D33: 52.1 | E33: 54 | F33: 71.8 | G33: 96.3 | H33: 74.1 | I33: 76.9 | J33: 76.5 | K33: 72 | L33: 74.1 | M33: 75.7 | N33: 73.5 | O33: 84.2 | P33: 77.6 | Q33: 76.9 | R33: 85.3 | S33: 92 | T33: 93.8 | U33: 97 | AF33: 96.3 | AG33: 72 | AH33: 84.2 | AI33: 92
C34: Construction in progress | D34: 28.7 | E34: 59.2 | F34: 50.4 | G34: 29.6 | H34: 37.1 | I34: 33.4 | J34: 49.6 | K34: 14.9 | L34: 25.3 | M34: 41.6 | N34: 73.2 | O34: 45 | P34: 55.7 | Q34: 53 | R34: 48.5 | S34: 37.8 | T34: 53.2 | U34: 87.6 | AF34: 29.6 | AG34: 14.9 | AH34: 45 | AI34: 37.8
C35: Right-of-use assets | D35: 105.9 | E35: 101.9 | F35: 370.4 | G35: 430.2 | H35: 326.8 | I35: 400.6 | J35: 386.3 | K35: 255.7 | L35: 251.2 | M35: 257.9 | N35: 239.7 | O35: 251.7 | P35: 220 | Q35: 200.5 | R35: 224.6 | S35: 212.3 | T35: 209 | U35: 210.4 | AF35: 430.2 | AG35: 255.7 | AH35: 251.7 | AI35: 212.3
C36: Non-current receivables | D36: 0 | E36: 0 | F36: 0 | G36: 0 | H36: 0 | I36: 0 | J36: 0 | K36: 0.9 | L36: 0 | M36: 0 | N36: 0 | O36: 2.5 | P36: 0 | Q36: 0 | R36: 0 | S36: 3 | T36: 3.3 | U36: 2.9 | AF36: 0 | AG36: 0.9 | AH36: 2.5 | AI36: 3
C37: Deferred tax asset | D37: 55.7 | E37: 55.5 | F37: 55 | G37: 24.3 | H37: 27.4 | I37: 28.9 | J37: 22.7 | K37: 27.5 | L37: 23.9 | M37: 33.4 | N37: 35.5 | O37: 73.9 | P37: 68.5 | Q37: 66.6 | R37: 57.3 | S37: 48.9 | T37: 49.9 | U37: 50.9 | AF37: 24.3 | AG37: 27.5 | AH37: 73.9 | AI37: 48.9
C38: Raw materials and consumables | D38: 523.4 | E38: 609.2 | F38: 674.5 | G38: 628.1 | H38: 557.9 | I38: 606.7 | J38: 622.4 | K38: 531.9 | L38: 512 | M38: 511.3 | N38: 533.1 | O38: 467.7 | P38: 476.5 | Q38: 450 | R38: 494.5 | S38: 405.1 | T38: 474.4 | U38: 520.4 | AF38: 628.1 | AG38: 531.9 | AH38: 467.7 | AI38: 405.1
C39: Work in progress | D39: 118.9 | E39: 128.6 | F39: 141.5 | G39: 123.9 | H39: 140 | I39: 149.3 | J39: 155.1 | K39: 142.9 | L39: 157.2 | M39: 155.5 | N39: 148.9 | O39: 135.8 | P39: 143.6 | Q39: 144.6 | R39: 158 | S39: 151.7 | T39: 173.6 | U39: 185.5 | AF39: 123.9 | AG39: 142.9 | AH39: 135.8 | AI39: 151.7
C40: Finished products and merchandise | D40: 271.6 | E40: 325.8 | F40: 346.3 | G40: 358.5 | H40: 375.7 | I40: 401.3 | J40: 363.5 | K40: 364.4 | L40: 373.3 | M40: 409.5 | N40: 369.1 | O40: 354.3 | P40: 349.6 | Q40: 389.6 | R40: 396.4 | S40: 339.2 | T40: 349.9 | U40: 367.4 | AF40: 358.5 | AG40: 364.4 | AH40: 354.3 | AI40: 339.2
... C46: Cash | D46: 709.5 | E46: 628.5 | F46: 609.8 | G46: 498.8 | H46: 464.7 | I46: 416.6 | J46: 1055.2 | K46: 885.9 | L46: 1030.5 | M46: 916.6 | N46: 927.3 | O46: 949.7 | P46: 925.2 | Q46: 906.1 | R46: 779.8 | S46: 1108.4 | T46: 1117.6 | U46: 984 | AF46: 498.8 | AG46: 885.9 | AH46: 949.7 | AI46: 1108.4
C47: Total assets | D47: =SUM(D29:D46) -> 5022.9 | E47: =SUM(E29:E46) -> 5212.3 | F47: =SUM(F29:F46) -> 5586.9 | G47: =SUM(G29:G46) -> 5412 | H47: =SUM(H29:H46) -> 5402.7 | I47: =SUM(I29:I46) -> 5729.6 | J47: =SUM(J29:J46) -> 6259.7 | K47: =SUM(K29:K46) -> 5970.1 | ... U47: =SUM(U29:U46) -> 7660.1 | AF47: =SUM(AF29:AF46) -> 5412 | AG47: =SUM(AG29:AG46) -> 5970.1 | AH47: =SUM(AH29:AH46) -> 6524.4 | AI47: =SUM(AI29:AI46) -> 7077
C48: Share capital | D48: 65.5 | E48: 65.5 | F48: 65.5 | G48: 65.5 | H48: 65.5 | I48: 65.5 | J48: 65.5 | K48: 65.5 | L48: 65.5 | M48: 65.5 | N48: 65.5 | O48: 65.5 | P48: 65.5 | Q48: 65.5 | R48: 65.6 | S48: 66 | T48: 65.5 | U48: 65.5 | AF48: 65.5 | AG48: 65.5 | AH48: 65.5 | AI48: 66
...

Sheet T&T
B3: SEK million | C3: Q122 | D3: Q222 | E3: Q322 | F3: Q422 | G3: 2022 | H3: Q123 | I3: Q223 | J3: Q323 | K3: Q423 | L3: 2023 | M3: Q124 | N3: Q224 | O3: Q324 | P3: Q424 | Q3: 2024 | R3: Q125 | S3: Q225 | T3: Q325 | U3: Q425 | V3: 2025 | W3: Q126 | X3: Q226 | Y3: Q326 | Z3: Q426 | AA3: 2026
B4: Truck and Trailer
B5: Revenue | C5: 434.8 | D5: 388.3 | E5: 362.4 | F5: 443.2 | G5: =SUM(C5:F5) -> 1628.7 | H5: 495.7 | I5: 437.9 | J5: 381.7 | K5: 412.3 | L5: =SUM(H5:K5) -> 1727.6 | M5: 439 | N5: 390.5 | O5: 340.7 | P5: 367 | Q5: =SUM(M5:P5) -> 1537.2 | R5: 433.2 | S5: 399.8 | T5: 370 | U5: 405.7 | V5: =SUM(R5:U5) -> 1608.7 | W5: 447.6 | X5: 412.3 | AA5: =SUM(W5:Z5) -> 859.9
B6: Growth % | H6: =(H5-C5)/C5 -> 0.1400644 | I6: =(I5-D5)/D5 -> 0.12773629 | J6: =(J5-E5)/E5 -> 0.053256071 | K6: =(K5-F5)/F5 -> -0.069720217 | L6: =(L5-G5)/G5 -> 0.060723276 | M6: =(M5-H5)/H5 -> -0.1143837 | N6: =(N5-I5)/I5 -> -0.10824389 | O6: =(O5-J5)/J5 -> -0.1074142 | ... AA6: =(AA5-V5)/V5 -> -0.46546901
B7: EBITDA | C7: 101.5 | D7: 79.4 | E7: 61.5 | F7: 98.9 | G7: =SUM(C7:F7) -> 341.3 | H7: 123 | I7: 97.6 | J7: 89.9 | K7: 82.7 | L7: =SUM(H7:K7) -> 393.2 | M7: 108.8 | N7: 68.5 | O7: 60.5 | P7: 91 | Q7: =SUM(M7:P7) -> 328.8 | R7: 104.1 | S7: 77.9 | T7: 73.7 | U7: 95.9 | V7: =SUM(R7:U7) -> 351.6 | W7: 108.2 | X7: 94.3 | AA7: =SUM(W7:Z7) -> 202.5
B8: EBITA | C8: 93.4 | D8: 69.1 | E8: 52.6 | F8: 92.5 | G8: =SUM(C8:F8) -> 307.6 | H8: 114.7 | I8: 88.6 | J8: 81.2 | K8: 85.9 | L8: =SUM(H8:K8) -> 370.4 | M8: 100.6 | N8: 61.1 | O8: 52.4 | P8: 82.6 | Q8: =SUM(M8:P8) -> 296.7 | R8: 93.6 | S8: 67.4 | T8: 66.3 | U8: 80 | V8: =SUM(R8:U8) -> 307.3 | W8: 96.4 | X8: 82.3 | AA8: =SUM(W8:Z8) -> 178.7
B9: EBITA margin % | C9: 0.215 | D9: 0.178 | E9: 0.145 | F9: 0.209 | G9: =G8/G5 -> 0.18886228 | H9: 0.231 | I9: 0.202 | J9: 0.213 | K9: 0.208 | L9: =L8/L5 -> 0.21440148 | M9: 0.229 | N9: 0.156 | O9: 0.154 | P9: 0.225 | Q9: =Q8/Q5 -> 0.19301327 | R9: 0.216 | S9: 0.169 | T9: 0.179 | U9: 0.197 | V9: =V8/V5 -> 0.19102381 | W9: 0.215 | X9: 0.2 | AA9: =AA8/AA5 -> 0.20781486
B10: EBIT | C10: 92.2 | D10: 67.9 | E10: 51.4 | F10: 91.1 | G10: =SUM(C10:F10) -> 302.6 | H10: 113.3 | I10: 87.3 | J10: 79.3 | K10: 84.2 | L10: =SUM(H10:K10) -> 364.1 | M10: 99 | N10: 59.4 | O10: 50.8 | P10: 80.9 | Q10: =SUM(M10:P10) -> 290.1 | R10: 91.9 | S10: 65.8 | T10: 64.6 | U10: 78.3 | V10: =SUM(R10:U10) -> 300.6 | W10: 94.9 | X10: 80.7 | AA10: =SUM(W10:Z10) -> 175.6
B11: EBIT margin | C11: 0.212 | D11: 0.175 | E11: 0.142 | F11: 0.206 | G11: =G10/G5 -> 0.18579235 | H11: 0.229 | I11: 0.199 | J11: 0.208 | K11: 0.204 | L11: =L10/L5 -> 0.2107548 | M11: 0.225 | N11: 0.152 | O11: 0.149 | P11: 0.221 | Q11: =Q10/Q5 -> 0.18871975 | R11: 0.212 | S11: 0.165 | T11: 0.175 | U11: 0.193 | V11: =V10/V5 -> 0.18685895 | W11: 0.212 | X11: 0.196 | AA11: =AA10/AA5 -> 0.20420979
B12: Sweden | C12: 76.2 | D12: 72.9 | E12: 52.2 | F12: 69.7 | G12: =SUM(C12:F12) -> 271 | H12: 84.1 | I12: 74.8 | J12: 46.5 | K12: 68.4 | L12: =SUM(H12:K12) -> 273.8 | M12: 81.3 | N12: 66.7 | O12: 50.7 | P12: 59.6 | Q12: =SUM(M12:P12) -> 258.3 | R12: 76.4 | S12: 66.7 | T12: 74.4 | U12: 91.7 | V12: =SUM(R12:U12) -> 309.2 | W12: 93.9 | X12: 83.9 | AA12: =SUM(W12:Z12) -> 177.8
B13: Growth % | H13: =(H12-C12)/C12 -> 0.10367454 | I13: =(I12-D12)/D12 -> 0.0260631 | J13: =(J12-E12)/E12 -> -0.1091954 | K13: =(K12-F12)/F12 -> -0.018651363 | L13: =(L12-G12)/G12 -> 0.010332103 | M13: =(M12-H12)/H12 -> -0.033293698 | N13: =(N12-I12)/I12 -> -0.10828877 | O13: =(O12-J12)/J12 -> 0.090322581 | ... AA13: =(AA12-V12)/V12 -> -0.42496766
B14: Other Nordic countries | C14: 52.1 | D14: 48.7 | E14: 45.1 | F14: 48.5 | G14: =SUM(C14:F14) -> 194.4 | H14: 60.5 | I14: 55.4 | J14: 45.6 | K14: 54 | L14: =SUM(H14:K14) -> 215.5 | M14: 61 | N14: 53.7 | O14: 45.5 | P14: 51.2 | Q14: =SUM(M14:P14) -> 211.4 | R14: 63.6 | S14: 46.3 | T14: 41.6 | U14: 54 | V14: =SUM(R14:U14) -> 205.5 | W14: 57.1 | X14: 55.2 | AA14: =SUM(W14:Z14) -> 112.3
B15: Growth % | H15: =(H14-C14)/C14 -> 0.16122841 | I15: =(I14-D14)/D14 -> 0.137577 | J15: =(J14-E14)/E14 -> 0.011086475 | K15: =(K14-F14)/F14 -> 0.11340206 | L15: =(L14-G14)/G14 -> 0.10853909 | M15: =(M14-H14)/H14 -> 0.0082644628 | N15: =(N14-I14)/I14 -> -0.030685921 | O15: =(O14-J14)/J14 -> -0.0021929825 | ... AA15: =(AA14-V14)/V14 -> -0.45352798
B16: Germany | C16: 102.5 | D16: 91.8 | E16: 84.2 | F16: 94.8 | G16: =SUM(C16:F16) -> 373.3 | H16: 104.6 | I16: 74.7 | J16: 75.9 | K16: 64 | L16: =SUM(H16:K16) -> 319.2 | M16: 83.3 | N16: 72.7 | O16: 60.1 | P16: 60.3 | Q16: =SUM(M16:P16) -> 276.4 | R16: 66.5 | S16: 60.9 | T16: 71.4 | U16: 60.1 | V16: =SUM(R16:U16) -> 258.9 | W16: 83.3 | X16: 64.8 | AA16: =SUM(W16:Z16) -> 148.1
B17: Growth % | H17: =(H16-C16)/C16 -> 0.020487805 | I17: =(I16-D16)/D16 -> -0.18627451 | J17: =(J16-E16)/E16 -> -0.098574822 | K17: =(K16-F16)/F16 -> -0.32489451 | L17: =(L16-G16)/G16 -> -0.14492365 | M17: =(M16-H16)/H16 -> -0.20363289 | N17: =(N16-I16)/I16 -> -0.026773762 | O17: =(O16-J16)/J16 -> -0.20816864 | ... T17: =(T16-O16)/O16 -> 0.18801997 | U17: 0.475 | V17: =(V16-Q16)/Q16 -> -0.063314038 | W17: =(W16-R16)/R16 -> 0.25263158 | X17: =(X16-S16)/S16 -> 0.064039409 | Y17: =(Y16-T16)/T16 -> -1 | Z17: =(Z16-U16)/U16 -> -1 | AA17: =(AA16-V16)/V16 -> -0.42796447
B18: Other European countries | C18: 136.1 | D18: 111.6 | E18: 117.1 | F18: 130.6 | G18: =SUM(C18:F18) -> 495.4 | H18: 169.5 | I18: 152.1 | J18: 135 | K18: 134.7 | L18: =SUM(H18:K18) -> 591.3 | M18: 134.8 | N18: 112.8 | O18: 102.6 | P18: 96.2 | Q18: =SUM(M18:P18) -> 446.4 | R18: 123.3 | S18: 126.8 | T18: 109 | U18: 109.8 | V18: =SUM(R18:U18) -> 468.9 | W18: 133 | X18: 126.7 | AA18: =SUM(W18:Z18) -> 259.7
B19: Growth % | H19: =(H18-C18)/C18 -> 0.24540779 | I19: =(I18-D18)/D18 -> 0.36290323 | J19: =(J18-E18)/E18 -> 0.1528608 | K19: =(K18-F18)/F18 -> 0.031393568 | L19: =(L18-G18)/G18 -> 0.19358094 | M19: =(M18-H18)/H18 -> -0.20471976 | N19: =(N18-I18)/I18 -> -0.25838264 | O19: =(O18-J18)/J18 -> -0.24 | ... AA19: =(AA18-V18)/V18 -> -0.44615057
B20: US | C20: 34.4 | D20: 24.1 | E20: 33 | F20: 45.4 | G20: =SUM(C20:F20) -> 136.9 | H20: 43.8 | I20: 33.3 | J20: 33.4 | K20: 49 | L20: =SUM(H20:K20) -> 159.5 | M20: 39.4 | N20: 26.7 | O20: 33 | P20: 55.2 | Q20: =SUM(M20:P20) -> 154.3 | R20: 43.5 | S20: 41.8 | T20: 44.6 | U20: 47.5 | V20: =SUM(R20:U20) -> 177.4 | W20: 37.9 | X20: 29 | AA20: =SUM(W20:Z20) -> 66.9
B21: Growth % | H21: =(H20-C20)/C20 -> 0.27325581 | I21: =(I20-D20)/D20 -> 0.38174274 | J21: =(J20-E20)/E20 -> 0.012121212 | K21: =(K20-F20)/F20 -> 0.079295154 | L21: =(L20-G20)/G20 -> 0.165084 | M21: =(M20-H20)/H20 -> -0.10045662 | N21: =(N20-I20)/I20 -> -0.1981982 | O21: =(O20-J20)/J20 -> -0.011976048 | ... AA21: =(AA20-V20)/V20 -> -0.62288613
B22: Rest of North America | C22: 2.6 | D22: 2.4 | E22: 3 | F22: 3.5 | G22: =SUM(C22:F22) -> 11.5 | H22: 3.3 | I22: 5.6 | J22: 6.7 | K22: 5.5 | L22: =SUM(H22:K22) -> 21.1 | M22: 5.5 | N22: 3.7 | O22: 4.4 | P22: 3.4 | Q22: =SUM(M22:P22) -> 17 | R22: 2.1 | S22: 1.1 | T22: 1.8 | U22: 2.4 | V22: =SUM(R22:U22) -> 7.4 | W22: 1.6 | X22: 1.1 | AA22: =SUM(W22:Z22) -> 2.7
B23: Growth % | H23: =(H22-C22)/C22 -> 0.26923077 | I23: =(I22-D22)/D22 -> 1.3333333 | J23: =(J22-E22)/E22 -> 1.2333333 | K23: =(K22-F22)/F22 -> 0.57142857 | L23: =(L22-G22)/G22 -> 0.83478261 | M23: =(M22-H22)/H22 -> 0.66666667 | N23: =(N22-I22)/I22 -> -0.33928571 | O23: =(O22-J22)/J22 -> -0.34328358 | ... AA23: =(AA22-V22)/V22 -> -0.63513514
B24: Australia/New Zealand | C24: 21.4 | D24: 24.5 | E24: 19 | F24: 40.3 | G24: =SUM(C24:F24) -> 105.2 | H24: 24.7 | I24: 31.9 | J24: 29.7 | K24: 26.3 | L24: =SUM(H24:K24) -> 112.6 | M24: 27.2 | N24: 38.7 | O24: 23.6 | P24: 26.3 | Q24: =SUM(M24:P24) -> 115.8 | R24: 44.3 | S24: 32.4 | T24: 19.2 | U24: 34.2 | V24: =SUM(R24:U24) -> 130.1 | W24: 34.2 | X24: 40.4 | AA24: =SUM(W24:Z24) -> 74.6
B25: Growth % | H25: =(H24-C24)/C24 -> 0.15420561 | I25: =(I24-D24)/D24 -> 0.30204082 | J25: =(J24-E24)/E24 -> 0.56315789 | K25: =(K24-F24)/F24 -> -0.34739454 | L25: =(L24-G24)/G24 -> 0.070342205 | M25: =(M24-H24)/H24 -> 0.10121457 | N25: =(N24-I24)/I24 -> 0.21316614 | O25: =(O24-J24)/J24 -> -0.20538721 | ... AA25: =(AA24-V24)/V24 -> -0.42659493
B26: China | C26: 0.1 | D26: 1.9 | E26: 1.2 | F26: 1.7 | G26: =SUM(C26:F26) -> 4.9 | H26: 0.2 | I26: 0 | J26: 0 | K26: 0.1 | L26: =SUM(H26:K26) -> 0.3 | M26: 0 | N26: 6.1 | O26: 12 | P26: 11.3 | Q26: =SUM(M26:P26) -> 29.4 | R26: 7.5 | S26: 18 | T26: 0.2 | U26: 0.4 | V26: =SUM(R26:U26) -> 26.1 | W26: 0.1 | X26: 0.6 | AA26: =SUM(W26:Z26) -> 0.7
B27: Growth % | H27: =(H26-C26)/C26 -> 1 | I27: =(I26-D26)/D26 -> -1 | J27: =(J26-E27)/E27 -> #DIV/0! | K27: =(K26-F26)/F26 -> -0.94117647 | L27: =(L26-G26)/G26 -> -0.93877551 | M27: =(M26-H26)/H26 -> -1 | N27: =(N26-I26)/I26 -> #DIV/0! | O27: =(O26-J26)/J26 -> #DIV/0! | P27: =(P26-K26)/K26 -> 112 | Q27: =(Q26-L26)/L26 -> 97 | R27: =(R26-M26)/M26 -> #DIV/0! | ... AA27: =(AA26-V26)/V26 -> -0.97318008
B28: Rest of world | C28: 9.4 | D28: 10.4 | E28: 7.7 | F28: 8.7 | G28: =SUM(C28:F28) -> 36.2 | H28: 5.1 | I28: 10 | J28: 8.8 | K28: 10.4 | L28: =SUM(H28:K28) -> 34.3 | M28: 6.5 | N28: 9.4 | O28: 8.7 | P28: 3.5 | Q28: =SUM(M28:P28) -> 28.1 | R28: 6 | S28: 6 | T28: 7.7 | U28: 5.5 | V28: =SUM(R28:U28) -> 25.2 | W28: 6.4 | X28: 10.4 | AA28: =SUM(W28:Z28) -> 16.8
B29: Growth % | H29: =(H28-C28)/C28 -> -0.45744681 | I29: =(I28-D28)/D28 -> -0.038461538 | J29: =(J28-E28)/E28 -> 0.14285714 | K29: =(K28-F28)/F28 -> 0.1954023 | L29: =(L28-G28)/G28 -> -0.052486188 | M29: =(M28-H28)/H28 -> 0.2745098 | N29: =(N28-I28)/I28 -> -0.06 | O29: =(O28-J28)/J28 -> -0.011363636 | ... AA29: =(AA28-V28)/V28 -> -0.33333333
B30: Truck and Trailer | C30: =C12+C14+C16+C18+C20+C22+C24+C26+C28 -> 434.8 | D30: =D12+D14+D16+D18+D20+D22+D24+D26+D28 -> 388.3 | E30: =E12+E14+E16+E18+E20+E22+E24+E26+E28 -> 362.5 | F30: =F12+F14+F16+F18+F20+F22+F24+F26+F28 -> 443.2 | G30: =SUM(C30:F30) -> 1628.8 | H30: =H12+H14+H16+H18+H20+H22+H24+H26+H28 -> 495.8 | I30: =I12+I14+I16+I18+I20+I22+I24+I26+I28 -> 437.8 | J30: =J12+J14+J16+J18+J20+J22+J24+J26+J28 -> 381.6 | K30: =K12+K14+K16+K18+K20+K22+K24+K26+K28 -> 412.4 | L30: =SUM(H30:K30) -> 1727.6 | M30: =M12+M14+M16+M18+M20+M22+M24+M26+M28 -> 439 | N30: =N12+N14+N16+N18+N20+N22+N24+N26+N28 -> 390.5 | O30: =O12+O14+O16+O18+O20+O22+O24+O26+O28 -> 340.6 | P30: =P12+P14+P16+P18+P20+P22+P24+P26+P28 -> 367 | Q30: =SUM(M30:P30) -> 1537.1 | R30: =R12+R14+R16+R18+R20+R22+R24+R26+R28 -> 433.2 | S30: =S12+S14+S16+S18+S20+S22+S24+S26+S28 -> 400 | T30: =T12+T14+T16+T18+T20+T22+T24+T26+T28 -> 369.9 | U30: =U12+U14+U16+U18+U20+U22+U24+U26+U28 -> 405.6 | V30: =SUM(R30:U30) -> 1608.7 | W30: =W12+W14+W16+W18+W20+W22+W24+W26+W28 -> 447.5 | X30: =X12+X14+X16+X18+X20+X22+X24+X26+X28 -> 412.1 | Y30: =Y12+Y14+Y16+Y18+Y20+Y22+Y24+Y26+Y28 -> 0 | Z30: =Z12+Z14+Z16+Z18+Z20+Z22+Z24+Z26+Z28 -> 0 | AA30: =SUM(W30:Z30) -> 859.6

Sheet Mobile thermal sol
B3: SEK million | C3: Q122 | D3: Q222 | E3: Q322 | F3: Q422 | G3: 2022 | H3: Q123 | I3: Q223 | J3: Q323 | K3: Q423 | L3: 2023 | M3: Q124 | N3: Q224 | O3: Q324 | P3: Q424 | Q3: 2024 | R3: Q125 | S3: Q225 | T3: Q325 | U3: Q425 | V3: 2025 | W3: Q126 | X3: Q226 | Y3: Q326 | Z3: Q426 | AA3: 2026
B4: Mobile Thermal sol
B5: Revenue | C5: 552 | D5: 574.6 | E5: 549.1 | F5: 558.8 | G5: =SUM(C5:F5) -> 2234.5 | H5: 710.8 | I5: 820.4 | J5: 835.7 | K5: 794.8 | L5: =SUM(H5:K5) -> 3161.7 | M5: 854.8 | N5: 847.5 | O5: 706.3 | P5: 635.8 | Q5: =SUM(M5:P5) -> 3044.4 | R5: 703.6 | S5: 731.8 | T5: 718.3 | U5: 640.6 | V5: =SUM(R5:U5) -> 2794.3 | W5: 671.1 | X5: 782.9 | AA5: =SUM(W5:Z5) -> 1454
B6: Growth % | H6: =(H5-C5)/C5 -> 0.28768116 | I6: =(I5-D5)/D5 -> 0.42777584 | J6: =(J5-E5)/E5 -> 0.521945 | K6: =(K5-F5)/F5 -> 0.42233357 | L6: =(L5-G5)/G5 -> 0.41494742 | M6: =(M5-H5)/H5 -> 0.20258863 | N6: =(N5-I5)/I5 -> 0.033032667 | O6: =(O5-J5)/J5 -> -0.15484025 | ... AA6: =(AA5-V5)/V5 -> -0.47965501
B7: EBITDA | C7: 54.1 | D7: 62.8 | E7: 67.4 | F7: 28.3 | G7: =SUM(C7:F7) -> 212.6 | H7: 90 | I7: 116.3 | J7: 123 | K7: 108.9 | L7: =SUM(H7:K7) -> 438.2 | M7: 140 | N7: 134.1 | O7: 108.2 | P7: 75.5 | Q7: =SUM(M7:P7) -> 457.8 | R7: 90.4 | S7: 99.3 | T7: 85 | U7: 61.4 | V7: =SUM(R7:U7) -> 336.1 | W7: 72.1 | X7: 71.8 | AA7: =SUM(W7:Z7) -> 143.9
B8: EBITA | C8: 47.3 | D8: 56.9 | E8: 42.2 | F8: 12 | G8: =SUM(C8:F8) -> 158.4 | H8: 74.6 | I8: 100.6 | J8: 106.7 | K8: 109.2 | L8: =SUM(H8:K8) -> 391.1 | M8: 129.6 | N8: 121.2 | O8: 96.4 | P8: 63 | Q8: =SUM(M8:P8) -> 410.2 | R8: 77.6 | S8: 86 | T8: 76.3 | U8: 40.6 | V8: =SUM(R8:U8) -> 280.5 | W8: 58.2 | X8: 58.1 | AA8: =SUM(W8:Z8) -> 116.3
B9: EBITA margin % | C9: 0.086 | D9: 0.099 | E9: 0.077 | F9: 0.021 | G9: =G8/G5 -> 0.070888342 | H9: 0.105 | I9: 0.123 | J9: 0.128 | K9: 0.137 | L9: =L8/L5 -> 0.12369928 | M9: 0.152 | N9: 0.143 | O9: 0.136 | P9: 0.099 | Q9: =Q8/Q5 -> 0.13473919 | R9: 0.11 | S9: 0.117 | T9: 0.106 | U9: 0.063 | V9: =V8/V5 -> 0.10038292 | W9: 0.087 | X9: 0.074 | AA9: =AA8/AA5 -> 0.079986245
B10: EBIT | C10: 42.2 | D10: 51.8 | E10: 37.1 | F10: 6.7 | G10: =SUM(C10:F10) -> 137.8 | H10: 69.5 | I10: 95.2 | J10: 101.2 | K10: 103.7 | L10: =SUM(H10:K10) -> 369.6 | M10: 124.3 | N10: 116.1 | O10: 91.4 | P10: 58 | Q10: =SUM(M10:P10) -> 389.8 | R10: 72.6 | S10: 81 | T10: 69.4 | U10: 33.7 | V10: =SUM(R10:U10) -> 256.7 | W10: 51.3 | X10: 51.1 | AA10: =SUM(W10:Z10) -> 102.4
B11: EBIT margin | C11: 0.076 | D11: 0.09 | E11: 0.068 | F11: 0.012 | G11: =G10/G5 -> 0.061669277 | H11: 0.098 | I11: 0.116 | J11: 0.121 | K11: 0.131 | L11: =L10/L5 -> 0.11689914 | M11: 0.145 | N11: 0.137 | O11: 0.129 | P11: 0.091 | Q11: =Q10/Q5 -> 0.12803837 | R11: 0.103 | S11: 0.111 | T11: 0.097 | U11: 0.053 | V11: =V10/V5 -> 0.091865584 | W11: 0.076 | X11: 0.065 | AA11: =AA10/AA5 -> 0.07042641
B12: Sweden | C12: 11 | D12: 13.4 | E12: 11.6 | F12: 12.7 | G12: =SUM(C12:F12) -> 48.7 | H12: 15 | I12: 11.5 | J12: 9.5 | K12: 11.9 | L12: =SUM(H12:K12) -> 47.9 | M12: 13 | N12: 11.9 | O12: 9.9 | P12: 11.8 | Q12: =SUM(M12:P12) -> 46.6 | R12: 13.4 | S12: 11.8 | T12: 10.2 | U12: 12.2 | V12: =SUM(R12:U12) -> 47.6 | W12: 13.1 | X12: 15.6 | AA12: =SUM(W12:Z12) -> 28.7
B13: Growth % | H13: =(H12-C12)/C12 -> 0.36363636 | I13: =(I12-D12)/D12 -> -0.14179104 | J13: =(J12-E12)/E12 -> -0.18103448 | K13: =(K12-F12)/F12 -> -0.062992126 | L13: =(L12-G12)/G12 -> -0.016427105 | M13: =(M12-H12)/H12 -> -0.13333333 | N13: =(N12-I12)/I12 -> 0.034782609 | O13: =(O12-J12)/J12 -> 0.042105263 | ... AA13: =(AA12-V12)/V12 -> -0.39705882
B14: Other Nordic countries | C14: 12.9 | D14: 13.3 | E14: 14.2 | F14: 10.3 | G14: =SUM(C14:F14) -> 50.7 | H14: 13.3 | I14: 12.9 | J14: 12.6 | K14: 11.6 | L14: =SUM(H14:K14) -> 50.4 | M14: 11.5 | N14: 11.5 | O14: 12.5 | P14: 15 | Q14: =SUM(M14:P14) -> 50.5 | R14: 14 | S14: 13.7 | T14: 12.3 | U14: 13.7 | V14: =SUM(R14:U14) -> 53.7 | W14: 13.9 | X14: 14.8 | AA14: =SUM(W14:Z14) -> 28.7
B15: Growth % | H15: =(H14-C14)/C14 -> 0.031007752 | I15: =(I14-D14)/D14 -> -0.030075188 | J15: =(J14-E14)/E14 -> -0.11267606 | K15: =(K14-F14)/F14 -> 0.12621359 | L15: =(L14-G14)/G14 -> -0.0059171598 | M15: =(M14-H14)/H14 -> -0.13533835 | N15: =(N14-I14)/I14 -> -0.10852713 | O15: =(O14-J14)/J14 -> -0.0079365079 | ... AA15: =(AA14-V14)/V14 -> -0.46554935
B16: Germany | C16: 6.8 | D16: 7.5 | E16: 6.4 | F16: 5.2 | G16: =SUM(C16:F16) -> 25.9 | H16: 9 | I16: 9.2 | J16: 8.2 | K16: 8.1 | L16: =SUM(H16:K16) -> 34.5 | M16: 15.3 | N16: 11.3 | O16: 9.6 | P16: 10.9 | Q16: =SUM(M16:P16) -> 47.1 | R16: 11.1 | S16: 10.2 | T16: 7.1 | U16: 7.4 | V16: =SUM(R16:U16) -> 35.8 | W16: 7 | X16: 8.9 | AA16: =SUM(W16:Z16) -> 15.9
B17: Growth % | H17: =(H16-C16)/C16 -> 0.32352941 | I17: =(I16-D16)/D16 -> 0.22666667 | J17: =(J16-E16)/E16 -> 0.28125 | K17: =(K16-F16)/F16 -> 0.55769231 | L17: =(L16-G16)/G16 -> 0.33204633 | M17: =(M16-H16)/H16 -> 0.7 | N17: =(N16-I16)/I16 -> 0.22826087 | O17: =(O16-J16)/J16 -> 0.17073171 | ... AA17: =(AA16-V16)/V16 -> -0.55586592
B18: Other European countries | C18: 52 | D18: 55.7 | E18: 44.9 | F18: 51.7 | G18: =SUM(C18:F18) -> 204.3 | H18: 59.6 | I18: 60.7 | J18: 53.6 | K18: 52.7 | L18: =SUM(H18:K18) -> 226.6 | M18: 57.9 | N18: 59.3 | O18: 47 | P18: 44.4 | Q18: =SUM(M18:P18) -> 208.6 | R18: 45.2 | S18: 50.1 | T18: 47.3 | U18: 39.3 | V18: =SUM(R18:U18) -> 181.9 | W18: 51.3 | X18: 52.1 | AA18: =SUM(W18:Z18) -> 103.4
B19: Growth % | H19: =(H18-C18)/C18 -> 0.14615385 | I19: =(I18-D18)/D18 -> 0.089766607 | J19: =(J18-E18)/E18 -> 0.19376392 | K19: =(K18-F18)/F18 -> 0.01934236 | L19: =(L18-G18)/G18 -> 0.10915321 | M19: =(M18-H18)/H18 -> -0.02852349 | N19: =(N18-I18)/I18 -> -0.02306425 | O19: =(O18-J18)/J18 -> -0.12313433 | ... AA19: =(AA18-V18)/V18 -> -0.4315558
B20: US | C20: 373.8 | D20: 386.8 | E20: 365.2 | F20: 388.6 | G20: =SUM(C20:F20) -> 1514.4 | H20: 478.1 | I20: 560.9 | J20: 585.7 | K20: 565.9 | L20: =SUM(H20:K20) -> 2190.6 | M20: 569.9 | N20: 558.9 | O20: 449 | P20: 398.6 | Q20: =SUM(M20:P20) -> 1976.4 | R20: 447 | S20: 418.8 | T20: 436.1 | U20: 378.1 | V20: =SUM(R20:U20) -> 1680 | W20: 385.7 | X20: 467.4 | AA20: =SUM(W20:Z20) -> 853.1
B21: Growth % | H21: =(H20-C20)/C20 -> 0.27902622 | I21: =(I20-D20)/D20 -> 0.45010341 | J21: =(J20-E20)/E20 -> 0.60377875 | K21: =(K20-F20)/F20 -> 0.45625322 | L21: =(L20-G20)/G20 -> 0.44651347 | M21: =(M20-H20)/H20 -> 0.19201004 | N21: =(N20-I20)/I20 -> -0.003565698 | O21: =(O20-J20)/J20 -> -0.23339594 | ... AA21: =(AA20-V20)/V20 -> -0.49220238
B22: Rest of North America | C22: 85.4 | D22: 86.8 | E22: 96.7 | F22: 80.6 | G22: =SUM(C22:F22) -> 349.5 | H22: 126.1 | I22: 150.8 | J22: 150.8 | K22: 132.4 | L22: =SUM(H22:K22) -> 560.1 | M22: 173.3 | N22: 184.3 | O22: 164.2 | P22: 140.9 | Q22: =SUM(M22:P22) -> 662.7 | R22: 137 | S22: 182.7 | T22: 159.1 | U22: 151.5 | V22: =SUM(R22:U22) -> 630.3 | W22: 161.4 | X22: 180 | AA22: =SUM(W22:Z22) -> 341.4
B23: Growth % | H23: =(H22-C22)/C22 -> 0.4765808 | I23: =(I22-D22)/D22 -> 0.73732719 | J23: =(J22-E22)/E22 -> 0.55946225 | K23: =(K22-F22)/F22 -> 0.6426799 | L23: =(L22-G22)/G22 -> 0.60257511 | M23: =(M22-H22)/H22 -> 0.37430611 | N23: =(N22-I22)/I22 -> 0.22214854 | O23: =(O22-J22)/J22 -> 0.088859416 | ... AA23: =(AA22-V22)/V22 -> -0.45835317
B24: China | C24: 5.8 | D24: 4.7 | E24: 5.7 | F24: 5 | G24: =SUM(C24:F24) -> 21.2 | H24: 5 | I24: 7.6 | J24: 8.2 | K24: 6.8 | L24: =SUM(H24:K24) -> 27.6 | M24: 7.6 | N24: 6.1 | O24: 9.2 | P24: 8 | Q24: =SUM(M24:P24) -> 30.9 | R24: 6.3 | S24: 6.5 | T24: 5.9 | U24: 6.6 | V24: =SUM(R24:U24) -> 25.3 | W24: 4.6 | X24: 9.7 | AA24: =SUM(W24:Z24) -> 14.3
B25: Growth % | H25: =(H24-C24)/C24 -> -0.13793103 | I25: =(I24-D24)/D24 -> 0.61702128 | J25: =(J24-E24)/E24 -> 0.43859649 | K25: =(K24-F24)/F24 -> 0.36 | L25: =(L24-G24)/G24 -> 0.30188679 | M25: =(M24-H24)/H24 -> 0.52 | N25: =(N24-I24)/I24 -> -0.19736842 | O25: =(O24-J24)/J24 -> 0.12195122 | ... AA25: =(AA24-V24)/V24 -> -0.43478261
B26: Rest of world | C26: 4.3 | D26: 6.3 | E26: 4.4 | F26: 4.5 | G26: =SUM(C26:F26) -> 19.5 | H26: 4.6 | I26: 6.9 | J26: 7.1 | K26: 5.5 | L26: =SUM(H26:K26) -> 24.1 | M26: 6.5 | N26: 4.2 | O26: 5 | P26: 6.2 | Q26: =SUM(M26:P26) -> 21.9 | R26: 29.5 | S26: 38 | T26: 40.1 | U26: 31.7 | V26: =SUM(R26:U26) -> 139.3 | W26: 34 | X26: 34.4 | AA26: =SUM(W26:Z26) -> 68.4
B27: Growth % | H27: =(H26-C26)/C26 -> 0.069767442 | I27: =(I26-D26)/D26 -> 0.095238095 | J27: =(J26-E26)/E26 -> 0.61363636 | K27: =(K26-F26)/F26 -> 0.22222222 | L27: =(L26-G26)/G26 -> 0.23589744 | M27: =(M26-H26)/H26 -> 0.41304348 | N27: =(N26-I26)/I26 -> -0.39130435 | O27: =(O26-J26)/J26 -> -0.29577465 | ... AA27: =(AA26-V26)/V26 -> -0.50897344
B28: Mobile Thermal sol | C28: =C12+C14+C16+C18+C20+C22+C24+C26 -> 552 | D28: =D12+D14+D16+D18+D20+D22+D24+D26 -> 574.5 | E28: =E12+E14+E16+E18+E20+E22+E24+E26 -> 549.1 | F28: =F12+F14+F16+F18+F20+F22+F24+F26 -> 558.6 | G28: =SUM(C28:F28) -> 2234.2 | H28: =H12+H14+H16+H18+H20+H22+H24+H26 -> 710.7 | I28: =I12+I14+I16+I18+I20+I22+I24+I26 -> 820.5 | J28: =J12+J14+J16+J18+J20+J22+J24+J26 -> 835.7 | K28: =K12+K14+K16+K18+K20+K22+K24+K26 -> 794.9 | L28: =SUM(H28:K28) -> 3161.8 | M28: =M12+M14+M16+M18+M20+M22+M24+M26 -> 855 | N28: =N12+N14+N16+N18+N20+N22+N24+N26 -> 847.5 | O28: =O12+O14+O16+O18+O20+O22+O24+O26 -> 706.4 | P28: =P12+P14+P16+P18+P20+P22+P24+P26 -> 635.8 | Q28: =SUM(M28:P28) -> 3044.7 | R28: =R12+R14+R16+R18+R20+R22+R24+R26 -> 703.5 | S28: =S12+S14+S16+S18+S20+S22+S24+S26 -> 731.8 | T28: =T12+T14+T16+T18+T20+T22+T24+T26 -> 718.1 | U28: =U12+U14+U16+U18+U20+U22+U24+U26 -> 640.5 | V28: =SUM(R28:U28) -> 2793.9 | W28: =W12+W14+W16+W18+W20+W22+W24+W26 -> 671 | X28: =X12+X14+X16+X18+X20+X22+X24+X26 -> 782.9 | Y28: =Y12+Y14+Y16+Y18+Y20+Y22+Y24+Y26 -> 0 | Z28: =Z12+Z14+Z16+Z18+Z20+Z22+Z24+Z26 -> 0 | AA28: =SUM(W28:Z28) -> 1453.9

Sheet Ringfender power trans
B3: SEK million | C3: Q122 | D3: Q222 | E3: Q322 | F3: Q422 | G3: 2022 | H3: Q123 | I3: Q223 | J3: Q323 | K3: Q423 | L3: 2023 | M3: Q124 | N3: Q224 | O3: Q324 | P3: Q424 | Q3: 2024 | R3: Q125 | S3: Q225 | T3: Q325 | U3: Q425 | V3: 2025 | W3: Q126 | X3: Q226 | Y3: Q326 | Z3: Q426 | AA3: 2026
B4: Mobile Thermal sol
B5: Revenue | C5: 168.9 | D5: 178.3 | E5: 180 | F5: 189.5 | G5: =SUM(C5:F5) -> 716.7 | H5: 193.4 | I5: 191.9 | J5: 222.4 | K5: 242.7 | L5: =SUM(H5:K5) -> 850.4 | M5: 241.7 | N5: 255.8 | O5: 225.9 | P5: 273.9 | Q5: =SUM(M5:P5) -> 997.3 | R5: 214.5 | S5: 230.9 | T5: 279.5 | U5: 266.3 | V5: =SUM(R5:U5) -> 991.2 | W5: 257.7 | X5: 285.2 | AA5: =SUM(W5:Z5) -> 542.9
B6: Growth % | H6: =(H5-C5)/C5 -> 0.14505625 | I6: =(I5-D5)/D5 -> 0.076275939 | J6: =(J5-E5)/E5 -> 0.23555556 | K6: =(K5-F5)/F5 -> 0.28073879 | L6: =(L5-G5)/G5 -> 0.18654946 | M6: =(M5-H5)/H5 -> 0.24974147 | N6: =(N5-I5)/I5 -> 0.33298593 | O6: =(O5-J5)/J5 -> 0.01573741 | ... AA6: =(AA5-V5)/V5 -> -0.45228006
B7: EBITDA | C7: 31.3 | D7: 29.6 | E7: 24.8 | F7: 44.1 | G7: =SUM(C7:F7) -> 129.8 | H7: 27.6 | I7: 36.2 | J7: 45 | K7: 38.2 | L7: =SUM(H7:K7) -> 147 | M7: 39.5 | N7: 46 | O7: 32.2 | P7: 61.9 | Q7: =SUM(M7:P7) -> 179.6 | R7: 21.2 | S7: 39.5 | T7: 41.1 | U7: 66.6 | V7: =SUM(R7:U7) -> 168.4 | W7: 36.7 | X7: 26.2 | AA7: =SUM(W7:Z7) -> 62.9
B8: EBITA | C8: 27.2 | D8: 25.6 | E8: 21.2 | F8: 39.8 | G8: =SUM(C8:F8) -> 113.8 | H8: 22.5 | I8: 31.3 | J8: 40 | K8: 31.6 | L8: =SUM(H8:K8) -> 125.4 | M8: 35.3 | N8: 39.6 | O8: 27.1 | P8: 54.9 | Q8: =SUM(M8:P8) -> 156.9 | R8: 13.8 | S8: 32.6 | T8: 35.6 | U8: 58 | V8: =SUM(R8:U8) -> 140 | W8: 28.9 | X8: 17.7 | AA8: =SUM(W8:Z8) -> 46.6
B9: EBITA margin % | C9: 0.161 | D9: 0.144 | E9: 0.118 | F9: 0.21 | G9: =G8/G5 -> 0.15878331 | H9: 0.116 | I9: 0.163 | J9: 0.18 | K9: 0.13 | L9: =L8/L5 -> 0.14746002 | M9: 0.146 | N9: 0.155 | O9: 0.12 | P9: 0.2 | Q9: =Q8/Q5 -> 0.15732478 | R9: 0.064 | S9: 0.141 | T9: 0.127 | U9: 0.218 | V9: =V8/V5 -> 0.14124294 | W9: 0.112 | X9: 0.062 | AA9: =AA8/AA5 -> 0.085835329
B10: EBIT | C10: 25.8 | D10: 24.1 | E10: 20.5 | F10: 38.7 | G10: =SUM(C10:F10) -> 109.1 | H10: 21.1 | I10: 29.9 | J10: 38.6 | K10: 30.1 | L10: =SUM(H10:K10) -> 119.7 | M10: 34.2 | N10: 38.5 | O10: 26.1 | P10: 38.2 | Q10: =SUM(M10:P10) -> 137 | R10: 9 | S10: 28.1 | T10: 31.1 | U10: 53.4 | V10: =SUM(R10:U10) -> 121.6 | W10: 24.5 | X10: 13 | AA10: =SUM(W10:Z10) -> 37.5
B11: EBIT margin | C11: 0.153 | D11: 0.135 | E11: 0.114 | F11: 0.204 | G11: =G10/G5 -> 0.15222548 | H11: 0.109 | I11: 0.156 | J11: 0.173 | K11: 0.124 | L11: =L10/L5 -> 0.14075729 | M11: 0.141 | N11: 0.15 | O11: 0.115 | P11: 0.14 | Q11: =Q10/Q5 -> 0.1373709 | R11: 0.042 | S11: 0.122 | T11: 0.111 | U11: 0.201 | V11: =V10/V5 -> 0.12267958 | W11: 0.095 | X11: 0.047 | AA11: =AA10/AA5 -> 0.069073494
B12: Sweden | C12: 0.9 | D12: 1.2 | E12: 1.1 | F12: 0.9 | G12: =SUM(C12:F12) -> 4.1 | H12: 1 | I12: 1 | J12: 0.8 | K12: 1.3 | L12: =SUM(H12:K12) -> 4.1 | M12: 1.1 | N12: 1.1 | O12: 1.2 | P12: 1.5 | Q12: =SUM(M12:P12) -> 4.9 | R12: 1.3 | S12: 1.7 | T12: 1 | U12: 1.8 | V12: =SUM(R12:U12) -> 5.8 | W12: 1.3 | X12: 2.1 | AA12: =SUM(W12:Z12) -> 3.4
B13: Growth % | H13: =(H12-C12)/C12 -> 0.11111111 | I13: =(I12-D12)/D12 -> -0.16666667 | J13: =(J12-E12)/E12 -> -0.27272727 | K13: =(K12-F12)/F12 -> 0.44444444 | L13: =(L12-G12)/G12 -> -2.1662888e-16 | M13: =(M12-H12)/H12 -> 0.1 | N13: =(N12-I12)/I12 -> 0.1 | O13: =(O12-J12)/J12 -> 0.5 | ... AA13: =(AA12-V12)/V12 -> -0.4137931
B14: Other Nordic countries | C14: 0.7 | D14: 0.7 | E14: 0.9 | F14: 0.9 | G14: =SUM(C14:F14) -> 3.2 | H14: 1.5 | I14: 0.8 | J14: 1.1 | K14: 1.3 | L14: =SUM(H14:K14) -> 4.7 | M14: 1.3 | N14: 0.9 | O14: 1.3 | P14: 1 | Q14: =SUM(M14:P14) -> 4.5 | R14: 0.9 | S14: 0.2 | T14: 3 | U14: 1.7 | V14: =SUM(R14:U14) -> 5.8 | W14: 2.6 | X14: 1.8 | AA14: =SUM(W14:Z14) -> 4.4
B15: Growth % | H15: =(H14-C14)/C14 -> 1.1428571 | I15: =(I14-D14)/D14 -> 0.14285714 | J15: =(J14-E14)/E14 -> 0.22222222 | K15: =(K14-F14)/F14 -> 0.44444444 | L15: =(L14-G14)/G14 -> 0.46875 | M15: =(M14-H14)/H14 -> -0.13333333 | N15: =(N14-I14)/I14 -> 0.125 | O15: =(O14-J14)/J14 -> 0.18181818 | ... AA15: =(AA14-V14)/V14 -> -0.24137931
B16: Germany | C16: 50.7 | D16: 46.6 | E16: 46.3 | F16: 46.5 | G16: =SUM(C16:F16) -> 190.1 | H16: 51.8 | I16: 49.3 | J16: 48.8 | K16: 49.2 | L16: =SUM(H16:K16) -> 199.1 | M16: 55.9 | N16: 48.7 | O16: 42.5 | P16: 52.7 | Q16: =SUM(M16:P16) -> 199.8 | R16: 46.4 | S16: 43.4 | T16: 56.4 | U16: 45.7 | V16: =SUM(R16:U16) -> 191.9 | W16: 60.9 | X16: 62.8 | AA16: =SUM(W16:Z16) -> 123.7
B17: Growth % | H17: =(H16-C16)/C16 -> 0.021696252 | I17: =(I16-D16)/D16 -> 0.057939914 | J17: =(J16-E16)/E16 -> 0.05399568 | K17: =(K16-F16)/F16 -> 0.058064516 | L17: =(L16-G16)/G16 -> 0.047343503 | M17: =(M16-H16)/H16 -> 0.079150579 | N17: =(N16-I16)/I16 -> -0.012170385 | O17: =(O16-J16)/J16 -> -0.12909836 | ... AA17: =(AA16-V16)/V16 -> -0.35539343
B18: Other European countries | C18: 17.7 | D18: 19.1 | E18: 17.7 | F18: 27.8 | G18: =SUM(C18:F18) -> 82.3 | H18: 21.9 | I18: 24.7 | J18: 38.4 | K18: 46.5 | L18: =SUM(H18:K18) -> 131.5 | M18: 33.9 | N18: 43.9 | O18: 17.4 | P18: 36.8 | Q18: =SUM(M18:P18) -> 132 | R18: 21.8 | S18: 26.9 | T18: 21.3 | U18: 29 | V18: =SUM(R18:U18) -> 99 | W18: 26.9 | X18: 34.8 | AA18: =SUM(W18:Z18) -> 61.7
B19: Growth % | H19: =(H18-C18)/C18 -> 0.23728814 | I19: =(I18-D18)/D18 -> 0.29319372 | J19: =(J18-E18)/E18 -> 1.1694915 | K19: =(K18-F18)/F18 -> 0.67266187 | L19: =(L18-G18)/G18 -> 0.59781288 | M19: =(M18-H18)/H18 -> 0.54794521 | N19: =(N18-I18)/I18 -> 0.77732794 | O19: =(O18-J18)/J18 -> -0.546875 | ... AA19: =(AA18-V18)/V18 -> -0.37676768
B20: US | C20: 49.9 | D20: 47.9 | E20: 48.6 | F20: 42 | G20: =SUM(C20:F20) -> 188.4 | H20: 53.2 | I20: 48.9 | J20: 51.8 | K20: 49 | L20: =SUM(H20:K20) -> 202.9 | M20: 48.6 | N20: 51.7 | O20: 51.5 | P20: 70.5 | Q20: =SUM(M20:P20) -> 222.3 | R20: 48.4 | S20: 57.6 | T20: 66.1 | U20: 63.9 | V20: =SUM(R20:U20) -> 236 | W20: 55.7 | X20: 63.6 | AA20: =SUM(W20:Z20) -> 119.3
B21: Growth % | H21: =(H20-C20)/C20 -> 0.066132265 | I21: =(I20-D20)/D20 -> 0.020876827 | J21: =(J20-E20)/E20 -> 0.065843621 | K21: =(K20-F20)/F20 -> 0.16666667 | L21: =(L20-G20)/G20 -> 0.076963907 | M21: =(M20-H20)/H20 -> -0.086466165 | N21: =(N20-I20)/I20 -> 0.057259714 | O21: =(O20-J20)/J20 -> -0.0057915058 | ... AA21: =(AA20-V20)/V20 -> -0.49449153
B22: Rest of North America | C22: 1.4 | D22: 1.1 | E22: 1.3 | F22: 1.9 | G22: =SUM(C22:F22) -> 5.7 | H22: 2.7 | I22: 2.2 | J22: 2.3 | K22: 2.3 | L22: =SUM(H22:K22) -> 9.5 | M22: 1.4 | N22: 1.8 | O22: 2.2 | P22: 2.4 | Q22: =SUM(M22:P22) -> 7.8 | R22: 2.3 | S22: 2.8 | T22: 1.6 | U22: 5.7 | V22: =SUM(R22:U22) -> 12.4 | W22: 1.7 | X22: 4.1 | AA22: =SUM(W22:Z22) -> 5.8
B23: Growth % | H23: =(H22-C22)/C22 -> 0.92857143 | I23: =(I22-D22)/D22 -> 1 | J23: =(J22-E22)/E22 -> 0.76923077 | K23: =(K22-F22)/F22 -> 0.21052632 | L23: =(L22-G22)/G22 -> 0.66666667 | M23: =(M22-H22)/H22 -> -0.48148148 | N23: =(N22-I22)/I22 -> -0.18181818 | O23: =(O22-J22)/J22 -> -0.043478261 | ... AA23: =(AA22-V22)/V22 -> -0.53225806
B24: Brazil | C24: 21.1 | D24: 30.7 | E24: 28.4 | F24: 26.1 | G24: =SUM(C24:F24) -> 106.3 | H24: 27.3 | I24: 35.9 | J24: 38.3 | K24: 35.3 | L24: =SUM(H24:K24) -> 136.8 | M24: 31.1 | N24: 33.8 | O24: 32.2 | P24: 26 | Q24: =SUM(M24:P24) -> 123.1 | R24: 28.7 | S24: 33.8 | T24: 34.4 | U24: 31.4 | V24: =SUM(R24:U24) -> 128.3 | W24: 28.1 | X24: 33.8 | AA24: =SUM(W24:Z24) -> 61.9
B25: Growth % | H25: =(H24-C24)/C24 -> 0.29383886 | I25: =(I24-D24)/D24 -> 0.16938111 | J25: =(J24-E24)/E24 -> 0.34859155 | K25: =(K24-F24)/F24 -> 0.35249042 | L25: =(L24-G24)/G24 -> 0.2869238 | M25: =(M24-H24)/H24 -> 0.13919414 | N25: =(N24-I24)/I24 -> -0.058495822 | O25: =(O24-J24)/J24 -> -0.15926893 | ... AA25: =(AA24-V24)/V24 -> -0.51753702
B26: Australia/New Zealand | C26: 5.4 | D26: 4.1 | E26: 3.4 | F26: 4 | G26: =SUM(C26:F26) -> 16.9 | H26: 6.5 | I26: 3.3 | J26: 8.9 | K26: 8.9 | L26: =SUM(H26:K26) -> 27.6 | M26: 12.1 | N26: 14.3 | O26: 16.8 | P26: 23.8 | Q26: =SUM(M26:P26) -> 67 | R26: 12.9 | S26: 10.9 | T26: 14.3 | U26: 12.1 | V26: =SUM(R26:U26) -> 50.2 | W26: 10 | X26: 10.5 | AA26: =SUM(W26:Z26) -> 20.5
B27: Growth % | H27: =(H26-C26)/C26 -> 0.2037037 | I27: =(I26-D26)/D26 -> -0.19512195 | J27: =(J26-E26)/E26 -> 1.6176471 | K27: =(K26-F26)/F26 -> 1.225 | L27: =(L26-G26)/G26 -> 0.63313609 | M27: =(M26-H26)/H26 -> 0.86153846 | N27: =(N26-I26)/I26 -> 3.3333333 | O27: =(O26-J26)/J26 -> 0.88764045 | ... AA27: =(AA26-V26)/V26 -> -0.59163347
B28: China | C28: 4.9 | D28: 6.4 | E28: 13.6 | F28: 18.8 | G28: =SUM(C28:F28) -> 43.7 | H28: 5.4 | I28: 6.6 | J28: 10.4 | K28: 7.3 | L28: =SUM(H28:K28) -> 29.7 | M28: 5.4 | N28: 8.4 | O28: 6.3 | P28: 6.5 | Q28: =SUM(M28:P28) -> 26.6 | R28: 5.9 | S28: 6.2 | T28: 25.5 | U28: 15.4 | V28: =SUM(R28:U28) -> 53 | W28: 21 | X28: 11.4 | AA28: =SUM(W28:Z28) -> 32.4
B29: Growth % | H29: =(H28-C28)/C28 -> 0.10204082 | I29: =(I28-D28)/D28 -> 0.03125 | J29: =(J28-E28)/E28 -> -0.23529412 | K29: =(K28-F28)/F28 -> -0.61170213 | L29: =(L28-G28)/G28 -> -0.32036613 | M29: =(M28-H28)/H28 -> 0 | N29: =(N28-I28)/I28 -> 0.27272727 | O29: =(O28-J28)/J28 -> -0.39423077 | ... AA29: =(AA28-V28)/V28 -> -0.38867925
B30: Rest of world | C30: 16.1 | D30: 20.4 | E30: 18.7 | F30: 20.6 | G30: =SUM(C30:F30) -> 75.8 | H30: 22.2 | I30: 19.1 | J30: 21.5 | K30: 41.6 | L30: =SUM(H30:K30) -> 104.4 | M30: 51 | N30: 51.1 | O30: 54.6 | P30: 62.7 | Q30: =SUM(M30:P30) -> 219.4 | R30: 46 | S30: 47.3 | T30: 56 | U30: 59.7 | V30: =SUM(R30:U30) -> 209 | W30: 49.4 | X30: 60.3 | AA30: =SUM(W30:Z30) -> 109.7
B31: Growth % | H31: =(H30-C30)/C30 -> 0.37888199 | I31: =(I30-D30)/D30 -> -0.06372549 | J31: =(J30-E30)/E30 -> 0.14973262 | K31: =(K30-F30)/F30 -> 1.0194175 | L31: =(L30-G30)/G30 -> 0.37730871 | M31: =(M30-H30)/H30 -> 1.2972973 | N31: =(N30-I30)/I30 -> 1.6753927 | O31: =(O30-J30)/J30 -> 1.5395349 | ... AA31: =(AA30-V30)/V30 -> -0.47511962
B32: Group | C32: =C12+C14+C16+C18+C20+C22+C24+C26+C28+C30 -> 168.8 | D32: =D12+D14+D16+D18+D20+D22+D24+D26+D28+D30 -> 178.2 | E32: =E12+E14+E16+E18+E20+E22+E24+E26+E28+E30 -> 180 | F32: =F12+F14+F16+F18+F20+F22+F24+F26+F28+F30 -> 189.5 | G32: =SUM(C32:F32) -> 716.5 | H32: =H12+H14+H16+H18+H20+H22+H24+H26+H28+H30 -> 193.5 | I32: =I12+I14+I16+I18+I20+I22+I24+I26+I28+I30 -> 191.8 | J32: =J12+J14+J16+J18+J20+J22+J24+J26+J28+J30 -> 222.3 | K32: =K12+K14+K16+K18+K20+K22+K24+K26+K28+K30 -> 242.7 | L32: =SUM(H32:K32) -> 850.3 | M32: =M12+M14+M16+M18+M20+M22+M24+M26+M28+M30 -> 241.8 | N32: =N12+N14+N16+N18+N20+N22+N24+N26+N28+N30 -> 255.7 | O32: =O12+O14+O16+O18+O20+O22+O24+O26+O28+O30 -> 226 | P32: =P12+P14+P16+P18+P20+P22+P24+P26+P28+P30 -> 283.9 | Q32: =SUM(M32:P32) -> 1007.4 | R32: =R12+R14+R16+R18+R20+R22+R24+R26+R28+R30 -> 214.6 | S32: =S12+S14+S16+S18+S20+S22+S24+S26+S28+S30 -> 230.8 | T32: =T12+T14+T16+T18+T20+T22+T24+T26+T28+T30 -> 279.6 | U32: =U12+U14+U16+U18+U20+U22+U24+U26+U28+U30 -> 266.4 | V32: =SUM(R32:U32) -> 991.4 | W32: =W12+W14+W16+W18+W20+W22+W24+W26+W28+W30 -> 257.6 | X32: =X12+X14+X16+X18+X20+X22+X24+X26+X28+X30 -> 285.2 | Y32: =Y12+Y14+Y16+Y18+Y20+Y22+Y24+Y26+Y28+Y30 -> 0 | Z32: =Z12+Z14+Z16+Z18+Z20+Z22+Z24+Z26+Z28+Z30 -> 0 | AA32: =SUM(W32:Z32) -> 542.8

Sheet Land
B3: SEK million | C3: Q122 | D3: Q222 | E3: Q322 | F3: Q422 | G3: 2022 | H3: Q123 | I3: Q223 | J3: Q323 | K3: Q423 | L3: 2023 | M3: Q124 | N3: Q224 | O3: Q324 | P3: Q424 | Q3: 2024 | R3: Q125 | S3: Q225 | T3: Q325 | U3: Q425 | V3: 2025 | W3: Q126 | X3: Q226 | Y3: Q326 | Z3: Q426 | AA3: 2026
B4: Sweden | C4: 88.1 | D4: 87.5 | E4: 64.9 | F4: 83.3 | G4: =SUM(C4:F4) -> 323.8 | H4: 100.1 | I4: 87.3 | J4: 56.9 | K4: 81.5 | L4: =SUM(H4:K4) -> 325.8 | M4: 95.4 | N4: 79.8 | O4: 61.8 | P4: 72.9 | Q4: =SUM(M4:P4) -> 309.9 | R4: 91.1 | S4: 80.2 | T4: 85.7 | U4: 105.6 | V4: =SUM(R4:U4) -> 362.6 | AA4: =SUM(W4:Z4) -> 0
B5: Growth % | H5: =(H4-C4)/C4 -> 0.13620885 | I5: =(I4-D4)/D4 -> -0.0022857143 | J5: =(J4-E4)/E4 -> -0.12326656 | K5: =(K4-F4)/F4 -> -0.021608643 | L5: =(L4-G4)/G4 -> 0.0061766523 | M5: =(M4-H4)/H4 -> -0.046953047 | N5: =(N4-I4)/I4 -> -0.085910653 | O5: =(O4-J4)/J4 -> 0.086115993 | ... AA5: =(AA4-V4)/V4 -> -1
B6: Other Nordic countries | C6: 65.7 | D6: 62.8 | E6: 60.2 | F6: 59.7 | G6: =SUM(C6:F6) -> 248.4 | H6: 75.3 | I6: 69.2 | J6: 59.4 | K6: 66.9 | L6: =SUM(H6:K6) -> 270.8 | M6: 73.3 | N6: 66.5 | O6: 59.4 | P6: 67.2 | Q6: =SUM(M6:P6) -> 266.4 | R6: 78.5 | S6: 60.2 | T6: 56.9 | U6: 69.5 | V6: =SUM(R6:U6) -> 265.1 | AA6: =SUM(W6:Z6) -> 0
B7: Growth % | H7: =(H6-C6)/C6 -> 0.14611872 | I7: =(I6-D6)/D6 -> 0.10191083 | J7: =(J6-E6)/E6 -> -0.013289037 | K7: =(K6-F6)/F6 -> 0.12060302 | L7: =(L6-G6)/G6 -> 0.090177134 | M7: =(M6-H6)/H6 -> -0.026560425 | N7: =(N6-I6)/I6 -> -0.039017341 | O7: =(O6-J6)/J6 -> 0 | ... AA7: =(AA6-V6)/V6 -> -1
B8: Germany | C8: 159.9 | D8: 146 | E8: 136.9 | F8: 146.5 | G8: =SUM(C8:F8) -> 589.3 | H8: 165.5 | I8: 133.2 | J8: 132.9 | K8: 121.3 | L8: =SUM(H8:K8) -> 552.9 | M8: 154.5 | N8: 132.7 | O8: 112.1 | P8: 123.9 | Q8: =SUM(M8:P8) -> 523.2 | R8: 124.1 | S8: 114.5 | T8: 135 | U8: 113.2 | V8: =SUM(R8:U8) -> 486.8 | AA8: =SUM(W8:Z8) -> 0
B9: Growth % | H9: =(H8-C8)/C8 -> 0.035021889 | I9: =(I8-D8)/D8 -> -0.087671233 | J9: =(J8-E8)/E8 -> -0.029218408 | K9: =(K8-F8)/F8 -> -0.17201365 | L9: =(L8-G8)/G8 -> -0.0617682 | M9: =(M8-H8)/H8 -> -0.066465257 | N9: =(N8-I8)/I8 -> -0.0037537538 | O9: =(O8-J8)/J8 -> -0.15650865 | ... AA9: =(AA8-V8)/V8 -> -1
B10: Other European countries | C10: 205.7 | D10: 186.5 | E10: 179.8 | F10: 210.1 | G10: =SUM(C10:F10) -> 782.1 | H10: 251 | I10: 237.6 | J10: 227 | K10: 233.8 | L10: =SUM(H10:K10) -> 949.4 | M10: 226.4 | N10: 216.1 | O10: 167 | P10: 177.4 | Q10: =SUM(M10:P10) -> 786.9 | R10: 190.3 | S10: 203.7 | T10: 177.5 | U10: 178.1 | V10: =SUM(R10:U10) -> 749.6 | AA10: =SUM(W10:Z10) -> 0
B11: Growth % | H11: =(H10-C10)/C10 -> 0.22022363 | I11: =(I10-D10)/D10 -> 0.27399464 | J11: =(J10-E10)/E10 -> 0.2625139 | K11: =(K10-F10)/F10 -> 0.11280343 | L11: =(L10-G10)/G10 -> 0.21391126 | M11: =(M10-H10)/H10 -> -0.098007968 | N11: =(N10-I10)/I10 -> -0.090488215 | O11: =(O10-J10)/J10 -> -0.26431718 | ... AA11: =(AA10-V10)/V10 -> -1
B12: US | C12: 458.9 | D12: 458.9 | E12: 446.8 | F12: 476 | G12: =SUM(C12:F12) -> 1840.6 | H12: 575.1 | I12: 643 | J12: 671 | K12: 663.9 | L12: =SUM(H12:K12) -> 2553 | M12: 657.8 | N12: 637.4 | O12: 533.5 | P12: 524.3 | Q12: =SUM(M12:P12) -> 2353 | R12: 538.8 | S12: 518.2 | T12: 547.1 | U12: 489.5 | V12: =SUM(R12:U12) -> 2093.6 | AA12: =SUM(W12:Z12) -> 0
B13: Growth % | H13: =(H12-C12)/C12 -> 0.25321421 | I13: =(I12-D12)/D12 -> 0.40117673 | J13: =(J12-E12)/E12 -> 0.50179051 | K13: =(K12-F12)/F12 -> 0.3947479 | L13: =(L12-G12)/G12 -> 0.3870477 | M13: =(M12-H12)/H12 -> 0.14380108 | N13: =(N12-I12)/I12 -> -0.0087091757 | O13: =(O12-J12)/J12 -> -0.20491803 | ... AA13: =(AA12-V12)/V12 -> -1
B14: Rest of North America | C14: 90.3 | D14: 90.3 | E14: 101 | F14: 86.1 | G14: =SUM(C14:F14) -> 367.7 | H14: 132.1 | I14: 158.6 | J14: 159.9 | K14: 140.2 | L14: =SUM(H14:K14) -> 590.8 | M14: 180.2 | N14: 189.7 | O14: 170.8 | P14: 146.7 | Q14: =SUM(M14:P14) -> 687.4 | R14: 141.3 | S14: 186.6 | T14: 162.5 | U14: 159.6 | V14: =SUM(R14:U14) -> 650 | AA14: =SUM(W14:Z14) -> 0
B15: Growth % | H15: =(H14-C14)/C14 -> 0.46290144 | I15: =(I14-D14)/D14 -> 0.75636766 | J15: =(J14-E14)/E14 -> 0.58316832 | K15: =(K14-F14)/F14 -> 0.62833914 | L15: =(L14-G14)/G14 -> 0.60674463 | M15: =(M14-H14)/H14 -> 0.36411809 | N15: =(N14-I14)/I14 -> 0.19609079 | O15: =(O14-J14)/J14 -> 0.068167605 | ... AA15: =(AA14-V14)/V14 -> -1
B16: Brazil | C16: 34.7 | D16: 34.7 | E16: 30.9 | F16: 29.4 | G16: =SUM(C16:F16) -> 129.7 | H16: 29.2 | I16: 39 | J16: 40.3 | K16: 37 | L16: =SUM(H16:K16) -> 145.5 | M16: 32.9 | N16: 35.1 | O16: 33.6 | P16: 26.8 | Q16: =SUM(M16:P16) -> 128.4 | R16: 52 | S16: 63.3 | T16: 69.1 | U16: 58.7 | V16: =SUM(R16:U16) -> 243.1 | AA16: =SUM(W16:Z16) -> 0
B17: Growth % | H17: =(H16-C16)/C16 -> -0.15850144 | I17: =(I16-D16)/D16 -> 0.12391931 | J17: =(J16-E16)/E16 -> 0.30420712 | K17: =(K16-F16)/F16 -> 0.2585034 | L17: =(L16-G16)/G16 -> 0.12181958 | M17: =(M16-H16)/H16 -> 0.12671233 | N17: =(N16-I16)/I16 -> -0.1 | O17: =(O16-J16)/J16 -> -0.1662531 | ... AA17: =(AA16-V16)/V16 -> -1
B18: Australia/New Zealand | C18: 29 | D18: 29 | E18: 22.6 | F18: 44.8 | G18: =SUM(C18:F18) -> 125.4 | H18: 31.6 | I18: 35.9 | J18: 39.1 | K18: 35.9 | L18: =SUM(H18:K18) -> 142.5 | M18: 40.3 | N18: 53.3 | O18: 40.9 | P18: 40.5 | Q18: =SUM(M18:P18) -> 175 | R18: 57.6 | S18: 43.7 | T18: 34.1 | U18: 47.4 | V18: =SUM(R18:U18) -> 182.8 | AA18: =SUM(W18:Z18) -> 0
B19: Growth % | H19: =(H18-C18)/C18 -> 0.089655172 | I19: =(I18-D18)/D18 -> 0.23793103 | J19: =(J18-E18)/E18 -> 0.7300885 | K19: =(K18-F18)/F18 -> -0.19866071 | L19: =(L18-G18)/G18 -> 0.13636364 | M19: =(M18-H18)/H18 -> 0.27531646 | N19: =(N18-I18)/I18 -> 0.48467967 | O19: =(O18-J18)/J18 -> 0.046035806 | ... AA19: =(AA18-V18)/V18 -> -1
B20: China | C20: 12.9 | D20: 12.9 | E20: 20.5 | F20: 25.5 | G20: =SUM(C20:F20) -> 71.8 | H20: 10.5 | I20: 14.3 | J20: 18.6 | K20: 14.2 | L20: =SUM(H20:K20) -> 57.6 | M20: 13 | N20: 20.6 | O20: 27.4 | P20: 25.8 | Q20: =SUM(M20:P20) -> 86.8 | R20: 19.7 | S20: 30.8 | T20: 31.5 | U20: 22.3 | V20: =SUM(R20:U20) -> 104.3 | AA20: =SUM(W20:Z20) -> 0
B21: Growth % | H21: =(H20-C20)/C20 -> -0.18604651 | I21: =(I20-D20)/D20 -> 0.10852713 | J21: =(J20-E20)/E20 -> -0.092682927 | K21: =(K20-F20)/F20 -> -0.44313725 | L21: =(L20-G20)/G20 -> -0.19777159 | M21: =(M20-H20)/H20 -> 0.23809524 | N21: =(N20-I20)/I20 -> 0.44055944 | O21: =(O20-J20)/J20 -> 0.47311828 | ... AA21: =(AA20-V20)/V20 -> -1
B22: Rest of world | C22: 32.8 | D22: 32.8 | E22: 28.1 | F22: 30.2 | G22: =SUM(C22:F22) -> 123.9 | H22: 29 | I22: 32.2 | J22: 34.7 | K22: 55.2 | L22: =SUM(H22:K22) -> 151.1 | M22: 61.2 | N22: 63.1 | O22: 66.5 | P22: 71.2 | Q22: =SUM(M22:P22) -> 262 | R22: 57.8 | S22: 61.3 | T22: 68.5 | U22: 68.5 | V22: =SUM(R22:U22) -> 256.1 | AA22: =SUM(W22:Z22) -> 0
B23: Growth % | H23: =(H22-C22)/C22 -> -0.11585366 | I23: =(I22-D22)/D22 -> -0.018292683 | J23: =(J22-E22)/E22 -> 0.23487544 | K23: =(K22-F22)/F22 -> 0.82781457 | L23: =(L22-G22)/G22 -> 0.21953188 | M23: =(M22-H22)/H22 -> 1.1103448 | N23: =(N22-I22)/I22 -> 0.95962733 | O23: =(O22-J22)/J22 -> 0.91642651 | ... AA23: =(AA22-V22)/V22 -> -1
B24: Group | C24: =C4+C6+C8+C10+C12+C14+C16+C18+C20+C22 -> 1178 | D24: =D4+D6+D8+D10+D12+D14+D16+D18+D20+D22 -> 1141.4 | E24: =E4+E6+E8+E10+E12+E14+E16+E18+E20+E22 -> 1091.7 | F24: =F4+F6+F8+F10+F12+F14+F16+F18+F20+F22 -> 1191.6 | G24: =SUM(C24:F24) -> 4602.7 | H24: =H4+H6+H8+H10+H12+H14+H16+H18+H20+H22 -> 1399.4 | I24: =I4+I6+I8+I10+I12+I14+I16+I18+I20+I22 -> 1450.3 | J24: =J4+J6+J8+J10+J12+J14+J16+J18+J20+J22 -> 1439.8 | K24: =K4+K6+K8+K10+K12+K14+K16+K18+K20+K22 -> 1449.9 | L24: =SUM(H24:K24) -> 5739.4 | M24: =M4+M6+M8+M10+M12+M14+M16+M18+M20+M22 -> 1535 | N24: =N4+N6+N8+N10+N12+N14+N16+N18+N20+N22 -> 1494.3 | O24: =O4+O6+O8+O10+O12+O14+O16+O18+O20+O22 -> 1273 | P24: =P4+P6+P8+P10+P12+P14+P16+P18+P20+P22 -> 1276.7 | Q24: =SUM(M24:P24) -> 5579 | R24: =R4+R6+R8+R10+R12+R14+R16+R18+R20+R22 -> 1351.2 | S24: =S4+S6+S8+S10+S12+S14+S16+S18+S20+S22 -> 1362.5 | T24: =T4+T6+T8+T10+T12+T14+T16+T18+T20+T22 -> 1367.9 | U24: =U4+U6+U8+U10+U12+U14+U16+U18+U20+U22 -> 1312.4 | V24: =SUM(R24:U24) -> 5394 | W24: =W4+W6+W8+W10+W12+W14+W16+W18+W20+W22 -> 0 | X24: =X4+X6+X8+X10+X12+X14+X16+X18+X20+X22 -> 0 | Y24: =Y4+Y6+Y8+Y10+Y12+Y14+Y16+Y18+Y20+Y22 -> 0 | AA24: =SUM(W24:Z24) -> 0

Sheet SOTP
C6: SEKm | D6: EBIT 26E | E6: EV/EBIT | F6: Value | G6: SEK/Share
C7: T&T | D7: 335 | E7: 15 | F7: =D7*E7 -> 5025 | G7: =F7/Modell!$B$5 -> 200.97588
C8: Mobile thermal sol | D8: 300 | E8: 5 | F8: =D8*E8 -> 1500 | G8: =F8/Modell!$B$5 -> 59.992801
C9: Ringfender power trans | D9: 130 | E9: 10 | F9: =D9*E9 -> 1300 | G9: =F9/Modell!$B$5 -> 51.993761
C10: Enterprise value | G10: =SUM(G7:G9) -> 312.96244
C12: Cash | F12: =Modell!B7 -> 984 | G12: =F12/Modell!$B$5 -> 39.355277
C13: Debt | F13: =Modell!B8 -> 1480.2 | G13: =-F13/Modell!$B$5 -> -59.200896
C15: Equity value | G15: =SUM(G10:G13) -> 293.11683
A56: T&T | B56: =G7 -> 200.97588
A57: Mobile thermal sol | B57: =G8 -> 59.992801
A58: Ringfender power trans | B58: =G9 -> 51.993761
A59: EV | B59: =G10 -> 312.96244
A61: Cash | B61: =G12 -> 39.355277
A62: Debt | B62: =G13 -> -59.200896
A64: Equity value | B64: =G15 -> 293.11683

Sheet Nøkkeltall
