Workbook

Sheet Info
A2: Maritme service:
H3: Press releases:
H4: 11.05.26: WWI kjøper tilbake 847 000 aksjer
H5: 29.04.26: WWI fullfører salget av Edda Wind flåten. WWI vil generer net cash flow på 55 USDm
H6: 04.03.26: Wilhelmsen med flere selger hele flåten sin i Edda Wind
H7: 02.06.25: WWI skal kjøpe tilbake 400 000 aksjer
H8: 29.04.25: Geveran, Wilhelmsen og EPS ventures kjøper Edda av børs for 23 kroner
H9: 27.02.25: WWI kjøper tilbake 875 000 akjser
H10: 01.11.24: CFO kjøper aksjer 600 WWIB
H11: 14.10.24: WWI kjøper 150 000 aksjer i Treasure, eier nå 84,16%
H12: 11.10.24: WWI kjøper 7 061 352 aksjer i Treasure, Eier nå 84,09%
H13: 11.10.24: WWI kjøper 4 021 523 aksjer i Treasure, eier nå 80,64%
H14: 21.08.24: WWI kjøper 875 000 aksjer
A17: New Energy:
A26: Strategic holdings and investments

Sheet Modell
A3: Kapitalstruktur | C3: USD million | D3: Q122 | E3: Q222 | F3: Q322 | G3: Q422 | H3: Q123 | I3: Q223 | J3: Q323 | K3: Q423 | L3: Q124 | M3: Q224 | N3: Q324 | O3: Q424 | P3: Q125 | Q3: Q225 | R3: Q325 | S3: Q425 | T3: Q126 | U3: Q226 | V3: Q326 | W3: Q426 | Z3: FY 2019 | AA3: FY 2020 | AB3: FY 2021 | AC3: FY 2022 | AD3: FY 2023 | AE3: FY 2024 | AF3: FY 2025 | AG3: FY 2026 | AH3: FY 2027 | AI3: FY 2028 | AJ3: FY 2029 | AK3: FY 2030 | AL3: FY 2031 | AM3: FY 2032 | AN3: FY 2033 | AO3: FY 2034 | AP3: FY 2035
A4: Price | B4: 943 | C4: Operating revenue | D4: 232 | E4: 239 | F4: 236 | G4: 237 | H4: 262 | I4: 261 | J4: 254 | K4: 250 | L4: 265 | M4: 301 | N4: 296 | O4: 274 | P4: 297 | Q4: 316 | R4: 311 | S4: 310 | T4: 308 | U4: 320 | Z4: 836 | AA4: 807 | AB4: 873 | AC4: 943 | AD4: 1027 | AE4: 1136 | AF4: 1234 | AG4: =AF4*1.03 -> 1271.02 | AH4: =AG4*1.04 -> 1321.8608 | AI4: =AH4*1.04 -> 1374.7352 | AJ4: =AI4*1.04 -> 1429.7246 | AK4: =AJ4*1.04 -> 1486.9136 | AL4: =AK4*1.04 -> 1546.3902 | AM4: =AL4*1.04 -> 1608.2458 | AN4: =AM4*1.04 -> 1672.5756 | AO4: =AN4*1.04 -> 1739.4786 | AP4: =AO4*1.04 -> 1809.0578
A5: S/O | B5: =34+10.58 -> 44.58 | C5: Other gain | D5: 9 | E5: -1 | F5: -2 | G5: 9 | H5: -1 | I5: -2 | J5: -1 | K5: 5 | L5: -1 | M5: 0 | N5: -1 | O5: 4 | P5: -1 | Q5: -2 | R5: -1 | S5: 0 | T5: 0 | U5: 0 | Z5: 14 | AA5: 5 | AB5: 2 | AC5: 15 | AD5: 1 | AE5: 2 | AF5: -4 | AG5: 0 | AH5: 0 | AI5: 0 | AJ5: 0 | AK5: 0 | AL5: 0 | AM5: 0 | AN5: 0 | AO5: 0 | AP5: 0
A6: MC NOKm | B6: =B4*B5 -> 42038.94 | C6: Total income | D6: =SUM(D4:D5) -> 241 | E6: =SUM(E4:E5) -> 238 | F6: =SUM(F4:F5) -> 234 | G6: =SUM(G4:G5) -> 246 | H6: =SUM(H4:H5) -> 261 | I6: =SUM(I4:I5) -> 259 | J6: =SUM(J4:J5) -> 253 | K6: =SUM(K4:K5) -> 255 | ... U6: =SUM(U4:U5) -> 320 | Z6: =SUM(Z4:Z5) -> 850 | AA6: =SUM(AA4:AA5) -> 812 | AB6: =SUM(AB4:AB5) -> 875 | AC6: =SUM(AC4:AC5) -> 958 | AD6: =SUM(AD4:AD5) -> 1028 | AE6: =SUM(AE4:AE5) -> 1138 | AF6: =SUM(AF4:AF5) -> 1230 | AG6: =SUM(AG4:AG5) -> 1271.02 | ... AP6: =SUM(AP4:AP5) -> 1809.0578
A7: Cash NOKm | B7: 2573.2 | C7: COGS | D7: -75 | E7: -76 | F7: -80 | G7: -82 | H7: -90 | I7: -87 | J7: -83 | K7: -81 | L7: -86 | M7: -108 | N7: -108 | O7: -89 | P7: -103 | Q7: -113 | R7: -103 | S7: -101 | T7: -98 | U7: -97 | Z7: -247 | AA7: -243 | AB7: -277 | AC7: -313 | AD7: -340 | AE7: -391 | AF7: -420 | AG7: -420 | AH7: =AG7*1.04 -> -436.8 | AI7: =AH7*1.04 -> -454.272 | AJ7: =AI7*1.04 -> -472.44288 | AK7: =AJ7*1.04 -> -491.3406 | AL7: =AK7*1.04 -> -510.99422 | AM7: =AL7*1.04 -> -531.43399 | AN7: =AM7*1.04 -> -552.69135 | AO7: =AN7*1.04 -> -574.799 | AP7: =AO7*1.04 -> -597.79096
A8: Debt NOKm | B8: 2600.77 | C8: Employee benefits | D8: -84 | E8: -83 | F8: -83 | G8: -92 | H8: -94 | I8: -94 | J8: -99 | K8: -100 | L8: -102 | M8: -104 | N8: -109 | O8: -108 | P8: -110 | Q8: -112 | R8: -117 | S8: -117 | T8: -116 | U8: -117 | Z8: -306 | AA8: -299 | AB8: -321 | AC8: -341 | AD8: -387 | AE8: -423 | AF8: -456 | AG8: -466 | AH8: =AG8*1.04 -> -484.64 | AI8: =AH8*1.04 -> -504.0256 | AJ8: =AI8*1.04 -> -524.18662 | AK8: =AJ8*1.04 -> -545.15409 | AL8: =AK8*1.04 -> -566.96025 | AM8: =AL8*1.04 -> -589.63866 | AN8: =AM8*1.04 -> -613.22421 | AO8: =AN8*1.04 -> -637.75318 | AP8: =AO8*1.04 -> -663.2633
A9: EV NOKm | B9: =B6-B7+B8 -> 42066.51 | C9: Other expenses | D9: -38 | E9: -40 | F9: -34 | G9: -39 | H9: -38 | I9: -39 | J9: -35 | K9: -42 | L9: -38 | M9: -43 | N9: -40 | O9: -44 | P9: -38 | Q9: -41 | R9: -48 | S9: -47 | T9: -42 | U9: -44 | Z9: -148 | AA9: -131 | AB9: -136 | AC9: -151 | AD9: -153 | AE9: -166 | AF9: -174 | AG9: -172 | AH9: =AG9*1.04 -> -178.88 | AI9: =AH9*1.04 -> -186.0352 | AJ9: =AI9*1.04 -> -193.47661 | AK9: =AJ9*1.04 -> -201.21567 | AL9: =AK9*1.04 -> -209.2643 | AM9: =AL9*1.04 -> -217.63487 | AN9: =AM9*1.04 -> -226.34027 | AO9: =AN9*1.04 -> -235.39388 | AP9: =AO9*1.04 -> -244.80963
C10: D/A/I | D10: -17 | E10: -12 | F10: -13 | G10: -27 | H10: -14 | I10: -14 | J10: -15 | K10: -16 | L10: -16 | M10: -16 | N10: -16 | O10: -26 | P10: -14 | Q10: -20 | R10: -22 | S10: -18 | T10: -19 | U10: -21 | Z10: -71 | AA10: -78 | AB10: -68 | AC10: -69 | AD10: -59 | AE10: -74 | AF10: -74 | AG10: -80 | AH10: =AG10*1.04 -> -83.2 | AI10: =AH10*1.04 -> -86.528 | AJ10: =AI10*1.04 -> -89.98912 | AK10: =AJ10*1.04 -> -93.588685 | AL10: =AK10*1.04 -> -97.332232 | AM10: =AL10*1.04 -> -101.22552 | AN10: =AM10*1.04 -> -105.27454 | AO10: =AN10*1.04 -> -109.48552 | AP10: =AO10*1.04 -> -113.86494
A11: USD/NOK | B11: 9.69 | C11: Operating profits EBIT | D11: =SUM(D6:D10) -> 27 | E11: =SUM(E6:E10) -> 27 | F11: =SUM(F6:F10) -> 24 | G11: =SUM(G6:G10) -> 6 | H11: =SUM(H6:H10) -> 25 | I11: =SUM(I6:I10) -> 25 | J11: =SUM(J6:J10) -> 21 | K11: =SUM(K6:K10) -> 16 | ... U11: =SUM(U6:U10) -> 41 | Z11: =SUM(Z6:Z10) -> 78 | AA11: =SUM(AA6:AA10) -> 61 | AB11: =SUM(AB6:AB10) -> 73 | AC11: =SUM(AC6:AC10) -> 84 | AD11: =SUM(AD6:AD10) -> 89 | AE11: =SUM(AE6:AE10) -> 84 | AF11: =SUM(AF6:AF10) -> 106 | AG11: =SUM(AG6:AG10) -> 133.02 | ... AP11: =SUM(AP6:AP10) -> 189.32894
C12: Share of profit from JV | D12: 64 | E12: 45 | F12: 87 | G12: 100 | H12: 83 | I12: 141 | J12: 138 | K12: 68 | L12: 92 | M12: 146 | N12: 118 | O12: 116 | P12: 121 | Q12: 208 | R12: 133 | S12: 109 | T12: 84 | U12: 112 | Z12: 49 | AA12: -50 | AB12: 101 | AC12: 296 | AD12: 431 | AE12: 472 | AF12: 571 | AG12: 400 | AH12: =AG12*0.95 -> 380 | AI12: =AH12*0.95 -> 361 | AJ12: =AI12*0.95 -> 342.95 | AK12: =AJ12*1.01 -> 346.3795 | AL12: =AK12*1.01 -> 349.8433 | AM12: =AL12*1.01 -> 353.34173 | AN12: =AM12*1.01 -> 356.87515 | AO12: =AN12*1.01 -> 360.4439 | AP12: =AO12*1.01 -> 364.04834
A13: P/NAV | B13: =SOTP!B4 -> 0.64208506 | C13: Change in fair value | D13: 70 | E13: 0 | F13: -106 | G13: 105 | H13: 1 | I13: 1 | J13: 4 | K13: 5 | L13: 8 | M13: 15 | N13: 3 | O13: 1 | P13: 0 | Q13: 7 | R13: -3 | S13: 0 | T13: 1 | U13: 4 | Z13: 34 | AA13: 192 | AB13: -107 | AC13: -50 | AD13: 11 | AE13: 27 | AF13: 4 | AG13: 0 | AH13: 0 | AI13: 0 | AJ13: 0 | AK13: 0 | AL13: 0 | AM13: 0 | AN13: 0 | AO13: 0 | AP13: 0
C14: Other financial income | D14: 4 | E14: 0 | F14: 0 | G14: 0 | H14: 0 | I14: 0 | J14: 0 | K14: 1 | L14: 0 | M14: 0 | N14: 1 | O14: 0 | P14: -7 | Q14: 23 | R14: 2 | S14: 18 | T14: 2 | U14: 3 | Z14: 33 | AA14: 46 | AB14: 42 | AC14: 30 | AD14: 39 | AE14: 25 | AF14: 36 | AG14: 0 | AH14: 0 | AI14: 0 | AJ14: 0 | AK14: 0 | AL14: 0 | AM14: 0 | AN14: 0 | AO14: 0 | AP14: 0
A15: P/B | B15: =B6/(U46*B11) -> 1.2227689 | C15: Other financial expense | D15: 0 | E15: -117 | F15: -29 | G15: 0 | H15: -2 | I15: -3 | J15: -6 | K15: 0 | L15: -6 | M15: -12 | N15: 0 | O15: -28 | P15: 4 | Q15: 0 | R15: 0 | S15: 0 | T15: 0 | U15: 0 | Z15: -49 | AA15: -44 | AB15: -43 | AC15: -55 | AD15: -54 | AE15: -71 | AF15: 4 | AG15: 0 | AH15: 0 | AI15: 0 | AJ15: 0 | AK15: 0 | AL15: 0 | AM15: 0 | AN15: 0 | AO15: 0 | AP15: 0
C16: PTP | D16: =SUM(D11:D15) -> 165 | E16: =SUM(E11:E15) -> -45 | F16: =SUM(F11:F15) -> -24 | G16: =SUM(G11:G15) -> 211 | H16: =SUM(H11:H15) -> 107 | I16: =SUM(I11:I15) -> 164 | J16: =SUM(J11:J15) -> 157 | K16: =SUM(K11:K15) -> 90 | ... U16: =SUM(U11:U15) -> 160 | Z16: =SUM(Z11:Z15) -> 145 | AA16: =SUM(AA11:AA15) -> 205 | AB16: =SUM(AB11:AB15) -> 66 | AC16: =SUM(AC11:AC15) -> 305 | AD16: =SUM(AD11:AD15) -> 516 | AE16: =SUM(AE11:AE15) -> 537 | AF16: =SUM(AF11:AF15) -> 721 | AG16: =SUM(AG11:AG15) -> 533.02 | ... AP16: =SUM(AP11:AP15) -> 553.37727
A17: 0,8 NAV | B17: =SOTP!G26*0.8 -> 1174.9222 | C17: Tax | D17: -5 | E17: 6 | F17: 0 | G17: -14 | H17: -6 | I17: -6 | J17: -5 | K17: -11 | L17: -2 | M17: -7 | N17: -7 | O17: -4 | P17: -12 | Q17: -8 | R17: -3 | S17: -25 | T17: -7 | U17: -13 | Z17: -15 | AA17: -27 | AB17: -13 | AC17: -13 | AD17: -27 | AE17: -20 | AF17: -48 | AG17: =AG16*-0.05 -> -26.651 | AH17: =AH16*-0.05 -> -25.91704 | AI17: =AI16*-0.05 -> -25.243722 | AJ17: =AJ16*-0.05 -> -24.62897 | AK17: =AK16*-0.05 -> -25.099704 | AL17: =AL16*-0.05 -> -25.584123 | AM17: =AM16*-0.05 -> -26.082723 | AN17: =AN16*-0.05 -> -26.59602 | ... AP17: =AP16*-0.05 -> -27.668864
C18: Net income | D18: =SUM(D16:D17) -> 160 | E18: =SUM(E16:E17) -> -39 | F18: =SUM(F16:F17) -> -24 | G18: =SUM(G16:G17) -> 197 | H18: =SUM(H16:H17) -> 101 | I18: =SUM(I16:I17) -> 158 | J18: =SUM(J16:J17) -> 152 | K18: =SUM(K16:K17) -> 79 | ... U18: =SUM(U16:U17) -> 147 | Z18: =SUM(Z16:Z17) -> 130 | AA18: =SUM(AA16:AA17) -> 178 | AB18: =SUM(AB16:AB17) -> 53 | AC18: =SUM(AC16:AC17) -> 292 | AD18: =SUM(AD16:AD17) -> 489 | AE18: =SUM(AE16:AE17) -> 517 | AF18: =SUM(AF16:AF17) -> 673 | AG18: =SUM(AG16:AG17) -> 506.369 | ... AP18: =SUM(AP16:AP17) -> 525.70841 | AQ18: =AP18*(1+$AS$21) -> 520.45133 | AR18: =AQ18*(1+$AS$21) -> 515.24681 | AS18: =AR18*(1+$AS$21) -> 510.09434 | AT18: =AS18*(1+$AS$21) -> 504.9934 | AU18: =AT18*(1+$AS$21) -> 499.94347 | AV18: =AU18*(1+$AS$21) -> 494.94403 | AW18: =AV18*(1+$AS$21) -> 489.99459 | AX18: =AW18*(1+$AS$21) -> 485.09465 | ... EQ18: =EP18*(1+$AS$21) -> 182.99548
A19: % to 0,8 | B19: =(B17-B4)/B17 -> 0.19739368 | C19: EPS (NOK) | D19: 19.07 | E19: 19.07 | F19: 19.07 | G19: 19.07 | H19: 19.07 | I19: 19.07 | J19: 19.07 | K19: =(K18/K20)*$B$11 -> 17.171602 | L19: =(L18/L20)*$B$11 -> 24.779273 | M19: =(M18/M20)*$B$11 -> 37.386272 | N19: =(N18/N20)*$B$11 -> 29.7786 | O19: =(O18/O20)*$B$11 -> 20.866756 | P19: =(P18/P20)*$B$11 -> 29.7786 | Q19: =(Q18/Q20)*$B$11 -> 56.079408 | R19: =(R18/R20)*$B$11 -> 32.386945 | ... U19: =(U18/U20)*$B$11 -> 31.952221 | Z19: =(Z18*$B$11)/Z20 -> 28.257066 | AA19: =(AA18*$B$11)/AA20 -> 38.690444 | AB19: =(AB18*$B$11)/AB20 -> 11.520188 | AC19: =(AC18*$B$11)/AC20 -> 63.469717 | AD19: =(AD18*$B$11)/AD20 -> 106.29004 | AE19: =(AE18*$B$11)/AE20 -> 112.37618 | AF19: =(AF18*$B$11)/AF20 -> 146.28466 | AG19: =(AG18*$B$11)/AG20 -> 110.0654 | ... AP19: =(AP18*$B$11)/AP20 -> 114.26906
C20: Share | D20: 44.58 | E20: 44.58 | F20: 44.58 | G20: 44.58 | H20: 44.58 | I20: 44.58 | J20: 44.58 | K20: =34+10.58 -> 44.58 | L20: =34+10.58 -> 44.58 | M20: =34+10.58 -> 44.58 | N20: =34+10.58 -> 44.58 | O20: =34+10.58 -> 44.58 | P20: 44.58 | Q20: 44.58 | R20: 44.58 | S20: 44.58 | T20: 44.58 | U20: 44.58 | Z20: =34+10.58 -> 44.58 | AA20: =34+10.58 -> 44.58 | AB20: =34+10.58 -> 44.58 | AC20: =34+10.58 -> 44.58 | AD20: =34+10.58 -> 44.58 | AE20: =34+10.58 -> 44.58 | AF20: =34+10.58 -> 44.58 | AG20: =34+10.58 -> 44.58 | ... AP20: =34+10.58 -> 44.58 | AR20: Discount | AS20: 0.08
A21: 0,7 NAV | B21: =SOTP!G26*0.7 -> 1028.0569 | AR21: TV | AS21: -0.01
C22: Revenue y/y | H22: =(H6-D6)/D6 -> 0.082987552 | I22: =(I6-E6)/E6 -> 0.088235294 | J22: =(J6-F6)/F6 -> 0.081196581 | K22: =(K6-G6)/G6 -> 0.036585366 | L22: =(L6-H6)/H6 -> 0.011494253 | M22: =(M6-I6)/I6 -> 0.16216216 | N22: =(N6-J6)/J6 -> 0.16600791 | O22: =(O6-K6)/K6 -> 0.090196078 | ... U22: =(U6-Q6)/Q6 -> 0.01910828 | AA22: =(AA6-Z6)/Z6 -> -0.044705882 | AB22: =(AB6-AA6)/AA6 -> 0.077586207 | AC22: =(AC6-AB6)/AB6 -> 0.094857143 | AD22: =(AD6-AC6)/AC6 -> 0.073068894 | AE22: =(AE6-AD6)/AD6 -> 0.10700389 | AF22: =(AF6-AE6)/AE6 -> 0.080843585 | AG22: =(AG6-AF6)/AF6 -> 0.033349593 | AH22: =(AH6-AG6)/AG6 -> 0.04 | ... AP22: =(AP6-AO6)/AO6 -> 0.04 | AR22: NPV | AS22: =NPV(AS20,AF18:EQ18)*B11 -> 59767.388
A23: % to 0,7 | B23: =(B21-B4)/B4 -> 0.090198238 | C23: EBIT margin | D23: =D11/D6 -> 0.1120332 | E23: =E11/E6 -> 0.11344538 | F23: =F11/F6 -> 0.1025641 | G23: =G11/G6 -> 0.024390244 | H23: =H11/H6 -> 0.095785441 | I23: =I11/I6 -> 0.096525097 | J23: =J11/J6 -> 0.083003953 | K23: =K11/K6 -> 0.062745098 | ... U23: =U11/U6 -> 0.128125 | Z23: =Z11/Z6 -> 0.091764706 | AA23: =AA11/AA6 -> 0.075123153 | AB23: =AB11/AB6 -> 0.083428571 | AC23: =AC11/AC6 -> 0.087682672 | AD23: =AD11/AD6 -> 0.086575875 | AE23: =AE11/AE6 -> 0.073813708 | AF23: =AF11/AF6 -> 0.086178862 | AG23: =AG11/AG6 -> 0.1046561 | ... AP23: =AP11/AP6 -> 0.1046561 | AR23: S/O | AS23: =34+10.58 -> 44.58
AR24: NPV/share | AS24: =AS22/AS23 -> 1340.6772
C25: EBITDA | D25: 44 | E25: 39 | F25: 36 | G25: 34 | H25: 39 | I25: 39 | J25: 36 | K25: 33 | L25: 38 | M25: 46 | N25: 48 | O25: 42 | P25: 45 | Q25: 50 | R25: 42 | S25: 45 | T25: 50 | U25: 62 | Z25: 149 | AA25: 138 | AB25: 141 | AC25: 153 | AD25: 147 | AE25: 159 | AF25: 180 | AR25: Opp/nedside | AS25: =(AS24-B4)/B4 -> 0.42171492
C26: EBITDA Margin | D26: =D25/D6 -> 0.18257261 | E26: =E25/E6 -> 0.16386555 | F26: =F25/F6 -> 0.15384615 | G26: =G25/G6 -> 0.13821138 | H26: =H25/H6 -> 0.14942529 | I26: =I25/I6 -> 0.15057915 | J26: =J25/J6 -> 0.14229249 | K26: =K25/K6 -> 0.12941176 | ... U26: =U25/U6 -> 0.19375 | Z26: =Z25/Z6 -> 0.17529412 | AA26: =AA25/AA6 -> 0.16995074 | AB26: =AB25/AB6 -> 0.16114286 | AC26: =AC25/AC6 -> 0.15970772 | AD26: =AD25/AD6 -> 0.14299611 | AE26: =AE25/AE6 -> 0.1397188 | AF26: =AF25/AF6 -> 0.14634146
C27: EBITDA LTM | G27: =SUM(D25:G25) -> 153 | H27: =SUM(E25:H25) -> 148 | I27: =SUM(F25:I25) -> 148 | J27: =SUM(G25:J25) -> 148 | K27: =SUM(H25:K25) -> 147 | L27: =SUM(I25:L25) -> 146 | M27: =SUM(J25:M25) -> 153 | N27: =SUM(K25:N25) -> 165 | ... U27: =SUM(R25:U25) -> 199
C29: Balanse USDm
C30: Deferred tax | D30: 58 | E30: 64 | F30: 63 | G30: 61 | H30: 64 | I30: 54 | J30: 54 | K30: 51 | L30: 52 | M30: 45 | N30: 39 | O30: 52 | P30: 45 | Q30: 43 | R30: 42 | S30: 39 | T30: 34 | U30: 27 | Z30: 57 | AA30: 55 | AB30: 64 | AC30: 61 | AD30: 51 | AE30: 52 | AF30: 39
C31: Goodwill and other intangible assets | D31: 137 | E31: 120 | F31: 111 | G31: 129 | H31: 132 | I31: 128 | J31: 126 | K31: 132 | L31: 124 | M31: 145 | N31: 145 | O31: 125 | P31: 126 | Q31: 129 | R31: =96+32 -> 128 | S31: =95+34 -> 129 | T31: 133 | U31: 141 | Z31: 151 | AA31: 141 | AB31: 135 | AC31: 129 | AD31: 132 | AE31: 125 | AF31: =95+34 -> 129
C32: property and other tangible assets | D32: 684 | E32: 617 | F32: 575 | G32: 623 | H32: 594 | I32: 584 | J32: 587 | K32: 623 | L32: 589 | M32: 596 | N32: 608 | O32: 571 | P32: 602 | Q32: 635 | R32: 647 | S32: 662 | T32: 685 | U32: 692 | Z32: 555 | AA32: 560 | AB32: 542 | AC32: 623 | AD32: 623 | AE32: 571 | AF32: 662
C33: Right of use assets | D33: 146 | E33: 100 | F33: 91 | G33: 102 | H33: 96 | I33: 95 | J33: 92 | K33: 112 | L33: 116 | M33: 114 | N33: 119 | O33: 121 | P33: 134 | Q33: 135 | R33: 142 | S33: 139 | T33: 140 | U33: 140 | Z33: 173 | AA33: 177 | AB33: 155 | AC33: 102 | AD33: 112 | AE33: 121 | AF33: 139
C34: Investments in JV and associates | D34: 1154 | E34: 1156 | F34: 1228 | G34: 1342 | H34: 2040 | I34: 1783 | J34: 1888 | K34: 1877 | L34: 2306 | M34: 1911 | N34: 1958 | O34: 2001 | P34: 1965 | Q34: 2233 | R34: 2172 | S34: 2274 | T34: 2171 | U34: 2266 | Z34: 1003 | AA34: 973 | AB34: 1093 | AC34: 1342 | AD34: 1877 | AE34: 2001 | AF34: 2274
C35: Financial assets to fair value | D35: 761 | E35: 640 | F35: 529 | G35: 613 | H35: 74 | I35: 75 | J35: 78 | K35: 87 | L35: 92 | M35: 109 | N35: 97 | O35: 86 | P35: 87 | Q35: 97 | R35: 118 | S35: 129 | T35: 133 | U35: 139 | Z35: 675 | AA35: 801 | AB35: 688 | AC35: 613 | AD35: 87 | AE35: 86 | AF35: 129
C36: Other non current assets | D36: 30 | E36: 25 | F36: 25 | G36: 28 | H36: 26 | I36: 28 | J36: 28 | K36: 42 | L36: 63 | M36: 32 | N36: 39 | O36: 39 | P36: 42 | Q36: 45 | R36: 22 | S36: 28 | T36: 30 | U36: 29 | Z36: 25 | AA36: 28 | AB36: 25 | AC36: 28 | AD36: 42 | AE36: 39 | AF36: 28
C37: Inventory | D37: 94 | E37: 93 | F37: 100 | G37: 114 | H37: 117 | I37: 118 | J37: 118 | K37: 121 | L37: 114 | M37: 108 | N37: 117 | O37: 119 | P37: 121 | Q37: 128 | R37: 131 | S37: 129 | T37: 128 | U37: 133 | Z37: 82 | AA37: 84 | AB37: 93 | AC37: 114 | AD37: 121 | AE37: 119 | AF37: 129
C38: Current financial investments | D38: 110 | E38: 95 | F38: 82 | G38: 104 | H38: 113 | I38: 114 | J38: 111 | K38: 124 | L38: 122 | M38: 130 | N38: 138 | O38: 121 | P38: 132 | Q38: 221 | R38: 310 | S38: 257 | T38: 309 | U38: 358 | Z38: 102 | AA38: 124 | AB38: 135 | AC38: 104 | AD38: 124 | AE38: 121 | AF38: 257
C39: Other current assets | D39: 344 | E39: 319 | F39: 308 | G39: 349 | H39: 377 | I39: 398 | J39: 373 | K39: 342 | L39: 348 | M39: 447 | N39: 553 | O39: 368 | P39: 599 | Q39: 419 | R39: 428 | S39: 411 | T39: 454 | U39: 556 | Z39: 317 | AA39: 274 | AB39: 287 | AC39: 349 | AD39: 342 | AE39: 368 | AF39: 411
C40: Cash | D40: 183 | E40: 163 | F40: 159 | G40: 163 | H40: 162 | I40: 179 | J40: 186 | K40: 224 | L40: 187 | M40: 177 | N40: 154 | O40: 155 | P40: 169 | Q40: 209 | R40: 303 | S40: 214 | T40: 280 | U40: 249 | Z40: 153 | AA40: 269 | AB40: 231 | AC40: 163 | AD40: 224 | AE40: 155 | AF40: 214
C41: Total Assets | D41: =SUM(D30:D40) -> 3701 | E41: =SUM(E30:E40) -> 3392 | F41: =SUM(F30:F40) -> 3271 | G41: =SUM(G30:G40) -> 3628 | H41: =SUM(H30:H40) -> 3795 | I41: =SUM(I30:I40) -> 3556 | J41: =SUM(J30:J40) -> 3641 | K41: =SUM(K30:K40) -> 3735 | ... U41: =SUM(U30:U40) -> 4730 | Z41: =SUM(Z30:Z40) -> 3293 | AA41: =SUM(AA30:AA40) -> 3486 | AB41: =SUM(AB30:AB40) -> 3448 | AC41: =SUM(AC30:AC40) -> 3628 | AD41: =SUM(AD30:AD40) -> 3735 | AE41: =SUM(AE30:AE40) -> 3758 | AF41: =SUM(AF30:AF40) -> 4411
C42: Paid in capital | D42: 118 | E42: 118 | F42: 118 | G42: 118 | H42: 118 | I42: 118 | J42: 118 | K42: 118 | L42: 118 | M42: 118 | N42: 118 | O42: 118 | P42: 118 | Q42: 118 | R42: 115 | S42: 115 | T42: 115 | U42: 115 | Z42: 118 | AA42: 122 | AB42: 118 | AC42: 118 | AD42: 118 | AE42: 118 | AF42: 115
C43: Own shares | D43: 0 | E43: 0 | F43: 0 | G43: 0 | H43: 0 | I43: -1 | J43: -1 | K43: -1 | L43: -1 | M43: -2 | N43: -3 | O43: -3 | P43: -4 | Q43: -5 | R43: -1 | S43: -1 | T43: -1 | U43: -2 | Z43: 0 | AA43: 0 | AB43: 0 | AC43: 0 | AD43: -1 | AE43: -3 | AF43: -1
...

Sheet Segementer
B3: USD million
C4: Q122 | D4: Q222 | E4: Q322 | F4: Q422 | G4: 2022 | H4: Q123 | I4: Q223 | J4: Q323 | K4: Q423 | L4: 2023 | M4: Q124 | N4: Q224 | O4: Q324 | P4: Q424 | Q4: 2024 | R4: Q125 | S4: Q225 | T4: Q325 | U4: Q425 | V4: 2025 | W4: Q126 | X4: Q226 | Y4: Q326 | Z4: Q426 | AA4: 2026
B5: Maritme service
B6: Total income | C6: 154 | D6: 156 | E6: 157 | F6: 162 | G6: =SUM(C6:F6) -> 629 | H6: 183 | I6: 185 | J6: 178 | K6: 187 | L6: =SUM(H6:K6) -> 733 | M6: 194 | N6: 220 | O6: 216 | P6: 202 | Q6: =SUM(M6:P6) -> 832 | R6: 213 | S6: 214 | T6: 222 | U6: 220 | V6: =SUM(R6:U6) -> 869 | W6: 223 | X6: 228 | AA6: =SUM(W6:Z6) -> 451
B7: y/y | H7: =(H6-C6)/C6 -> 0.18831169 | I7: =(I6-D6)/D6 -> 0.18589744 | J7: =(J6-E6)/E6 -> 0.13375796 | K7: =(K6-F6)/F6 -> 0.15432099 | L7: =(L6-G6)/G6 -> 0.16534181 | M7: =(M6-H6)/H6 -> 0.06010929 | N7: =(N6-I6)/I6 -> 0.18918919 | O7: =(O6-J6)/J6 -> 0.21348315 | ... AA7: =(AA6-V6)/V6 -> -0.48101266
B8: Of which Ships serivce | C8: 94 | D8: 99 | E8: 100 | F8: 102 | G8: =SUM(C8:F8) -> 395 | H8: 119 | I8: 119 | J8: 115 | K8: 115 | L8: =SUM(H8:K8) -> 468 | M8: 128 | N8: 128 | O8: 127 | P8: 125 | Q8: =SUM(M8:P8) -> 508 | R8: 125 | S8: 133 | T8: 136 | U8: 128 | V8: =SUM(R8:U8) -> 522 | W8: 134 | X8: 134 | AA8: =SUM(W8:Z8) -> 268
B9: Of which port serivce | C9: 33 | D9: 35 | E9: 34 | F9: 34 | G9: =SUM(C9:F9) -> 136 | H9: 37 | I9: 38 | J9: 37 | K9: 41 | L9: =SUM(H9:K9) -> 153 | M9: 40 | N9: 41 | O9: 39 | P9: 43 | Q9: =SUM(M9:P9) -> 163 | R9: 43 | S9: 41 | T9: 44 | U9: 47 | V9: =SUM(R9:U9) -> 175 | W9: 44 | X9: 44 | AA9: =SUM(W9:Z9) -> 88
B10: Of which Ship managment | C10: 16 | D10: 17 | E10: 17 | F10: 19 | G10: =SUM(C10:F10) -> 69 | H10: 20 | I10: 22 | J10: 22 | K10: 23 | L10: =SUM(H10:K10) -> 87 | M10: 21 | N10: 49 | O10: 47 | P10: 30 | Q10: =SUM(M10:P10) -> 147 | R10: 30 | S10: 40 | T10: 41 | U10: 42 | V10: =SUM(R10:U10) -> 153 | W10: 39 | X10: 39 | AA10: =SUM(W10:Z10) -> 78
B11: Of which other activities/eliminations | C11: 10 | D11: 5 | E11: 6 | F11: 8 | G11: =SUM(C11:F11) -> 29 | H11: 7 | I11: 7 | J11: 4 | K11: 8 | L11: =SUM(H11:K11) -> 26 | M11: 6 | N11: 2 | O11: 2 | P11: 4 | Q11: =SUM(M11:P11) -> 14 | R11: 4 | S11: -1 | T11: 1 | U11: 3 | V11: =SUM(R11:U11) -> 7 | W11: 6 | X11: 6 | AA11: =SUM(W11:Z11) -> 12
B12: EBITDA | C12: 20 | D12: 25 | E12: 24 | F12: 25 | G12: =SUM(C12:F12) -> 94 | H12: 28 | I12: 30 | J12: 24 | K12: 24 | L12: =SUM(H12:K12) -> 106 | M12: 28 | N12: 32 | O12: 26 | P12: 24 | Q12: =SUM(M12:P12) -> 110 | R12: 32 | S12: 28 | T12: 24 | U12: 28 | V12: =SUM(R12:U12) -> 112 | W12: 32 | X12: 39 | AA12: =SUM(W12:Z12) -> 71
B13: EBITDA margin | C13: 0.13 | D13: 0.16 | E13: 0.15 | F13: 0.15 | G13: =G12/G6 -> 0.14944356 | H13: 0.15 | I13: 0.16 | J13: 0.13 | K13: 0.13 | L13: =L12/L6 -> 0.14461119 | M13: 0.14 | N13: 0.15 | O13: 0.12 | P13: 0.12 | Q13: =Q12/Q6 -> 0.13221154 | R13: 0.15 | S13: 0.13 | T13: 0.11 | U13: 0.13 | V13: =V12/V6 -> 0.12888377 | W13: 0.14 | X13: 0.17 | AA13: =AA12/AA6 -> 0.15742794
B14: Operating profit/EBIT | C14: 14 | D14: 19 | E14: 18 | F14: 6 | G14: =SUM(C14:F14) -> 57 | H14: 21 | I14: 23 | J14: 17 | K14: 16 | L14: =SUM(H14:K14) -> 77 | M14: 21 | N14: 25 | O14: 18 | P14: 6 | Q14: =SUM(M14:P14) -> 70 | R14: 25 | S14: 20 | T14: 11 | U14: 20 | V14: =SUM(R14:U14) -> 76 | W14: 25 | X14: 30 | AA14: =SUM(W14:Z14) -> 55
B15: EBIT margin | C15: 0.09 | D15: 0.12 | E15: 0.12 | F15: 0.04 | G15: =G14/G6 -> 0.090620032 | H15: 0.12 | I15: 0.12 | J15: 0.09 | K15: 0.09 | L15: =L14/L6 -> 0.10504775 | M15: 0.11 | N15: 0.11 | O15: 0.09 | P15: 0.03 | Q15: =Q14/Q6 -> 0.084134615 | R15: 0.12 | S15: 0.09 | T15: 0.05 | U15: 0.09 | V15: =V14/V6 -> 0.087456847 | W15: 0.11 | X15: 0.13 | AA15: =AA14/AA6 -> 0.12195122
B16: Share of profit(loss) from associates | C16: 1 | D16: 2 | E16: 2 | F16: 1 | G16: =SUM(C16:F16) -> 6 | H16: 1 | I16: 1 | J16: 2 | K16: 2 | L16: =SUM(H16:K16) -> 6 | M16: 0 | N16: 1 | O16: 2 | P16: -1 | Q16: =SUM(M16:P16) -> 2 | R16: 1 | S16: 0 | T16: 0 | U16: 0 | V16: =SUM(R16:U16) -> 1 | W16: 0 | X16: 1 | AA16: =SUM(W16:Z16) -> 1
B17: Financial items | C17: 4 | D17: -23 | E17: -23 | F17: 22 | G17: =SUM(C17:F17) -> -20 | H17: -9 | I17: 0 | J17: -6 | K17: -4 | L17: =SUM(H17:K17) -> -19 | M17: -10 | N17: -4 | O17: 3 | P17: -26 | Q17: =SUM(M17:P17) -> -37 | R17: 18 | S17: 19 | T17: -4 | U17: -8 | V17: =SUM(R17:U17) -> 25 | W17: 1 | X17: -5 | AA17: =SUM(W17:Z17) -> -4
B18: Tax income/(expense) | C18: -4 | D18: 0 | E18: 1 | F18: -12 | G18: =SUM(C18:F18) -> -15 | H18: -3 | I18: -5 | J18: -3 | K18: -9 | L18: =SUM(H18:K18) -> -20 | M18: -2 | N18: -5 | O18: -5 | P18: 1 | Q18: =SUM(M18:P18) -> -11 | R18: -10 | S18: -8 | T18: -2 | U18: -17 | V18: =SUM(R18:U18) -> -37 | W18: -6 | X18: -6 | AA18: =SUM(W18:Z18) -> -12
B19: Profit/(loss) | C19: 15 | D19: -1 | E19: -2 | F19: 17 | G19: =SUM(C19:F19) -> 29 | H19: 11 | I19: 19 | J19: 10 | K19: 5 | L19: =SUM(H19:K19) -> 45 | M19: 8 | N19: 17 | O19: 19 | P19: -21 | Q19: =SUM(M19:P19) -> 23 | R19: 35 | S19: 31 | T19: 6 | U19: -4 | V19: =SUM(R19:U19) -> 68 | W19: 20 | X19: 21 | AA19: =SUM(W19:Z19) -> 41
B20: Profit margin | C20: 0.09 | D20: -0.01 | E20: -0.01 | F20: 0.1 | G20: =G19/G6 -> 0.046104928 | H20: 0.06 | I20: 0.1 | J20: 0.06 | K20: 0.03 | L20: =L19/L6 -> 0.061391542 | M20: 0.04 | N20: 0.08 | O20: 0.09 | P20: -0.1 | Q20: =Q19/Q6 -> 0.027644231 | R20: 0.16 | S20: 0.15 | T20: 0.03 | U20: 0.03 | V20: =V19/V6 -> 0.078250863 | W20: 0.09 | X20: 0.09 | AA20: =AA19/AA6 -> 0.090909091
B22: New Energy
B23: Total income | C23: 93 | D23: 81 | E23: 76 | F23: 83 | G23: =SUM(C23:F23) -> 333 | H23: 75 | I23: 74 | J23: 74 | K23: 68 | L23: =SUM(H23:K23) -> 291 | M23: 69 | N23: 80 | O23: 78 | P23: 75 | Q23: =SUM(M23:P23) -> 302 | R23: 82 | S23: 100 | T23: 87 | U23: 89 | V23: =SUM(R23:U23) -> 358 | W23: 84 | X23: 91 | AA23: =SUM(W23:Z23) -> 175
B24: y/y | H24: =(H23-C23)/C23 -> -0.19354839 | I24: =(I23-D23)/D23 -> -0.086419753 | J24: =(J23-E23)/E23 -> -0.026315789 | K24: =(K23-F23)/F23 -> -0.18072289 | L24: =(L23-G23)/G23 -> -0.12612613 | M24: =(M23-H23)/H23 -> -0.08 | N24: =(N23-I23)/I23 -> 0.081081081 | O24: =(O23-J23)/J23 -> 0.054054054 | ... AA24: =(AA23-V23)/V23 -> -0.51117318
B25: Of which NorSea (energy infrastructure) | C25: 84 | D25: 70 | E25: 64 | F25: 74 | G25: =SUM(C25:F25) -> 292 | H25: 69 | I25: 73 | J25: 74 | K25: 67 | L25: =SUM(H25:K25) -> 283 | M25: 68 | N25: 79 | O25: 78 | P25: 75 | Q25: =SUM(M25:P25) -> 300 | R25: 81 | S25: 99 | T25: 87 | U25: 88 | V25: =SUM(R25:U25) -> 355 | W25: 83 | X25: 90 | AA25: =SUM(W25:Z25) -> 173
B26: Of which other activities/eliminations | C26: 9 | D26: 11 | E26: 11 | F26: 10 | G26: =SUM(C26:F26) -> 41 | H26: 5 | I26: 1 | J26: 0 | K26: 1 | L26: =SUM(H26:K26) -> 7 | M26: 1 | N26: 1 | O26: 0 | P26: 0 | Q26: =SUM(M26:P26) -> 2 | R26: 1 | S26: 1 | T26: 1 | U26: 1 | V26: =SUM(R26:U26) -> 4 | W26: 1 | X26: 1 | AA26: =SUM(W26:Z26) -> 2
B27: EBITDA | C27: 31 | D27: 15 | E27: 13 | F27: 15 | G27: =SUM(C27:F27) -> 74 | H27: 12 | I27: 11 | J27: 14 | K27: 13 | L27: =SUM(H27:K27) -> 50 | M27: 12 | N27: 17 | O27: 15 | P27: 16 | Q27: =SUM(M27:P27) -> 60 | R27: 15 | S27: 21 | T27: 21 | U27: 22 | V27: =SUM(R27:U27) -> 79 | W27: 21 | X27: 25 | AA27: =SUM(W27:Z27) -> 46
B28: EBITDA margin | C28: 0.34 | D28: 0.18 | E28: 0.17 | F28: 0.18 | G28: =G27/G23 -> 0.22222222 | H28: 0.16 | I28: 0.15 | J28: 0.19 | K28: 0.19 | L28: =L27/L23 -> 0.17182131 | M28: 0.17 | N28: 0.21 | O28: 0.19 | P28: 0.21 | Q28: =Q27/Q23 -> 0.1986755 | R28: 0.19 | S28: 0.21 | T28: 0.24 | U28: 0.25 | V28: =V27/V23 -> 0.22067039 | W28: 0.25 | X28: 0.28 | AA28: =AA27/AA23 -> 0.26285714
B29: Operating profit/EBIT | C29: 22 | D29: 10 | E29: 7 | F29: 8 | G29: =SUM(C29:F29) -> 47 | H29: 6 | I29: 5 | J29: 7 | K29: 5 | L29: =SUM(H29:K29) -> 23 | M29: 4 | N29: 9 | O29: 7 | P29: 9 | Q29: =SUM(M29:P29) -> 29 | R29: 9 | S29: 11 | T29: 12 | U29: 12 | V29: =SUM(R29:U29) -> 44 | W29: 10 | X29: 14 | AA29: =SUM(W29:Z29) -> 24
B30: EBIT margin | C30: 0.24 | D30: 0.12 | E30: 0.09 | F30: 0.1 | G30: =G29/G23 -> 0.14114114 | H30: 0.08 | I30: 0.06 | J30: 0.1 | K30: 0.07 | L30: =L29/L23 -> 0.079037801 | M30: 0.06 | N30: 0.11 | O30: 0.09 | P30: 0.11 | Q30: =Q29/Q23 -> 0.09602649 | R30: 0.11 | S30: 0.11 | T30: 0.14 | U30: 0.14 | V30: =V29/V23 -> 0.12290503 | W30: 0.12 | X30: 0.16 | AA30: =AA29/AA23 -> 0.13714286
B31: Share of profit(loss) from associates | C31: 2 | D31: 3 | E31: 3 | F31: 1 | G31: =SUM(C31:F31) -> 9 | H31: 2 | I31: 1 | J31: 4 | K31: 3 | L31: =SUM(H31:K31) -> 10 | M31: 3 | N31: 3 | O31: 1 | P31: -1 | Q31: =SUM(M31:P31) -> 6 | R31: 4 | S31: 10 | T31: 4 | U31: 10 | V31: =SUM(R31:U31) -> 28 | W31: -2 | X31: 37 | AA31: =SUM(W31:Z31) -> 35
B32: Of which NorSea (energy infrastructure) | E32: 2 | G32: =SUM(C32:F32) -> 2 | I32: 1 | J32: 1 | K32: 1 | L32: =SUM(H32:K32) -> 3 | M32: 2 | N32: 3 | O32: 2 | P32: 0 | Q32: =SUM(M32:P32) -> 7 | R32: 2 | S32: 2 | V32: =SUM(R32:U32) -> 4 | AA32: =SUM(W32:Z32) -> 0
B33: Of which other activities/eliminations | E33: 1 | G33: =SUM(C33:F33) -> 1 | I33: 0 | J33: 2 | K33: 2 | L33: =SUM(H33:K33) -> 4 | M33: 1 | N33: 0 | O33: -1 | P33: -1 | Q33: =SUM(M33:P33) -> -1 | R33: 2 | S33: 8 | V33: =SUM(R33:U33) -> 10 | AA33: =SUM(W33:Z33) -> 0
B34: Financial items | C34: -4 | D34: -3 | E34: -4 | F34: -6 | G34: =SUM(C34:F34) -> -17 | H34: -4 | I34: -4 | J34: -2 | K34: -9 | L34: =SUM(H34:K34) -> -19 | M34: 0 | N34: 1 | O34: -8 | P34: 1 | Q34: =SUM(M34:P34) -> -6 | R34: -12 | S34: -7 | T34: -4 | U34: -1 | V34: =SUM(R34:U34) -> -24 | W34: -4 | X34: -2 | AA34: =SUM(W34:Z34) -> -6
B35: Tax income/(expense) | C35: 1 | D35: 0 | E35: 0 | F35: -3 | G35: =SUM(C35:F35) -> -2 | H35: 0 | I35: 0 | J35: -1 | K35: -1 | L35: =SUM(H35:K35) -> -2 | M35: 0 | N35: 1 | O35: -1 | P35: -2 | Q35: =SUM(M35:P35) -> -2 | R35: 0 | S35: 0 | T35: 0 | U35: -5 | V35: =SUM(R35:U35) -> -5 | W35: 0 | X35: -1 | AA35: =SUM(W35:Z35) -> -1
B36: Profit/(loss) | C36: 21 | D36: 9 | E36: 6 | F36: 2 | G36: =SUM(C36:F36) -> 38 | H36: 3 | I36: 2 | J36: 8 | K36: -1 | L36: =SUM(H36:K36) -> 12 | M36: 7 | N36: 14 | O36: -2 | P36: 7 | Q36: =SUM(M36:P36) -> 26 | R36: 1 | S36: 15 | T36: 12 | U36: 16 | V36: =SUM(R36:U36) -> 44 | W36: 4 | X36: 48 | AA36: =SUM(W36:Z36) -> 52
B37: Profit margin | C37: 0.23 | D37: 0.11 | E37: 0.08 | F37: 0.02 | G37: =G36/G23 -> 0.11411411 | H37: 0.04 | I37: 0.03 | J37: 0.11 | K37: -0.01 | L37: =L36/L23 -> 0.041237113 | M37: 0.1 | N37: 0.18 | O37: -0.02 | P37: 0.1 | Q37: =Q36/Q23 -> 0.086092715 | R37: 0.02 | S37: 0.15 | T37: 0.14 | U37: 0.18 | V37: =V36/V23 -> 0.12290503 | W37: 0.05 | X37: 0.53 | AA37: =AA36/AA23 -> 0.29714286
B39: Strategic holdings and investments
B40: Total income | C40: -2 | D40: 4 | E40: 4 | F40: 4 | G40: =SUM(C40:F40) -> 10 | H40: 5 | I40: 3 | J40: 4 | K40: 3 | L40: =SUM(H40:K40) -> 15 | M40: 5 | N40: 4 | O40: 4 | P40: 4 | Q40: =SUM(M40:P40) -> 17 | R40: 4 | S40: 4 | T40: 4 | U40: 4 | V40: =SUM(R40:U40) -> 16 | W40: 4 | X40: 4 | AA40: =SUM(W40:Z40) -> 8
B41: y/y | H41: =(H40-C40)/C40 -> -3.5 | I41: =(I40-D40)/D40 -> -0.25 | J41: =(J40-E40)/E40 -> 0 | K41: =(K40-F40)/F40 -> -0.25 | L41: =(L40-G40)/G40 -> 0.5 | M41: =(M40-H40)/H40 -> 0 | N41: =(N40-I40)/I40 -> 0.33333333 | O41: =(O40-J40)/J40 -> 0 | ... AA41: =(AA40-V40)/V40 -> -0.5
B42: Of which operating revenue | C42: 4 | D42: 5 | E42: 4 | F42: 4 | G42: =SUM(C42:F42) -> 17 | H42: 5 | I42: 3 | J42: 4 | K42: 3 | L42: =SUM(H42:K42) -> 15 | M42: 5 | N42: 4 | O42: 4 | P42: 4 | Q42: =SUM(M42:P42) -> 17 | R42: 4 | S42: 4 | T42: 4 | U42: 4 | V42: =SUM(R42:U42) -> 16 | W42: 4 | X42: 4 | AA42: =SUM(W42:Z42) -> 8
B43: Of which other gains/(loss) | C43: -7 | D43: -1 | E43: 0 | F43: 0 | G43: =SUM(C43:F43) -> -8 | H43: 0 | I43: 0 | J43: 0 | K43: 0 | L43: =SUM(H43:K43) -> 0 | M43: 0 | N43: 0 | O43: 0 | P43: 0 | Q43: =SUM(M43:P43) -> 0 | R43: 0 | S43: 0 | T43: 0 | U43: 0 | V43: =SUM(R43:U43) -> 0 | W43: 0 | X43: 0 | AA43: =SUM(W43:Z43) -> 0
B44: EBITDA | C44: -8 | D44: -1 | E44: -1 | F44: -6 | G44: =SUM(C44:G44) -> 0 | H44: 0 | I44: -2 | J44: -2 | K44: -3 | L44: =SUM(H44:L44) -> 0 | M44: -1 | N44: -2 | O44: -2 | P44: -3 | Q44: =SUM(M44:Q44) -> 0 | R44: -1 | S44: -1 | T44: -3 | U44: -5 | V44: =SUM(R44:V44) -> 0 | W44: -2 | X44: -2 | AA44: =SUM(W44:AA44) -> 0
...

Sheet SOTP
A4: P/NAV | B4: =Modell!B4/SOTP!G26 -> 0.64208506
A7: Business | B7: EBITDA 26E USD | D7: Multippel | E7: Valutakurs | F7: Verdi NOK | G7: Per aksje
A8: Maritime services | B8: 140000000 | D8: 10 | E8: 9.5 | F8: =(B8*E8)*D8 -> 13300000000 | G8: =F8/$B$26 -> 298.34006
A9: New energy | B9: 92000000 | D9: 12 | E9: 9.5 | F9: =(B9*E9)*D9 -> 10488000000 | G9: =F9/$B$26 -> 235.26245
A10: Holding | B10: -8000000 | D10: 6 | E10: 9.5 | F10: =(B10*E10)*D10 -> -456000000 | G10: =F10/$B$26 -> -10.228802
A11: Total | G11: =SUM(G8:G10) -> 523.37371
A13: Strategic holdings | B13: Antall aksjer | D13: Aksjekurs | E13: Valutakurs | F13: Verdi NOK | G13: Per aksje
A14: Wallenius wilhelmsen | B14: 160210000 | D14: 182.5 | E14: 1 | F14: =B14*D14 -> 29238325000 | G14: =F14/$B$26 -> 655.86193
A15: Treasure/Hyundai Glovis | B15: 8250000 | D15: 196900 | E15: =B30 -> 0.007 | F15: =(B15*D15)*E15 -> 11370975000 | G15: =F15/$B$26 -> 255.06898
A16: Reach Subsea | B16: 96844009 | D16: 6.6 | E16: 1 | F16: =(B16*D16) -> 6.3917046e+08 | G16: =F16/$B$26 -> 14.337606
A17: Total | G17: =SUM(G14:G16) -> 925.26852
A19: Debt | F19: Verdi NOK | G19: Per aksje
F20: =Modell!B7*1000000 -> 2573200000 | G20: =F20/B26 -> 57.720951
A22: Cash | F22: Verdi NOK | G22: Per aksje
D23: 864500000 | F23: =Modell!B8*1000000+D23 -> 3465270000 | G23: =F23/B26 -> 77.731494
A25: Total | B25: Total shares | F25: SUM NOK | G25: Per aksje
B26: 44580000 | F26: =SUM(F8:F10)+SUM(F14:F16)-F20+F23 -> 6.547254e+10 | G26: =F26/B26 -> 1468.6528
A28: Valuta
A29: USD/NOK | B29: 9.51
A30: KRW/NOK | B30: 0.007
A31: AUD/NOK | B31: 6.75
A91: Maritime services | B91: =G8 -> 298.34006
A92: New energy | B92: =G9 -> 235.26245
A93: Holding | B93: =G10 -> -10.228802
A94: Business | B94: =SUM(B91:B93) -> 523.37371
A96: Wallenius wilhelmsen | B96: =G14 -> 655.86193
A97: Treasure/Hyundai Glovis | B97: =G15 -> 255.06898
A98: Reach Subsea | B98: =G16 -> 14.337606
A99: Stratetic holdings | B99: =SUM(B96:B98) -> 925.26852
A101: Debt | B101: =-G20 -> -57.720951
A102: Cash | B102: =G23 -> 77.731494
A104: Total | B104: =B94+B99+B101+B102 -> 1468.6528

Sheet Nøkkeltall
D4: 2026 | E4: 2027 | F4: 2028
C5: EV/EBIT | D5: =Modell!$B$9/(Modell!AG11*Modell!$B$11) -> 32.635913 | E5: =Modell!$B$9/(Modell!AH11*Modell!$B$11) -> 31.380685 | F5: =Modell!$B$9/(Modell!AI11*Modell!$B$11) -> 30.173736
C6: P/E | D6: =Modell!$B$4/Modell!AG19 -> 8.5676333 | E6: =Modell!$B$4/Modell!AH19 -> 8.8102652 | F6: =Modell!$B$4/Modell!AI19 -> 9.0452588
