Workbook

Sheet Info
K1: Under construction (Investor update 15.09.25)
A4: "Farm-down" uttrykk for når Ørsted selger seg ned i sine assets
A5: for å finansiere andre prosjekter | G5: Guidance Q225
G6: EBITDA: | H6: 24-27 DKK billion
G7: Gross investments: | H7: 50-54 DKK billion
G9: EBITDA 26 | H9: > 28 BDKK
G10: EBITDA 27 | H10: > 32 BDKK
G11: Gross capex 25-27 | H11: 145 BDKK
A19: Press releases:
A20: 22.09.25: US District court of Columbia godkjente at ørsted kunne fortsette arbeide med Revolution Wind
A21: 25.08.25: Ørsted bekrefter at de fortsetter med den planlagte emisjonen.
A22: 5. sep er generalforsamling her skal de godkjenne og etter dette gi mer info om emi.
A23: 23.08.25: 22. aug fikk Ørsted en stoppordre fra USA om å stoppe byggingen av Revolution Wind
A24: 11.08.25: Ørsted henter 60mrd DKK i en emisjon med danske stat som garantist med 50,1%
A25: Grunnet uroligeheter i USA er det ikke mulig å utføre "the planned partial divestment and financing".
A26: De skal egentlig selge seg ned i Sunrise, noe de ikke har fått til. Aksjen falt 30%
A27: 10.07.2025: Ørsted sikrer finansiering på Greater Changua 2. Pakke som innebærer 25 banker for å sikre 20mrd DKK
A28: 07.05.25: Ørsted har vedtatt å droppe Hornsea 4 i sin gjeldende form. Siden de fikk lisense i sep24 har kostnadene økt, økning i renter og økende risiko
A29: 01.05.25: Ørsted har utført en "Farm-down" for en 24,5% andel i West of Duddon sands Offshore. Får inn 4mrd DKK
A32: Kapasitet offshore vind | D32: Kapasitet Onshore vind
A34: Land | B34: GW | D34: Land | E34: GW
A35: UK | B35: 13.2 | D35: UK | E35: 0.062
A36: Poland | B36: 2.75 | D36: Germany | E36: 0.05
A37: Germany | B37: 2.51 | D37: USA | E37: 3
A38: Taiwan | B38: 1.95
A39: USA | B39: 1.79
A40: Danmark | B40: 0.94

Sheet Modell
A3: Kapitalstruktur | C3: DKKm | D3: Q122 | E3: Q222 | F3: Q322 | G3: Q422 | H3: Q123 | I3: Q223 | J3: Q323 | K3: Q423 | L3: Q124 | M3: Q224 | N3: Q324 | O3: Q424 | P3: Q125 | Q3: Q225 | R3: Q325 | S3: Q425 | V3: FY 2015 | W3: FY 2016 | X3: FY 2017 | Y3: FY 2018 | Z3: FY 2019 | AA3: FY 2020 | AB3: FY 2021 | AC3: FY 2022 | AD3: FY 2023 | AE3: FY 2024 | AF3: FY 2025 | AG3: FY 2026 | AH3: FY 2027 | AI3: FY 2028 | AJ3: FY 2029 | AK3: FY 2030 | AL3: FY 2031 | AM3: FY 2032 | AN3: FY 2033 | AO3: FY 2034 | AP3: FY 2035
A4: Price | B4: 120 | C4: Revenues | D4: 33762 | E4: 26295 | F4: 36541 | G4: =132277-D4-E4-F4 -> 35679 | H4: 29369 | I4: 16477 | J4: 17441 | K4: =79255-H4-I4-J4 -> 15968 | L4: 19168 | M4: 15023 | N4: 15766 | O4: =71034-L4-M4-N4 -> 21077 | P4: 20705 | Q4: 17135 | V4: 66708 | W4: 57393 | X4: 59709 | Y4: 75520 | Z4: 70398 | AA4: 50151 | AB4: 77673 | AC4: 132277 | AD4: 79255 | AE4: 71034 | AF4: =AE4*1.16 -> 82399.44 | AG4: =AF4*1.1 -> 90639.384 | AH4: =AG4*1.1 -> 99703.322 | AI4: =AH4*1.1 -> 109673.65 | AJ4: =AI4*1.1 -> 120641.02 | AK4: =AJ4*1.1 -> 132705.12 | AL4: =AK4*1.1 -> 145975.63 | AM4: =AL4*1.1 -> 160573.2 | AN4: =AM4*1.1 -> 176630.52 | ... AP4: =AO4*1.1 -> 213722.93
A5: S/O | B5: 1321.1976 | C5: Cost of sales | D5: -24547 | E5: -19289 | F5: -28503 | G5: =-97163-D5-E5-F5 -> -24824 | H5: -20344 | I5: -11658 | J5: -10334 | K5: =-46624-H5-I5-J5 -> -4288 | L5: -9409 | M5: -7918 | N5: -8197 | O5: =-35963-L5-M5-N5 -> -10439 | P5: -10006 | Q5: -11292 | V5: -51541 | W5: -37622 | X5: -40694 | Y5: -54018 | Z5: -42836 | AA5: -25784 | AB5: -53110 | AC5: -97163 | AD5: -46624 | AE5: -35963 | AF5: =AF4*-0.51 -> -42023.714 | AG5: =AG4*-0.5 -> -45319.692 | AH5: =AH4*-0.5 -> -49851.661 | AI5: =AI4*-0.5 -> -54836.827 | AJ5: =AJ4*-0.5 -> -60320.51 | AK5: =AK4*-0.5 -> -66352.561 | AL5: =AL4*-0.5 -> -72987.817 | AM5: =AM4*-0.5 -> -80286.599 | AN5: =AN4*-0.5 -> -88315.259 | ... AP5: =AP4*-0.5 -> -106861.46
A6: MC DKKm | B6: =B4*B5 -> 158543.71 | C6: Gross profit | D6: =SUM(D4:D5) -> 9215 | E6: =SUM(E4:E5) -> 7006 | F6: =SUM(F4:F5) -> 8038 | G6: =SUM(G4:G5) -> 10855 | H6: =SUM(H4:H5) -> 9025 | I6: =SUM(I4:I5) -> 4819 | J6: =SUM(J4:J5) -> 7107 | K6: =SUM(K4:K5) -> 11680 | ... Q6: =SUM(Q4:Q5) -> 5843 | V6: =SUM(V4:V5) -> 15167 | W6: =SUM(W4:W5) -> 19771 | X6: =SUM(X4:X5) -> 19015 | Y6: =SUM(Y4:Y5) -> 21502 | Z6: =SUM(Z4:Z5) -> 27562 | AA6: =SUM(AA4:AA5) -> 24367 | AB6: =SUM(AB4:AB5) -> 24563 | AC6: =SUM(AC4:AC5) -> 35114 | ... AP6: =SUM(AP4:AP5) -> 106861.46
A7: Cash DKKm | B7: 45000 | C7: Other external expenses | D7: -1175 | E7: -1673 | F7: -1777 | G7: =-7049-D7-E7-F7 -> -2424 | H7: -1629 | I7: -1435 | J7: -1606 | K7: =-7406-H7-I7-J7 -> -2736 | L7: -1562 | M7: -1908 | N7: -2279 | O7: =-8697-L7-M7-N7 -> -2948 | P7: -1921 | Q7: -2273 | V7: -3263 | W7: -4078 | X7: -4241 | Y7: -5865 | Z7: -6091 | AA7: -5774 | AB7: -5760 | AC7: -7049 | AD7: -7406 | AE7: -8697 | AF7: =AE7*1.03 -> -8957.91 | AG7: =AF7*1.1 -> -9853.701 | AH7: =AG7*1.06 -> -10444.923 | AI7: =AH7*1.1 -> -11489.415 | AJ7: =AI7*1.1 -> -12638.357 | AK7: =AJ7*1.1 -> -13902.193 | AL7: =AK7*1.1 -> -15292.412 | AM7: =AL7*1.1 -> -16821.653 | AN7: =AM7*1.1 -> -18503.818 | AO7: =AN7*1.1 -> -20354.2 | AP7: =AO7*1.1 -> -22389.62
A8: Debt DKKm | B8: =Q64+Q71 -> 82748 | C8: Employee costs | D8: -1166 | E8: -1268 | F8: -1367 | G8: =-5278-D8-E8-F8 -> -1477 | H8: -1540 | I8: -1782 | J8: -1421 | K8: =-6374-H8-I8-J8 -> -1631 | L8: -1881 | M8: -1430 | N8: -1586 | O8: =-6532-L8-M8-N8 -> -1635 | P8: -1614 | Q8: -1514 | V8: -3310 | W8: -3088 | X8: -3197 | Y8: -3126 | Z8: -3952 | AA8: -4283 | AB8: -4289 | AC8: -5278 | AD8: -6374 | AE8: -6532 | AF8: =AE8*1.03 -> -6727.96 | AG8: =AF8*1.1 -> -7400.756 | AH8: =AG8*1.06 -> -7844.8014 | AI8: =AH8*1.1 -> -8629.2815 | AJ8: =AI8*1.1 -> -9492.2096 | AK8: =AJ8*1.1 -> -10441.431 | AL8: =AK8*1.1 -> -11485.574 | AM8: =AL8*1.1 -> -12634.131 | AN8: =AM8*1.1 -> -13897.544 | AO8: =AN8*1.1 -> -15287.299 | AP8: =AO8*1.1 -> -16816.028
A9: EV DKKm | B9: =B6-B7+B8 -> 196291.71 | C9: Share of JV | D9: 55 | E9: 1 | F9: -12 | G9: =-114-D9-E9-F9 -> -158 | H9: 62 | I9: -25 | J9: -7 | K9: =-55-H9-I9-J9 -> -85 | L9: 4 | M9: -26 | N9: -38 | O9: =-68-L9-M9-N9 -> -8 | P9: 24 | Q9: 3 | V9: 112 | W9: 25 | X9: -119 | Y9: -6 | Z9: -20 | AA9: 71 | AB9: -17 | AC9: 114 | AD9: -55 | AE9: -68 | AF9: =AE9*1 -> -68 | AG9: =AF9*1.05 -> -71.4 | AH9: =AG9*1.05 -> -74.97 | AI9: =AH9*1.05 -> -78.7185 | AJ9: =AI9*1.05 -> -82.654425 | AK9: =AJ9*1.05 -> -86.787146 | AL9: =AK9*1.05 -> -91.126504 | AM9: =AL9*1.05 -> -95.682829 | AN9: =AM9*1.05 -> -100.46697 | ... AP9: =AO9*1.05 -> -110.76483
C10: Other operating income | D10: 2576 | E10: 857 | F10: 9759 | G10: =14119-D10-E10-F10 -> 927 | H10: 1096 | I10: 2138 | J10: 4949 | K10: =10329-H10-I10-J10 -> 2146 | L10: 1300 | M10: 1370 | N10: 920 | O10: =5298-L10-M10-N10 -> 1708 | P10: 1864 | Q10: 4337 | V10: 1575 | W10: 4867 | X10: 11665 | Y10: 16275 | Z10: 1781 | AA10: 2620 | AB10: 10185 | AC10: 14119 | AD10: 10329 | AE10: 5298 | AF10: 0 | AG10: 0 | AH10: 0 | AI10: 0 | AJ10: 0 | AK10: 0 | AL10: 0 | AM10: 0 | AN10: 0 | AO10: 0 | AP10: 0
A11: P/B | C11: Other opex | D11: -76 | E11: -1308 | F11: -2324 | G11: =-4963-D11-E11-F11 -> -1255 | H11: -104 | I11: -395 | J11: 151 | K11: =-10408-H11-I11-J11 -> -10060 | L11: -132 | M11: 1459 | N11: 4962 | O11: =6887-L11-M11-N11 -> 598 | P11: -181 | Q11: 248 | V11: -393 | W11: -558 | X11: -549 | Y11: -289 | Z11: -260 | AA11: -403 | AB11: -386 | AC11: -4963 | AD11: -10408 | AE11: 6887 | AF11: 0 | AG11: 0 | AH11: 0 | AI11: 0 | AJ11: 0 | AK11: 0 | AL11: 0 | AM11: 0 | AN11: 0 | AO11: 0 | AP11: 0
A12: =B4/A13 -> 1.6274414 | C12: EBITDA | D12: =SUM(D6:D11) -> 9429 | E12: =SUM(E6:E11) -> 3615 | F12: =SUM(F6:F11) -> 12317 | G12: =SUM(G6:G11) -> 6468 | H12: =SUM(H6:H11) -> 6910 | I12: =SUM(I6:I11) -> 3320 | J12: =SUM(J6:J11) -> 9173 | K12: =SUM(K6:K11) -> -686 | ... Q12: =SUM(Q6:Q11) -> 6644 | V12: =SUM(V6:V11) -> 9888 | W12: =SUM(W6:W11) -> 16939 | X12: =SUM(X6:X11) -> 22574 | Y12: =SUM(Y6:Y11) -> 28491 | Z12: =SUM(Z6:Z11) -> 19020 | AA12: =SUM(AA6:AA11) -> 16598 | AB12: =SUM(AB6:AB11) -> 24296 | AC12: =SUM(AC6:AC11) -> 32057 | ... AP12: =SUM(AP6:AP11) -> 67545.05
A13: =Q60/B5 -> 73.735375 | C13: A/I | D13: -2128 | E13: -2304 | F13: -2530 | G13: =-12283-D13-E13-F13 -> -5321 | H13: -2438 | I13: =-2454 -> -2454 | J13: =-2537-28422 -> -30959 | K13: =-9795-26775-15563-H13-I13-J13 -> -16282 | L13: =-2423+761 -> -1662 | M13: =-2683-3913 -> -6596 | N13: =-2548-284 -> -2832 | O13: =-10225-15563-L13-M13-N13 -> -14698 | P13: =-2555+272 -> -2283 | Q13: =-2435-20 -> -2455 | V13: -6857 | W13: -5232 | X13: -6284 | Y13: -5375 | Z13: -7432 | AA13: -7588 | AB13: -8101 | AC13: -12283 | AD13: =-9795-26775 -> -36570 | AE13: =-10225-15563 -> -25788 | AF13: -14000 | AG13: -10000 | AH13: -10000 | AI13: -10000 | AJ13: -10000 | AK13: -10000 | AL13: -10000 | AM13: -10000 | AN13: -10000 | AO13: -10000 | AP13: -10000
C14: EBIT | D14: =SUM(D12:D13) -> 7301 | E14: =SUM(E12:E13) -> 1311 | F14: =SUM(F12:F13) -> 9787 | G14: =SUM(G12:G13) -> 1147 | H14: =SUM(H12:H13) -> 4472 | I14: =SUM(I12:I13) -> 866 | J14: =SUM(J12:J13) -> -21786 | K14: =SUM(K12:K13) -> -16968 | ... Q14: =SUM(Q12:Q13) -> 4189 | V14: =SUM(V12:V13) -> 3031 | W14: =SUM(W12:W13) -> 11707 | X14: =SUM(X12:X13) -> 16290 | Y14: =SUM(Y12:Y13) -> 23116 | Z14: =SUM(Z12:Z13) -> 11588 | AA14: =SUM(AA12:AA13) -> 9010 | AB14: =SUM(AB12:AB13) -> 16195 | AC14: =SUM(AC12:AC13) -> 19774 | ... AP14: =SUM(AP12:AP13) -> 57545.05
A15: 1000 MW | C15: Divestment of enterprises | D15: 108 | E15: 67 | F15: 124 | G15: =331-D15-E15-F15 -> 32 | H15: 169 | I15: 159 | J15: -50 | K15: =234-H15-I15-J15 -> -44 | L15: -52 | M15: -7 | N15: 14 | O15: =-11-L15-M15-N15 -> 34 | P15: 87 | Q15: 124 | V15: 56 | W15: 1250 | X15: -139 | Y15: 127 | Z15: -63 | AA15: 10831 | AB15: -742 | AC15: 331 | AD15: 234 | AE15: -11 | AF15: 422 | AG15: 0 | AH15: 0 | AI15: 0 | AJ15: 0 | AK15: 0 | AL15: 0 | AM15: 0 | AN15: 0 | AO15: 0 | AP15: 0
A16: 1 GW | C16: Share of JV | D16: 0 | E16: 1 | F16: 1 | G16: 360 | H16: 13 | I16: 9 | J16: 9 | K16: =36-H16-I16-J16 -> 5 | L16: 7 | M16: 10 | N16: 13 | O16: =37-L16-M16-N16 -> 7 | P16: 11 | Q16: 7 | V16: -8 | W16: -8 | X16: -10 | Y16: 1 | Z16: 2 | AA16: 7 | AB16: -10 | AC16: 40 | AD16: 36 | AE16: 37 | AF16: 36 | AG16: 0 | AH16: 0 | AI16: 0 | AJ16: 0 | AK16: 0 | AL16: 0 | AM16: 0 | AN16: 0 | AO16: 0 | AP16: 0
C17: Financial income | D17: 1063 | E17: 2028 | F17: 4685 | G17: =15514-D17-E17-F17 -> 7738 | H17: 3086 | I17: 835 | J17: 1360 | K17: =12379-H17-I17-J17 -> 7098 | L17: 1575 | M17: 2854 | N17: 1545 | O17: =8590-L17-M17-N17 -> 2616 | P17: 1819 | Q17: 2654 | V17: 9297 | W17: 8179 | X17: 4253 | Y17: 3179 | Z17: 7718 | AA17: 5779 | AB17: 4380 | AC17: 15514 | AD17: 12379 | AE17: 8590 | AF17: 8946 | AG17: =AF17*1.1 -> 9840.6 | AH17: =AG17*1.05 -> 10332.63 | AI17: =AH17*1.05 -> 10849.262 | AJ17: =AI17*1.05 -> 11391.725 | AK17: =AJ17*1.05 -> 11961.311 | AL17: =AK17*1.05 -> 12559.376 | AM17: =AL17*1.05 -> 13187.345 | AN17: =AM17*1.05 -> 13846.712 | AO17: =AN17*1.05 -> 14539.048 | AP17: =AO17*1.05 -> 15266
A18: 1000 GW | C18: Financial expenses | D18: -1911 | E18: -2514 | F18: -4902 | G18: =-18050-D18-E18-F18 -> -8723 | H18: -4605 | I18: -2632 | J18: -1488 | K18: =-13822-H18-I18-J18 -> -5097 | L18: -2922 | M18: -3406 | N18: -2780 | O18: =-12181-L18-M18-N18 -> -3073 | P18: -3386 | Q18: -2985 | V18: -10706 | W18: -8946 | X18: -5295 | Y18: -4457 | Z18: -8853 | AA18: -8303 | AB18: -6546 | AC18: -18050 | AD18: -13822 | AE18: -12181 | AF18: -12742 | AG18: =AF18*1.1 -> -14016.2 | AH18: =AG18*1.05 -> -14717.01 | AI18: =AH18*1.05 -> -15452.861 | AJ18: =AI18*1.05 -> -16225.504 | AK18: =AJ18*1.05 -> -17036.779 | AL18: =AK18*1.05 -> -17888.618 | AM18: =AL18*1.05 -> -18783.049 | AN18: =AM18*1.05 -> -19722.201 | AO18: =AN18*1.05 -> -20708.311 | AP18: =AO18*1.05 -> -21743.727
A19: 1 TW | C19: PTP | D19: =SUM(D14:D18) -> 6561 | E19: =SUM(E14:E18) -> 893 | F19: =SUM(F14:F18) -> 9695 | G19: =SUM(G14:G18) -> 554 | H19: =SUM(H14:H18) -> 3135 | I19: =SUM(I14:I18) -> -763 | J19: =SUM(J14:J18) -> -21955 | K19: =SUM(K14:K18) -> -15006 | ... Q19: =SUM(Q14:Q18) -> 3989 | V19: =SUM(V14:V18) -> 1670 | W19: =SUM(W14:W18) -> 12182 | X19: =SUM(X14:X18) -> 15099 | Y19: =SUM(Y14:Y18) -> 21966 | Z19: =SUM(Z14:Z18) -> 10392 | AA19: =SUM(AA14:AA18) -> 17324 | AB19: =SUM(AB14:AB18) -> 13277 | AC19: =SUM(AC14:AC18) -> 17609 | ... AP19: =SUM(AP14:AP18) -> 51067.324
C20: Tax | D20: -860 | E20: -624 | F20: -340 | G20: =-2613-D20-E20-F20 -> -789 | H20: 67 | I20: 225 | J20: -607 | K20: =-1156-H20-I20-J20 -> -841 | L20: -1825 | M20: -1103 | N20: -339 | O20: =-2590-L20-M20-N20 -> 677 | P20: -232 | Q20: -638 | V20: 184 | W20: -1715 | X20: -1778 | Y20: -3700 | Z20: -3101 | AA20: -1776 | AB20: -2390 | AC20: -2613 | AD20: -1156 | AE20: -2590 | AF20: =AF19*-0.2 -> -1456.7711 | AG20: =AG19*-0.2 -> -2763.647 | AH20: =AH19*-0.2 -> -3420.5174 | AI20: =AI19*-0.2 -> -4007.1626 | AJ20: =AJ19*-0.2 -> -4654.702 | AK20: =AK19*-0.2 -> -5369.3366 | AL20: =AL19*-0.2 -> -6157.8928 | AM20: =AM19*-0.2 -> -7027.8857 | ... AP20: =AP19*-0.2 -> -10213.465
C21: Net income | D21: =SUM(D19:D20) -> 5701 | E21: =SUM(E19:E20) -> 269 | F21: =SUM(F19:F20) -> 9355 | G21: -335 | H21: =SUM(H19:H20) -> 3202 | I21: =SUM(I19:I20) -> -538 | J21: =SUM(J19:J20) -> -22562 | K21: =SUM(K19:K20) -> -15847 | L21: =SUM(L19:L20) -> 2609 | M21: =SUM(M19:M20) -> -1678 | N21: =SUM(N19:N20) -> 5169 | O21: =SUM(O19:O20) -> -6084 | ... Q21: =SUM(Q19:Q20) -> 3351 | V21: =SUM(V19:V20) -> 1854 | W21: =SUM(W19:W20) -> 10467 | X21: =SUM(X19:X20) -> 13321 | Y21: =SUM(Y19:Y20) -> 18266 | Z21: =SUM(Z19:Z20) -> 7291 | AA21: =SUM(AA19:AA20) -> 15548 | AB21: =SUM(AB19:AB20) -> 10887 | AC21: =SUM(AC19:AC20) -> 14996 | ... AP21: =SUM(AP19:AP20) -> 40853.859 | AQ21: =AP21*(1+$AS$25) -> 40445.32 | AR21: =AQ21*(1+$AS$25) -> 40040.867 | AS21: =AR21*(1+$AS$25) -> 39640.458 | AT21: =AS21*(1+$AS$25) -> 39244.054 | AU21: =AT21*(1+$AS$25) -> 38851.613 | AV21: =AU21*(1+$AS$25) -> 38463.097 | AW21: =AV21*(1+$AS$25) -> 38078.466 | AX21: =AW21*(1+$AS$25) -> 37697.682 | ... EO21: =EN21*(1+$AS$25) -> 14509.69
C22: Share | D22: 420.381 | E22: 420.381 | F22: 420.381 | G22: 420.381 | H22: 420.381 | I22: 420.381 | J22: 420.381 | K22: 420.381 | L22: 420.381 | M22: 420.381 | N22: 420.381 | O22: 420.381 | P22: 420.381 | Q22: 420.381 | R22: 1321.1976 | S22: 1321.1976 | V22: 420.381 | W22: 420.381 | X22: 420.381 | Y22: 420.381 | Z22: 420.381 | AA22: 420.381 | AB22: 420.381 | AC22: 420.381 | AD22: 420.381 | AE22: 420.381 | AF22: 420.381 | AG22: 1321.1976 | AH22: 1321.1976 | AI22: 1321.1976 | AJ22: 1321.1976 | AK22: 1321.1976 | AL22: 1321.1976 | AM22: 1321.1976 | AN22: 1321.1976 | AO22: 1321.1976 | AP22: 1321.1976
C23: EPS | D23: =D21/D22 -> 13.561507 | E23: =E21/E22 -> 0.63989571 | F23: =F21/F22 -> 22.253622 | G23: =G21/G22 -> -0.79689615 | H23: =H21/H22 -> 7.6168999 | I23: =I21/I22 -> -1.2797914 | J23: =J21/J22 -> -53.670361 | K23: =K21/K22 -> -37.696756 | ... S23: =S21/S22 -> 0 | V23: =V21/V22 -> 4.410285 | W23: =W21/W22 -> 24.898842 | X23: =X21/X22 -> 31.687921 | Y23: =Y21/Y22 -> 43.45106 | Z23: =Z21/Z22 -> 17.343791 | AA23: =AA21/AA22 -> 36.985496 | AB23: =AB21/AB22 -> 25.897935 | AC23: =AC21/AC22 -> 35.672402 | ... AP23: =AP21/AP22 -> 30.921839
AR24: Discount | AS24: 0.08
C25: Revenue y/y | H25: =(H4-D4)/D4 -> -0.1301167 | I25: =(I4-E4)/E4 -> -0.37337897 | J25: =(J4-F4)/F4 -> -0.52270053 | K25: =(K4-G4)/G4 -> -0.55245382 | L25: =(L4-H4)/H4 -> -0.34733903 | M25: =(M4-I4)/I4 -> -0.088244219 | N25: =(N4-J4)/J4 -> -0.096038071 | O25: =(O4-K4)/K4 -> 0.3199524 | ... S25: =(S4-O4)/O4 -> -1 | W25: =(W4-V4)/V4 -> -0.13963842 | X25: =(X4-W4)/W4 -> 0.040353353 | Y25: =(Y4-X4)/X4 -> 0.26480095 | Z25: =(Z4-Y4)/Y4 -> -0.067823093 | AA25: =(AA4-Z4)/Z4 -> -0.2876076 | AB25: =(AB4-AA4)/AA4 -> 0.54878268 | AC25: =(AC4-AB4)/AB4 -> 0.70299847 | AD25: =(AD4-AC4)/AC4 -> -0.40084066 | ... AP25: =(AP4-AO4)/AO4 -> 0.1 | AR25: TV | AS25: -0.01
C26: Gross margin | D26: =D6/D4 -> 0.27293999 | E26: =E6/E4 -> 0.26643849 | F26: =F6/F4 -> 0.21997209 | G26: =G6/G4 -> 0.30424059 | H26: =H6/H4 -> 0.30729681 | I26: =I6/I4 -> 0.29246829 | J26: =J6/J4 -> 0.4074881 | K26: =K6/K4 -> 0.73146293 | ... S26: =S6/S4 -> #DIV/0! | V26: =V6/V4 -> 0.22736403 | W26: =W6/W4 -> 0.34448452 | X26: =X6/X4 -> 0.3184612 | Y26: =Y6/Y4 -> 0.28471928 | Z26: =Z6/Z4 -> 0.3915168 | AA26: =AA6/AA4 -> 0.48587266 | AB26: =AB6/AB4 -> 0.31623602 | AC26: =AC6/AC4 -> 0.26545809 | ... AP26: =AP6/AP4 -> 0.5 | AR26: NPV | AS26: =NPV(AS24,AF21:EO21) -> 336258.93
C27: EBITDA margin | D27: =D12/D4 -> 0.27927848 | E27: =E12/E4 -> 0.13747861 | F27: =F12/F4 -> 0.33707342 | G27: =G12/G4 -> 0.18128311 | H27: =H12/H4 -> 0.2352821 | I27: =I12/I4 -> 0.20149299 | J27: =J12/J4 -> 0.52594461 | K27: =K12/K4 -> -0.042960922 | ... S27: =S12/S4 -> #DIV/0! | V27: =V12/V4 -> 0.1482281 | W27: =W12/W4 -> 0.29514052 | X27: =X12/X4 -> 0.37806696 | Y27: =Y12/Y4 -> 0.3772643 | Z27: =Z12/Z4 -> 0.27017813 | AA27: =AA12/AA4 -> 0.3309605 | AB27: =AB12/AB4 -> 0.31279853 | AC27: =AC12/AC4 -> 0.2423475 | ... AP27: =AP12/AP4 -> 0.31604026 | AR27: S/O | AS27: 1321.1976
C28: EBIT margin | D28: =D14/D4 -> 0.21624904 | E28: =E14/E4 -> 0.049857387 | F28: =F14/F4 -> 0.26783613 | G28: =G14/G4 -> 0.032147762 | H28: =H14/H4 -> 0.1522694 | I28: =I14/I4 -> 0.052558111 | J28: =J14/J4 -> -1.2491256 | K28: =K14/K4 -> -1.0626253 | ... S28: =S14/S4 -> #DIV/0! | V28: =V14/V4 -> 0.045436829 | W28: =W14/W4 -> 0.20397958 | X28: =X14/X4 -> 0.27282319 | Y28: =Y14/Y4 -> 0.3060911 | Z28: =Z14/Z4 -> 0.16460695 | AA28: =AA14/AA4 -> 0.17965743 | AB28: =AB14/AB4 -> 0.20850231 | AC28: =AC14/AC4 -> 0.14948933 | ... AP28: =AP14/AP4 -> 0.26925071 | AR28: NPV/Share | AS28: =AS26/AS27 -> 254.51071
C29: ROCE | V29: 0.059 | W29: 0.244 | X29: 0.252 | Y29: 0.321 | Z29: 0.11 | AA29: 0.083 | AB29: 0.148 | AC29: 0.168 | AD29: -0.142 | AE29: 0.045 | AR29: Opp-/nedside | AS29: =(AS28-B4)/B4 -> 1.1209225
C31: Installed capacity (GW) | Y31: 5.6 | Z31: 9.9 | AA31: 11.3 | AB31: 13 | AC31: 15.1 | AD31: 15.7 | AE31: 18.2 | AH31: 27
C32: y/y | Z32: =(Z31-Y31)/Y31 -> 0.76785714 | AA32: =(AA31-Z31)/Z31 -> 0.14141414 | AB32: =(AB31-AA31)/AA31 -> 0.15044248 | AC32: =(AC31-AB31)/AB31 -> 0.16153846 | AD32: =(AD31-AC31)/AC31 -> 0.039735099 | AE32: =(AE31-AD31)/AD31 -> 0.15923567 | AF32: =(AF31-AE31)/AE31 -> -1 | AG32: =(AG31-AF31)/AF31 -> #DIV/0! | AH32: =(AH31-AG31)/AG31 -> #DIV/0!
C34: Balanse DKKm
C35: Land and buildings | D35: 7963 | E35: 8043 | F35: 8009 | G35: 7980 | H35: 8162 | I35: 8255 | J35: 8319 | K35: 7777 | L35: 7977 | M35: 7977 | N35: 7808 | O35: 7977 | P35: 7803 | Q35: 7269
C36: Production assets | D36: 100998 | E36: 115694 | F36: 114468 | G36: 119211 | H36: 117626 | I36: 122495 | J36: 122922 | K36: 121643 | L36: 138477 | M36: 138477 | N36: 134488 | O36: 138477 | P36: 129989 | Q36: 123322
C37: Fixtures and fittings | D37: 636 | E37: 1604 | F37: 1575 | G37: 1543 | H37: 1490 | I37: 1909 | J37: 2136 | K37: 2042 | L37: 2122 | M37: 2122 | N37: 2190 | O37: 2122 | P37: 1960 | Q37: 1930
C38: PP&E | D38: 55302 | E38: 48957 | F38: 52098 | G38: 48931 | H38: 55221 | I38: 54538 | J38: 44582 | K38: 48307 | L38: 53118 | M38: 53118 | N38: 51257 | O38: 53118 | P38: 63710 | Q38: 73205
C39: Investments in JV | D39: 662 | E39: 755 | F39: 1044 | G39: 772 | H39: 833 | I39: 964 | J39: 968 | K39: 960 | L39: 870 | M39: 870 | N39: 897 | O39: 870 | P39: 897 | Q39: 1067
C40: Receivables from JV | D40: 224 | E40: 0 | F40: 217 | G40: 0 | H40: 176 | I40: 44 | J40: 54 | K40: 77 | L40: 200 | M40: 200 | N40: 168 | O40: 200 | P40: 221 | Q40: 245
C41: Other securities | D41: 5809 | E41: 233 | F41: 13069 | G41: 182 | H41: 1213 | I41: 172 | J41: 174 | K41: 167 | L41: 344 | M41: 344 | N41: 155 | O41: 344 | P41: 323 | Q41: 298
C42: Derivatives | D42: 14730 | E42: 10188 | F42: 21719 | G42: 1804 | H42: 10114 | I42: 1374 | J42: 789 | K42: 1356 | L42: 960 | M42: 960 | N42: 1164 | O42: 960 | P42: 1167 | Q42: 1530
C43: Deferred tax | D43: 2670 | E43: 20874 | F43: 3290 | G43: 13719 | H43: 3408 | I43: 9881 | J43: 8798 | K43: 8192 | L43: 9250 | M43: 9250 | N43: 9178 | O43: 9250 | P43: 9985 | Q43: 9772
C44: Other receivables | D44: 16430 | E44: 2876 | F44: 17132 | G44: 3243 | H44: 13040 | I44: 3370 | J44: 3552 | K44: 3134 | L44: 3218 | M44: 3218 | N44: 3010 | O44: 3218 | P44: 3431 | Q44: 2959
...

Sheet Seg_off
B3: DKKm | C3: Q122 | D3: Q222 | E3: Q322 | F3: Q422 | G3: Q123 | H3: Q223 | I3: Q323 | J3: Q423 | K3: Q124 | L3: Q224 | M3: Q324 | N3: Q424 | O3: Q125 | P3: Q225 | Q3: Q325 | R3: Q425
B4: Business drivers
B5: Decided and installed cap (GW) | C5: 11.1 | D5: 11.1 | E5: 11.1 | F5: 11.1 | G5: 12 | H5: 12 | I5: 12 | J5: 15.5 | K5: 16.5 | L5: 16.8 | M5: 16.8 | N5: 16.8 | O5: 18.3 | P5: 18.3
B6: y/y | G6: =(G5-C5)/C5 -> 0.081081081 | H6: =(H5-D5)/D5 -> 0.081081081 | I6: =(I5-E5)/E5 -> 0.081081081 | J6: =(J5-F5)/F5 -> 0.3963964 | K6: =(K5-G5)/G5 -> 0.375 | L6: =(L5-H5)/H5 -> 0.4 | M6: =(M5-I5)/I5 -> 0.4 | N6: =(N5-J5)/J5 -> 0.083870968 | ... R6: =(R5-N5)/N5 -> -1
B7: Installed capacity (GW) | C7: 7.6 | D7: 7.6 | E7: 8.9 | F7: 8.9 | G7: 8.9 | H7: 8.9 | I7: 8.9 | J7: 8.9 | K7: 8.9 | L7: 9.8 | M7: 9.9 | N7: 9.9 | O7: 10.2 | P7: 10.2
B8: y/y | G8: =(G7-C7)/C7 -> 0.17105263 | H8: =(H7-D7)/D7 -> 0.17105263 | I8: =(I7-E7)/E7 -> 0 | J8: =(J7-F7)/F7 -> 0 | K8: =(K7-G7)/G7 -> 0 | L8: =(L7-H7)/H7 -> 0.1011236 | M8: =(M7-I7)/I7 -> 0.11235955 | N8: =(N7-J7)/J7 -> 0.11235955 | ... R8: =(R7-N7)/N7 -> -1
B9: Generation capacity (GW) | C9: 4.2 | D9: 4.8 | E9: 5.3 | F9: 4.7 | G9: 4.7 | H9: 4.9 | I9: 5 | J9: 5 | K9: 5.1 | L9: 5.1 | M9: 5.2 | N9: 5.3 | O9: 5.5 | P9: 5.4
B10: y/y | G10: =(G9-C9)/C9 -> 0.11904762 | H10: =(H9-D9)/D9 -> 0.020833333 | I10: =(I9-E9)/E9 -> -0.056603774 | J10: =(J9-F9)/F9 -> 0.063829787 | K10: =(K9-G9)/G9 -> 0.085106383 | L10: =(L9-H9)/H9 -> 0.040816327 | M10: =(M9-I9)/I9 -> 0.04 | N10: =(N9-J9)/J9 -> 0.06 | ... R10: =(R9-N9)/N9 -> -1
B11: Wind speed (M/S) | C11: 11.3 | D11: 35 | E11: 7.7 | F11: 9.5 | G11: 10.9 | H11: 8.1 | I11: 8.6 | J11: 9.8 | K11: 11.4 | L11: 9 | M11: 8.4 | N11: 10 | O11: 10.4 | P11: 8.5
B12: Load factor | C12: 0.54 | D12: 0.35 | E12: 0.28 | F12: 0.42 | G12: 0.53 | H12: 0.29 | I12: 0.33 | J12: 0.43 | K12: 0.52 | L12: 0.33 | M12: 0.31 | N12: 0.42 | O12: 0.47 | P12: 0.31
B13: Availability | C13: 0.95 | D13: 0.94 | E13: 0.91 | F13: 0.94 | G13: 0.95 | H13: 0.91 | I13: 0.93 | J13: 0.93 | K13: 0.85 | L13: 0.83 | M13: 0.89 | N13: 0.88 | O13: 0.94 | P13: 0.9
B14: Power generation (GWh) | C14: 4502 | D14: 3324 | E14: 3246 | F14: =16483-C14-D14-E14 -> 5411 | G14: 5162 | H14: 3044 | I14: 3544 | J14: =17761-G14-H14-I14 -> 6011 | K14: 5670 | L14: 3667 | M14: 3522 | N14: =18599-K14-L14-M14 -> 5740 | O14: 5470 | P14: 3646
B15: y/y | G15: =(G14-C14)/C14 -> 0.14660151 | H15: =(H14-D14)/D14 -> -0.08423586 | I15: =(I14-E14)/E14 -> 0.091805299 | J15: =(J14-F14)/F14 -> 0.11088523 | K15: =(K14-G14)/G14 -> 0.098411468 | L15: =(L14-H14)/H14 -> 0.20466491 | M15: =(M14-I14)/I14 -> -0.0062076749 | N15: =(N14-J14)/J14 -> -0.045084013 | ... R15: =(R14-N14)/N14 -> -1
B16: Denmark | C16: 641 | D16: 385 | E16: 423 | G16: 599 | H16: 371 | I16: 377 | K16: 690 | L16: 418 | M16: 356 | O16: 564 | P16: 345
B17: UK | C17: 2862 | D17: 2284 | E17: 2212 | G17: 3416 | H17: 1779 | I17: 2259 | K17: 3142 | L17: 2029 | M17: 2122 | O17: 3019 | P17: 2100
B18: Germany | C18: 565 | D18: 372 | E18: 387 | G18: 566 | H18: 398 | I18: 379 | K18: 753 | L18: 434 | M18: 467 | O18: 623 | P18: 417
B19: Netherlands | C19: 400 | D19: 262 | E19: 197 | G19: 412 | H19: 288 | I19: 259 | K19: 444 | L19: 269 | M19: 258 | O19: 276 | P19: 270
B20: APAC | C20: 0 | D20: 1 | E20: 0 | G20: 141 | H20: 190 | I20: 254 | K20: 579 | L20: 447 | M20: 271 | O20: 880 | P20: 413
B21: US | C21: 34 | D21: 20 | E21: 27 | G21: 28 | H21: 18 | I21: 16 | K21: 61 | L21: 70 | M21: 48 | O21: 108 | P21: 101
B22: Power sales (GWh) | C22: 9166 | D22: 7416 | E22: 5600 | F22: =23194-C22-D22-E22 -> 1012 | G22: 10642 | H22: 6739 | I22: 3948 | J22: =21448-G22-H22-I22 -> 119 | K22: 6264 | L22: 3854 | M22: 4010 | N22: =19967-K22-L22-M22 -> 5839 | O22: 4816 | P22: 3686
B23: y/y | G23: =(G22-C22)/C22 -> 0.16102989 | H23: =(H22-D22)/D22 -> -0.091289105 | I23: =(I22-E22)/E22 -> -0.295 | J23: =(J22-F22)/F22 -> -0.88241107 | K23: =(K22-G22)/G22 -> -0.41138884 | L23: =(L22-H22)/H22 -> -0.42810506 | M23: =(M22-I22)/I22 -> 0.015704154 | N23: =(N22-J22)/J22 -> 48.067227 | ... R23: =(R22-N22)/N22 -> -1
B24: Power price LEBA UK GBP/MWh | C24: 251 | D24: 188 | E24: 361 | G24: 145 | H24: 105 | I24: 98 | K24: 77 | L24: 79 | M24: 80 | O24: 129 | P24: 90
B25: Financial drivers
B26: Revenue | C26: 19806 | D26: 17336 | E26: 25057 | G26: 22144 | H26: 11522 | I26: 14265 | K26: 13991 | L26: 11526 | M26: 12088 | O26: 14637 | P26: 13371
B27: y/y | G27: =(G26-C26)/C26 -> 0.11804504 | H27: =(H26-D26)/D26 -> -0.33537148 | I27: =(I26-E26)/E26 -> -0.43069801 | J27: =(J26-F26)/F26 -> #DIV/0! | K27: =(K26-G26)/G26 -> -0.368181 | L27: =(L26-H26)/H26 -> 0.00034716195 | M27: =(M26-I26)/I26 -> -0.15261129 | N27: =(N26-J26)/J26 -> #DIV/0! | ... R27: =(R26-N26)/N26 -> #DIV/0!
B28: Sites, O&M and PPAs | C28: 3863 | D28: 4756 | E28: 3963 | G28: 5840 | H28: 4490 | I28: 4549 | K28: 7373 | L28: 5339 | M28: 5302 | O28: 7635 | P28: 5914
B29: Power sales | C29: 13977 | D29: 10355 | E29: 14460 | G29: 15499 | H29: 6851 | I29: 3978 | K29: 5582 | L29: 3680 | M29: 3034 | O29: 5474 | P29: 5122
B30: Construction agreements | C30: 1739 | D30: 2356 | E30: 6629 | G30: 572 | H30: -14 | I30: 5247 | K30: 1439 | L30: 2292 | M30: 3171 | O30: 1439 | P30: 2167
B31: Other | C31: 227 | D31: -131 | E31: 5 | G31: 233 | H31: 195 | I31: 491 | K31: 89 | L31: 215 | M31: 581 | O31: 89 | P31: 168
B32: EBITDA | C32: 5919 | D32: 1904 | E32: 9652 | G32: 5412 | H32: 2979 | I32: 8037 | K32: 6083 | L32: 5218 | M32: 8530 | O32: 6310 | P32: 5301
B33: Sites, O&M and PPAs | C33: 3698 | D33: 2031 | E33: 467 | G33: 5859 | H33: 3135 | I33: 4050 | K33: 6928 | L33: 4400 | M33: 3958 | O33: 7655 | P33: 4814
B34: Construction agreements and divestment gains | C34: 2620 | D34: 601 | E34: 9765 | G34: -42 | H34: 340 | I34: 4245 | K34: -283 | L34: 6 | M34: 106 | O34: -77 | P34: 2901
B35: Cancellation fees | C35: 0 | D35: 0 | E35: 0 | G35: -405 | H35: -496 | I35: 0 | K35: 0 | L35: 1300 | M35: 5109 | O35: 0 | P35: -1531
B36: Other | C36: -399 | D36: -728 | E36: -580 | G36: -1693 | H36: -1761 | I36: -258 | K36: -562 | L36: -488 | M36: -644 | O36: -1268 | P36: -883
B37: Depreciation | C37: -1521 | D37: -1671 | E37: -1820 | G37: -1693 | H37: -1761 | I37: -1733 | K37: -1722 | L37: -1809 | M37: -1752 | O37: -1776 | P37: -1688
B38: Impairment loss | C38: 0 | D38: 0 | E38: 0 | G38: 0 | H38: 0 | I38: -26988 | K38: 1063 | L38: -4149 | M38: 199 | O38: -224 | P38: -500
B39: EBIT | C39: 4398 | D39: 233 | E39: 7832 | G39: 3719 | H39: 1218 | I39: -20684 | K39: 5424 | L39: -740 | M39: 6977 | O39: 4310 | P39: 3113
... B42: Divestments | C42: 1945 | D42: 176 | E42: 22296 | G42: -21 | H42: -2007 | I42: 1738 | K42: -802 | L42: -7 | M42: -45 | O42: 105 | P42: 3822

Sheet Seg_on
B3: DKKm | C3: Q122 | D3: Q222 | E3: Q322 | F3: Q422 | G3: Q123 | H3: Q223 | I3: Q323 | J3: Q423 | K3: Q124 | L3: Q224 | M3: Q324 | N3: Q424 | O3: Q125 | P3: Q225 | Q3: Q325 | R3: Q425
B4: Business drivers
B5: Decided and installed cap (GW) | C5: 4.7 | D5: 4.9 | E5: 5.1 | G5: 6.2 | H5: 6.2 | I5: 6.2 | K5: 6.4 | L5: 6.4 | M5: 6.4 | N5: 7 | O5: 7 | P5: 7
B6: y/y | G6: =(G5-C5)/C5 -> 0.31914894 | H6: =(H5-D5)/D5 -> 0.26530612 | I6: =(I5-E5)/E5 -> 0.21568627 | J6: =(J5-F5)/F5 -> #DIV/0! | K6: =(K5-G5)/G5 -> 0.032258065 | L6: =(L5-H5)/H5 -> 0.032258065 | M6: =(M5-I5)/I5 -> 0.032258065 | N6: =(N5-J5)/J5 -> #DIV/0! | ... R6: =(R5-N5)/N5 -> -1
B7: Installed capacity (GW) | C7: 3.6 | D7: 4 | E7: 4.2 | G7: 4.5 | H7: 4.6 | I7: 4.8 | K7: 4.8 | L7: 5.6 | M7: 5.7 | N7: 6.2 | O7: 6.2 | P7: 6.2
B8: y/y | G8: =(G7-C7)/C7 -> 0.25 | H8: =(H7-D7)/D7 -> 0.15 | I8: =(I7-E7)/E7 -> 0.14285714 | J8: =(J7-F7)/F7 -> #DIV/0! | K8: =(K7-G7)/G7 -> 0.066666667 | L8: =(L7-H7)/H7 -> 0.2173913 | M8: =(M7-I7)/I7 -> 0.1875 | N8: =(N7-J7)/J7 -> #DIV/0! | ... R8: =(R7-N7)/N7 -> -1
B9: Wind speed (M/S) | C9: 7.9 | D9: 7.8 | E9: 6 | G9: 8.1 | H9: 6.7 | I9: 6.2 | K9: 7.9 | L9: 7.4 | M9: 6.2 | N9: 7.2 | O9: 8 | P9: 7.2
B10: Load factor Wind | C10: 0.47 | D10: 0.48 | E10: 0.3 | G10: 0.45 | H10: 0.35 | I10: 0.27 | K10: 0.42 | L10: 0.41 | M10: 0.26 | N10: 0.37 | O10: 0.44 | P10: 0.36
B11: Load factor, solar PV | C11: 0.21 | D11: 0.31 | E11: 0.32 | G11: 0.16 | H11: 0.3 | I11: 0.32 | K11: 0.18 | L11: 0.29 | M11: 0.31 | N11: 0.25 | O11: 0.21 | P11: 0.3
B12: Availability, Wind | C12: 0.96 | D12: 0.92 | E12: 0.92 | G12: 0.91 | H12: 0.92 | I12: 0.85 | K12: 0.89 | L12: 0.92 | M12: 0.87 | N12: 0.9 | O12: 0.91 | P12: 0.88
B13: Availability, Solar PV | C13: 0.99 | D13: 0.99 | E13: 0.96 | G13: 0.99 | H13: 0.98 | I13: 0.98 | K13: 0.98 | L13: 0.97 | M13: 0.97 | N13: 0.98 | O13: 0.98 | P13: 0.91
B14: Power generation (GWh) | C14: 3203 | D14: 3795 | E14: 2723 | G14: 3750 | H14: 3321 | I14: 2927 | K14: 3772 | L14: 4187 | M14: 3270 | N14: =15315-K14-L14-M14 -> 4086 | O14: 4294 | P14: 4002
B15: y/y | G15: =(G14-C14)/C14 -> 0.1707774 | H15: =(H14-D14)/D14 -> -0.12490119 | I15: =(I14-E14)/E14 -> 0.074917371 | J15: =(J14-F14)/F14 -> #DIV/0! | K15: =(K14-G14)/G14 -> 0.0058666667 | L15: =(L14-H14)/H14 -> 0.26076483 | M15: =(M14-I14)/I14 -> 0.11718483 | N15: =(N14-J14)/J14 -> #DIV/0! | ... R15: =(R14-N14)/N14 -> -1
B16: US, Wind | C16: 2675 | D16: 3057 | E16: 1946 | G16: 3055 | H16: 2454 | I16: 1975 | K16: 3003 | L16: 3064 | M16: 1947 | O16: 3208 | P16: 2746
B17: US, Solar PV | C17: 289 | D17: 567 | E17: 676 | G17: 363 | H17: 668 | I17: 708 | K17: 399 | L17: 906 | M17: 1158 | O17: 767 | P17: 1034
B18: Europe | C18: 239 | D18: 171 | E18: 101 | G18: 332 | H18: 199 | I18: 244 | K18: 370 | L18: 217 | M18: 166 | O18: 319 | P18: 222
B19: US dollar/DKK | C19: 6.6 | D19: 7 | E19: 7.4 | G19: 6.9 | H19: 6.8 | I19: 6.8 | K19: 6.9 | L19: 6.9 | M19: 6.8 | O19: 7.1 | P19: 6.6
B20: Financial perfomance
B21: Revenue | C21: 690 | D21: 730 | E21: 836 | G21: 721 | H21: 625 | I21: 676 | K21: 705 | L21: 660 | M21: 801 | O21: 846 | P21: 604
B22: y/y | G22: =(G21-C21)/C21 -> 0.044927536 | H22: =(H21-D21)/D21 -> -0.14383562 | I22: =(I21-E21)/E21 -> -0.19138756 | J22: =(J21-F21)/F21 -> #DIV/0! | K22: =(K21-G21)/G21 -> -0.022191401 | L22: =(L21-H21)/H21 -> 0.056 | M22: =(M21-I21)/I21 -> 0.18491124 | N22: =(N21-J21)/J21 -> #DIV/0! | ... R22: =(R21-N21)/N21 -> #DIV/0!
B23: EBITDA | C23: 850 | D23: 1075 | E23: 867 | G23: 834 | H23: 792 | I23: 819 | K23: 816 | L23: 990 | M23: 991 | O23: 1490 | P23: 1197
B24: US, Wind | C24: 496 | D24: 571 | E24: 610 | G24: 324 | H24: 292 | I24: 246 | K24: 1046 | L24: 1175 | M24: 419 | O24: 1416 | P24: 1104
B25: US, Solar PV | C25: 568 | D25: 679 | E25: 597 | G25: 759 | H25: 637 | I25: 581 | K25: 0 | L25: 0 | M25: 731 | O25: 304 | P25: 0
B26: Europe | C26: -214 | D26: -175 | E26: 340 | G26: -249 | H26: -137 | I26: -8 | K26: -230 | L26: -180 | M26: -159 | O26: -230 | P26: 93
B27: Depreciation | C27: -358 | D27: -382 | E27: -456 | G27: -441 | H27: -458 | I27: -560 | K27: -467 | L27: -641 | M27: -559 | O27: -546 | P27: -512
B28: Impairment loss | C28: 0 | D28: 0 | E28: 0 | G28: 0 | H28: 0 | I28: -1434 | K28: -302 | L28: 236 | M28: -483 | O28: 496 | P28: 480
B29: EBIT | C29: 492 | D29: 693 | E29: 411 | G29: 393 | H29: 334 | I29: -1175 | K29: 47 | L29: 590 | M29: -51 | O29: 1440 | P29: 1165
B30: CFFO | C30: -188 | D30: 1294 | E30: 364 | G30: 1442 | H30: -359 | I30: 1121 | K30: 366 | L30: 2578 | M30: 95 | O30: 369 | P30: -47
B31: Capex | C31: -1221 | D31: -997 | E31: -6322 | G31: -2668 | H31: -1917 | I31: -1460 | K31: -2128 | L31: -1690 | M31: -875 | O31: -1411 | P31: -1240
B32: Divestments | C32: 0 | D32: 44 | E32: -1 | G32: 3 | H32: -1 | I32: 0 | K32: 64 | L32: 3043 | M32: 152 | O32: 2883 | P32: 434

Sheet Seg_Bio
B3: DKKm | C3: Q122 | D3: Q222 | E3: Q322 | F3: Q422 | G3: Q123 | H3: Q223 | I3: Q323 | J3: Q423 | K3: Q124 | L3: Q224 | M3: Q324 | N3: Q424 | O3: Q125 | P3: Q225 | Q3: Q325 | R3: Q425
B4: Business drivers
B5: Degree days | C5: 1141 | D5: 448 | E5: 98 | G5: 1157 | H5: 409 | I5: 53 | K5: 1200 | L5: 360 | M5: 79 | O5: 1181 | P5: 418
B6: y/y | G6: =(G5-C5)/C5 -> 0.014022787 | H6: =(H5-D5)/D5 -> -0.087053571 | I6: =(I5-E5)/E5 -> -0.45918367 | J6: =(J5-F5)/F5 -> #DIV/0! | K6: =(K5-G5)/G5 -> 0.037165082 | L6: =(L5-H5)/H5 -> -0.1198044 | M6: =(M5-I5)/I5 -> 0.49056604 | N6: =(N5-J5)/J5 -> #DIV/0! | ... R6: =(R5-N5)/N5 -> #DIV/0!
B7: Heat generation (GWh) | C7: 3243 | D7: 823 | E7: 239 | G7: 3178 | H7: 790 | I7: 234 | K7: 3285 | L7: 935 | M7: 332 | O7: 3224 | P7: 707
B8: y/y | G8: =(G7-C7)/C7 -> -0.02004317 | H8: =(H7-D7)/D7 -> -0.040097205 | I8: =(I7-E7)/E7 -> -0.020920502 | J8: =(J7-F7)/F7 -> #DIV/0! | K8: =(K7-G7)/G7 -> 0.033668974 | L8: =(L7-H7)/H7 -> 0.1835443 | M8: =(M7-I7)/I7 -> 0.41880342 | N8: =(N7-J7)/J7 -> #DIV/0! | ... R8: =(R7-N7)/N7 -> #DIV/0!
B9: Power generation (GWh) | C9: 2138 | D9: 1102 | E9: 1363 | G9: 1697 | H9: 917 | I9: 781 | K9: 1484 | L9: 805 | M9: 805 | O9: 1480 | P9: 477
B10: y/y | G10: =(G9-C9)/C9 -> -0.20626754 | H10: =(H9-D9)/D9 -> -0.16787659 | I10: =(I9-E9)/E9 -> -0.42699927 | J10: =(J9-F9)/F9 -> #DIV/0! | K10: =(K9-G9)/G9 -> -0.12551562 | L10: =(L9-H9)/H9 -> -0.1221374 | M10: =(M9-I9)/I9 -> 0.030729834 | N10: =(N9-J9)/J9 -> #DIV/0! | ... R10: =(R9-N9)/N9 -> #DIV/0!
B11: Gas sales (GWh) | C11: 12993 | D11: 8891 | E11: 5706 | G11: 4468 | H11: 4016 | I11: 5355 | K11: 5167 | L11: 4051 | M11: 4138 | O11: 5280 | P11: 5798
B12: y/y | G12: =(G11-C11)/C11 -> -0.65612253 | H12: =(H11-D11)/D11 -> -0.54830728 | I12: =(I11-E11)/E11 -> -0.061514196 | J12: =(J11-F11)/F11 -> #DIV/0! | K12: =(K11-G11)/G11 -> 0.15644584 | L12: =(L11-H11)/H11 -> 0.0087151394 | M12: =(M11-I11)/I11 -> -0.22726424 | N12: =(N11-J11)/J11 -> #DIV/0! | ... R12: =(R11-N11)/N11 -> #DIV/0!
B13: Power sales (GWh) | C13: 1690 | D13: 1466 | E13: 1339 | G13: 877 | H13: 556 | I13: 566 | K13: 633 | L13: 581 | M13: 577 | O13: 632 | P13: 585
B14: y/y | G14: =(G13-C13)/C13 -> -0.48106509 | H14: =(H13-D13)/D13 -> -0.6207367 | I14: =(I13-E13)/E13 -> -0.57729649 | J14: =(J13-F13)/F13 -> #DIV/0! | K14: =(K13-G13)/G13 -> -0.27822121 | L14: =(L13-H13)/H13 -> 0.044964029 | M14: =(M13-I13)/I13 -> 0.019434629 | N14: =(N13-J13)/J13 -> #DIV/0! | ... R14: =(R13-N13)/N13 -> #DIV/0!
B15: Gas price, TTF (EUR/MWh) | C15: 95.6 | D15: 95.6 | E15: 196.2 | G15: 54.1 | H15: 35.1 | I15: 33 | K15: 27.4 | L15: 31.5 | M15: 35.3 | O15: 47 | P15: 35.4
B16: Power price, DK (EUR/MWh) | C16: 151.1 | D16: 179.8 | E16: 347.8 | G16: 103.3 | H16: 84 | I16: 78.8 | K16: 64.8 | L16: 61.1 | M16: 68.8 | O16: 99.3 | P16: 65.6
B17: Wood pellet spread, DK (EUR/MWh) | C17: 20.1 | D17: 34.1 | E17: 0 | G17: 20.1 | H17: -3.3 | I17: 9.2 | K17: 3.4 | L17: 5.2 | M17: 8.3 | O17: 18 | P17: 7.4
B18: Financial performance
B19: Revenue | C19: 14474 | D19: 9182 | E19: 12336 | G19: 6890 | H19: 4460 | I19: 2645 | K19: 4586 | L19: 3005 | M19: 3058 | O19: 5347 | P19: 3333
B20: y/y | G20: =(G19-C19)/C19 -> -0.52397402 | H20: =(H19-D19)/D19 -> -0.51426704 | I20: =(I19-E19)/E19 -> -0.7855869 | J20: =(J19-F19)/F19 -> #DIV/0! | K20: =(K19-G19)/G19 -> -0.33439768 | L20: =(L19-H19)/H19 -> -0.32623318 | M20: =(M19-I19)/I19 -> 0.15614367 | N20: =(N19-J19)/J19 -> #DIV/0! | ... R20: =(R19-N19)/N19 -> #DIV/0!
B21: EBITDA | C21: 2514 | D21: 647 | E21: 1849 | G21: 517 | H21: -583 | I21: 155 | K21: 434 | L21: -36 | M21: -185 | O21: 757 | P21: 78
B22: GHP plants | C22: 1823 | D22: 619 | E22: 1691 | G22: 845 | H22: -244 | I22: -219 | K22: 587 | L22: 77 | M22: -95 | O22: 734 | P22: 196
B23: Gas market & infrastructure | C23: 725 | D23: 66 | E23: 253 | G23: -237 | H23: -279 | I23: 485 | K23: -79 | L23: -42 | M23: 125 | O23: 210 | P23: 68
B24: Ohter | C24: -34 | D24: -38 | E24: -95 | G24: -91 | H24: -60 | I24: -111 | K24: -74 | L24: -71 | M24: -215 | O24: -187 | P24: -186
B25: Depreciation | C25: -189 | D25: -193 | E25: -190 | G25: -240 | H25: -170 | I25: -169 | K25: -165 | L25: -164 | M25: -167 | O25: -164 | P25: -163
B26: EBITDA | C26: 2325 | D26: 454 | E26: 1659 | G26: 277 | H26: -753 | I26: -14 | K26: 269 | L26: -200 | M26: -352 | O26: 593 | P26: -85
B27: CFFO | C27: 2439 | D27: 1326 | E27: -1881 | G27: -922 | H27: 984 | I27: 2130 | K27: 3038 | L27: 281 | M27: -286 | O27: 950 | P27: 259
B28: Capex | C28: -51 | D28: -107 | E28: -84 | G28: -56 | H28: -89 | I28: -208 | K28: -489 | L28: -425 | M28: -386 | O28: -645 | P28: -395
B29: Divestments | C29: -8 | D29: 6 | E29: 2 | G29: 0 | H29: -3 | I29: 0 | K29: 0 | L29: 0 | M29: 0 | O29: 0 | P29: 0
F32: Spørre vhatten om de ulike punkteene jeg ikke kan

Sheet Nøkkeltall
D4: 2025 | E4: 2026 | F4: 2027
C5: EV/EBITDA | D5: =Modell!$B$9/Modell!AF12 -> 7.972255 | E5: =Modell!$B$9/Modell!AG12 -> 7.0119622 | F5: =Modell!$B$9/Modell!AH12 -> 6.2340623
C6: EV/EBIT | D6: =Modell!$B$9/Modell!AF14 -> 18.479983 | E6: =Modell!$B$9/Modell!AG14 -> 10.908831 | F6: =Modell!$B$9/Modell!AH14 -> 9.1353849
C7: P/E | D7: =Modell!$B$4/Modell!AF23 -> 8.6571115 | E7: =Modell!$B$4/Modell!AG23 -> 14.341892 | F7: =Modell!$B$4/Modell!AH23 -> 11.5877

Sheet Nedsideberegning
A3: Nedside | D3: FY 2015 | E3: FY 2016 | F3: FY 2017 | G3: FY 2018 | H3: FY 2019 | I3: FY 2020 | J3: FY 2021 | K3: FY 2022 | L3: FY 2023 | M3: FY 2024 | N3: FY 2025 | O3: FY 2026 | P3: FY 2027 | Q3: FY 2028 | R3: FY 2029 | S3: FY 2030 | T3: FY 2031 | U3: FY 2032 | V3: FY 2033 | W3: FY 2034 | X3: FY 2035
A4: Nullvekst og konstante marginer | C4: Revenues | D4: 66708 | E4: 57393 | F4: 59709 | G4: 75520 | H4: 70398 | I4: 50151 | J4: 77673 | K4: 132277 | L4: 79255 | M4: 71034 | N4: =M4*1.15 -> 81689.1 | O4: =N4 -> 81689.1 | P4: =O4 -> 81689.1 | Q4: =P4 -> 81689.1 | R4: =Q4 -> 81689.1 | S4: =R4 -> 81689.1 | T4: =S4 -> 81689.1 | U4: =T4 -> 81689.1 | V4: =U4 -> 81689.1 | ... X4: =W4 -> 81689.1
A5: =AA28 -> 75.213758 | C5: Cost of sales | D5: -51541 | E5: -37622 | F5: -40694 | G5: -54018 | H5: -42836 | I5: -25784 | J5: -53110 | K5: -97163 | L5: -46624 | M5: -35963 | N5: =N4*-0.55 -> -44929.005 | O5: =O4*-0.55 -> -44929.005 | P5: =P4*-0.55 -> -44929.005 | Q5: =Q4*-0.55 -> -44929.005 | R5: =R4*-0.55 -> -44929.005 | S5: =S4*-0.55 -> -44929.005 | T5: =T4*-0.55 -> -44929.005 | U5: =U4*-0.55 -> -44929.005 | ... X5: =X4*-0.55 -> -44929.005
A6: =AA29 -> -0.37321868 | C6: Gross profit | D6: =SUM(D4:D5) -> 15167 | E6: =SUM(E4:E5) -> 19771 | F6: =SUM(F4:F5) -> 19015 | G6: =SUM(G4:G5) -> 21502 | H6: =SUM(H4:H5) -> 27562 | I6: =SUM(I4:I5) -> 24367 | J6: =SUM(J4:J5) -> 24563 | K6: =SUM(K4:K5) -> 35114 | ... X6: =SUM(X4:X5) -> 36760.095
C7: Other external expenses | D7: -3263 | E7: -4078 | F7: -4241 | G7: -5865 | H7: -6091 | I7: -5774 | J7: -5760 | K7: -7049 | L7: -7406 | M7: -8697 | N7: =M7*1.14 -> -9914.58 | O7: =N7 -> -9914.58 | P7: =O7 -> -9914.58 | Q7: =P7 -> -9914.58 | R7: =Q7 -> -9914.58 | S7: =R7 -> -9914.58 | T7: =S7 -> -9914.58 | U7: =T7 -> -9914.58 | V7: =U7 -> -9914.58 | ... X7: =W7 -> -9914.58
C8: Employee costs | D8: -3310 | E8: -3088 | F8: -3197 | G8: -3126 | H8: -3952 | I8: -4283 | J8: -4289 | K8: -5278 | L8: -6374 | M8: -6532 | N8: =M8*1.14 -> -7446.48 | O8: =N8 -> -7446.48 | P8: =O8 -> -7446.48 | Q8: =P8 -> -7446.48 | R8: =Q8 -> -7446.48 | S8: =R8 -> -7446.48 | T8: =S8 -> -7446.48 | U8: =T8 -> -7446.48 | V8: =U8 -> -7446.48 | ... X8: =W8 -> -7446.48
C9: Share of JV | D9: 112 | E9: 25 | F9: -119 | G9: -6 | H9: -20 | I9: 71 | J9: -17 | K9: 114 | L9: -55 | M9: -68 | N9: =M9*1.14 -> -77.52 | O9: 0 | P9: 0 | Q9: 0 | R9: 0 | S9: 0 | T9: 0 | U9: 0 | V9: 0 | W9: 0 | X9: 0
C10: Other operating income | D10: 1575 | E10: 4867 | F10: 11665 | G10: 16275 | H10: 1781 | I10: 2620 | J10: 10185 | K10: 14119 | L10: 10329 | M10: 5298 | N10: 0 | O10: 0 | P10: 0 | Q10: 0 | R10: 0 | S10: 0 | T10: 0 | U10: 0 | V10: 0 | W10: 0 | X10: 0
C11: Other opex | D11: -393 | E11: -558 | F11: -549 | G11: -289 | H11: -260 | I11: -403 | J11: -386 | K11: -4963 | L11: -10408 | M11: 6887 | N11: 0 | O11: 0 | P11: 0 | Q11: 0 | R11: 0 | S11: 0 | T11: 0 | U11: 0 | V11: 0 | W11: 0 | X11: 0
C12: EBITDA | D12: =SUM(D6:D11) -> 9888 | E12: =SUM(E6:E11) -> 16939 | F12: =SUM(F6:F11) -> 22574 | G12: =SUM(G6:G11) -> 28491 | H12: =SUM(H6:H11) -> 19020 | I12: =SUM(I6:I11) -> 16598 | J12: =SUM(J6:J11) -> 24296 | K12: =SUM(K6:K11) -> 32057 | ... X12: =SUM(X6:X11) -> 19399.035
C13: A/I | D13: -6857 | E13: -5232 | F13: -6284 | G13: -5375 | H13: -7432 | I13: -7588 | J13: -8101 | K13: -12283 | L13: =-9795-26775 -> -36570 | M13: =-10225-15563 -> -25788 | N13: -7000 | O13: -5000 | P13: -5000 | Q13: -5000 | R13: -5000 | S13: -5000 | T13: -5000 | U13: -5000 | V13: -5000 | W13: -5000 | X13: -5000
C14: EBIT | D14: =SUM(D12:D13) -> 3031 | E14: =SUM(E12:E13) -> 11707 | F14: =SUM(F12:F13) -> 16290 | G14: =SUM(G12:G13) -> 23116 | H14: =SUM(H12:H13) -> 11588 | I14: =SUM(I12:I13) -> 9010 | J14: =SUM(J12:J13) -> 16195 | K14: =SUM(K12:K13) -> 19774 | ... X14: =SUM(X12:X13) -> 14399.035
C15: Divestment of enterprises | D15: 56 | E15: 1250 | F15: -139 | G15: 127 | H15: -63 | I15: 10831 | J15: -742 | K15: 331 | L15: 234 | M15: -11 | N15: 422 | O15: 0 | P15: 0 | Q15: 0 | R15: 0 | S15: 0 | T15: 0 | U15: 0 | V15: 0 | W15: 0 | X15: 0
C16: Share of JV | D16: -8 | E16: -8 | F16: -10 | G16: 1 | H16: 2 | I16: 7 | J16: -10 | K16: 40 | L16: 36 | M16: 37 | N16: 36 | O16: 0 | P16: 0 | Q16: 0 | R16: 0 | S16: 0 | T16: 0 | U16: 0 | V16: 0 | W16: 0 | X16: 0
C17: Financial income | D17: 9297 | E17: 8179 | F17: 4253 | G17: 3179 | H17: 7718 | I17: 5779 | J17: 4380 | K17: 15514 | L17: 12379 | M17: 8590 | N17: 8946 | O17: =N17 -> 8946 | P17: =O17 -> 8946 | Q17: =P17 -> 8946 | R17: =Q17 -> 8946 | S17: =R17 -> 8946 | T17: =S17 -> 8946 | U17: =T17 -> 8946 | V17: =U17 -> 8946 | ... X17: =W17 -> 8946
C18: Financial expenses | D18: -10706 | E18: -8946 | F18: -5295 | G18: -4457 | H18: -8853 | I18: -8303 | J18: -6546 | K18: -18050 | L18: -13822 | M18: -12181 | N18: -12742 | O18: =N18 -> -12742 | P18: =O18 -> -12742 | Q18: =P18 -> -12742 | R18: =Q18 -> -12742 | S18: =R18 -> -12742 | T18: =S18 -> -12742 | U18: =T18 -> -12742 | V18: =U18 -> -12742 | ... X18: =W18 -> -12742
C19: PTP | D19: =SUM(D14:D18) -> 1670 | E19: =SUM(E14:E18) -> 12182 | F19: =SUM(F14:F18) -> 15099 | G19: =SUM(G14:G18) -> 21966 | H19: =SUM(H14:H18) -> 10392 | I19: =SUM(I14:I18) -> 17324 | J19: =SUM(J14:J18) -> 13277 | K19: =SUM(K14:K18) -> 17609 | ... X19: =SUM(X14:X18) -> 10603.035
C20: Tax | D20: 184 | E20: -1715 | F20: -1778 | G20: -3700 | H20: -3101 | I20: -1776 | J20: -2390 | K20: -2613 | L20: -1156 | M20: -2590 | N20: =N19*-0.2 -> -1796.703 | O20: =O19*-0.2 -> -2120.607 | P20: =P19*-0.2 -> -2120.607 | Q20: =Q19*-0.2 -> -2120.607 | R20: =R19*-0.2 -> -2120.607 | S20: =S19*-0.2 -> -2120.607 | T20: =T19*-0.2 -> -2120.607 | U20: =U19*-0.2 -> -2120.607 | ... X20: =X19*-0.2 -> -2120.607
C21: Net income | D21: =SUM(D19:D20) -> 1854 | E21: =SUM(E19:E20) -> 10467 | F21: =SUM(F19:F20) -> 13321 | G21: =SUM(G19:G20) -> 18266 | H21: =SUM(H19:H20) -> 7291 | I21: =SUM(I19:I20) -> 15548 | J21: =SUM(J19:J20) -> 10887 | K21: =SUM(K19:K20) -> 14996 | ... X21: =SUM(X19:X20) -> 8482.428 | Y21: =X21*(1+$AA$25) -> 8397.6037 | Z21: =Y21*(1+$AA$25) -> 8313.6277 | AA21: =Z21*(1+$AA$25) -> 8230.4914 | AB21: =AA21*(1+$AA$25) -> 8148.1865 | AC21: =AB21*(1+$AA$25) -> 8066.7046 | AD21: =AC21*(1+$AA$25) -> 7986.0376 | AE21: =AD21*(1+$AA$25) -> 7906.1772 | AF21: =AE21*(1+$AA$25) -> 7827.1154 | ... EK21: =EJ21*(1+$AA$25) -> 2617.2063
C22: Share | D22: 420.381 | E22: 420.381 | F22: 420.381 | G22: 420.381 | H22: 420.381 | I22: 420.381 | J22: 420.381 | K22: 420.381 | L22: 420.381 | M22: 420.381 | N22: 420.381 | O22: 1321.1976 | P22: 1321.1976 | Q22: 1321.1976 | R22: 1321.1976 | S22: 1321.1976 | T22: 1321.1976 | U22: 1321.1976 | V22: 1321.1976 | W22: 1321.1976 | X22: 1321.1976
C23: EPS | D23: =D21/D22 -> 4.410285 | E23: =E21/E22 -> 24.898842 | F23: =F21/F22 -> 31.687921 | G23: =G21/G22 -> 43.45106 | H23: =H21/H22 -> 17.343791 | I23: =I21/I22 -> 36.985496 | J23: =J21/J22 -> 25.897935 | K23: =K21/K22 -> 35.672402 | ... X23: =X21/X22 -> 6.4202569
Z24: Discount | AA24: 0.08
C25: Revenue y/y | E25: =(E4-D4)/D4 -> -0.13963842 | F25: =(F4-E4)/E4 -> 0.040353353 | G25: =(G4-F4)/F4 -> 0.26480095 | H25: =(H4-G4)/G4 -> -0.067823093 | I25: =(I4-H4)/H4 -> -0.2876076 | J25: =(J4-I4)/I4 -> 0.54878268 | K25: =(K4-J4)/J4 -> 0.70299847 | L25: =(L4-K4)/K4 -> -0.40084066 | ... X25: =(X4-W4)/W4 -> 0 | Z25: TV | AA25: -0.01
C26: Gross margin | D26: =D6/D4 -> 0.22736403 | E26: =E6/E4 -> 0.34448452 | F26: =F6/F4 -> 0.3184612 | G26: =G6/G4 -> 0.28471928 | H26: =H6/H4 -> 0.3915168 | I26: =I6/I4 -> 0.48587266 | J26: =J6/J4 -> 0.31623602 | K26: =K6/K4 -> 0.26545809 | ... X26: =X6/X4 -> 0.45 | Z26: NPV | AA26: =NPV(AA24,N21:EK21) -> 99372.237
C27: EBITDA margin | D27: =D12/D4 -> 0.1482281 | E27: =E12/E4 -> 0.29514052 | F27: =F12/F4 -> 0.37806696 | G27: =G12/G4 -> 0.3772643 | H27: =H12/H4 -> 0.27017813 | I27: =I12/I4 -> 0.3309605 | J27: =J12/J4 -> 0.31279853 | K27: =K12/K4 -> 0.2423475 | ... X27: =X12/X4 -> 0.23747397 | Z27: S/O | AA27: 1321.1976
C28: EBIT margin | D28: =D14/D4 -> 0.045436829 | E28: =E14/E4 -> 0.20397958 | F28: =F14/F4 -> 0.27282319 | G28: =G14/G4 -> 0.3060911 | H28: =H14/H4 -> 0.16460695 | I28: =I14/I4 -> 0.17965743 | J28: =J14/J4 -> 0.20850231 | K28: =K14/K4 -> 0.14948933 | ... X28: =X14/X4 -> 0.1762663 | Z28: NPV/Share | AA28: =AA26/AA27 -> 75.213758
Z29: Opp/nedside | AA29: =(AA28-Modell!B4)/Modell!B4 -> -0.37321868

Sheet Off wind
A2: USA | E2: UK | O2: Taiwan | T2: Tyskland/Danmark
A4: Block island wind farm | E4: Barrow | J4: Isle of Man | O4: Formosa 1 | T4: Borkum Riffgrund 1 | Z4: Anholdt
A5: Overall capacity: 30 MW | E5: Number of turbines: 30 | J5: Satus: In development | O5: Location: 2-6 km off the coast of Miaoli County | T5: Location: 37km from Borkum, in the German North sea | Z5: Overall capacity: 400 MW
A6: Number of turbines: 5 | E6: Overall capacity 90 MW | O6: Overall capacity: 128 MW | T6: Overall capacity: 312 MW | Z6: Number of turbines: 111
A7: Wind turbine capaicity: 6 MW | E7: Operation since: 2006 | J7: Lincs: | O7: Number of turbines: 22 | T7: Number of turbines: 78 | Z7: Operation since: 2013
A8: Location: 3 miles southeast of Bloclk Island, RI | E8: Location: Northwest coast of England | J8: Location: 8km off the east coast, near Ksegness in Lincolnshire | O8: Operation since: 2017 | T8: Operation since: 2015 | Z8: Location: Between Djursland and Anholt
A9: Operation since: 2016 | E9: Ownership: 100% | J9: Number of turbines: 75 | O9: Ownership: 35% | T9: Ownership: 50% (Greencoat renewables) | Z9: Ownership: 50% (PensionDanmark)
A10: Ownership: 100% | J10: Overall capacity: 270 MW
E11: Burbo Bank | J11: Operation since: 2013 | O11: Greater Changhua | T11: Borkum Riffgrund 2 | Z11: Avedøre
A12: Revolution wind | E12: Number of turbines: 25 | J12: Ownership: 25% (GIG; Octupus renewables | O12: Location: 35-50km of the coast of Changhua County | T12: Location: Adjacent to BR 1 | Z12: Overall capacity: 7,2 MW
A13: Status: Under construction | E13: Overall capacity: 90 MW | O13: Number of turbines: 75 | T13: Overall capacity: 450 MW | Z13: Number of turbines: 2
A14: Capacity: 400 MW to RI and 304 MW to Connecticut | E14: Operation since: 2007 | J14: Race Bank | O14: Overall capacity: 605,2 MW | T14: Number of turbines: 56 | Z14: Operation since: 2009-2011
A15: Location: 15 miles south of the RI coast | E15: Location: Burbo Flats in Liverpool Bay | J15: Location: 17 miles off Blakeney Point | O15: Ownership: 50% (CDPQ & Cathay PE | T15: Operation since: 2018 | Z15: Location: Avedøre
A16: Expected completion: H2 2026 | E16: Ownership: 100% | J16: Number of turbines: 91 | O16: Operation since: 2024 | T16: Ownership: 50% (Gulf Energy) | Z16: Ownership: 100%
A17: Ownership: 50% (Global Infrastructure partners) | J17: Overall capicity: 546 MW
E18: Burbo Bank Extension | J18: Operation since: 2018 | O18: Greater Changhua 2a | T18: Borkum Riffgrund 3 | Z18: Horns Rev 1
A19: South fork wind | E19: Number of turbines: 32 | J19: Ownership: 50% (MIRA, RE Fund) | O19: Location: 35-50km of the coast of Changhua County | T19: Status: Under construction | Z19: Overall capacity: 160 MW
A20: Capacity: 132 MW | E20: Overall capacity 250 MW | O20: Number of turbines: 36 | T20: Location: Adjacent to BR 1 and 2 | Z20: Number of turbines: 80
A21: Number of turbines: 12 | E21: Operation since: 2017 | J21: Walney | O21: Overall capacity: 294,8 MW | T21: Overall capacity: 913 MW | Z21: Operation since: 2002
A22: Wind turbine capacity: 11MW | E22: Location: Burbo Flats in Liverpool Bay | J22: Location: 15km from Coastline of Walney Island | O22: Ownership: 100% | T22: Number of turbines: 83 | Z22: Location: North sea
A23: Location: 35 miles east of Montauk Point | E23: Ownership: 50% (LEGO (Kirkbi), Greencoat | J23: Number of turbines: 102 | O23: Operation since: 2024 | T23: Ownership: 50% (Nuveen Infrastructure) | Z23: Ownership: 40% (Vattenfall)
A24: Operation since: 2024 | J24: Overall capacity: 367 MW | T24: Expected Commissioning: Q1 2026
A25: Owership: 50% (Global Infrastructure partners) | E25: Gunfleet Sands 1& 2 | J25: Operation since 2012 | O25: Greater Changhua 2b & 4 | Z25: Horns Rev 2
E26: Number of turbines: 48 | J26: Ownership: 50% (PGGM; Greencoat) | O26: Status: Under construction | T26: Gode wind 1 & 2 | Z26: Overall capacity: 209 MW
A27: Sunrise wind | E27: Overall capacity: 173 MW | O27: Location: Coast of Changhua County | T27: Location: 50km from Lower Saxony coast | Z27: Number of turbines: 91
A28: Status: Under construction | E28: Operation since: 2010 | J28: Walney Extension | O28: Overall capacity: 940 MW | T28: Overall capacity: 582 MW | Z28: Operation since: 2009
A29: Capacity: 924 MW | E29: Location: 7km southeast of Essex | J29: Location: approx 19 km West of Barrow-in-Furness | O29: Ownership: 100% | T29: Number of turbines: 97 | Z29: Location: 30km off Esbjerg
A30: Location: 30 miles east of Long Island's Montauk Point | E30: Ownership: 50% (JERA, Dev bank of Japan) | J30: Number of turbines: 87 | O30: Expected commissioning: Q3 26 | T30: Operation since: 2016 | Z30: Ownership: 100%
A31: Expection operation: H2 27 | J31: Overall capacity: 659 MW | T31: Ownership: 50% (Nuveen infrastructure ...)
A32: Ownership: 100% | E32: Gunfleet Sands 3 | J32: Operation since 2018 | O32: Poland | Z32: Nysted
E33: Location: 7km southeast of Essex | J33: Ownership: 50% (AIP, PFA) | T33: Gode wind 3 | Z33: Overall capacity: 165,6 MW
E34: Number of turbines: 2 | O34: Baltica 2 & 3 | T34: Location: 50km from Lower Saxony coast | Z34: Number of turbines: 72
E35: Overall capacity: 12 MW | J35: West of Duddon Sands | O35: Status: awarded | T35: Overall capacity: 253 MW | Z35: Operation since: 2003
E36: Operation since: 2013 | J36: Location: 14km from Walney Island, Cumbria | O36: Capacity: Baltica 2 (1498 MW), Baltica 3 (1255 MW) | T36: Number of turbines: 23 | Z36: Location: 10km South of Nysted
E37: Ownership: 100% | J37: Number of turbines: 108 | O37: Expected commissioning: Baltica 2 ( H2 2027), Baltica 3 (2029) | T37: Operation since: 2025 | Z37: Ownership: 42,7%
J38: Overall capacity: 389 MW | T38: Ownership: 50% (Nuveen infrastructure)
E39: Hornsea 1 | J39: Operation since: 2014 | O39: Nederland
E40: Number of turbines: 174 | J40: Ownership: 50% (Scottish Power Renewables)
E41: Overall capacity: 1218 MW | O41: Borssele 1 & 2
E42: Wind turbines capacity: 7 MW | J42: Westermost Rough | O42: Location: In the North Sea, 23 km off the Dutch Zeeland coast
...

Sheet On wind

Sheet Solar
A15: Germany | D15: Ireland/UK | I15: US
A16: Altenschwand | D16: Ballinrea solar farm | I16: Eleven mile solar center
A17: Status: in operation | D17: Status: Under construction | I17: Status: in operation
A18: Location: Bodenwöhr, Bavaria | D18: Solar capacity: 55 MWac | I18: Location: Pinal County, Arizona
A19: Number of panels: 18 972 | D19: Target operation: 2026 | I19: Solar capacity: 300 MWac
A20: Solar capacity: 10,4 MWp | I20: Operation since: 2022
A21: Operation since: 2022 | D21: Garreenleen solar farm
D22: Status: Under construction | I22: Helena Energy Center
A23: Amberg Sud | D23: Location: 15 km outside of Carlow town | I23: Status: in operation
A24: Status: in operation | D24: Solar capacity: first phase 81 MW, second phase 79 MW | I24: Location: Bee County, Texas
A25: Location: Amberg, in the Oberpfalz | D25: Target operation: 2026 | I25: Solar capacity: 250 MWac
A26: Number of panels: 7 690 | I26: Operation since: 2024
A27: Solar capacity: 4,8 MWac | D27: Carnegie Road Storage project
A28: Operation since: 2024 | D28: Status: In operation | I28: Mocingbird Solar center
D29: Location: Liverpool | I29: Status: in operation
A30: Hatzenhof Solarpark | D30: Solar capacity: 20 MWc | I30: Location: Lamar County, Texas
A31: Status: in operation | D31: Operation since: 2018 | I31: Solar capacity: 470 MWac
A32: Solar capacity: 9 MWac | I32: Operation since: 2024
A33: Operation since: 2025
I34: Muscle Shoals
A35: Rottenegg Solarpark | I35: Status: in operation
A36: Status: Under construction | I36: Location: Colbert County, alabama
A37: Solar capacity: 6 MWac | I37: Solar capacity: 227 MWac
A38: Operation since: 2025 | I38: Operation since: 2021
I40: Old 300 Solar center
I41: Status: in operation
I42: Location: Fort Bend County, Texas
I43: Solar capacity: 430 MWac
I44: Operation since: 2023
I46: Permian Energy center
I47: Status: in operation
I48: Location: Andrews County, Texas
I49: Solar capacity: 420 MWac
I50: Operation since: 2021
